ts_recv,ts_event,rtype,publisher_id,instrument_id,action,side,depth,price,size,flags,ts_in_delta,sequence,bid_px_00,bid_sz_00,bid_ct_00,ask_px_00,ask_sz_00,ask_ct_00,bid_px_01,bid_sz_01,bid_ct_01,ask_px_01,ask_sz_01,ask_ct_01,bid_px_02,bid_sz_02,bid_ct_02,ask_px_02,ask_sz_02,ask_ct_02,bid_px_03,bid_sz_03,bid_ct_03,ask_px_03,ask_sz_03,ask_ct_03,bid_px_04,bid_sz_04,bid_ct_04,ask_px_04,ask_sz_04,ask_ct_04,bid_px_05,bid_sz_05,bid_ct_05,ask_px_05,ask_sz_05,ask_ct_05,bid_px_06,bid_sz_06,bid_ct_06,ask_px_06,ask_sz_06,ask_ct_06,bid_px_07,bid_sz_07,bid_ct_07,ask_px_07,ask_sz_07,ask_ct_07,bid_px_08,bid_sz_08,bid_ct_08,ask_px_08,ask_sz_08,ask_ct_08,bid_px_09,bid_sz_09,bid_ct_09,ask_px_09,ask_sz_09,ask_ct_09,symbol,order_id
2025-07-17T15:36:36.152132527Z,2025-07-17T15:36:36.151966883Z,10,2,1108,A,B,1,13.26,100,130,165644,245183955,13.270000,10,1,13.780000,100,1,13.260000,100,1,13.800000,100,1,13.140000,2,1,13.950000,2,1,13.030000,100,1,14.120000,100,1,12.730000,100,1,14.400000,100,1,12.710000,100,1,14.560000,800,2,12.500000,700,1,14.600000,700,1,12.460000,200,2,14.650000,100,1,12.430000,700,1,14.680000,1400,2,12.420000,700,1,14.720000,200,2,ARL,291975017
2025-07-17T15:36:46.889917278Z,2025-07-17T15:36:46.889749756Z,10,2,1108,C,B,0,13.27,10,128,167522,245499598,13.260000,100,1,13.780000,100,1,13.140000,2,1,13.800000,100,1,13.030000,100,1,13.950000,2,1,12.730000,100,1,14.120000,100,1,12.710000,100,1,14.400000,100,1,12.500000,700,1,14.560000,800,2,12.460000,200,2,14.600000,700,1,12.430000,700,1,14.650000,100,1,12.420000,700,1,14.680000,1400,2,12.370000,700,1,14.720000,200,2,ARL,291964737
2025-07-17T15:36:46.986820391Z,2025-07-17T15:36:46.986655137Z,10,2,1108,C,A,1,13.80,100,130,165254,245503745,13.260000,100,1,13.780000,100,1,13.140000,2,1,13.950000,2,1,13.030000,100,1,14.120000,100,1,12.730000,100,1,14.400000,100,1,12.710000,100,1,14.560000,800,2,12.500000,700,1,14.600000,700,1,12.460000,200,2,14.650000,100,1,12.430000,700,1,14.680000,1400,2,12.420000,700,1,14.720000,200,2,12.370000,700,1,14.810000,200,2,ARL,291778909
2025-07-17T15:36:50.997434689Z,2025-07-17T15:36:50.997269299Z,10,2,1108,A,A,1,13.82,100,130,165390,245564901,13.260000,100,1,13.780000,100,1,13.140000,2,1,13.820000,100,1,13.030000,100,1,13.950000,2,1,12.730000,100,1,14.120000,100,1,12.710000,100,1,14.400000,100,1,12.500000,700,1,14.560000,800,2,12.460000,200,2,14.600000,700,1,12.430000,700,1,14.650000,100,1,12.420000,700,1,14.680000,1400,2,12.370000,700,1,14.720000,200,2,ARL,292434813
2025-07-17T15:37:40.389737573Z,2025-07-17T15:37:40.389572053Z,10,2,1108,C,B,1,13.14,2,0,165520,246491394,13.260000,100,1,13.780000,100,1,13.030000,100,1,13.820000,100,1,12.730000,100,1,13.950000,2,1,12.710000,100,1,14.120000,100,1,12.500000,700,1,14.400000,100,1,12.460000,200,2,14.560000,800,2,12.430000,700,1,14.600000,700,1,12.420000,700,1,14.650000,100,1,12.370000,700,1,14.680000,1400,2,12.360000,200,2,14.720000,200,2,ARL,289828293
2025-07-17T15:37:40.389737573Z,2025-07-17T15:37:40.389572053Z,10,2,1108,A,B,1,13.04,2,130,165520,246491394,13.260000,100,1,13.780000,100,1,13.040000,2,1,13.820000,100,1,13.030000,100,1,13.950000,2,1,12.730000,100,1,14.120000,100,1,12.710000,100,1,14.400000,100,1,12.500000,700,1,14.560000,800,2,12.460000,200,2,14.600000,700,1,12.430000,700,1,14.650000,100,1,12.420000,700,1,14.680000,1400,2,12.370000,700,1,14.720000,200,2,ARL,293594281
2025-07-17T15:39:27.070109669Z,2025-07-17T15:39:27.069942913Z,10,2,1108,A,A,1,13.80,100,128,166756,248436908,13.260000,100,1,13.780000,100,1,13.040000,2,1,13.800000,100,1,13.030000,100,1,13.820000,100,1,12.730000,100,1,13.950000,2,1,12.710000,100,1,14.120000,100,1,12.500000,700,1,14.400000,100,1,12.460000,200,2,14.560000,800,2,12.430000,700,1,14.600000,700,1,12.420000,700,1,14.650000,100,1,12.370000,700,1,14.680000,1400,2,ARL,296059685
2025-07-17T15:39:27.077565902Z,2025-07-17T15:39:27.077400388Z,10,2,1108,C,A,2,13.82,100,130,165514,248437548,13.260000,100,1,13.780000,100,1,13.040000,2,1,13.800000,100,1,13.030000,100,1,13.950000,2,1,12.730000,100,1,14.120000,100,1,12.710000,100,1,14.400000,100,1,12.500000,700,1,14.560000,800,2,12.460000,200,2,14.600000,700,1,12.430000,700,1,14.650000,100,1,12.420000,700,1,14.680000,1400,2,12.370000,700,1,14.720000,200,2,ARL,292434813
2025-07-17T15:39:30.509853083Z,2025-07-17T15:39:30.509687817Z,10,2,1108,A,A,0,13.76,15,130,165266,248491930,13.260000,100,1,13.760000,15,1,13.040000,2,1,13.780000,100,1,13.030000,100,1,13.800000,100,1,12.730000,100,1,13.950000,2,1,12.710000,100,1,14.120000,100,1,12.500000,700,1,14.400000,100,1,12.460000,200,2,14.560000,800,2,12.430000,700,1,14.600000,700,1,12.420000,700,1,14.650000,100,1,12.370000,700,1,14.680000,1400,2,ARL,296136617
2025-07-17T15:39:30.573217843Z,2025-07-17T15:39:30.573052284Z,10,2,1108,C,A,1,13.78,100,0,165559,248492793,13.260000,100,1,13.760000,15,1,13.040000,2,1,13.800000,100,1,13.030000,100,1,13.950000,2,1,12.730000,100,1,14.120000,100,1,12.710000,100,1,14.400000,100,1,12.500000,700,1,14.560000,800,2,12.460000,200,2,14.600000,700,1,12.430000,700,1,14.650000,100,1,12.420000,700,1,14.680000,1400,2,12.370000,700,1,14.720000,200,2,ARL,289726281
2025-07-17T15:39:30.573217843Z,2025-07-17T15:39:30.573052284Z,10,2,1108,A,A,1,13.77,100,130,165559,248492793,13.260000,100,1,13.760000,15,1,13.040000,2,1,13.770000,100,1,13.030000,100,1,13.800000,100,1,12.730000,100,1,13.950000,2,1,12.710000,100,1,14.120000,100,1,12.500000,700,1,14.400000,100,1,12.460000,200,2,14.560000,800,2,12.430000,700,1,14.600000,700,1,12.420000,700,1,14.650000,100,1,12.370000,700,1,14.680000,1400,2,ARL,296137537
2025-07-17T15:39:30.589169820Z,2025-07-17T15:39:30.589004378Z,10,2,1108,C,A,4,14.12,100,130,165442,248493012,13.260000,100,1,13.760000,15,1,13.040000,2,1,13.770000,100,1,13.030000,100,1,13.800000,100,1,12.730000,100,1,13.950000,2,1,12.710000,100,1,14.400000,100,1,12.500000,700,1,14.560000,800,2,12.460000,200,2,14.600000,700,1,12.430000,700,1,14.650000,100,1,12.420000,700,1,14.680000,1400,2,12.370000,700,1,14.720000,200,2,ARL,286680917
2025-07-17T15:39:30.589224596Z,2025-07-17T15:39:30.589059301Z,10,2,1108,A,A,4,14.05,100,130,165295,248493014,13.260000,100,1,13.760000,15,1,13.040000,2,1,13.770000,100,1,13.030000,100,1,13.800000,100,1,12.730000,100,1,13.950000,2,1,12.710000,100,1,14.050000,100,1,12.500000,700,1,14.400000,100,1,12.460000,200,2,14.560000,800,2,12.430000,700,1,14.600000,700,1,12.420000,700,1,14.650000,100,1,12.370000,700,1,14.680000,1400,2,ARL,296137769
2025-07-17T15:39:31.092010369Z,2025-07-17T15:39:31.091844988Z,10,2,1108,A,A,2,13.78,100,130,165381,248502203,13.260000,100,1,13.760000,15,1,13.040000,2,1,13.770000,100,1,13.030000,100,1,13.780000,100,1,12.730000,100,1,13.800000,100,1,12.710000,100,1,13.950000,2,1,12.500000,700,1,14.050000,100,1,12.460000,200,2,14.400000,100,1,12.430000,700,1,14.560000,800,2,12.420000,700,1,14.600000,700,1,12.370000,700,1,14.650000,100,1,ARL,296149845
2025-07-17T15:39:31.098856641Z,2025-07-17T15:39:31.098691429Z,10,2,1108,C,A,3,13.80,100,130,165212,248502510,13.260000,100,1,13.760000,15,1,13.040000,2,1,13.770000,100,1,13.030000,100,1,13.780000,100,1,12.730000,100,1,13.950000,2,1,12.710000,100,1,14.050000,100,1,12.500000,700,1,14.400000,100,1,12.460000,200,2,14.560000,800,2,12.430000,700,1,14.600000,700,1,12.420000,700,1,14.650000,100,1,12.370000,700,1,14.680000,1400,2,ARL,296059685
2025-07-17T15:39:40.691151435Z,2025-07-17T15:39:40.690971606Z,10,2,1108,A,A,0,13.73,15,128,179829,248666930,13.260000,100,1,13.730000,15,1,13.040000,2,1,13.760000,15,1,13.030000,100,1,13.770000,100,1,12.730000,100,1,13.780000,100,1,12.710000,100,1,13.950000,2,1,12.500000,700,1,14.050000,100,1,12.460000,200,2,14.400000,100,1,12.430000,700,1,14.560000,800,2,12.420000,700,1,14.600000,700,1,12.370000,700,1,14.650000,100,1,ARL,296365029
2025-07-17T15:39:40.696349429Z,2025-07-17T15:39:40.696182148Z,10,2,1108,C,A,2,13.77,100,0,167281,248669978,13.260000,100,1,13.730000,15,1,13.040000,2,1,13.760000,15,1,13.030000,100,1,13.780000,100,1,12.730000,100,1,13.950000,2,1,12.710000,100,1,14.050000,100,1,12.500000,700,1,14.400000,100,1,12.460000,200,2,14.560000,800,2,12.430000,700,1,14.600000,700,1,12.420000,700,1,14.650000,100,1,12.370000,700,1,14.680000,1400,2,ARL,296137537
2025-07-17T15:39:40.696349429Z,2025-07-17T15:39:40.696182148Z,10,2,1108,A,A,1,13.74,100,130,167281,248669978,13.260000,100,1,13.730000,15,1,13.040000,2,1,13.740000,100,1,13.030000,100,1,13.760000,15,1,12.730000,100,1,13.780000,100,1,12.710000,100,1,13.950000,2,1,12.500000,700,1,14.050000,100,1,12.460000,200,2,14.400000,100,1,12.430000,700,1,14.560000,800,2,12.420000,700,1,14.600000,700,1,12.370000,700,1,14.650000,100,1,ARL,296368281
2025-07-17T15:39:40.697414147Z,2025-07-17T15:39:40.697247480Z,10,2,1108,C,A,14,14.85,100,0,166667,248670386,13.260000,100,1,13.730000,15,1,13.040000,2,1,13.740000,100,1,13.030000,100,1,13.760000,15,1,12.730000,100,1,13.780000,100,1,12.710000,100,1,13.950000,2,1,12.500000,700,1,14.050000,100,1,12.460000,200,2,14.400000,100,1,12.430000,700,1,14.560000,800,2,12.420000,700,1,14.600000,700,1,12.370000,700,1,14.650000,100,1,ARL,289726349
2025-07-17T15:39:40.697414147Z,2025-07-17T15:39:40.697247480Z,10,2,1108,A,A,-1,14.81,100,128,166667,248670386,13.260000,100,1,13.730000,15,1,13.040000,2,1,13.740000,100,1,13.030000,100,1,13.760000,15,1,12.730000,100,1,13.780000,100,1,12.710000,100,1,13.950000,2,1,12.500000,700,1,14.050000,100,1,12.460000,200,2,14.400000,100,1,12.430000,700,1,14.560000,800,2,12.420000,700,1,14.600000,700,1,12.370000,700,1,14.650000,100,1,ARL,296368709
2025-07-17T15:39:40.708810377Z,2025-07-17T15:39:40.708645114Z,10,2,1108,A,A,2,13.76,100,130,165263,248674504,13.260000,100,1,13.730000,15,1,13.040000,2,1,13.740000,100,1,13.030000,100,1,13.760000,115,2,12.730000,100,1,13.780000,100,1,12.710000,100,1,13.950000,2,1,12.500000,700,1,14.050000,100,1,12.460000,200,2,14.400000,100,1,12.430000,700,1,14.560000,800,2,12.420000,700,1,14.600000,700,1,12.370000,700,1,14.650000,100,1,ARL,296372577
2025-07-17T15:39:40.731431547Z,2025-07-17T15:39:40.731266408Z,10,2,1108,C,A,3,13.78,100,130,165139,248676672,13.260000,100,1,13.730000,15,1,13.040000,2,1,13.740000,100,1,13.030000,100,1,13.760000,115,2,12.730000,100,1,13.950000,2,1,12.710000,100,1,14.050000,100,1,12.500000,700,1,14.400000,100,1,12.460000,200,2,14.560000,800,2,12.430000,700,1,14.600000,700,1,12.420000,700,1,14.650000,100,1,12.370000,700,1,14.680000,1400,2,ARL,296149845
2025-07-17T15:39:40.908095999Z,2025-07-17T15:39:40.907929975Z,10,2,1108,C,A,15,15.40,100,0,166024,248685584,13.260000,100,1,13.730000,15,1,13.040000,2,1,13.740000,100,1,13.030000,100,1,13.760000,115,2,12.730000,100,1,13.950000,2,1,12.710000,100,1,14.050000,100,1,12.500000,700,1,14.400000,100,1,12.460000,200,2,14.560000,800,2,12.430000,700,1,14.600000,700,1,12.420000,700,1,14.650000,100,1,12.370000,700,1,14.680000,1400,2,ARL,146959177
2025-07-17T15:39:40.908095999Z,2025-07-17T15:39:40.907929975Z,10,2,1108,A,A,-1,15.12,100,130,166024,248685584,13.260000,100,1,13.730000,15,1,13.040000,2,1,13.740000,100,1,13.030000,100,1,13.760000,115,2,12.730000,100,1,13.950000,2,1,12.710000,100,1,14.050000,100,1,12.500000,700,1,14.400000,100,1,12.460000,200,2,14.560000,800,2,12.430000,700,1,14.600000,700,1,12.420000,700,1,14.650000,100,1,12.370000,700,1,14.680000,1400,2,ARL,296387089
2025-07-17T15:39:41.085864728Z,2025-07-17T15:39:41.085699437Z,10,2,1108,A,A,6,14.56,100,130,165291,248688410,13.260000,100,1,13.730000,15,1,13.040000,2,1,13.740000,100,1,13.030000,100,1,13.760000,115,2,12.730000,100,1,13.950000,2,1,12.710000,100,1,14.050000,100,1,12.500000,700,1,14.400000,100,1,12.460000,200,2,14.560000,900,3,12.430000,700,1,14.600000,700,1,12.420000,700,1,14.650000,100,1,12.370000,700,1,14.680000,1400,2,ARL,296391881
2025-07-17T15:39:41.085877317Z,2025-07-17T15:39:41.085711985Z,10,2,1108,C,A,12,14.84,100,130,165332,248688411,13.260000,100,1,13.730000,15,1,13.040000,2,1,13.740000,100,1,13.030000,100,1,13.760000,115,2,12.730000,100,1,13.950000,2,1,12.710000,100,1,14.050000,100,1,12.500000,700,1,14.400000,100,1,12.460000,200,2,14.560000,900,3,12.430000,700,1,14.600000,700,1,12.420000,700,1,14.650000,100,1,12.370000,700,1,14.680000,1400,2,ARL,146962993
2025-07-17T15:39:43.773811774Z,2025-07-17T15:39:43.773645905Z,10,2,1108,C,A,10,14.72,100,0,165869,248737506,13.260000,100,1,13.730000,15,1,13.040000,2,1,13.740000,100,1,13.030000,100,1,13.760000,115,2,12.730000,100,1,13.950000,2,1,12.710000,100,1,14.050000,100,1,12.500000,700,1,14.400000,100,1,12.460000,200,2,14.560000,900,3,12.430000,700,1,14.600000,700,1,12.420000,700,1,14.650000,100,1,12.370000,700,1,14.680000,1400,2,ARL,286680577
2025-07-17T15:39:43.773811774Z,2025-07-17T15:39:43.773645905Z,10,2,1108,A,A,8,14.61,100,130,165869,248737506,13.260000,100,1,13.730000,15,1,13.040000,2,1,13.740000,100,1,13.030000,100,1,13.760000,115,2,12.730000,100,1,13.950000,2,1,12.710000,100,1,14.050000,100,1,12.500000,700,1,14.400000,100,1,12.460000,200,2,14.560000,900,3,12.430000,700,1,14.600000,700,1,12.420000,700,1,14.610000,100,1,12.370000,700,1,14.650000,100,1,ARL,296455037
2025-07-17T15:39:43.773904473Z,2025-07-17T15:39:43.773738855Z,10,2,1108,C,A,11,14.72,100,0,165618,248737508,13.260000,100,1,13.730000,15,1,13.040000,2,1,13.740000,100,1,13.030000,100,1,13.760000,115,2,12.730000,100,1,13.950000,2,1,12.710000,100,1,14.050000,100,1,12.500000,700,1,14.400000,100,1,12.460000,200,2,14.560000,900,3,12.430000,700,1,14.600000,700,1,12.420000,700,1,14.610000,100,1,12.370000,700,1,14.650000,100,1,ARL,286680573
2025-07-17T15:39:43.773904473Z,2025-07-17T15:39:43.773738855Z,10,2,1108,A,A,8,14.61,100,130,165618,248737508,13.260000,100,1,13.730000,15,1,13.040000,2,1,13.740000,100,1,13.030000,100,1,13.760000,115,2,12.730000,100,1,13.950000,2,1,12.710000,100,1,14.050000,100,1,12.500000,700,1,14.400000,100,1,12.460000,200,2,14.560000,900,3,12.430000,700,1,14.600000,700,1,12.420000,700,1,14.610000,200,2,12.370000,700,1,14.650000,100,1,ARL,296455041
2025-07-17T15:39:44.428670900Z,2025-07-17T15:39:44.428505546Z,10,2,1108,C,A,2,13.76,15,130,165354,248751670,13.260000,100,1,13.730000,15,1,13.040000,2,1,13.740000,100,1,13.030000,100,1,13.760000,100,1,12.730000,100,1,13.950000,2,1,12.710000,100,1,14.050000,100,1,12.500000,700,1,14.400000,100,1,12.460000,200,2,14.560000,900,3,12.430000,700,1,14.600000,700,1,12.420000,700,1,14.610000,200,2,12.370000,700,1,14.650000,100,1,ARL,296136617
2025-07-17T15:39:44.433539292Z,2025-07-17T15:39:44.433372235Z,10,2,1108,C,A,0,13.73,15,128,167057,248752483,13.260000,100,1,13.740000,100,1,13.040000,2,1,13.760000,100,1,13.030000,100,1,13.950000,2,1,12.730000,100,1,14.050000,100,1,12.710000,100,1,14.400000,100,1,12.500000,700,1,14.560000,900,3,12.460000,200,2,14.600000,700,1,12.430000,700,1,14.610000,200,2,12.420000,700,1,14.650000,100,1,12.370000,700,1,14.680000,1400,2,ARL,296365029
2025-07-17T15:39:44.436054885Z,2025-07-17T15:39:44.435889060Z,10,2,1108,C,A,0,13.74,100,130,165825,248752938,13.260000,100,1,13.760000,100,1,13.040000,2,1,13.950000,2,1,13.030000,100,1,14.050000,100,1,12.730000,100,1,14.400000,100,1,12.710000,100,1,14.560000,900,3,12.500000,700,1,14.600000,700,1,12.460000,200,2,14.610000,200,2,12.430000,700,1,14.650000,100,1,12.420000,700,1,14.680000,1400,2,12.370000,700,1,14.810000,300,3,ARL,296368281
2025-07-17T15:39:44.450239090Z,2025-07-17T15:39:44.450073949Z,10,2,1108,C,A,0,13.76,100,130,165141,248753643,13.260000,100,1,13.950000,2,1,13.040000,2,1,14.050000,100,1,13.030000,100,1,14.400000,100,1,12.730000,100,1,14.560000,900,3,12.710000,100,1,14.600000,700,1,12.500000,700,1,14.610000,200,2,12.460000,200,2,14.650000,100,1,12.430000,700,1,14.680000,1400,2,12.420000,700,1,14.810000,300,3,12.370000,700,1,15.120000,100,1,ARL,296372577
2025-07-17T15:39:44.450972330Z,2025-07-17T15:39:44.450806746Z,10,2,1108,C,A,8,14.81,100,0,165584,248753673,13.260000,100,1,13.950000,2,1,13.040000,2,1,14.050000,100,1,13.030000,100,1,14.400000,100,1,12.730000,100,1,14.560000,900,3,12.710000,100,1,14.600000,700,1,12.500000,700,1,14.610000,200,2,12.460000,200,2,14.650000,100,1,12.430000,700,1,14.680000,1400,2,12.420000,700,1,14.810000,200,2,12.370000,700,1,15.120000,100,1,ARL,296368709
2025-07-17T15:39:44.450972330Z,2025-07-17T15:39:44.450806746Z,10,2,1108,A,A,9,15.06,100,130,165584,248753673,13.260000,100,1,13.950000,2,1,13.040000,2,1,14.050000,100,1,13.030000,100,1,14.400000,100,1,12.730000,100,1,14.560000,900,3,12.710000,100,1,14.600000,700,1,12.500000,700,1,14.610000,200,2,12.460000,200,2,14.650000,100,1,12.430000,700,1,14.680000,1400,2,12.420000,700,1,14.810000,200,2,12.370000,700,1,15.060000,100,1,ARL,296478965
2025-07-17T15:39:44.451075992Z,2025-07-17T15:39:44.450910591Z,10,2,1108,C,A,0,13.95,2,0,165401,248753678,13.260000,100,1,14.050000,100,1,13.040000,2,1,14.400000,100,1,13.030000,100,1,14.560000,900,3,12.730000,100,1,14.600000,700,1,12.710000,100,1,14.610000,200,2,12.500000,700,1,14.650000,100,1,12.460000,200,2,14.680000,1400,2,12.430000,700,1,14.810000,200,2,12.420000,700,1,15.060000,100,1,12.370000,700,1,15.120000,100,1,ARL,287540393
2025-07-17T15:39:44.451075992Z,2025-07-17T15:39:44.450910591Z,10,2,1108,A,A,1,14.07,2,130,165401,248753678,13.260000,100,1,14.050000,100,1,13.040000,2,1,14.070000,2,1,13.030000,100,1,14.400000,100,1,12.730000,100,1,14.560000,900,3,12.710000,100,1,14.600000,700,1,12.500000,700,1,14.610000,200,2,12.460000,200,2,14.650000,100,1,12.430000,700,1,14.680000,1400,2,12.420000,700,1,14.810000,200,2,12.370000,700,1,15.060000,100,1,ARL,296478973
2025-07-17T15:39:44.455130297Z,2025-07-17T15:39:44.454964327Z,10,2,1108,C,A,8,14.81,100,0,165970,248753748,13.260000,100,1,14.050000,100,1,13.040000,2,1,14.070000,2,1,13.030000,100,1,14.400000,100,1,12.730000,100,1,14.560000,900,3,12.710000,100,1,14.600000,700,1,12.500000,700,1,14.610000,200,2,12.460000,200,2,14.650000,100,1,12.430000,700,1,14.680000,1400,2,12.420000,700,1,14.810000,100,1,12.370000,700,1,15.060000,100,1,ARL,286680741
2025-07-17T15:39:44.455130297Z,2025-07-17T15:39:44.454964327Z,10,2,1108,A,A,9,14.96,100,130,165970,248753748,13.260000,100,1,14.050000,100,1,13.040000,2,1,14.070000,2,1,13.030000,100,1,14.400000,100,1,12.730000,100,1,14.560000,900,3,12.710000,100,1,14.600000,700,1,12.500000,700,1,14.610000,200,2,12.460000,200,2,14.650000,100,1,12.430000,700,1,14.680000,1400,2,12.420000,700,1,14.810000,100,1,12.370000,700,1,14.960000,100,1,ARL,296479053
2025-07-17T15:39:44.456288062Z,2025-07-17T15:39:44.456122660Z,10,2,1108,C,A,6,14.65,100,130,165402,248753812,13.260000,100,1,14.050000,100,1,13.040000,2,1,14.070000,2,1,13.030000,100,1,14.400000,100,1,12.730000,100,1,14.560000,900,3,12.710000,100,1,14.600000,700,1,12.500000,700,1,14.610000,200,2,12.460000,200,2,14.680000,1400,2,12.430000,700,1,14.810000,100,1,12.420000,700,1,14.960000,100,1,12.370000,700,1,15.060000,100,1,ARL,286680905
2025-07-17T15:39:44.456377500Z,2025-07-17T15:39:44.456211953Z,10,2,1108,A,A,7,14.78,100,130,165547,248753815,13.260000,100,1,14.050000,100,1,13.040000,2,1,14.070000,2,1,13.030000,100,1,14.400000,100,1,12.730000,100,1,14.560000,900,3,12.710000,100,1,14.600000,700,1,12.500000,700,1,14.610000,200,2,12.460000,200,2,14.680000,1400,2,12.430000,700,1,14.780000,100,1,12.420000,700,1,14.810000,100,1,12.370000,700,1,14.960000,100,1,ARL,296479285
2025-07-17T15:39:44.462055094Z,2025-07-17T15:39:44.461889886Z,10,2,1108,C,A,0,14.05,100,130,165208,248753947,13.260000,100,1,14.070000,2,1,13.040000,2,1,14.400000,100,1,13.030000,100,1,14.560000,900,3,12.730000,100,1,14.600000,700,1,12.710000,100,1,14.610000,200,2,12.500000,700,1,14.680000,1400,2,12.460000,200,2,14.780000,100,1,12.430000,700,1,14.810000,100,1,12.420000,700,1,14.960000,100,1,12.370000,700,1,15.060000,100,1,ARL,296137769
2025-07-17T15:39:44.462108809Z,2025-07-17T15:39:44.461943584Z,10,2,1108,A,A,1,14.26,100,130,165225,248753952,13.260000,100,1,14.070000,2,1,13.040000,2,1,14.260000,100,1,13.030000,100,1,14.400000,100,1,12.730000,100,1,14.560000,900,3,12.710000,100,1,14.600000,700,1,12.500000,700,1,14.610000,200,2,12.460000,200,2,14.680000,1400,2,12.430000,700,1,14.780000,100,1,12.420000,700,1,14.810000,100,1,12.370000,700,1,14.960000,100,1,ARL,296479425
2025-07-17T15:39:44.478923366Z,2025-07-17T15:39:44.478757958Z,10,2,1108,C,A,18,17.58,100,0,165408,248754361,13.260000,100,1,14.070000,2,1,13.040000,2,1,14.260000,100,1,13.030000,100,1,14.400000,100,1,12.730000,100,1,14.560000,900,3,12.710000,100,1,14.600000,700,1,12.500000,700,1,14.610000,200,2,12.460000,200,2,14.680000,1400,2,12.430000,700,1,14.780000,100,1,12.420000,700,1,14.810000,100,1,12.370000,700,1,14.960000,100,1,ARL,286681057
2025-07-17T15:39:44.478923366Z,2025-07-17T15:39:44.478757958Z,10,2,1108,A,A,-1,17.76,100,130,165408,248754361,13.260000,100,1,14.070000,2,1,13.040000,2,1,14.260000,100,1,13.030000,100,1,14.400000,100,1,12.730000,100,1,14.560000,900,3,12.710000,100,1,14.600000,700,1,12.500000,700,1,14.610000,200,2,12.460000,200,2,14.680000,1400,2,12.430000,700,1,14.780000,100,1,12.420000,700,1,14.810000,100,1,12.370000,700,1,14.960000,100,1,ARL,296479893
2025-07-17T15:39:44.491018431Z,2025-07-17T15:39:44.490852860Z,10,2,1108,C,A,15,15.92,100,0,165571,248754608,13.260000,100,1,14.070000,2,1,13.040000,2,1,14.260000,100,1,13.030000,100,1,14.400000,100,1,12.730000,100,1,14.560000,900,3,12.710000,100,1,14.600000,700,1,12.500000,700,1,14.610000,200,2,12.460000,200,2,14.680000,1400,2,12.430000,700,1,14.780000,100,1,12.420000,700,1,14.810000,100,1,12.370000,700,1,14.960000,100,1,ARL,286681229
2025-07-17T15:39:44.491018431Z,2025-07-17T15:39:44.490852860Z,10,2,1108,A,A,-1,16.08,100,130,165571,248754608,13.260000,100,1,14.070000,2,1,13.040000,2,1,14.260000,100,1,13.030000,100,1,14.400000,100,1,12.730000,100,1,14.560000,900,3,12.710000,100,1,14.600000,700,1,12.500000,700,1,14.610000,200,2,12.460000,200,2,14.680000,1400,2,12.430000,700,1,14.780000,100,1,12.420000,700,1,14.810000,100,1,12.370000,700,1,14.960000,100,1,ARL,296480097
2025-07-17T15:39:44.593773213Z,2025-07-17T15:39:44.593607433Z,10,2,1108,C,A,8,14.81,100,0,165780,248756227,13.260000,100,1,14.070000,2,1,13.040000,2,1,14.260000,100,1,13.030000,100,1,14.400000,100,1,12.730000,100,1,14.560000,900,3,12.710000,100,1,14.600000,700,1,12.500000,700,1,14.610000,200,2,12.460000,200,2,14.680000,1400,2,12.430000,700,1,14.780000,100,1,12.420000,700,1,14.960000,100,1,12.370000,700,1,15.060000,100,1,ARL,286684005
2025-07-17T15:39:44.593773213Z,2025-07-17T15:39:44.593607433Z,10,2,1108,A,A,8,14.96,100,130,165780,248756227,13.260000,100,1,14.070000,2,1,13.040000,2,1,14.260000,100,1,13.030000,100,1,14.400000,100,1,12.730000,100,1,14.560000,900,3,12.710000,100,1,14.600000,700,1,12.500000,700,1,14.610000,200,2,12.460000,200,2,14.680000,1400,2,12.430000,700,1,14.780000,100,1,12.420000,700,1,14.960000,200,2,12.370000,700,1,15.060000,100,1,ARL,296482509
2025-07-17T15:39:44.859886562Z,2025-07-17T15:39:44.859720946Z,10,2,1108,C,A,5,14.61,100,0,165616,248760319,13.260000,100,1,14.070000,2,1,13.040000,2,1,14.260000,100,1,13.030000,100,1,14.400000,100,1,12.730000,100,1,14.560000,900,3,12.710000,100,1,14.600000,700,1,12.500000,700,1,14.610000,100,1,12.460000,200,2,14.680000,1400,2,12.430000,700,1,14.780000,100,1,12.420000,700,1,14.960000,200,2,12.370000,700,1,15.060000,100,1,ARL,296455041
2025-07-17T15:39:44.859886562Z,2025-07-17T15:39:44.859720946Z,10,2,1108,A,A,-1,15.10,100,130,165616,248760319,13.260000,100,1,14.070000,2,1,13.040000,2,1,14.260000,100,1,13.030000,100,1,14.400000,100,1,12.730000,100,1,14.560000,900,3,12.710000,100,1,14.600000,700,1,12.500000,700,1,14.610000,100,1,12.460000,200,2,14.680000,1400,2,12.430000,700,1,14.780000,100,1,12.420000,700,1,14.960000,200,2,12.370000,700,1,15.060000,100,1,ARL,296485621
2025-07-17T15:39:44.860160096Z,2025-07-17T15:39:44.859994671Z,10,2,1108,A,A,1,14.08,100,130,165425,248760324,13.260000,100,1,14.070000,2,1,13.040000,2,1,14.080000,100,1,13.030000,100,1,14.260000,100,1,12.730000,100,1,14.400000,100,1,12.710000,100,1,14.560000,900,3,12.500000,700,1,14.600000,700,1,12.460000,200,2,14.610000,100,1,12.430000,700,1,14.680000,1400,2,12.420000,700,1,14.780000,100,1,12.370000,700,1,14.960000,200,2,ARL,296485629
2025-07-17T15:39:44.863678795Z,2025-07-17T15:39:44.863513587Z,10,2,1108,C,A,6,14.61,100,0,165208,248760417,13.260000,100,1,14.070000,2,1,13.040000,2,1,14.080000,100,1,13.030000,100,1,14.260000,100,1,12.730000,100,1,14.400000,100,1,12.710000,100,1,14.560000,900,3,12.500000,700,1,14.600000,700,1,12.460000,200,2,14.680000,1400,2,12.430000,700,1,14.780000,100,1,12.420000,700,1,14.960000,200,2,12.370000,700,1,15.060000,100,1,ARL,296455037
2025-07-17T15:39:44.863678795Z,2025-07-17T15:39:44.863513587Z,10,2,1108,A,A,-1,15.10,100,130,165208,248760417,13.260000,100,1,14.070000,2,1,13.040000,2,1,14.080000,100,1,13.030000,100,1,14.260000,100,1,12.730000,100,1,14.400000,100,1,12.710000,100,1,14.560000,900,3,12.500000,700,1,14.600000,700,1,12.460000,200,2,14.680000,1400,2,12.430000,700,1,14.780000,100,1,12.420000,700,1,14.960000,200,2,12.370000,700,1,15.060000,100,1,ARL,296485649
2025-07-17T15:39:54.187008224Z,2025-07-17T15:39:54.186842327Z,10,2,1108,C,A,10,15.10,100,0,165897,248915116,13.260000,100,1,14.070000,2,1,13.040000,2,1,14.080000,100,1,13.030000,100,1,14.260000,100,1,12.730000,100,1,14.400000,100,1,12.710000,100,1,14.560000,900,3,12.500000,700,1,14.600000,700,1,12.460000,200,2,14.680000,1400,2,12.430000,700,1,14.780000,100,1,12.420000,700,1,14.960000,200,2,12.370000,700,1,15.060000,100,1,ARL,296485649
2025-07-17T15:39:54.187008224Z,2025-07-17T15:39:54.186842327Z,10,2,1108,A,A,8,14.88,100,130,165897,248915116,13.260000,100,1,14.070000,2,1,13.040000,2,1,14.080000,100,1,13.030000,100,1,14.260000,100,1,12.730000,100,1,14.400000,100,1,12.710000,100,1,14.560000,900,3,12.500000,700,1,14.600000,700,1,12.460000,200,2,14.680000,1400,2,12.430000,700,1,14.780000,100,1,12.420000,700,1,14.880000,100,1,12.370000,700,1,14.960000,200,2,ARL,296679277
2025-07-17T15:39:54.187557412Z,2025-07-17T15:39:54.187391707Z,10,2,1108,C,A,11,15.10,100,0,165705,248915126,13.260000,100,1,14.070000,2,1,13.040000,2,1,14.080000,100,1,13.030000,100,1,14.260000,100,1,12.730000,100,1,14.400000,100,1,12.710000,100,1,14.560000,900,3,12.500000,700,1,14.600000,700,1,12.460000,200,2,14.680000,1400,2,12.430000,700,1,14.780000,100,1,12.420000,700,1,14.880000,100,1,12.370000,700,1,14.960000,200,2,ARL,296485621
2025-07-17T15:39:54.187557412Z,2025-07-17T15:39:54.187391707Z,10,2,1108,A,A,8,14.88,100,130,165705,248915126,13.260000,100,1,14.070000,2,1,13.040000,2,1,14.080000,100,1,13.030000,100,1,14.260000,100,1,12.730000,100,1,14.400000,100,1,12.710000,100,1,14.560000,900,3,12.500000,700,1,14.600000,700,1,12.460000,200,2,14.680000,1400,2,12.430000,700,1,14.780000,100,1,12.420000,700,1,14.880000,200,2,12.370000,700,1,14.960000,200,2,ARL,296679285
2025-07-17T15:42:06.780503054Z,2025-07-17T15:42:06.780337543Z,10,2,1108,A,A,0,13.90,15,130,165511,251407709,13.260000,100,1,13.900000,15,1,13.040000,2,1,14.070000,2,1,13.030000,100,1,14.080000,100,1,12.730000,100,1,14.260000,100,1,12.710000,100,1,14.400000,100,1,12.500000,700,1,14.560000,900,3,12.460000,200,2,14.600000,700,1,12.430000,700,1,14.680000,1400,2,12.420000,700,1,14.780000,100,1,12.370000,700,1,14.880000,200,2,ARL,299689753
2025-07-17T15:42:06.780767761Z,2025-07-17T15:42:06.780602350Z,10,2,1108,C,A,2,14.08,100,0,165411,251407713,13.260000,100,1,13.900000,15,1,13.040000,2,1,14.070000,2,1,13.030000,100,1,14.260000,100,1,12.730000,100,1,14.400000,100,1,12.710000,100,1,14.560000,900,3,12.500000,700,1,14.600000,700,1,12.460000,200,2,14.680000,1400,2,12.430000,700,1,14.780000,100,1,12.420000,700,1,14.880000,200,2,12.370000,700,1,14.960000,200,2,ARL,296485629
2025-07-17T15:42:06.780767761Z,2025-07-17T15:42:06.780602350Z,10,2,1108,A,A,1,13.91,100,130,165411,251407713,13.260000,100,1,13.900000,15,1,13.040000,2,1,13.910000,100,1,13.030000,100,1,14.070000,2,1,12.730000,100,1,14.260000,100,1,12.710000,100,1,14.400000,100,1,12.500000,700,1,14.560000,900,3,12.460000,200,2,14.600000,700,1,12.430000,700,1,14.680000,1400,2,12.420000,700,1,14.780000,100,1,12.370000,700,1,14.880000,200,2,ARL,299689769
2025-07-17T15:42:06.781502831Z,2025-07-17T15:42:06.781336642Z,10,2,1108,C,A,11,15.06,100,0,166189,251407747,13.260000,100,1,13.900000,15,1,13.040000,2,1,13.910000,100,1,13.030000,100,1,14.070000,2,1,12.730000,100,1,14.260000,100,1,12.710000,100,1,14.400000,100,1,12.500000,700,1,14.560000,900,3,12.460000,200,2,14.600000,700,1,12.430000,700,1,14.680000,1400,2,12.420000,700,1,14.780000,100,1,12.370000,700,1,14.880000,200,2,ARL,296478965
2025-07-17T15:42:06.781502831Z,2025-07-17T15:42:06.781336642Z,10,2,1108,A,A,-1,14.99,100,130,166189,251407747,13.260000,100,1,13.900000,15,1,13.040000,2,1,13.910000,100,1,13.030000,100,1,14.070000,2,1,12.730000,100,1,14.260000,100,1,12.710000,100,1,14.400000,100,1,12.500000,700,1,14.560000,900,3,12.460000,200,2,14.600000,700,1,12.430000,700,1,14.680000,1400,2,12.420000,700,1,14.780000,100,1,12.370000,700,1,14.880000,200,2,ARL,299689857
2025-07-17T15:42:06.795521307Z,2025-07-17T15:42:06.795355762Z,10,2,1108,C,A,3,14.26,100,130,165545,251408268,13.260000,100,1,13.900000,15,1,13.040000,2,1,13.910000,100,1,13.030000,100,1,14.070000,2,1,12.730000,100,1,14.400000,100,1,12.710000,100,1,14.560000,900,3,12.500000,700,1,14.600000,700,1,12.460000,200,2,14.680000,1400,2,12.430000,700,1,14.780000,100,1,12.420000,700,1,14.880000,200,2,12.370000,700,1,14.960000,200,2,ARL,296479425
2025-07-17T15:42:06.795573392Z,2025-07-17T15:42:06.795408057Z,10,2,1108,A,A,3,14.19,100,130,165335,251408269,13.260000,100,1,13.900000,15,1,13.040000,2,1,13.910000,100,1,13.030000,100,1,14.070000,2,1,12.730000,100,1,14.190000,100,1,12.710000,100,1,14.400000,100,1,12.500000,700,1,14.560000,900,3,12.460000,200,2,14.600000,700,1,12.430000,700,1,14.680000,1400,2,12.420000,700,1,14.780000,100,1,12.370000,700,1,14.880000,200,2,ARL,299690593
2025-07-17T15:42:16.264132159Z,2025-07-17T15:42:16.263966448Z,10,2,1108,C,A,9,14.88,100,0,165711,251574391,13.260000,100,1,13.900000,15,1,13.040000,2,1,13.910000,100,1,13.030000,100,1,14.070000,2,1,12.730000,100,1,14.190000,100,1,12.710000,100,1,14.400000,100,1,12.500000,700,1,14.560000,900,3,12.460000,200,2,14.600000,700,1,12.430000,700,1,14.680000,1400,2,12.420000,700,1,14.780000,100,1,12.370000,700,1,14.880000,100,1,ARL,296679285
2025-07-17T15:42:16.264132159Z,2025-07-17T15:42:16.263966448Z,10,2,1108,A,A,8,14.76,100,130,165711,251574391,13.260000,100,1,13.900000,15,1,13.040000,2,1,13.910000,100,1,13.030000,100,1,14.070000,2,1,12.730000,100,1,14.190000,100,1,12.710000,100,1,14.400000,100,1,12.500000,700,1,14.560000,900,3,12.460000,200,2,14.600000,700,1,12.430000,700,1,14.680000,1400,2,12.420000,700,1,14.760000,100,1,12.370000,700,1,14.780000,100,1,ARL,299903169
2025-07-17T15:42:17.356766715Z,2025-07-17T15:42:17.356601231Z,10,2,1108,A,A,0,13.83,15,130,165484,251593608,13.260000,100,1,13.830000,15,1,13.040000,2,1,13.900000,15,1,13.030000,100,1,13.910000,100,1,12.730000,100,1,14.070000,2,1,12.710000,100,1,14.190000,100,1,12.500000,700,1,14.400000,100,1,12.460000,200,2,14.560000,900,3,12.430000,700,1,14.600000,700,1,12.420000,700,1,14.680000,1400,2,12.370000,700,1,14.760000,100,1,ARL,299923773
2025-07-17T15:42:17.577474246Z,2025-07-17T15:42:17.577308779Z,10,2,1108,C,A,2,13.91,100,0,165467,251595553,13.260000,100,1,13.830000,15,1,13.040000,2,1,13.900000,15,1,13.030000,100,1,14.070000,2,1,12.730000,100,1,14.190000,100,1,12.710000,100,1,14.400000,100,1,12.500000,700,1,14.560000,900,3,12.460000,200,2,14.600000,700,1,12.430000,700,1,14.680000,1400,2,12.420000,700,1,14.760000,100,1,12.370000,700,1,14.780000,100,1,ARL,299689769
2025-07-17T15:42:17.577474246Z,2025-07-17T15:42:17.577308779Z,10,2,1108,A,A,1,13.84,100,130,165467,251595553,13.260000,100,1,13.830000,15,1,13.040000,2,1,13.840000,100,1,13.030000,100,1,13.900000,15,1,12.730000,100,1,14.070000,2,1,12.710000,100,1,14.190000,100,1,12.500000,700,1,14.400000,100,1,12.460000,200,2,14.560000,900,3,12.430000,700,1,14.600000,700,1,12.420000,700,1,14.680000,1400,2,12.370000,700,1,14.760000,100,1,ARL,299926781
2025-07-17T15:42:17.578219175Z,2025-07-17T15:42:17.578053644Z,10,2,1108,C,A,13,14.99,100,0,165531,251595563,13.260000,100,1,13.830000,15,1,13.040000,2,1,13.840000,100,1,13.030000,100,1,13.900000,15,1,12.730000,100,1,14.070000,2,1,12.710000,100,1,14.190000,100,1,12.500000,700,1,14.400000,100,1,12.460000,200,2,14.560000,900,3,12.430000,700,1,14.600000,700,1,12.420000,700,1,14.680000,1400,2,12.370000,700,1,14.760000,100,1,ARL,299689857
2025-07-17T15:42:17.578219175Z,2025-07-17T15:42:17.578053644Z,10,2,1108,A,A,-1,14.91,100,130,165531,251595563,13.260000,100,1,13.830000,15,1,13.040000,2,1,13.840000,100,1,13.030000,100,1,13.900000,15,1,12.730000,100,1,14.070000,2,1,12.710000,100,1,14.190000,100,1,12.500000,700,1,14.400000,100,1,12.460000,200,2,14.560000,900,3,12.430000,700,1,14.600000,700,1,12.420000,700,1,14.680000,1400,2,12.370000,700,1,14.760000,100,1,ARL,299926801
2025-07-17T15:42:17.579343189Z,2025-07-17T15:42:17.579177582Z,10,2,1108,C,A,10,14.78,100,0,165607,251595571,13.260000,100,1,13.830000,15,1,13.040000,2,1,13.840000,100,1,13.030000,100,1,13.900000,15,1,12.730000,100,1,14.070000,2,1,12.710000,100,1,14.190000,100,1,12.500000,700,1,14.400000,100,1,12.460000,200,2,14.560000,900,3,12.430000,700,1,14.600000,700,1,12.420000,700,1,14.680000,1400,2,12.370000,700,1,14.760000,100,1,ARL,296479285
2025-07-17T15:42:17.579343189Z,2025-07-17T15:42:17.579177582Z,10,2,1108,A,A,8,14.64,100,130,165607,251595571,13.260000,100,1,13.830000,15,1,13.040000,2,1,13.840000,100,1,13.030000,100,1,13.900000,15,1,12.730000,100,1,14.070000,2,1,12.710000,100,1,14.190000,100,1,12.500000,700,1,14.400000,100,1,12.460000,200,2,14.560000,900,3,12.430000,700,1,14.600000,700,1,12.420000,700,1,14.640000,100,1,12.370000,700,1,14.680000,1400,2,ARL,299926813
2025-07-17T15:42:17.580008869Z,2025-07-17T15:42:17.579843331Z,10,2,1108,C,A,13,14.96,100,0,165538,251595576,13.260000,100,1,13.830000,15,1,13.040000,2,1,13.840000,100,1,13.030000,100,1,13.900000,15,1,12.730000,100,1,14.070000,2,1,12.710000,100,1,14.190000,100,1,12.500000,700,1,14.400000,100,1,12.460000,200,2,14.560000,900,3,12.430000,700,1,14.600000,700,1,12.420000,700,1,14.640000,100,1,12.370000,700,1,14.680000,1400,2,ARL,296479053
2025-07-17T15:42:17.580008869Z,2025-07-17T15:42:17.579843331Z,10,2,1108,A,A,-1,14.81,100,130,165538,251595576,13.260000,100,1,13.830000,15,1,13.040000,2,1,13.840000,100,1,13.030000,100,1,13.900000,15,1,12.730000,100,1,14.070000,2,1,12.710000,100,1,14.190000,100,1,12.500000,700,1,14.400000,100,1,12.460000,200,2,14.560000,900,3,12.430000,700,1,14.600000,700,1,12.420000,700,1,14.640000,100,1,12.370000,700,1,14.680000,1400,2,ARL,299926849
2025-07-17T15:42:17.580035793Z,2025-07-17T15:42:17.579870309Z,10,2,1108,C,A,19,16.08,100,0,165484,251595577,13.260000,100,1,13.830000,15,1,13.040000,2,1,13.840000,100,1,13.030000,100,1,13.900000,15,1,12.730000,100,1,14.070000,2,1,12.710000,100,1,14.190000,100,1,12.500000,700,1,14.400000,100,1,12.460000,200,2,14.560000,900,3,12.430000,700,1,14.600000,700,1,12.420000,700,1,14.640000,100,1,12.370000,700,1,14.680000,1400,2,ARL,296480097
2025-07-17T15:42:17.580035793Z,2025-07-17T15:42:17.579870309Z,10,2,1108,A,A,-1,15.92,100,130,165484,251595577,13.260000,100,1,13.830000,15,1,13.040000,2,1,13.840000,100,1,13.030000,100,1,13.900000,15,1,12.730000,100,1,14.070000,2,1,12.710000,100,1,14.190000,100,1,12.500000,700,1,14.400000,100,1,12.460000,200,2,14.560000,900,3,12.430000,700,1,14.600000,700,1,12.420000,700,1,14.640000,100,1,12.370000,700,1,14.680000,1400,2,ARL,299926853
2025-07-17T15:42:17.580061097Z,2025-07-17T15:42:17.579895610Z,10,2,1108,C,A,14,14.96,100,0,165487,251595578,13.260000,100,1,13.830000,15,1,13.040000,2,1,13.840000,100,1,13.030000,100,1,13.900000,15,1,12.730000,100,1,14.070000,2,1,12.710000,100,1,14.190000,100,1,12.500000,700,1,14.400000,100,1,12.460000,200,2,14.560000,900,3,12.430000,700,1,14.600000,700,1,12.420000,700,1,14.640000,100,1,12.370000,700,1,14.680000,1400,2,ARL,296482509
2025-07-17T15:42:17.580061097Z,2025-07-17T15:42:17.579895610Z,10,2,1108,A,A,-1,14.81,100,130,165487,251595578,13.260000,100,1,13.830000,15,1,13.040000,2,1,13.840000,100,1,13.030000,100,1,13.900000,15,1,12.730000,100,1,14.070000,2,1,12.710000,100,1,14.190000,100,1,12.500000,700,1,14.400000,100,1,12.460000,200,2,14.560000,900,3,12.430000,700,1,14.600000,700,1,12.420000,700,1,14.640000,100,1,12.370000,700,1,14.680000,1400,2,ARL,299926857
2025-07-17T15:42:17.580093535Z,2025-07-17T15:42:17.579928136Z,10,2,1108,C,A,21,17.76,100,0,165399,251595580,13.260000,100,1,13.830000,15,1,13.040000,2,1,13.840000,100,1,13.030000,100,1,13.900000,15,1,12.730000,100,1,14.070000,2,1,12.710000,100,1,14.190000,100,1,12.500000,700,1,14.400000,100,1,12.460000,200,2,14.560000,900,3,12.430000,700,1,14.600000,700,1,12.420000,700,1,14.640000,100,1,12.370000,700,1,14.680000,1400,2,ARL,296479893
2025-07-17T15:42:17.580093535Z,2025-07-17T15:42:17.579928136Z,10,2,1108,A,A,-1,17.58,100,130,165399,251595580,13.260000,100,1,13.830000,15,1,13.040000,2,1,13.840000,100,1,13.030000,100,1,13.900000,15,1,12.730000,100,1,14.070000,2,1,12.710000,100,1,14.190000,100,1,12.500000,700,1,14.400000,100,1,12.460000,200,2,14.560000,900,3,12.430000,700,1,14.600000,700,1,12.420000,700,1,14.640000,100,1,12.370000,700,1,14.680000,1400,2,ARL,299926861
2025-07-17T15:42:17.589263550Z,2025-07-17T15:42:17.589098227Z,10,2,1108,C,A,4,14.19,100,130,165323,251595691,13.260000,100,1,13.830000,15,1,13.040000,2,1,13.840000,100,1,13.030000,100,1,13.900000,15,1,12.730000,100,1,14.070000,2,1,12.710000,100,1,14.400000,100,1,12.500000,700,1,14.560000,900,3,12.460000,200,2,14.600000,700,1,12.430000,700,1,14.640000,100,1,12.420000,700,1,14.680000,1400,2,12.370000,700,1,14.760000,100,1,ARL,299690593
2025-07-17T15:42:17.589316911Z,2025-07-17T15:42:17.589151325Z,10,2,1108,A,A,4,14.12,100,130,165586,251595692,13.260000,100,1,13.830000,15,1,13.040000,2,1,13.840000,100,1,13.030000,100,1,13.900000,15,1,12.730000,100,1,14.070000,2,1,12.710000,100,1,14.120000,100,1,12.500000,700,1,14.400000,100,1,12.460000,200,2,14.560000,900,3,12.430000,700,1,14.600000,700,1,12.420000,700,1,14.640000,100,1,12.370000,700,1,14.680000,1400,2,ARL,299926965
2025-07-17T15:42:18.398220000Z,2025-07-17T15:42:18.398054465Z,10,2,1108,C,A,12,14.88,100,0,165535,251612478,13.260000,100,1,13.830000,15,1,13.040000,2,1,13.840000,100,1,13.030000,100,1,13.900000,15,1,12.730000,100,1,14.070000,2,1,12.710000,100,1,14.120000,100,1,12.500000,700,1,14.400000,100,1,12.460000,200,2,14.560000,900,3,12.430000,700,1,14.600000,700,1,12.420000,700,1,14.640000,100,1,12.370000,700,1,14.680000,1400,2,ARL,296679277
2025-07-17T15:42:18.398220000Z,2025-07-17T15:42:18.398054465Z,10,2,1108,A,A,-1,14.73,100,130,165535,251612478,13.260000,100,1,13.830000,15,1,13.040000,2,1,13.840000,100,1,13.030000,100,1,13.900000,15,1,12.730000,100,1,14.070000,2,1,12.710000,100,1,14.120000,100,1,12.500000,700,1,14.400000,100,1,12.460000,200,2,14.560000,900,3,12.430000,700,1,14.600000,700,1,12.420000,700,1,14.640000,100,1,12.370000,700,1,14.680000,1400,2,ARL,299945073
2025-07-17T15:42:21.517871714Z,2025-07-17T15:42:21.517706139Z,10,2,1108,C,A,2,13.90,15,130,165575,251668179,13.260000,100,1,13.830000,15,1,13.040000,2,1,13.840000,100,1,13.030000,100,1,14.070000,2,1,12.730000,100,1,14.120000,100,1,12.710000,100,1,14.400000,100,1,12.500000,700,1,14.560000,900,3,12.460000,200,2,14.600000,700,1,12.430000,700,1,14.640000,100,1,12.420000,700,1,14.680000,1400,2,12.370000,700,1,14.730000,100,1,ARL,299689753
2025-07-17T15:42:22.522744242Z,2025-07-17T15:42:22.522578675Z,10,2,1108,A,A,0,13.79,15,130,165567,251690950,13.260000,100,1,13.790000,15,1,13.040000,2,1,13.830000,15,1,13.030000,100,1,13.840000,100,1,12.730000,100,1,14.070000,2,1,12.710000,100,1,14.120000,100,1,12.500000,700,1,14.400000,100,1,12.460000,200,2,14.560000,900,3,12.430000,700,1,14.600000,700,1,12.420000,700,1,14.640000,100,1,12.370000,700,1,14.680000,1400,2,ARL,300042293
2025-07-17T15:42:22.533681479Z,2025-07-17T15:42:22.533515955Z,10,2,1108,A,A,1,13.82,100,130,165524,251691033,13.260000,100,1,13.790000,15,1,13.040000,2,1,13.820000,100,1,13.030000,100,1,13.830000,15,1,12.730000,100,1,13.840000,100,1,12.710000,100,1,14.070000,2,1,12.500000,700,1,14.120000,100,1,12.460000,200,2,14.400000,100,1,12.430000,700,1,14.560000,900,3,12.420000,700,1,14.600000,700,1,12.370000,700,1,14.640000,100,1,ARL,300042385
2025-07-17T15:42:23.490247121Z,2025-07-17T15:42:23.490079821Z,10,2,1108,C,A,3,13.84,100,0,167300,251710173,13.260000,100,1,13.790000,15,1,13.040000,2,1,13.820000,100,1,13.030000,100,1,13.830000,15,1,12.730000,100,1,14.070000,2,1,12.710000,100,1,14.120000,100,1,12.500000,700,1,14.400000,100,1,12.460000,200,2,14.560000,900,3,12.430000,700,1,14.600000,700,1,12.420000,700,1,14.640000,100,1,12.370000,700,1,14.680000,1400,2,ARL,299926781
2025-07-17T15:42:23.490247121Z,2025-07-17T15:42:23.490079821Z,10,2,1108,A,A,1,13.80,100,128,167300,251710173,13.260000,100,1,13.790000,15,1,13.040000,2,1,13.800000,100,1,13.030000,100,1,13.820000,100,1,12.730000,100,1,13.830000,15,1,12.710000,100,1,14.070000,2,1,12.500000,700,1,14.120000,100,1,12.460000,200,2,14.400000,100,1,12.430000,700,1,14.560000,900,3,12.420000,700,1,14.600000,700,1,12.370000,700,1,14.640000,100,1,ARL,300061581
2025-07-17T15:42:23.491451368Z,2025-07-17T15:42:23.491285065Z,10,2,1108,C,A,14,14.91,100,0,166303,251710647,13.260000,100,1,13.790000,15,1,13.040000,2,1,13.800000,100,1,13.030000,100,1,13.820000,100,1,12.730000,100,1,13.830000,15,1,12.710000,100,1,14.070000,2,1,12.500000,700,1,14.120000,100,1,12.460000,200,2,14.400000,100,1,12.430000,700,1,14.560000,900,3,12.420000,700,1,14.600000,700,1,12.370000,700,1,14.640000,100,1,ARL,299926801
2025-07-17T15:42:23.491451368Z,2025-07-17T15:42:23.491285065Z,10,2,1108,A,A,-1,14.87,100,128,166303,251710647,13.260000,100,1,13.790000,15,1,13.040000,2,1,13.800000,100,1,13.030000,100,1,13.820000,100,1,12.730000,100,1,13.830000,15,1,12.710000,100,1,14.070000,2,1,12.500000,700,1,14.120000,100,1,12.460000,200,2,14.400000,100,1,12.430000,700,1,14.560000,900,3,12.420000,700,1,14.600000,700,1,12.370000,700,1,14.640000,100,1,ARL,300061989
2025-07-17T15:42:23.589065154Z,2025-07-17T15:42:23.588899941Z,10,2,1108,C,A,0,13.79,15,130,165213,251718746,13.260000,100,1,13.800000,100,1,13.040000,2,1,13.820000,100,1,13.030000,100,1,13.830000,15,1,12.730000,100,1,14.070000,2,1,12.710000,100,1,14.120000,100,1,12.500000,700,1,14.400000,100,1,12.460000,200,2,14.560000,900,3,12.430000,700,1,14.600000,700,1,12.420000,700,1,14.640000,100,1,12.370000,700,1,14.680000,1400,2,ARL,300042293
2025-07-17T15:42:23.589220778Z,2025-07-17T15:42:23.589055082Z,10,2,1108,C,A,2,13.83,15,130,165696,251718767,13.260000,100,1,13.800000,100,1,13.040000,2,1,13.820000,100,1,13.030000,100,1,14.070000,2,1,12.730000,100,1,14.120000,100,1,12.710000,100,1,14.400000,100,1,12.500000,700,1,14.560000,900,3,12.460000,200,2,14.600000,700,1,12.430000,700,1,14.640000,100,1,12.420000,700,1,14.680000,1400,2,12.370000,700,1,14.730000,100,1,ARL,299923773
2025-07-17T15:42:34.003710081Z,2025-07-17T15:42:34.003544527Z,10,2,1108,C,A,0,13.80,100,130,165554,251901273,13.260000,100,1,13.820000,100,1,13.040000,2,1,14.070000,2,1,13.030000,100,1,14.120000,100,1,12.730000,100,1,14.400000,100,1,12.710000,100,1,14.560000,900,3,12.500000,700,1,14.600000,700,1,12.460000,200,2,14.640000,100,1,12.430000,700,1,14.680000,1400,2,12.420000,700,1,14.730000,100,1,12.370000,700,1,14.760000,100,1,ARL,300061581
2025-07-17T15:42:34.003949340Z,2025-07-17T15:42:34.003783950Z,10,2,1108,C,A,0,13.82,100,130,165390,251901275,13.260000,100,1,14.070000,2,1,13.040000,2,1,14.120000,100,1,13.030000,100,1,14.400000,100,1,12.730000,100,1,14.560000,900,3,12.710000,100,1,14.600000,700,1,12.500000,700,1,14.640000,100,1,12.460000,200,2,14.680000,1400,2,12.430000,700,1,14.730000,100,1,12.420000,700,1,14.760000,100,1,12.370000,700,1,14.810000,200,2,ARL,300042385
2025-07-17T15:42:34.004225180Z,2025-07-17T15:42:34.004059450Z,10,2,1108,C,A,7,14.73,100,0,165730,251901280,13.260000,100,1,14.070000,2,1,13.040000,2,1,14.120000,100,1,13.030000,100,1,14.400000,100,1,12.730000,100,1,14.560000,900,3,12.710000,100,1,14.600000,700,1,12.500000,700,1,14.640000,100,1,12.460000,200,2,14.680000,1400,2,12.430000,700,1,14.760000,100,1,12.420000,700,1,14.810000,200,2,12.370000,700,1,14.870000,100,1,ARL,299945073
2025-07-17T15:42:34.004225180Z,2025-07-17T15:42:34.004059450Z,10,2,1108,A,A,-1,14.88,100,130,165730,251901280,13.260000,100,1,14.070000,2,1,13.040000,2,1,14.120000,100,1,13.030000,100,1,14.400000,100,1,12.730000,100,1,14.560000,900,3,12.710000,100,1,14.600000,700,1,12.500000,700,1,14.640000,100,1,12.460000,200,2,14.680000,1400,2,12.430000,700,1,14.760000,100,1,12.420000,700,1,14.810000,200,2,12.370000,700,1,14.870000,100,1,ARL,300280745
2025-07-17T15:42:34.004671652Z,2025-07-17T15:42:34.004506043Z,10,2,1108,C,A,9,14.87,100,0,165609,251901285,13.260000,100,1,14.070000,2,1,13.040000,2,1,14.120000,100,1,13.030000,100,1,14.400000,100,1,12.730000,100,1,14.560000,900,3,12.710000,100,1,14.600000,700,1,12.500000,700,1,14.640000,100,1,12.460000,200,2,14.680000,1400,2,12.430000,700,1,14.760000,100,1,12.420000,700,1,14.810000,200,2,12.370000,700,1,14.880000,100,1,ARL,300061989
2025-07-17T15:42:34.004671652Z,2025-07-17T15:42:34.004506043Z,10,2,1108,A,A,-1,15.06,100,130,165609,251901285,13.260000,100,1,14.070000,2,1,13.040000,2,1,14.120000,100,1,13.030000,100,1,14.400000,100,1,12.730000,100,1,14.560000,900,3,12.710000,100,1,14.600000,700,1,12.500000,700,1,14.640000,100,1,12.460000,200,2,14.680000,1400,2,12.430000,700,1,14.760000,100,1,12.420000,700,1,14.810000,200,2,12.370000,700,1,14.880000,100,1,ARL,300280757
2025-07-17T15:42:34.004677786Z,2025-07-17T15:42:34.004512153Z,10,2,1108,C,A,7,14.76,100,0,165633,251901286,13.260000,100,1,14.070000,2,1,13.040000,2,1,14.120000,100,1,13.030000,100,1,14.400000,100,1,12.730000,100,1,14.560000,900,3,12.710000,100,1,14.600000,700,1,12.500000,700,1,14.640000,100,1,12.460000,200,2,14.680000,1400,2,12.430000,700,1,14.810000,200,2,12.420000,700,1,14.880000,100,1,12.370000,700,1,15.060000,100,1,ARL,299903169
2025-07-17T15:42:34.004677786Z,2025-07-17T15:42:34.004512153Z,10,2,1108,A,A,8,14.88,100,130,165633,251901286,13.260000,100,1,14.070000,2,1,13.040000,2,1,14.120000,100,1,13.030000,100,1,14.400000,100,1,12.730000,100,1,14.560000,900,3,12.710000,100,1,14.600000,700,1,12.500000,700,1,14.640000,100,1,12.460000,200,2,14.680000,1400,2,12.430000,700,1,14.810000,200,2,12.420000,700,1,14.880000,200,2,12.370000,700,1,15.060000,100,1,ARL,300280761
2025-07-17T15:42:34.005574760Z,2025-07-17T15:42:34.005409139Z,10,2,1108,C,A,14,15.92,100,0,165621,251901302,13.260000,100,1,14.070000,2,1,13.040000,2,1,14.120000,100,1,13.030000,100,1,14.400000,100,1,12.730000,100,1,14.560000,900,3,12.710000,100,1,14.600000,700,1,12.500000,700,1,14.640000,100,1,12.460000,200,2,14.680000,1400,2,12.430000,700,1,14.810000,200,2,12.420000,700,1,14.880000,200,2,12.370000,700,1,15.060000,100,1,ARL,299926853
2025-07-17T15:42:34.005574760Z,2025-07-17T15:42:34.005409139Z,10,2,1108,A,A,-1,16.08,100,130,165621,251901302,13.260000,100,1,14.070000,2,1,13.040000,2,1,14.120000,100,1,13.030000,100,1,14.400000,100,1,12.730000,100,1,14.560000,900,3,12.710000,100,1,14.600000,700,1,12.500000,700,1,14.640000,100,1,12.460000,200,2,14.680000,1400,2,12.430000,700,1,14.810000,200,2,12.420000,700,1,14.880000,200,2,12.370000,700,1,15.060000,100,1,ARL,300280773
2025-07-17T15:42:34.005832926Z,2025-07-17T15:42:34.005667449Z,10,2,1108,C,A,7,14.81,100,0,165477,251901305,13.260000,100,1,14.070000,2,1,13.040000,2,1,14.120000,100,1,13.030000,100,1,14.400000,100,1,12.730000,100,1,14.560000,900,3,12.710000,100,1,14.600000,700,1,12.500000,700,1,14.640000,100,1,12.460000,200,2,14.680000,1400,2,12.430000,700,1,14.810000,100,1,12.420000,700,1,14.880000,200,2,12.370000,700,1,15.060000,100,1,ARL,299926849
2025-07-17T15:42:34.005832926Z,2025-07-17T15:42:34.005667449Z,10,2,1108,A,A,9,14.96,100,130,165477,251901305,13.260000,100,1,14.070000,2,1,13.040000,2,1,14.120000,100,1,13.030000,100,1,14.400000,100,1,12.730000,100,1,14.560000,900,3,12.710000,100,1,14.600000,700,1,12.500000,700,1,14.640000,100,1,12.460000,200,2,14.680000,1400,2,12.430000,700,1,14.810000,100,1,12.420000,700,1,14.880000,200,2,12.370000,700,1,14.960000,100,1,ARL,300280777
2025-07-17T15:42:34.006831024Z,2025-07-17T15:42:34.006665512Z,10,2,1108,C,A,17,17.58,100,0,165512,251901319,13.260000,100,1,14.070000,2,1,13.040000,2,1,14.120000,100,1,13.030000,100,1,14.400000,100,1,12.730000,100,1,14.560000,900,3,12.710000,100,1,14.600000,700,1,12.500000,700,1,14.640000,100,1,12.460000,200,2,14.680000,1400,2,12.430000,700,1,14.810000,100,1,12.420000,700,1,14.880000,200,2,12.370000,700,1,14.960000,100,1,ARL,299926861
2025-07-17T15:42:34.006831024Z,2025-07-17T15:42:34.006665512Z,10,2,1108,A,A,-1,17.76,100,130,165512,251901319,13.260000,100,1,14.070000,2,1,13.040000,2,1,14.120000,100,1,13.030000,100,1,14.400000,100,1,12.730000,100,1,14.560000,900,3,12.710000,100,1,14.600000,700,1,12.500000,700,1,14.640000,100,1,12.460000,200,2,14.680000,1400,2,12.430000,700,1,14.810000,100,1,12.420000,700,1,14.880000,200,2,12.370000,700,1,14.960000,100,1,ARL,300280797
2025-07-17T15:42:34.007908678Z,2025-07-17T15:42:34.007743383Z,10,2,1108,C,A,5,14.64,100,130,165295,251901330,13.260000,100,1,14.070000,2,1,13.040000,2,1,14.120000,100,1,13.030000,100,1,14.400000,100,1,12.730000,100,1,14.560000,900,3,12.710000,100,1,14.600000,700,1,12.500000,700,1,14.680000,1400,2,12.460000,200,2,14.810000,100,1,12.430000,700,1,14.880000,200,2,12.420000,700,1,14.960000,100,1,12.370000,700,1,15.060000,100,1,ARL,299926813
2025-07-17T15:42:34.008072663Z,2025-07-17T15:42:34.007907269Z,10,2,1108,A,A,6,14.78,100,130,165394,251901331,13.260000,100,1,14.070000,2,1,13.040000,2,1,14.120000,100,1,13.030000,100,1,14.400000,100,1,12.730000,100,1,14.560000,900,3,12.710000,100,1,14.600000,700,1,12.500000,700,1,14.680000,1400,2,12.460000,200,2,14.780000,100,1,12.430000,700,1,14.810000,100,1,12.420000,700,1,14.880000,200,2,12.370000,700,1,14.960000,100,1,ARL,300280825
2025-07-17T15:42:34.010196831Z,2025-07-17T15:42:34.010031518Z,10,2,1108,C,A,1,14.12,100,130,165313,251901352,13.260000,100,1,14.070000,2,1,13.040000,2,1,14.400000,100,1,13.030000,100,1,14.560000,900,3,12.730000,100,1,14.600000,700,1,12.710000,100,1,14.680000,1400,2,12.500000,700,1,14.780000,100,1,12.460000,200,2,14.810000,100,1,12.430000,700,1,14.880000,200,2,12.420000,700,1,14.960000,100,1,12.370000,700,1,15.060000,100,1,ARL,299926965
2025-07-17T15:42:34.010248842Z,2025-07-17T15:42:34.010083409Z,10,2,1108,A,A,1,14.26,100,130,165433,251901353,13.260000,100,1,14.070000,2,1,13.040000,2,1,14.260000,100,1,13.030000,100,1,14.400000,100,1,12.730000,100,1,14.560000,900,3,12.710000,100,1,14.600000,700,1,12.500000,700,1,14.680000,1400,2,12.460000,200,2,14.780000,100,1,12.430000,700,1,14.810000,100,1,12.420000,700,1,14.880000,200,2,12.370000,700,1,14.960000,100,1,ARL,300280857
2025-07-17T15:42:34.010572370Z,2025-07-17T15:42:34.010406771Z,10,2,1108,C,A,7,14.81,100,0,165599,251901355,13.260000,100,1,14.070000,2,1,13.040000,2,1,14.260000,100,1,13.030000,100,1,14.400000,100,1,12.730000,100,1,14.560000,900,3,12.710000,100,1,14.600000,700,1,12.500000,700,1,14.680000,1400,2,12.460000,200,2,14.780000,100,1,12.430000,700,1,14.880000,200,2,12.420000,700,1,14.960000,100,1,12.370000,700,1,15.060000,100,1,ARL,299926857
2025-07-17T15:42:34.010572370Z,2025-07-17T15:42:34.010406771Z,10,2,1108,A,A,8,14.96,100,130,165599,251901355,13.260000,100,1,14.070000,2,1,13.040000,2,1,14.260000,100,1,13.030000,100,1,14.400000,100,1,12.730000,100,1,14.560000,900,3,12.710000,100,1,14.600000,700,1,12.500000,700,1,14.680000,1400,2,12.460000,200,2,14.780000,100,1,12.430000,700,1,14.880000,200,2,12.420000,700,1,14.960000,200,2,12.370000,700,1,15.060000,100,1,ARL,300280873
2025-07-17T15:42:34.952098027Z,2025-07-17T15:42:34.951932909Z,10,2,1108,A,A,1,14.08,100,130,165118,251912292,13.260000,100,1,14.070000,2,1,13.040000,2,1,14.080000,100,1,13.030000,100,1,14.260000,100,1,12.730000,100,1,14.400000,100,1,12.710000,100,1,14.560000,900,3,12.500000,700,1,14.600000,700,1,12.460000,200,2,14.680000,1400,2,12.430000,700,1,14.780000,100,1,12.420000,700,1,14.880000,200,2,12.370000,700,1,14.960000,200,2,ARL,300294885
2025-07-17T15:43:21.513838949Z,2025-07-17T15:43:21.513673603Z,10,2,1108,A,A,0,13.92,15,130,165346,252622568,13.260000,100,1,13.920000,15,1,13.040000,2,1,14.070000,2,1,13.030000,100,1,14.080000,100,1,12.730000,100,1,14.260000,100,1,12.710000,100,1,14.400000,100,1,12.500000,700,1,14.560000,900,3,12.460000,200,2,14.600000,700,1,12.430000,700,1,14.680000,1400,2,12.420000,700,1,14.780000,100,1,12.370000,700,1,14.880000,200,2,ARL,301218889
2025-07-17T15:43:24.878236760Z,2025-07-17T15:43:24.878071152Z,10,2,1108,C,A,2,14.08,100,0,165608,252681819,13.260000,100,1,13.920000,15,1,13.040000,2,1,14.070000,2,1,13.030000,100,1,14.260000,100,1,12.730000,100,1,14.400000,100,1,12.710000,100,1,14.560000,900,3,12.500000,700,1,14.600000,700,1,12.460000,200,2,14.680000,1400,2,12.430000,700,1,14.780000,100,1,12.420000,700,1,14.880000,200,2,12.370000,700,1,14.960000,200,2,ARL,300294885
2025-07-17T15:43:24.878236760Z,2025-07-17T15:43:24.878071152Z,10,2,1108,A,A,1,13.93,100,130,165608,252681819,13.260000,100,1,13.920000,15,1,13.040000,2,1,13.930000,100,1,13.030000,100,1,14.070000,2,1,12.730000,100,1,14.260000,100,1,12.710000,100,1,14.400000,100,1,12.500000,700,1,14.560000,900,3,12.460000,200,2,14.600000,700,1,12.430000,700,1,14.680000,1400,2,12.420000,700,1,14.780000,100,1,12.370000,700,1,14.880000,200,2,ARL,301295841
2025-07-17T15:43:24.879003443Z,2025-07-17T15:43:24.878837670Z,10,2,1108,C,A,11,15.06,100,0,165773,252681832,13.260000,100,1,13.920000,15,1,13.040000,2,1,13.930000,100,1,13.030000,100,1,14.070000,2,1,12.730000,100,1,14.260000,100,1,12.710000,100,1,14.400000,100,1,12.500000,700,1,14.560000,900,3,12.460000,200,2,14.600000,700,1,12.430000,700,1,14.680000,1400,2,12.420000,700,1,14.780000,100,1,12.370000,700,1,14.880000,200,2,ARL,300280757
2025-07-17T15:43:24.879003443Z,2025-07-17T15:43:24.878837670Z,10,2,1108,A,A,-1,15.01,100,130,165773,252681832,13.260000,100,1,13.920000,15,1,13.040000,2,1,13.930000,100,1,13.030000,100,1,14.070000,2,1,12.730000,100,1,14.260000,100,1,12.710000,100,1,14.400000,100,1,12.500000,700,1,14.560000,900,3,12.460000,200,2,14.600000,700,1,12.430000,700,1,14.680000,1400,2,12.420000,700,1,14.780000,100,1,12.370000,700,1,14.880000,200,2,ARL,301295873
2025-07-17T15:43:32.780372412Z,2025-07-17T15:43:32.780206927Z,10,2,1108,A,A,0,13.88,15,130,165485,252800884,13.260000,100,1,13.880000,15,1,13.040000,2,1,13.920000,15,1,13.030000,100,1,13.930000,100,1,12.730000,100,1,14.070000,2,1,12.710000,100,1,14.260000,100,1,12.500000,700,1,14.400000,100,1,12.460000,200,2,14.560000,900,3,12.430000,700,1,14.600000,700,1,12.420000,700,1,14.680000,1400,2,12.370000,700,1,14.780000,100,1,ARL,301451057
2025-07-17T15:43:32.780639619Z,2025-07-17T15:43:32.780474141Z,10,2,1108,C,A,2,13.93,100,0,165478,252800887,13.260000,100,1,13.880000,15,1,13.040000,2,1,13.920000,15,1,13.030000,100,1,14.070000,2,1,12.730000,100,1,14.260000,100,1,12.710000,100,1,14.400000,100,1,12.500000,700,1,14.560000,900,3,12.460000,200,2,14.600000,700,1,12.430000,700,1,14.680000,1400,2,12.420000,700,1,14.780000,100,1,12.370000,700,1,14.880000,200,2,ARL,301295841
2025-07-17T15:43:32.780639619Z,2025-07-17T15:43:32.780474141Z,10,2,1108,A,A,1,13.89,100,130,165478,252800887,13.260000,100,1,13.880000,15,1,13.040000,2,1,13.890000,100,1,13.030000,100,1,13.920000,15,1,12.730000,100,1,14.070000,2,1,12.710000,100,1,14.260000,100,1,12.500000,700,1,14.400000,100,1,12.460000,200,2,14.560000,900,3,12.430000,700,1,14.600000,700,1,12.420000,700,1,14.680000,1400,2,12.370000,700,1,14.780000,100,1,ARL,301451061
2025-07-17T15:43:32.781382162Z,2025-07-17T15:43:32.781216589Z,10,2,1108,C,A,12,15.01,100,0,165573,252800892,13.260000,100,1,13.880000,15,1,13.040000,2,1,13.890000,100,1,13.030000,100,1,13.920000,15,1,12.730000,100,1,14.070000,2,1,12.710000,100,1,14.260000,100,1,12.500000,700,1,14.400000,100,1,12.460000,200,2,14.560000,900,3,12.430000,700,1,14.600000,700,1,12.420000,700,1,14.680000,1400,2,12.370000,700,1,14.780000,100,1,ARL,301295873
2025-07-17T15:43:32.781382162Z,2025-07-17T15:43:32.781216589Z,10,2,1108,A,A,-1,14.97,100,130,165573,252800892,13.260000,100,1,13.880000,15,1,13.040000,2,1,13.890000,100,1,13.030000,100,1,13.920000,15,1,12.730000,100,1,14.070000,2,1,12.710000,100,1,14.260000,100,1,12.500000,700,1,14.400000,100,1,12.460000,200,2,14.560000,900,3,12.430000,700,1,14.600000,700,1,12.420000,700,1,14.680000,1400,2,12.370000,700,1,14.780000,100,1,ARL,301451077
2025-07-17T15:43:32.792119698Z,2025-07-17T15:43:32.791954053Z,10,2,1108,C,A,4,14.26,100,130,165645,252801681,13.260000,100,1,13.880000,15,1,13.040000,2,1,13.890000,100,1,13.030000,100,1,13.920000,15,1,12.730000,100,1,14.070000,2,1,12.710000,100,1,14.400000,100,1,12.500000,700,1,14.560000,900,3,12.460000,200,2,14.600000,700,1,12.430000,700,1,14.680000,1400,2,12.420000,700,1,14.780000,100,1,12.370000,700,1,14.880000,200,2,ARL,300280857
2025-07-17T15:43:32.792174617Z,2025-07-17T15:43:32.792008881Z,10,2,1108,A,A,4,14.17,100,130,165736,252801689,13.260000,100,1,13.880000,15,1,13.040000,2,1,13.890000,100,1,13.030000,100,1,13.920000,15,1,12.730000,100,1,14.070000,2,1,12.710000,100,1,14.170000,100,1,12.500000,700,1,14.400000,100,1,12.460000,200,2,14.560000,900,3,12.430000,700,1,14.600000,700,1,12.420000,700,1,14.680000,1400,2,12.370000,700,1,14.780000,100,1,ARL,301452785
2025-07-17T15:43:44.004832641Z,2025-07-17T15:43:44.004667259Z,10,2,1108,C,A,2,13.92,15,130,165382,252977583,13.260000,100,1,13.880000,15,1,13.040000,2,1,13.890000,100,1,13.030000,100,1,14.070000,2,1,12.730000,100,1,14.170000,100,1,12.710000,100,1,14.400000,100,1,12.500000,700,1,14.560000,900,3,12.460000,200,2,14.600000,700,1,12.430000,700,1,14.680000,1400,2,12.420000,700,1,14.780000,100,1,12.370000,700,1,14.880000,200,2,ARL,301218889
2025-07-17T15:43:44.005191111Z,2025-07-17T15:43:44.005025587Z,10,2,1108,C,A,9,14.88,100,0,165524,252977592,13.260000,100,1,13.880000,15,1,13.040000,2,1,13.890000,100,1,13.030000,100,1,14.070000,2,1,12.730000,100,1,14.170000,100,1,12.710000,100,1,14.400000,100,1,12.500000,700,1,14.560000,900,3,12.460000,200,2,14.600000,700,1,12.430000,700,1,14.680000,1400,2,12.420000,700,1,14.780000,100,1,12.370000,700,1,14.880000,100,1,ARL,300280761
2025-07-17T15:43:44.005191111Z,2025-07-17T15:43:44.005025587Z,10,2,1108,A,A,8,14.77,100,130,165524,252977592,13.260000,100,1,13.880000,15,1,13.040000,2,1,13.890000,100,1,13.030000,100,1,14.070000,2,1,12.730000,100,1,14.170000,100,1,12.710000,100,1,14.400000,100,1,12.500000,700,1,14.560000,900,3,12.460000,200,2,14.600000,700,1,12.430000,700,1,14.680000,1400,2,12.420000,700,1,14.770000,100,1,12.370000,700,1,14.780000,100,1,ARL,301671709
2025-07-17T15:43:44.005313071Z,2025-07-17T15:43:44.005147707Z,10,2,1108,C,A,10,14.88,100,0,165364,252977595,13.260000,100,1,13.880000,15,1,13.040000,2,1,13.890000,100,1,13.030000,100,1,14.070000,2,1,12.730000,100,1,14.170000,100,1,12.710000,100,1,14.400000,100,1,12.500000,700,1,14.560000,900,3,12.460000,200,2,14.600000,700,1,12.430000,700,1,14.680000,1400,2,12.420000,700,1,14.770000,100,1,12.370000,700,1,14.780000,100,1,ARL,300280745
2025-07-17T15:43:44.005313071Z,2025-07-17T15:43:44.005147707Z,10,2,1108,A,A,8,14.77,100,130,165364,252977595,13.260000,100,1,13.880000,15,1,13.040000,2,1,13.890000,100,1,13.030000,100,1,14.070000,2,1,12.730000,100,1,14.170000,100,1,12.710000,100,1,14.400000,100,1,12.500000,700,1,14.560000,900,3,12.460000,200,2,14.600000,700,1,12.430000,700,1,14.680000,1400,2,12.420000,700,1,14.770000,200,2,12.370000,700,1,14.780000,100,1,ARL,301671713
2025-07-17T15:43:48.787497664Z,2025-07-17T15:43:48.787332399Z,10,2,1108,A,A,0,13.83,15,130,165265,253027890,13.260000,100,1,13.830000,15,1,13.040000,2,1,13.880000,15,1,13.030000,100,1,13.890000,100,1,12.730000,100,1,14.070000,2,1,12.710000,100,1,14.170000,100,1,12.500000,700,1,14.400000,100,1,12.460000,200,2,14.560000,900,3,12.430000,700,1,14.600000,700,1,12.420000,700,1,14.680000,1400,2,12.370000,700,1,14.770000,200,2,ARL,301746941
2025-07-17T15:43:48.787766907Z,2025-07-17T15:43:48.787601640Z,10,2,1108,C,A,2,13.89,100,0,165267,253027924,13.260000,100,1,13.830000,15,1,13.040000,2,1,13.880000,15,1,13.030000,100,1,14.070000,2,1,12.730000,100,1,14.170000,100,1,12.710000,100,1,14.400000,100,1,12.500000,700,1,14.560000,900,3,12.460000,200,2,14.600000,700,1,12.430000,700,1,14.680000,1400,2,12.420000,700,1,14.770000,200,2,12.370000,700,1,14.780000,100,1,ARL,301451061
2025-07-17T15:43:48.787766907Z,2025-07-17T15:43:48.787601640Z,10,2,1108,A,A,1,13.84,100,130,165267,253027924,13.260000,100,1,13.830000,15,1,13.040000,2,1,13.840000,100,1,13.030000,100,1,13.880000,15,1,12.730000,100,1,14.070000,2,1,12.710000,100,1,14.170000,100,1,12.500000,700,1,14.400000,100,1,12.460000,200,2,14.560000,900,3,12.430000,700,1,14.600000,700,1,12.420000,700,1,14.680000,1400,2,12.370000,700,1,14.770000,200,2,ARL,301746949
2025-07-17T15:43:48.788512022Z,2025-07-17T15:43:48.788345787Z,10,2,1108,C,A,12,14.97,100,0,166235,253027959,13.260000,100,1,13.830000,15,1,13.040000,2,1,13.840000,100,1,13.030000,100,1,13.880000,15,1,12.730000,100,1,14.070000,2,1,12.710000,100,1,14.170000,100,1,12.500000,700,1,14.400000,100,1,12.460000,200,2,14.560000,900,3,12.430000,700,1,14.600000,700,1,12.420000,700,1,14.680000,1400,2,12.370000,700,1,14.770000,200,2,ARL,301451077
2025-07-17T15:43:48.788512022Z,2025-07-17T15:43:48.788345787Z,10,2,1108,A,A,-1,14.91,100,128,166235,253027959,13.260000,100,1,13.830000,15,1,13.040000,2,1,13.840000,100,1,13.030000,100,1,13.880000,15,1,12.730000,100,1,14.070000,2,1,12.710000,100,1,14.170000,100,1,12.500000,700,1,14.400000,100,1,12.460000,200,2,14.560000,900,3,12.430000,700,1,14.600000,700,1,12.420000,700,1,14.680000,1400,2,12.370000,700,1,14.770000,200,2,ARL,301746969
2025-07-17T15:43:48.790573820Z,2025-07-17T15:43:48.790408191Z,10,2,1108,C,A,12,14.96,100,0,165629,253028026,13.260000,100,1,13.830000,15,1,13.040000,2,1,13.840000,100,1,13.030000,100,1,13.880000,15,1,12.730000,100,1,14.070000,2,1,12.710000,100,1,14.170000,100,1,12.500000,700,1,14.400000,100,1,12.460000,200,2,14.560000,900,3,12.430000,700,1,14.600000,700,1,12.420000,700,1,14.680000,1400,2,12.370000,700,1,14.770000,200,2,ARL,300280777
2025-07-17T15:43:48.790573820Z,2025-07-17T15:43:48.790408191Z,10,2,1108,A,A,-1,14.81,100,130,165629,253028026,13.260000,100,1,13.830000,15,1,13.040000,2,1,13.840000,100,1,13.030000,100,1,13.880000,15,1,12.730000,100,1,14.070000,2,1,12.710000,100,1,14.170000,100,1,12.500000,700,1,14.400000,100,1,12.460000,200,2,14.560000,900,3,12.430000,700,1,14.600000,700,1,12.420000,700,1,14.680000,1400,2,12.370000,700,1,14.770000,200,2,ARL,301747001
2025-07-17T15:43:48.790600546Z,2025-07-17T15:43:48.790434947Z,10,2,1108,C,A,10,14.78,100,0,165599,253028027,13.260000,100,1,13.830000,15,1,13.040000,2,1,13.840000,100,1,13.030000,100,1,13.880000,15,1,12.730000,100,1,14.070000,2,1,12.710000,100,1,14.170000,100,1,12.500000,700,1,14.400000,100,1,12.460000,200,2,14.560000,900,3,12.430000,700,1,14.600000,700,1,12.420000,700,1,14.680000,1400,2,12.370000,700,1,14.770000,200,2,ARL,300280825
2025-07-17T15:43:48.790600546Z,2025-07-17T15:43:48.790434947Z,10,2,1108,A,A,8,14.64,100,130,165599,253028027,13.260000,100,1,13.830000,15,1,13.040000,2,1,13.840000,100,1,13.030000,100,1,13.880000,15,1,12.730000,100,1,14.070000,2,1,12.710000,100,1,14.170000,100,1,12.500000,700,1,14.400000,100,1,12.460000,200,2,14.560000,900,3,12.430000,700,1,14.600000,700,1,12.420000,700,1,14.640000,100,1,12.370000,700,1,14.680000,1400,2,ARL,301747005
2025-07-17T15:43:48.800959598Z,2025-07-17T15:43:48.800794196Z,10,2,1108,C,A,20,17.76,100,0,165402,253028707,13.260000,100,1,13.830000,15,1,13.040000,2,1,13.840000,100,1,13.030000,100,1,13.880000,15,1,12.730000,100,1,14.070000,2,1,12.710000,100,1,14.170000,100,1,12.500000,700,1,14.400000,100,1,12.460000,200,2,14.560000,900,3,12.430000,700,1,14.600000,700,1,12.420000,700,1,14.640000,100,1,12.370000,700,1,14.680000,1400,2,ARL,300280797
2025-07-17T15:43:48.800959598Z,2025-07-17T15:43:48.800794196Z,10,2,1108,A,A,-1,17.58,100,130,165402,253028707,13.260000,100,1,13.830000,15,1,13.040000,2,1,13.840000,100,1,13.030000,100,1,13.880000,15,1,12.730000,100,1,14.070000,2,1,12.710000,100,1,14.170000,100,1,12.500000,700,1,14.400000,100,1,12.460000,200,2,14.560000,900,3,12.430000,700,1,14.600000,700,1,12.420000,700,1,14.640000,100,1,12.370000,700,1,14.680000,1400,2,ARL,301747261
2025-07-17T15:43:48.806845249Z,2025-07-17T15:43:48.806679708Z,10,2,1108,C,A,18,16.08,100,0,165541,253028803,13.260000,100,1,13.830000,15,1,13.040000,2,1,13.840000,100,1,13.030000,100,1,13.880000,15,1,12.730000,100,1,14.070000,2,1,12.710000,100,1,14.170000,100,1,12.500000,700,1,14.400000,100,1,12.460000,200,2,14.560000,900,3,12.430000,700,1,14.600000,700,1,12.420000,700,1,14.640000,100,1,12.370000,700,1,14.680000,1400,2,ARL,300280773
2025-07-17T15:43:48.806845249Z,2025-07-17T15:43:48.806679708Z,10,2,1108,A,A,-1,15.92,100,130,165541,253028803,13.260000,100,1,13.830000,15,1,13.040000,2,1,13.840000,100,1,13.030000,100,1,13.880000,15,1,12.730000,100,1,14.070000,2,1,12.710000,100,1,14.170000,100,1,12.500000,700,1,14.400000,100,1,12.460000,200,2,14.560000,900,3,12.430000,700,1,14.600000,700,1,12.420000,700,1,14.640000,100,1,12.370000,700,1,14.680000,1400,2,ARL,301747301
2025-07-17T15:43:48.852570853Z,2025-07-17T15:43:48.852405047Z,10,2,1108,C,A,13,14.96,100,0,165806,253029437,13.260000,100,1,13.830000,15,1,13.040000,2,1,13.840000,100,1,13.030000,100,1,13.880000,15,1,12.730000,100,1,14.070000,2,1,12.710000,100,1,14.170000,100,1,12.500000,700,1,14.400000,100,1,12.460000,200,2,14.560000,900,3,12.430000,700,1,14.600000,700,1,12.420000,700,1,14.640000,100,1,12.370000,700,1,14.680000,1400,2,ARL,300280873
2025-07-17T15:43:48.852570853Z,2025-07-17T15:43:48.852405047Z,10,2,1108,A,A,-1,14.81,100,130,165806,253029437,13.260000,100,1,13.830000,15,1,13.040000,2,1,13.840000,100,1,13.030000,100,1,13.880000,15,1,12.730000,100,1,14.070000,2,1,12.710000,100,1,14.170000,100,1,12.500000,700,1,14.400000,100,1,12.460000,200,2,14.560000,900,3,12.430000,700,1,14.600000,700,1,12.420000,700,1,14.640000,100,1,12.370000,700,1,14.680000,1400,2,ARL,301747957
2025-07-17T15:43:53.123817759Z,2025-07-17T15:43:53.123652480Z,10,2,1108,C,A,2,13.88,15,130,165279,253100941,13.260000,100,1,13.830000,15,1,13.040000,2,1,13.840000,100,1,13.030000,100,1,14.070000,2,1,12.730000,100,1,14.170000,100,1,12.710000,100,1,14.400000,100,1,12.500000,700,1,14.560000,900,3,12.460000,200,2,14.600000,700,1,12.430000,700,1,14.640000,100,1,12.420000,700,1,14.680000,1400,2,12.370000,700,1,14.770000,200,2,ARL,301451057
2025-07-17T15:43:54.126276976Z,2025-07-17T15:43:54.126111293Z,10,2,1108,A,A,0,13.81,15,130,165683,253121467,13.260000,100,1,13.810000,15,1,13.040000,2,1,13.830000,15,1,13.030000,100,1,13.840000,100,1,12.730000,100,1,14.070000,2,1,12.710000,100,1,14.170000,100,1,12.500000,700,1,14.400000,100,1,12.460000,200,2,14.560000,900,3,12.430000,700,1,14.600000,700,1,12.420000,700,1,14.640000,100,1,12.370000,700,1,14.680000,1400,2,ARL,301867541
2025-07-17T15:43:54.998238933Z,2025-07-17T15:43:54.998073317Z,10,2,1108,C,A,2,13.84,100,0,165616,253137948,13.260000,100,1,13.810000,15,1,13.040000,2,1,13.830000,15,1,13.030000,100,1,14.070000,2,1,12.730000,100,1,14.170000,100,1,12.710000,100,1,14.400000,100,1,12.500000,700,1,14.560000,900,3,12.460000,200,2,14.600000,700,1,12.430000,700,1,14.640000,100,1,12.420000,700,1,14.680000,1400,2,12.370000,700,1,14.770000,200,2,ARL,301746949
2025-07-17T15:43:54.998238933Z,2025-07-17T15:43:54.998073317Z,10,2,1108,A,A,1,13.82,100,130,165616,253137948,13.260000,100,1,13.810000,15,1,13.040000,2,1,13.820000,100,1,13.030000,100,1,13.830000,15,1,12.730000,100,1,14.070000,2,1,12.710000,100,1,14.170000,100,1,12.500000,700,1,14.400000,100,1,12.460000,200,2,14.560000,900,3,12.430000,700,1,14.600000,700,1,12.420000,700,1,14.640000,100,1,12.370000,700,1,14.680000,1400,2,ARL,301885353
2025-07-17T15:43:55.019172741Z,2025-07-17T15:43:55.019007300Z,10,2,1108,C,A,4,14.17,100,130,165441,253138492,13.260000,100,1,13.810000,15,1,13.040000,2,1,13.820000,100,1,13.030000,100,1,13.830000,15,1,12.730000,100,1,14.070000,2,1,12.710000,100,1,14.400000,100,1,12.500000,700,1,14.560000,900,3,12.460000,200,2,14.600000,700,1,12.430000,700,1,14.640000,100,1,12.420000,700,1,14.680000,1400,2,12.370000,700,1,14.770000,200,2,ARL,301452785
2025-07-17T15:43:55.019225935Z,2025-07-17T15:43:55.019060515Z,10,2,1108,A,A,4,14.10,100,130,165420,253138493,13.260000,100,1,13.810000,15,1,13.040000,2,1,13.820000,100,1,13.030000,100,1,13.830000,15,1,12.730000,100,1,14.070000,2,1,12.710000,100,1,14.100000,100,1,12.500000,700,1,14.400000,100,1,12.460000,200,2,14.560000,900,3,12.430000,700,1,14.600000,700,1,12.420000,700,1,14.640000,100,1,12.370000,700,1,14.680000,1400,2,ARL,301886057
2025-07-17T15:44:01.698791467Z,2025-07-17T15:44:01.698626200Z,10,2,1108,C,A,2,13.83,15,130,165267,253246317,13.260000,100,1,13.810000,15,1,13.040000,2,1,13.820000,100,1,13.030000,100,1,14.070000,2,1,12.730000,100,1,14.100000,100,1,12.710000,100,1,14.400000,100,1,12.500000,700,1,14.560000,900,3,12.460000,200,2,14.600000,700,1,12.430000,700,1,14.640000,100,1,12.420000,700,1,14.680000,1400,2,12.370000,700,1,14.770000,200,2,ARL,301746941
2025-07-17T15:44:04.014878156Z,2025-07-17T15:44:04.014712730Z,10,2,1108,A,A,2,13.83,100,130,165426,253292355,13.260000,100,1,13.810000,15,1,13.040000,2,1,13.820000,100,1,13.030000,100,1,13.830000,100,1,12.730000,100,1,14.070000,2,1,12.710000,100,1,14.100000,100,1,12.500000,700,1,14.400000,100,1,12.460000,200,2,14.560000,900,3,12.430000,700,1,14.600000,700,1,12.420000,700,1,14.640000,100,1,12.370000,700,1,14.680000,1400,2,ARL,302078553
2025-07-17T15:44:05.055626948Z,2025-07-17T15:44:05.055461574Z,10,2,1108,A,A,0,13.81,100,130,165374,253307083,13.260000,100,1,13.810000,115,2,13.040000,2,1,13.820000,100,1,13.030000,100,1,13.830000,100,1,12.730000,100,1,14.070000,2,1,12.710000,100,1,14.100000,100,1,12.500000,700,1,14.400000,100,1,12.460000,200,2,14.560000,900,3,12.430000,700,1,14.600000,700,1,12.420000,700,1,14.640000,100,1,12.370000,700,1,14.680000,1400,2,ARL,302100649
2025-07-17T15:44:05.062431949Z,2025-07-17T15:44:05.062266845Z,10,2,1108,C,A,2,13.83,100,130,165104,253307147,13.260000,100,1,13.810000,115,2,13.040000,2,1,13.820000,100,1,13.030000,100,1,14.070000,2,1,12.730000,100,1,14.100000,100,1,12.710000,100,1,14.400000,100,1,12.500000,700,1,14.560000,900,3,12.460000,200,2,14.600000,700,1,12.430000,700,1,14.640000,100,1,12.420000,700,1,14.680000,1400,2,12.370000,700,1,14.770000,200,2,ARL,302078553
2025-07-17T15:44:09.389713730Z,2025-07-17T15:44:09.389548394Z,10,2,1108,A,A,0,13.76,15,130,165336,253384422,13.260000,100,1,13.760000,15,1,13.040000,2,1,13.810000,115,2,13.030000,100,1,13.820000,100,1,12.730000,100,1,14.070000,2,1,12.710000,100,1,14.100000,100,1,12.500000,700,1,14.400000,100,1,12.460000,200,2,14.560000,900,3,12.430000,700,1,14.600000,700,1,12.420000,700,1,14.640000,100,1,12.370000,700,1,14.680000,1400,2,ARL,302205249
2025-07-17T15:44:09.390496140Z,2025-07-17T15:44:09.390329935Z,10,2,1108,C,A,10,14.77,100,0,166205,253384438,13.260000,100,1,13.760000,15,1,13.040000,2,1,13.810000,115,2,13.030000,100,1,13.820000,100,1,12.730000,100,1,14.070000,2,1,12.710000,100,1,14.100000,100,1,12.500000,700,1,14.400000,100,1,12.460000,200,2,14.560000,900,3,12.430000,700,1,14.600000,700,1,12.420000,700,1,14.640000,100,1,12.370000,700,1,14.680000,1400,2,ARL,301671709
2025-07-17T15:44:09.390496140Z,2025-07-17T15:44:09.390329935Z,10,2,1108,A,A,9,14.66,100,128,166205,253384438,13.260000,100,1,13.760000,15,1,13.040000,2,1,13.810000,115,2,13.030000,100,1,13.820000,100,1,12.730000,100,1,14.070000,2,1,12.710000,100,1,14.100000,100,1,12.500000,700,1,14.400000,100,1,12.460000,200,2,14.560000,900,3,12.430000,700,1,14.600000,700,1,12.420000,700,1,14.640000,100,1,12.370000,700,1,14.660000,100,1,ARL,302205289
2025-07-17T15:44:09.391058486Z,2025-07-17T15:44:09.390893172Z,10,2,1108,C,A,11,14.77,100,0,165314,253384456,13.260000,100,1,13.760000,15,1,13.040000,2,1,13.810000,115,2,13.030000,100,1,13.820000,100,1,12.730000,100,1,14.070000,2,1,12.710000,100,1,14.100000,100,1,12.500000,700,1,14.400000,100,1,12.460000,200,2,14.560000,900,3,12.430000,700,1,14.600000,700,1,12.420000,700,1,14.640000,100,1,12.370000,700,1,14.660000,100,1,ARL,301671713
2025-07-17T15:44:09.391058486Z,2025-07-17T15:44:09.390893172Z,10,2,1108,A,A,9,14.66,100,130,165314,253384456,13.260000,100,1,13.760000,15,1,13.040000,2,1,13.810000,115,2,13.030000,100,1,13.820000,100,1,12.730000,100,1,14.070000,2,1,12.710000,100,1,14.100000,100,1,12.500000,700,1,14.400000,100,1,12.460000,200,2,14.560000,900,3,12.430000,700,1,14.600000,700,1,12.420000,700,1,14.640000,100,1,12.370000,700,1,14.660000,200,2,ARL,302205309
2025-07-17T15:44:09.395447612Z,2025-07-17T15:44:09.395281780Z,10,2,1108,C,A,2,13.82,100,0,165832,253384698,13.260000,100,1,13.760000,15,1,13.040000,2,1,13.810000,115,2,13.030000,100,1,14.070000,2,1,12.730000,100,1,14.100000,100,1,12.710000,100,1,14.400000,100,1,12.500000,700,1,14.560000,900,3,12.460000,200,2,14.600000,700,1,12.430000,700,1,14.640000,100,1,12.420000,700,1,14.660000,200,2,12.370000,700,1,14.680000,1400,2,ARL,301885353
2025-07-17T15:44:09.395447612Z,2025-07-17T15:44:09.395281780Z,10,2,1108,A,A,1,13.77,100,130,165832,253384698,13.260000,100,1,13.760000,15,1,13.040000,2,1,13.770000,100,1,13.030000,100,1,13.810000,115,2,12.730000,100,1,14.070000,2,1,12.710000,100,1,14.100000,100,1,12.500000,700,1,14.400000,100,1,12.460000,200,2,14.560000,900,3,12.430000,700,1,14.600000,700,1,12.420000,700,1,14.640000,100,1,12.370000,700,1,14.660000,200,2,ARL,302205493
2025-07-17T15:44:09.396195647Z,2025-07-17T15:44:09.396030225Z,10,2,1108,C,A,12,14.91,100,0,165422,253384731,13.260000,100,1,13.760000,15,1,13.040000,2,1,13.770000,100,1,13.030000,100,1,13.810000,115,2,12.730000,100,1,14.070000,2,1,12.710000,100,1,14.100000,100,1,12.500000,700,1,14.400000,100,1,12.460000,200,2,14.560000,900,3,12.430000,700,1,14.600000,700,1,12.420000,700,1,14.640000,100,1,12.370000,700,1,14.660000,200,2,ARL,301746969
2025-07-17T15:44:09.396195647Z,2025-07-17T15:44:09.396030225Z,10,2,1108,A,A,-1,14.84,100,130,165422,253384731,13.260000,100,1,13.760000,15,1,13.040000,2,1,13.770000,100,1,13.030000,100,1,13.810000,115,2,12.730000,100,1,14.070000,2,1,12.710000,100,1,14.100000,100,1,12.500000,700,1,14.400000,100,1,12.460000,200,2,14.560000,900,3,12.430000,700,1,14.600000,700,1,12.420000,700,1,14.640000,100,1,12.370000,700,1,14.660000,200,2,ARL,302205537
2025-07-17T15:44:09.398011186Z,2025-07-17T15:44:09.397845986Z,10,2,1108,A,A,2,13.79,100,130,165200,253384788,13.260000,100,1,13.760000,15,1,13.040000,2,1,13.770000,100,1,13.030000,100,1,13.790000,100,1,12.730000,100,1,13.810000,115,2,12.710000,100,1,14.070000,2,1,12.500000,700,1,14.100000,100,1,12.460000,200,2,14.400000,100,1,12.430000,700,1,14.560000,900,3,12.420000,700,1,14.600000,700,1,12.370000,700,1,14.640000,100,1,ARL,302205561
2025-07-17T15:44:09.404828956Z,2025-07-17T15:44:09.404663816Z,10,2,1108,C,A,3,13.81,100,130,165140,253385013,13.260000,100,1,13.760000,15,1,13.040000,2,1,13.770000,100,1,13.030000,100,1,13.790000,100,1,12.730000,100,1,13.810000,15,1,12.710000,100,1,14.070000,2,1,12.500000,700,1,14.100000,100,1,12.460000,200,2,14.400000,100,1,12.430000,700,1,14.560000,900,3,12.420000,700,1,14.600000,700,1,12.370000,700,1,14.640000,100,1,ARL,302100649
2025-07-17T15:44:20.402535831Z,2025-07-17T15:44:20.402370565Z,10,2,1108,C,A,3,13.81,15,130,165266,253562230,13.260000,100,1,13.760000,15,1,13.040000,2,1,13.770000,100,1,13.030000,100,1,13.790000,100,1,12.730000,100,1,14.070000,2,1,12.710000,100,1,14.100000,100,1,12.500000,700,1,14.400000,100,1,12.460000,200,2,14.560000,900,3,12.430000,700,1,14.600000,700,1,12.420000,700,1,14.640000,100,1,12.370000,700,1,14.660000,200,2,ARL,301867541
2025-07-17T15:44:21.405486122Z,2025-07-17T15:44:21.405320730Z,10,2,1108,A,A,0,13.74,15,130,165392,253582427,13.260000,100,1,13.740000,15,1,13.040000,2,1,13.760000,15,1,13.030000,100,1,13.770000,100,1,12.730000,100,1,13.790000,100,1,12.710000,100,1,14.070000,2,1,12.500000,700,1,14.100000,100,1,12.460000,200,2,14.400000,100,1,12.430000,700,1,14.560000,900,3,12.420000,700,1,14.600000,700,1,12.370000,700,1,14.640000,100,1,ARL,302458113
2025-07-17T15:44:21.843235911Z,2025-07-17T15:44:21.843070079Z,10,2,1108,C,A,2,13.77,100,0,165832,253590641,13.260000,100,1,13.740000,15,1,13.040000,2,1,13.760000,15,1,13.030000,100,1,13.790000,100,1,12.730000,100,1,14.070000,2,1,12.710000,100,1,14.100000,100,1,12.500000,700,1,14.400000,100,1,12.460000,200,2,14.560000,900,3,12.430000,700,1,14.600000,700,1,12.420000,700,1,14.640000,100,1,12.370000,700,1,14.660000,200,2,ARL,302205493
2025-07-17T15:44:21.843235911Z,2025-07-17T15:44:21.843070079Z,10,2,1108,A,A,1,13.75,100,130,165832,253590641,13.260000,100,1,13.740000,15,1,13.040000,2,1,13.750000,100,1,13.030000,100,1,13.760000,15,1,12.730000,100,1,13.790000,100,1,12.710000,100,1,14.070000,2,1,12.500000,700,1,14.100000,100,1,12.460000,200,2,14.400000,100,1,12.430000,700,1,14.560000,900,3,12.420000,700,1,14.600000,700,1,12.370000,700,1,14.640000,100,1,ARL,302466045
2025-07-17T15:44:21.855416093Z,2025-07-17T15:44:21.855250804Z,10,2,1108,C,A,5,14.10,100,130,165289,253590837,13.260000,100,1,13.740000,15,1,13.040000,2,1,13.750000,100,1,13.030000,100,1,13.760000,15,1,12.730000,100,1,13.790000,100,1,12.710000,100,1,14.070000,2,1,12.500000,700,1,14.400000,100,1,12.460000,200,2,14.560000,900,3,12.430000,700,1,14.600000,700,1,12.420000,700,1,14.640000,100,1,12.370000,700,1,14.660000,200,2,ARL,301886057
2025-07-17T15:44:21.855471158Z,2025-07-17T15:44:21.855305995Z,10,2,1108,A,A,4,14.03,100,130,165163,253590838,13.260000,100,1,13.740000,15,1,13.040000,2,1,13.750000,100,1,13.030000,100,1,13.760000,15,1,12.730000,100,1,13.790000,100,1,12.710000,100,1,14.030000,100,1,12.500000,700,1,14.070000,2,1,12.460000,200,2,14.400000,100,1,12.430000,700,1,14.560000,900,3,12.420000,700,1,14.600000,700,1,12.370000,700,1,14.640000,100,1,ARL,302466157
2025-07-17T15:44:24.447075532Z,2025-07-17T15:44:24.446910206Z,10,2,1108,A,A,3,13.77,100,130,165326,253614407,13.260000,100,1,13.740000,15,1,13.040000,2,1,13.750000,100,1,13.030000,100,1,13.760000,15,1,12.730000,100,1,13.770000,100,1,12.710000,100,1,13.790000,100,1,12.500000,700,1,14.030000,100,1,12.460000,200,2,14.070000,2,1,12.430000,700,1,14.400000,100,1,12.420000,700,1,14.560000,900,3,12.370000,700,1,14.600000,700,1,ARL,302500469
2025-07-17T15:44:24.465555818Z,2025-07-17T15:44:24.465390625Z,10,2,1108,C,A,4,13.79,100,130,165193,253614591,13.260000,100,1,13.740000,15,1,13.040000,2,1,13.750000,100,1,13.030000,100,1,13.760000,15,1,12.730000,100,1,13.770000,100,1,12.710000,100,1,14.030000,100,1,12.500000,700,1,14.070000,2,1,12.460000,200,2,14.400000,100,1,12.430000,700,1,14.560000,900,3,12.420000,700,1,14.600000,700,1,12.370000,700,1,14.640000,100,1,ARL,302205561
2025-07-17T15:44:30.846822983Z,2025-07-17T15:44:30.846657613Z,10,2,1108,C,A,2,13.76,15,130,165370,253704439,13.260000,100,1,13.740000,15,1,13.040000,2,1,13.750000,100,1,13.030000,100,1,13.770000,100,1,12.730000,100,1,14.030000,100,1,12.710000,100,1,14.070000,2,1,12.500000,700,1,14.400000,100,1,12.460000,200,2,14.560000,900,3,12.430000,700,1,14.600000,700,1,12.420000,700,1,14.640000,100,1,12.370000,700,1,14.660000,200,2,ARL,302205249
2025-07-17T15:44:31.849784693Z,2025-07-17T15:44:31.849618640Z,10,2,1108,A,A,0,13.72,15,130,166053,253721156,13.260000,100,1,13.720000,15,1,13.040000,2,1,13.740000,15,1,13.030000,100,1,13.750000,100,1,12.730000,100,1,13.770000,100,1,12.710000,100,1,14.030000,100,1,12.500000,700,1,14.070000,2,1,12.460000,200,2,14.400000,100,1,12.430000,700,1,14.560000,900,3,12.420000,700,1,14.600000,700,1,12.370000,700,1,14.640000,100,1,ARL,302649021
2025-07-17T15:44:31.849921857Z,2025-07-17T15:44:31.849756452Z,10,2,1108,A,A,2,13.75,100,130,165405,253721157,13.260000,100,1,13.720000,15,1,13.040000,2,1,13.740000,15,1,13.030000,100,1,13.750000,200,2,12.730000,100,1,13.770000,100,1,12.710000,100,1,14.030000,100,1,12.500000,700,1,14.070000,2,1,12.460000,200,2,14.400000,100,1,12.430000,700,1,14.560000,900,3,12.420000,700,1,14.600000,700,1,12.370000,700,1,14.640000,100,1,ARL,302649029
2025-07-17T15:44:31.910124978Z,2025-07-17T15:44:31.909959614Z,10,2,1108,C,A,3,13.77,100,130,165364,253722140,13.260000,100,1,13.720000,15,1,13.040000,2,1,13.740000,15,1,13.030000,100,1,13.750000,200,2,12.730000,100,1,14.030000,100,1,12.710000,100,1,14.070000,2,1,12.500000,700,1,14.400000,100,1,12.460000,200,2,14.560000,900,3,12.430000,700,1,14.600000,700,1,12.420000,700,1,14.640000,100,1,12.370000,700,1,14.660000,200,2,ARL,302500469
2025-07-17T15:44:32.484497230Z,2025-07-17T15:44:32.484331764Z,10,2,1108,C,A,2,13.75,100,0,165466,253730877,13.260000,100,1,13.720000,15,1,13.040000,2,1,13.740000,15,1,13.030000,100,1,13.750000,100,1,12.730000,100,1,14.030000,100,1,12.710000,100,1,14.070000,2,1,12.500000,700,1,14.400000,100,1,12.460000,200,2,14.560000,900,3,12.430000,700,1,14.600000,700,1,12.420000,700,1,14.640000,100,1,12.370000,700,1,14.660000,200,2,ARL,302466045
2025-07-17T15:44:32.484497230Z,2025-07-17T15:44:32.484331764Z,10,2,1108,A,A,1,13.73,100,130,165466,253730877,13.260000,100,1,13.720000,15,1,13.040000,2,1,13.730000,100,1,13.030000,100,1,13.740000,15,1,12.730000,100,1,13.750000,100,1,12.710000,100,1,14.030000,100,1,12.500000,700,1,14.070000,2,1,12.460000,200,2,14.400000,100,1,12.430000,700,1,14.560000,900,3,12.420000,700,1,14.600000,700,1,12.370000,700,1,14.640000,100,1,ARL,302662769
2025-07-17T15:44:32.485238209Z,2025-07-17T15:44:32.485072552Z,10,2,1108,C,A,13,14.84,100,0,165657,253730907,13.260000,100,1,13.720000,15,1,13.040000,2,1,13.730000,100,1,13.030000,100,1,13.740000,15,1,12.730000,100,1,13.750000,100,1,12.710000,100,1,14.030000,100,1,12.500000,700,1,14.070000,2,1,12.460000,200,2,14.400000,100,1,12.430000,700,1,14.560000,900,3,12.420000,700,1,14.600000,700,1,12.370000,700,1,14.640000,100,1,ARL,302205537
2025-07-17T15:44:32.485238209Z,2025-07-17T15:44:32.485072552Z,10,2,1108,A,A,-1,14.79,100,130,165657,253730907,13.260000,100,1,13.720000,15,1,13.040000,2,1,13.730000,100,1,13.030000,100,1,13.740000,15,1,12.730000,100,1,13.750000,100,1,12.710000,100,1,14.030000,100,1,12.500000,700,1,14.070000,2,1,12.460000,200,2,14.400000,100,1,12.430000,700,1,14.560000,900,3,12.420000,700,1,14.600000,700,1,12.370000,700,1,14.640000,100,1,ARL,302662821
2025-07-17T15:44:33.389387814Z,2025-07-17T15:44:33.389222513Z,10,2,1108,A,A,6,14.28,100,130,165301,253745665,13.260000,100,1,13.720000,15,1,13.040000,2,1,13.730000,100,1,13.030000,100,1,13.740000,15,1,12.730000,100,1,13.750000,100,1,12.710000,100,1,14.030000,100,1,12.500000,700,1,14.070000,2,1,12.460000,200,2,14.280000,100,1,12.430000,700,1,14.400000,100,1,12.420000,700,1,14.560000,900,3,12.370000,700,1,14.600000,700,1,ARL,302681357
2025-07-17T15:44:33.389389030Z,2025-07-17T15:44:33.389223581Z,10,2,1108,C,A,8,14.56,100,130,165449,253745666,13.260000,100,1,13.720000,15,1,13.040000,2,1,13.730000,100,1,13.030000,100,1,13.740000,15,1,12.730000,100,1,13.750000,100,1,12.710000,100,1,14.030000,100,1,12.500000,700,1,14.070000,2,1,12.460000,200,2,14.280000,100,1,12.430000,700,1,14.400000,100,1,12.420000,700,1,14.560000,800,2,12.370000,700,1,14.600000,700,1,ARL,146960005
2025-07-17T15:44:36.362187673Z,2025-07-17T15:44:36.362022168Z,10,2,1108,C,A,2,13.74,15,130,165505,253783635,13.260000,100,1,13.720000,15,1,13.040000,2,1,13.730000,100,1,13.030000,100,1,13.750000,100,1,12.730000,100,1,14.030000,100,1,12.710000,100,1,14.070000,2,1,12.500000,700,1,14.280000,100,1,12.460000,200,2,14.400000,100,1,12.430000,700,1,14.560000,800,2,12.420000,700,1,14.600000,700,1,12.370000,700,1,14.640000,100,1,ARL,302458113
2025-07-17T15:44:37.364377419Z,2025-07-17T15:44:37.364212109Z,10,2,1108,A,A,0,13.70,15,130,165310,253797506,13.260000,100,1,13.700000,15,1,13.040000,2,1,13.720000,15,1,13.030000,100,1,13.730000,100,1,12.730000,100,1,13.750000,100,1,12.710000,100,1,14.030000,100,1,12.500000,700,1,14.070000,2,1,12.460000,200,2,14.280000,100,1,12.430000,700,1,14.400000,100,1,12.420000,700,1,14.560000,800,2,12.370000,700,1,14.600000,700,1,ARL,302750929
2025-07-17T15:44:37.364519067Z,2025-07-17T15:44:37.364353897Z,10,2,1108,A,A,2,13.73,100,130,165170,253797510,13.260000,100,1,13.700000,15,1,13.040000,2,1,13.720000,15,1,13.030000,100,1,13.730000,200,2,12.730000,100,1,13.750000,100,1,12.710000,100,1,14.030000,100,1,12.500000,700,1,14.070000,2,1,12.460000,200,2,14.280000,100,1,12.430000,700,1,14.400000,100,1,12.420000,700,1,14.560000,800,2,12.370000,700,1,14.600000,700,1,ARL,302750937
2025-07-17T15:44:37.458119494Z,2025-07-17T15:44:37.457954350Z,10,2,1108,C,A,3,13.75,100,130,165144,253798432,13.260000,100,1,13.700000,15,1,13.040000,2,1,13.720000,15,1,13.030000,100,1,13.730000,200,2,12.730000,100,1,14.030000,100,1,12.710000,100,1,14.070000,2,1,12.500000,700,1,14.280000,100,1,12.460000,200,2,14.400000,100,1,12.430000,700,1,14.560000,800,2,12.420000,700,1,14.600000,700,1,12.370000,700,1,14.640000,100,1,ARL,302649029
2025-07-17T15:44:38.432460509Z,2025-07-17T15:44:38.432294362Z,10,2,1108,C,A,2,13.73,100,0,166147,253807786,13.260000,100,1,13.700000,15,1,13.040000,2,1,13.720000,15,1,13.030000,100,1,13.730000,100,1,12.730000,100,1,14.030000,100,1,12.710000,100,1,14.070000,2,1,12.500000,700,1,14.280000,100,1,12.460000,200,2,14.400000,100,1,12.430000,700,1,14.560000,800,2,12.420000,700,1,14.600000,700,1,12.370000,700,1,14.640000,100,1,ARL,302662769
2025-07-17T15:44:38.432460509Z,2025-07-17T15:44:38.432294362Z,10,2,1108,A,A,1,13.71,100,130,166147,253807786,13.260000,100,1,13.700000,15,1,13.040000,2,1,13.710000,100,1,13.030000,100,1,13.720000,15,1,12.730000,100,1,13.730000,100,1,12.710000,100,1,14.030000,100,1,12.500000,700,1,14.070000,2,1,12.460000,200,2,14.280000,100,1,12.430000,700,1,14.400000,100,1,12.420000,700,1,14.560000,800,2,12.370000,700,1,14.600000,700,1,ARL,302763889
2025-07-17T15:44:38.439253975Z,2025-07-17T15:44:38.439088042Z,10,2,1108,C,A,19,15.92,100,0,165933,253808105,13.260000,100,1,13.700000,15,1,13.040000,2,1,13.710000,100,1,13.030000,100,1,13.720000,15,1,12.730000,100,1,13.730000,100,1,12.710000,100,1,14.030000,100,1,12.500000,700,1,14.070000,2,1,12.460000,200,2,14.280000,100,1,12.430000,700,1,14.400000,100,1,12.420000,700,1,14.560000,800,2,12.370000,700,1,14.600000,700,1,ARL,301747301
2025-07-17T15:44:38.439253975Z,2025-07-17T15:44:38.439088042Z,10,2,1108,A,A,-1,15.77,100,130,165933,253808105,13.260000,100,1,13.700000,15,1,13.040000,2,1,13.710000,100,1,13.030000,100,1,13.720000,15,1,12.730000,100,1,13.730000,100,1,12.710000,100,1,14.030000,100,1,12.500000,700,1,14.070000,2,1,12.460000,200,2,14.280000,100,1,12.430000,700,1,14.400000,100,1,12.420000,700,1,14.560000,800,2,12.370000,700,1,14.600000,700,1,ARL,302764121
2025-07-17T15:44:38.440321697Z,2025-07-17T15:44:38.440156077Z,10,2,1108,C,A,22,17.58,100,0,165620,253808122,13.260000,100,1,13.700000,15,1,13.040000,2,1,13.710000,100,1,13.030000,100,1,13.720000,15,1,12.730000,100,1,13.730000,100,1,12.710000,100,1,14.030000,100,1,12.500000,700,1,14.070000,2,1,12.460000,200,2,14.280000,100,1,12.430000,700,1,14.400000,100,1,12.420000,700,1,14.560000,800,2,12.370000,700,1,14.600000,700,1,ARL,301747261
2025-07-17T15:44:38.440321697Z,2025-07-17T15:44:38.440156077Z,10,2,1108,A,A,-1,17.42,100,130,165620,253808122,13.260000,100,1,13.700000,15,1,13.040000,2,1,13.710000,100,1,13.030000,100,1,13.720000,15,1,12.730000,100,1,13.730000,100,1,12.710000,100,1,14.030000,100,1,12.500000,700,1,14.070000,2,1,12.460000,200,2,14.280000,100,1,12.430000,700,1,14.400000,100,1,12.420000,700,1,14.560000,800,2,12.370000,700,1,14.600000,700,1,ARL,302764137
2025-07-17T15:44:43.019262217Z,2025-07-17T15:44:43.019083502Z,10,2,1108,C,A,0,13.70,15,128,178715,253875920,13.260000,100,1,13.710000,100,1,13.040000,2,1,13.720000,15,1,13.030000,100,1,13.730000,100,1,12.730000,100,1,14.030000,100,1,12.710000,100,1,14.070000,2,1,12.500000,700,1,14.280000,100,1,12.460000,200,2,14.400000,100,1,12.430000,700,1,14.560000,800,2,12.420000,700,1,14.600000,700,1,12.370000,700,1,14.640000,100,1,ARL,302750929
2025-07-17T15:44:43.019352658Z,2025-07-17T15:44:43.019184132Z,10,2,1108,C,A,1,13.72,15,128,168526,253876010,13.260000,100,1,13.710000,100,1,13.040000,2,1,13.730000,100,1,13.030000,100,1,14.030000,100,1,12.730000,100,1,14.070000,2,1,12.710000,100,1,14.280000,100,1,12.500000,700,1,14.400000,100,1,12.460000,200,2,14.560000,800,2,12.430000,700,1,14.600000,700,1,12.420000,700,1,14.640000,100,1,12.370000,700,1,14.660000,200,2,ARL,302649021
2025-07-17T15:44:44.076009999Z,2025-07-17T15:44:44.075843113Z,10,2,1108,A,A,0,13.70,15,128,166886,253892869,13.260000,100,1,13.700000,15,1,13.040000,2,1,13.710000,100,1,13.030000,100,1,13.730000,100,1,12.730000,100,1,14.030000,100,1,12.710000,100,1,14.070000,2,1,12.500000,700,1,14.280000,100,1,12.460000,200,2,14.400000,100,1,12.430000,700,1,14.560000,800,2,12.420000,700,1,14.600000,700,1,12.370000,700,1,14.640000,100,1,ARL,302867209
2025-07-17T15:44:44.781630732Z,2025-07-17T15:44:44.781464821Z,10,2,1108,C,A,0,13.70,15,130,165911,253901222,13.260000,100,1,13.710000,100,1,13.040000,2,1,13.730000,100,1,13.030000,100,1,14.030000,100,1,12.730000,100,1,14.070000,2,1,12.710000,100,1,14.280000,100,1,12.500000,700,1,14.400000,100,1,12.460000,200,2,14.560000,800,2,12.430000,700,1,14.600000,700,1,12.420000,700,1,14.640000,100,1,12.370000,700,1,14.660000,200,2,ARL,302867209
2025-07-17T15:44:53.143249270Z,2025-07-17T15:44:53.143083969Z,10,2,1108,C,A,1,13.73,100,130,165301,254011871,13.260000,100,1,13.710000,100,1,13.040000,2,1,14.030000,100,1,13.030000,100,1,14.070000,2,1,12.730000,100,1,14.280000,100,1,12.710000,100,1,14.400000,100,1,12.500000,700,1,14.560000,800,2,12.460000,200,2,14.600000,700,1,12.430000,700,1,14.640000,100,1,12.420000,700,1,14.660000,200,2,12.370000,700,1,14.680000,1400,2,ARL,302750937
2025-07-17T15:44:57.191188470Z,2025-07-17T15:44:57.191023026Z,10,2,1108,A,A,1,13.75,100,130,165444,254079162,13.260000,100,1,13.710000,100,1,13.040000,2,1,13.750000,100,1,13.030000,100,1,14.030000,100,1,12.730000,100,1,14.070000,2,1,12.710000,100,1,14.280000,100,1,12.500000,700,1,14.400000,100,1,12.460000,200,2,14.560000,800,2,12.430000,700,1,14.600000,700,1,12.420000,700,1,14.640000,100,1,12.370000,700,1,14.660000,200,2,ARL,303118785
2025-07-17T15:45:07.065756574Z,2025-07-17T15:45:07.065587919Z,10,2,1108,C,A,0,13.71,100,128,168655,254244597,13.260000,100,1,13.750000,100,1,13.040000,2,1,14.030000,100,1,13.030000,100,1,14.070000,2,1,12.730000,100,1,14.280000,100,1,12.710000,100,1,14.400000,100,1,12.500000,700,1,14.560000,800,2,12.460000,200,2,14.600000,700,1,12.430000,700,1,14.640000,100,1,12.420000,700,1,14.660000,200,2,12.370000,700,1,14.680000,1400,2,ARL,302763889
2025-07-17T15:45:07.080131505Z,2025-07-17T15:45:07.079966224Z,10,2,1108,C,A,0,13.75,100,130,165281,254245492,13.260000,100,1,14.030000,100,1,13.040000,2,1,14.070000,2,1,13.030000,100,1,14.280000,100,1,12.730000,100,1,14.400000,100,1,12.710000,100,1,14.560000,800,2,12.500000,700,1,14.600000,700,1,12.460000,200,2,14.640000,100,1,12.430000,700,1,14.660000,200,2,12.420000,700,1,14.680000,1400,2,12.370000,700,1,14.790000,100,1,ARL,303118785
2025-07-17T15:45:07.080687215Z,2025-07-17T15:45:07.080521807Z,10,2,1108,C,A,7,14.66,100,0,165408,254245505,13.260000,100,1,14.030000,100,1,13.040000,2,1,14.070000,2,1,13.030000,100,1,14.280000,100,1,12.730000,100,1,14.400000,100,1,12.710000,100,1,14.560000,800,2,12.500000,700,1,14.600000,700,1,12.460000,200,2,14.640000,100,1,12.430000,700,1,14.660000,100,1,12.420000,700,1,14.680000,1400,2,12.370000,700,1,14.790000,100,1,ARL,302205289
2025-07-17T15:45:07.080687215Z,2025-07-17T15:45:07.080521807Z,10,2,1108,A,A,-1,14.89,100,130,165408,254245505,13.260000,100,1,14.030000,100,1,13.040000,2,1,14.070000,2,1,13.030000,100,1,14.280000,100,1,12.730000,100,1,14.400000,100,1,12.710000,100,1,14.560000,800,2,12.500000,700,1,14.600000,700,1,12.460000,200,2,14.640000,100,1,12.430000,700,1,14.660000,100,1,12.420000,700,1,14.680000,1400,2,12.370000,700,1,14.790000,100,1,ARL,303330477
2025-07-17T15:45:07.080872245Z,2025-07-17T15:45:07.080706110Z,10,2,1108,C,A,9,14.79,100,0,166135,254245511,13.260000,100,1,14.030000,100,1,13.040000,2,1,14.070000,2,1,13.030000,100,1,14.280000,100,1,12.730000,100,1,14.400000,100,1,12.710000,100,1,14.560000,800,2,12.500000,700,1,14.600000,700,1,12.460000,200,2,14.640000,100,1,12.430000,700,1,14.660000,100,1,12.420000,700,1,14.680000,1400,2,12.370000,700,1,14.810000,200,2,ARL,302662821
2025-07-17T15:45:07.080872245Z,2025-07-17T15:45:07.080706110Z,10,2,1108,A,A,-1,15.06,100,130,166135,254245511,13.260000,100,1,14.030000,100,1,13.040000,2,1,14.070000,2,1,13.030000,100,1,14.280000,100,1,12.730000,100,1,14.400000,100,1,12.710000,100,1,14.560000,800,2,12.500000,700,1,14.600000,700,1,12.460000,200,2,14.640000,100,1,12.430000,700,1,14.660000,100,1,12.420000,700,1,14.680000,1400,2,12.370000,700,1,14.810000,200,2,ARL,303330485
2025-07-17T15:45:07.081578064Z,2025-07-17T15:45:07.081407507Z,10,2,1108,C,A,9,14.81,100,0,170557,254245568,13.260000,100,1,14.030000,100,1,13.040000,2,1,14.070000,2,1,13.030000,100,1,14.280000,100,1,12.730000,100,1,14.400000,100,1,12.710000,100,1,14.560000,800,2,12.500000,700,1,14.600000,700,1,12.460000,200,2,14.640000,100,1,12.430000,700,1,14.660000,100,1,12.420000,700,1,14.680000,1400,2,12.370000,700,1,14.810000,100,1,ARL,301747001
2025-07-17T15:45:07.081578064Z,2025-07-17T15:45:07.081407507Z,10,2,1108,A,A,-1,14.96,100,128,170557,254245568,13.260000,100,1,14.030000,100,1,13.040000,2,1,14.070000,2,1,13.030000,100,1,14.280000,100,1,12.730000,100,1,14.400000,100,1,12.710000,100,1,14.560000,800,2,12.500000,700,1,14.600000,700,1,12.460000,200,2,14.640000,100,1,12.430000,700,1,14.660000,100,1,12.420000,700,1,14.680000,1400,2,12.370000,700,1,14.810000,100,1,ARL,303330509
2025-07-17T15:45:07.081607970Z,2025-07-17T15:45:07.081441134Z,10,2,1108,C,A,7,14.66,100,0,166836,254245576,13.260000,100,1,14.030000,100,1,13.040000,2,1,14.070000,2,1,13.030000,100,1,14.280000,100,1,12.730000,100,1,14.400000,100,1,12.710000,100,1,14.560000,800,2,12.500000,700,1,14.600000,700,1,12.460000,200,2,14.640000,100,1,12.430000,700,1,14.680000,1400,2,12.420000,700,1,14.810000,100,1,12.370000,700,1,14.890000,100,1,ARL,302205309
2025-07-17T15:45:07.081607970Z,2025-07-17T15:45:07.081441134Z,10,2,1108,A,A,9,14.89,100,130,166836,254245576,13.260000,100,1,14.030000,100,1,13.040000,2,1,14.070000,2,1,13.030000,100,1,14.280000,100,1,12.730000,100,1,14.400000,100,1,12.710000,100,1,14.560000,800,2,12.500000,700,1,14.600000,700,1,12.460000,200,2,14.640000,100,1,12.430000,700,1,14.680000,1400,2,12.420000,700,1,14.810000,100,1,12.370000,700,1,14.890000,200,2,ARL,303330521
2025-07-17T15:45:07.083898999Z,2025-07-17T15:45:07.083732443Z,10,2,1108,C,A,19,17.42,100,0,166556,254246327,13.260000,100,1,14.030000,100,1,13.040000,2,1,14.070000,2,1,13.030000,100,1,14.280000,100,1,12.730000,100,1,14.400000,100,1,12.710000,100,1,14.560000,800,2,12.500000,700,1,14.600000,700,1,12.460000,200,2,14.640000,100,1,12.430000,700,1,14.680000,1400,2,12.420000,700,1,14.810000,100,1,12.370000,700,1,14.890000,200,2,ARL,302764137
2025-07-17T15:45:07.083898999Z,2025-07-17T15:45:07.083732443Z,10,2,1108,A,A,-1,17.76,100,130,166556,254246327,13.260000,100,1,14.030000,100,1,13.040000,2,1,14.070000,2,1,13.030000,100,1,14.280000,100,1,12.730000,100,1,14.400000,100,1,12.710000,100,1,14.560000,800,2,12.500000,700,1,14.600000,700,1,12.460000,200,2,14.640000,100,1,12.430000,700,1,14.680000,1400,2,12.420000,700,1,14.810000,100,1,12.370000,700,1,14.890000,200,2,ARL,303331309
2025-07-17T15:45:07.085222525Z,2025-07-17T15:45:07.085057258Z,10,2,1108,C,A,0,14.03,100,130,165267,254246434,13.260000,100,1,14.070000,2,1,13.040000,2,1,14.280000,100,1,13.030000,100,1,14.400000,100,1,12.730000,100,1,14.560000,800,2,12.710000,100,1,14.600000,700,1,12.500000,700,1,14.640000,100,1,12.460000,200,2,14.680000,1400,2,12.430000,700,1,14.810000,100,1,12.420000,700,1,14.890000,200,2,12.370000,700,1,14.960000,100,1,ARL,302466157
2025-07-17T15:45:07.085274852Z,2025-07-17T15:45:07.085109545Z,10,2,1108,A,A,1,14.26,100,130,165307,254246437,13.260000,100,1,14.070000,2,1,13.040000,2,1,14.260000,100,1,13.030000,100,1,14.280000,100,1,12.730000,100,1,14.400000,100,1,12.710000,100,1,14.560000,800,2,12.500000,700,1,14.600000,700,1,12.460000,200,2,14.640000,100,1,12.430000,700,1,14.680000,1400,2,12.420000,700,1,14.810000,100,1,12.370000,700,1,14.890000,200,2,ARL,303331401
2025-07-17T15:45:07.086534700Z,2025-07-17T15:45:07.086368957Z,10,2,1108,C,A,6,14.64,100,130,165743,254246501,13.260000,100,1,14.070000,2,1,13.040000,2,1,14.260000,100,1,13.030000,100,1,14.280000,100,1,12.730000,100,1,14.400000,100,1,12.710000,100,1,14.560000,800,2,12.500000,700,1,14.600000,700,1,12.460000,200,2,14.680000,1400,2,12.430000,700,1,14.810000,100,1,12.420000,700,1,14.890000,200,2,12.370000,700,1,14.960000,100,1,ARL,301747005
2025-07-17T15:45:07.086660325Z,2025-07-17T15:45:07.086494745Z,10,2,1108,A,A,7,14.78,100,130,165580,254246502,13.260000,100,1,14.070000,2,1,13.040000,2,1,14.260000,100,1,13.030000,100,1,14.280000,100,1,12.730000,100,1,14.400000,100,1,12.710000,100,1,14.560000,800,2,12.500000,700,1,14.600000,700,1,12.460000,200,2,14.680000,1400,2,12.430000,700,1,14.780000,100,1,12.420000,700,1,14.810000,100,1,12.370000,700,1,14.890000,200,2,ARL,303331425
2025-07-17T15:45:07.087389466Z,2025-07-17T15:45:07.087223859Z,10,2,1108,C,A,15,15.77,100,0,165607,254246529,13.260000,100,1,14.070000,2,1,13.040000,2,1,14.260000,100,1,13.030000,100,1,14.280000,100,1,12.730000,100,1,14.400000,100,1,12.710000,100,1,14.560000,800,2,12.500000,700,1,14.600000,700,1,12.460000,200,2,14.680000,1400,2,12.430000,700,1,14.780000,100,1,12.420000,700,1,14.810000,100,1,12.370000,700,1,14.890000,200,2,ARL,302764121
2025-07-17T15:45:07.087389466Z,2025-07-17T15:45:07.087223859Z,10,2,1108,A,A,-1,16.08,100,130,165607,254246529,13.260000,100,1,14.070000,2,1,13.040000,2,1,14.260000,100,1,13.030000,100,1,14.280000,100,1,12.730000,100,1,14.400000,100,1,12.710000,100,1,14.560000,800,2,12.500000,700,1,14.600000,700,1,12.460000,200,2,14.680000,1400,2,12.430000,700,1,14.780000,100,1,12.420000,700,1,14.810000,100,1,12.370000,700,1,14.890000,200,2,ARL,303331429
2025-07-17T15:45:07.133978488Z,2025-07-17T15:45:07.133812895Z,10,2,1108,C,A,8,14.81,100,0,165593,254250625,13.260000,100,1,14.070000,2,1,13.040000,2,1,14.260000,100,1,13.030000,100,1,14.280000,100,1,12.730000,100,1,14.400000,100,1,12.710000,100,1,14.560000,800,2,12.500000,700,1,14.600000,700,1,12.460000,200,2,14.680000,1400,2,12.430000,700,1,14.780000,100,1,12.420000,700,1,14.890000,200,2,12.370000,700,1,14.960000,100,1,ARL,301747957
2025-07-17T15:45:07.133978488Z,2025-07-17T15:45:07.133812895Z,10,2,1108,A,A,9,14.96,100,130,165593,254250625,13.260000,100,1,14.070000,2,1,13.040000,2,1,14.260000,100,1,13.030000,100,1,14.280000,100,1,12.730000,100,1,14.400000,100,1,12.710000,100,1,14.560000,800,2,12.500000,700,1,14.600000,700,1,12.460000,200,2,14.680000,1400,2,12.430000,700,1,14.780000,100,1,12.420000,700,1,14.890000,200,2,12.370000,700,1,14.960000,200,2,ARL,303334253
2025-07-17T15:45:07.469961302Z,2025-07-17T15:45:07.469796155Z,10,2,1108,A,A,1,14.08,100,130,165147,254258029,13.260000,100,1,14.070000,2,1,13.040000,2,1,14.080000,100,1,13.030000,100,1,14.260000,100,1,12.730000,100,1,14.280000,100,1,12.710000,100,1,14.400000,100,1,12.500000,700,1,14.560000,800,2,12.460000,200,2,14.600000,700,1,12.430000,700,1,14.680000,1400,2,12.420000,700,1,14.780000,100,1,12.370000,700,1,14.890000,200,2,ARL,303340405
2025-07-17T15:45:08.094768552Z,2025-07-17T15:45:08.094603115Z,10,2,1108,C,A,9,14.89,100,0,165437,254266885,13.260000,100,1,14.070000,2,1,13.040000,2,1,14.080000,100,1,13.030000,100,1,14.260000,100,1,12.730000,100,1,14.280000,100,1,12.710000,100,1,14.400000,100,1,12.500000,700,1,14.560000,800,2,12.460000,200,2,14.600000,700,1,12.430000,700,1,14.680000,1400,2,12.420000,700,1,14.780000,100,1,12.370000,700,1,14.890000,100,1,ARL,303330521
2025-07-17T15:45:08.094768552Z,2025-07-17T15:45:08.094603115Z,10,2,1108,A,A,-1,15.10,100,130,165437,254266885,13.260000,100,1,14.070000,2,1,13.040000,2,1,14.080000,100,1,13.030000,100,1,14.260000,100,1,12.730000,100,1,14.280000,100,1,12.710000,100,1,14.400000,100,1,12.500000,700,1,14.560000,800,2,12.460000,200,2,14.600000,700,1,12.430000,700,1,14.680000,1400,2,12.420000,700,1,14.780000,100,1,12.370000,700,1,14.890000,100,1,ARL,303349309
2025-07-17T15:45:08.103306644Z,2025-07-17T15:45:08.103141155Z,10,2,1108,C,A,9,14.89,100,0,165489,254266971,13.260000,100,1,14.070000,2,1,13.040000,2,1,14.080000,100,1,13.030000,100,1,14.260000,100,1,12.730000,100,1,14.280000,100,1,12.710000,100,1,14.400000,100,1,12.500000,700,1,14.560000,800,2,12.460000,200,2,14.600000,700,1,12.430000,700,1,14.680000,1400,2,12.420000,700,1,14.780000,100,1,12.370000,700,1,14.960000,200,2,ARL,303330477
2025-07-17T15:45:08.103306644Z,2025-07-17T15:45:08.103141155Z,10,2,1108,A,A,-1,15.10,100,130,165489,254266971,13.260000,100,1,14.070000,2,1,13.040000,2,1,14.080000,100,1,13.030000,100,1,14.260000,100,1,12.730000,100,1,14.280000,100,1,12.710000,100,1,14.400000,100,1,12.500000,700,1,14.560000,800,2,12.460000,200,2,14.600000,700,1,12.430000,700,1,14.680000,1400,2,12.420000,700,1,14.780000,100,1,12.370000,700,1,14.960000,200,2,ARL,303349377
2025-07-17T15:45:24.187008278Z,2025-07-17T15:45:24.186842413Z,10,2,1108,C,A,11,15.10,100,0,165865,254547413,13.260000,100,1,14.070000,2,1,13.040000,2,1,14.080000,100,1,13.030000,100,1,14.260000,100,1,12.730000,100,1,14.280000,100,1,12.710000,100,1,14.400000,100,1,12.500000,700,1,14.560000,800,2,12.460000,200,2,14.600000,700,1,12.430000,700,1,14.680000,1400,2,12.420000,700,1,14.780000,100,1,12.370000,700,1,14.960000,200,2,ARL,303349309
2025-07-17T15:45:24.187008278Z,2025-07-17T15:45:24.186842413Z,10,2,1108,A,A,9,14.88,100,130,165865,254547413,13.260000,100,1,14.070000,2,1,13.040000,2,1,14.080000,100,1,13.030000,100,1,14.260000,100,1,12.730000,100,1,14.280000,100,1,12.710000,100,1,14.400000,100,1,12.500000,700,1,14.560000,800,2,12.460000,200,2,14.600000,700,1,12.430000,700,1,14.680000,1400,2,12.420000,700,1,14.780000,100,1,12.370000,700,1,14.880000,100,1,ARL,303682385
2025-07-17T15:45:24.187441892Z,2025-07-17T15:45:24.187276389Z,10,2,1108,C,A,12,15.10,100,0,165503,254547415,13.260000,100,1,14.070000,2,1,13.040000,2,1,14.080000,100,1,13.030000,100,1,14.260000,100,1,12.730000,100,1,14.280000,100,1,12.710000,100,1,14.400000,100,1,12.500000,700,1,14.560000,800,2,12.460000,200,2,14.600000,700,1,12.430000,700,1,14.680000,1400,2,12.420000,700,1,14.780000,100,1,12.370000,700,1,14.880000,100,1,ARL,303349377
2025-07-17T15:45:24.187441892Z,2025-07-17T15:45:24.187276389Z,10,2,1108,A,A,9,14.88,100,130,165503,254547415,13.260000,100,1,14.070000,2,1,13.040000,2,1,14.080000,100,1,13.030000,100,1,14.260000,100,1,12.730000,100,1,14.280000,100,1,12.710000,100,1,14.400000,100,1,12.500000,700,1,14.560000,800,2,12.460000,200,2,14.600000,700,1,12.430000,700,1,14.680000,1400,2,12.420000,700,1,14.780000,100,1,12.370000,700,1,14.880000,200,2,ARL,303682389
2025-07-17T15:45:37.509454888Z,2025-07-17T15:45:37.509289536Z,10,2,1108,A,A,0,13.94,15,130,165352,254851462,13.260000,100,1,13.940000,15,1,13.040000,2,1,14.070000,2,1,13.030000,100,1,14.080000,100,1,12.730000,100,1,14.260000,100,1,12.710000,100,1,14.280000,100,1,12.500000,700,1,14.400000,100,1,12.460000,200,2,14.560000,800,2,12.430000,700,1,14.600000,700,1,12.420000,700,1,14.680000,1400,2,12.370000,700,1,14.780000,100,1,ARL,304056997
2025-07-17T15:45:37.998133497Z,2025-07-17T15:45:37.997967775Z,10,2,1108,C,A,2,14.08,100,0,165722,254864588,13.260000,100,1,13.940000,15,1,13.040000,2,1,14.070000,2,1,13.030000,100,1,14.260000,100,1,12.730000,100,1,14.280000,100,1,12.710000,100,1,14.400000,100,1,12.500000,700,1,14.560000,800,2,12.460000,200,2,14.600000,700,1,12.430000,700,1,14.680000,1400,2,12.420000,700,1,14.780000,100,1,12.370000,700,1,14.880000,200,2,ARL,303340405
2025-07-17T15:45:37.998133497Z,2025-07-17T15:45:37.997967775Z,10,2,1108,A,A,1,13.95,100,130,165722,254864588,13.260000,100,1,13.940000,15,1,13.040000,2,1,13.950000,100,1,13.030000,100,1,14.070000,2,1,12.730000,100,1,14.260000,100,1,12.710000,100,1,14.280000,100,1,12.500000,700,1,14.400000,100,1,12.460000,200,2,14.560000,800,2,12.430000,700,1,14.600000,700,1,12.420000,700,1,14.680000,1400,2,12.370000,700,1,14.780000,100,1,ARL,304072245
2025-07-17T15:45:44.700593408Z,2025-07-17T15:45:44.700428155Z,10,2,1108,A,A,0,13.89,15,130,165253,254999429,13.260000,100,1,13.890000,15,1,13.040000,2,1,13.940000,15,1,13.030000,100,1,13.950000,100,1,12.730000,100,1,14.070000,2,1,12.710000,100,1,14.260000,100,1,12.500000,700,1,14.280000,100,1,12.460000,200,2,14.400000,100,1,12.430000,700,1,14.560000,800,2,12.420000,700,1,14.600000,700,1,12.370000,700,1,14.680000,1400,2,ARL,304238913
2025-07-17T15:45:45.262537122Z,2025-07-17T15:45:45.262371701Z,10,2,1108,C,A,2,13.95,100,0,165421,255010979,13.260000,100,1,13.890000,15,1,13.040000,2,1,13.940000,15,1,13.030000,100,1,14.070000,2,1,12.730000,100,1,14.260000,100,1,12.710000,100,1,14.280000,100,1,12.500000,700,1,14.400000,100,1,12.460000,200,2,14.560000,800,2,12.430000,700,1,14.600000,700,1,12.420000,700,1,14.680000,1400,2,12.370000,700,1,14.780000,100,1,ARL,304072245
2025-07-17T15:45:45.262537122Z,2025-07-17T15:45:45.262371701Z,10,2,1108,A,A,1,13.90,100,130,165421,255010979,13.260000,100,1,13.890000,15,1,13.040000,2,1,13.900000,100,1,13.030000,100,1,13.940000,15,1,12.730000,100,1,14.070000,2,1,12.710000,100,1,14.260000,100,1,12.500000,700,1,14.280000,100,1,12.460000,200,2,14.400000,100,1,12.430000,700,1,14.560000,800,2,12.420000,700,1,14.600000,700,1,12.370000,700,1,14.680000,1400,2,ARL,304252313
2025-07-17T15:45:45.263289023Z,2025-07-17T15:45:45.263123432Z,10,2,1108,C,A,13,15.06,100,0,165591,255010987,13.260000,100,1,13.890000,15,1,13.040000,2,1,13.900000,100,1,13.030000,100,1,13.940000,15,1,12.730000,100,1,14.070000,2,1,12.710000,100,1,14.260000,100,1,12.500000,700,1,14.280000,100,1,12.460000,200,2,14.400000,100,1,12.430000,700,1,14.560000,800,2,12.420000,700,1,14.600000,700,1,12.370000,700,1,14.680000,1400,2,ARL,303330485
2025-07-17T15:45:45.263289023Z,2025-07-17T15:45:45.263123432Z,10,2,1108,A,A,-1,14.98,100,130,165591,255010987,13.260000,100,1,13.890000,15,1,13.040000,2,1,13.900000,100,1,13.030000,100,1,13.940000,15,1,12.730000,100,1,14.070000,2,1,12.710000,100,1,14.260000,100,1,12.500000,700,1,14.280000,100,1,12.460000,200,2,14.400000,100,1,12.430000,700,1,14.560000,800,2,12.420000,700,1,14.600000,700,1,12.370000,700,1,14.680000,1400,2,ARL,304252333
2025-07-17T15:45:45.274360382Z,2025-07-17T15:45:45.274194870Z,10,2,1108,C,A,4,14.26,100,130,165512,255011158,13.260000,100,1,13.890000,15,1,13.040000,2,1,13.900000,100,1,13.030000,100,1,13.940000,15,1,12.730000,100,1,14.070000,2,1,12.710000,100,1,14.280000,100,1,12.500000,700,1,14.400000,100,1,12.460000,200,2,14.560000,800,2,12.430000,700,1,14.600000,700,1,12.420000,700,1,14.680000,1400,2,12.370000,700,1,14.780000,100,1,ARL,303331401
2025-07-17T15:45:45.274410721Z,2025-07-17T15:45:45.274245387Z,10,2,1108,A,A,4,14.18,100,130,165334,255011161,13.260000,100,1,13.890000,15,1,13.040000,2,1,13.900000,100,1,13.030000,100,1,13.940000,15,1,12.730000,100,1,14.070000,2,1,12.710000,100,1,14.180000,100,1,12.500000,700,1,14.280000,100,1,12.460000,200,2,14.400000,100,1,12.430000,700,1,14.560000,800,2,12.420000,700,1,14.600000,700,1,12.370000,700,1,14.680000,1400,2,ARL,304252469
2025-07-17T15:45:58.419783333Z,2025-07-17T15:45:58.419617935Z,10,2,1108,C,A,2,13.94,15,130,165398,255183198,13.260000,100,1,13.890000,15,1,13.040000,2,1,13.900000,100,1,13.030000,100,1,14.070000,2,1,12.730000,100,1,14.180000,100,1,12.710000,100,1,14.280000,100,1,12.500000,700,1,14.400000,100,1,12.460000,200,2,14.560000,800,2,12.430000,700,1,14.600000,700,1,12.420000,700,1,14.680000,1400,2,12.370000,700,1,14.780000,100,1,ARL,304056997
2025-07-17T15:45:58.420278691Z,2025-07-17T15:45:58.420113307Z,10,2,1108,C,A,10,14.88,100,0,165384,255183203,13.260000,100,1,13.890000,15,1,13.040000,2,1,13.900000,100,1,13.030000,100,1,14.070000,2,1,12.730000,100,1,14.180000,100,1,12.710000,100,1,14.280000,100,1,12.500000,700,1,14.400000,100,1,12.460000,200,2,14.560000,800,2,12.430000,700,1,14.600000,700,1,12.420000,700,1,14.680000,1400,2,12.370000,700,1,14.780000,100,1,ARL,303682389
2025-07-17T15:45:58.420278691Z,2025-07-17T15:45:58.420113307Z,10,2,1108,A,A,9,14.77,100,130,165384,255183203,13.260000,100,1,13.890000,15,1,13.040000,2,1,13.900000,100,1,13.030000,100,1,14.070000,2,1,12.730000,100,1,14.180000,100,1,12.710000,100,1,14.280000,100,1,12.500000,700,1,14.400000,100,1,12.460000,200,2,14.560000,800,2,12.430000,700,1,14.600000,700,1,12.420000,700,1,14.680000,1400,2,12.370000,700,1,14.770000,100,1,ARL,304503585
2025-07-17T15:45:58.420755889Z,2025-07-17T15:45:58.420590199Z,10,2,1108,C,A,11,14.88,100,0,165690,255183204,13.260000,100,1,13.890000,15,1,13.040000,2,1,13.900000,100,1,13.030000,100,1,14.070000,2,1,12.730000,100,1,14.180000,100,1,12.710000,100,1,14.280000,100,1,12.500000,700,1,14.400000,100,1,12.460000,200,2,14.560000,800,2,12.430000,700,1,14.600000,700,1,12.420000,700,1,14.680000,1400,2,12.370000,700,1,14.770000,100,1,ARL,303682385
2025-07-17T15:45:58.420755889Z,2025-07-17T15:45:58.420590199Z,10,2,1108,A,A,9,14.77,100,130,165690,255183204,13.260000,100,1,13.890000,15,1,13.040000,2,1,13.900000,100,1,13.030000,100,1,14.070000,2,1,12.730000,100,1,14.180000,100,1,12.710000,100,1,14.280000,100,1,12.500000,700,1,14.400000,100,1,12.460000,200,2,14.560000,800,2,12.430000,700,1,14.600000,700,1,12.420000,700,1,14.680000,1400,2,12.370000,700,1,14.770000,200,2,ARL,304503593
2025-07-17T15:45:58.782892109Z,2025-07-17T15:45:58.782726994Z,10,2,1108,C,A,0,13.89,15,130,165115,255189425,13.260000,100,1,13.900000,100,1,13.040000,2,1,14.070000,2,1,13.030000,100,1,14.180000,100,1,12.730000,100,1,14.280000,100,1,12.710000,100,1,14.400000,100,1,12.500000,700,1,14.560000,800,2,12.460000,200,2,14.600000,700,1,12.430000,700,1,14.680000,1400,2,12.420000,700,1,14.770000,200,2,12.370000,700,1,14.780000,100,1,ARL,304238913
2025-07-17T15:46:16.783057616Z,2025-07-17T15:46:16.782892334Z,10,2,1108,A,A,0,13.88,15,130,165282,255552962,13.260000,100,1,13.880000,15,1,13.040000,2,1,13.900000,100,1,13.030000,100,1,14.070000,2,1,12.730000,100,1,14.180000,100,1,12.710000,100,1,14.280000,100,1,12.500000,700,1,14.400000,100,1,12.460000,200,2,14.560000,800,2,12.430000,700,1,14.600000,700,1,12.420000,700,1,14.680000,1400,2,12.370000,700,1,14.770000,200,2,ARL,304949689
2025-07-17T15:46:16.783326241Z,2025-07-17T15:46:16.783160795Z,10,2,1108,C,A,1,13.90,100,0,165446,255552970,13.260000,100,1,13.880000,15,1,13.040000,2,1,14.070000,2,1,13.030000,100,1,14.180000,100,1,12.730000,100,1,14.280000,100,1,12.710000,100,1,14.400000,100,1,12.500000,700,1,14.560000,800,2,12.460000,200,2,14.600000,700,1,12.430000,700,1,14.680000,1400,2,12.420000,700,1,14.770000,200,2,12.370000,700,1,14.780000,100,1,ARL,304252313
2025-07-17T15:46:16.783326241Z,2025-07-17T15:46:16.783160795Z,10,2,1108,A,A,1,13.89,100,130,165446,255552970,13.260000,100,1,13.880000,15,1,13.040000,2,1,13.890000,100,1,13.030000,100,1,14.070000,2,1,12.730000,100,1,14.180000,100,1,12.710000,100,1,14.280000,100,1,12.500000,700,1,14.400000,100,1,12.460000,200,2,14.560000,800,2,12.430000,700,1,14.600000,700,1,12.420000,700,1,14.680000,1400,2,12.370000,700,1,14.770000,200,2,ARL,304949697
2025-07-17T15:46:18.782897570Z,2025-07-17T15:46:18.782732218Z,10,2,1108,C,A,0,13.88,15,130,165352,255587336,13.260000,100,1,13.890000,100,1,13.040000,2,1,14.070000,2,1,13.030000,100,1,14.180000,100,1,12.730000,100,1,14.280000,100,1,12.710000,100,1,14.400000,100,1,12.500000,700,1,14.560000,800,2,12.460000,200,2,14.600000,700,1,12.430000,700,1,14.680000,1400,2,12.420000,700,1,14.770000,200,2,12.370000,700,1,14.780000,100,1,ARL,304949689
2025-07-17T15:46:28.474166897Z,2025-07-17T15:46:28.474001551Z,10,2,1108,C,A,0,13.89,100,130,165346,255746167,13.260000,100,1,14.070000,2,1,13.040000,2,1,14.180000,100,1,13.030000,100,1,14.280000,100,1,12.730000,100,1,14.400000,100,1,12.710000,100,1,14.560000,800,2,12.500000,700,1,14.600000,700,1,12.460000,200,2,14.680000,1400,2,12.430000,700,1,14.770000,200,2,12.420000,700,1,14.780000,100,1,12.370000,700,1,14.960000,200,2,ARL,304949697
2025-07-17T15:46:28.474726594Z,2025-07-17T15:46:28.474561156Z,10,2,1108,C,A,7,14.77,100,0,165438,255746173,13.260000,100,1,14.070000,2,1,13.040000,2,1,14.180000,100,1,13.030000,100,1,14.280000,100,1,12.730000,100,1,14.400000,100,1,12.710000,100,1,14.560000,800,2,12.500000,700,1,14.600000,700,1,12.460000,200,2,14.680000,1400,2,12.430000,700,1,14.770000,100,1,12.420000,700,1,14.780000,100,1,12.370000,700,1,14.960000,200,2,ARL,304503593
2025-07-17T15:46:28.474726594Z,2025-07-17T15:46:28.474561156Z,10,2,1108,A,A,9,14.88,100,130,165438,255746173,13.260000,100,1,14.070000,2,1,13.040000,2,1,14.180000,100,1,13.030000,100,1,14.280000,100,1,12.730000,100,1,14.400000,100,1,12.710000,100,1,14.560000,800,2,12.500000,700,1,14.600000,700,1,12.460000,200,2,14.680000,1400,2,12.430000,700,1,14.770000,100,1,12.420000,700,1,14.780000,100,1,12.370000,700,1,14.880000,100,1,ARL,305184937
2025-07-17T15:46:28.474896460Z,2025-07-17T15:46:28.474730225Z,10,2,1108,C,A,7,14.77,100,0,166235,255746176,13.260000,100,1,14.070000,2,1,13.040000,2,1,14.180000,100,1,13.030000,100,1,14.280000,100,1,12.730000,100,1,14.400000,100,1,12.710000,100,1,14.560000,800,2,12.500000,700,1,14.600000,700,1,12.460000,200,2,14.680000,1400,2,12.430000,700,1,14.780000,100,1,12.420000,700,1,14.880000,100,1,12.370000,700,1,14.960000,200,2,ARL,304503585
2025-07-17T15:46:28.474896460Z,2025-07-17T15:46:28.474730225Z,10,2,1108,A,A,8,14.88,100,130,166235,255746176,13.260000,100,1,14.070000,2,1,13.040000,2,1,14.180000,100,1,13.030000,100,1,14.280000,100,1,12.730000,100,1,14.400000,100,1,12.710000,100,1,14.560000,800,2,12.500000,700,1,14.600000,700,1,12.460000,200,2,14.680000,1400,2,12.430000,700,1,14.780000,100,1,12.420000,700,1,14.880000,200,2,12.370000,700,1,14.960000,200,2,ARL,305184953
2025-07-17T15:46:28.474902154Z,2025-07-17T15:46:28.474736101Z,10,2,1108,C,A,10,14.98,100,0,166053,255746178,13.260000,100,1,14.070000,2,1,13.040000,2,1,14.180000,100,1,13.030000,100,1,14.280000,100,1,12.730000,100,1,14.400000,100,1,12.710000,100,1,14.560000,800,2,12.500000,700,1,14.600000,700,1,12.460000,200,2,14.680000,1400,2,12.430000,700,1,14.780000,100,1,12.420000,700,1,14.880000,200,2,12.370000,700,1,14.960000,200,2,ARL,304252333
2025-07-17T15:46:28.474902154Z,2025-07-17T15:46:28.474736101Z,10,2,1108,A,A,-1,15.03,100,128,166053,255746178,13.260000,100,1,14.070000,2,1,13.040000,2,1,14.180000,100,1,13.030000,100,1,14.280000,100,1,12.730000,100,1,14.400000,100,1,12.710000,100,1,14.560000,800,2,12.500000,700,1,14.600000,700,1,12.460000,200,2,14.680000,1400,2,12.430000,700,1,14.780000,100,1,12.420000,700,1,14.880000,200,2,12.370000,700,1,14.960000,200,2,ARL,305184957
2025-07-17T15:46:28.492881980Z,2025-07-17T15:46:28.492716775Z,10,2,1108,C,A,1,14.18,100,130,165205,255746619,13.260000,100,1,14.070000,2,1,13.040000,2,1,14.280000,100,1,13.030000,100,1,14.400000,100,1,12.730000,100,1,14.560000,800,2,12.710000,100,1,14.600000,700,1,12.500000,700,1,14.680000,1400,2,12.460000,200,2,14.780000,100,1,12.430000,700,1,14.880000,200,2,12.420000,700,1,14.960000,200,2,12.370000,700,1,15.030000,100,1,ARL,304252469
2025-07-17T15:46:28.492931279Z,2025-07-17T15:46:28.492765859Z,10,2,1108,A,A,1,14.26,100,130,165420,255746621,13.260000,100,1,14.070000,2,1,13.040000,2,1,14.260000,100,1,13.030000,100,1,14.280000,100,1,12.730000,100,1,14.400000,100,1,12.710000,100,1,14.560000,800,2,12.500000,700,1,14.600000,700,1,12.460000,200,2,14.680000,1400,2,12.430000,700,1,14.780000,100,1,12.420000,700,1,14.880000,200,2,12.370000,700,1,14.960000,200,2,ARL,305185529
2025-07-17T15:46:28.646273467Z,2025-07-17T15:46:28.646108242Z,10,2,1108,A,A,1,14.08,100,130,165225,255748568,13.260000,100,1,14.070000,2,1,13.040000,2,1,14.080000,100,1,13.030000,100,1,14.260000,100,1,12.730000,100,1,14.280000,100,1,12.710000,100,1,14.400000,100,1,12.500000,700,1,14.560000,800,2,12.460000,200,2,14.600000,700,1,12.430000,700,1,14.680000,1400,2,12.420000,700,1,14.780000,100,1,12.370000,700,1,14.880000,200,2,ARL,305187077
2025-07-17T15:46:57.524024658Z,2025-07-17T15:46:57.523859388Z,10,2,1108,A,A,0,13.92,15,130,165270,256268482,13.260000,100,1,13.920000,15,1,13.040000,2,1,14.070000,2,1,13.030000,100,1,14.080000,100,1,12.730000,100,1,14.260000,100,1,12.710000,100,1,14.280000,100,1,12.500000,700,1,14.400000,100,1,12.460000,200,2,14.560000,800,2,12.430000,700,1,14.600000,700,1,12.420000,700,1,14.680000,1400,2,12.370000,700,1,14.780000,100,1,ARL,305862145
2025-07-17T15:46:57.932842994Z,2025-07-17T15:46:57.932677299Z,10,2,1108,C,A,2,14.08,100,0,165695,256280751,13.260000,100,1,13.920000,15,1,13.040000,2,1,14.070000,2,1,13.030000,100,1,14.260000,100,1,12.730000,100,1,14.280000,100,1,12.710000,100,1,14.400000,100,1,12.500000,700,1,14.560000,800,2,12.460000,200,2,14.600000,700,1,12.430000,700,1,14.680000,1400,2,12.420000,700,1,14.780000,100,1,12.370000,700,1,14.880000,200,2,ARL,305187077
2025-07-17T15:46:57.932842994Z,2025-07-17T15:46:57.932677299Z,10,2,1108,A,A,1,13.93,100,130,165695,256280751,13.260000,100,1,13.920000,15,1,13.040000,2,1,13.930000,100,1,13.030000,100,1,14.070000,2,1,12.730000,100,1,14.260000,100,1,12.710000,100,1,14.280000,100,1,12.500000,700,1,14.400000,100,1,12.460000,200,2,14.560000,800,2,12.430000,700,1,14.600000,700,1,12.420000,700,1,14.680000,1400,2,12.370000,700,1,14.780000,100,1,ARL,305878881
2025-07-17T15:47:06.609456251Z,2025-07-17T15:47:06.609290857Z,10,2,1108,A,A,0,13.88,15,130,165394,256488374,13.260000,100,1,13.880000,15,1,13.040000,2,1,13.920000,15,1,13.030000,100,1,13.930000,100,1,12.730000,100,1,14.070000,2,1,12.710000,100,1,14.260000,100,1,12.500000,700,1,14.280000,100,1,12.460000,200,2,14.400000,100,1,12.430000,700,1,14.560000,800,2,12.420000,700,1,14.600000,700,1,12.370000,700,1,14.680000,1400,2,ARL,306121113
2025-07-17T15:47:08.787695144Z,2025-07-17T15:47:08.787529505Z,10,2,1108,C,A,2,13.93,100,0,165639,256532991,13.260000,100,1,13.880000,15,1,13.040000,2,1,13.920000,15,1,13.030000,100,1,14.070000,2,1,12.730000,100,1,14.260000,100,1,12.710000,100,1,14.280000,100,1,12.500000,700,1,14.400000,100,1,12.460000,200,2,14.560000,800,2,12.430000,700,1,14.600000,700,1,12.420000,700,1,14.680000,1400,2,12.370000,700,1,14.780000,100,1,ARL,305878881
2025-07-17T15:47:08.787695144Z,2025-07-17T15:47:08.787529505Z,10,2,1108,A,A,1,13.89,100,130,165639,256532991,13.260000,100,1,13.880000,15,1,13.040000,2,1,13.890000,100,1,13.030000,100,1,13.920000,15,1,12.730000,100,1,14.070000,2,1,12.710000,100,1,14.260000,100,1,12.500000,700,1,14.280000,100,1,12.460000,200,2,14.400000,100,1,12.430000,700,1,14.560000,800,2,12.420000,700,1,14.600000,700,1,12.370000,700,1,14.680000,1400,2,ARL,306170837
2025-07-17T15:47:08.788440762Z,2025-07-17T15:47:08.788275184Z,10,2,1108,C,A,13,15.03,100,0,165578,256533005,13.260000,100,1,13.880000,15,1,13.040000,2,1,13.890000,100,1,13.030000,100,1,13.920000,15,1,12.730000,100,1,14.070000,2,1,12.710000,100,1,14.260000,100,1,12.500000,700,1,14.280000,100,1,12.460000,200,2,14.400000,100,1,12.430000,700,1,14.560000,800,2,12.420000,700,1,14.600000,700,1,12.370000,700,1,14.680000,1400,2,ARL,305184957
2025-07-17T15:47:08.788440762Z,2025-07-17T15:47:08.788275184Z,10,2,1108,A,A,-1,14.97,100,130,165578,256533005,13.260000,100,1,13.880000,15,1,13.040000,2,1,13.890000,100,1,13.030000,100,1,13.920000,15,1,12.730000,100,1,14.070000,2,1,12.710000,100,1,14.260000,100,1,12.500000,700,1,14.280000,100,1,12.460000,200,2,14.400000,100,1,12.430000,700,1,14.560000,800,2,12.420000,700,1,14.600000,700,1,12.370000,700,1,14.680000,1400,2,ARL,306170869
2025-07-17T15:47:08.805983406Z,2025-07-17T15:47:08.805818249Z,10,2,1108,C,A,4,14.26,100,130,165157,256533442,13.260000,100,1,13.880000,15,1,13.040000,2,1,13.890000,100,1,13.030000,100,1,13.920000,15,1,12.730000,100,1,14.070000,2,1,12.710000,100,1,14.280000,100,1,12.500000,700,1,14.400000,100,1,12.460000,200,2,14.560000,800,2,12.430000,700,1,14.600000,700,1,12.420000,700,1,14.680000,1400,2,12.370000,700,1,14.780000,100,1,ARL,305185529
2025-07-17T15:47:08.806033773Z,2025-07-17T15:47:08.805868059Z,10,2,1108,A,A,4,14.17,100,130,165714,256533443,13.260000,100,1,13.880000,15,1,13.040000,2,1,13.890000,100,1,13.030000,100,1,13.920000,15,1,12.730000,100,1,14.070000,2,1,12.710000,100,1,14.170000,100,1,12.500000,700,1,14.280000,100,1,12.460000,200,2,14.400000,100,1,12.430000,700,1,14.560000,800,2,12.420000,700,1,14.600000,700,1,12.370000,700,1,14.680000,1400,2,ARL,306171457
2025-07-17T15:47:13.121454355Z,2025-07-17T15:47:13.121288953Z,10,2,1108,C,A,0,13.88,15,130,165402,256612694,13.260000,100,1,13.890000,100,1,13.040000,2,1,13.920000,15,1,13.030000,100,1,14.070000,2,1,12.730000,100,1,14.170000,100,1,12.710000,100,1,14.280000,100,1,12.500000,700,1,14.400000,100,1,12.460000,200,2,14.560000,800,2,12.430000,700,1,14.600000,700,1,12.420000,700,1,14.680000,1400,2,12.370000,700,1,14.780000,100,1,ARL,306121113
2025-07-17T15:47:13.122562533Z,2025-07-17T15:47:13.122396816Z,10,2,1108,C,A,1,13.92,15,130,165717,256612757,13.260000,100,1,13.890000,100,1,13.040000,2,1,14.070000,2,1,13.030000,100,1,14.170000,100,1,12.730000,100,1,14.280000,100,1,12.710000,100,1,14.400000,100,1,12.500000,700,1,14.560000,800,2,12.460000,200,2,14.600000,700,1,12.430000,700,1,14.680000,1400,2,12.420000,700,1,14.780000,100,1,12.370000,700,1,14.880000,200,2,ARL,305862145
2025-07-17T15:47:24.786476266Z,2025-07-17T15:47:24.786310694Z,10,2,1108,A,A,0,13.87,15,130,165572,256812416,13.260000,100,1,13.870000,15,1,13.040000,2,1,13.890000,100,1,13.030000,100,1,14.070000,2,1,12.730000,100,1,14.170000,100,1,12.710000,100,1,14.280000,100,1,12.500000,700,1,14.400000,100,1,12.460000,200,2,14.560000,800,2,12.430000,700,1,14.600000,700,1,12.420000,700,1,14.680000,1400,2,12.370000,700,1,14.780000,100,1,ARL,306519385
2025-07-17T15:47:24.786745657Z,2025-07-17T15:47:24.786580061Z,10,2,1108,C,A,1,13.89,100,0,165596,256812420,13.260000,100,1,13.870000,15,1,13.040000,2,1,14.070000,2,1,13.030000,100,1,14.170000,100,1,12.730000,100,1,14.280000,100,1,12.710000,100,1,14.400000,100,1,12.500000,700,1,14.560000,800,2,12.460000,200,2,14.600000,700,1,12.430000,700,1,14.680000,1400,2,12.420000,700,1,14.780000,100,1,12.370000,700,1,14.880000,200,2,ARL,306170837
2025-07-17T15:47:24.786745657Z,2025-07-17T15:47:24.786580061Z,10,2,1108,A,A,1,13.88,100,130,165596,256812420,13.260000,100,1,13.870000,15,1,13.040000,2,1,13.880000,100,1,13.030000,100,1,14.070000,2,1,12.730000,100,1,14.170000,100,1,12.710000,100,1,14.280000,100,1,12.500000,700,1,14.400000,100,1,12.460000,200,2,14.560000,800,2,12.430000,700,1,14.600000,700,1,12.420000,700,1,14.680000,1400,2,12.370000,700,1,14.780000,100,1,ARL,306519397
2025-07-17T15:47:24.786925729Z,2025-07-17T15:47:24.786759805Z,10,2,1108,C,A,10,14.88,100,0,165924,256812422,13.260000,100,1,13.870000,15,1,13.040000,2,1,13.880000,100,1,13.030000,100,1,14.070000,2,1,12.730000,100,1,14.170000,100,1,12.710000,100,1,14.280000,100,1,12.500000,700,1,14.400000,100,1,12.460000,200,2,14.560000,800,2,12.430000,700,1,14.600000,700,1,12.420000,700,1,14.680000,1400,2,12.370000,700,1,14.780000,100,1,ARL,305184937
2025-07-17T15:47:24.786925729Z,2025-07-17T15:47:24.786759805Z,10,2,1108,A,A,9,14.77,100,130,165924,256812422,13.260000,100,1,13.870000,15,1,13.040000,2,1,13.880000,100,1,13.030000,100,1,14.070000,2,1,12.730000,100,1,14.170000,100,1,12.710000,100,1,14.280000,100,1,12.500000,700,1,14.400000,100,1,12.460000,200,2,14.560000,800,2,12.430000,700,1,14.600000,700,1,12.420000,700,1,14.680000,1400,2,12.370000,700,1,14.770000,100,1,ARL,306519409
2025-07-17T15:47:24.800616004Z,2025-07-17T15:47:24.800449950Z,10,2,1108,C,A,11,14.88,100,0,166054,256812578,13.260000,100,1,13.870000,15,1,13.040000,2,1,13.880000,100,1,13.030000,100,1,14.070000,2,1,12.730000,100,1,14.170000,100,1,12.710000,100,1,14.280000,100,1,12.500000,700,1,14.400000,100,1,12.460000,200,2,14.560000,800,2,12.430000,700,1,14.600000,700,1,12.420000,700,1,14.680000,1400,2,12.370000,700,1,14.770000,100,1,ARL,305184953
2025-07-17T15:47:24.800616004Z,2025-07-17T15:47:24.800449950Z,10,2,1108,A,A,9,14.75,100,130,166054,256812578,13.260000,100,1,13.870000,15,1,13.040000,2,1,13.880000,100,1,13.030000,100,1,14.070000,2,1,12.730000,100,1,14.170000,100,1,12.710000,100,1,14.280000,100,1,12.500000,700,1,14.400000,100,1,12.460000,200,2,14.560000,800,2,12.430000,700,1,14.600000,700,1,12.420000,700,1,14.680000,1400,2,12.370000,700,1,14.750000,100,1,ARL,306519741
2025-07-17T15:47:27.860272892Z,2025-07-17T15:47:27.860107552Z,10,2,1108,A,A,0,13.83,15,130,165340,256866835,13.260000,100,1,13.830000,15,1,13.040000,2,1,13.870000,15,1,13.030000,100,1,13.880000,100,1,12.730000,100,1,14.070000,2,1,12.710000,100,1,14.170000,100,1,12.500000,700,1,14.280000,100,1,12.460000,200,2,14.400000,100,1,12.430000,700,1,14.560000,800,2,12.420000,700,1,14.600000,700,1,12.370000,700,1,14.680000,1400,2,ARL,306587393
2025-07-17T15:47:31.407029312Z,2025-07-17T15:47:31.406863918Z,10,2,1108,C,A,2,13.88,100,0,165394,256910124,13.260000,100,1,13.830000,15,1,13.040000,2,1,13.870000,15,1,13.030000,100,1,14.070000,2,1,12.730000,100,1,14.170000,100,1,12.710000,100,1,14.280000,100,1,12.500000,700,1,14.400000,100,1,12.460000,200,2,14.560000,800,2,12.430000,700,1,14.600000,700,1,12.420000,700,1,14.680000,1400,2,12.370000,700,1,14.750000,100,1,ARL,306519397
2025-07-17T15:47:31.407029312Z,2025-07-17T15:47:31.406863918Z,10,2,1108,A,A,1,13.84,100,130,165394,256910124,13.260000,100,1,13.830000,15,1,13.040000,2,1,13.840000,100,1,13.030000,100,1,13.870000,15,1,12.730000,100,1,14.070000,2,1,12.710000,100,1,14.170000,100,1,12.500000,700,1,14.280000,100,1,12.460000,200,2,14.400000,100,1,12.430000,700,1,14.560000,800,2,12.420000,700,1,14.600000,700,1,12.370000,700,1,14.680000,1400,2,ARL,306647425
2025-07-17T15:47:31.407771110Z,2025-07-17T15:47:31.407605685Z,10,2,1108,C,A,14,14.97,100,0,165425,256910129,13.260000,100,1,13.830000,15,1,13.040000,2,1,13.840000,100,1,13.030000,100,1,13.870000,15,1,12.730000,100,1,14.070000,2,1,12.710000,100,1,14.170000,100,1,12.500000,700,1,14.280000,100,1,12.460000,200,2,14.400000,100,1,12.430000,700,1,14.560000,800,2,12.420000,700,1,14.600000,700,1,12.370000,700,1,14.680000,1400,2,ARL,306170869
2025-07-17T15:47:31.407771110Z,2025-07-17T15:47:31.407605685Z,10,2,1108,A,A,-1,14.91,100,130,165425,256910129,13.260000,100,1,13.830000,15,1,13.040000,2,1,13.840000,100,1,13.030000,100,1,13.870000,15,1,12.730000,100,1,14.070000,2,1,12.710000,100,1,14.170000,100,1,12.500000,700,1,14.280000,100,1,12.460000,200,2,14.400000,100,1,12.430000,700,1,14.560000,800,2,12.420000,700,1,14.600000,700,1,12.370000,700,1,14.680000,1400,2,ARL,306647445
2025-07-17T15:47:31.413491477Z,2025-07-17T15:47:31.413325908Z,10,2,1108,C,A,12,14.78,100,0,165569,256910184,13.260000,100,1,13.830000,15,1,13.040000,2,1,13.840000,100,1,13.030000,100,1,13.870000,15,1,12.730000,100,1,14.070000,2,1,12.710000,100,1,14.170000,100,1,12.500000,700,1,14.280000,100,1,12.460000,200,2,14.400000,100,1,12.430000,700,1,14.560000,800,2,12.420000,700,1,14.600000,700,1,12.370000,700,1,14.680000,1400,2,ARL,303331425
2025-07-17T15:47:31.413491477Z,2025-07-17T15:47:31.413325908Z,10,2,1108,A,A,9,14.64,100,130,165569,256910184,13.260000,100,1,13.830000,15,1,13.040000,2,1,13.840000,100,1,13.030000,100,1,13.870000,15,1,12.730000,100,1,14.070000,2,1,12.710000,100,1,14.170000,100,1,12.500000,700,1,14.280000,100,1,12.460000,200,2,14.400000,100,1,12.430000,700,1,14.560000,800,2,12.420000,700,1,14.600000,700,1,12.370000,700,1,14.640000,100,1,ARL,306647521
2025-07-17T15:47:31.433486283Z,2025-07-17T15:47:31.433320466Z,10,2,1108,C,A,14,14.96,100,0,165817,256910721,13.260000,100,1,13.830000,15,1,13.040000,2,1,13.840000,100,1,13.030000,100,1,13.870000,15,1,12.730000,100,1,14.070000,2,1,12.710000,100,1,14.170000,100,1,12.500000,700,1,14.280000,100,1,12.460000,200,2,14.400000,100,1,12.430000,700,1,14.560000,800,2,12.420000,700,1,14.600000,700,1,12.370000,700,1,14.640000,100,1,ARL,303330509
2025-07-17T15:47:31.433486283Z,2025-07-17T15:47:31.433320466Z,10,2,1108,A,A,-1,14.81,100,130,165817,256910721,13.260000,100,1,13.830000,15,1,13.040000,2,1,13.840000,100,1,13.030000,100,1,13.870000,15,1,12.730000,100,1,14.070000,2,1,12.710000,100,1,14.170000,100,1,12.500000,700,1,14.280000,100,1,12.460000,200,2,14.400000,100,1,12.430000,700,1,14.560000,800,2,12.420000,700,1,14.600000,700,1,12.370000,700,1,14.640000,100,1,ARL,306649913
2025-07-17T15:47:31.574128504Z,2025-07-17T15:47:31.573963059Z,10,2,1108,C,A,20,16.08,100,0,165445,256912087,13.260000,100,1,13.830000,15,1,13.040000,2,1,13.840000,100,1,13.030000,100,1,13.870000,15,1,12.730000,100,1,14.070000,2,1,12.710000,100,1,14.170000,100,1,12.500000,700,1,14.280000,100,1,12.460000,200,2,14.400000,100,1,12.430000,700,1,14.560000,800,2,12.420000,700,1,14.600000,700,1,12.370000,700,1,14.640000,100,1,ARL,303331429
2025-07-17T15:47:31.574128504Z,2025-07-17T15:47:31.573963059Z,10,2,1108,A,A,-1,15.92,100,130,165445,256912087,13.260000,100,1,13.830000,15,1,13.040000,2,1,13.840000,100,1,13.030000,100,1,13.870000,15,1,12.730000,100,1,14.070000,2,1,12.710000,100,1,14.170000,100,1,12.500000,700,1,14.280000,100,1,12.460000,200,2,14.400000,100,1,12.430000,700,1,14.560000,800,2,12.420000,700,1,14.600000,700,1,12.370000,700,1,14.640000,100,1,ARL,306652001
2025-07-17T15:47:31.575374481Z,2025-07-17T15:47:31.575209032Z,10,2,1108,C,A,23,17.76,100,0,165449,256912094,13.260000,100,1,13.830000,15,1,13.040000,2,1,13.840000,100,1,13.030000,100,1,13.870000,15,1,12.730000,100,1,14.070000,2,1,12.710000,100,1,14.170000,100,1,12.500000,700,1,14.280000,100,1,12.460000,200,2,14.400000,100,1,12.430000,700,1,14.560000,800,2,12.420000,700,1,14.600000,700,1,12.370000,700,1,14.640000,100,1,ARL,303331309
2025-07-17T15:47:31.575374481Z,2025-07-17T15:47:31.575209032Z,10,2,1108,A,A,-1,17.58,100,130,165449,256912094,13.260000,100,1,13.830000,15,1,13.040000,2,1,13.840000,100,1,13.030000,100,1,13.870000,15,1,12.730000,100,1,14.070000,2,1,12.710000,100,1,14.170000,100,1,12.500000,700,1,14.280000,100,1,12.460000,200,2,14.400000,100,1,12.430000,700,1,14.560000,800,2,12.420000,700,1,14.600000,700,1,12.370000,700,1,14.640000,100,1,ARL,306652017
2025-07-17T15:47:31.740095714Z,2025-07-17T15:47:31.739930142Z,10,2,1108,C,A,15,14.96,100,0,165572,256914067,13.260000,100,1,13.830000,15,1,13.040000,2,1,13.840000,100,1,13.030000,100,1,13.870000,15,1,12.730000,100,1,14.070000,2,1,12.710000,100,1,14.170000,100,1,12.500000,700,1,14.280000,100,1,12.460000,200,2,14.400000,100,1,12.430000,700,1,14.560000,800,2,12.420000,700,1,14.600000,700,1,12.370000,700,1,14.640000,100,1,ARL,303334253
2025-07-17T15:47:31.740095714Z,2025-07-17T15:47:31.739930142Z,10,2,1108,A,A,-1,14.81,100,130,165572,256914067,13.260000,100,1,13.830000,15,1,13.040000,2,1,13.840000,100,1,13.030000,100,1,13.870000,15,1,12.730000,100,1,14.070000,2,1,12.710000,100,1,14.170000,100,1,12.500000,700,1,14.280000,100,1,12.460000,200,2,14.400000,100,1,12.430000,700,1,14.560000,800,2,12.420000,700,1,14.600000,700,1,12.370000,700,1,14.640000,100,1,ARL,306653713
2025-07-17T15:47:37.159589804Z,2025-07-17T15:47:37.159424166Z,10,2,1108,C,A,2,13.87,15,130,165638,256983942,13.260000,100,1,13.830000,15,1,13.040000,2,1,13.840000,100,1,13.030000,100,1,14.070000,2,1,12.730000,100,1,14.170000,100,1,12.710000,100,1,14.280000,100,1,12.500000,700,1,14.400000,100,1,12.460000,200,2,14.560000,800,2,12.430000,700,1,14.600000,700,1,12.420000,700,1,14.640000,100,1,12.370000,700,1,14.680000,1400,2,ARL,306519385
2025-07-17T15:47:37.172000440Z,2025-07-17T15:47:37.171834941Z,10,2,1108,A,A,2,13.85,100,130,165499,256984053,13.260000,100,1,13.830000,15,1,13.040000,2,1,13.840000,100,1,13.030000,100,1,13.850000,100,1,12.730000,100,1,14.070000,2,1,12.710000,100,1,14.170000,100,1,12.500000,700,1,14.280000,100,1,12.460000,200,2,14.400000,100,1,12.430000,700,1,14.560000,800,2,12.420000,700,1,14.600000,700,1,12.370000,700,1,14.640000,100,1,ARL,306749753
2025-07-17T15:47:38.161181283Z,2025-07-17T15:47:38.161015969Z,10,2,1108,A,A,0,13.79,15,130,165314,256998606,13.260000,100,1,13.790000,15,1,13.040000,2,1,13.830000,15,1,13.030000,100,1,13.840000,100,1,12.730000,100,1,13.850000,100,1,12.710000,100,1,14.070000,2,1,12.500000,700,1,14.170000,100,1,12.460000,200,2,14.280000,100,1,12.430000,700,1,14.400000,100,1,12.420000,700,1,14.560000,800,2,12.370000,700,1,14.600000,700,1,ARL,306770041
2025-07-17T15:47:38.794962245Z,2025-07-17T15:47:38.794795887Z,10,2,1108,C,A,2,13.84,100,0,166358,257010989,13.260000,100,1,13.790000,15,1,13.040000,2,1,13.830000,15,1,13.030000,100,1,13.850000,100,1,12.730000,100,1,14.070000,2,1,12.710000,100,1,14.170000,100,1,12.500000,700,1,14.280000,100,1,12.460000,200,2,14.400000,100,1,12.430000,700,1,14.560000,800,2,12.420000,700,1,14.600000,700,1,12.370000,700,1,14.640000,100,1,ARL,306647425
2025-07-17T15:47:38.794962245Z,2025-07-17T15:47:38.794795887Z,10,2,1108,A,A,1,13.80,100,128,166358,257010989,13.260000,100,1,13.790000,15,1,13.040000,2,1,13.800000,100,1,13.030000,100,1,13.830000,15,1,12.730000,100,1,13.850000,100,1,12.710000,100,1,14.070000,2,1,12.500000,700,1,14.170000,100,1,12.460000,200,2,14.280000,100,1,12.430000,700,1,14.400000,100,1,12.420000,700,1,14.560000,800,2,12.370000,700,1,14.600000,700,1,ARL,306784133
2025-07-17T15:47:38.795723570Z,2025-07-17T15:47:38.795557785Z,10,2,1108,C,A,15,14.91,100,0,165785,257011058,13.260000,100,1,13.790000,15,1,13.040000,2,1,13.800000,100,1,13.030000,100,1,13.830000,15,1,12.730000,100,1,13.850000,100,1,12.710000,100,1,14.070000,2,1,12.500000,700,1,14.170000,100,1,12.460000,200,2,14.280000,100,1,12.430000,700,1,14.400000,100,1,12.420000,700,1,14.560000,800,2,12.370000,700,1,14.600000,700,1,ARL,306647445
2025-07-17T15:47:38.795723570Z,2025-07-17T15:47:38.795557785Z,10,2,1108,A,A,-1,14.87,100,130,165785,257011058,13.260000,100,1,13.790000,15,1,13.040000,2,1,13.800000,100,1,13.030000,100,1,13.830000,15,1,12.730000,100,1,13.850000,100,1,12.710000,100,1,14.070000,2,1,12.500000,700,1,14.170000,100,1,12.460000,200,2,14.280000,100,1,12.430000,700,1,14.400000,100,1,12.420000,700,1,14.560000,800,2,12.370000,700,1,14.600000,700,1,ARL,306784201
2025-07-17T15:47:38.804624258Z,2025-07-17T15:47:38.804458744Z,10,2,1108,C,A,5,14.17,100,130,165514,257011716,13.260000,100,1,13.790000,15,1,13.040000,2,1,13.800000,100,1,13.030000,100,1,13.830000,15,1,12.730000,100,1,13.850000,100,1,12.710000,100,1,14.070000,2,1,12.500000,700,1,14.280000,100,1,12.460000,200,2,14.400000,100,1,12.430000,700,1,14.560000,800,2,12.420000,700,1,14.600000,700,1,12.370000,700,1,14.640000,100,1,ARL,306171457
2025-07-17T15:47:38.804679592Z,2025-07-17T15:47:38.804513793Z,10,2,1108,A,A,5,14.08,100,130,165799,257011717,13.260000,100,1,13.790000,15,1,13.040000,2,1,13.800000,100,1,13.030000,100,1,13.830000,15,1,12.730000,100,1,13.850000,100,1,12.710000,100,1,14.070000,2,1,12.500000,700,1,14.080000,100,1,12.460000,200,2,14.280000,100,1,12.430000,700,1,14.400000,100,1,12.420000,700,1,14.560000,800,2,12.370000,700,1,14.600000,700,1,ARL,306784853
2025-07-17T15:47:39.092472059Z,2025-07-17T15:47:39.092305947Z,10,2,1108,C,A,0,13.79,15,130,166112,257018687,13.260000,100,1,13.800000,100,1,13.040000,2,1,13.830000,15,1,13.030000,100,1,13.850000,100,1,12.730000,100,1,14.070000,2,1,12.710000,100,1,14.080000,100,1,12.500000,700,1,14.280000,100,1,12.460000,200,2,14.400000,100,1,12.430000,700,1,14.560000,800,2,12.420000,700,1,14.600000,700,1,12.370000,700,1,14.640000,100,1,ARL,306770041
2025-07-17T15:47:39.095920859Z,2025-07-17T15:47:39.095755335Z,10,2,1108,C,A,1,13.83,15,130,165524,257018796,13.260000,100,1,13.800000,100,1,13.040000,2,1,13.850000,100,1,13.030000,100,1,14.070000,2,1,12.730000,100,1,14.080000,100,1,12.710000,100,1,14.280000,100,1,12.500000,700,1,14.400000,100,1,12.460000,200,2,14.560000,800,2,12.430000,700,1,14.600000,700,1,12.420000,700,1,14.640000,100,1,12.370000,700,1,14.680000,1400,2,ARL,306587393
2025-07-17T15:48:08.909366905Z,2025-07-17T15:48:08.909201576Z,10,2,1108,A,A,1,13.83,100,130,165329,257603755,13.260000,100,1,13.800000,100,1,13.040000,2,1,13.830000,100,1,13.030000,100,1,13.850000,100,1,12.730000,100,1,14.070000,2,1,12.710000,100,1,14.080000,100,1,12.500000,700,1,14.280000,100,1,12.460000,200,2,14.400000,100,1,12.430000,700,1,14.560000,800,2,12.420000,700,1,14.600000,700,1,12.370000,700,1,14.640000,100,1,ARL,307567929
2025-07-17T15:48:08.916721098Z,2025-07-17T15:48:08.916555821Z,10,2,1108,C,A,2,13.85,100,130,165277,257604057,13.260000,100,1,13.800000,100,1,13.040000,2,1,13.830000,100,1,13.030000,100,1,14.070000,2,1,12.730000,100,1,14.080000,100,1,12.710000,100,1,14.280000,100,1,12.500000,700,1,14.400000,100,1,12.460000,200,2,14.560000,800,2,12.430000,700,1,14.600000,700,1,12.420000,700,1,14.640000,100,1,12.370000,700,1,14.680000,1400,2,ARL,306749753
2025-07-17T15:48:09.653473465Z,2025-07-17T15:48:09.653308042Z,10,2,1108,A,A,0,13.78,15,130,165423,257621095,13.260000,100,1,13.780000,15,1,13.040000,2,1,13.800000,100,1,13.030000,100,1,13.830000,100,1,12.730000,100,1,14.070000,2,1,12.710000,100,1,14.080000,100,1,12.500000,700,1,14.280000,100,1,12.460000,200,2,14.400000,100,1,12.430000,700,1,14.560000,800,2,12.420000,700,1,14.600000,700,1,12.370000,700,1,14.640000,100,1,ARL,307587873
2025-07-17T15:48:11.166689254Z,2025-07-17T15:48:11.166517494Z,10,2,1108,C,A,0,13.78,15,128,171760,257644020,13.260000,100,1,13.800000,100,1,13.040000,2,1,13.830000,100,1,13.030000,100,1,14.070000,2,1,12.730000,100,1,14.080000,100,1,12.710000,100,1,14.280000,100,1,12.500000,700,1,14.400000,100,1,12.460000,200,2,14.560000,800,2,12.430000,700,1,14.600000,700,1,12.420000,700,1,14.640000,100,1,12.370000,700,1,14.680000,1400,2,ARL,307587873
2025-07-17T15:48:13.509078553Z,2025-07-17T15:48:13.508913083Z,10,2,1108,A,A,0,13.78,15,130,165470,257727039,13.260000,100,1,13.780000,15,1,13.040000,2,1,13.800000,100,1,13.030000,100,1,13.830000,100,1,12.730000,100,1,14.070000,2,1,12.710000,100,1,14.080000,100,1,12.500000,700,1,14.280000,100,1,12.460000,200,2,14.400000,100,1,12.430000,700,1,14.560000,800,2,12.420000,700,1,14.600000,700,1,12.370000,700,1,14.640000,100,1,ARL,307714769
2025-07-17T15:48:13.525953545Z,2025-07-17T15:48:13.525788139Z,10,2,1108,A,A,2,13.81,100,130,165406,257727301,13.260000,100,1,13.780000,15,1,13.040000,2,1,13.800000,100,1,13.030000,100,1,13.810000,100,1,12.730000,100,1,13.830000,100,1,12.710000,100,1,14.070000,2,1,12.500000,700,1,14.080000,100,1,12.460000,200,2,14.280000,100,1,12.430000,700,1,14.400000,100,1,12.420000,700,1,14.560000,800,2,12.370000,700,1,14.600000,700,1,ARL,307715101
2025-07-17T15:48:13.532608874Z,2025-07-17T15:48:13.532443045Z,10,2,1108,C,A,3,13.83,100,130,165829,257727457,13.260000,100,1,13.780000,15,1,13.040000,2,1,13.800000,100,1,13.030000,100,1,13.810000,100,1,12.730000,100,1,14.070000,2,1,12.710000,100,1,14.080000,100,1,12.500000,700,1,14.280000,100,1,12.460000,200,2,14.400000,100,1,12.430000,700,1,14.560000,800,2,12.420000,700,1,14.600000,700,1,12.370000,700,1,14.640000,100,1,ARL,307567929
2025-07-17T15:48:15.568544154Z,2025-07-17T15:48:15.568378275Z,10,2,1108,C,A,1,13.80,100,0,165879,257757458,13.260000,100,1,13.780000,15,1,13.040000,2,1,13.810000,100,1,13.030000,100,1,14.070000,2,1,12.730000,100,1,14.080000,100,1,12.710000,100,1,14.280000,100,1,12.500000,700,1,14.400000,100,1,12.460000,200,2,14.560000,800,2,12.430000,700,1,14.600000,700,1,12.420000,700,1,14.640000,100,1,12.370000,700,1,14.680000,1400,2,ARL,306784133
2025-07-17T15:48:15.568544154Z,2025-07-17T15:48:15.568378275Z,10,2,1108,A,A,1,13.79,100,130,165879,257757458,13.260000,100,1,13.780000,15,1,13.040000,2,1,13.790000,100,1,13.030000,100,1,13.810000,100,1,12.730000,100,1,14.070000,2,1,12.710000,100,1,14.080000,100,1,12.500000,700,1,14.280000,100,1,12.460000,200,2,14.400000,100,1,12.430000,700,1,14.560000,800,2,12.420000,700,1,14.600000,700,1,12.370000,700,1,14.640000,100,1,ARL,307753241
2025-07-17T15:48:24.009355346Z,2025-07-17T15:48:24.009190157Z,10,2,1108,A,A,0,13.75,15,130,165189,257928318,13.260000,100,1,13.750000,15,1,13.040000,2,1,13.780000,15,1,13.030000,100,1,13.790000,100,1,12.730000,100,1,13.810000,100,1,12.710000,100,1,14.070000,2,1,12.500000,700,1,14.080000,100,1,12.460000,200,2,14.280000,100,1,12.430000,700,1,14.400000,100,1,12.420000,700,1,14.560000,800,2,12.370000,700,1,14.600000,700,1,ARL,307964605
2025-07-17T15:48:24.009522633Z,2025-07-17T15:48:24.009357442Z,10,2,1108,A,A,2,13.79,100,130,165191,257928319,13.260000,100,1,13.750000,15,1,13.040000,2,1,13.780000,15,1,13.030000,100,1,13.790000,200,2,12.730000,100,1,13.810000,100,1,12.710000,100,1,14.070000,2,1,12.500000,700,1,14.080000,100,1,12.460000,200,2,14.280000,100,1,12.430000,700,1,14.400000,100,1,12.420000,700,1,14.560000,800,2,12.370000,700,1,14.600000,700,1,ARL,307964609
2025-07-17T15:48:24.009944381Z,2025-07-17T15:48:24.009778967Z,10,2,1108,C,A,2,13.79,100,0,165414,257928325,13.260000,100,1,13.750000,15,1,13.040000,2,1,13.780000,15,1,13.030000,100,1,13.790000,100,1,12.730000,100,1,13.810000,100,1,12.710000,100,1,14.070000,2,1,12.500000,700,1,14.080000,100,1,12.460000,200,2,14.280000,100,1,12.430000,700,1,14.400000,100,1,12.420000,700,1,14.560000,800,2,12.370000,700,1,14.600000,700,1,ARL,307753241
2025-07-17T15:48:24.009944381Z,2025-07-17T15:48:24.009778967Z,10,2,1108,A,A,1,13.76,100,130,165414,257928325,13.260000,100,1,13.750000,15,1,13.040000,2,1,13.760000,100,1,13.030000,100,1,13.780000,15,1,12.730000,100,1,13.790000,100,1,12.710000,100,1,13.810000,100,1,12.500000,700,1,14.070000,2,1,12.460000,200,2,14.080000,100,1,12.430000,700,1,14.280000,100,1,12.420000,700,1,14.400000,100,1,12.370000,700,1,14.560000,800,2,ARL,307964621
2025-07-17T15:48:24.009974166Z,2025-07-17T15:48:24.009808793Z,10,2,1108,C,A,4,13.81,100,130,165373,257928326,13.260000,100,1,13.750000,15,1,13.040000,2,1,13.760000,100,1,13.030000,100,1,13.780000,15,1,12.730000,100,1,13.790000,100,1,12.710000,100,1,14.070000,2,1,12.500000,700,1,14.080000,100,1,12.460000,200,2,14.280000,100,1,12.430000,700,1,14.400000,100,1,12.420000,700,1,14.560000,800,2,12.370000,700,1,14.600000,700,1,ARL,307715101
2025-07-17T15:48:24.010555416Z,2025-07-17T15:48:24.010390029Z,10,2,1108,C,A,13,14.77,100,0,165387,257928333,13.260000,100,1,13.750000,15,1,13.040000,2,1,13.760000,100,1,13.030000,100,1,13.780000,15,1,12.730000,100,1,13.790000,100,1,12.710000,100,1,14.070000,2,1,12.500000,700,1,14.080000,100,1,12.460000,200,2,14.280000,100,1,12.430000,700,1,14.400000,100,1,12.420000,700,1,14.560000,800,2,12.370000,700,1,14.600000,700,1,ARL,306519409
2025-07-17T15:48:24.010555416Z,2025-07-17T15:48:24.010390029Z,10,2,1108,A,A,-1,14.65,100,130,165387,257928333,13.260000,100,1,13.750000,15,1,13.040000,2,1,13.760000,100,1,13.030000,100,1,13.780000,15,1,12.730000,100,1,13.790000,100,1,12.710000,100,1,14.070000,2,1,12.500000,700,1,14.080000,100,1,12.460000,200,2,14.280000,100,1,12.430000,700,1,14.400000,100,1,12.420000,700,1,14.560000,800,2,12.370000,700,1,14.600000,700,1,ARL,307964661
2025-07-17T15:48:24.010677522Z,2025-07-17T15:48:24.010512050Z,10,2,1108,C,A,15,14.87,100,0,165472,257928340,13.260000,100,1,13.750000,15,1,13.040000,2,1,13.760000,100,1,13.030000,100,1,13.780000,15,1,12.730000,100,1,13.790000,100,1,12.710000,100,1,14.070000,2,1,12.500000,700,1,14.080000,100,1,12.460000,200,2,14.280000,100,1,12.430000,700,1,14.400000,100,1,12.420000,700,1,14.560000,800,2,12.370000,700,1,14.600000,700,1,ARL,306784201
2025-07-17T15:48:24.010677522Z,2025-07-17T15:48:24.010512050Z,10,2,1108,A,A,-1,14.83,100,130,165472,257928340,13.260000,100,1,13.750000,15,1,13.040000,2,1,13.760000,100,1,13.030000,100,1,13.780000,15,1,12.730000,100,1,13.790000,100,1,12.710000,100,1,14.070000,2,1,12.500000,700,1,14.080000,100,1,12.460000,200,2,14.280000,100,1,12.430000,700,1,14.400000,100,1,12.420000,700,1,14.560000,800,2,12.370000,700,1,14.600000,700,1,ARL,307964665
2025-07-17T15:48:42.009954046Z,2025-07-17T15:48:42.009788565Z,10,2,1108,C,A,2,13.78,15,130,165481,258199397,13.260000,100,1,13.750000,15,1,13.040000,2,1,13.760000,100,1,13.030000,100,1,13.790000,100,1,12.730000,100,1,14.070000,2,1,12.710000,100,1,14.080000,100,1,12.500000,700,1,14.280000,100,1,12.460000,200,2,14.400000,100,1,12.430000,700,1,14.560000,800,2,12.420000,700,1,14.600000,700,1,12.370000,700,1,14.640000,100,1,ARL,307714769
2025-07-17T15:48:42.011846392Z,2025-07-17T15:48:42.011680742Z,10,2,1108,C,A,12,14.75,100,0,165650,258199535,13.260000,100,1,13.750000,15,1,13.040000,2,1,13.760000,100,1,13.030000,100,1,13.790000,100,1,12.730000,100,1,14.070000,2,1,12.710000,100,1,14.080000,100,1,12.500000,700,1,14.280000,100,1,12.460000,200,2,14.400000,100,1,12.430000,700,1,14.560000,800,2,12.420000,700,1,14.600000,700,1,12.370000,700,1,14.640000,100,1,ARL,306519741
2025-07-17T15:48:42.011846392Z,2025-07-17T15:48:42.011680742Z,10,2,1108,A,A,9,14.64,100,130,165650,258199535,13.260000,100,1,13.750000,15,1,13.040000,2,1,13.760000,100,1,13.030000,100,1,13.790000,100,1,12.730000,100,1,14.070000,2,1,12.710000,100,1,14.080000,100,1,12.500000,700,1,14.280000,100,1,12.460000,200,2,14.400000,100,1,12.430000,700,1,14.560000,800,2,12.420000,700,1,14.600000,700,1,12.370000,700,1,14.640000,200,2,ARL,308296381
2025-07-17T15:48:42.016761374Z,2025-07-17T15:48:42.016595806Z,10,2,1108,A,A,2,13.77,100,130,165568,258199787,13.260000,100,1,13.750000,15,1,13.040000,2,1,13.760000,100,1,13.030000,100,1,13.770000,100,1,12.730000,100,1,13.790000,100,1,12.710000,100,1,14.070000,2,1,12.500000,700,1,14.080000,100,1,12.460000,200,2,14.280000,100,1,12.430000,700,1,14.400000,100,1,12.420000,700,1,14.560000,800,2,12.370000,700,1,14.600000,700,1,ARL,308296741
2025-07-17T15:48:42.023432407Z,2025-07-17T15:48:42.023266760Z,10,2,1108,C,A,3,13.79,100,130,165647,258199990,13.260000,100,1,13.750000,15,1,13.040000,2,1,13.760000,100,1,13.030000,100,1,13.770000,100,1,12.730000,100,1,14.070000,2,1,12.710000,100,1,14.080000,100,1,12.500000,700,1,14.280000,100,1,12.460000,200,2,14.400000,100,1,12.430000,700,1,14.560000,800,2,12.420000,700,1,14.600000,700,1,12.370000,700,1,14.640000,200,2,ARL,307964609
2025-07-17T15:48:46.750088490Z,2025-07-17T15:48:46.749922127Z,10,2,1108,A,A,0,13.73,15,128,166363,258260871,13.260000,100,1,13.730000,15,1,13.040000,2,1,13.750000,15,1,13.030000,100,1,13.760000,100,1,12.730000,100,1,13.770000,100,1,12.710000,100,1,14.070000,2,1,12.500000,700,1,14.080000,100,1,12.460000,200,2,14.280000,100,1,12.430000,700,1,14.400000,100,1,12.420000,700,1,14.560000,800,2,12.370000,700,1,14.600000,700,1,ARL,308374537
2025-07-17T15:48:46.758551033Z,2025-07-17T15:48:46.758385367Z,10,2,1108,C,A,2,13.76,100,0,165666,258261154,13.260000,100,1,13.730000,15,1,13.040000,2,1,13.750000,15,1,13.030000,100,1,13.770000,100,1,12.730000,100,1,14.070000,2,1,12.710000,100,1,14.080000,100,1,12.500000,700,1,14.280000,100,1,12.460000,200,2,14.400000,100,1,12.430000,700,1,14.560000,800,2,12.420000,700,1,14.600000,700,1,12.370000,700,1,14.640000,200,2,ARL,307964621
2025-07-17T15:48:46.758551033Z,2025-07-17T15:48:46.758385367Z,10,2,1108,A,A,1,13.74,100,130,165666,258261154,13.260000,100,1,13.730000,15,1,13.040000,2,1,13.740000,100,1,13.030000,100,1,13.750000,15,1,12.730000,100,1,13.770000,100,1,12.710000,100,1,14.070000,2,1,12.500000,700,1,14.080000,100,1,12.460000,200,2,14.280000,100,1,12.430000,700,1,14.400000,100,1,12.420000,700,1,14.560000,800,2,12.370000,700,1,14.600000,700,1,ARL,308374881
2025-07-17T15:48:46.773668988Z,2025-07-17T15:48:46.773503306Z,10,2,1108,C,A,5,14.08,100,130,165682,258261538,13.260000,100,1,13.730000,15,1,13.040000,2,1,13.740000,100,1,13.030000,100,1,13.750000,15,1,12.730000,100,1,13.770000,100,1,12.710000,100,1,14.070000,2,1,12.500000,700,1,14.280000,100,1,12.460000,200,2,14.400000,100,1,12.430000,700,1,14.560000,800,2,12.420000,700,1,14.600000,700,1,12.370000,700,1,14.640000,200,2,ARL,306784853
2025-07-17T15:48:46.773720726Z,2025-07-17T15:48:46.773555566Z,10,2,1108,A,A,4,14.01,100,130,165160,258261539,13.260000,100,1,13.730000,15,1,13.040000,2,1,13.740000,100,1,13.030000,100,1,13.750000,15,1,12.730000,100,1,13.770000,100,1,12.710000,100,1,14.010000,100,1,12.500000,700,1,14.070000,2,1,12.460000,200,2,14.280000,100,1,12.430000,700,1,14.400000,100,1,12.420000,700,1,14.560000,800,2,12.370000,700,1,14.600000,700,1,ARL,308375185
2025-07-17T15:49:02.010494480Z,2025-07-17T15:49:02.010329052Z,10,2,1108,A,A,2,13.75,100,130,165428,258502869,13.260000,100,1,13.730000,15,1,13.040000,2,1,13.740000,100,1,13.030000,100,1,13.750000,115,2,12.730000,100,1,13.770000,100,1,12.710000,100,1,14.010000,100,1,12.500000,700,1,14.070000,2,1,12.460000,200,2,14.280000,100,1,12.430000,700,1,14.400000,100,1,12.420000,700,1,14.560000,800,2,12.370000,700,1,14.600000,700,1,ARL,308705489
2025-07-17T15:49:02.019989567Z,2025-07-17T15:49:02.019824230Z,10,2,1108,C,A,3,13.77,100,130,165337,258502929,13.260000,100,1,13.730000,15,1,13.040000,2,1,13.740000,100,1,13.030000,100,1,13.750000,115,2,12.730000,100,1,14.010000,100,1,12.710000,100,1,14.070000,2,1,12.500000,700,1,14.280000,100,1,12.460000,200,2,14.400000,100,1,12.430000,700,1,14.560000,800,2,12.420000,700,1,14.600000,700,1,12.370000,700,1,14.640000,200,2,ARL,308296741
2025-07-17T15:49:03.406005590Z,2025-07-17T15:49:03.405840358Z,10,2,1108,C,A,2,13.75,15,130,165232,258527308,13.260000,100,1,13.730000,15,1,13.040000,2,1,13.740000,100,1,13.030000,100,1,13.750000,100,1,12.730000,100,1,14.010000,100,1,12.710000,100,1,14.070000,2,1,12.500000,700,1,14.280000,100,1,12.460000,200,2,14.400000,100,1,12.430000,700,1,14.560000,800,2,12.420000,700,1,14.600000,700,1,12.370000,700,1,14.640000,200,2,ARL,307964605
2025-07-17T15:49:04.713997925Z,2025-07-17T15:49:04.713831675Z,10,2,1108,A,A,0,13.71,15,128,166250,258547335,13.260000,100,1,13.710000,15,1,13.040000,2,1,13.730000,15,1,13.030000,100,1,13.740000,100,1,12.730000,100,1,13.750000,100,1,12.710000,100,1,14.010000,100,1,12.500000,700,1,14.070000,2,1,12.460000,200,2,14.280000,100,1,12.430000,700,1,14.400000,100,1,12.420000,700,1,14.560000,800,2,12.370000,700,1,14.600000,700,1,ARL,308763065
2025-07-17T15:49:06.013111941Z,2025-07-17T15:49:06.012946379Z,10,2,1108,A,A,1,13.73,100,130,165562,258567259,13.260000,100,1,13.710000,15,1,13.040000,2,1,13.730000,115,2,13.030000,100,1,13.740000,100,1,12.730000,100,1,13.750000,100,1,12.710000,100,1,14.010000,100,1,12.500000,700,1,14.070000,2,1,12.460000,200,2,14.280000,100,1,12.430000,700,1,14.400000,100,1,12.420000,700,1,14.560000,800,2,12.370000,700,1,14.600000,700,1,ARL,308786185
2025-07-17T15:49:06.023292147Z,2025-07-17T15:49:06.023126600Z,10,2,1108,C,A,3,13.75,100,130,165547,258567405,13.260000,100,1,13.710000,15,1,13.040000,2,1,13.730000,115,2,13.030000,100,1,13.740000,100,1,12.730000,100,1,14.010000,100,1,12.710000,100,1,14.070000,2,1,12.500000,700,1,14.280000,100,1,12.460000,200,2,14.400000,100,1,12.430000,700,1,14.560000,800,2,12.420000,700,1,14.600000,700,1,12.370000,700,1,14.640000,200,2,ARL,308705489
2025-07-17T15:49:06.344356890Z,2025-07-17T15:49:06.344191321Z,10,2,1108,C,A,2,13.74,100,0,165569,258574949,13.260000,100,1,13.710000,15,1,13.040000,2,1,13.730000,115,2,13.030000,100,1,14.010000,100,1,12.730000,100,1,14.070000,2,1,12.710000,100,1,14.280000,100,1,12.500000,700,1,14.400000,100,1,12.460000,200,2,14.560000,800,2,12.430000,700,1,14.600000,700,1,12.420000,700,1,14.640000,200,2,12.370000,700,1,14.650000,100,1,ARL,308374881
2025-07-17T15:49:06.344356890Z,2025-07-17T15:49:06.344191321Z,10,2,1108,A,A,1,13.72,100,130,165569,258574949,13.260000,100,1,13.710000,15,1,13.040000,2,1,13.720000,100,1,13.030000,100,1,13.730000,115,2,12.730000,100,1,14.010000,100,1,12.710000,100,1,14.070000,2,1,12.500000,700,1,14.280000,100,1,12.460000,200,2,14.400000,100,1,12.430000,700,1,14.560000,800,2,12.420000,700,1,14.600000,700,1,12.370000,700,1,14.640000,200,2,ARL,308797069
2025-07-17T15:49:06.345104491Z,2025-07-17T15:49:06.344938975Z,10,2,1108,C,A,13,14.83,100,0,165516,258575013,13.260000,100,1,13.710000,15,1,13.040000,2,1,13.720000,100,1,13.030000,100,1,13.730000,115,2,12.730000,100,1,14.010000,100,1,12.710000,100,1,14.070000,2,1,12.500000,700,1,14.280000,100,1,12.460000,200,2,14.400000,100,1,12.430000,700,1,14.560000,800,2,12.420000,700,1,14.600000,700,1,12.370000,700,1,14.640000,200,2,ARL,307964665
2025-07-17T15:49:06.345104491Z,2025-07-17T15:49:06.344938975Z,10,2,1108,A,A,-1,14.78,100,130,165516,258575013,13.260000,100,1,13.710000,15,1,13.040000,2,1,13.720000,100,1,13.030000,100,1,13.730000,115,2,12.730000,100,1,14.010000,100,1,12.710000,100,1,14.070000,2,1,12.500000,700,1,14.280000,100,1,12.460000,200,2,14.400000,100,1,12.430000,700,1,14.560000,800,2,12.420000,700,1,14.600000,700,1,12.370000,700,1,14.640000,200,2,ARL,308797245
2025-07-17T15:49:06.362945410Z,2025-07-17T15:49:06.362779870Z,10,2,1108,C,A,21,17.58,100,0,165540,258575963,13.260000,100,1,13.710000,15,1,13.040000,2,1,13.720000,100,1,13.030000,100,1,13.730000,115,2,12.730000,100,1,14.010000,100,1,12.710000,100,1,14.070000,2,1,12.500000,700,1,14.280000,100,1,12.460000,200,2,14.400000,100,1,12.430000,700,1,14.560000,800,2,12.420000,700,1,14.600000,700,1,12.370000,700,1,14.640000,200,2,ARL,306652017
2025-07-17T15:49:06.362945410Z,2025-07-17T15:49:06.362779870Z,10,2,1108,A,A,-1,17.43,100,130,165540,258575963,13.260000,100,1,13.710000,15,1,13.040000,2,1,13.720000,100,1,13.030000,100,1,13.730000,115,2,12.730000,100,1,14.010000,100,1,12.710000,100,1,14.070000,2,1,12.500000,700,1,14.280000,100,1,12.460000,200,2,14.400000,100,1,12.430000,700,1,14.560000,800,2,12.420000,700,1,14.600000,700,1,12.370000,700,1,14.640000,200,2,ARL,308799373
2025-07-17T15:49:10.459317885Z,2025-07-17T15:49:10.459152457Z,10,2,1108,C,A,2,13.73,15,130,165428,258636400,13.260000,100,1,13.710000,15,1,13.040000,2,1,13.720000,100,1,13.030000,100,1,13.730000,100,1,12.730000,100,1,14.010000,100,1,12.710000,100,1,14.070000,2,1,12.500000,700,1,14.280000,100,1,12.460000,200,2,14.400000,100,1,12.430000,700,1,14.560000,800,2,12.420000,700,1,14.600000,700,1,12.370000,700,1,14.640000,200,2,ARL,308374537
2025-07-17T15:49:11.460597600Z,2025-07-17T15:49:11.460432218Z,10,2,1108,A,A,0,13.69,15,130,165382,258650544,13.260000,100,1,13.690000,15,1,13.040000,2,1,13.710000,15,1,13.030000,100,1,13.720000,100,1,12.730000,100,1,13.730000,100,1,12.710000,100,1,14.010000,100,1,12.500000,700,1,14.070000,2,1,12.460000,200,2,14.280000,100,1,12.430000,700,1,14.400000,100,1,12.420000,700,1,14.560000,800,2,12.370000,700,1,14.600000,700,1,ARL,308893737
2025-07-17T15:49:11.891643099Z,2025-07-17T15:49:11.891477604Z,10,2,1108,C,A,2,13.72,100,0,165495,258658721,13.260000,100,1,13.690000,15,1,13.040000,2,1,13.710000,15,1,13.030000,100,1,13.730000,100,1,12.730000,100,1,14.010000,100,1,12.710000,100,1,14.070000,2,1,12.500000,700,1,14.280000,100,1,12.460000,200,2,14.400000,100,1,12.430000,700,1,14.560000,800,2,12.420000,700,1,14.600000,700,1,12.370000,700,1,14.640000,200,2,ARL,308797069
2025-07-17T15:49:11.891643099Z,2025-07-17T15:49:11.891477604Z,10,2,1108,A,A,1,13.70,100,130,165495,258658721,13.260000,100,1,13.690000,15,1,13.040000,2,1,13.700000,100,1,13.030000,100,1,13.710000,15,1,12.730000,100,1,13.730000,100,1,12.710000,100,1,14.010000,100,1,12.500000,700,1,14.070000,2,1,12.460000,200,2,14.280000,100,1,12.430000,700,1,14.400000,100,1,12.420000,700,1,14.560000,800,2,12.370000,700,1,14.600000,700,1,ARL,308901793
2025-07-17T15:49:11.893989071Z,2025-07-17T15:49:11.893823458Z,10,2,1108,C,A,14,14.81,100,0,165613,258658835,13.260000,100,1,13.690000,15,1,13.040000,2,1,13.700000,100,1,13.030000,100,1,13.710000,15,1,12.730000,100,1,13.730000,100,1,12.710000,100,1,14.010000,100,1,12.500000,700,1,14.070000,2,1,12.460000,200,2,14.280000,100,1,12.430000,700,1,14.400000,100,1,12.420000,700,1,14.560000,800,2,12.370000,700,1,14.600000,700,1,ARL,306649913
2025-07-17T15:49:11.893989071Z,2025-07-17T15:49:11.893823458Z,10,2,1108,A,A,-1,14.66,100,130,165613,258658835,13.260000,100,1,13.690000,15,1,13.040000,2,1,13.700000,100,1,13.030000,100,1,13.710000,15,1,12.730000,100,1,13.730000,100,1,12.710000,100,1,14.010000,100,1,12.500000,700,1,14.070000,2,1,12.460000,200,2,14.280000,100,1,12.430000,700,1,14.400000,100,1,12.420000,700,1,14.560000,800,2,12.370000,700,1,14.600000,700,1,ARL,308901981
2025-07-17T15:49:11.904231149Z,2025-07-17T15:49:11.904065674Z,10,2,1108,C,A,20,15.92,100,0,165475,258659039,13.260000,100,1,13.690000,15,1,13.040000,2,1,13.700000,100,1,13.030000,100,1,13.710000,15,1,12.730000,100,1,13.730000,100,1,12.710000,100,1,14.010000,100,1,12.500000,700,1,14.070000,2,1,12.460000,200,2,14.280000,100,1,12.430000,700,1,14.400000,100,1,12.420000,700,1,14.560000,800,2,12.370000,700,1,14.600000,700,1,ARL,306652001
2025-07-17T15:49:11.904231149Z,2025-07-17T15:49:11.904065674Z,10,2,1108,A,A,-1,15.76,100,130,165475,258659039,13.260000,100,1,13.690000,15,1,13.040000,2,1,13.700000,100,1,13.030000,100,1,13.710000,15,1,12.730000,100,1,13.730000,100,1,12.710000,100,1,14.010000,100,1,12.500000,700,1,14.070000,2,1,12.460000,200,2,14.280000,100,1,12.430000,700,1,14.400000,100,1,12.420000,700,1,14.560000,800,2,12.370000,700,1,14.600000,700,1,ARL,308902229
2025-07-17T15:49:11.935521687Z,2025-07-17T15:49:11.935356090Z,10,2,1108,C,A,15,14.81,100,0,165597,258659320,13.260000,100,1,13.690000,15,1,13.040000,2,1,13.700000,100,1,13.030000,100,1,13.710000,15,1,12.730000,100,1,13.730000,100,1,12.710000,100,1,14.010000,100,1,12.500000,700,1,14.070000,2,1,12.460000,200,2,14.280000,100,1,12.430000,700,1,14.400000,100,1,12.420000,700,1,14.560000,800,2,12.370000,700,1,14.600000,700,1,ARL,306653713
2025-07-17T15:49:11.935521687Z,2025-07-17T15:49:11.935356090Z,10,2,1108,A,A,-1,14.66,100,130,165597,258659320,13.260000,100,1,13.690000,15,1,13.040000,2,1,13.700000,100,1,13.030000,100,1,13.710000,15,1,12.730000,100,1,13.730000,100,1,12.710000,100,1,14.010000,100,1,12.500000,700,1,14.070000,2,1,12.460000,200,2,14.280000,100,1,12.430000,700,1,14.400000,100,1,12.420000,700,1,14.560000,800,2,12.370000,700,1,14.600000,700,1,ARL,308903001
2025-07-17T15:49:11.948701049Z,2025-07-17T15:49:11.948535655Z,10,2,1108,C,A,10,14.64,100,130,165394,258659496,13.260000,100,1,13.690000,15,1,13.040000,2,1,13.700000,100,1,13.030000,100,1,13.710000,15,1,12.730000,100,1,13.730000,100,1,12.710000,100,1,14.010000,100,1,12.500000,700,1,14.070000,2,1,12.460000,200,2,14.280000,100,1,12.430000,700,1,14.400000,100,1,12.420000,700,1,14.560000,800,2,12.370000,700,1,14.600000,700,1,ARL,306647521
2025-07-17T15:49:11.948829112Z,2025-07-17T15:49:11.948663655Z,10,2,1108,A,A,8,14.50,100,130,165457,258659499,13.260000,100,1,13.690000,15,1,13.040000,2,1,13.700000,100,1,13.030000,100,1,13.710000,15,1,12.730000,100,1,13.730000,100,1,12.710000,100,1,14.010000,100,1,12.500000,700,1,14.070000,2,1,12.460000,200,2,14.280000,100,1,12.430000,700,1,14.400000,100,1,12.420000,700,1,14.500000,100,1,12.370000,700,1,14.560000,800,2,ARL,308903349
2025-07-17T15:49:12.221221367Z,2025-07-17T15:49:12.221056085Z,10,2,1108,A,A,2,13.71,100,130,165282,258663292,13.260000,100,1,13.690000,15,1,13.040000,2,1,13.700000,100,1,13.030000,100,1,13.710000,115,2,12.730000,100,1,13.730000,100,1,12.710000,100,1,14.010000,100,1,12.500000,700,1,14.070000,2,1,12.460000,200,2,14.280000,100,1,12.430000,700,1,14.400000,100,1,12.420000,700,1,14.500000,100,1,12.370000,700,1,14.560000,800,2,ARL,308909249
2025-07-17T15:49:12.227986905Z,2025-07-17T15:49:12.227821500Z,10,2,1108,C,A,3,13.73,100,130,165405,258663378,13.260000,100,1,13.690000,15,1,13.040000,2,1,13.700000,100,1,13.030000,100,1,13.710000,115,2,12.730000,100,1,14.010000,100,1,12.710000,100,1,14.070000,2,1,12.500000,700,1,14.280000,100,1,12.460000,200,2,14.400000,100,1,12.430000,700,1,14.500000,100,1,12.420000,700,1,14.560000,800,2,12.370000,700,1,14.600000,700,1,ARL,308786185
2025-07-17T15:49:14.463229121Z,2025-07-17T15:49:14.463063539Z,10,2,1108,C,A,2,13.71,15,130,165582,258702625,13.260000,100,1,13.690000,15,1,13.040000,2,1,13.700000,100,1,13.030000,100,1,13.710000,100,1,12.730000,100,1,14.010000,100,1,12.710000,100,1,14.070000,2,1,12.500000,700,1,14.280000,100,1,12.460000,200,2,14.400000,100,1,12.430000,700,1,14.500000,100,1,12.420000,700,1,14.560000,800,2,12.370000,700,1,14.600000,700,1,ARL,308763065
2025-07-17T15:49:15.466365122Z,2025-07-17T15:49:15.466199239Z,10,2,1108,A,A,0,13.67,15,130,165883,258716863,13.260000,100,1,13.670000,15,1,13.040000,2,1,13.690000,15,1,13.030000,100,1,13.700000,100,1,12.730000,100,1,13.710000,100,1,12.710000,100,1,14.010000,100,1,12.500000,700,1,14.070000,2,1,12.460000,200,2,14.280000,100,1,12.430000,700,1,14.400000,100,1,12.420000,700,1,14.500000,100,1,12.370000,700,1,14.560000,800,2,ARL,308980305
2025-07-17T15:49:16.351024588Z,2025-07-17T15:49:16.350859152Z,10,2,1108,C,A,2,13.70,100,0,165436,258727929,13.260000,100,1,13.670000,15,1,13.040000,2,1,13.690000,15,1,13.030000,100,1,13.710000,100,1,12.730000,100,1,14.010000,100,1,12.710000,100,1,14.070000,2,1,12.500000,700,1,14.280000,100,1,12.460000,200,2,14.400000,100,1,12.430000,700,1,14.500000,100,1,12.420000,700,1,14.560000,800,2,12.370000,700,1,14.600000,700,1,ARL,308901793
2025-07-17T15:49:16.351024588Z,2025-07-17T15:49:16.350859152Z,10,2,1108,A,A,1,13.68,100,130,165436,258727929,13.260000,100,1,13.670000,15,1,13.040000,2,1,13.680000,100,1,13.030000,100,1,13.690000,15,1,12.730000,100,1,13.710000,100,1,12.710000,100,1,14.010000,100,1,12.500000,700,1,14.070000,2,1,12.460000,200,2,14.280000,100,1,12.430000,700,1,14.400000,100,1,12.420000,700,1,14.500000,100,1,12.370000,700,1,14.560000,800,2,ARL,308998225
2025-07-17T15:49:16.351759618Z,2025-07-17T15:49:16.351594042Z,10,2,1108,C,A,15,14.78,100,0,165576,258727956,13.260000,100,1,13.670000,15,1,13.040000,2,1,13.680000,100,1,13.030000,100,1,13.690000,15,1,12.730000,100,1,13.710000,100,1,12.710000,100,1,14.010000,100,1,12.500000,700,1,14.070000,2,1,12.460000,200,2,14.280000,100,1,12.430000,700,1,14.400000,100,1,12.420000,700,1,14.500000,100,1,12.370000,700,1,14.560000,800,2,ARL,308797245
2025-07-17T15:49:16.351759618Z,2025-07-17T15:49:16.351594042Z,10,2,1108,A,A,-1,14.74,100,130,165576,258727956,13.260000,100,1,13.670000,15,1,13.040000,2,1,13.680000,100,1,13.030000,100,1,13.690000,15,1,12.730000,100,1,13.710000,100,1,12.710000,100,1,14.010000,100,1,12.500000,700,1,14.070000,2,1,12.460000,200,2,14.280000,100,1,12.430000,700,1,14.400000,100,1,12.420000,700,1,14.500000,100,1,12.370000,700,1,14.560000,800,2,ARL,308998341
2025-07-17T15:49:16.494111490Z,2025-07-17T15:49:16.493946243Z,10,2,1108,A,A,2,13.69,100,130,165247,258729266,13.260000,100,1,13.670000,15,1,13.040000,2,1,13.680000,100,1,13.030000,100,1,13.690000,115,2,12.730000,100,1,13.710000,100,1,12.710000,100,1,14.010000,100,1,12.500000,700,1,14.070000,2,1,12.460000,200,2,14.280000,100,1,12.430000,700,1,14.400000,100,1,12.420000,700,1,14.500000,100,1,12.370000,700,1,14.560000,800,2,ARL,309001525
2025-07-17T15:49:16.557924863Z,2025-07-17T15:49:16.557759633Z,10,2,1108,C,A,3,13.71,100,130,165230,258730034,13.260000,100,1,13.670000,15,1,13.040000,2,1,13.680000,100,1,13.030000,100,1,13.690000,115,2,12.730000,100,1,14.010000,100,1,12.710000,100,1,14.070000,2,1,12.500000,700,1,14.280000,100,1,12.460000,200,2,14.400000,100,1,12.430000,700,1,14.500000,100,1,12.420000,700,1,14.560000,800,2,12.370000,700,1,14.600000,700,1,ARL,308909249
2025-07-17T15:49:21.186150487Z,2025-07-17T15:49:21.185984774Z,10,2,1108,C,A,4,14.07,2,0,165713,258786552,13.260000,100,1,13.670000,15,1,13.040000,2,1,13.680000,100,1,13.030000,100,1,13.690000,115,2,12.730000,100,1,14.010000,100,1,12.710000,100,1,14.280000,100,1,12.500000,700,1,14.400000,100,1,12.460000,200,2,14.500000,100,1,12.430000,700,1,14.560000,800,2,12.420000,700,1,14.600000,700,1,12.370000,700,1,14.640000,100,1,ARL,296478973
2025-07-17T15:49:21.186150487Z,2025-07-17T15:49:21.185984774Z,10,2,1108,A,A,3,13.98,2,130,165713,258786552,13.260000,100,1,13.670000,15,1,13.040000,2,1,13.680000,100,1,13.030000,100,1,13.690000,115,2,12.730000,100,1,13.980000,2,1,12.710000,100,1,14.010000,100,1,12.500000,700,1,14.280000,100,1,12.460000,200,2,14.400000,100,1,12.430000,700,1,14.500000,100,1,12.420000,700,1,14.560000,800,2,12.370000,700,1,14.600000,700,1,ARL,309091513
2025-07-17T15:49:24.283152112Z,2025-07-17T15:49:24.282985894Z,10,2,1108,C,A,2,13.69,15,130,166218,258838460,13.260000,100,1,13.670000,15,1,13.040000,2,1,13.680000,100,1,13.030000,100,1,13.690000,100,1,12.730000,100,1,13.980000,2,1,12.710000,100,1,14.010000,100,1,12.500000,700,1,14.280000,100,1,12.460000,200,2,14.400000,100,1,12.430000,700,1,14.500000,100,1,12.420000,700,1,14.560000,800,2,12.370000,700,1,14.600000,700,1,ARL,308893737
2025-07-17T15:49:34.570197134Z,2025-07-17T15:49:34.570031718Z,10,2,1108,C,A,0,13.67,15,130,165416,258980876,13.260000,100,1,13.680000,100,1,13.040000,2,1,13.690000,100,1,13.030000,100,1,13.980000,2,1,12.730000,100,1,14.010000,100,1,12.710000,100,1,14.280000,100,1,12.500000,700,1,14.400000,100,1,12.460000,200,2,14.500000,100,1,12.430000,700,1,14.560000,800,2,12.420000,700,1,14.600000,700,1,12.370000,700,1,14.640000,100,1,ARL,308980305
2025-07-17T15:49:34.591512915Z,2025-07-17T15:49:34.591347169Z,10,2,1108,C,A,1,13.69,100,130,165746,258983321,13.260000,100,1,13.680000,100,1,13.040000,2,1,13.980000,2,1,13.030000,100,1,14.010000,100,1,12.730000,100,1,14.280000,100,1,12.710000,100,1,14.400000,100,1,12.500000,700,1,14.500000,100,1,12.460000,200,2,14.560000,800,2,12.430000,700,1,14.600000,700,1,12.420000,700,1,14.640000,100,1,12.370000,700,1,14.650000,100,1,ARL,309001525
2025-07-17T15:49:38.610017394Z,2025-07-17T15:49:38.609851985Z,10,2,1108,A,A,1,13.72,100,130,165409,259031220,13.260000,100,1,13.680000,100,1,13.040000,2,1,13.720000,100,1,13.030000,100,1,13.980000,2,1,12.730000,100,1,14.010000,100,1,12.710000,100,1,14.280000,100,1,12.500000,700,1,14.400000,100,1,12.460000,200,2,14.500000,100,1,12.430000,700,1,14.560000,800,2,12.420000,700,1,14.600000,700,1,12.370000,700,1,14.640000,100,1,ARL,309410565
2025-07-17T15:49:38.610073334Z,2025-07-17T15:49:38.609907720Z,10,2,1108,C,B,0,13.26,100,130,165614,259031221,13.040000,2,1,13.680000,100,1,13.030000,100,1,13.720000,100,1,12.730000,100,1,13.980000,2,1,12.710000,100,1,14.010000,100,1,12.500000,700,1,14.280000,100,1,12.460000,200,2,14.400000,100,1,12.430000,700,1,14.500000,100,1,12.420000,700,1,14.560000,800,2,12.370000,700,1,14.600000,700,1,12.360000,200,2,14.640000,100,1,ARL,291975017
2025-07-17T15:49:39.068515005Z,2025-07-17T15:49:39.068349660Z,10,2,1108,A,B,2,13.02,100,130,165345,259035032,13.040000,2,1,13.680000,100,1,13.030000,100,1,13.720000,100,1,13.020000,100,1,13.980000,2,1,12.730000,100,1,14.010000,100,1,12.710000,100,1,14.280000,100,1,12.500000,700,1,14.400000,100,1,12.460000,200,2,14.500000,100,1,12.430000,700,1,14.560000,800,2,12.420000,700,1,14.600000,700,1,12.370000,700,1,14.640000,100,1,ARL,309415429
2025-07-17T15:49:44.788414401Z,2025-07-17T15:49:44.788249210Z,10,2,1108,A,A,0,13.67,15,130,165191,259105347,13.040000,2,1,13.670000,15,1,13.030000,100,1,13.680000,100,1,13.020000,100,1,13.720000,100,1,12.730000,100,1,13.980000,2,1,12.710000,100,1,14.010000,100,1,12.500000,700,1,14.280000,100,1,12.460000,200,2,14.400000,100,1,12.430000,700,1,14.500000,100,1,12.420000,700,1,14.560000,800,2,12.370000,700,1,14.600000,700,1,ARL,309524921
2025-07-17T15:49:44.789020757Z,2025-07-17T15:49:44.788855587Z,10,2,1108,A,A,2,13.70,100,130,165170,259105361,13.040000,2,1,13.670000,15,1,13.030000,100,1,13.680000,100,1,13.020000,100,1,13.700000,100,1,12.730000,100,1,13.720000,100,1,12.710000,100,1,13.980000,2,1,12.500000,700,1,14.010000,100,1,12.460000,200,2,14.280000,100,1,12.430000,700,1,14.400000,100,1,12.420000,700,1,14.500000,100,1,12.370000,700,1,14.560000,800,2,ARL,309524933
2025-07-17T15:49:44.789702916Z,2025-07-17T15:49:44.789537536Z,10,2,1108,C,A,3,13.72,100,130,165380,259105380,13.040000,2,1,13.670000,15,1,13.030000,100,1,13.680000,100,1,13.020000,100,1,13.700000,100,1,12.730000,100,1,13.980000,2,1,12.710000,100,1,14.010000,100,1,12.500000,700,1,14.280000,100,1,12.460000,200,2,14.400000,100,1,12.430000,700,1,14.500000,100,1,12.420000,700,1,14.560000,800,2,12.370000,700,1,14.600000,700,1,ARL,309410565
2025-07-17T15:49:54.788658841Z,2025-07-17T15:49:54.788493605Z,10,2,1108,A,A,0,13.65,15,130,165236,259253294,13.040000,2,1,13.650000,15,1,13.030000,100,1,13.670000,15,1,13.020000,100,1,13.680000,100,1,12.730000,100,1,13.700000,100,1,12.710000,100,1,13.980000,2,1,12.500000,700,1,14.010000,100,1,12.460000,200,2,14.280000,100,1,12.430000,700,1,14.400000,100,1,12.420000,700,1,14.500000,100,1,12.370000,700,1,14.560000,800,2,ARL,309707269
2025-07-17T15:49:54.799535744Z,2025-07-17T15:49:54.799370442Z,10,2,1108,A,A,2,13.68,100,130,165302,259253527,13.040000,2,1,13.650000,15,1,13.030000,100,1,13.670000,15,1,13.020000,100,1,13.680000,200,2,12.730000,100,1,13.700000,100,1,12.710000,100,1,13.980000,2,1,12.500000,700,1,14.010000,100,1,12.460000,200,2,14.280000,100,1,12.430000,700,1,14.400000,100,1,12.420000,700,1,14.500000,100,1,12.370000,700,1,14.560000,800,2,ARL,309707413
2025-07-17T15:49:54.820634917Z,2025-07-17T15:49:54.820469390Z,10,2,1108,C,A,3,13.70,100,130,165527,259253732,13.040000,2,1,13.650000,15,1,13.030000,100,1,13.670000,15,1,13.020000,100,1,13.680000,200,2,12.730000,100,1,13.980000,2,1,12.710000,100,1,14.010000,100,1,12.500000,700,1,14.280000,100,1,12.460000,200,2,14.400000,100,1,12.430000,700,1,14.500000,100,1,12.420000,700,1,14.560000,800,2,12.370000,700,1,14.600000,700,1,ARL,309524933
2025-07-17T15:49:59.512104064Z,2025-07-17T15:49:59.511938438Z,10,2,1108,C,A,2,13.68,100,0,165626,259313537,13.040000,2,1,13.650000,15,1,13.030000,100,1,13.670000,15,1,13.020000,100,1,13.680000,100,1,12.730000,100,1,13.980000,2,1,12.710000,100,1,14.010000,100,1,12.500000,700,1,14.280000,100,1,12.460000,200,2,14.400000,100,1,12.430000,700,1,14.500000,100,1,12.420000,700,1,14.560000,800,2,12.370000,700,1,14.600000,700,1,ARL,308998225
2025-07-17T15:49:59.512104064Z,2025-07-17T15:49:59.511938438Z,10,2,1108,A,A,1,13.66,100,130,165626,259313537,13.040000,2,1,13.650000,15,1,13.030000,100,1,13.660000,100,1,13.020000,100,1,13.670000,15,1,12.730000,100,1,13.680000,100,1,12.710000,100,1,13.980000,2,1,12.500000,700,1,14.010000,100,1,12.460000,200,2,14.280000,100,1,12.430000,700,1,14.400000,100,1,12.420000,700,1,14.500000,100,1,12.370000,700,1,14.560000,800,2,ARL,309782481
2025-07-17T15:49:59.534062634Z,2025-07-17T15:49:59.533897369Z,10,2,1108,C,A,5,14.01,100,130,165265,259314032,13.040000,2,1,13.650000,15,1,13.030000,100,1,13.660000,100,1,13.020000,100,1,13.670000,15,1,12.730000,100,1,13.680000,100,1,12.710000,100,1,13.980000,2,1,12.500000,700,1,14.280000,100,1,12.460000,200,2,14.400000,100,1,12.430000,700,1,14.500000,100,1,12.420000,700,1,14.560000,800,2,12.370000,700,1,14.600000,700,1,ARL,308375185
2025-07-17T15:49:59.534115275Z,2025-07-17T15:49:59.533948952Z,10,2,1108,A,A,4,13.93,100,130,166323,259314033,13.040000,2,1,13.650000,15,1,13.030000,100,1,13.660000,100,1,13.020000,100,1,13.670000,15,1,12.730000,100,1,13.680000,100,1,12.710000,100,1,13.930000,100,1,12.500000,700,1,13.980000,2,1,12.460000,200,2,14.280000,100,1,12.430000,700,1,14.400000,100,1,12.420000,700,1,14.500000,100,1,12.370000,700,1,14.560000,800,2,ARL,309782973
2025-07-17T15:50:00.547404972Z,2025-07-17T15:50:00.547239401Z,10,2,1108,C,A,2,13.67,15,130,165571,259349868,13.040000,2,1,13.650000,15,1,13.030000,100,1,13.660000,100,1,13.020000,100,1,13.680000,100,1,12.730000,100,1,13.930000,100,1,12.710000,100,1,13.980000,2,1,12.500000,700,1,14.280000,100,1,12.460000,200,2,14.400000,100,1,12.430000,700,1,14.500000,100,1,12.420000,700,1,14.560000,800,2,12.370000,700,1,14.600000,700,1,ARL,309524921
2025-07-17T15:50:00.555536688Z,2025-07-17T15:50:00.555363249Z,10,2,1108,C,A,11,14.65,100,0,173439,259353226,13.040000,2,1,13.650000,15,1,13.030000,100,1,13.660000,100,1,13.020000,100,1,13.680000,100,1,12.730000,100,1,13.930000,100,1,12.710000,100,1,13.980000,2,1,12.500000,700,1,14.280000,100,1,12.460000,200,2,14.400000,100,1,12.430000,700,1,14.500000,100,1,12.420000,700,1,14.560000,800,2,12.370000,700,1,14.600000,700,1,ARL,307964661
2025-07-17T15:50:00.555536688Z,2025-07-17T15:50:00.555363249Z,10,2,1108,A,A,8,14.54,100,128,173439,259353226,13.040000,2,1,13.650000,15,1,13.030000,100,1,13.660000,100,1,13.020000,100,1,13.680000,100,1,12.730000,100,1,13.930000,100,1,12.710000,100,1,13.980000,2,1,12.500000,700,1,14.280000,100,1,12.460000,200,2,14.400000,100,1,12.430000,700,1,14.500000,100,1,12.420000,700,1,14.540000,100,1,12.370000,700,1,14.560000,800,2,ARL,309823025
2025-07-17T15:50:03.412422880Z,2025-07-17T15:50:03.412257475Z,10,2,1108,A,A,0,13.63,15,130,165405,259413272,13.040000,2,1,13.630000,15,1,13.030000,100,1,13.650000,15,1,13.020000,100,1,13.660000,100,1,12.730000,100,1,13.680000,100,1,12.710000,100,1,13.930000,100,1,12.500000,700,1,13.980000,2,1,12.460000,200,2,14.280000,100,1,12.430000,700,1,14.400000,100,1,12.420000,700,1,14.500000,100,1,12.370000,700,1,14.540000,100,1,ARL,309899025
2025-07-17T15:50:03.415527372Z,2025-07-17T15:50:03.415361851Z,10,2,1108,C,A,12,14.64,100,0,165521,259413427,13.040000,2,1,13.630000,15,1,13.030000,100,1,13.650000,15,1,13.020000,100,1,13.660000,100,1,12.730000,100,1,13.680000,100,1,12.710000,100,1,13.930000,100,1,12.500000,700,1,13.980000,2,1,12.460000,200,2,14.280000,100,1,12.430000,700,1,14.400000,100,1,12.420000,700,1,14.500000,100,1,12.370000,700,1,14.540000,100,1,ARL,308296381
2025-07-17T15:50:03.415527372Z,2025-07-17T15:50:03.415361851Z,10,2,1108,A,A,9,14.53,100,130,165521,259413427,13.040000,2,1,13.630000,15,1,13.030000,100,1,13.650000,15,1,13.020000,100,1,13.660000,100,1,12.730000,100,1,13.680000,100,1,12.710000,100,1,13.930000,100,1,12.500000,700,1,13.980000,2,1,12.460000,200,2,14.280000,100,1,12.430000,700,1,14.400000,100,1,12.420000,700,1,14.500000,100,1,12.370000,700,1,14.530000,100,1,ARL,309899141
2025-07-17T15:50:03.824292152Z,2025-07-17T15:50:03.824126753Z,10,2,1108,C,A,2,13.66,100,0,165399,259418661,13.040000,2,1,13.630000,15,1,13.030000,100,1,13.650000,15,1,13.020000,100,1,13.680000,100,1,12.730000,100,1,13.930000,100,1,12.710000,100,1,13.980000,2,1,12.500000,700,1,14.280000,100,1,12.460000,200,2,14.400000,100,1,12.430000,700,1,14.500000,100,1,12.420000,700,1,14.530000,100,1,12.370000,700,1,14.540000,100,1,ARL,309782481
2025-07-17T15:50:03.824292152Z,2025-07-17T15:50:03.824126753Z,10,2,1108,A,A,1,13.64,100,130,165399,259418661,13.040000,2,1,13.630000,15,1,13.030000,100,1,13.640000,100,1,13.020000,100,1,13.650000,15,1,12.730000,100,1,13.680000,100,1,12.710000,100,1,13.930000,100,1,12.500000,700,1,13.980000,2,1,12.460000,200,2,14.280000,100,1,12.430000,700,1,14.400000,100,1,12.420000,700,1,14.500000,100,1,12.370000,700,1,14.530000,100,1,ARL,309903973
2025-07-17T15:50:03.825028460Z,2025-07-17T15:50:03.824863026Z,10,2,1108,C,A,15,14.74,100,0,165434,259418664,13.040000,2,1,13.630000,15,1,13.030000,100,1,13.640000,100,1,13.020000,100,1,13.650000,15,1,12.730000,100,1,13.680000,100,1,12.710000,100,1,13.930000,100,1,12.500000,700,1,13.980000,2,1,12.460000,200,2,14.280000,100,1,12.430000,700,1,14.400000,100,1,12.420000,700,1,14.500000,100,1,12.370000,700,1,14.530000,100,1,ARL,308998341
2025-07-17T15:50:03.825028460Z,2025-07-17T15:50:03.824863026Z,10,2,1108,A,A,-1,14.70,100,130,165434,259418664,13.040000,2,1,13.630000,15,1,13.030000,100,1,13.640000,100,1,13.020000,100,1,13.650000,15,1,12.730000,100,1,13.680000,100,1,12.710000,100,1,13.930000,100,1,12.500000,700,1,13.980000,2,1,12.460000,200,2,14.280000,100,1,12.430000,700,1,14.400000,100,1,12.420000,700,1,14.500000,100,1,12.370000,700,1,14.530000,100,1,ARL,309903993
2025-07-17T15:50:04.484898759Z,2025-07-17T15:50:04.484733438Z,10,2,1108,A,A,3,13.66,100,130,165321,259433904,13.040000,2,1,13.630000,15,1,13.030000,100,1,13.640000,100,1,13.020000,100,1,13.650000,15,1,12.730000,100,1,13.660000,100,1,12.710000,100,1,13.680000,100,1,12.500000,700,1,13.930000,100,1,12.460000,200,2,13.980000,2,1,12.430000,700,1,14.280000,100,1,12.420000,700,1,14.400000,100,1,12.370000,700,1,14.500000,100,1,ARL,309922345
2025-07-17T15:50:04.524729039Z,2025-07-17T15:50:04.524563568Z,10,2,1108,C,A,4,13.68,100,130,165471,259434652,13.040000,2,1,13.630000,15,1,13.030000,100,1,13.640000,100,1,13.020000,100,1,13.650000,15,1,12.730000,100,1,13.660000,100,1,12.710000,100,1,13.930000,100,1,12.500000,700,1,13.980000,2,1,12.460000,200,2,14.280000,100,1,12.430000,700,1,14.400000,100,1,12.420000,700,1,14.500000,100,1,12.370000,700,1,14.530000,100,1,ARL,309707413
2025-07-17T15:50:06.787826975Z,2025-07-17T15:50:06.787661846Z,10,2,1108,C,A,0,13.63,15,130,165129,259472951,13.040000,2,1,13.640000,100,1,13.030000,100,1,13.650000,15,1,13.020000,100,1,13.660000,100,1,12.730000,100,1,13.930000,100,1,12.710000,100,1,13.980000,2,1,12.500000,700,1,14.280000,100,1,12.460000,200,2,14.400000,100,1,12.430000,700,1,14.500000,100,1,12.420000,700,1,14.530000,100,1,12.370000,700,1,14.540000,100,1,ARL,309899025
2025-07-17T15:50:09.185499367Z,2025-07-17T15:50:09.185334126Z,10,2,1108,A,A,0,13.61,15,130,165241,259516855,13.040000,2,1,13.610000,15,1,13.030000,100,1,13.640000,100,1,13.020000,100,1,13.650000,15,1,12.730000,100,1,13.660000,100,1,12.710000,100,1,13.930000,100,1,12.500000,700,1,13.980000,2,1,12.460000,200,2,14.280000,100,1,12.430000,700,1,14.400000,100,1,12.420000,700,1,14.500000,100,1,12.370000,700,1,14.530000,100,1,ARL,310030465
2025-07-17T15:50:09.198476437Z,2025-07-17T15:50:09.198311198Z,10,2,1108,A,A,1,13.64,100,130,165239,259517754,13.040000,2,1,13.610000,15,1,13.030000,100,1,13.640000,200,2,13.020000,100,1,13.650000,15,1,12.730000,100,1,13.660000,100,1,12.710000,100,1,13.930000,100,1,12.500000,700,1,13.980000,2,1,12.460000,200,2,14.280000,100,1,12.430000,700,1,14.400000,100,1,12.420000,700,1,14.500000,100,1,12.370000,700,1,14.530000,100,1,ARL,310031625
2025-07-17T15:50:09.205487416Z,2025-07-17T15:50:09.205322092Z,10,2,1108,C,A,3,13.66,100,130,165324,259517973,13.040000,2,1,13.610000,15,1,13.030000,100,1,13.640000,200,2,13.020000,100,1,13.650000,15,1,12.730000,100,1,13.930000,100,1,12.710000,100,1,13.980000,2,1,12.500000,700,1,14.280000,100,1,12.460000,200,2,14.400000,100,1,12.430000,700,1,14.500000,100,1,12.420000,700,1,14.530000,100,1,12.370000,700,1,14.540000,100,1,ARL,309922345
2025-07-17T15:50:09.330738153Z,2025-07-17T15:50:09.330572653Z,10,2,1108,C,A,1,13.64,100,0,165500,259522708,13.040000,2,1,13.610000,15,1,13.030000,100,1,13.640000,100,1,13.020000,100,1,13.650000,15,1,12.730000,100,1,13.930000,100,1,12.710000,100,1,13.980000,2,1,12.500000,700,1,14.280000,100,1,12.460000,200,2,14.400000,100,1,12.430000,700,1,14.500000,100,1,12.420000,700,1,14.530000,100,1,12.370000,700,1,14.540000,100,1,ARL,309903973
2025-07-17T15:50:09.330738153Z,2025-07-17T15:50:09.330572653Z,10,2,1108,A,A,1,13.62,100,130,165500,259522708,13.040000,2,1,13.610000,15,1,13.030000,100,1,13.620000,100,1,13.020000,100,1,13.640000,100,1,12.730000,100,1,13.650000,15,1,12.710000,100,1,13.930000,100,1,12.500000,700,1,13.980000,2,1,12.460000,200,2,14.280000,100,1,12.430000,700,1,14.400000,100,1,12.420000,700,1,14.500000,100,1,12.370000,700,1,14.530000,100,1,ARL,310037965
2025-07-17T15:50:20.204539185Z,2025-07-17T15:50:20.204373858Z,10,2,1108,C,A,3,13.65,15,130,165327,259737768,13.040000,2,1,13.610000,15,1,13.030000,100,1,13.620000,100,1,13.020000,100,1,13.640000,100,1,12.730000,100,1,13.930000,100,1,12.710000,100,1,13.980000,2,1,12.500000,700,1,14.280000,100,1,12.460000,200,2,14.400000,100,1,12.430000,700,1,14.500000,100,1,12.420000,700,1,14.530000,100,1,12.370000,700,1,14.540000,100,1,ARL,309707269
2025-07-17T15:50:25.935579034Z,2025-07-17T15:50:25.935412900Z,10,2,1108,A,A,0,13.59,15,128,166134,259828644,13.040000,2,1,13.590000,15,1,13.030000,100,1,13.610000,15,1,13.020000,100,1,13.620000,100,1,12.730000,100,1,13.640000,100,1,12.710000,100,1,13.930000,100,1,12.500000,700,1,13.980000,2,1,12.460000,200,2,14.280000,100,1,12.430000,700,1,14.400000,100,1,12.420000,700,1,14.500000,100,1,12.370000,700,1,14.530000,100,1,ARL,310424077
2025-07-17T15:50:26.954828150Z,2025-07-17T15:50:26.954662143Z,10,2,1108,C,A,2,13.62,100,0,166007,259847181,13.040000,2,1,13.590000,15,1,13.030000,100,1,13.610000,15,1,13.020000,100,1,13.640000,100,1,12.730000,100,1,13.930000,100,1,12.710000,100,1,13.980000,2,1,12.500000,700,1,14.280000,100,1,12.460000,200,2,14.400000,100,1,12.430000,700,1,14.500000,100,1,12.420000,700,1,14.530000,100,1,12.370000,700,1,14.540000,100,1,ARL,310037965
2025-07-17T15:50:26.954828150Z,2025-07-17T15:50:26.954662143Z,10,2,1108,A,A,1,13.60,100,130,166007,259847181,13.040000,2,1,13.590000,15,1,13.030000,100,1,13.600000,100,1,13.020000,100,1,13.610000,15,1,12.730000,100,1,13.640000,100,1,12.710000,100,1,13.930000,100,1,12.500000,700,1,13.980000,2,1,12.460000,200,2,14.280000,100,1,12.430000,700,1,14.400000,100,1,12.420000,700,1,14.500000,100,1,12.370000,700,1,14.530000,100,1,ARL,310446249
2025-07-17T15:50:26.955565904Z,2025-07-17T15:50:26.955400327Z,10,2,1108,C,A,15,14.70,100,0,165577,259847190,13.040000,2,1,13.590000,15,1,13.030000,100,1,13.600000,100,1,13.020000,100,1,13.610000,15,1,12.730000,100,1,13.640000,100,1,12.710000,100,1,13.930000,100,1,12.500000,700,1,13.980000,2,1,12.460000,200,2,14.280000,100,1,12.430000,700,1,14.400000,100,1,12.420000,700,1,14.500000,100,1,12.370000,700,1,14.530000,100,1,ARL,309903993
2025-07-17T15:50:26.955565904Z,2025-07-17T15:50:26.955400327Z,10,2,1108,A,A,-1,14.65,100,130,165577,259847190,13.040000,2,1,13.590000,15,1,13.030000,100,1,13.600000,100,1,13.020000,100,1,13.610000,15,1,12.730000,100,1,13.640000,100,1,12.710000,100,1,13.930000,100,1,12.500000,700,1,13.980000,2,1,12.460000,200,2,14.280000,100,1,12.430000,700,1,14.400000,100,1,12.420000,700,1,14.500000,100,1,12.370000,700,1,14.530000,100,1,ARL,310446269
2025-07-17T15:50:26.956259508Z,2025-07-17T15:50:26.956094101Z,10,2,1108,C,A,23,17.43,100,0,165407,259847199,13.040000,2,1,13.590000,15,1,13.030000,100,1,13.600000,100,1,13.020000,100,1,13.610000,15,1,12.730000,100,1,13.640000,100,1,12.710000,100,1,13.930000,100,1,12.500000,700,1,13.980000,2,1,12.460000,200,2,14.280000,100,1,12.430000,700,1,14.400000,100,1,12.420000,700,1,14.500000,100,1,12.370000,700,1,14.530000,100,1,ARL,308799373
2025-07-17T15:50:26.956259508Z,2025-07-17T15:50:26.956094101Z,10,2,1108,A,A,-1,17.28,100,130,165407,259847199,13.040000,2,1,13.590000,15,1,13.030000,100,1,13.600000,100,1,13.020000,100,1,13.610000,15,1,12.730000,100,1,13.640000,100,1,12.710000,100,1,13.930000,100,1,12.500000,700,1,13.980000,2,1,12.460000,200,2,14.280000,100,1,12.430000,700,1,14.400000,100,1,12.420000,700,1,14.500000,100,1,12.370000,700,1,14.530000,100,1,ARL,310446293
2025-07-17T15:50:26.983044736Z,2025-07-17T15:50:26.982879448Z,10,2,1108,A,A,-1,15.51,100,130,165288,259847556,13.040000,2,1,13.590000,15,1,13.030000,100,1,13.600000,100,1,13.020000,100,1,13.610000,15,1,12.730000,100,1,13.640000,100,1,12.710000,100,1,13.930000,100,1,12.500000,700,1,13.980000,2,1,12.460000,200,2,14.280000,100,1,12.430000,700,1,14.400000,100,1,12.420000,700,1,14.500000,100,1,12.370000,700,1,14.530000,100,1,ARL,310447441
2025-07-17T15:50:26.983057675Z,2025-07-17T15:50:26.982892468Z,10,2,1108,C,A,21,15.78,100,130,165207,259847557,13.040000,2,1,13.590000,15,1,13.030000,100,1,13.600000,100,1,13.020000,100,1,13.610000,15,1,12.730000,100,1,13.640000,100,1,12.710000,100,1,13.930000,100,1,12.500000,700,1,13.980000,2,1,12.460000,200,2,14.280000,100,1,12.430000,700,1,14.400000,100,1,12.420000,700,1,14.500000,100,1,12.370000,700,1,14.530000,100,1,ARL,282776733
2025-07-17T15:50:30.046879569Z,2025-07-17T15:50:30.046714265Z,10,2,1108,C,A,0,13.59,15,130,165304,259916670,13.040000,2,1,13.600000,100,1,13.030000,100,1,13.610000,15,1,13.020000,100,1,13.640000,100,1,12.730000,100,1,13.930000,100,1,12.710000,100,1,13.980000,2,1,12.500000,700,1,14.280000,100,1,12.460000,200,2,14.400000,100,1,12.430000,700,1,14.500000,100,1,12.420000,700,1,14.530000,100,1,12.370000,700,1,14.540000,100,1,ARL,310424077
2025-07-17T15:50:30.047015114Z,2025-07-17T15:50:30.046849726Z,10,2,1108,C,A,1,13.61,15,130,165388,259916674,13.040000,2,1,13.600000,100,1,13.030000,100,1,13.640000,100,1,13.020000,100,1,13.930000,100,1,12.730000,100,1,13.980000,2,1,12.710000,100,1,14.280000,100,1,12.500000,700,1,14.400000,100,1,12.460000,200,2,14.500000,100,1,12.430000,700,1,14.530000,100,1,12.420000,700,1,14.540000,100,1,12.370000,700,1,14.560000,800,2,ARL,310030465
2025-07-17T15:51:37.986158330Z,2025-07-17T15:51:37.985992174Z,10,2,1108,C,A,3,13.98,2,0,166156,261130345,13.040000,2,1,13.600000,100,1,13.030000,100,1,13.640000,100,1,13.020000,100,1,13.930000,100,1,12.730000,100,1,14.280000,100,1,12.710000,100,1,14.400000,100,1,12.500000,700,1,14.500000,100,1,12.460000,200,2,14.530000,100,1,12.430000,700,1,14.540000,100,1,12.420000,700,1,14.560000,800,2,12.370000,700,1,14.600000,700,1,ARL,309091513
2025-07-17T15:51:37.986158330Z,2025-07-17T15:51:37.985992174Z,10,2,1108,A,A,2,13.89,2,130,166156,261130345,13.040000,2,1,13.600000,100,1,13.030000,100,1,13.640000,100,1,13.020000,100,1,13.890000,2,1,12.730000,100,1,13.930000,100,1,12.710000,100,1,14.280000,100,1,12.500000,700,1,14.400000,100,1,12.460000,200,2,14.500000,100,1,12.430000,700,1,14.530000,100,1,12.420000,700,1,14.540000,100,1,12.370000,700,1,14.560000,800,2,ARL,311979125
2025-07-17T15:52:16.372434625Z,2025-07-17T15:52:16.372269170Z,10,2,1108,C,A,0,13.60,100,130,165455,261713790,13.040000,2,1,13.640000,100,1,13.030000,100,1,13.890000,2,1,13.020000,100,1,13.930000,100,1,12.730000,100,1,14.280000,100,1,12.710000,100,1,14.400000,100,1,12.500000,700,1,14.500000,100,1,12.460000,200,2,14.530000,100,1,12.430000,700,1,14.540000,100,1,12.420000,700,1,14.560000,800,2,12.370000,700,1,14.600000,700,1,ARL,310446249
2025-07-17T15:52:16.373188791Z,2025-07-17T15:52:16.373023186Z,10,2,1108,C,A,10,14.65,100,0,165605,261713830,13.040000,2,1,13.640000,100,1,13.030000,100,1,13.890000,2,1,13.020000,100,1,13.930000,100,1,12.730000,100,1,14.280000,100,1,12.710000,100,1,14.400000,100,1,12.500000,700,1,14.500000,100,1,12.460000,200,2,14.530000,100,1,12.430000,700,1,14.540000,100,1,12.420000,700,1,14.560000,800,2,12.370000,700,1,14.600000,700,1,ARL,310446269
2025-07-17T15:52:16.373188791Z,2025-07-17T15:52:16.373023186Z,10,2,1108,A,A,-1,14.70,100,130,165605,261713830,13.040000,2,1,13.640000,100,1,13.030000,100,1,13.890000,2,1,13.020000,100,1,13.930000,100,1,12.730000,100,1,14.280000,100,1,12.710000,100,1,14.400000,100,1,12.500000,700,1,14.500000,100,1,12.460000,200,2,14.530000,100,1,12.430000,700,1,14.540000,100,1,12.420000,700,1,14.560000,800,2,12.370000,700,1,14.600000,700,1,ARL,312771573
2025-07-17T15:52:16.374353159Z,2025-07-17T15:52:16.374186508Z,10,2,1108,C,A,0,13.64,100,130,166651,261713870,13.040000,2,1,13.890000,2,1,13.030000,100,1,13.930000,100,1,13.020000,100,1,14.280000,100,1,12.730000,100,1,14.400000,100,1,12.710000,100,1,14.500000,100,1,12.500000,700,1,14.530000,100,1,12.460000,200,2,14.540000,100,1,12.430000,700,1,14.560000,800,2,12.420000,700,1,14.600000,700,1,12.370000,700,1,14.660000,200,2,ARL,310031625
2025-07-17T15:52:16.374480183Z,2025-07-17T15:52:16.374312976Z,10,2,1108,A,A,-1,15.86,100,128,167207,261713880,13.040000,2,1,13.890000,2,1,13.030000,100,1,13.930000,100,1,13.020000,100,1,14.280000,100,1,12.730000,100,1,14.400000,100,1,12.710000,100,1,14.500000,100,1,12.500000,700,1,14.530000,100,1,12.460000,200,2,14.540000,100,1,12.430000,700,1,14.560000,800,2,12.420000,700,1,14.600000,700,1,12.370000,700,1,14.660000,200,2,ARL,312771645
2025-07-17T15:52:16.374493650Z,2025-07-17T15:52:16.374327668Z,10,2,1108,C,A,15,15.51,100,130,165982,261713884,13.040000,2,1,13.890000,2,1,13.030000,100,1,13.930000,100,1,13.020000,100,1,14.280000,100,1,12.730000,100,1,14.400000,100,1,12.710000,100,1,14.500000,100,1,12.500000,700,1,14.530000,100,1,12.460000,200,2,14.540000,100,1,12.430000,700,1,14.560000,800,2,12.420000,700,1,14.600000,700,1,12.370000,700,1,14.660000,200,2,ARL,310447441
2025-07-17T15:52:16.375388285Z,2025-07-17T15:52:16.375222836Z,10,2,1108,C,A,6,14.54,100,0,165449,261713944,13.040000,2,1,13.890000,2,1,13.030000,100,1,13.930000,100,1,13.020000,100,1,14.280000,100,1,12.730000,100,1,14.400000,100,1,12.710000,100,1,14.500000,100,1,12.500000,700,1,14.530000,100,1,12.460000,200,2,14.560000,800,2,12.430000,700,1,14.600000,700,1,12.420000,700,1,14.660000,200,2,12.370000,700,1,14.680000,1400,2,ARL,309823025
2025-07-17T15:52:16.375388285Z,2025-07-17T15:52:16.375222836Z,10,2,1108,A,A,-1,14.81,100,130,165449,261713944,13.040000,2,1,13.890000,2,1,13.030000,100,1,13.930000,100,1,13.020000,100,1,14.280000,100,1,12.730000,100,1,14.400000,100,1,12.710000,100,1,14.500000,100,1,12.500000,700,1,14.530000,100,1,12.460000,200,2,14.560000,800,2,12.430000,700,1,14.600000,700,1,12.420000,700,1,14.660000,200,2,12.370000,700,1,14.680000,1400,2,ARL,312771781
2025-07-17T15:52:16.375414247Z,2025-07-17T15:52:16.375248654Z,10,2,1108,C,A,8,14.66,100,0,165593,261713945,13.040000,2,1,13.890000,2,1,13.030000,100,1,13.930000,100,1,13.020000,100,1,14.280000,100,1,12.730000,100,1,14.400000,100,1,12.710000,100,1,14.500000,100,1,12.500000,700,1,14.530000,100,1,12.460000,200,2,14.560000,800,2,12.430000,700,1,14.600000,700,1,12.420000,700,1,14.660000,100,1,12.370000,700,1,14.680000,1400,2,ARL,308901981
2025-07-17T15:52:16.375414247Z,2025-07-17T15:52:16.375248654Z,10,2,1108,A,A,-1,14.89,100,130,165593,261713945,13.040000,2,1,13.890000,2,1,13.030000,100,1,13.930000,100,1,13.020000,100,1,14.280000,100,1,12.730000,100,1,14.400000,100,1,12.710000,100,1,14.500000,100,1,12.500000,700,1,14.530000,100,1,12.460000,200,2,14.560000,800,2,12.430000,700,1,14.600000,700,1,12.420000,700,1,14.660000,100,1,12.370000,700,1,14.680000,1400,2,ARL,312771785
2025-07-17T15:52:16.375828154Z,2025-07-17T15:52:16.375662552Z,10,2,1108,C,A,5,14.53,100,0,165602,261713959,13.040000,2,1,13.890000,2,1,13.030000,100,1,13.930000,100,1,13.020000,100,1,14.280000,100,1,12.730000,100,1,14.400000,100,1,12.710000,100,1,14.500000,100,1,12.500000,700,1,14.560000,800,2,12.460000,200,2,14.600000,700,1,12.430000,700,1,14.660000,100,1,12.420000,700,1,14.680000,1400,2,12.370000,700,1,14.700000,100,1,ARL,309899141
2025-07-17T15:52:16.375828154Z,2025-07-17T15:52:16.375662552Z,10,2,1108,A,A,-1,14.76,100,130,165602,261713959,13.040000,2,1,13.890000,2,1,13.030000,100,1,13.930000,100,1,13.020000,100,1,14.280000,100,1,12.730000,100,1,14.400000,100,1,12.710000,100,1,14.500000,100,1,12.500000,700,1,14.560000,800,2,12.460000,200,2,14.600000,700,1,12.430000,700,1,14.660000,100,1,12.420000,700,1,14.680000,1400,2,12.370000,700,1,14.700000,100,1,ARL,312771829
2025-07-17T15:52:16.377345053Z,2025-07-17T15:52:16.377179230Z,10,2,1108,C,A,20,17.28,100,0,165823,261714104,13.040000,2,1,13.890000,2,1,13.030000,100,1,13.930000,100,1,13.020000,100,1,14.280000,100,1,12.730000,100,1,14.400000,100,1,12.710000,100,1,14.500000,100,1,12.500000,700,1,14.560000,800,2,12.460000,200,2,14.600000,700,1,12.430000,700,1,14.660000,100,1,12.420000,700,1,14.680000,1400,2,12.370000,700,1,14.700000,100,1,ARL,310446293
2025-07-17T15:52:16.377345053Z,2025-07-17T15:52:16.377179230Z,10,2,1108,A,A,-1,17.70,100,130,165823,261714104,13.040000,2,1,13.890000,2,1,13.030000,100,1,13.930000,100,1,13.020000,100,1,14.280000,100,1,12.730000,100,1,14.400000,100,1,12.710000,100,1,14.500000,100,1,12.500000,700,1,14.560000,800,2,12.460000,200,2,14.600000,700,1,12.430000,700,1,14.660000,100,1,12.420000,700,1,14.680000,1400,2,12.370000,700,1,14.700000,100,1,ARL,312772009
2025-07-17T15:52:16.378239114Z,2025-07-17T15:52:16.378073674Z,10,2,1108,C,A,16,15.76,100,0,165440,261714140,13.040000,2,1,13.890000,2,1,13.030000,100,1,13.930000,100,1,13.020000,100,1,14.280000,100,1,12.730000,100,1,14.400000,100,1,12.710000,100,1,14.500000,100,1,12.500000,700,1,14.560000,800,2,12.460000,200,2,14.600000,700,1,12.430000,700,1,14.660000,100,1,12.420000,700,1,14.680000,1400,2,12.370000,700,1,14.700000,100,1,ARL,308902229
2025-07-17T15:52:16.378239114Z,2025-07-17T15:52:16.378073674Z,10,2,1108,A,A,-1,16.02,100,130,165440,261714140,13.040000,2,1,13.890000,2,1,13.030000,100,1,13.930000,100,1,13.020000,100,1,14.280000,100,1,12.730000,100,1,14.400000,100,1,12.710000,100,1,14.500000,100,1,12.500000,700,1,14.560000,800,2,12.460000,200,2,14.600000,700,1,12.430000,700,1,14.660000,100,1,12.420000,700,1,14.680000,1400,2,12.370000,700,1,14.700000,100,1,ARL,312772057
2025-07-17T15:52:16.378385943Z,2025-07-17T15:52:16.378220434Z,10,2,1108,C,A,4,14.50,100,0,165509,261714145,13.040000,2,1,13.890000,2,1,13.030000,100,1,13.930000,100,1,13.020000,100,1,14.280000,100,1,12.730000,100,1,14.400000,100,1,12.710000,100,1,14.560000,800,2,12.500000,700,1,14.600000,700,1,12.460000,200,2,14.660000,100,1,12.430000,700,1,14.680000,1400,2,12.420000,700,1,14.700000,100,1,12.370000,700,1,14.760000,100,1,ARL,308903349
2025-07-17T15:52:16.378385943Z,2025-07-17T15:52:16.378220434Z,10,2,1108,A,A,9,14.72,100,130,165509,261714145,13.040000,2,1,13.890000,2,1,13.030000,100,1,13.930000,100,1,13.020000,100,1,14.280000,100,1,12.730000,100,1,14.400000,100,1,12.710000,100,1,14.560000,800,2,12.500000,700,1,14.600000,700,1,12.460000,200,2,14.660000,100,1,12.430000,700,1,14.680000,1400,2,12.420000,700,1,14.700000,100,1,12.370000,700,1,14.720000,100,1,ARL,312772061
2025-07-17T15:52:16.378870638Z,2025-07-17T15:52:16.378705201Z,10,2,1108,A,B,0,13.27,10,130,165437,261714171,13.270000,10,1,13.890000,2,1,13.040000,2,1,13.930000,100,1,13.030000,100,1,14.280000,100,1,13.020000,100,1,14.400000,100,1,12.730000,100,1,14.560000,800,2,12.710000,100,1,14.600000,700,1,12.500000,700,1,14.660000,100,1,12.460000,200,2,14.680000,1400,2,12.430000,700,1,14.700000,100,1,12.420000,700,1,14.720000,100,1,ARL,312772069
2025-07-17T15:52:16.378872385Z,2025-07-17T15:52:16.378707041Z,10,2,1108,A,A,0,13.86,15,130,165344,261714172,13.270000,10,1,13.860000,15,1,13.040000,2,1,13.890000,2,1,13.030000,100,1,13.930000,100,1,13.020000,100,1,14.280000,100,1,12.730000,100,1,14.400000,100,1,12.710000,100,1,14.560000,800,2,12.500000,700,1,14.600000,700,1,12.460000,200,2,14.660000,100,1,12.430000,700,1,14.680000,1400,2,12.420000,700,1,14.700000,100,1,ARL,312772073
2025-07-17T15:52:16.379127782Z,2025-07-17T15:52:16.378962330Z,10,2,1108,C,B,3,13.02,100,0,165452,261714185,13.270000,10,1,13.860000,15,1,13.040000,2,1,13.890000,2,1,13.030000,100,1,13.930000,100,1,12.730000,100,1,14.280000,100,1,12.710000,100,1,14.400000,100,1,12.500000,700,1,14.560000,800,2,12.460000,200,2,14.600000,700,1,12.430000,700,1,14.660000,100,1,12.420000,700,1,14.680000,1400,2,12.370000,700,1,14.700000,100,1,ARL,309415429
2025-07-17T15:52:16.379127782Z,2025-07-17T15:52:16.378962330Z,10,2,1108,A,B,1,13.26,100,130,165452,261714185,13.270000,10,1,13.860000,15,1,13.260000,100,1,13.890000,2,1,13.040000,2,1,13.930000,100,1,13.030000,100,1,14.280000,100,1,12.730000,100,1,14.400000,100,1,12.710000,100,1,14.560000,800,2,12.500000,700,1,14.600000,700,1,12.460000,200,2,14.660000,100,1,12.430000,700,1,14.680000,1400,2,12.420000,700,1,14.700000,100,1,ARL,312772077
2025-07-17T15:52:16.389025469Z,2025-07-17T15:52:16.388859982Z,10,2,1108,C,A,2,13.93,100,130,165487,261714477,13.270000,10,1,13.860000,15,1,13.260000,100,1,13.890000,2,1,13.040000,2,1,14.280000,100,1,13.030000,100,1,14.400000,100,1,12.730000,100,1,14.560000,800,2,12.710000,100,1,14.600000,700,1,12.500000,700,1,14.660000,100,1,12.460000,200,2,14.680000,1400,2,12.430000,700,1,14.700000,100,1,12.420000,700,1,14.720000,100,1,ARL,309782973
2025-07-17T15:52:16.389082451Z,2025-07-17T15:52:16.388917108Z,10,2,1108,A,A,2,14.19,100,130,165343,261714481,13.270000,10,1,13.860000,15,1,13.260000,100,1,13.890000,2,1,13.040000,2,1,14.190000,100,1,13.030000,100,1,14.280000,100,1,12.730000,100,1,14.400000,100,1,12.710000,100,1,14.560000,800,2,12.500000,700,1,14.600000,700,1,12.460000,200,2,14.660000,100,1,12.430000,700,1,14.680000,1400,2,12.420000,700,1,14.700000,100,1,ARL,312772501
2025-07-17T15:52:16.396174502Z,2025-07-17T15:52:16.396008715Z,10,2,1108,C,A,7,14.66,100,0,165787,261714603,13.270000,10,1,13.860000,15,1,13.260000,100,1,13.890000,2,1,13.040000,2,1,14.190000,100,1,13.030000,100,1,14.280000,100,1,12.730000,100,1,14.400000,100,1,12.710000,100,1,14.560000,800,2,12.500000,700,1,14.600000,700,1,12.460000,200,2,14.680000,1400,2,12.430000,700,1,14.700000,100,1,12.420000,700,1,14.720000,100,1,ARL,308903001
2025-07-17T15:52:16.396174502Z,2025-07-17T15:52:16.396008715Z,10,2,1108,A,A,-1,14.96,100,130,165787,261714603,13.270000,10,1,13.860000,15,1,13.260000,100,1,13.890000,2,1,13.040000,2,1,14.190000,100,1,13.030000,100,1,14.280000,100,1,12.730000,100,1,14.400000,100,1,12.710000,100,1,14.560000,800,2,12.500000,700,1,14.600000,700,1,12.460000,200,2,14.680000,1400,2,12.430000,700,1,14.700000,100,1,12.420000,700,1,14.720000,100,1,ARL,312772869
2025-07-17T15:52:16.397677681Z,2025-07-17T15:52:16.397512710Z,10,2,1108,C,A,2,14.19,100,130,164971,261714619,13.270000,10,1,13.860000,15,1,13.260000,100,1,13.890000,2,1,13.040000,2,1,14.280000,100,1,13.030000,100,1,14.400000,100,1,12.730000,100,1,14.560000,800,2,12.710000,100,1,14.600000,700,1,12.500000,700,1,14.680000,1400,2,12.460000,200,2,14.700000,100,1,12.430000,700,1,14.720000,100,1,12.420000,700,1,14.760000,100,1,ARL,312772501
2025-07-17T15:52:16.397727042Z,2025-07-17T15:52:16.397561691Z,10,2,1108,A,A,2,14.26,100,130,165351,261714620,13.270000,10,1,13.860000,15,1,13.260000,100,1,13.890000,2,1,13.040000,2,1,14.260000,100,1,13.030000,100,1,14.280000,100,1,12.730000,100,1,14.400000,100,1,12.710000,100,1,14.560000,800,2,12.500000,700,1,14.600000,700,1,12.460000,200,2,14.680000,1400,2,12.430000,700,1,14.700000,100,1,12.420000,700,1,14.720000,100,1,ARL,312772901
2025-07-17T15:52:16.424137423Z,2025-07-17T15:52:16.423972000Z,10,2,1108,C,A,8,14.70,100,0,165423,261714976,13.270000,10,1,13.860000,15,1,13.260000,100,1,13.890000,2,1,13.040000,2,1,14.260000,100,1,13.030000,100,1,14.280000,100,1,12.730000,100,1,14.400000,100,1,12.710000,100,1,14.560000,800,2,12.500000,700,1,14.600000,700,1,12.460000,200,2,14.680000,1400,2,12.430000,700,1,14.720000,100,1,12.420000,700,1,14.760000,100,1,ARL,312771573
2025-07-17T15:52:16.424137423Z,2025-07-17T15:52:16.423972000Z,10,2,1108,A,A,-1,15.06,100,130,165423,261714976,13.270000,10,1,13.860000,15,1,13.260000,100,1,13.890000,2,1,13.040000,2,1,14.260000,100,1,13.030000,100,1,14.280000,100,1,12.730000,100,1,14.400000,100,1,12.710000,100,1,14.560000,800,2,12.500000,700,1,14.600000,700,1,12.460000,200,2,14.680000,1400,2,12.430000,700,1,14.720000,100,1,12.420000,700,1,14.760000,100,1,ARL,312773353
2025-07-17T15:52:16.464781343Z,2025-07-17T15:52:16.464616142Z,10,2,1108,A,A,1,13.87,100,130,165201,261715303,13.270000,10,1,13.860000,15,1,13.260000,100,1,13.870000,100,1,13.040000,2,1,13.890000,2,1,13.030000,100,1,14.260000,100,1,12.730000,100,1,14.280000,100,1,12.710000,100,1,14.400000,100,1,12.500000,700,1,14.560000,800,2,12.460000,200,2,14.600000,700,1,12.430000,700,1,14.680000,1400,2,12.420000,700,1,14.720000,100,1,ARL,312773881
2025-07-17T15:52:16.473556948Z,2025-07-17T15:52:16.473391480Z,10,2,1108,C,A,14,15.06,100,0,165468,261715409,13.270000,10,1,13.860000,15,1,13.260000,100,1,13.870000,100,1,13.040000,2,1,13.890000,2,1,13.030000,100,1,14.260000,100,1,12.730000,100,1,14.280000,100,1,12.710000,100,1,14.400000,100,1,12.500000,700,1,14.560000,800,2,12.460000,200,2,14.600000,700,1,12.430000,700,1,14.680000,1400,2,12.420000,700,1,14.720000,100,1,ARL,312773353
2025-07-17T15:52:16.473556948Z,2025-07-17T15:52:16.473391480Z,10,2,1108,A,A,-1,14.95,100,130,165468,261715409,13.270000,10,1,13.860000,15,1,13.260000,100,1,13.870000,100,1,13.040000,2,1,13.890000,2,1,13.030000,100,1,14.260000,100,1,12.730000,100,1,14.280000,100,1,12.710000,100,1,14.400000,100,1,12.500000,700,1,14.560000,800,2,12.460000,200,2,14.600000,700,1,12.430000,700,1,14.680000,1400,2,12.420000,700,1,14.720000,100,1,ARL,312774001
2025-07-17T15:52:16.480090894Z,2025-07-17T15:52:16.479925781Z,10,2,1108,C,A,3,14.26,100,130,165113,261715467,13.270000,10,1,13.860000,15,1,13.260000,100,1,13.870000,100,1,13.040000,2,1,13.890000,2,1,13.030000,100,1,14.280000,100,1,12.730000,100,1,14.400000,100,1,12.710000,100,1,14.560000,800,2,12.500000,700,1,14.600000,700,1,12.460000,200,2,14.680000,1400,2,12.430000,700,1,14.720000,100,1,12.420000,700,1,14.760000,100,1,ARL,312772901
2025-07-17T15:52:16.480140131Z,2025-07-17T15:52:16.479974840Z,10,2,1108,A,A,3,14.15,100,130,165291,261715468,13.270000,10,1,13.860000,15,1,13.260000,100,1,13.870000,100,1,13.040000,2,1,13.890000,2,1,13.030000,100,1,14.150000,100,1,12.730000,100,1,14.280000,100,1,12.710000,100,1,14.400000,100,1,12.500000,700,1,14.560000,800,2,12.460000,200,2,14.600000,700,1,12.430000,700,1,14.680000,1400,2,12.420000,700,1,14.720000,100,1,ARL,312774033
2025-07-17T15:52:28.787316865Z,2025-07-17T15:52:28.787151494Z,10,2,1108,C,B,0,13.27,10,130,165371,261883294,13.260000,100,1,13.860000,15,1,13.040000,2,1,13.870000,100,1,13.030000,100,1,13.890000,2,1,12.730000,100,1,14.150000,100,1,12.710000,100,1,14.280000,100,1,12.500000,700,1,14.400000,100,1,12.460000,200,2,14.560000,800,2,12.430000,700,1,14.600000,700,1,12.420000,700,1,14.680000,1400,2,12.370000,700,1,14.720000,100,1,ARL,312772069
