ts_recv,ts_event,rtype,publisher_id,instrument_id,action,side,depth,price,size,flags,ts_in_delta,sequence,bid_px_00,bid_sz_00,bid_ct_00,ask_px_00,ask_sz_00,ask_ct_00,bid_px_01,bid_sz_01,bid_ct_01,ask_px_01,ask_sz_01,ask_ct_01,bid_px_02,bid_sz_02,bid_ct_02,ask_px_02,ask_sz_02,ask_ct_02,bid_px_03,bid_sz_03,bid_ct_03,ask_px_03,ask_sz_03,ask_ct_03,bid_px_04,bid_sz_04,bid_ct_04,ask_px_04,ask_sz_04,ask_ct_04,bid_px_05,bid_sz_05,bid_ct_05,ask_px_05,ask_sz_05,ask_ct_05,bid_px_06,bid_sz_06,bid_ct_06,ask_px_06,ask_sz_06,ask_ct_06,bid_px_07,bid_sz_07,bid_ct_07,ask_px_07,ask_sz_07,ask_ct_07,bid_px_08,bid_sz_08,bid_ct_08,ask_px_08,ask_sz_08,ask_ct_08,bid_px_09,bid_sz_09,bid_ct_09,ask_px_09,ask_sz_09,ask_ct_09,symbol,order_id
2025-07-17T15:52:28.787317827Z,2025-07-17T15:52:28.787152437Z,10,2,1108,C,A,0,13.86,15,130,165390,261883295,13.260000,100,1,13.870000,100,1,13.040000,2,1,13.890000,2,1,13.030000,100,1,14.150000,100,1,12.730000,100,1,14.280000,100,1,12.710000,100,1,14.400000,100,1,12.500000,700,1,14.560000,800,2,12.460000,200,2,14.600000,700,1,12.430000,700,1,14.680000,1400,2,12.420000,700,1,14.720000,100,1,12.370000,700,1,14.760000,100,1,ARL,312772073
2025-07-17T15:52:43.128371033Z,2025-07-17T15:52:43.128203357Z,10,2,1108,C,A,1,13.89,2,0,167676,262115170,13.260000,100,1,13.870000,100,1,13.040000,2,1,14.150000,100,1,13.030000,100,1,14.280000,100,1,12.730000,100,1,14.400000,100,1,12.710000,100,1,14.560000,800,2,12.500000,700,1,14.600000,700,1,12.460000,200,2,14.680000,1400,2,12.430000,700,1,14.720000,100,1,12.420000,700,1,14.760000,100,1,12.370000,700,1,14.810000,100,1,ARL,311979125
2025-07-17T15:52:43.128371033Z,2025-07-17T15:52:43.128203357Z,10,2,1108,A,A,1,13.99,2,128,167676,262115170,13.260000,100,1,13.870000,100,1,13.040000,2,1,13.990000,2,1,13.030000,100,1,14.150000,100,1,12.730000,100,1,14.280000,100,1,12.710000,100,1,14.400000,100,1,12.500000,700,1,14.560000,800,2,12.460000,200,2,14.600000,700,1,12.430000,700,1,14.680000,1400,2,12.420000,700,1,14.720000,100,1,12.370000,700,1,14.760000,100,1,ARL,313336713
2025-07-17T15:54:24.908483782Z,2025-07-17T15:54:24.908318259Z,10,2,1108,A,B,0,13.29,10,130,165523,263863872,13.290000,10,1,13.870000,100,1,13.260000,100,1,13.990000,2,1,13.040000,2,1,14.150000,100,1,13.030000,100,1,14.280000,100,1,12.730000,100,1,14.400000,100,1,12.710000,100,1,14.560000,800,2,12.500000,700,1,14.600000,700,1,12.460000,200,2,14.680000,1400,2,12.430000,700,1,14.720000,100,1,12.420000,700,1,14.760000,100,1,ARL,315581981
2025-07-17T15:54:26.792478456Z,2025-07-17T15:54:26.792313320Z,10,2,1108,C,B,0,13.29,10,130,165136,263895481,13.260000,100,1,13.870000,100,1,13.040000,2,1,13.990000,2,1,13.030000,100,1,14.150000,100,1,12.730000,100,1,14.280000,100,1,12.710000,100,1,14.400000,100,1,12.500000,700,1,14.560000,800,2,12.460000,200,2,14.600000,700,1,12.430000,700,1,14.680000,1400,2,12.420000,700,1,14.720000,100,1,12.370000,700,1,14.760000,100,1,ARL,315581981
2025-07-17T15:54:52.986116083Z,2025-07-17T15:54:52.985950259Z,10,2,1108,C,A,1,13.99,2,0,165824,264262615,13.260000,100,1,13.870000,100,1,13.040000,2,1,14.150000,100,1,13.030000,100,1,14.280000,100,1,12.730000,100,1,14.400000,100,1,12.710000,100,1,14.560000,800,2,12.500000,700,1,14.600000,700,1,12.460000,200,2,14.680000,1400,2,12.430000,700,1,14.720000,100,1,12.420000,700,1,14.760000,100,1,12.370000,700,1,14.810000,100,1,ARL,313336713
2025-07-17T15:54:52.986116083Z,2025-07-17T15:54:52.985950259Z,10,2,1108,A,A,1,14.10,2,130,165824,264262615,13.260000,100,1,13.870000,100,1,13.040000,2,1,14.100000,2,1,13.030000,100,1,14.150000,100,1,12.730000,100,1,14.280000,100,1,12.710000,100,1,14.400000,100,1,12.500000,700,1,14.560000,800,2,12.460000,200,2,14.600000,700,1,12.430000,700,1,14.680000,1400,2,12.420000,700,1,14.720000,100,1,12.370000,700,1,14.760000,100,1,ARL,316098525
2025-07-17T15:55:33.673598252Z,2025-07-17T15:55:33.673432762Z,10,2,1108,A,B,0,13.29,10,130,165490,264905534,13.290000,10,1,13.870000,100,1,13.260000,100,1,14.100000,2,1,13.040000,2,1,14.150000,100,1,13.030000,100,1,14.280000,100,1,12.730000,100,1,14.400000,100,1,12.710000,100,1,14.560000,800,2,12.500000,700,1,14.600000,700,1,12.460000,200,2,14.680000,1400,2,12.430000,700,1,14.720000,100,1,12.420000,700,1,14.760000,100,1,ARL,316911465
2025-07-17T15:55:34.257417204Z,2025-07-17T15:55:34.257251787Z,10,2,1108,C,B,1,13.26,100,0,165417,264919835,13.290000,10,1,13.870000,100,1,13.040000,2,1,14.100000,2,1,13.030000,100,1,14.150000,100,1,12.730000,100,1,14.280000,100,1,12.710000,100,1,14.400000,100,1,12.500000,700,1,14.560000,800,2,12.460000,200,2,14.600000,700,1,12.430000,700,1,14.680000,1400,2,12.420000,700,1,14.720000,100,1,12.370000,700,1,14.760000,100,1,ARL,312772077
2025-07-17T15:55:34.257417204Z,2025-07-17T15:55:34.257251787Z,10,2,1108,A,B,1,13.28,100,130,165417,264919835,13.290000,10,1,13.870000,100,1,13.280000,100,1,14.100000,2,1,13.040000,2,1,14.150000,100,1,13.030000,100,1,14.280000,100,1,12.730000,100,1,14.400000,100,1,12.710000,100,1,14.560000,800,2,12.500000,700,1,14.600000,700,1,12.460000,200,2,14.680000,1400,2,12.430000,700,1,14.720000,100,1,12.420000,700,1,14.760000,100,1,ARL,316924721
2025-07-17T15:55:40.197750400Z,2025-07-17T15:55:40.197584524Z,10,2,1108,C,B,0,13.29,10,130,165876,265015966,13.280000,100,1,13.870000,100,1,13.040000,2,1,14.100000,2,1,13.030000,100,1,14.150000,100,1,12.730000,100,1,14.280000,100,1,12.710000,100,1,14.400000,100,1,12.500000,700,1,14.560000,800,2,12.460000,200,2,14.600000,700,1,12.430000,700,1,14.680000,1400,2,12.420000,700,1,14.720000,100,1,12.370000,700,1,14.760000,100,1,ARL,316911465
2025-07-17T15:57:51.328863560Z,2025-07-17T15:57:51.328698198Z,10,2,1108,C,A,0,13.87,100,130,165362,267272430,13.280000,100,1,14.100000,2,1,13.040000,2,1,14.150000,100,1,13.030000,100,1,14.280000,100,1,12.730000,100,1,14.400000,100,1,12.710000,100,1,14.560000,800,2,12.500000,700,1,14.600000,700,1,12.460000,200,2,14.680000,1400,2,12.430000,700,1,14.720000,100,1,12.420000,700,1,14.760000,100,1,12.370000,700,1,14.810000,100,1,ARL,312773881
2025-07-17T15:57:51.329613584Z,2025-07-17T15:57:51.329447325Z,10,2,1108,C,A,11,14.95,100,0,166259,267272438,13.280000,100,1,14.100000,2,1,13.040000,2,1,14.150000,100,1,13.030000,100,1,14.280000,100,1,12.730000,100,1,14.400000,100,1,12.710000,100,1,14.560000,800,2,12.500000,700,1,14.600000,700,1,12.460000,200,2,14.680000,1400,2,12.430000,700,1,14.720000,100,1,12.420000,700,1,14.760000,100,1,12.370000,700,1,14.810000,100,1,ARL,312774001
2025-07-17T15:57:51.329613584Z,2025-07-17T15:57:51.329447325Z,10,2,1108,A,A,-1,15.00,100,130,166259,267272438,13.280000,100,1,14.100000,2,1,13.040000,2,1,14.150000,100,1,13.030000,100,1,14.280000,100,1,12.730000,100,1,14.400000,100,1,12.710000,100,1,14.560000,800,2,12.500000,700,1,14.600000,700,1,12.460000,200,2,14.680000,1400,2,12.430000,700,1,14.720000,100,1,12.420000,700,1,14.760000,100,1,12.370000,700,1,14.810000,100,1,ARL,319985021
2025-07-17T15:57:51.329857672Z,2025-07-17T15:57:51.329692071Z,10,2,1108,C,A,8,14.76,100,0,165601,267272442,13.280000,100,1,14.100000,2,1,13.040000,2,1,14.150000,100,1,13.030000,100,1,14.280000,100,1,12.730000,100,1,14.400000,100,1,12.710000,100,1,14.560000,800,2,12.500000,700,1,14.600000,700,1,12.460000,200,2,14.680000,1400,2,12.430000,700,1,14.720000,100,1,12.420000,700,1,14.810000,100,1,12.370000,700,1,14.890000,100,1,ARL,312771829
2025-07-17T15:57:51.329857672Z,2025-07-17T15:57:51.329692071Z,10,2,1108,A,A,9,14.89,100,130,165601,267272442,13.280000,100,1,14.100000,2,1,13.040000,2,1,14.150000,100,1,13.030000,100,1,14.280000,100,1,12.730000,100,1,14.400000,100,1,12.710000,100,1,14.560000,800,2,12.500000,700,1,14.600000,700,1,12.460000,200,2,14.680000,1400,2,12.430000,700,1,14.720000,100,1,12.420000,700,1,14.810000,100,1,12.370000,700,1,14.890000,200,2,ARL,319985025
2025-07-17T15:57:51.339328219Z,2025-07-17T15:57:51.339162512Z,10,2,1108,C,A,1,14.15,100,130,165707,267272660,13.280000,100,1,14.100000,2,1,13.040000,2,1,14.280000,100,1,13.030000,100,1,14.400000,100,1,12.730000,100,1,14.560000,800,2,12.710000,100,1,14.600000,700,1,12.500000,700,1,14.680000,1400,2,12.460000,200,2,14.720000,100,1,12.430000,700,1,14.810000,100,1,12.420000,700,1,14.890000,200,2,12.370000,700,1,14.960000,100,1,ARL,312774033
2025-07-17T15:57:51.339382098Z,2025-07-17T15:57:51.339216923Z,10,2,1108,A,A,1,14.26,100,130,165175,267272665,13.280000,100,1,14.100000,2,1,13.040000,2,1,14.260000,100,1,13.030000,100,1,14.280000,100,1,12.730000,100,1,14.400000,100,1,12.710000,100,1,14.560000,800,2,12.500000,700,1,14.600000,700,1,12.460000,200,2,14.680000,1400,2,12.430000,700,1,14.720000,100,1,12.420000,700,1,14.810000,100,1,12.370000,700,1,14.890000,200,2,ARL,319985165
2025-07-17T15:57:51.379736852Z,2025-07-17T15:57:51.379570470Z,10,2,1108,C,A,11,15.00,100,0,166382,267273071,13.280000,100,1,14.100000,2,1,13.040000,2,1,14.260000,100,1,13.030000,100,1,14.280000,100,1,12.730000,100,1,14.400000,100,1,12.710000,100,1,14.560000,800,2,12.500000,700,1,14.600000,700,1,12.460000,200,2,14.680000,1400,2,12.430000,700,1,14.720000,100,1,12.420000,700,1,14.810000,100,1,12.370000,700,1,14.890000,200,2,ARL,319985021
2025-07-17T15:57:51.379736852Z,2025-07-17T15:57:51.379570470Z,10,2,1108,A,A,-1,15.06,100,128,166382,267273071,13.280000,100,1,14.100000,2,1,13.040000,2,1,14.260000,100,1,13.030000,100,1,14.280000,100,1,12.730000,100,1,14.400000,100,1,12.710000,100,1,14.560000,800,2,12.500000,700,1,14.600000,700,1,12.460000,200,2,14.680000,1400,2,12.430000,700,1,14.720000,100,1,12.420000,700,1,14.810000,100,1,12.370000,700,1,14.890000,200,2,ARL,319985497
2025-07-17T15:57:52.378369524Z,2025-07-17T15:57:52.378204338Z,10,2,1108,A,A,1,14.11,100,130,165186,267283873,13.280000,100,1,14.100000,2,1,13.040000,2,1,14.110000,100,1,13.030000,100,1,14.260000,100,1,12.730000,100,1,14.280000,100,1,12.710000,100,1,14.400000,100,1,12.500000,700,1,14.560000,800,2,12.460000,200,2,14.600000,700,1,12.430000,700,1,14.680000,1400,2,12.420000,700,1,14.720000,100,1,12.370000,700,1,14.810000,100,1,ARL,320000233
2025-07-17T15:58:14.483909354Z,2025-07-17T15:58:14.483743947Z,10,2,1108,A,A,0,13.76,4,130,165407,267657011,13.280000,100,1,13.760000,4,1,13.040000,2,1,14.100000,2,1,13.030000,100,1,14.110000,100,1,12.730000,100,1,14.260000,100,1,12.710000,100,1,14.280000,100,1,12.500000,700,1,14.400000,100,1,12.460000,200,2,14.560000,800,2,12.430000,700,1,14.600000,700,1,12.420000,700,1,14.680000,1400,2,12.370000,700,1,14.720000,100,1,ARL,320484625
2025-07-17T15:58:14.484164551Z,2025-07-17T15:58:14.483999049Z,10,2,1108,C,A,2,14.11,100,0,165502,267657013,13.280000,100,1,13.760000,4,1,13.040000,2,1,14.100000,2,1,13.030000,100,1,14.260000,100,1,12.730000,100,1,14.280000,100,1,12.710000,100,1,14.400000,100,1,12.500000,700,1,14.560000,800,2,12.460000,200,2,14.600000,700,1,12.430000,700,1,14.680000,1400,2,12.420000,700,1,14.720000,100,1,12.370000,700,1,14.810000,100,1,ARL,320000233
2025-07-17T15:58:14.484164551Z,2025-07-17T15:58:14.483999049Z,10,2,1108,A,A,1,13.77,100,130,165502,267657013,13.280000,100,1,13.760000,4,1,13.040000,2,1,13.770000,100,1,13.030000,100,1,14.100000,2,1,12.730000,100,1,14.260000,100,1,12.710000,100,1,14.280000,100,1,12.500000,700,1,14.400000,100,1,12.460000,200,2,14.560000,800,2,12.430000,700,1,14.600000,700,1,12.420000,700,1,14.680000,1400,2,12.370000,700,1,14.720000,100,1,ARL,320484637
2025-07-17T15:58:14.484183413Z,2025-07-17T15:58:14.484017806Z,10,2,1108,C,B,0,13.28,100,130,165607,267657014,13.040000,2,1,13.760000,4,1,13.030000,100,1,13.770000,100,1,12.730000,100,1,14.100000,2,1,12.710000,100,1,14.260000,100,1,12.500000,700,1,14.280000,100,1,12.460000,200,2,14.400000,100,1,12.430000,700,1,14.560000,800,2,12.420000,700,1,14.600000,700,1,12.370000,700,1,14.680000,1400,2,12.360000,200,2,14.720000,100,1,ARL,316924721
2025-07-17T15:58:14.484312532Z,2025-07-17T15:58:14.484147359Z,10,2,1108,A,A,2,13.79,100,130,165173,267657020,13.040000,2,1,13.760000,4,1,13.030000,100,1,13.770000,100,1,12.730000,100,1,13.790000,100,1,12.710000,100,1,14.100000,2,1,12.500000,700,1,14.260000,100,1,12.460000,200,2,14.280000,100,1,12.430000,700,1,14.400000,100,1,12.420000,700,1,14.560000,800,2,12.370000,700,1,14.600000,700,1,12.360000,200,2,14.680000,1400,2,ARL,320484661
2025-07-17T15:58:14.484902175Z,2025-07-17T15:58:14.484736787Z,10,2,1108,C,A,14,15.06,100,0,165388,267657063,13.040000,2,1,13.760000,4,1,13.030000,100,1,13.770000,100,1,12.730000,100,1,13.790000,100,1,12.710000,100,1,14.100000,2,1,12.500000,700,1,14.260000,100,1,12.460000,200,2,14.280000,100,1,12.430000,700,1,14.400000,100,1,12.420000,700,1,14.560000,800,2,12.370000,700,1,14.600000,700,1,12.360000,200,2,14.680000,1400,2,ARL,319985497
2025-07-17T15:58:14.484902175Z,2025-07-17T15:58:14.484736787Z,10,2,1108,A,A,-1,14.84,100,130,165388,267657063,13.040000,2,1,13.760000,4,1,13.030000,100,1,13.770000,100,1,12.730000,100,1,13.790000,100,1,12.710000,100,1,14.100000,2,1,12.500000,700,1,14.260000,100,1,12.460000,200,2,14.280000,100,1,12.430000,700,1,14.400000,100,1,12.420000,700,1,14.560000,800,2,12.370000,700,1,14.600000,700,1,12.360000,200,2,14.680000,1400,2,ARL,320484709
2025-07-17T15:58:14.484927848Z,2025-07-17T15:58:14.484761664Z,10,2,1108,C,A,0,13.76,4,128,166184,267657070,13.040000,2,1,13.770000,100,1,13.030000,100,1,13.790000,100,1,12.730000,100,1,14.100000,2,1,12.710000,100,1,14.260000,100,1,12.500000,700,1,14.280000,100,1,12.460000,200,2,14.400000,100,1,12.430000,700,1,14.560000,800,2,12.420000,700,1,14.600000,700,1,12.370000,700,1,14.680000,1400,2,12.360000,200,2,14.720000,100,1,ARL,320484625
2025-07-17T15:58:14.484963870Z,2025-07-17T15:58:14.484798779Z,10,2,1108,C,A,0,13.77,100,130,165091,267657073,13.040000,2,1,13.790000,100,1,13.030000,100,1,14.100000,2,1,12.730000,100,1,14.260000,100,1,12.710000,100,1,14.280000,100,1,12.500000,700,1,14.400000,100,1,12.460000,200,2,14.560000,800,2,12.430000,700,1,14.600000,700,1,12.420000,700,1,14.680000,1400,2,12.370000,700,1,14.720000,100,1,12.360000,200,2,14.810000,100,1,ARL,320484637
2025-07-17T15:58:14.485392903Z,2025-07-17T15:58:14.485227487Z,10,2,1108,C,A,9,14.81,100,0,165416,267657092,13.040000,2,1,13.790000,100,1,13.030000,100,1,14.100000,2,1,12.730000,100,1,14.260000,100,1,12.710000,100,1,14.280000,100,1,12.500000,700,1,14.400000,100,1,12.460000,200,2,14.560000,800,2,12.430000,700,1,14.600000,700,1,12.420000,700,1,14.680000,1400,2,12.370000,700,1,14.720000,100,1,12.360000,200,2,14.840000,100,1,ARL,312771781
2025-07-17T15:58:14.485392903Z,2025-07-17T15:58:14.485227487Z,10,2,1108,A,A,7,14.68,100,130,165416,267657092,13.040000,2,1,13.790000,100,1,13.030000,100,1,14.100000,2,1,12.730000,100,1,14.260000,100,1,12.710000,100,1,14.280000,100,1,12.500000,700,1,14.400000,100,1,12.460000,200,2,14.560000,800,2,12.430000,700,1,14.600000,700,1,12.420000,700,1,14.680000,1500,3,12.370000,700,1,14.720000,100,1,12.360000,200,2,14.840000,100,1,ARL,320484781
2025-07-17T15:58:14.485831602Z,2025-07-17T15:58:14.485666254Z,10,2,1108,C,A,16,16.02,100,0,165348,267657097,13.040000,2,1,13.790000,100,1,13.030000,100,1,14.100000,2,1,12.730000,100,1,14.260000,100,1,12.710000,100,1,14.280000,100,1,12.500000,700,1,14.400000,100,1,12.460000,200,2,14.560000,800,2,12.430000,700,1,14.600000,700,1,12.420000,700,1,14.680000,1500,3,12.370000,700,1,14.720000,100,1,12.360000,200,2,14.840000,100,1,ARL,312772057
2025-07-17T15:58:14.485831602Z,2025-07-17T15:58:14.485666254Z,10,2,1108,A,A,-1,15.86,100,130,165348,267657097,13.040000,2,1,13.790000,100,1,13.030000,100,1,14.100000,2,1,12.730000,100,1,14.260000,100,1,12.710000,100,1,14.280000,100,1,12.500000,700,1,14.400000,100,1,12.460000,200,2,14.560000,800,2,12.430000,700,1,14.600000,700,1,12.420000,700,1,14.680000,1500,3,12.370000,700,1,14.720000,100,1,12.360000,200,2,14.840000,100,1,ARL,320484817
2025-07-17T15:58:14.485850874Z,2025-07-17T15:58:14.485685308Z,10,2,1108,C,A,11,14.96,100,0,165566,267657098,13.040000,2,1,13.790000,100,1,13.030000,100,1,14.100000,2,1,12.730000,100,1,14.260000,100,1,12.710000,100,1,14.280000,100,1,12.500000,700,1,14.400000,100,1,12.460000,200,2,14.560000,800,2,12.430000,700,1,14.600000,700,1,12.420000,700,1,14.680000,1500,3,12.370000,700,1,14.720000,100,1,12.360000,200,2,14.840000,100,1,ARL,312772869
2025-07-17T15:58:14.485850874Z,2025-07-17T15:58:14.485685308Z,10,2,1108,A,A,9,14.76,100,130,165566,267657098,13.040000,2,1,13.790000,100,1,13.030000,100,1,14.100000,2,1,12.730000,100,1,14.260000,100,1,12.710000,100,1,14.280000,100,1,12.500000,700,1,14.400000,100,1,12.460000,200,2,14.560000,800,2,12.430000,700,1,14.600000,700,1,12.420000,700,1,14.680000,1500,3,12.370000,700,1,14.720000,100,1,12.360000,200,2,14.760000,100,1,ARL,320484821
2025-07-17T15:58:14.485989643Z,2025-07-17T15:58:14.485824228Z,10,2,1108,C,A,11,14.89,100,0,165415,267657101,13.040000,2,1,13.790000,100,1,13.030000,100,1,14.100000,2,1,12.730000,100,1,14.260000,100,1,12.710000,100,1,14.280000,100,1,12.500000,700,1,14.400000,100,1,12.460000,200,2,14.560000,800,2,12.430000,700,1,14.600000,700,1,12.420000,700,1,14.680000,1500,3,12.370000,700,1,14.720000,100,1,12.360000,200,2,14.760000,100,1,ARL,319985025
2025-07-17T15:58:14.485989643Z,2025-07-17T15:58:14.485824228Z,10,2,1108,A,A,8,14.69,100,130,165415,267657101,13.040000,2,1,13.790000,100,1,13.030000,100,1,14.100000,2,1,12.730000,100,1,14.260000,100,1,12.710000,100,1,14.280000,100,1,12.500000,700,1,14.400000,100,1,12.460000,200,2,14.560000,800,2,12.430000,700,1,14.600000,700,1,12.420000,700,1,14.680000,1500,3,12.370000,700,1,14.690000,100,1,12.360000,200,2,14.720000,100,1,ARL,320484825
2025-07-17T15:58:14.486406355Z,2025-07-17T15:58:14.486240860Z,10,2,1108,C,A,19,17.70,100,0,165495,267657116,13.040000,2,1,13.790000,100,1,13.030000,100,1,14.100000,2,1,12.730000,100,1,14.260000,100,1,12.710000,100,1,14.280000,100,1,12.500000,700,1,14.400000,100,1,12.460000,200,2,14.560000,800,2,12.430000,700,1,14.600000,700,1,12.420000,700,1,14.680000,1500,3,12.370000,700,1,14.690000,100,1,12.360000,200,2,14.720000,100,1,ARL,312772009
2025-07-17T15:58:14.486406355Z,2025-07-17T15:58:14.486240860Z,10,2,1108,A,A,-1,17.52,100,130,165495,267657116,13.040000,2,1,13.790000,100,1,13.030000,100,1,14.100000,2,1,12.730000,100,1,14.260000,100,1,12.710000,100,1,14.280000,100,1,12.500000,700,1,14.400000,100,1,12.460000,200,2,14.560000,800,2,12.430000,700,1,14.600000,700,1,12.420000,700,1,14.680000,1500,3,12.370000,700,1,14.690000,100,1,12.360000,200,2,14.720000,100,1,ARL,320484837
2025-07-17T15:58:14.508177256Z,2025-07-17T15:58:14.508012098Z,10,2,1108,C,A,2,14.26,100,130,165158,267657330,13.040000,2,1,13.790000,100,1,13.030000,100,1,14.100000,2,1,12.730000,100,1,14.280000,100,1,12.710000,100,1,14.400000,100,1,12.500000,700,1,14.560000,800,2,12.460000,200,2,14.600000,700,1,12.430000,700,1,14.680000,1500,3,12.420000,700,1,14.690000,100,1,12.370000,700,1,14.720000,100,1,12.360000,200,2,14.760000,100,1,ARL,319985165
2025-07-17T15:58:14.508227890Z,2025-07-17T15:58:14.508062605Z,10,2,1108,A,A,1,14.05,100,130,165285,267657333,13.040000,2,1,13.790000,100,1,13.030000,100,1,14.050000,100,1,12.730000,100,1,14.100000,2,1,12.710000,100,1,14.280000,100,1,12.500000,700,1,14.400000,100,1,12.460000,200,2,14.560000,800,2,12.430000,700,1,14.600000,700,1,12.420000,700,1,14.680000,1500,3,12.370000,700,1,14.690000,100,1,12.360000,200,2,14.720000,100,1,ARL,320484985
2025-07-17T15:58:14.529557108Z,2025-07-17T15:58:14.529391743Z,10,2,1108,A,B,2,13.02,100,130,165365,267657561,13.040000,2,1,13.790000,100,1,13.030000,100,1,14.050000,100,1,13.020000,100,1,14.100000,2,1,12.730000,100,1,14.280000,100,1,12.710000,100,1,14.400000,100,1,12.500000,700,1,14.560000,800,2,12.460000,200,2,14.600000,700,1,12.430000,700,1,14.680000,1500,3,12.420000,700,1,14.690000,100,1,12.370000,700,1,14.720000,100,1,ARL,320485385
2025-07-17T15:58:14.529578291Z,2025-07-17T15:58:14.529413184Z,10,2,1108,A,A,1,13.80,100,130,165107,267657562,13.040000,2,1,13.790000,100,1,13.030000,100,1,13.800000,100,1,13.020000,100,1,14.050000,100,1,12.730000,100,1,14.100000,2,1,12.710000,100,1,14.280000,100,1,12.500000,700,1,14.400000,100,1,12.460000,200,2,14.560000,800,2,12.430000,700,1,14.600000,700,1,12.420000,700,1,14.680000,1500,3,12.370000,700,1,14.690000,100,1,ARL,320485389
2025-07-17T15:58:14.659899426Z,2025-07-17T15:58:14.659734381Z,10,2,1108,C,A,0,13.79,100,130,165045,267658873,13.040000,2,1,13.800000,100,1,13.030000,100,1,14.050000,100,1,13.020000,100,1,14.100000,2,1,12.730000,100,1,14.280000,100,1,12.710000,100,1,14.400000,100,1,12.500000,700,1,14.560000,800,2,12.460000,200,2,14.600000,700,1,12.430000,700,1,14.680000,1500,3,12.420000,700,1,14.690000,100,1,12.370000,700,1,14.720000,100,1,ARL,320484661
2025-07-17T15:58:14.659939230Z,2025-07-17T15:58:14.659773896Z,10,2,1108,C,A,0,13.80,100,130,165334,267658879,13.040000,2,1,14.050000,100,1,13.030000,100,1,14.100000,2,1,13.020000,100,1,14.280000,100,1,12.730000,100,1,14.400000,100,1,12.710000,100,1,14.560000,800,2,12.500000,700,1,14.600000,700,1,12.460000,200,2,14.680000,1500,3,12.430000,700,1,14.690000,100,1,12.420000,700,1,14.720000,100,1,12.370000,700,1,14.760000,100,1,ARL,320485389
2025-07-17T15:58:14.660667636Z,2025-07-17T15:58:14.660502341Z,10,2,1108,C,A,10,14.84,100,0,165295,267658892,13.040000,2,1,14.050000,100,1,13.030000,100,1,14.100000,2,1,13.020000,100,1,14.280000,100,1,12.730000,100,1,14.400000,100,1,12.710000,100,1,14.560000,800,2,12.500000,700,1,14.600000,700,1,12.460000,200,2,14.680000,1500,3,12.430000,700,1,14.690000,100,1,12.420000,700,1,14.720000,100,1,12.370000,700,1,14.760000,100,1,ARL,320484709
2025-07-17T15:58:14.660667636Z,2025-07-17T15:58:14.660502341Z,10,2,1108,A,A,-1,14.91,100,130,165295,267658892,13.040000,2,1,14.050000,100,1,13.030000,100,1,14.100000,2,1,13.020000,100,1,14.280000,100,1,12.730000,100,1,14.400000,100,1,12.710000,100,1,14.560000,800,2,12.500000,700,1,14.600000,700,1,12.460000,200,2,14.680000,1500,3,12.430000,700,1,14.690000,100,1,12.420000,700,1,14.720000,100,1,12.370000,700,1,14.760000,100,1,ARL,320486925
2025-07-17T15:58:14.664378962Z,2025-07-17T15:58:14.664213722Z,10,2,1108,C,A,18,17.52,100,0,165240,267658928,13.040000,2,1,14.050000,100,1,13.030000,100,1,14.100000,2,1,13.020000,100,1,14.280000,100,1,12.730000,100,1,14.400000,100,1,12.710000,100,1,14.560000,800,2,12.500000,700,1,14.600000,700,1,12.460000,200,2,14.680000,1500,3,12.430000,700,1,14.690000,100,1,12.420000,700,1,14.720000,100,1,12.370000,700,1,14.760000,100,1,ARL,320484837
2025-07-17T15:58:14.664378962Z,2025-07-17T15:58:14.664213722Z,10,2,1108,A,A,-1,17.76,100,130,165240,267658928,13.040000,2,1,14.050000,100,1,13.030000,100,1,14.100000,2,1,13.020000,100,1,14.280000,100,1,12.730000,100,1,14.400000,100,1,12.710000,100,1,14.560000,800,2,12.500000,700,1,14.600000,700,1,12.460000,200,2,14.680000,1500,3,12.430000,700,1,14.690000,100,1,12.420000,700,1,14.720000,100,1,12.370000,700,1,14.760000,100,1,ARL,320486937
2025-07-17T15:58:14.664939310Z,2025-07-17T15:58:14.664774078Z,10,2,1108,C,A,15,15.86,100,0,165232,267658931,13.040000,2,1,14.050000,100,1,13.030000,100,1,14.100000,2,1,13.020000,100,1,14.280000,100,1,12.730000,100,1,14.400000,100,1,12.710000,100,1,14.560000,800,2,12.500000,700,1,14.600000,700,1,12.460000,200,2,14.680000,1500,3,12.430000,700,1,14.690000,100,1,12.420000,700,1,14.720000,100,1,12.370000,700,1,14.760000,100,1,ARL,320484817
2025-07-17T15:58:14.664939310Z,2025-07-17T15:58:14.664774078Z,10,2,1108,A,A,-1,16.08,100,130,165232,267658931,13.040000,2,1,14.050000,100,1,13.030000,100,1,14.100000,2,1,13.020000,100,1,14.280000,100,1,12.730000,100,1,14.400000,100,1,12.710000,100,1,14.560000,800,2,12.500000,700,1,14.600000,700,1,12.460000,200,2,14.680000,1500,3,12.430000,700,1,14.690000,100,1,12.420000,700,1,14.720000,100,1,12.370000,700,1,14.760000,100,1,ARL,320486945
2025-07-17T15:58:14.672315806Z,2025-07-17T15:58:14.672150755Z,10,2,1108,C,A,0,14.05,100,130,165051,267658982,13.040000,2,1,14.100000,2,1,13.030000,100,1,14.280000,100,1,13.020000,100,1,14.400000,100,1,12.730000,100,1,14.560000,800,2,12.710000,100,1,14.600000,700,1,12.500000,700,1,14.680000,1500,3,12.460000,200,2,14.690000,100,1,12.430000,700,1,14.720000,100,1,12.420000,700,1,14.760000,100,1,12.370000,700,1,14.890000,100,1,ARL,320484985
2025-07-17T15:58:14.672365974Z,2025-07-17T15:58:14.672200872Z,10,2,1108,A,A,1,14.12,100,130,165102,267658983,13.040000,2,1,14.100000,2,1,13.030000,100,1,14.120000,100,1,13.020000,100,1,14.280000,100,1,12.730000,100,1,14.400000,100,1,12.710000,100,1,14.560000,800,2,12.500000,700,1,14.600000,700,1,12.460000,200,2,14.680000,1500,3,12.430000,700,1,14.690000,100,1,12.420000,700,1,14.720000,100,1,12.370000,700,1,14.760000,100,1,ARL,320487017
2025-07-17T15:58:14.673184116Z,2025-07-17T15:58:14.673019194Z,10,2,1108,C,A,1,14.12,100,130,164922,267658989,13.040000,2,1,14.100000,2,1,13.030000,100,1,14.280000,100,1,13.020000,100,1,14.400000,100,1,12.730000,100,1,14.560000,800,2,12.710000,100,1,14.600000,700,1,12.500000,700,1,14.680000,1500,3,12.460000,200,2,14.690000,100,1,12.430000,700,1,14.720000,100,1,12.420000,700,1,14.760000,100,1,12.370000,700,1,14.890000,100,1,ARL,320487017
2025-07-17T15:58:14.673230480Z,2025-07-17T15:58:14.673065320Z,10,2,1108,A,A,1,14.26,100,130,165160,267658990,13.040000,2,1,14.100000,2,1,13.030000,100,1,14.260000,100,1,13.020000,100,1,14.280000,100,1,12.730000,100,1,14.400000,100,1,12.710000,100,1,14.560000,800,2,12.500000,700,1,14.600000,700,1,12.460000,200,2,14.680000,1500,3,12.430000,700,1,14.690000,100,1,12.420000,700,1,14.720000,100,1,12.370000,700,1,14.760000,100,1,ARL,320487025
2025-07-17T15:58:14.682945541Z,2025-07-17T15:58:14.682780396Z,10,2,1108,C,A,9,14.76,100,0,165145,267659018,13.040000,2,1,14.100000,2,1,13.030000,100,1,14.260000,100,1,13.020000,100,1,14.280000,100,1,12.730000,100,1,14.400000,100,1,12.710000,100,1,14.560000,800,2,12.500000,700,1,14.600000,700,1,12.460000,200,2,14.680000,1500,3,12.430000,700,1,14.690000,100,1,12.420000,700,1,14.720000,100,1,12.370000,700,1,14.890000,100,1,ARL,320484821
2025-07-17T15:58:14.682945541Z,2025-07-17T15:58:14.682780396Z,10,2,1108,A,A,-1,14.96,100,130,165145,267659018,13.040000,2,1,14.100000,2,1,13.030000,100,1,14.260000,100,1,13.020000,100,1,14.280000,100,1,12.730000,100,1,14.400000,100,1,12.710000,100,1,14.560000,800,2,12.500000,700,1,14.600000,700,1,12.460000,200,2,14.680000,1500,3,12.430000,700,1,14.690000,100,1,12.420000,700,1,14.720000,100,1,12.370000,700,1,14.890000,100,1,ARL,320487105
2025-07-17T15:58:14.710787891Z,2025-07-17T15:58:14.710622495Z,10,2,1108,C,A,10,14.91,100,0,165396,267659178,13.040000,2,1,14.100000,2,1,13.030000,100,1,14.260000,100,1,13.020000,100,1,14.280000,100,1,12.730000,100,1,14.400000,100,1,12.710000,100,1,14.560000,800,2,12.500000,700,1,14.600000,700,1,12.460000,200,2,14.680000,1500,3,12.430000,700,1,14.690000,100,1,12.420000,700,1,14.720000,100,1,12.370000,700,1,14.890000,100,1,ARL,320486925
2025-07-17T15:58:14.710787891Z,2025-07-17T15:58:14.710622495Z,10,2,1108,A,A,-1,15.06,100,130,165396,267659178,13.040000,2,1,14.100000,2,1,13.030000,100,1,14.260000,100,1,13.020000,100,1,14.280000,100,1,12.730000,100,1,14.400000,100,1,12.710000,100,1,14.560000,800,2,12.500000,700,1,14.600000,700,1,12.460000,200,2,14.680000,1500,3,12.430000,700,1,14.690000,100,1,12.420000,700,1,14.720000,100,1,12.370000,700,1,14.890000,100,1,ARL,320487357
2025-07-17T15:58:15.564070256Z,2025-07-17T15:58:15.563904700Z,10,2,1108,C,A,6,14.68,100,0,165556,267672469,13.040000,2,1,14.100000,2,1,13.030000,100,1,14.260000,100,1,13.020000,100,1,14.280000,100,1,12.730000,100,1,14.400000,100,1,12.710000,100,1,14.560000,800,2,12.500000,700,1,14.600000,700,1,12.460000,200,2,14.680000,1400,2,12.430000,700,1,14.690000,100,1,12.420000,700,1,14.720000,100,1,12.370000,700,1,14.890000,100,1,ARL,320484781
2025-07-17T15:58:15.564070256Z,2025-07-17T15:58:15.563904700Z,10,2,1108,A,A,9,14.87,100,130,165556,267672469,13.040000,2,1,14.100000,2,1,13.030000,100,1,14.260000,100,1,13.020000,100,1,14.280000,100,1,12.730000,100,1,14.400000,100,1,12.710000,100,1,14.560000,800,2,12.500000,700,1,14.600000,700,1,12.460000,200,2,14.680000,1400,2,12.430000,700,1,14.690000,100,1,12.420000,700,1,14.720000,100,1,12.370000,700,1,14.870000,100,1,ARL,320504473
2025-07-17T15:58:15.577719796Z,2025-07-17T15:58:15.577554368Z,10,2,1108,C,A,7,14.69,100,0,165428,267672549,13.040000,2,1,14.100000,2,1,13.030000,100,1,14.260000,100,1,13.020000,100,1,14.280000,100,1,12.730000,100,1,14.400000,100,1,12.710000,100,1,14.560000,800,2,12.500000,700,1,14.600000,700,1,12.460000,200,2,14.680000,1400,2,12.430000,700,1,14.720000,100,1,12.420000,700,1,14.870000,100,1,12.370000,700,1,14.890000,100,1,ARL,320484825
2025-07-17T15:58:15.577719796Z,2025-07-17T15:58:15.577554368Z,10,2,1108,A,A,9,14.88,100,130,165428,267672549,13.040000,2,1,14.100000,2,1,13.030000,100,1,14.260000,100,1,13.020000,100,1,14.280000,100,1,12.730000,100,1,14.400000,100,1,12.710000,100,1,14.560000,800,2,12.500000,700,1,14.600000,700,1,12.460000,200,2,14.680000,1400,2,12.430000,700,1,14.720000,100,1,12.420000,700,1,14.870000,100,1,12.370000,700,1,14.880000,100,1,ARL,320504609
2025-07-17T15:58:16.502080515Z,2025-07-17T15:58:16.501915292Z,10,2,1108,A,A,1,14.11,100,130,165223,267685252,13.040000,2,1,14.100000,2,1,13.030000,100,1,14.110000,100,1,13.020000,100,1,14.260000,100,1,12.730000,100,1,14.280000,100,1,12.710000,100,1,14.400000,100,1,12.500000,700,1,14.560000,800,2,12.460000,200,2,14.600000,700,1,12.430000,700,1,14.680000,1400,2,12.420000,700,1,14.720000,100,1,12.370000,700,1,14.870000,100,1,ARL,320519893
2025-07-17T15:58:19.965200980Z,2025-07-17T15:58:19.965034325Z,10,2,1108,A,A,0,13.94,15,130,166655,267738403,13.040000,2,1,13.940000,15,1,13.030000,100,1,14.100000,2,1,13.020000,100,1,14.110000,100,1,12.730000,100,1,14.260000,100,1,12.710000,100,1,14.280000,100,1,12.500000,700,1,14.400000,100,1,12.460000,200,2,14.560000,800,2,12.430000,700,1,14.600000,700,1,12.420000,700,1,14.680000,1400,2,12.370000,700,1,14.720000,100,1,ARL,320588689
2025-07-17T15:58:20.237833402Z,2025-07-17T15:58:20.237668047Z,10,2,1108,C,A,2,14.11,100,0,165355,267745213,13.040000,2,1,13.940000,15,1,13.030000,100,1,14.100000,2,1,13.020000,100,1,14.260000,100,1,12.730000,100,1,14.280000,100,1,12.710000,100,1,14.400000,100,1,12.500000,700,1,14.560000,800,2,12.460000,200,2,14.600000,700,1,12.430000,700,1,14.680000,1400,2,12.420000,700,1,14.720000,100,1,12.370000,700,1,14.870000,100,1,ARL,320519893
2025-07-17T15:58:20.237833402Z,2025-07-17T15:58:20.237668047Z,10,2,1108,A,A,1,13.95,100,130,165355,267745213,13.040000,2,1,13.940000,15,1,13.030000,100,1,13.950000,100,1,13.020000,100,1,14.100000,2,1,12.730000,100,1,14.260000,100,1,12.710000,100,1,14.280000,100,1,12.500000,700,1,14.400000,100,1,12.460000,200,2,14.560000,800,2,12.430000,700,1,14.600000,700,1,12.420000,700,1,14.680000,1400,2,12.370000,700,1,14.720000,100,1,ARL,320595817
2025-07-17T15:58:20.705512171Z,2025-07-17T15:58:20.705344578Z,10,2,1108,C,A,0,13.94,15,128,167593,267754327,13.040000,2,1,13.950000,100,1,13.030000,100,1,14.100000,2,1,13.020000,100,1,14.260000,100,1,12.730000,100,1,14.280000,100,1,12.710000,100,1,14.400000,100,1,12.500000,700,1,14.560000,800,2,12.460000,200,2,14.600000,700,1,12.430000,700,1,14.680000,1400,2,12.420000,700,1,14.720000,100,1,12.370000,700,1,14.870000,100,1,ARL,320588689
2025-07-17T15:58:30.800053062Z,2025-07-17T15:58:30.799887713Z,10,2,1108,A,A,0,13.89,15,130,165349,267913947,13.040000,2,1,13.890000,15,1,13.030000,100,1,13.950000,100,1,13.020000,100,1,14.100000,2,1,12.730000,100,1,14.260000,100,1,12.710000,100,1,14.280000,100,1,12.500000,700,1,14.400000,100,1,12.460000,200,2,14.560000,800,2,12.430000,700,1,14.600000,700,1,12.420000,700,1,14.680000,1400,2,12.370000,700,1,14.720000,100,1,ARL,320833897
2025-07-17T15:58:30.905657319Z,2025-07-17T15:58:30.905491759Z,10,2,1108,C,A,1,13.95,100,0,165560,267919515,13.040000,2,1,13.890000,15,1,13.030000,100,1,14.100000,2,1,13.020000,100,1,14.260000,100,1,12.730000,100,1,14.280000,100,1,12.710000,100,1,14.400000,100,1,12.500000,700,1,14.560000,800,2,12.460000,200,2,14.600000,700,1,12.430000,700,1,14.680000,1400,2,12.420000,700,1,14.720000,100,1,12.370000,700,1,14.870000,100,1,ARL,320595817
2025-07-17T15:58:30.905657319Z,2025-07-17T15:58:30.905491759Z,10,2,1108,A,A,1,13.90,100,130,165560,267919515,13.040000,2,1,13.890000,15,1,13.030000,100,1,13.900000,100,1,13.020000,100,1,14.100000,2,1,12.730000,100,1,14.260000,100,1,12.710000,100,1,14.280000,100,1,12.500000,700,1,14.400000,100,1,12.460000,200,2,14.560000,800,2,12.430000,700,1,14.600000,700,1,12.420000,700,1,14.680000,1400,2,12.370000,700,1,14.720000,100,1,ARL,320839125
2025-07-17T15:58:30.906412286Z,2025-07-17T15:58:30.906246950Z,10,2,1108,C,A,14,15.06,100,0,165336,267919540,13.040000,2,1,13.890000,15,1,13.030000,100,1,13.900000,100,1,13.020000,100,1,14.100000,2,1,12.730000,100,1,14.260000,100,1,12.710000,100,1,14.280000,100,1,12.500000,700,1,14.400000,100,1,12.460000,200,2,14.560000,800,2,12.430000,700,1,14.600000,700,1,12.420000,700,1,14.680000,1400,2,12.370000,700,1,14.720000,100,1,ARL,320487357
2025-07-17T15:58:30.906412286Z,2025-07-17T15:58:30.906246950Z,10,2,1108,A,A,-1,14.98,100,130,165336,267919540,13.040000,2,1,13.890000,15,1,13.030000,100,1,13.900000,100,1,13.020000,100,1,14.100000,2,1,12.730000,100,1,14.260000,100,1,12.710000,100,1,14.280000,100,1,12.500000,700,1,14.400000,100,1,12.460000,200,2,14.560000,800,2,12.430000,700,1,14.600000,700,1,12.420000,700,1,14.680000,1400,2,12.370000,700,1,14.720000,100,1,ARL,320839149
2025-07-17T15:58:30.916726353Z,2025-07-17T15:58:30.916561264Z,10,2,1108,C,A,3,14.26,100,130,165089,267919917,13.040000,2,1,13.890000,15,1,13.030000,100,1,13.900000,100,1,13.020000,100,1,14.100000,2,1,12.730000,100,1,14.280000,100,1,12.710000,100,1,14.400000,100,1,12.500000,700,1,14.560000,800,2,12.460000,200,2,14.600000,700,1,12.430000,700,1,14.680000,1400,2,12.420000,700,1,14.720000,100,1,12.370000,700,1,14.870000,100,1,ARL,320487025
2025-07-17T15:58:30.916784278Z,2025-07-17T15:58:30.916619122Z,10,2,1108,A,A,3,14.18,100,130,165156,267919919,13.040000,2,1,13.890000,15,1,13.030000,100,1,13.900000,100,1,13.020000,100,1,14.100000,2,1,12.730000,100,1,14.180000,100,1,12.710000,100,1,14.280000,100,1,12.500000,700,1,14.400000,100,1,12.460000,200,2,14.560000,800,2,12.430000,700,1,14.600000,700,1,12.420000,700,1,14.680000,1400,2,12.370000,700,1,14.720000,100,1,ARL,320839577
2025-07-17T15:58:31.124388717Z,2025-07-17T15:58:31.124222733Z,10,2,1108,C,A,10,14.87,100,0,165984,267925564,13.040000,2,1,13.890000,15,1,13.030000,100,1,13.900000,100,1,13.020000,100,1,14.100000,2,1,12.730000,100,1,14.180000,100,1,12.710000,100,1,14.280000,100,1,12.500000,700,1,14.400000,100,1,12.460000,200,2,14.560000,800,2,12.430000,700,1,14.600000,700,1,12.420000,700,1,14.680000,1400,2,12.370000,700,1,14.720000,100,1,ARL,320504473
2025-07-17T15:58:31.124388717Z,2025-07-17T15:58:31.124222733Z,10,2,1108,A,A,-1,14.76,100,130,165984,267925564,13.040000,2,1,13.890000,15,1,13.030000,100,1,13.900000,100,1,13.020000,100,1,14.100000,2,1,12.730000,100,1,14.180000,100,1,12.710000,100,1,14.280000,100,1,12.500000,700,1,14.400000,100,1,12.460000,200,2,14.560000,800,2,12.430000,700,1,14.600000,700,1,12.420000,700,1,14.680000,1400,2,12.370000,700,1,14.720000,100,1,ARL,320845893
2025-07-17T15:58:31.136439248Z,2025-07-17T15:58:31.136273403Z,10,2,1108,C,A,11,14.88,100,0,165845,267925951,13.040000,2,1,13.890000,15,1,13.030000,100,1,13.900000,100,1,13.020000,100,1,14.100000,2,1,12.730000,100,1,14.180000,100,1,12.710000,100,1,14.280000,100,1,12.500000,700,1,14.400000,100,1,12.460000,200,2,14.560000,800,2,12.430000,700,1,14.600000,700,1,12.420000,700,1,14.680000,1400,2,12.370000,700,1,14.720000,100,1,ARL,320504609
2025-07-17T15:58:31.136439248Z,2025-07-17T15:58:31.136273403Z,10,2,1108,A,A,-1,14.77,100,130,165845,267925951,13.040000,2,1,13.890000,15,1,13.030000,100,1,13.900000,100,1,13.020000,100,1,14.100000,2,1,12.730000,100,1,14.180000,100,1,12.710000,100,1,14.280000,100,1,12.500000,700,1,14.400000,100,1,12.460000,200,2,14.560000,800,2,12.430000,700,1,14.600000,700,1,12.420000,700,1,14.680000,1400,2,12.370000,700,1,14.720000,100,1,ARL,320846429
2025-07-17T15:58:40.799952243Z,2025-07-17T15:58:40.799787018Z,10,2,1108,A,A,0,13.83,15,130,165225,268074431,13.040000,2,1,13.830000,15,1,13.030000,100,1,13.890000,15,1,13.020000,100,1,13.900000,100,1,12.730000,100,1,14.100000,2,1,12.710000,100,1,14.180000,100,1,12.500000,700,1,14.280000,100,1,12.460000,200,2,14.400000,100,1,12.430000,700,1,14.560000,800,2,12.420000,700,1,14.600000,700,1,12.370000,700,1,14.680000,1400,2,ARL,321038033
2025-07-17T15:58:43.690244473Z,2025-07-17T15:58:43.690078924Z,10,2,1108,C,A,2,13.90,100,0,165549,268115228,13.040000,2,1,13.830000,15,1,13.030000,100,1,13.890000,15,1,13.020000,100,1,14.100000,2,1,12.730000,100,1,14.180000,100,1,12.710000,100,1,14.280000,100,1,12.500000,700,1,14.400000,100,1,12.460000,200,2,14.560000,800,2,12.430000,700,1,14.600000,700,1,12.420000,700,1,14.680000,1400,2,12.370000,700,1,14.720000,100,1,ARL,320839125
2025-07-17T15:58:43.690244473Z,2025-07-17T15:58:43.690078924Z,10,2,1108,A,A,1,13.84,100,130,165549,268115228,13.040000,2,1,13.830000,15,1,13.030000,100,1,13.840000,100,1,13.020000,100,1,13.890000,15,1,12.730000,100,1,14.100000,2,1,12.710000,100,1,14.180000,100,1,12.500000,700,1,14.280000,100,1,12.460000,200,2,14.400000,100,1,12.430000,700,1,14.560000,800,2,12.420000,700,1,14.600000,700,1,12.370000,700,1,14.680000,1400,2,ARL,321096769
2025-07-17T15:58:43.690988921Z,2025-07-17T15:58:43.690823184Z,10,2,1108,C,A,15,14.98,100,0,165737,268115235,13.040000,2,1,13.830000,15,1,13.030000,100,1,13.840000,100,1,13.020000,100,1,13.890000,15,1,12.730000,100,1,14.100000,2,1,12.710000,100,1,14.180000,100,1,12.500000,700,1,14.280000,100,1,12.460000,200,2,14.400000,100,1,12.430000,700,1,14.560000,800,2,12.420000,700,1,14.600000,700,1,12.370000,700,1,14.680000,1400,2,ARL,320839149
2025-07-17T15:58:43.690988921Z,2025-07-17T15:58:43.690823184Z,10,2,1108,A,A,-1,14.91,100,130,165737,268115235,13.040000,2,1,13.830000,15,1,13.030000,100,1,13.840000,100,1,13.020000,100,1,13.890000,15,1,12.730000,100,1,14.100000,2,1,12.710000,100,1,14.180000,100,1,12.500000,700,1,14.280000,100,1,12.460000,200,2,14.400000,100,1,12.430000,700,1,14.560000,800,2,12.420000,700,1,14.600000,700,1,12.370000,700,1,14.680000,1400,2,ARL,321096793
2025-07-17T15:58:43.693394500Z,2025-07-17T15:58:43.693228946Z,10,2,1108,C,A,22,17.76,100,0,165554,268115265,13.040000,2,1,13.830000,15,1,13.030000,100,1,13.840000,100,1,13.020000,100,1,13.890000,15,1,12.730000,100,1,14.100000,2,1,12.710000,100,1,14.180000,100,1,12.500000,700,1,14.280000,100,1,12.460000,200,2,14.400000,100,1,12.430000,700,1,14.560000,800,2,12.420000,700,1,14.600000,700,1,12.370000,700,1,14.680000,1400,2,ARL,320486937
2025-07-17T15:58:43.693394500Z,2025-07-17T15:58:43.693228946Z,10,2,1108,A,A,-1,17.58,100,130,165554,268115265,13.040000,2,1,13.830000,15,1,13.030000,100,1,13.840000,100,1,13.020000,100,1,13.890000,15,1,12.730000,100,1,14.100000,2,1,12.710000,100,1,14.180000,100,1,12.500000,700,1,14.280000,100,1,12.460000,200,2,14.400000,100,1,12.430000,700,1,14.560000,800,2,12.420000,700,1,14.600000,700,1,12.370000,700,1,14.680000,1400,2,ARL,321096825
2025-07-17T15:58:43.695055785Z,2025-07-17T15:58:43.694890264Z,10,2,1108,C,A,20,16.08,100,0,165521,268115287,13.040000,2,1,13.830000,15,1,13.030000,100,1,13.840000,100,1,13.020000,100,1,13.890000,15,1,12.730000,100,1,14.100000,2,1,12.710000,100,1,14.180000,100,1,12.500000,700,1,14.280000,100,1,12.460000,200,2,14.400000,100,1,12.430000,700,1,14.560000,800,2,12.420000,700,1,14.600000,700,1,12.370000,700,1,14.680000,1400,2,ARL,320486945
2025-07-17T15:58:43.695055785Z,2025-07-17T15:58:43.694890264Z,10,2,1108,A,A,-1,15.92,100,130,165521,268115287,13.040000,2,1,13.830000,15,1,13.030000,100,1,13.840000,100,1,13.020000,100,1,13.890000,15,1,12.730000,100,1,14.100000,2,1,12.710000,100,1,14.180000,100,1,12.500000,700,1,14.280000,100,1,12.460000,200,2,14.400000,100,1,12.430000,700,1,14.560000,800,2,12.420000,700,1,14.600000,700,1,12.370000,700,1,14.680000,1400,2,ARL,321096889
2025-07-17T15:58:43.716437124Z,2025-07-17T15:58:43.716271172Z,10,2,1108,C,A,15,14.96,100,0,165952,268115456,13.040000,2,1,13.830000,15,1,13.030000,100,1,13.840000,100,1,13.020000,100,1,13.890000,15,1,12.730000,100,1,14.100000,2,1,12.710000,100,1,14.180000,100,1,12.500000,700,1,14.280000,100,1,12.460000,200,2,14.400000,100,1,12.430000,700,1,14.560000,800,2,12.420000,700,1,14.600000,700,1,12.370000,700,1,14.680000,1400,2,ARL,320487105
2025-07-17T15:58:43.716437124Z,2025-07-17T15:58:43.716271172Z,10,2,1108,A,A,-1,14.81,100,130,165952,268115456,13.040000,2,1,13.830000,15,1,13.030000,100,1,13.840000,100,1,13.020000,100,1,13.890000,15,1,12.730000,100,1,14.100000,2,1,12.710000,100,1,14.180000,100,1,12.500000,700,1,14.280000,100,1,12.460000,200,2,14.400000,100,1,12.430000,700,1,14.560000,800,2,12.420000,700,1,14.600000,700,1,12.370000,700,1,14.680000,1400,2,ARL,321097197
2025-07-17T15:58:44.903740109Z,2025-07-17T15:58:44.903574654Z,10,2,1108,A,A,0,13.83,100,130,165455,268129040,13.040000,2,1,13.830000,115,2,13.030000,100,1,13.840000,100,1,13.020000,100,1,13.890000,15,1,12.730000,100,1,14.100000,2,1,12.710000,100,1,14.180000,100,1,12.500000,700,1,14.280000,100,1,12.460000,200,2,14.400000,100,1,12.430000,700,1,14.560000,800,2,12.420000,700,1,14.600000,700,1,12.370000,700,1,14.680000,1400,2,ARL,321114473
2025-07-17T15:58:44.924114268Z,2025-07-17T15:58:44.923948853Z,10,2,1108,C,A,4,14.18,100,130,165415,268129217,13.040000,2,1,13.830000,115,2,13.030000,100,1,13.840000,100,1,13.020000,100,1,13.890000,15,1,12.730000,100,1,14.100000,2,1,12.710000,100,1,14.280000,100,1,12.500000,700,1,14.400000,100,1,12.460000,200,2,14.560000,800,2,12.430000,700,1,14.600000,700,1,12.420000,700,1,14.680000,1400,2,12.370000,700,1,14.720000,100,1,ARL,320839577
2025-07-17T15:58:44.924165875Z,2025-07-17T15:58:44.924000519Z,10,2,1108,A,A,4,14.11,100,130,165356,268129218,13.040000,2,1,13.830000,115,2,13.030000,100,1,13.840000,100,1,13.020000,100,1,13.890000,15,1,12.730000,100,1,14.100000,2,1,12.710000,100,1,14.110000,100,1,12.500000,700,1,14.280000,100,1,12.460000,200,2,14.400000,100,1,12.430000,700,1,14.560000,800,2,12.420000,700,1,14.600000,700,1,12.370000,700,1,14.680000,1400,2,ARL,321114729
2025-07-17T15:58:51.241342265Z,2025-07-17T15:58:51.241176997Z,10,2,1108,C,A,2,13.89,15,130,165268,268212338,13.040000,2,1,13.830000,115,2,13.030000,100,1,13.840000,100,1,13.020000,100,1,14.100000,2,1,12.730000,100,1,14.110000,100,1,12.710000,100,1,14.280000,100,1,12.500000,700,1,14.400000,100,1,12.460000,200,2,14.560000,800,2,12.430000,700,1,14.600000,700,1,12.420000,700,1,14.680000,1400,2,12.370000,700,1,14.720000,100,1,ARL,320833897
2025-07-17T15:58:51.254127339Z,2025-07-17T15:58:51.253961905Z,10,2,1108,A,A,0,13.80,100,130,165434,268212497,13.040000,2,1,13.800000,100,1,13.030000,100,1,13.830000,115,2,13.020000,100,1,13.840000,100,1,12.730000,100,1,14.100000,2,1,12.710000,100,1,14.110000,100,1,12.500000,700,1,14.280000,100,1,12.460000,200,2,14.400000,100,1,12.430000,700,1,14.560000,800,2,12.420000,700,1,14.600000,700,1,12.370000,700,1,14.680000,1400,2,ARL,321225725
2025-07-17T15:58:51.254871890Z,2025-07-17T15:58:51.254706004Z,10,2,1108,C,A,15,14.91,100,0,165886,268212499,13.040000,2,1,13.800000,100,1,13.030000,100,1,13.830000,115,2,13.020000,100,1,13.840000,100,1,12.730000,100,1,14.100000,2,1,12.710000,100,1,14.110000,100,1,12.500000,700,1,14.280000,100,1,12.460000,200,2,14.400000,100,1,12.430000,700,1,14.560000,800,2,12.420000,700,1,14.600000,700,1,12.370000,700,1,14.680000,1400,2,ARL,321096793
2025-07-17T15:58:51.254871890Z,2025-07-17T15:58:51.254706004Z,10,2,1108,A,A,-1,14.87,100,130,165886,268212499,13.040000,2,1,13.800000,100,1,13.030000,100,1,13.830000,115,2,13.020000,100,1,13.840000,100,1,12.730000,100,1,14.100000,2,1,12.710000,100,1,14.110000,100,1,12.500000,700,1,14.280000,100,1,12.460000,200,2,14.400000,100,1,12.430000,700,1,14.560000,800,2,12.420000,700,1,14.600000,700,1,12.370000,700,1,14.680000,1400,2,ARL,321225745
2025-07-17T15:58:51.260753179Z,2025-07-17T15:58:51.260587778Z,10,2,1108,C,A,1,13.83,100,130,165401,268212534,13.040000,2,1,13.800000,100,1,13.030000,100,1,13.830000,15,1,13.020000,100,1,13.840000,100,1,12.730000,100,1,14.100000,2,1,12.710000,100,1,14.110000,100,1,12.500000,700,1,14.280000,100,1,12.460000,200,2,14.400000,100,1,12.430000,700,1,14.560000,800,2,12.420000,700,1,14.600000,700,1,12.370000,700,1,14.680000,1400,2,ARL,321114473
2025-07-17T15:58:53.579628288Z,2025-07-17T15:58:53.579462029Z,10,2,1108,C,A,1,13.83,15,130,166259,268250290,13.040000,2,1,13.800000,100,1,13.030000,100,1,13.840000,100,1,13.020000,100,1,14.100000,2,1,12.730000,100,1,14.110000,100,1,12.710000,100,1,14.280000,100,1,12.500000,700,1,14.400000,100,1,12.460000,200,2,14.560000,800,2,12.430000,700,1,14.600000,700,1,12.420000,700,1,14.680000,1400,2,12.370000,700,1,14.720000,100,1,ARL,321038033
2025-07-17T15:58:53.580217445Z,2025-07-17T15:58:53.580052014Z,10,2,1108,C,A,1,13.84,100,0,165431,268250346,13.040000,2,1,13.800000,100,1,13.030000,100,1,14.100000,2,1,13.020000,100,1,14.110000,100,1,12.730000,100,1,14.280000,100,1,12.710000,100,1,14.400000,100,1,12.500000,700,1,14.560000,800,2,12.460000,200,2,14.600000,700,1,12.430000,700,1,14.680000,1400,2,12.420000,700,1,14.720000,100,1,12.370000,700,1,14.760000,100,1,ARL,321096769
2025-07-17T15:58:53.580217445Z,2025-07-17T15:58:53.580052014Z,10,2,1108,A,A,1,13.81,100,130,165431,268250346,13.040000,2,1,13.800000,100,1,13.030000,100,1,13.810000,100,1,13.020000,100,1,14.100000,2,1,12.730000,100,1,14.110000,100,1,12.710000,100,1,14.280000,100,1,12.500000,700,1,14.400000,100,1,12.460000,200,2,14.560000,800,2,12.430000,700,1,14.600000,700,1,12.420000,700,1,14.680000,1400,2,12.370000,700,1,14.720000,100,1,ARL,321272581
2025-07-17T15:58:54.584124215Z,2025-07-17T15:58:54.583958582Z,10,2,1108,C,A,11,14.77,100,0,165633,268265585,13.040000,2,1,13.800000,100,1,13.030000,100,1,13.810000,100,1,13.020000,100,1,14.100000,2,1,12.730000,100,1,14.110000,100,1,12.710000,100,1,14.280000,100,1,12.500000,700,1,14.400000,100,1,12.460000,200,2,14.560000,800,2,12.430000,700,1,14.600000,700,1,12.420000,700,1,14.680000,1400,2,12.370000,700,1,14.720000,100,1,ARL,320846429
2025-07-17T15:58:54.584124215Z,2025-07-17T15:58:54.583958582Z,10,2,1108,A,A,8,14.65,100,130,165633,268265585,13.040000,2,1,13.800000,100,1,13.030000,100,1,13.810000,100,1,13.020000,100,1,14.100000,2,1,12.730000,100,1,14.110000,100,1,12.710000,100,1,14.280000,100,1,12.500000,700,1,14.400000,100,1,12.460000,200,2,14.560000,800,2,12.430000,700,1,14.600000,700,1,12.420000,700,1,14.650000,100,1,12.370000,700,1,14.680000,1400,2,ARL,321293737
2025-07-17T15:58:54.584260712Z,2025-07-17T15:58:54.584094980Z,10,2,1108,C,A,11,14.76,100,0,165732,268265586,13.040000,2,1,13.800000,100,1,13.030000,100,1,13.810000,100,1,13.020000,100,1,14.100000,2,1,12.730000,100,1,14.110000,100,1,12.710000,100,1,14.280000,100,1,12.500000,700,1,14.400000,100,1,12.460000,200,2,14.560000,800,2,12.430000,700,1,14.600000,700,1,12.420000,700,1,14.650000,100,1,12.370000,700,1,14.680000,1400,2,ARL,320845893
2025-07-17T15:58:54.584260712Z,2025-07-17T15:58:54.584094980Z,10,2,1108,A,A,8,14.64,100,130,165732,268265586,13.040000,2,1,13.800000,100,1,13.030000,100,1,13.810000,100,1,13.020000,100,1,14.100000,2,1,12.730000,100,1,14.110000,100,1,12.710000,100,1,14.280000,100,1,12.500000,700,1,14.400000,100,1,12.460000,200,2,14.560000,800,2,12.430000,700,1,14.600000,700,1,12.420000,700,1,14.640000,100,1,12.370000,700,1,14.650000,100,1,ARL,321293741
2025-07-17T15:58:55.305104029Z,2025-07-17T15:58:55.304938318Z,10,2,1108,A,A,0,13.78,100,130,165711,268277940,13.040000,2,1,13.780000,100,1,13.030000,100,1,13.800000,100,1,13.020000,100,1,13.810000,100,1,12.730000,100,1,14.100000,2,1,12.710000,100,1,14.110000,100,1,12.500000,700,1,14.280000,100,1,12.460000,200,2,14.400000,100,1,12.430000,700,1,14.560000,800,2,12.420000,700,1,14.600000,700,1,12.370000,700,1,14.640000,100,1,ARL,321309865
2025-07-17T15:58:55.307508305Z,2025-07-17T15:58:55.307342971Z,10,2,1108,C,A,12,14.72,100,130,165334,268277999,13.040000,2,1,13.780000,100,1,13.030000,100,1,13.800000,100,1,13.020000,100,1,13.810000,100,1,12.730000,100,1,14.100000,2,1,12.710000,100,1,14.110000,100,1,12.500000,700,1,14.280000,100,1,12.460000,200,2,14.400000,100,1,12.430000,700,1,14.560000,800,2,12.420000,700,1,14.600000,700,1,12.370000,700,1,14.640000,100,1,ARL,312772061
2025-07-17T15:58:55.307637209Z,2025-07-17T15:58:55.307472032Z,10,2,1108,A,A,8,14.58,100,130,165177,268278004,13.040000,2,1,13.780000,100,1,13.030000,100,1,13.800000,100,1,13.020000,100,1,13.810000,100,1,12.730000,100,1,14.100000,2,1,12.710000,100,1,14.110000,100,1,12.500000,700,1,14.280000,100,1,12.460000,200,2,14.400000,100,1,12.430000,700,1,14.560000,800,2,12.420000,700,1,14.580000,100,1,12.370000,700,1,14.600000,700,1,ARL,321309941
2025-07-17T15:58:55.311899965Z,2025-07-17T15:58:55.311734700Z,10,2,1108,C,A,1,13.80,100,130,165265,268278030,13.040000,2,1,13.780000,100,1,13.030000,100,1,13.810000,100,1,13.020000,100,1,14.100000,2,1,12.730000,100,1,14.110000,100,1,12.710000,100,1,14.280000,100,1,12.500000,700,1,14.400000,100,1,12.460000,200,2,14.560000,800,2,12.430000,700,1,14.580000,100,1,12.420000,700,1,14.600000,700,1,12.370000,700,1,14.640000,100,1,ARL,321225725
2025-07-17T15:58:58.668252306Z,2025-07-17T15:58:58.668086788Z,10,2,1108,C,A,1,13.81,100,0,165518,268321684,13.040000,2,1,13.780000,100,1,13.030000,100,1,14.100000,2,1,13.020000,100,1,14.110000,100,1,12.730000,100,1,14.280000,100,1,12.710000,100,1,14.400000,100,1,12.500000,700,1,14.560000,800,2,12.460000,200,2,14.580000,100,1,12.430000,700,1,14.600000,700,1,12.420000,700,1,14.640000,100,1,12.370000,700,1,14.650000,100,1,ARL,321272581
2025-07-17T15:58:58.668252306Z,2025-07-17T15:58:58.668086788Z,10,2,1108,A,A,1,13.79,100,130,165518,268321684,13.040000,2,1,13.780000,100,1,13.030000,100,1,13.790000,100,1,13.020000,100,1,14.100000,2,1,12.730000,100,1,14.110000,100,1,12.710000,100,1,14.280000,100,1,12.500000,700,1,14.400000,100,1,12.460000,200,2,14.560000,800,2,12.430000,700,1,14.580000,100,1,12.420000,700,1,14.600000,700,1,12.370000,700,1,14.640000,100,1,ARL,321364281
2025-07-17T15:59:03.613692913Z,2025-07-17T15:59:03.613527621Z,10,2,1108,A,A,0,13.72,15,130,165292,268437919,13.040000,2,1,13.720000,15,1,13.030000,100,1,13.780000,100,1,13.020000,100,1,13.790000,100,1,12.730000,100,1,14.100000,2,1,12.710000,100,1,14.110000,100,1,12.500000,700,1,14.280000,100,1,12.460000,200,2,14.400000,100,1,12.430000,700,1,14.560000,800,2,12.420000,700,1,14.580000,100,1,12.370000,700,1,14.600000,700,1,ARL,321500117
2025-07-17T15:59:03.626346616Z,2025-07-17T15:59:03.626181384Z,10,2,1108,A,A,1,13.76,100,130,165232,268438110,13.040000,2,1,13.720000,15,1,13.030000,100,1,13.760000,100,1,13.020000,100,1,13.780000,100,1,12.730000,100,1,13.790000,100,1,12.710000,100,1,14.100000,2,1,12.500000,700,1,14.110000,100,1,12.460000,200,2,14.280000,100,1,12.430000,700,1,14.400000,100,1,12.420000,700,1,14.560000,800,2,12.370000,700,1,14.580000,100,1,ARL,321500317
2025-07-17T15:59:03.627086888Z,2025-07-17T15:59:03.626920954Z,10,2,1108,C,A,15,14.87,100,0,165934,268438112,13.040000,2,1,13.720000,15,1,13.030000,100,1,13.760000,100,1,13.020000,100,1,13.780000,100,1,12.730000,100,1,13.790000,100,1,12.710000,100,1,14.100000,2,1,12.500000,700,1,14.110000,100,1,12.460000,200,2,14.280000,100,1,12.430000,700,1,14.400000,100,1,12.420000,700,1,14.560000,800,2,12.370000,700,1,14.580000,100,1,ARL,321225745
2025-07-17T15:59:03.627086888Z,2025-07-17T15:59:03.626920954Z,10,2,1108,A,A,-1,14.83,100,130,165934,268438112,13.040000,2,1,13.720000,15,1,13.030000,100,1,13.760000,100,1,13.020000,100,1,13.780000,100,1,12.730000,100,1,13.790000,100,1,12.710000,100,1,14.100000,2,1,12.500000,700,1,14.110000,100,1,12.460000,200,2,14.280000,100,1,12.430000,700,1,14.400000,100,1,12.420000,700,1,14.560000,800,2,12.370000,700,1,14.580000,100,1,ARL,321500333
2025-07-17T15:59:03.628945278Z,2025-07-17T15:59:03.628779364Z,10,2,1108,C,A,16,14.89,100,0,165914,268438129,13.040000,2,1,13.720000,15,1,13.030000,100,1,13.760000,100,1,13.020000,100,1,13.780000,100,1,12.730000,100,1,13.790000,100,1,12.710000,100,1,14.100000,2,1,12.500000,700,1,14.110000,100,1,12.460000,200,2,14.280000,100,1,12.430000,700,1,14.400000,100,1,12.420000,700,1,14.560000,800,2,12.370000,700,1,14.580000,100,1,ARL,312771785
2025-07-17T15:59:03.628945278Z,2025-07-17T15:59:03.628779364Z,10,2,1108,A,A,-1,14.73,100,130,165914,268438129,13.040000,2,1,13.720000,15,1,13.030000,100,1,13.760000,100,1,13.020000,100,1,13.780000,100,1,12.730000,100,1,13.790000,100,1,12.710000,100,1,14.100000,2,1,12.500000,700,1,14.110000,100,1,12.460000,200,2,14.280000,100,1,12.430000,700,1,14.400000,100,1,12.420000,700,1,14.560000,800,2,12.370000,700,1,14.580000,100,1,ARL,321500349
2025-07-17T15:59:03.633093258Z,2025-07-17T15:59:03.632928023Z,10,2,1108,C,A,2,13.78,100,130,165235,268438149,13.040000,2,1,13.720000,15,1,13.030000,100,1,13.760000,100,1,13.020000,100,1,13.790000,100,1,12.730000,100,1,14.100000,2,1,12.710000,100,1,14.110000,100,1,12.500000,700,1,14.280000,100,1,12.460000,200,2,14.400000,100,1,12.430000,700,1,14.560000,800,2,12.420000,700,1,14.580000,100,1,12.370000,700,1,14.600000,700,1,ARL,321309865
2025-07-17T15:59:03.649282063Z,2025-07-17T15:59:03.649116452Z,10,2,1108,C,A,4,14.11,100,130,165611,268438330,13.040000,2,1,13.720000,15,1,13.030000,100,1,13.760000,100,1,13.020000,100,1,13.790000,100,1,12.730000,100,1,14.100000,2,1,12.710000,100,1,14.280000,100,1,12.500000,700,1,14.400000,100,1,12.460000,200,2,14.560000,800,2,12.430000,700,1,14.580000,100,1,12.420000,700,1,14.600000,700,1,12.370000,700,1,14.640000,100,1,ARL,321114729
2025-07-17T15:59:03.649332873Z,2025-07-17T15:59:03.649167617Z,10,2,1108,A,A,3,14.04,100,130,165256,268438331,13.040000,2,1,13.720000,15,1,13.030000,100,1,13.760000,100,1,13.020000,100,1,13.790000,100,1,12.730000,100,1,14.040000,100,1,12.710000,100,1,14.100000,2,1,12.500000,700,1,14.280000,100,1,12.460000,200,2,14.400000,100,1,12.430000,700,1,14.560000,800,2,12.420000,700,1,14.580000,100,1,12.370000,700,1,14.600000,700,1,ARL,321500957
2025-07-17T15:59:04.224000805Z,2025-07-17T15:59:04.223835151Z,10,2,1108,C,A,2,13.79,100,0,165654,268447989,13.040000,2,1,13.720000,15,1,13.030000,100,1,13.760000,100,1,13.020000,100,1,14.040000,100,1,12.730000,100,1,14.100000,2,1,12.710000,100,1,14.280000,100,1,12.500000,700,1,14.400000,100,1,12.460000,200,2,14.560000,800,2,12.430000,700,1,14.580000,100,1,12.420000,700,1,14.600000,700,1,12.370000,700,1,14.640000,100,1,ARL,321364281
2025-07-17T15:59:04.224000805Z,2025-07-17T15:59:04.223835151Z,10,2,1108,A,A,1,13.73,100,130,165654,268447989,13.040000,2,1,13.720000,15,1,13.030000,100,1,13.730000,100,1,13.020000,100,1,13.760000,100,1,12.730000,100,1,14.040000,100,1,12.710000,100,1,14.100000,2,1,12.500000,700,1,14.280000,100,1,12.460000,200,2,14.400000,100,1,12.430000,700,1,14.560000,800,2,12.420000,700,1,14.580000,100,1,12.370000,700,1,14.600000,700,1,ARL,321511377
2025-07-17T15:59:04.224749333Z,2025-07-17T15:59:04.224583946Z,10,2,1108,C,A,15,14.83,100,0,165387,268448014,13.040000,2,1,13.720000,15,1,13.030000,100,1,13.730000,100,1,13.020000,100,1,13.760000,100,1,12.730000,100,1,14.040000,100,1,12.710000,100,1,14.100000,2,1,12.500000,700,1,14.280000,100,1,12.460000,200,2,14.400000,100,1,12.430000,700,1,14.560000,800,2,12.420000,700,1,14.580000,100,1,12.370000,700,1,14.600000,700,1,ARL,321500333
2025-07-17T15:59:04.224749333Z,2025-07-17T15:59:04.224583946Z,10,2,1108,A,A,-1,14.79,100,130,165387,268448014,13.040000,2,1,13.720000,15,1,13.030000,100,1,13.730000,100,1,13.020000,100,1,13.760000,100,1,12.730000,100,1,14.040000,100,1,12.710000,100,1,14.100000,2,1,12.500000,700,1,14.280000,100,1,12.460000,200,2,14.400000,100,1,12.430000,700,1,14.560000,800,2,12.420000,700,1,14.580000,100,1,12.370000,700,1,14.600000,700,1,ARL,321511477
2025-07-17T15:59:04.799998642Z,2025-07-17T15:59:04.799833206Z,10,2,1108,C,A,0,13.72,15,130,165436,268457531,13.040000,2,1,13.730000,100,1,13.030000,100,1,13.760000,100,1,13.020000,100,1,14.040000,100,1,12.730000,100,1,14.100000,2,1,12.710000,100,1,14.280000,100,1,12.500000,700,1,14.400000,100,1,12.460000,200,2,14.560000,800,2,12.430000,700,1,14.580000,100,1,12.420000,700,1,14.600000,700,1,12.370000,700,1,14.640000,100,1,ARL,321500117
2025-07-17T16:00:13.989937414Z,2025-07-17T16:00:13.989771852Z,10,2,1108,C,A,3,14.10,2,0,165562,269514876,13.040000,2,1,13.730000,100,1,13.030000,100,1,13.760000,100,1,13.020000,100,1,14.040000,100,1,12.730000,100,1,14.280000,100,1,12.710000,100,1,14.400000,100,1,12.500000,700,1,14.560000,800,2,12.460000,200,2,14.580000,100,1,12.430000,700,1,14.600000,700,1,12.420000,700,1,14.640000,100,1,12.370000,700,1,14.650000,100,1,ARL,316098525
2025-07-17T16:00:13.989937414Z,2025-07-17T16:00:13.989771852Z,10,2,1108,A,A,2,14.01,2,130,165562,269514876,13.040000,2,1,13.730000,100,1,13.030000,100,1,13.760000,100,1,13.020000,100,1,14.010000,2,1,12.730000,100,1,14.040000,100,1,12.710000,100,1,14.280000,100,1,12.500000,700,1,14.400000,100,1,12.460000,200,2,14.560000,800,2,12.430000,700,1,14.580000,100,1,12.420000,700,1,14.600000,700,1,12.370000,700,1,14.640000,100,1,ARL,322898193
2025-07-17T16:00:28.803015930Z,2025-07-17T16:00:28.802849928Z,10,2,1108,A,A,0,13.72,15,130,166002,269765653,13.040000,2,1,13.720000,15,1,13.030000,100,1,13.730000,100,1,13.020000,100,1,13.760000,100,1,12.730000,100,1,14.010000,2,1,12.710000,100,1,14.040000,100,1,12.500000,700,1,14.280000,100,1,12.460000,200,2,14.400000,100,1,12.430000,700,1,14.560000,800,2,12.420000,700,1,14.580000,100,1,12.370000,700,1,14.600000,700,1,ARL,323238809
2025-07-17T16:00:32.549412616Z,2025-07-17T16:00:32.549247168Z,10,2,1108,A,A,2,13.74,100,130,165448,269878282,13.040000,2,1,13.720000,15,1,13.030000,100,1,13.730000,100,1,13.020000,100,1,13.740000,100,1,12.730000,100,1,13.760000,100,1,12.710000,100,1,14.010000,2,1,12.500000,700,1,14.040000,100,1,12.460000,200,2,14.280000,100,1,12.430000,700,1,14.400000,100,1,12.420000,700,1,14.560000,800,2,12.370000,700,1,14.580000,100,1,ARL,323370569
2025-07-17T16:00:32.560989093Z,2025-07-17T16:00:32.560823786Z,10,2,1108,C,A,3,13.76,100,130,165307,269878639,13.040000,2,1,13.720000,15,1,13.030000,100,1,13.730000,100,1,13.020000,100,1,13.740000,100,1,12.730000,100,1,14.010000,2,1,12.710000,100,1,14.040000,100,1,12.500000,700,1,14.280000,100,1,12.460000,200,2,14.400000,100,1,12.430000,700,1,14.560000,800,2,12.420000,700,1,14.580000,100,1,12.370000,700,1,14.600000,700,1,ARL,321500317
2025-07-17T16:00:35.513164458Z,2025-07-17T16:00:35.512999155Z,10,2,1108,A,A,0,13.69,15,130,165303,269940539,13.040000,2,1,13.690000,15,1,13.030000,100,1,13.720000,15,1,13.020000,100,1,13.730000,100,1,12.730000,100,1,13.740000,100,1,12.710000,100,1,14.010000,2,1,12.500000,700,1,14.040000,100,1,12.460000,200,2,14.280000,100,1,12.430000,700,1,14.400000,100,1,12.420000,700,1,14.560000,800,2,12.370000,700,1,14.580000,100,1,ARL,323455221
2025-07-17T16:00:42.614229184Z,2025-07-17T16:00:42.614063415Z,10,2,1108,C,A,2,13.73,100,0,165769,270051089,13.040000,2,1,13.690000,15,1,13.030000,100,1,13.720000,15,1,13.020000,100,1,13.740000,100,1,12.730000,100,1,14.010000,2,1,12.710000,100,1,14.040000,100,1,12.500000,700,1,14.280000,100,1,12.460000,200,2,14.400000,100,1,12.430000,700,1,14.560000,800,2,12.420000,700,1,14.580000,100,1,12.370000,700,1,14.600000,700,1,ARL,321511377
2025-07-17T16:00:42.614229184Z,2025-07-17T16:00:42.614063415Z,10,2,1108,A,A,1,13.70,100,130,165769,270051089,13.040000,2,1,13.690000,15,1,13.030000,100,1,13.700000,100,1,13.020000,100,1,13.720000,15,1,12.730000,100,1,13.740000,100,1,12.710000,100,1,14.010000,2,1,12.500000,700,1,14.040000,100,1,12.460000,200,2,14.280000,100,1,12.430000,700,1,14.400000,100,1,12.420000,700,1,14.560000,800,2,12.370000,700,1,14.580000,100,1,ARL,323599605
2025-07-17T16:00:42.614254199Z,2025-07-17T16:00:42.614088947Z,10,2,1108,A,A,2,13.72,100,130,165252,270051090,13.040000,2,1,13.690000,15,1,13.030000,100,1,13.700000,100,1,13.020000,100,1,13.720000,115,2,12.730000,100,1,13.740000,100,1,12.710000,100,1,14.010000,2,1,12.500000,700,1,14.040000,100,1,12.460000,200,2,14.280000,100,1,12.430000,700,1,14.400000,100,1,12.420000,700,1,14.560000,800,2,12.370000,700,1,14.580000,100,1,ARL,323599609
2025-07-17T16:00:42.614396214Z,2025-07-17T16:00:42.614231125Z,10,2,1108,C,A,3,13.74,100,130,165089,270051092,13.040000,2,1,13.690000,15,1,13.030000,100,1,13.700000,100,1,13.020000,100,1,13.720000,115,2,12.730000,100,1,14.010000,2,1,12.710000,100,1,14.040000,100,1,12.500000,700,1,14.280000,100,1,12.460000,200,2,14.400000,100,1,12.430000,700,1,14.560000,800,2,12.420000,700,1,14.580000,100,1,12.370000,700,1,14.600000,700,1,ARL,323370569
2025-07-17T16:00:42.616178962Z,2025-07-17T16:00:42.616013371Z,10,2,1108,C,A,15,14.81,100,0,165591,270051093,13.040000,2,1,13.690000,15,1,13.030000,100,1,13.700000,100,1,13.020000,100,1,13.720000,115,2,12.730000,100,1,14.010000,2,1,12.710000,100,1,14.040000,100,1,12.500000,700,1,14.280000,100,1,12.460000,200,2,14.400000,100,1,12.430000,700,1,14.560000,800,2,12.420000,700,1,14.580000,100,1,12.370000,700,1,14.600000,700,1,ARL,321097197
2025-07-17T16:00:42.616178962Z,2025-07-17T16:00:42.616013371Z,10,2,1108,A,A,-1,14.66,100,130,165591,270051093,13.040000,2,1,13.690000,15,1,13.030000,100,1,13.700000,100,1,13.020000,100,1,13.720000,115,2,12.730000,100,1,14.010000,2,1,12.710000,100,1,14.040000,100,1,12.500000,700,1,14.280000,100,1,12.460000,200,2,14.400000,100,1,12.430000,700,1,14.560000,800,2,12.420000,700,1,14.580000,100,1,12.370000,700,1,14.600000,700,1,ARL,323599625
2025-07-17T16:00:42.616321879Z,2025-07-17T16:00:42.616156310Z,10,2,1108,C,A,20,15.92,100,0,165569,270051094,13.040000,2,1,13.690000,15,1,13.030000,100,1,13.700000,100,1,13.020000,100,1,13.720000,115,2,12.730000,100,1,14.010000,2,1,12.710000,100,1,14.040000,100,1,12.500000,700,1,14.280000,100,1,12.460000,200,2,14.400000,100,1,12.430000,700,1,14.560000,800,2,12.420000,700,1,14.580000,100,1,12.370000,700,1,14.600000,700,1,ARL,321096889
2025-07-17T16:00:42.616321879Z,2025-07-17T16:00:42.616156310Z,10,2,1108,A,A,-1,15.76,100,130,165569,270051094,13.040000,2,1,13.690000,15,1,13.030000,100,1,13.700000,100,1,13.020000,100,1,13.720000,115,2,12.730000,100,1,14.010000,2,1,12.710000,100,1,14.040000,100,1,12.500000,700,1,14.280000,100,1,12.460000,200,2,14.400000,100,1,12.430000,700,1,14.560000,800,2,12.420000,700,1,14.580000,100,1,12.370000,700,1,14.600000,700,1,ARL,323599629
2025-07-17T16:00:42.616352247Z,2025-07-17T16:00:42.616186901Z,10,2,1108,C,A,23,17.58,100,0,165346,270051095,13.040000,2,1,13.690000,15,1,13.030000,100,1,13.700000,100,1,13.020000,100,1,13.720000,115,2,12.730000,100,1,14.010000,2,1,12.710000,100,1,14.040000,100,1,12.500000,700,1,14.280000,100,1,12.460000,200,2,14.400000,100,1,12.430000,700,1,14.560000,800,2,12.420000,700,1,14.580000,100,1,12.370000,700,1,14.600000,700,1,ARL,321096825
2025-07-17T16:00:42.616352247Z,2025-07-17T16:00:42.616186901Z,10,2,1108,A,A,-1,17.40,100,130,165346,270051095,13.040000,2,1,13.690000,15,1,13.030000,100,1,13.700000,100,1,13.020000,100,1,13.720000,115,2,12.730000,100,1,14.010000,2,1,12.710000,100,1,14.040000,100,1,12.500000,700,1,14.280000,100,1,12.460000,200,2,14.400000,100,1,12.430000,700,1,14.560000,800,2,12.420000,700,1,14.580000,100,1,12.370000,700,1,14.600000,700,1,ARL,323599633
2025-07-17T16:00:42.636761176Z,2025-07-17T16:00:42.636595817Z,10,2,1108,C,A,4,14.04,100,130,165359,270051179,13.040000,2,1,13.690000,15,1,13.030000,100,1,13.700000,100,1,13.020000,100,1,13.720000,115,2,12.730000,100,1,14.010000,2,1,12.710000,100,1,14.280000,100,1,12.500000,700,1,14.400000,100,1,12.460000,200,2,14.560000,800,2,12.430000,700,1,14.580000,100,1,12.420000,700,1,14.600000,700,1,12.370000,700,1,14.640000,100,1,ARL,321500957
2025-07-17T16:00:42.636814704Z,2025-07-17T16:00:42.636649389Z,10,2,1108,A,A,3,13.97,100,130,165315,270051181,13.040000,2,1,13.690000,15,1,13.030000,100,1,13.700000,100,1,13.020000,100,1,13.720000,115,2,12.730000,100,1,13.970000,100,1,12.710000,100,1,14.010000,2,1,12.500000,700,1,14.280000,100,1,12.460000,200,2,14.400000,100,1,12.430000,700,1,14.560000,800,2,12.420000,700,1,14.580000,100,1,12.370000,700,1,14.600000,700,1,ARL,323599765
2025-07-17T16:00:46.803262460Z,2025-07-17T16:00:46.803097192Z,10,2,1108,C,A,2,13.72,15,130,165268,270102799,13.040000,2,1,13.690000,15,1,13.030000,100,1,13.700000,100,1,13.020000,100,1,13.720000,100,1,12.730000,100,1,13.970000,100,1,12.710000,100,1,14.010000,2,1,12.500000,700,1,14.280000,100,1,12.460000,200,2,14.400000,100,1,12.430000,700,1,14.560000,800,2,12.420000,700,1,14.580000,100,1,12.370000,700,1,14.600000,700,1,ARL,323238809
2025-07-17T16:00:49.255631264Z,2025-07-17T16:00:49.255465939Z,10,2,1108,A,A,0,13.66,15,130,165325,270140405,13.040000,2,1,13.660000,15,1,13.030000,100,1,13.690000,15,1,13.020000,100,1,13.700000,100,1,12.730000,100,1,13.720000,100,1,12.710000,100,1,13.970000,100,1,12.500000,700,1,14.010000,2,1,12.460000,200,2,14.280000,100,1,12.430000,700,1,14.400000,100,1,12.420000,700,1,14.560000,800,2,12.370000,700,1,14.580000,100,1,ARL,323720189
2025-07-17T16:00:49.739644604Z,2025-07-17T16:00:49.739479408Z,10,2,1108,A,A,2,13.70,100,130,165196,270146528,13.040000,2,1,13.660000,15,1,13.030000,100,1,13.690000,15,1,13.020000,100,1,13.700000,200,2,12.730000,100,1,13.720000,100,1,12.710000,100,1,13.970000,100,1,12.500000,700,1,14.010000,2,1,12.460000,200,2,14.280000,100,1,12.430000,700,1,14.400000,100,1,12.420000,700,1,14.560000,800,2,12.370000,700,1,14.580000,100,1,ARL,323730309
2025-07-17T16:00:49.745038261Z,2025-07-17T16:00:49.744872763Z,10,2,1108,C,A,2,13.70,100,0,165498,270146577,13.040000,2,1,13.660000,15,1,13.030000,100,1,13.690000,15,1,13.020000,100,1,13.700000,100,1,12.730000,100,1,13.720000,100,1,12.710000,100,1,13.970000,100,1,12.500000,700,1,14.010000,2,1,12.460000,200,2,14.280000,100,1,12.430000,700,1,14.400000,100,1,12.420000,700,1,14.560000,800,2,12.370000,700,1,14.580000,100,1,ARL,323599605
2025-07-17T16:00:49.745038261Z,2025-07-17T16:00:49.744872763Z,10,2,1108,A,A,1,13.67,100,130,165498,270146577,13.040000,2,1,13.660000,15,1,13.030000,100,1,13.670000,100,1,13.020000,100,1,13.690000,15,1,12.730000,100,1,13.700000,100,1,12.710000,100,1,13.720000,100,1,12.500000,700,1,13.970000,100,1,12.460000,200,2,14.010000,2,1,12.430000,700,1,14.280000,100,1,12.420000,700,1,14.400000,100,1,12.370000,700,1,14.560000,800,2,ARL,323730353
2025-07-17T16:00:49.745778725Z,2025-07-17T16:00:49.745613051Z,10,2,1108,C,A,17,14.79,100,0,165674,270146581,13.040000,2,1,13.660000,15,1,13.030000,100,1,13.670000,100,1,13.020000,100,1,13.690000,15,1,12.730000,100,1,13.700000,100,1,12.710000,100,1,13.720000,100,1,12.500000,700,1,13.970000,100,1,12.460000,200,2,14.010000,2,1,12.430000,700,1,14.280000,100,1,12.420000,700,1,14.400000,100,1,12.370000,700,1,14.560000,800,2,ARL,321511477
2025-07-17T16:00:49.745778725Z,2025-07-17T16:00:49.745613051Z,10,2,1108,A,A,-1,14.73,100,130,165674,270146581,13.040000,2,1,13.660000,15,1,13.030000,100,1,13.670000,100,1,13.020000,100,1,13.690000,15,1,12.730000,100,1,13.700000,100,1,12.710000,100,1,13.720000,100,1,12.500000,700,1,13.970000,100,1,12.460000,200,2,14.010000,2,1,12.430000,700,1,14.280000,100,1,12.420000,700,1,14.400000,100,1,12.370000,700,1,14.560000,800,2,ARL,323730369
2025-07-17T16:00:49.746422142Z,2025-07-17T16:00:49.746256906Z,10,2,1108,C,A,4,13.72,100,130,165236,270146586,13.040000,2,1,13.660000,15,1,13.030000,100,1,13.670000,100,1,13.020000,100,1,13.690000,15,1,12.730000,100,1,13.700000,100,1,12.710000,100,1,13.970000,100,1,12.500000,700,1,14.010000,2,1,12.460000,200,2,14.280000,100,1,12.430000,700,1,14.400000,100,1,12.420000,700,1,14.560000,800,2,12.370000,700,1,14.580000,100,1,ARL,323599609
2025-07-17T16:00:49.772631967Z,2025-07-17T16:00:49.772466772Z,10,2,1108,A,A,-1,15.59,100,130,165195,270146838,13.040000,2,1,13.660000,15,1,13.030000,100,1,13.670000,100,1,13.020000,100,1,13.690000,15,1,12.730000,100,1,13.700000,100,1,12.710000,100,1,13.970000,100,1,12.500000,700,1,14.010000,2,1,12.460000,200,2,14.280000,100,1,12.430000,700,1,14.400000,100,1,12.420000,700,1,14.560000,800,2,12.370000,700,1,14.580000,100,1,ARL,323730697
2025-07-17T16:00:49.772645303Z,2025-07-17T16:00:49.772479921Z,10,2,1108,C,A,21,15.86,100,130,165382,270146839,13.040000,2,1,13.660000,15,1,13.030000,100,1,13.670000,100,1,13.020000,100,1,13.690000,15,1,12.730000,100,1,13.700000,100,1,12.710000,100,1,13.970000,100,1,12.500000,700,1,14.010000,2,1,12.460000,200,2,14.280000,100,1,12.430000,700,1,14.400000,100,1,12.420000,700,1,14.560000,800,2,12.370000,700,1,14.580000,100,1,ARL,312771645
2025-07-17T16:00:51.624811889Z,2025-07-17T16:00:51.624646272Z,10,2,1108,C,A,12,14.65,100,0,165617,270181394,13.040000,2,1,13.660000,15,1,13.030000,100,1,13.670000,100,1,13.020000,100,1,13.690000,15,1,12.730000,100,1,13.700000,100,1,12.710000,100,1,13.970000,100,1,12.500000,700,1,14.010000,2,1,12.460000,200,2,14.280000,100,1,12.430000,700,1,14.400000,100,1,12.420000,700,1,14.560000,800,2,12.370000,700,1,14.580000,100,1,ARL,321293737
2025-07-17T16:00:51.624811889Z,2025-07-17T16:00:51.624646272Z,10,2,1108,A,A,8,14.54,100,130,165617,270181394,13.040000,2,1,13.660000,15,1,13.030000,100,1,13.670000,100,1,13.020000,100,1,13.690000,15,1,12.730000,100,1,13.700000,100,1,12.710000,100,1,13.970000,100,1,12.500000,700,1,14.010000,2,1,12.460000,200,2,14.280000,100,1,12.430000,700,1,14.400000,100,1,12.420000,700,1,14.540000,100,1,12.370000,700,1,14.560000,800,2,ARL,323775433
2025-07-17T16:00:51.625372516Z,2025-07-17T16:00:51.625206675Z,10,2,1108,C,A,12,14.64,100,0,165841,270181399,13.040000,2,1,13.660000,15,1,13.030000,100,1,13.670000,100,1,13.020000,100,1,13.690000,15,1,12.730000,100,1,13.700000,100,1,12.710000,100,1,13.970000,100,1,12.500000,700,1,14.010000,2,1,12.460000,200,2,14.280000,100,1,12.430000,700,1,14.400000,100,1,12.420000,700,1,14.540000,100,1,12.370000,700,1,14.560000,800,2,ARL,321293741
2025-07-17T16:00:51.625372516Z,2025-07-17T16:00:51.625206675Z,10,2,1108,A,A,8,14.53,100,130,165841,270181399,13.040000,2,1,13.660000,15,1,13.030000,100,1,13.670000,100,1,13.020000,100,1,13.690000,15,1,12.730000,100,1,13.700000,100,1,12.710000,100,1,13.970000,100,1,12.500000,700,1,14.010000,2,1,12.460000,200,2,14.280000,100,1,12.430000,700,1,14.400000,100,1,12.420000,700,1,14.530000,100,1,12.370000,700,1,14.540000,100,1,ARL,323775457
2025-07-17T16:00:53.749335010Z,2025-07-17T16:00:53.749169565Z,10,2,1108,A,A,1,13.67,100,130,165445,270204567,13.040000,2,1,13.660000,15,1,13.030000,100,1,13.670000,200,2,13.020000,100,1,13.690000,15,1,12.730000,100,1,13.700000,100,1,12.710000,100,1,13.970000,100,1,12.500000,700,1,14.010000,2,1,12.460000,200,2,14.280000,100,1,12.430000,700,1,14.400000,100,1,12.420000,700,1,14.530000,100,1,12.370000,700,1,14.540000,100,1,ARL,323803301
2025-07-17T16:00:53.755966680Z,2025-07-17T16:00:53.755801462Z,10,2,1108,C,A,3,13.70,100,130,165218,270204616,13.040000,2,1,13.660000,15,1,13.030000,100,1,13.670000,200,2,13.020000,100,1,13.690000,15,1,12.730000,100,1,13.970000,100,1,12.710000,100,1,14.010000,2,1,12.500000,700,1,14.280000,100,1,12.460000,200,2,14.400000,100,1,12.430000,700,1,14.530000,100,1,12.420000,700,1,14.540000,100,1,12.370000,700,1,14.560000,800,2,ARL,323730309
2025-07-17T16:01:00.801342739Z,2025-07-17T16:01:00.801177403Z,10,2,1108,C,A,2,13.69,15,130,165336,270319932,13.040000,2,1,13.660000,15,1,13.030000,100,1,13.670000,200,2,13.020000,100,1,13.970000,100,1,12.730000,100,1,14.010000,2,1,12.710000,100,1,14.280000,100,1,12.500000,700,1,14.400000,100,1,12.460000,200,2,14.530000,100,1,12.430000,700,1,14.540000,100,1,12.420000,700,1,14.560000,800,2,12.370000,700,1,14.580000,100,1,ARL,323455221
2025-07-17T16:01:10.802877570Z,2025-07-17T16:01:10.802712247Z,10,2,1108,A,A,0,13.62,15,130,165323,270493149,13.040000,2,1,13.620000,15,1,13.030000,100,1,13.660000,15,1,13.020000,100,1,13.670000,200,2,12.730000,100,1,13.970000,100,1,12.710000,100,1,14.010000,2,1,12.500000,700,1,14.280000,100,1,12.460000,200,2,14.400000,100,1,12.430000,700,1,14.530000,100,1,12.420000,700,1,14.540000,100,1,12.370000,700,1,14.560000,800,2,ARL,324161541
2025-07-17T16:01:11.418837472Z,2025-07-17T16:01:11.418671671Z,10,2,1108,A,A,1,13.65,100,130,165801,270503944,13.040000,2,1,13.620000,15,1,13.030000,100,1,13.650000,100,1,13.020000,100,1,13.660000,15,1,12.730000,100,1,13.670000,200,2,12.710000,100,1,13.970000,100,1,12.500000,700,1,14.010000,2,1,12.460000,200,2,14.280000,100,1,12.430000,700,1,14.400000,100,1,12.420000,700,1,14.530000,100,1,12.370000,700,1,14.540000,100,1,ARL,324175569
2025-07-17T16:01:11.425922184Z,2025-07-17T16:01:11.425757014Z,10,2,1108,C,A,3,13.67,100,130,165170,270504009,13.040000,2,1,13.620000,15,1,13.030000,100,1,13.650000,100,1,13.020000,100,1,13.660000,15,1,12.730000,100,1,13.670000,100,1,12.710000,100,1,13.970000,100,1,12.500000,700,1,14.010000,2,1,12.460000,200,2,14.280000,100,1,12.430000,700,1,14.400000,100,1,12.420000,700,1,14.530000,100,1,12.370000,700,1,14.540000,100,1,ARL,323803301
2025-07-17T16:01:11.820753616Z,2025-07-17T16:01:11.820588141Z,10,2,1108,C,A,3,13.67,100,0,165475,270509970,13.040000,2,1,13.620000,15,1,13.030000,100,1,13.650000,100,1,13.020000,100,1,13.660000,15,1,12.730000,100,1,13.970000,100,1,12.710000,100,1,14.010000,2,1,12.500000,700,1,14.280000,100,1,12.460000,200,2,14.400000,100,1,12.430000,700,1,14.530000,100,1,12.420000,700,1,14.540000,100,1,12.370000,700,1,14.560000,800,2,ARL,323730353
2025-07-17T16:01:11.820753616Z,2025-07-17T16:01:11.820588141Z,10,2,1108,A,A,1,13.63,100,130,165475,270509970,13.040000,2,1,13.620000,15,1,13.030000,100,1,13.630000,100,1,13.020000,100,1,13.650000,100,1,12.730000,100,1,13.660000,15,1,12.710000,100,1,13.970000,100,1,12.500000,700,1,14.010000,2,1,12.460000,200,2,14.280000,100,1,12.430000,700,1,14.400000,100,1,12.420000,700,1,14.530000,100,1,12.370000,700,1,14.540000,100,1,ARL,324186213
2025-07-17T16:01:11.821515043Z,2025-07-17T16:01:11.821349600Z,10,2,1108,C,A,15,14.73,100,0,165443,270509983,13.040000,2,1,13.620000,15,1,13.030000,100,1,13.630000,100,1,13.020000,100,1,13.650000,100,1,12.730000,100,1,13.660000,15,1,12.710000,100,1,13.970000,100,1,12.500000,700,1,14.010000,2,1,12.460000,200,2,14.280000,100,1,12.430000,700,1,14.400000,100,1,12.420000,700,1,14.530000,100,1,12.370000,700,1,14.540000,100,1,ARL,323730369
2025-07-17T16:01:11.821515043Z,2025-07-17T16:01:11.821349600Z,10,2,1108,A,A,-1,14.69,100,130,165443,270509983,13.040000,2,1,13.620000,15,1,13.030000,100,1,13.630000,100,1,13.020000,100,1,13.650000,100,1,12.730000,100,1,13.660000,15,1,12.710000,100,1,13.970000,100,1,12.500000,700,1,14.010000,2,1,12.460000,200,2,14.280000,100,1,12.430000,700,1,14.400000,100,1,12.420000,700,1,14.530000,100,1,12.370000,700,1,14.540000,100,1,ARL,324186233
2025-07-17T16:01:11.826399871Z,2025-07-17T16:01:11.826234488Z,10,2,1108,C,A,4,13.97,100,130,165383,270510142,13.040000,2,1,13.620000,15,1,13.030000,100,1,13.630000,100,1,13.020000,100,1,13.650000,100,1,12.730000,100,1,13.660000,15,1,12.710000,100,1,14.010000,2,1,12.500000,700,1,14.280000,100,1,12.460000,200,2,14.400000,100,1,12.430000,700,1,14.530000,100,1,12.420000,700,1,14.540000,100,1,12.370000,700,1,14.560000,800,2,ARL,323599765
2025-07-17T16:01:11.826451447Z,2025-07-17T16:01:11.826286284Z,10,2,1108,A,A,4,13.90,100,130,165163,270510143,13.040000,2,1,13.620000,15,1,13.030000,100,1,13.630000,100,1,13.020000,100,1,13.650000,100,1,12.730000,100,1,13.660000,15,1,12.710000,100,1,13.900000,100,1,12.500000,700,1,14.010000,2,1,12.460000,200,2,14.280000,100,1,12.430000,700,1,14.400000,100,1,12.420000,700,1,14.530000,100,1,12.370000,700,1,14.540000,100,1,ARL,324186721
2025-07-17T16:01:11.828630414Z,2025-07-17T16:01:11.828464891Z,10,2,1108,C,A,11,14.58,100,0,165523,270510182,13.040000,2,1,13.620000,15,1,13.030000,100,1,13.630000,100,1,13.020000,100,1,13.650000,100,1,12.730000,100,1,13.660000,15,1,12.710000,100,1,13.900000,100,1,12.500000,700,1,14.010000,2,1,12.460000,200,2,14.280000,100,1,12.430000,700,1,14.400000,100,1,12.420000,700,1,14.530000,100,1,12.370000,700,1,14.540000,100,1,ARL,321309941
2025-07-17T16:01:11.828630414Z,2025-07-17T16:01:11.828464891Z,10,2,1108,A,A,8,14.43,100,130,165523,270510182,13.040000,2,1,13.620000,15,1,13.030000,100,1,13.630000,100,1,13.020000,100,1,13.650000,100,1,12.730000,100,1,13.660000,15,1,12.710000,100,1,13.900000,100,1,12.500000,700,1,14.010000,2,1,12.460000,200,2,14.280000,100,1,12.430000,700,1,14.400000,100,1,12.420000,700,1,14.430000,100,1,12.370000,700,1,14.530000,100,1,ARL,324186781
2025-07-17T16:01:22.802518536Z,2025-07-17T16:01:22.802353061Z,10,2,1108,C,A,3,13.66,15,130,165475,270674903,13.040000,2,1,13.620000,15,1,13.030000,100,1,13.630000,100,1,13.020000,100,1,13.650000,100,1,12.730000,100,1,13.900000,100,1,12.710000,100,1,14.010000,2,1,12.500000,700,1,14.280000,100,1,12.460000,200,2,14.400000,100,1,12.430000,700,1,14.430000,100,1,12.420000,700,1,14.530000,100,1,12.370000,700,1,14.540000,100,1,ARL,323720189
2025-07-17T16:01:32.804004639Z,2025-07-17T16:01:32.803839043Z,10,2,1108,A,A,0,13.60,15,130,165596,270824320,13.040000,2,1,13.600000,15,1,13.030000,100,1,13.620000,15,1,13.020000,100,1,13.630000,100,1,12.730000,100,1,13.650000,100,1,12.710000,100,1,13.900000,100,1,12.500000,700,1,14.010000,2,1,12.460000,200,2,14.280000,100,1,12.430000,700,1,14.400000,100,1,12.420000,700,1,14.430000,100,1,12.370000,700,1,14.530000,100,1,ARL,324619361
2025-07-17T16:01:32.804274168Z,2025-07-17T16:01:32.804108576Z,10,2,1108,C,A,2,13.63,100,0,165592,270824323,13.040000,2,1,13.600000,15,1,13.030000,100,1,13.620000,15,1,13.020000,100,1,13.650000,100,1,12.730000,100,1,13.900000,100,1,12.710000,100,1,14.010000,2,1,12.500000,700,1,14.280000,100,1,12.460000,200,2,14.400000,100,1,12.430000,700,1,14.430000,100,1,12.420000,700,1,14.530000,100,1,12.370000,700,1,14.540000,100,1,ARL,324186213
2025-07-17T16:01:32.804274168Z,2025-07-17T16:01:32.804108576Z,10,2,1108,A,A,1,13.61,100,130,165592,270824323,13.040000,2,1,13.600000,15,1,13.030000,100,1,13.610000,100,1,13.020000,100,1,13.620000,15,1,12.730000,100,1,13.650000,100,1,12.710000,100,1,13.900000,100,1,12.500000,700,1,14.010000,2,1,12.460000,200,2,14.280000,100,1,12.430000,700,1,14.400000,100,1,12.420000,700,1,14.430000,100,1,12.370000,700,1,14.530000,100,1,ARL,324619369
2025-07-17T16:01:32.806299464Z,2025-07-17T16:01:32.806134020Z,10,2,1108,C,A,16,14.73,100,0,165444,270824400,13.040000,2,1,13.600000,15,1,13.030000,100,1,13.610000,100,1,13.020000,100,1,13.620000,15,1,12.730000,100,1,13.650000,100,1,12.710000,100,1,13.900000,100,1,12.500000,700,1,14.010000,2,1,12.460000,200,2,14.280000,100,1,12.430000,700,1,14.400000,100,1,12.420000,700,1,14.430000,100,1,12.370000,700,1,14.530000,100,1,ARL,321500349
2025-07-17T16:01:32.806299464Z,2025-07-17T16:01:32.806134020Z,10,2,1108,A,A,-1,14.57,100,130,165444,270824400,13.040000,2,1,13.600000,15,1,13.030000,100,1,13.610000,100,1,13.020000,100,1,13.620000,15,1,12.730000,100,1,13.650000,100,1,12.710000,100,1,13.900000,100,1,12.500000,700,1,14.010000,2,1,12.460000,200,2,14.280000,100,1,12.430000,700,1,14.400000,100,1,12.420000,700,1,14.430000,100,1,12.370000,700,1,14.530000,100,1,ARL,324619409
2025-07-17T16:01:32.815913520Z,2025-07-17T16:01:32.815748258Z,10,2,1108,A,A,3,13.63,100,130,165262,270824657,13.040000,2,1,13.600000,15,1,13.030000,100,1,13.610000,100,1,13.020000,100,1,13.620000,15,1,12.730000,100,1,13.630000,100,1,12.710000,100,1,13.650000,100,1,12.500000,700,1,13.900000,100,1,12.460000,200,2,14.010000,2,1,12.430000,700,1,14.280000,100,1,12.420000,700,1,14.400000,100,1,12.370000,700,1,14.430000,100,1,ARL,324619837
2025-07-17T16:01:32.822608966Z,2025-07-17T16:01:32.822443626Z,10,2,1108,C,A,4,13.65,100,130,165340,270824747,13.040000,2,1,13.600000,15,1,13.030000,100,1,13.610000,100,1,13.020000,100,1,13.620000,15,1,12.730000,100,1,13.630000,100,1,12.710000,100,1,13.900000,100,1,12.500000,700,1,14.010000,2,1,12.460000,200,2,14.280000,100,1,12.430000,700,1,14.400000,100,1,12.420000,700,1,14.430000,100,1,12.370000,700,1,14.530000,100,1,ARL,324175569
2025-07-17T16:01:37.242690420Z,2025-07-17T16:01:37.242525208Z,10,2,1108,C,A,2,13.62,15,130,165212,270889017,13.040000,2,1,13.600000,15,1,13.030000,100,1,13.610000,100,1,13.020000,100,1,13.630000,100,1,12.730000,100,1,13.900000,100,1,12.710000,100,1,14.010000,2,1,12.500000,700,1,14.280000,100,1,12.460000,200,2,14.400000,100,1,12.430000,700,1,14.430000,100,1,12.420000,700,1,14.530000,100,1,12.370000,700,1,14.540000,100,1,ARL,324161541
2025-07-17T16:01:40.605797765Z,2025-07-17T16:01:40.605632399Z,10,2,1108,A,A,1,13.61,100,130,165366,270946497,13.040000,2,1,13.600000,15,1,13.030000,100,1,13.610000,200,2,13.020000,100,1,13.630000,100,1,12.730000,100,1,13.900000,100,1,12.710000,100,1,14.010000,2,1,12.500000,700,1,14.280000,100,1,12.460000,200,2,14.400000,100,1,12.430000,700,1,14.430000,100,1,12.420000,700,1,14.530000,100,1,12.370000,700,1,14.540000,100,1,ARL,324782841
2025-07-17T16:01:40.653738176Z,2025-07-17T16:01:40.653572805Z,10,2,1108,C,A,2,13.63,100,130,165371,270946779,13.040000,2,1,13.600000,15,1,13.030000,100,1,13.610000,200,2,13.020000,100,1,13.900000,100,1,12.730000,100,1,14.010000,2,1,12.710000,100,1,14.280000,100,1,12.500000,700,1,14.400000,100,1,12.460000,200,2,14.430000,100,1,12.430000,700,1,14.530000,100,1,12.420000,700,1,14.540000,100,1,12.370000,700,1,14.560000,800,2,ARL,324619837
2025-07-17T16:01:47.565991684Z,2025-07-17T16:01:47.565825466Z,10,2,1108,A,A,0,13.57,15,128,166218,271062350,13.040000,2,1,13.570000,15,1,13.030000,100,1,13.600000,15,1,13.020000,100,1,13.610000,200,2,12.730000,100,1,13.900000,100,1,12.710000,100,1,14.010000,2,1,12.500000,700,1,14.280000,100,1,12.460000,200,2,14.400000,100,1,12.430000,700,1,14.430000,100,1,12.420000,700,1,14.530000,100,1,12.370000,700,1,14.540000,100,1,ARL,324934601
2025-07-17T16:01:47.902969773Z,2025-07-17T16:01:47.902804446Z,10,2,1108,C,A,2,13.61,100,0,165327,271068098,13.040000,2,1,13.570000,15,1,13.030000,100,1,13.600000,15,1,13.020000,100,1,13.610000,100,1,12.730000,100,1,13.900000,100,1,12.710000,100,1,14.010000,2,1,12.500000,700,1,14.280000,100,1,12.460000,200,2,14.400000,100,1,12.430000,700,1,14.430000,100,1,12.420000,700,1,14.530000,100,1,12.370000,700,1,14.540000,100,1,ARL,324619369
2025-07-17T16:01:47.902969773Z,2025-07-17T16:01:47.902804446Z,10,2,1108,A,A,1,13.58,100,130,165327,271068098,13.040000,2,1,13.570000,15,1,13.030000,100,1,13.580000,100,1,13.020000,100,1,13.600000,15,1,12.730000,100,1,13.610000,100,1,12.710000,100,1,13.900000,100,1,12.500000,700,1,14.010000,2,1,12.460000,200,2,14.280000,100,1,12.430000,700,1,14.400000,100,1,12.420000,700,1,14.430000,100,1,12.370000,700,1,14.530000,100,1,ARL,324942229
2025-07-17T16:01:47.903711757Z,2025-07-17T16:01:47.903546622Z,10,2,1108,C,A,7,14.40,100,130,165135,271068105,13.040000,2,1,13.570000,15,1,13.030000,100,1,13.580000,100,1,13.020000,100,1,13.600000,15,1,12.730000,100,1,13.610000,100,1,12.710000,100,1,13.900000,100,1,12.500000,700,1,14.010000,2,1,12.460000,200,2,14.280000,100,1,12.430000,700,1,14.430000,100,1,12.420000,700,1,14.530000,100,1,12.370000,700,1,14.540000,100,1,ARL,289726421
2025-07-17T16:01:47.903714323Z,2025-07-17T16:01:47.903548861Z,10,2,1108,C,A,15,14.69,100,0,165462,271068106,13.040000,2,1,13.570000,15,1,13.030000,100,1,13.580000,100,1,13.020000,100,1,13.600000,15,1,12.730000,100,1,13.610000,100,1,12.710000,100,1,13.900000,100,1,12.500000,700,1,14.010000,2,1,12.460000,200,2,14.280000,100,1,12.430000,700,1,14.430000,100,1,12.420000,700,1,14.530000,100,1,12.370000,700,1,14.540000,100,1,ARL,324186233
2025-07-17T16:01:47.903714323Z,2025-07-17T16:01:47.903548861Z,10,2,1108,A,A,-1,14.63,100,130,165462,271068106,13.040000,2,1,13.570000,15,1,13.030000,100,1,13.580000,100,1,13.020000,100,1,13.600000,15,1,12.730000,100,1,13.610000,100,1,12.710000,100,1,13.900000,100,1,12.500000,700,1,14.010000,2,1,12.460000,200,2,14.280000,100,1,12.430000,700,1,14.430000,100,1,12.420000,700,1,14.530000,100,1,12.370000,700,1,14.540000,100,1,ARL,324942257
2025-07-17T16:01:47.904067686Z,2025-07-17T16:01:47.903902473Z,10,2,1108,A,A,6,14.19,100,130,165213,271068115,13.040000,2,1,13.570000,15,1,13.030000,100,1,13.580000,100,1,13.020000,100,1,13.600000,15,1,12.730000,100,1,13.610000,100,1,12.710000,100,1,13.900000,100,1,12.500000,700,1,14.010000,2,1,12.460000,200,2,14.190000,100,1,12.430000,700,1,14.280000,100,1,12.420000,700,1,14.430000,100,1,12.370000,700,1,14.530000,100,1,ARL,324942273
2025-07-17T16:01:47.905355779Z,2025-07-17T16:01:47.905189816Z,10,2,1108,C,A,18,15.23,100,0,165963,271068134,13.040000,2,1,13.570000,15,1,13.030000,100,1,13.580000,100,1,13.020000,100,1,13.600000,15,1,12.730000,100,1,13.610000,100,1,12.710000,100,1,13.900000,100,1,12.500000,700,1,14.010000,2,1,12.460000,200,2,14.190000,100,1,12.430000,700,1,14.280000,100,1,12.420000,700,1,14.430000,100,1,12.370000,700,1,14.530000,100,1,ARL,282776017
2025-07-17T16:01:47.905355779Z,2025-07-17T16:01:47.905189816Z,10,2,1108,A,A,-1,14.94,100,130,165963,271068134,13.040000,2,1,13.570000,15,1,13.030000,100,1,13.580000,100,1,13.020000,100,1,13.600000,15,1,12.730000,100,1,13.610000,100,1,12.710000,100,1,13.900000,100,1,12.500000,700,1,14.010000,2,1,12.460000,200,2,14.190000,100,1,12.430000,700,1,14.280000,100,1,12.420000,700,1,14.430000,100,1,12.370000,700,1,14.530000,100,1,ARL,324942277
2025-07-17T16:01:47.909479724Z,2025-07-17T16:01:47.909314303Z,10,2,1108,C,A,24,17.40,100,0,165421,271068173,13.040000,2,1,13.570000,15,1,13.030000,100,1,13.580000,100,1,13.020000,100,1,13.600000,15,1,12.730000,100,1,13.610000,100,1,12.710000,100,1,13.900000,100,1,12.500000,700,1,14.010000,2,1,12.460000,200,2,14.190000,100,1,12.430000,700,1,14.280000,100,1,12.420000,700,1,14.430000,100,1,12.370000,700,1,14.530000,100,1,ARL,323599633
2025-07-17T16:01:47.909479724Z,2025-07-17T16:01:47.909314303Z,10,2,1108,A,A,-1,17.25,100,130,165421,271068173,13.040000,2,1,13.570000,15,1,13.030000,100,1,13.580000,100,1,13.020000,100,1,13.600000,15,1,12.730000,100,1,13.610000,100,1,12.710000,100,1,13.900000,100,1,12.500000,700,1,14.010000,2,1,12.460000,200,2,14.190000,100,1,12.430000,700,1,14.280000,100,1,12.420000,700,1,14.430000,100,1,12.370000,700,1,14.530000,100,1,ARL,324942361
2025-07-17T16:01:50.799100504Z,2025-07-17T16:01:50.798934838Z,10,2,1108,A,A,2,13.59,100,130,165666,271131418,13.040000,2,1,13.570000,15,1,13.030000,100,1,13.580000,100,1,13.020000,100,1,13.590000,100,1,12.730000,100,1,13.600000,15,1,12.710000,100,1,13.610000,100,1,12.500000,700,1,13.900000,100,1,12.460000,200,2,14.010000,2,1,12.430000,700,1,14.190000,100,1,12.420000,700,1,14.280000,100,1,12.370000,700,1,14.430000,100,1,ARL,325022101
2025-07-17T16:01:50.805653961Z,2025-07-17T16:01:50.805488726Z,10,2,1108,C,A,4,13.61,100,130,165235,271131583,13.040000,2,1,13.570000,15,1,13.030000,100,1,13.580000,100,1,13.020000,100,1,13.590000,100,1,12.730000,100,1,13.600000,15,1,12.710000,100,1,13.900000,100,1,12.500000,700,1,14.010000,2,1,12.460000,200,2,14.190000,100,1,12.430000,700,1,14.280000,100,1,12.420000,700,1,14.430000,100,1,12.370000,700,1,14.530000,100,1,ARL,324782841
2025-07-17T16:01:52.133063761Z,2025-07-17T16:01:52.132898568Z,10,2,1108,C,A,3,13.60,15,130,165193,271153294,13.040000,2,1,13.570000,15,1,13.030000,100,1,13.580000,100,1,13.020000,100,1,13.590000,100,1,12.730000,100,1,13.900000,100,1,12.710000,100,1,14.010000,2,1,12.500000,700,1,14.190000,100,1,12.460000,200,2,14.280000,100,1,12.430000,700,1,14.430000,100,1,12.420000,700,1,14.530000,100,1,12.370000,700,1,14.540000,100,1,ARL,324619361
2025-07-17T16:01:53.137501962Z,2025-07-17T16:01:53.137336077Z,10,2,1108,A,A,0,13.55,15,130,165885,271200452,13.040000,2,1,13.550000,15,1,13.030000,100,1,13.570000,15,1,13.020000,100,1,13.580000,100,1,12.730000,100,1,13.590000,100,1,12.710000,100,1,13.900000,100,1,12.500000,700,1,14.010000,2,1,12.460000,200,2,14.190000,100,1,12.430000,700,1,14.280000,100,1,12.420000,700,1,14.430000,100,1,12.370000,700,1,14.530000,100,1,ARL,325109165
2025-07-17T16:01:56.264154095Z,2025-07-17T16:01:56.263988198Z,10,2,1108,C,A,2,13.58,100,0,165897,271251019,13.040000,2,1,13.550000,15,1,13.030000,100,1,13.570000,15,1,13.020000,100,1,13.590000,100,1,12.730000,100,1,13.900000,100,1,12.710000,100,1,14.010000,2,1,12.500000,700,1,14.190000,100,1,12.460000,200,2,14.280000,100,1,12.430000,700,1,14.430000,100,1,12.420000,700,1,14.530000,100,1,12.370000,700,1,14.540000,100,1,ARL,324942229
2025-07-17T16:01:56.264154095Z,2025-07-17T16:01:56.263988198Z,10,2,1108,A,A,1,13.56,100,130,165897,271251019,13.040000,2,1,13.550000,15,1,13.030000,100,1,13.560000,100,1,13.020000,100,1,13.570000,15,1,12.730000,100,1,13.590000,100,1,12.710000,100,1,13.900000,100,1,12.500000,700,1,14.010000,2,1,12.460000,200,2,14.190000,100,1,12.430000,700,1,14.280000,100,1,12.420000,700,1,14.430000,100,1,12.370000,700,1,14.530000,100,1,ARL,325176181
2025-07-17T16:01:56.269623788Z,2025-07-17T16:01:56.269458197Z,10,2,1108,C,A,4,13.90,100,130,165591,271251357,13.040000,2,1,13.550000,15,1,13.030000,100,1,13.560000,100,1,13.020000,100,1,13.570000,15,1,12.730000,100,1,13.590000,100,1,12.710000,100,1,14.010000,2,1,12.500000,700,1,14.190000,100,1,12.460000,200,2,14.280000,100,1,12.430000,700,1,14.430000,100,1,12.420000,700,1,14.530000,100,1,12.370000,700,1,14.540000,100,1,ARL,324186721
2025-07-17T16:01:56.269674232Z,2025-07-17T16:01:56.269508928Z,10,2,1108,A,A,4,13.83,100,130,165304,271251358,13.040000,2,1,13.550000,15,1,13.030000,100,1,13.560000,100,1,13.020000,100,1,13.570000,15,1,12.730000,100,1,13.590000,100,1,12.710000,100,1,13.830000,100,1,12.500000,700,1,14.010000,2,1,12.460000,200,2,14.190000,100,1,12.430000,700,1,14.280000,100,1,12.420000,700,1,14.430000,100,1,12.370000,700,1,14.530000,100,1,ARL,325176373
2025-07-17T16:01:56.272340730Z,2025-07-17T16:01:56.272175169Z,10,2,1108,C,A,21,15.76,100,0,165561,271251490,13.040000,2,1,13.550000,15,1,13.030000,100,1,13.560000,100,1,13.020000,100,1,13.570000,15,1,12.730000,100,1,13.590000,100,1,12.710000,100,1,13.830000,100,1,12.500000,700,1,14.010000,2,1,12.460000,200,2,14.190000,100,1,12.430000,700,1,14.280000,100,1,12.420000,700,1,14.430000,100,1,12.370000,700,1,14.530000,100,1,ARL,323599629
2025-07-17T16:01:56.272340730Z,2025-07-17T16:01:56.272175169Z,10,2,1108,A,A,-1,15.60,100,130,165561,271251490,13.040000,2,1,13.550000,15,1,13.030000,100,1,13.560000,100,1,13.020000,100,1,13.570000,15,1,12.730000,100,1,13.590000,100,1,12.710000,100,1,13.830000,100,1,12.500000,700,1,14.010000,2,1,12.460000,200,2,14.190000,100,1,12.430000,700,1,14.280000,100,1,12.420000,700,1,14.430000,100,1,12.370000,700,1,14.530000,100,1,ARL,325176677
2025-07-17T16:01:56.300889378Z,2025-07-17T16:01:56.300723805Z,10,2,1108,C,A,15,14.66,100,0,165573,271252044,13.040000,2,1,13.550000,15,1,13.030000,100,1,13.560000,100,1,13.020000,100,1,13.570000,15,1,12.730000,100,1,13.590000,100,1,12.710000,100,1,13.830000,100,1,12.500000,700,1,14.010000,2,1,12.460000,200,2,14.190000,100,1,12.430000,700,1,14.280000,100,1,12.420000,700,1,14.430000,100,1,12.370000,700,1,14.530000,100,1,ARL,323599625
2025-07-17T16:01:56.300889378Z,2025-07-17T16:01:56.300723805Z,10,2,1108,A,A,9,14.51,100,130,165573,271252044,13.040000,2,1,13.550000,15,1,13.030000,100,1,13.560000,100,1,13.020000,100,1,13.570000,15,1,12.730000,100,1,13.590000,100,1,12.710000,100,1,13.830000,100,1,12.500000,700,1,14.010000,2,1,12.460000,200,2,14.190000,100,1,12.430000,700,1,14.280000,100,1,12.420000,700,1,14.430000,100,1,12.370000,700,1,14.510000,100,1,ARL,325177757
2025-07-17T16:02:01.992544607Z,2025-07-17T16:02:01.992379223Z,10,2,1108,C,A,5,14.01,2,0,165384,271343251,13.040000,2,1,13.550000,15,1,13.030000,100,1,13.560000,100,1,13.020000,100,1,13.570000,15,1,12.730000,100,1,13.590000,100,1,12.710000,100,1,13.830000,100,1,12.500000,700,1,14.190000,100,1,12.460000,200,2,14.280000,100,1,12.430000,700,1,14.430000,100,1,12.420000,700,1,14.510000,100,1,12.370000,700,1,14.530000,100,1,ARL,322898193
2025-07-17T16:02:01.992544607Z,2025-07-17T16:02:01.992379223Z,10,2,1108,A,A,5,13.92,2,130,165384,271343251,13.040000,2,1,13.550000,15,1,13.030000,100,1,13.560000,100,1,13.020000,100,1,13.570000,15,1,12.730000,100,1,13.590000,100,1,12.710000,100,1,13.830000,100,1,12.500000,700,1,13.920000,2,1,12.460000,200,2,14.190000,100,1,12.430000,700,1,14.280000,100,1,12.420000,700,1,14.430000,100,1,12.370000,700,1,14.510000,100,1,ARL,325297093
2025-07-17T16:02:03.207720826Z,2025-07-17T16:02:03.207555626Z,10,2,1108,C,A,2,13.57,15,130,165200,271367066,13.040000,2,1,13.550000,15,1,13.030000,100,1,13.560000,100,1,13.020000,100,1,13.590000,100,1,12.730000,100,1,13.830000,100,1,12.710000,100,1,13.920000,2,1,12.500000,700,1,14.190000,100,1,12.460000,200,2,14.280000,100,1,12.430000,700,1,14.430000,100,1,12.420000,700,1,14.510000,100,1,12.370000,700,1,14.530000,100,1,ARL,324934601
2025-07-17T16:02:04.212956339Z,2025-07-17T16:02:04.212791108Z,10,2,1108,A,A,0,13.53,15,130,165231,271415821,13.040000,2,1,13.530000,15,1,13.030000,100,1,13.550000,15,1,13.020000,100,1,13.560000,100,1,12.730000,100,1,13.590000,100,1,12.710000,100,1,13.830000,100,1,12.500000,700,1,13.920000,2,1,12.460000,200,2,14.190000,100,1,12.430000,700,1,14.280000,100,1,12.420000,700,1,14.430000,100,1,12.370000,700,1,14.510000,100,1,ARL,325382429
2025-07-17T16:02:04.214348814Z,2025-07-17T16:02:04.214183279Z,10,2,1108,C,A,11,14.54,100,0,165535,271415834,13.040000,2,1,13.530000,15,1,13.030000,100,1,13.550000,15,1,13.020000,100,1,13.560000,100,1,12.730000,100,1,13.590000,100,1,12.710000,100,1,13.830000,100,1,12.500000,700,1,13.920000,2,1,12.460000,200,2,14.190000,100,1,12.430000,700,1,14.280000,100,1,12.420000,700,1,14.430000,100,1,12.370000,700,1,14.510000,100,1,ARL,323775433
2025-07-17T16:02:04.214348814Z,2025-07-17T16:02:04.214183279Z,10,2,1108,A,A,8,14.43,100,130,165535,271415834,13.040000,2,1,13.530000,15,1,13.030000,100,1,13.550000,15,1,13.020000,100,1,13.560000,100,1,12.730000,100,1,13.590000,100,1,12.710000,100,1,13.830000,100,1,12.500000,700,1,13.920000,2,1,12.460000,200,2,14.190000,100,1,12.430000,700,1,14.280000,100,1,12.420000,700,1,14.430000,200,2,12.370000,700,1,14.510000,100,1,ARL,325382437
2025-07-17T16:02:04.840132668Z,2025-07-17T16:02:04.839967173Z,10,2,1108,C,A,2,13.56,100,0,165495,271432190,13.040000,2,1,13.530000,15,1,13.030000,100,1,13.550000,15,1,13.020000,100,1,13.590000,100,1,12.730000,100,1,13.830000,100,1,12.710000,100,1,13.920000,2,1,12.500000,700,1,14.190000,100,1,12.460000,200,2,14.280000,100,1,12.430000,700,1,14.430000,200,2,12.420000,700,1,14.510000,100,1,12.370000,700,1,14.530000,100,1,ARL,325176181
2025-07-17T16:02:04.840132668Z,2025-07-17T16:02:04.839967173Z,10,2,1108,A,A,1,13.54,100,130,165495,271432190,13.040000,2,1,13.530000,15,1,13.030000,100,1,13.540000,100,1,13.020000,100,1,13.550000,15,1,12.730000,100,1,13.590000,100,1,12.710000,100,1,13.830000,100,1,12.500000,700,1,13.920000,2,1,12.460000,200,2,14.190000,100,1,12.430000,700,1,14.280000,100,1,12.420000,700,1,14.430000,200,2,12.370000,700,1,14.510000,100,1,ARL,325400045
2025-07-17T16:02:04.840171240Z,2025-07-17T16:02:04.840006082Z,10,2,1108,A,A,7,14.27,700,130,165158,271432192,13.040000,2,1,13.530000,15,1,13.030000,100,1,13.540000,100,1,13.020000,100,1,13.550000,15,1,12.730000,100,1,13.590000,100,1,12.710000,100,1,13.830000,100,1,12.500000,700,1,13.920000,2,1,12.460000,200,2,14.190000,100,1,12.430000,700,1,14.270000,700,1,12.420000,700,1,14.280000,100,1,12.370000,700,1,14.430000,200,2,ARL,325400053
2025-07-17T16:02:04.840210880Z,2025-07-17T16:02:04.840045694Z,10,2,1108,C,A,16,14.68,700,130,165186,271432193,13.040000,2,1,13.530000,15,1,13.030000,100,1,13.540000,100,1,13.020000,100,1,13.550000,15,1,12.730000,100,1,13.590000,100,1,12.710000,100,1,13.830000,100,1,12.500000,700,1,13.920000,2,1,12.460000,200,2,14.190000,100,1,12.430000,700,1,14.270000,700,1,12.420000,700,1,14.280000,100,1,12.370000,700,1,14.430000,200,2,ARL,283592941
2025-07-17T16:02:04.840877603Z,2025-07-17T16:02:04.840711803Z,10,2,1108,C,A,15,14.63,100,0,165800,271432231,13.040000,2,1,13.530000,15,1,13.030000,100,1,13.540000,100,1,13.020000,100,1,13.550000,15,1,12.730000,100,1,13.590000,100,1,12.710000,100,1,13.830000,100,1,12.500000,700,1,13.920000,2,1,12.460000,200,2,14.190000,100,1,12.430000,700,1,14.270000,700,1,12.420000,700,1,14.280000,100,1,12.370000,700,1,14.430000,200,2,ARL,324942257
2025-07-17T16:02:04.840877603Z,2025-07-17T16:02:04.840711803Z,10,2,1108,A,A,-1,14.59,100,130,165800,271432231,13.040000,2,1,13.530000,15,1,13.030000,100,1,13.540000,100,1,13.020000,100,1,13.550000,15,1,12.730000,100,1,13.590000,100,1,12.710000,100,1,13.830000,100,1,12.500000,700,1,13.920000,2,1,12.460000,200,2,14.190000,100,1,12.430000,700,1,14.270000,700,1,12.420000,700,1,14.280000,100,1,12.370000,700,1,14.430000,200,2,ARL,325400105
2025-07-17T16:02:11.249291142Z,2025-07-17T16:02:11.249125653Z,10,2,1108,C,A,11,14.53,100,0,165489,271526467,13.040000,2,1,13.530000,15,1,13.030000,100,1,13.540000,100,1,13.020000,100,1,13.550000,15,1,12.730000,100,1,13.590000,100,1,12.710000,100,1,13.830000,100,1,12.500000,700,1,13.920000,2,1,12.460000,200,2,14.190000,100,1,12.430000,700,1,14.270000,700,1,12.420000,700,1,14.280000,100,1,12.370000,700,1,14.430000,200,2,ARL,323775457
2025-07-17T16:02:11.249291142Z,2025-07-17T16:02:11.249125653Z,10,2,1108,A,A,9,14.42,100,130,165489,271526467,13.040000,2,1,13.530000,15,1,13.030000,100,1,13.540000,100,1,13.020000,100,1,13.550000,15,1,12.730000,100,1,13.590000,100,1,12.710000,100,1,13.830000,100,1,12.500000,700,1,13.920000,2,1,12.460000,200,2,14.190000,100,1,12.430000,700,1,14.270000,700,1,12.420000,700,1,14.280000,100,1,12.370000,700,1,14.420000,100,1,ARL,325520705
2025-07-17T16:02:15.062774661Z,2025-07-17T16:02:15.062605521Z,10,2,1108,C,A,0,13.53,15,128,169140,271576282,13.040000,2,1,13.540000,100,1,13.030000,100,1,13.550000,15,1,13.020000,100,1,13.590000,100,1,12.730000,100,1,13.830000,100,1,12.710000,100,1,13.920000,2,1,12.500000,700,1,14.190000,100,1,12.460000,200,2,14.270000,700,1,12.430000,700,1,14.280000,100,1,12.420000,700,1,14.420000,100,1,12.370000,700,1,14.430000,200,2,ARL,325382429
2025-07-17T16:02:15.068449048Z,2025-07-17T16:02:15.068283706Z,10,2,1108,C,A,1,13.55,15,130,165342,271577104,13.040000,2,1,13.540000,100,1,13.030000,100,1,13.590000,100,1,13.020000,100,1,13.830000,100,1,12.730000,100,1,13.920000,2,1,12.710000,100,1,14.190000,100,1,12.500000,700,1,14.270000,700,1,12.460000,200,2,14.280000,100,1,12.430000,700,1,14.420000,100,1,12.420000,700,1,14.430000,200,2,12.370000,700,1,14.510000,100,1,ARL,325109165
2025-07-17T16:02:20.635028489Z,2025-07-17T16:02:20.634863301Z,10,2,1108,C,A,0,13.54,100,130,165188,271675842,13.040000,2,1,13.590000,100,1,13.030000,100,1,13.830000,100,1,13.020000,100,1,13.920000,2,1,12.730000,100,1,14.190000,100,1,12.710000,100,1,14.270000,700,1,12.500000,700,1,14.280000,100,1,12.460000,200,2,14.420000,100,1,12.430000,700,1,14.430000,200,2,12.420000,700,1,14.510000,100,1,12.370000,700,1,14.560000,800,2,ARL,325400045
2025-07-17T16:02:20.635782472Z,2025-07-17T16:02:20.635616654Z,10,2,1108,C,A,11,14.59,100,0,165818,271675858,13.040000,2,1,13.590000,100,1,13.030000,100,1,13.830000,100,1,13.020000,100,1,13.920000,2,1,12.730000,100,1,14.190000,100,1,12.710000,100,1,14.270000,700,1,12.500000,700,1,14.280000,100,1,12.460000,200,2,14.420000,100,1,12.430000,700,1,14.430000,200,2,12.420000,700,1,14.510000,100,1,12.370000,700,1,14.560000,800,2,ARL,325400105
2025-07-17T16:02:20.635782472Z,2025-07-17T16:02:20.635616654Z,10,2,1108,A,A,-1,14.64,100,130,165818,271675858,13.040000,2,1,13.590000,100,1,13.030000,100,1,13.830000,100,1,13.020000,100,1,13.920000,2,1,12.730000,100,1,14.190000,100,1,12.710000,100,1,14.270000,700,1,12.500000,700,1,14.280000,100,1,12.460000,200,2,14.420000,100,1,12.430000,700,1,14.430000,200,2,12.420000,700,1,14.510000,100,1,12.370000,700,1,14.560000,800,2,ARL,325714169
2025-07-17T16:02:20.650466751Z,2025-07-17T16:02:20.650301212Z,10,2,1108,C,A,0,13.59,100,130,165539,271676032,13.040000,2,1,13.830000,100,1,13.030000,100,1,13.920000,2,1,13.020000,100,1,14.190000,100,1,12.730000,100,1,14.270000,700,1,12.710000,100,1,14.280000,100,1,12.500000,700,1,14.420000,100,1,12.460000,200,2,14.430000,200,2,12.430000,700,1,14.510000,100,1,12.420000,700,1,14.560000,800,2,12.370000,700,1,14.570000,100,1,ARL,325022101
2025-07-17T16:02:20.650501448Z,2025-07-17T16:02:20.650335946Z,10,2,1108,C,A,3,14.27,700,130,165502,271676033,13.040000,2,1,13.830000,100,1,13.030000,100,1,13.920000,2,1,13.020000,100,1,14.190000,100,1,12.730000,100,1,14.280000,100,1,12.710000,100,1,14.420000,100,1,12.500000,700,1,14.430000,200,2,12.460000,200,2,14.510000,100,1,12.430000,700,1,14.560000,800,2,12.420000,700,1,14.570000,100,1,12.370000,700,1,14.600000,700,1,ARL,325400053
2025-07-17T16:02:20.650546483Z,2025-07-17T16:02:20.650381040Z,10,2,1108,A,A,7,14.53,700,130,165443,271676035,13.040000,2,1,13.830000,100,1,13.030000,100,1,13.920000,2,1,13.020000,100,1,14.190000,100,1,12.730000,100,1,14.280000,100,1,12.710000,100,1,14.420000,100,1,12.500000,700,1,14.430000,200,2,12.460000,200,2,14.510000,100,1,12.430000,700,1,14.530000,700,1,12.420000,700,1,14.560000,800,2,12.370000,700,1,14.570000,100,1,ARL,325714545
2025-07-17T16:02:20.651186537Z,2025-07-17T16:02:20.651020858Z,10,2,1108,C,A,4,14.42,100,0,165679,271676048,13.040000,2,1,13.830000,100,1,13.030000,100,1,13.920000,2,1,13.020000,100,1,14.190000,100,1,12.730000,100,1,14.280000,100,1,12.710000,100,1,14.430000,200,2,12.500000,700,1,14.510000,100,1,12.460000,200,2,14.530000,700,1,12.430000,700,1,14.560000,800,2,12.420000,700,1,14.570000,100,1,12.370000,700,1,14.600000,700,1,ARL,325520705
2025-07-17T16:02:20.651186537Z,2025-07-17T16:02:20.651020858Z,10,2,1108,A,A,-1,14.73,100,130,165679,271676048,13.040000,2,1,13.830000,100,1,13.030000,100,1,13.920000,2,1,13.020000,100,1,14.190000,100,1,12.730000,100,1,14.280000,100,1,12.710000,100,1,14.430000,200,2,12.500000,700,1,14.510000,100,1,12.460000,200,2,14.530000,700,1,12.430000,700,1,14.560000,800,2,12.420000,700,1,14.570000,100,1,12.370000,700,1,14.600000,700,1,ARL,325714577
2025-07-17T16:02:20.651201182Z,2025-07-17T16:02:20.651035000Z,10,2,1108,C,A,2,14.19,100,130,166182,271676049,13.040000,2,1,13.830000,100,1,13.030000,100,1,13.920000,2,1,13.020000,100,1,14.280000,100,1,12.730000,100,1,14.430000,200,2,12.710000,100,1,14.510000,100,1,12.500000,700,1,14.530000,700,1,12.460000,200,2,14.560000,800,2,12.430000,700,1,14.570000,100,1,12.420000,700,1,14.600000,700,1,12.370000,700,1,14.640000,100,1,ARL,324942273
2025-07-17T16:02:20.651459317Z,2025-07-17T16:02:20.651293729Z,10,2,1108,C,A,19,17.25,100,0,165588,271676055,13.040000,2,1,13.830000,100,1,13.030000,100,1,13.920000,2,1,13.020000,100,1,14.280000,100,1,12.730000,100,1,14.430000,200,2,12.710000,100,1,14.510000,100,1,12.500000,700,1,14.530000,700,1,12.460000,200,2,14.560000,800,2,12.430000,700,1,14.570000,100,1,12.420000,700,1,14.600000,700,1,12.370000,700,1,14.640000,100,1,ARL,324942361
2025-07-17T16:02:20.651459317Z,2025-07-17T16:02:20.651293729Z,10,2,1108,A,A,-1,17.57,100,130,165588,271676055,13.040000,2,1,13.830000,100,1,13.030000,100,1,13.920000,2,1,13.020000,100,1,14.280000,100,1,12.730000,100,1,14.430000,200,2,12.710000,100,1,14.510000,100,1,12.500000,700,1,14.530000,700,1,12.460000,200,2,14.560000,800,2,12.430000,700,1,14.570000,100,1,12.420000,700,1,14.600000,700,1,12.370000,700,1,14.640000,100,1,ARL,325714589
2025-07-17T16:02:20.651558948Z,2025-07-17T16:02:20.651393708Z,10,2,1108,A,A,4,14.45,100,130,165240,271676057,13.040000,2,1,13.830000,100,1,13.030000,100,1,13.920000,2,1,13.020000,100,1,14.280000,100,1,12.730000,100,1,14.430000,200,2,12.710000,100,1,14.450000,100,1,12.500000,700,1,14.510000,100,1,12.460000,200,2,14.530000,700,1,12.430000,700,1,14.560000,800,2,12.420000,700,1,14.570000,100,1,12.370000,700,1,14.600000,700,1,ARL,325714601
2025-07-17T16:02:20.651787813Z,2025-07-17T16:02:20.651618897Z,10,2,1108,C,A,3,14.43,100,0,168916,271676089,13.040000,2,1,13.830000,100,1,13.030000,100,1,13.920000,2,1,13.020000,100,1,14.280000,100,1,12.730000,100,1,14.430000,100,1,12.710000,100,1,14.450000,100,1,12.500000,700,1,14.510000,100,1,12.460000,200,2,14.530000,700,1,12.430000,700,1,14.560000,800,2,12.420000,700,1,14.570000,100,1,12.370000,700,1,14.600000,700,1,ARL,325382437
2025-07-17T16:02:20.651787813Z,2025-07-17T16:02:20.651618897Z,10,2,1108,A,A,-1,14.73,100,128,168916,271676089,13.040000,2,1,13.830000,100,1,13.030000,100,1,13.920000,2,1,13.020000,100,1,14.280000,100,1,12.730000,100,1,14.430000,100,1,12.710000,100,1,14.450000,100,1,12.500000,700,1,14.510000,100,1,12.460000,200,2,14.530000,700,1,12.430000,700,1,14.560000,800,2,12.420000,700,1,14.570000,100,1,12.370000,700,1,14.600000,700,1,ARL,325714613
2025-07-17T16:02:20.652021618Z,2025-07-17T16:02:20.651854531Z,10,2,1108,C,A,8,14.57,100,0,167087,271676104,13.040000,2,1,13.830000,100,1,13.030000,100,1,13.920000,2,1,13.020000,100,1,14.280000,100,1,12.730000,100,1,14.430000,100,1,12.710000,100,1,14.450000,100,1,12.500000,700,1,14.510000,100,1,12.460000,200,2,14.530000,700,1,12.430000,700,1,14.560000,800,2,12.420000,700,1,14.600000,700,1,12.370000,700,1,14.640000,100,1,ARL,324619409
2025-07-17T16:02:20.652021618Z,2025-07-17T16:02:20.651854531Z,10,2,1108,A,A,-1,14.80,100,130,167087,271676104,13.040000,2,1,13.830000,100,1,13.030000,100,1,13.920000,2,1,13.020000,100,1,14.280000,100,1,12.730000,100,1,14.430000,100,1,12.710000,100,1,14.450000,100,1,12.500000,700,1,14.510000,100,1,12.460000,200,2,14.530000,700,1,12.430000,700,1,14.560000,800,2,12.420000,700,1,14.600000,700,1,12.370000,700,1,14.640000,100,1,ARL,325714629
2025-07-17T16:02:20.652097288Z,2025-07-17T16:02:20.651932129Z,10,2,1108,C,A,3,14.43,100,130,165159,271676110,13.040000,2,1,13.830000,100,1,13.030000,100,1,13.920000,2,1,13.020000,100,1,14.280000,100,1,12.730000,100,1,14.450000,100,1,12.710000,100,1,14.510000,100,1,12.500000,700,1,14.530000,700,1,12.460000,200,2,14.560000,800,2,12.430000,700,1,14.600000,700,1,12.420000,700,1,14.640000,100,1,12.370000,700,1,14.680000,700,1,ARL,324186781
2025-07-17T16:02:20.652160470Z,2025-07-17T16:02:20.651994883Z,10,2,1108,C,A,16,15.60,100,0,165587,271676111,13.040000,2,1,13.830000,100,1,13.030000,100,1,13.920000,2,1,13.020000,100,1,14.280000,100,1,12.730000,100,1,14.450000,100,1,12.710000,100,1,14.510000,100,1,12.500000,700,1,14.530000,700,1,12.460000,200,2,14.560000,800,2,12.430000,700,1,14.600000,700,1,12.420000,700,1,14.640000,100,1,12.370000,700,1,14.680000,700,1,ARL,325176677
2025-07-17T16:02:20.652160470Z,2025-07-17T16:02:20.651994883Z,10,2,1108,A,A,-1,15.91,100,130,165587,271676111,13.040000,2,1,13.830000,100,1,13.030000,100,1,13.920000,2,1,13.020000,100,1,14.280000,100,1,12.730000,100,1,14.450000,100,1,12.710000,100,1,14.510000,100,1,12.500000,700,1,14.530000,700,1,12.460000,200,2,14.560000,800,2,12.430000,700,1,14.600000,700,1,12.420000,700,1,14.640000,100,1,12.370000,700,1,14.680000,700,1,ARL,325714633
2025-07-17T16:02:20.652259931Z,2025-07-17T16:02:20.652094426Z,10,2,1108,A,A,8,14.63,100,130,165505,271676118,13.040000,2,1,13.830000,100,1,13.030000,100,1,13.920000,2,1,13.020000,100,1,14.280000,100,1,12.730000,100,1,14.450000,100,1,12.710000,100,1,14.510000,100,1,12.500000,700,1,14.530000,700,1,12.460000,200,2,14.560000,800,2,12.430000,700,1,14.600000,700,1,12.420000,700,1,14.630000,100,1,12.370000,700,1,14.640000,100,1,ARL,325714653
2025-07-17T16:02:20.653626391Z,2025-07-17T16:02:20.653460814Z,10,2,1108,A,B,0,13.27,10,130,165577,271676147,13.270000,10,1,13.830000,100,1,13.040000,2,1,13.920000,2,1,13.030000,100,1,14.280000,100,1,13.020000,100,1,14.450000,100,1,12.730000,100,1,14.510000,100,1,12.710000,100,1,14.530000,700,1,12.500000,700,1,14.560000,800,2,12.460000,200,2,14.600000,700,1,12.430000,700,1,14.630000,100,1,12.420000,700,1,14.640000,100,1,ARL,325714717
2025-07-17T16:02:20.653627232Z,2025-07-17T16:02:20.653461966Z,10,2,1108,A,A,0,13.83,15,130,165266,271676148,13.270000,10,1,13.830000,115,2,13.040000,2,1,13.920000,2,1,13.030000,100,1,14.280000,100,1,13.020000,100,1,14.450000,100,1,12.730000,100,1,14.510000,100,1,12.710000,100,1,14.530000,700,1,12.500000,700,1,14.560000,800,2,12.460000,200,2,14.600000,700,1,12.430000,700,1,14.630000,100,1,12.420000,700,1,14.640000,100,1,ARL,325714721
2025-07-17T16:02:20.653886896Z,2025-07-17T16:02:20.653721185Z,10,2,1108,C,B,3,13.02,100,0,165711,271676153,13.270000,10,1,13.830000,115,2,13.040000,2,1,13.920000,2,1,13.030000,100,1,14.280000,100,1,12.730000,100,1,14.450000,100,1,12.710000,100,1,14.510000,100,1,12.500000,700,1,14.530000,700,1,12.460000,200,2,14.560000,800,2,12.430000,700,1,14.600000,700,1,12.420000,700,1,14.630000,100,1,12.370000,700,1,14.640000,100,1,ARL,320485385
2025-07-17T16:02:20.653886896Z,2025-07-17T16:02:20.653721185Z,10,2,1108,A,B,1,13.26,100,130,165711,271676153,13.270000,10,1,13.830000,115,2,13.260000,100,1,13.920000,2,1,13.040000,2,1,14.280000,100,1,13.030000,100,1,14.450000,100,1,12.730000,100,1,14.510000,100,1,12.710000,100,1,14.530000,700,1,12.500000,700,1,14.560000,800,2,12.460000,200,2,14.600000,700,1,12.430000,700,1,14.630000,100,1,12.420000,700,1,14.640000,100,1,ARL,325714729
2025-07-17T16:02:20.655277066Z,2025-07-17T16:02:20.655111649Z,10,2,1108,C,B,2,13.04,2,0,165417,271676165,13.270000,10,1,13.830000,115,2,13.260000,100,1,13.920000,2,1,13.030000,100,1,14.280000,100,1,12.730000,100,1,14.450000,100,1,12.710000,100,1,14.510000,100,1,12.500000,700,1,14.530000,700,1,12.460000,200,2,14.560000,800,2,12.430000,700,1,14.600000,700,1,12.420000,700,1,14.630000,100,1,12.370000,700,1,14.640000,100,1,ARL,293594281
2025-07-17T16:02:20.655277066Z,2025-07-17T16:02:20.655111649Z,10,2,1108,A,B,3,12.91,2,130,165417,271676165,13.270000,10,1,13.830000,115,2,13.260000,100,1,13.920000,2,1,13.030000,100,1,14.280000,100,1,12.910000,2,1,14.450000,100,1,12.730000,100,1,14.510000,100,1,12.710000,100,1,14.530000,700,1,12.500000,700,1,14.560000,800,2,12.460000,200,2,14.600000,700,1,12.430000,700,1,14.630000,100,1,12.420000,700,1,14.640000,100,1,ARL,325714741
2025-07-17T16:02:20.663374576Z,2025-07-17T16:02:20.663209235Z,10,2,1108,C,A,0,13.83,100,130,165341,271676274,13.270000,10,1,13.830000,15,1,13.260000,100,1,13.920000,2,1,13.030000,100,1,14.280000,100,1,12.910000,2,1,14.450000,100,1,12.730000,100,1,14.510000,100,1,12.710000,100,1,14.530000,700,1,12.500000,700,1,14.560000,800,2,12.460000,200,2,14.600000,700,1,12.430000,700,1,14.630000,100,1,12.420000,700,1,14.640000,100,1,ARL,325176373
2025-07-17T16:02:20.663406861Z,2025-07-17T16:02:20.663241882Z,10,2,1108,C,A,5,14.53,700,130,164979,271676275,13.270000,10,1,13.830000,15,1,13.260000,100,1,13.920000,2,1,13.030000,100,1,14.280000,100,1,12.910000,2,1,14.450000,100,1,12.730000,100,1,14.510000,100,1,12.710000,100,1,14.560000,800,2,12.500000,700,1,14.600000,700,1,12.460000,200,2,14.630000,100,1,12.430000,700,1,14.640000,100,1,12.420000,700,1,14.680000,700,1,ARL,325714545
2025-07-17T16:02:20.663426974Z,2025-07-17T16:02:20.663261632Z,10,2,1108,A,A,2,14.11,100,130,165342,271676276,13.270000,10,1,13.830000,15,1,13.260000,100,1,13.920000,2,1,13.030000,100,1,14.110000,100,1,12.910000,2,1,14.280000,100,1,12.730000,100,1,14.450000,100,1,12.710000,100,1,14.510000,100,1,12.500000,700,1,14.560000,800,2,12.460000,200,2,14.600000,700,1,12.430000,700,1,14.630000,100,1,12.420000,700,1,14.640000,100,1,ARL,325714905
2025-07-17T16:02:20.663559466Z,2025-07-17T16:02:20.663394059Z,10,2,1108,A,A,-1,15.94,100,130,165407,271676277,13.270000,10,1,13.830000,15,1,13.260000,100,1,13.920000,2,1,13.030000,100,1,14.110000,100,1,12.910000,2,1,14.280000,100,1,12.730000,100,1,14.450000,100,1,12.710000,100,1,14.510000,100,1,12.500000,700,1,14.560000,800,2,12.460000,200,2,14.600000,700,1,12.430000,700,1,14.630000,100,1,12.420000,700,1,14.640000,100,1,ARL,325714909
2025-07-17T16:02:20.663572634Z,2025-07-17T16:02:20.663407337Z,10,2,1108,C,A,16,15.59,100,130,165297,271676278,13.270000,10,1,13.830000,15,1,13.260000,100,1,13.920000,2,1,13.030000,100,1,14.110000,100,1,12.910000,2,1,14.280000,100,1,12.730000,100,1,14.450000,100,1,12.710000,100,1,14.510000,100,1,12.500000,700,1,14.560000,800,2,12.460000,200,2,14.600000,700,1,12.430000,700,1,14.630000,100,1,12.420000,700,1,14.640000,100,1,ARL,323730697
2025-07-17T16:02:20.664956400Z,2025-07-17T16:02:20.664790768Z,10,2,1108,C,A,20,17.57,100,0,165632,271676310,13.270000,10,1,13.830000,15,1,13.260000,100,1,13.920000,2,1,13.030000,100,1,14.110000,100,1,12.910000,2,1,14.280000,100,1,12.730000,100,1,14.450000,100,1,12.710000,100,1,14.510000,100,1,12.500000,700,1,14.560000,800,2,12.460000,200,2,14.600000,700,1,12.430000,700,1,14.630000,100,1,12.420000,700,1,14.640000,100,1,ARL,325714589
2025-07-17T16:02:20.664956400Z,2025-07-17T16:02:20.664790768Z,10,2,1108,A,A,-1,17.76,100,130,165632,271676310,13.270000,10,1,13.830000,15,1,13.260000,100,1,13.920000,2,1,13.030000,100,1,14.110000,100,1,12.910000,2,1,14.280000,100,1,12.730000,100,1,14.450000,100,1,12.710000,100,1,14.510000,100,1,12.500000,700,1,14.560000,800,2,12.460000,200,2,14.600000,700,1,12.430000,700,1,14.630000,100,1,12.420000,700,1,14.640000,100,1,ARL,325714949
2025-07-17T16:02:20.665129279Z,2025-07-17T16:02:20.664963386Z,10,2,1108,C,A,12,14.80,100,0,165893,271676320,13.270000,10,1,13.830000,15,1,13.260000,100,1,13.920000,2,1,13.030000,100,1,14.110000,100,1,12.910000,2,1,14.280000,100,1,12.730000,100,1,14.450000,100,1,12.710000,100,1,14.510000,100,1,12.500000,700,1,14.560000,800,2,12.460000,200,2,14.600000,700,1,12.430000,700,1,14.630000,100,1,12.420000,700,1,14.640000,100,1,ARL,325714629
2025-07-17T16:02:20.665129279Z,2025-07-17T16:02:20.664963386Z,10,2,1108,A,A,-1,14.96,100,130,165893,271676320,13.270000,10,1,13.830000,15,1,13.260000,100,1,13.920000,2,1,13.030000,100,1,14.110000,100,1,12.910000,2,1,14.280000,100,1,12.730000,100,1,14.450000,100,1,12.710000,100,1,14.510000,100,1,12.500000,700,1,14.560000,800,2,12.460000,200,2,14.600000,700,1,12.430000,700,1,14.630000,100,1,12.420000,700,1,14.640000,100,1,ARL,325714953
2025-07-17T16:02:20.665200392Z,2025-07-17T16:02:20.665034825Z,10,2,1108,C,A,16,15.91,100,0,165567,271676330,13.270000,10,1,13.830000,15,1,13.260000,100,1,13.920000,2,1,13.030000,100,1,14.110000,100,1,12.910000,2,1,14.280000,100,1,12.730000,100,1,14.450000,100,1,12.710000,100,1,14.510000,100,1,12.500000,700,1,14.560000,800,2,12.460000,200,2,14.600000,700,1,12.430000,700,1,14.630000,100,1,12.420000,700,1,14.640000,100,1,ARL,325714633
2025-07-17T16:02:20.665200392Z,2025-07-17T16:02:20.665034825Z,10,2,1108,A,A,-1,16.08,100,130,165567,271676330,13.270000,10,1,13.830000,15,1,13.260000,100,1,13.920000,2,1,13.030000,100,1,14.110000,100,1,12.910000,2,1,14.280000,100,1,12.730000,100,1,14.450000,100,1,12.710000,100,1,14.510000,100,1,12.500000,700,1,14.560000,800,2,12.460000,200,2,14.600000,700,1,12.430000,700,1,14.630000,100,1,12.420000,700,1,14.640000,100,1,ARL,325714957
2025-07-17T16:02:20.665457595Z,2025-07-17T16:02:20.665292049Z,10,2,1108,C,A,12,14.94,100,0,165546,271676355,13.270000,10,1,13.830000,15,1,13.260000,100,1,13.920000,2,1,13.030000,100,1,14.110000,100,1,12.910000,2,1,14.280000,100,1,12.730000,100,1,14.450000,100,1,12.710000,100,1,14.510000,100,1,12.500000,700,1,14.560000,800,2,12.460000,200,2,14.600000,700,1,12.430000,700,1,14.630000,100,1,12.420000,700,1,14.640000,100,1,ARL,324942277
2025-07-17T16:02:20.665457595Z,2025-07-17T16:02:20.665292049Z,10,2,1108,A,A,-1,15.38,100,130,165546,271676355,13.270000,10,1,13.830000,15,1,13.260000,100,1,13.920000,2,1,13.030000,100,1,14.110000,100,1,12.910000,2,1,14.280000,100,1,12.730000,100,1,14.450000,100,1,12.710000,100,1,14.510000,100,1,12.500000,700,1,14.560000,800,2,12.460000,200,2,14.600000,700,1,12.430000,700,1,14.630000,100,1,12.420000,700,1,14.640000,100,1,ARL,325714965
2025-07-17T16:02:20.669701452Z,2025-07-17T16:02:20.669536385Z,10,2,1108,C,A,2,14.11,100,130,165067,271676398,13.270000,10,1,13.830000,15,1,13.260000,100,1,13.920000,2,1,13.030000,100,1,14.280000,100,1,12.910000,2,1,14.450000,100,1,12.730000,100,1,14.510000,100,1,12.710000,100,1,14.560000,800,2,12.500000,700,1,14.600000,700,1,12.460000,200,2,14.630000,100,1,12.430000,700,1,14.640000,100,1,12.420000,700,1,14.680000,700,1,ARL,325714905
2025-07-17T16:02:20.669748954Z,2025-07-17T16:02:20.669583810Z,10,2,1108,A,A,2,14.26,100,130,165144,271676399,13.270000,10,1,13.830000,15,1,13.260000,100,1,13.920000,2,1,13.030000,100,1,14.260000,100,1,12.910000,2,1,14.280000,100,1,12.730000,100,1,14.450000,100,1,12.710000,100,1,14.510000,100,1,12.500000,700,1,14.560000,800,2,12.460000,200,2,14.600000,700,1,12.430000,700,1,14.630000,100,1,12.420000,700,1,14.640000,100,1,ARL,325715045
2025-07-17T16:02:20.669752979Z,2025-07-17T16:02:20.669587514Z,10,2,1108,C,A,5,14.51,100,0,165465,271676400,13.270000,10,1,13.830000,15,1,13.260000,100,1,13.920000,2,1,13.030000,100,1,14.260000,100,1,12.910000,2,1,14.280000,100,1,12.730000,100,1,14.450000,100,1,12.710000,100,1,14.560000,800,2,12.500000,700,1,14.600000,700,1,12.460000,200,2,14.630000,100,1,12.430000,700,1,14.640000,100,1,12.420000,700,1,14.680000,700,1,ARL,325177757
2025-07-17T16:02:20.669752979Z,2025-07-17T16:02:20.669587514Z,10,2,1108,A,A,-1,14.96,100,130,165465,271676400,13.270000,10,1,13.830000,15,1,13.260000,100,1,13.920000,2,1,13.030000,100,1,14.260000,100,1,12.910000,2,1,14.280000,100,1,12.730000,100,1,14.450000,100,1,12.710000,100,1,14.560000,800,2,12.500000,700,1,14.600000,700,1,12.460000,200,2,14.630000,100,1,12.430000,700,1,14.640000,100,1,12.420000,700,1,14.680000,700,1,ARL,325715053
2025-07-17T16:02:20.685252049Z,2025-07-17T16:02:20.685086585Z,10,2,1108,C,A,8,14.64,100,0,165464,271676621,13.270000,10,1,13.830000,15,1,13.260000,100,1,13.920000,2,1,13.030000,100,1,14.260000,100,1,12.910000,2,1,14.280000,100,1,12.730000,100,1,14.450000,100,1,12.710000,100,1,14.560000,800,2,12.500000,700,1,14.600000,700,1,12.460000,200,2,14.630000,100,1,12.430000,700,1,14.680000,700,1,12.420000,700,1,14.730000,200,2,ARL,325714169
2025-07-17T16:02:20.685252049Z,2025-07-17T16:02:20.685086585Z,10,2,1108,A,A,-1,15.06,100,130,165464,271676621,13.270000,10,1,13.830000,15,1,13.260000,100,1,13.920000,2,1,13.030000,100,1,14.260000,100,1,12.910000,2,1,14.280000,100,1,12.730000,100,1,14.450000,100,1,12.710000,100,1,14.560000,800,2,12.500000,700,1,14.600000,700,1,12.460000,200,2,14.630000,100,1,12.430000,700,1,14.680000,700,1,12.420000,700,1,14.730000,200,2,ARL,325715113
2025-07-17T16:02:20.832112637Z,2025-07-17T16:02:20.831947250Z,10,2,1108,A,A,8,14.68,700,130,165387,271678584,13.270000,10,1,13.830000,15,1,13.260000,100,1,13.920000,2,1,13.030000,100,1,14.260000,100,1,12.910000,2,1,14.280000,100,1,12.730000,100,1,14.450000,100,1,12.710000,100,1,14.560000,800,2,12.500000,700,1,14.600000,700,1,12.460000,200,2,14.630000,100,1,12.430000,700,1,14.680000,1400,2,12.420000,700,1,14.730000,200,2,ARL,325716945
2025-07-17T16:02:20.936787418Z,2025-07-17T16:02:20.936622241Z,10,2,1108,C,B,1,13.26,100,130,165177,271679553,13.270000,10,1,13.830000,15,1,13.030000,100,1,13.920000,2,1,12.910000,2,1,14.260000,100,1,12.730000,100,1,14.280000,100,1,12.710000,100,1,14.450000,100,1,12.500000,700,1,14.560000,800,2,12.460000,200,2,14.600000,700,1,12.430000,700,1,14.630000,100,1,12.420000,700,1,14.680000,1400,2,12.370000,700,1,14.730000,200,2,ARL,325714729
2025-07-17T16:02:20.936837611Z,2025-07-17T16:02:20.936672130Z,10,2,1108,A,A,1,13.91,5,130,165481,271679555,13.270000,10,1,13.830000,15,1,13.030000,100,1,13.910000,5,1,12.910000,2,1,13.920000,2,1,12.730000,100,1,14.260000,100,1,12.710000,100,1,14.280000,100,1,12.500000,700,1,14.450000,100,1,12.460000,200,2,14.560000,800,2,12.430000,700,1,14.600000,700,1,12.420000,700,1,14.630000,100,1,12.370000,700,1,14.680000,1400,2,ARL,325718477
2025-07-17T16:02:20.936999211Z,2025-07-17T16:02:20.936833988Z,10,2,1108,A,A,1,13.84,100,130,165223,271679558,13.270000,10,1,13.830000,15,1,13.030000,100,1,13.840000,100,1,12.910000,2,1,13.910000,5,1,12.730000,100,1,13.920000,2,1,12.710000,100,1,14.260000,100,1,12.500000,700,1,14.280000,100,1,12.460000,200,2,14.450000,100,1,12.430000,700,1,14.560000,800,2,12.420000,700,1,14.600000,700,1,12.370000,700,1,14.630000,100,1,ARL,325718485
2025-07-17T16:02:20.937744264Z,2025-07-17T16:02:20.937578907Z,10,2,1108,C,A,13,15.06,100,0,165357,271679565,13.270000,10,1,13.830000,15,1,13.030000,100,1,13.840000,100,1,12.910000,2,1,13.910000,5,1,12.730000,100,1,13.920000,2,1,12.710000,100,1,14.260000,100,1,12.500000,700,1,14.280000,100,1,12.460000,200,2,14.450000,100,1,12.430000,700,1,14.560000,800,2,12.420000,700,1,14.600000,700,1,12.370000,700,1,14.630000,100,1,ARL,325715113
2025-07-17T16:02:20.937744264Z,2025-07-17T16:02:20.937578907Z,10,2,1108,A,A,-1,14.91,100,130,165357,271679565,13.270000,10,1,13.830000,15,1,13.030000,100,1,13.840000,100,1,12.910000,2,1,13.910000,5,1,12.730000,100,1,13.920000,2,1,12.710000,100,1,14.260000,100,1,12.500000,700,1,14.280000,100,1,12.460000,200,2,14.450000,100,1,12.430000,700,1,14.560000,800,2,12.420000,700,1,14.600000,700,1,12.370000,700,1,14.630000,100,1,ARL,325718509
2025-07-17T16:02:20.937901293Z,2025-07-17T16:02:20.937736247Z,10,2,1108,C,A,2,13.91,5,130,165046,271679567,13.270000,10,1,13.830000,15,1,13.030000,100,1,13.840000,100,1,12.910000,2,1,13.920000,2,1,12.730000,100,1,14.260000,100,1,12.710000,100,1,14.280000,100,1,12.500000,700,1,14.450000,100,1,12.460000,200,2,14.560000,800,2,12.430000,700,1,14.600000,700,1,12.420000,700,1,14.630000,100,1,12.370000,700,1,14.680000,1400,2,ARL,325718477
2025-07-17T16:02:20.938093286Z,2025-07-17T16:02:20.937927380Z,10,2,1108,C,A,12,14.96,100,0,165906,271679569,13.270000,10,1,13.830000,15,1,13.030000,100,1,13.840000,100,1,12.910000,2,1,13.920000,2,1,12.730000,100,1,14.260000,100,1,12.710000,100,1,14.280000,100,1,12.500000,700,1,14.450000,100,1,12.460000,200,2,14.560000,800,2,12.430000,700,1,14.600000,700,1,12.420000,700,1,14.630000,100,1,12.370000,700,1,14.680000,1400,2,ARL,325715053
2025-07-17T16:02:20.938093286Z,2025-07-17T16:02:20.937927380Z,10,2,1108,A,A,-1,14.81,100,130,165906,271679569,13.270000,10,1,13.830000,15,1,13.030000,100,1,13.840000,100,1,12.910000,2,1,13.920000,2,1,12.730000,100,1,14.260000,100,1,12.710000,100,1,14.280000,100,1,12.500000,700,1,14.450000,100,1,12.460000,200,2,14.560000,800,2,12.430000,700,1,14.600000,700,1,12.420000,700,1,14.630000,100,1,12.370000,700,1,14.680000,1400,2,ARL,325718517
2025-07-17T16:02:20.938297839Z,2025-07-17T16:02:20.938132716Z,10,2,1108,C,A,18,16.08,100,0,165123,271679571,13.270000,10,1,13.830000,15,1,13.030000,100,1,13.840000,100,1,12.910000,2,1,13.920000,2,1,12.730000,100,1,14.260000,100,1,12.710000,100,1,14.280000,100,1,12.500000,700,1,14.450000,100,1,12.460000,200,2,14.560000,800,2,12.430000,700,1,14.600000,700,1,12.420000,700,1,14.630000,100,1,12.370000,700,1,14.680000,1400,2,ARL,325714957
2025-07-17T16:02:20.938297839Z,2025-07-17T16:02:20.938132716Z,10,2,1108,A,A,-1,15.92,100,130,165123,271679571,13.270000,10,1,13.830000,15,1,13.030000,100,1,13.840000,100,1,12.910000,2,1,13.920000,2,1,12.730000,100,1,14.260000,100,1,12.710000,100,1,14.280000,100,1,12.500000,700,1,14.450000,100,1,12.460000,200,2,14.560000,800,2,12.430000,700,1,14.600000,700,1,12.420000,700,1,14.630000,100,1,12.370000,700,1,14.680000,1400,2,ARL,325718525
2025-07-17T16:02:20.938616654Z,2025-07-17T16:02:20.938451331Z,10,2,1108,C,A,13,14.96,100,0,165323,271679575,13.270000,10,1,13.830000,15,1,13.030000,100,1,13.840000,100,1,12.910000,2,1,13.920000,2,1,12.730000,100,1,14.260000,100,1,12.710000,100,1,14.280000,100,1,12.500000,700,1,14.450000,100,1,12.460000,200,2,14.560000,800,2,12.430000,700,1,14.600000,700,1,12.420000,700,1,14.630000,100,1,12.370000,700,1,14.680000,1400,2,ARL,325714953
2025-07-17T16:02:20.938616654Z,2025-07-17T16:02:20.938451331Z,10,2,1108,A,A,-1,14.81,100,130,165323,271679575,13.270000,10,1,13.830000,15,1,13.030000,100,1,13.840000,100,1,12.910000,2,1,13.920000,2,1,12.730000,100,1,14.260000,100,1,12.710000,100,1,14.280000,100,1,12.500000,700,1,14.450000,100,1,12.460000,200,2,14.560000,800,2,12.430000,700,1,14.600000,700,1,12.420000,700,1,14.630000,100,1,12.370000,700,1,14.680000,1400,2,ARL,325718549
2025-07-17T16:02:20.938889819Z,2025-07-17T16:02:20.938724516Z,10,2,1108,C,A,20,17.76,100,0,165303,271679576,13.270000,10,1,13.830000,15,1,13.030000,100,1,13.840000,100,1,12.910000,2,1,13.920000,2,1,12.730000,100,1,14.260000,100,1,12.710000,100,1,14.280000,100,1,12.500000,700,1,14.450000,100,1,12.460000,200,2,14.560000,800,2,12.430000,700,1,14.600000,700,1,12.420000,700,1,14.630000,100,1,12.370000,700,1,14.680000,1400,2,ARL,325714949
2025-07-17T16:02:20.938889819Z,2025-07-17T16:02:20.938724516Z,10,2,1108,A,A,-1,17.58,100,130,165303,271679576,13.270000,10,1,13.830000,15,1,13.030000,100,1,13.840000,100,1,12.910000,2,1,13.920000,2,1,12.730000,100,1,14.260000,100,1,12.710000,100,1,14.280000,100,1,12.500000,700,1,14.450000,100,1,12.460000,200,2,14.560000,800,2,12.430000,700,1,14.600000,700,1,12.420000,700,1,14.630000,100,1,12.370000,700,1,14.680000,1400,2,ARL,325718557
2025-07-17T16:02:20.939554686Z,2025-07-17T16:02:20.939389367Z,10,2,1108,A,B,2,13.02,100,130,165319,271679578,13.270000,10,1,13.830000,15,1,13.030000,100,1,13.840000,100,1,13.020000,100,1,13.920000,2,1,12.910000,2,1,14.260000,100,1,12.730000,100,1,14.280000,100,1,12.710000,100,1,14.450000,100,1,12.500000,700,1,14.560000,800,2,12.460000,200,2,14.600000,700,1,12.430000,700,1,14.630000,100,1,12.420000,700,1,14.680000,1400,2,ARL,325718561
2025-07-17T16:02:20.946406202Z,2025-07-17T16:02:20.946240970Z,10,2,1108,C,A,3,14.26,100,130,165232,271679616,13.270000,10,1,13.830000,15,1,13.030000,100,1,13.840000,100,1,13.020000,100,1,13.920000,2,1,12.910000,2,1,14.280000,100,1,12.730000,100,1,14.450000,100,1,12.710000,100,1,14.560000,800,2,12.500000,700,1,14.600000,700,1,12.460000,200,2,14.630000,100,1,12.430000,700,1,14.680000,1400,2,12.420000,700,1,14.730000,200,2,ARL,325715045
2025-07-17T16:02:20.946456786Z,2025-07-17T16:02:20.946291345Z,10,2,1108,A,A,3,14.12,100,130,165441,271679617,13.270000,10,1,13.830000,15,1,13.030000,100,1,13.840000,100,1,13.020000,100,1,13.920000,2,1,12.910000,2,1,14.120000,100,1,12.730000,100,1,14.280000,100,1,12.710000,100,1,14.450000,100,1,12.500000,700,1,14.560000,800,2,12.460000,200,2,14.600000,700,1,12.430000,700,1,14.630000,100,1,12.420000,700,1,14.680000,1400,2,ARL,325718637
2025-07-17T16:02:20.957051613Z,2025-07-17T16:02:20.956886401Z,10,2,1108,C,B,2,13.02,100,0,165212,271679685,13.270000,10,1,13.830000,15,1,13.030000,100,1,13.840000,100,1,12.910000,2,1,13.920000,2,1,12.730000,100,1,14.120000,100,1,12.710000,100,1,14.280000,100,1,12.500000,700,1,14.450000,100,1,12.460000,200,2,14.560000,800,2,12.430000,700,1,14.600000,700,1,12.420000,700,1,14.630000,100,1,12.370000,700,1,14.680000,1400,2,ARL,325718561
2025-07-17T16:02:20.957051613Z,2025-07-17T16:02:20.956886401Z,10,2,1108,A,B,1,13.26,100,130,165212,271679685,13.270000,10,1,13.830000,15,1,13.260000,100,1,13.840000,100,1,13.030000,100,1,13.920000,2,1,12.910000,2,1,14.120000,100,1,12.730000,100,1,14.280000,100,1,12.710000,100,1,14.450000,100,1,12.500000,700,1,14.560000,800,2,12.460000,200,2,14.600000,700,1,12.430000,700,1,14.630000,100,1,12.420000,700,1,14.680000,1400,2,ARL,325718821
2025-07-17T16:02:20.957089143Z,2025-07-17T16:02:20.956923753Z,10,2,1108,A,B,2,13.12,100,130,165390,271679686,13.270000,10,1,13.830000,15,1,13.260000,100,1,13.840000,100,1,13.120000,100,1,13.920000,2,1,13.030000,100,1,14.120000,100,1,12.910000,2,1,14.280000,100,1,12.730000,100,1,14.450000,100,1,12.710000,100,1,14.560000,800,2,12.500000,700,1,14.600000,700,1,12.460000,200,2,14.630000,100,1,12.430000,700,1,14.680000,1400,2,ARL,325718833
2025-07-17T16:02:20.957090484Z,2025-07-17T16:02:20.956925447Z,10,2,1108,A,B,2,13.12,100,130,165037,271679687,13.270000,10,1,13.830000,15,1,13.260000,100,1,13.840000,100,1,13.120000,200,2,13.920000,2,1,13.030000,100,1,14.120000,100,1,12.910000,2,1,14.280000,100,1,12.730000,100,1,14.450000,100,1,12.710000,100,1,14.560000,800,2,12.500000,700,1,14.600000,700,1,12.460000,200,2,14.630000,100,1,12.430000,700,1,14.680000,1400,2,ARL,325718837
2025-07-17T16:02:20.988655870Z,2025-07-17T16:02:20.988490644Z,10,2,1108,A,A,3,13.98,100,130,165226,271679923,13.270000,10,1,13.830000,15,1,13.260000,100,1,13.840000,100,1,13.120000,200,2,13.920000,2,1,13.030000,100,1,13.980000,100,1,12.910000,2,1,14.120000,100,1,12.730000,100,1,14.280000,100,1,12.710000,100,1,14.450000,100,1,12.500000,700,1,14.560000,800,2,12.460000,200,2,14.600000,700,1,12.430000,700,1,14.630000,100,1,ARL,325719353
2025-07-17T16:02:20.988656944Z,2025-07-17T16:02:20.988491826Z,10,2,1108,A,A,3,13.98,100,130,165118,271679924,13.270000,10,1,13.830000,15,1,13.260000,100,1,13.840000,100,1,13.120000,200,2,13.920000,2,1,13.030000,100,1,13.980000,200,2,12.910000,2,1,14.120000,100,1,12.730000,100,1,14.280000,100,1,12.710000,100,1,14.450000,100,1,12.500000,700,1,14.560000,800,2,12.460000,200,2,14.600000,700,1,12.430000,700,1,14.630000,100,1,ARL,325719357
2025-07-17T16:02:30.805193695Z,2025-07-17T16:02:30.805028316Z,10,2,1108,C,B,0,13.27,10,130,165379,271818376,13.260000,100,1,13.830000,15,1,13.120000,200,2,13.840000,100,1,13.030000,100,1,13.920000,2,1,12.910000,2,1,13.980000,200,2,12.730000,100,1,14.120000,100,1,12.710000,100,1,14.280000,100,1,12.500000,700,1,14.450000,100,1,12.460000,200,2,14.560000,800,2,12.430000,700,1,14.600000,700,1,12.420000,700,1,14.630000,100,1,ARL,325714717
2025-07-17T16:02:34.987171397Z,2025-07-17T16:02:34.987005787Z,10,2,1108,C,B,3,12.91,2,0,165610,271871706,13.260000,100,1,13.830000,15,1,13.120000,200,2,13.840000,100,1,13.030000,100,1,13.920000,2,1,12.730000,100,1,13.980000,200,2,12.710000,100,1,14.120000,100,1,12.500000,700,1,14.280000,100,1,12.460000,200,2,14.450000,100,1,12.430000,700,1,14.560000,800,2,12.420000,700,1,14.600000,700,1,12.370000,700,1,14.630000,100,1,ARL,325714741
2025-07-17T16:02:34.987171397Z,2025-07-17T16:02:34.987005787Z,10,2,1108,A,B,3,13.00,2,130,165610,271871706,13.260000,100,1,13.830000,15,1,13.120000,200,2,13.840000,100,1,13.030000,100,1,13.920000,2,1,13.000000,2,1,13.980000,200,2,12.730000,100,1,14.120000,100,1,12.710000,100,1,14.280000,100,1,12.500000,700,1,14.450000,100,1,12.460000,200,2,14.560000,800,2,12.430000,700,1,14.600000,700,1,12.420000,700,1,14.630000,100,1,ARL,325967705
2025-07-17T16:02:39.809464961Z,2025-07-17T16:02:39.809299504Z,10,2,1108,A,A,0,13.79,15,130,165457,271952021,13.260000,100,1,13.790000,15,1,13.120000,200,2,13.830000,15,1,13.030000,100,1,13.840000,100,1,13.000000,2,1,13.920000,2,1,12.730000,100,1,13.980000,200,2,12.710000,100,1,14.120000,100,1,12.500000,700,1,14.280000,100,1,12.460000,200,2,14.450000,100,1,12.430000,700,1,14.560000,800,2,12.420000,700,1,14.600000,700,1,ARL,326077141
2025-07-17T16:02:40.007472020Z,2025-07-17T16:02:40.007306432Z,10,2,1108,C,A,2,13.84,100,0,165588,271957331,13.260000,100,1,13.790000,15,1,13.120000,200,2,13.830000,15,1,13.030000,100,1,13.920000,2,1,13.000000,2,1,13.980000,200,2,12.730000,100,1,14.120000,100,1,12.710000,100,1,14.280000,100,1,12.500000,700,1,14.450000,100,1,12.460000,200,2,14.560000,800,2,12.430000,700,1,14.600000,700,1,12.420000,700,1,14.630000,100,1,ARL,325718485
2025-07-17T16:02:40.007472020Z,2025-07-17T16:02:40.007306432Z,10,2,1108,A,A,1,13.80,100,130,165588,271957331,13.260000,100,1,13.790000,15,1,13.120000,200,2,13.800000,100,1,13.030000,100,1,13.830000,15,1,13.000000,2,1,13.920000,2,1,12.730000,100,1,13.980000,200,2,12.710000,100,1,14.120000,100,1,12.500000,700,1,14.280000,100,1,12.460000,200,2,14.450000,100,1,12.430000,700,1,14.560000,800,2,12.420000,700,1,14.600000,700,1,ARL,326082329
2025-07-17T16:02:40.008213654Z,2025-07-17T16:02:40.008048023Z,10,2,1108,C,A,14,14.91,100,0,165631,271957349,13.260000,100,1,13.790000,15,1,13.120000,200,2,13.800000,100,1,13.030000,100,1,13.830000,15,1,13.000000,2,1,13.920000,2,1,12.730000,100,1,13.980000,200,2,12.710000,100,1,14.120000,100,1,12.500000,700,1,14.280000,100,1,12.460000,200,2,14.450000,100,1,12.430000,700,1,14.560000,800,2,12.420000,700,1,14.600000,700,1,ARL,325718509
2025-07-17T16:02:40.008213654Z,2025-07-17T16:02:40.008048023Z,10,2,1108,A,A,-1,14.87,100,130,165631,271957349,13.260000,100,1,13.790000,15,1,13.120000,200,2,13.800000,100,1,13.030000,100,1,13.830000,15,1,13.000000,2,1,13.920000,2,1,12.730000,100,1,13.980000,200,2,12.710000,100,1,14.120000,100,1,12.500000,700,1,14.280000,100,1,12.460000,200,2,14.450000,100,1,12.430000,700,1,14.560000,800,2,12.420000,700,1,14.600000,700,1,ARL,326082353
2025-07-17T16:02:40.795014471Z,2025-07-17T16:02:40.794847674Z,10,2,1108,C,A,0,13.79,15,130,166797,271972417,13.260000,100,1,13.800000,100,1,13.120000,200,2,13.830000,15,1,13.030000,100,1,13.920000,2,1,13.000000,2,1,13.980000,200,2,12.730000,100,1,14.120000,100,1,12.710000,100,1,14.280000,100,1,12.500000,700,1,14.450000,100,1,12.460000,200,2,14.560000,800,2,12.430000,700,1,14.600000,700,1,12.420000,700,1,14.630000,100,1,ARL,326077141
2025-07-17T16:02:40.806305895Z,2025-07-17T16:02:40.806140621Z,10,2,1108,C,A,1,13.83,15,130,165274,271973288,13.260000,100,1,13.800000,100,1,13.120000,200,2,13.920000,2,1,13.030000,100,1,13.980000,200,2,13.000000,2,1,14.120000,100,1,12.730000,100,1,14.280000,100,1,12.710000,100,1,14.450000,100,1,12.500000,700,1,14.560000,800,2,12.460000,200,2,14.600000,700,1,12.430000,700,1,14.630000,100,1,12.420000,700,1,14.680000,1400,2,ARL,325714721
2025-07-17T16:02:43.841852430Z,2025-07-17T16:02:43.841686908Z,10,2,1108,C,B,0,13.26,100,130,165522,272014658,13.120000,200,2,13.800000,100,1,13.030000,100,1,13.920000,2,1,13.000000,2,1,13.980000,200,2,12.730000,100,1,14.120000,100,1,12.710000,100,1,14.280000,100,1,12.500000,700,1,14.450000,100,1,12.460000,200,2,14.560000,800,2,12.430000,700,1,14.600000,700,1,12.420000,700,1,14.630000,100,1,12.370000,700,1,14.680000,1400,2,ARL,325718821
2025-07-17T16:02:43.841912053Z,2025-07-17T16:02:43.841746626Z,10,2,1108,A,A,1,13.90,4,130,165427,272014659,13.120000,200,2,13.800000,100,1,13.030000,100,1,13.900000,4,1,13.000000,2,1,13.920000,2,1,12.730000,100,1,13.980000,200,2,12.710000,100,1,14.120000,100,1,12.500000,700,1,14.280000,100,1,12.460000,200,2,14.450000,100,1,12.430000,700,1,14.560000,800,2,12.420000,700,1,14.600000,700,1,12.370000,700,1,14.630000,100,1,ARL,326158809
2025-07-17T16:02:43.842295427Z,2025-07-17T16:02:43.842130114Z,10,2,1108,C,A,0,13.80,100,130,165313,272014661,13.120000,200,2,13.900000,4,1,13.030000,100,1,13.920000,2,1,13.000000,2,1,13.980000,200,2,12.730000,100,1,14.120000,100,1,12.710000,100,1,14.280000,100,1,12.500000,700,1,14.450000,100,1,12.460000,200,2,14.560000,800,2,12.430000,700,1,14.600000,700,1,12.420000,700,1,14.630000,100,1,12.370000,700,1,14.680000,1400,2,ARL,326082329
2025-07-17T16:02:43.843036936Z,2025-07-17T16:02:43.842871428Z,10,2,1108,C,A,12,14.87,100,0,165508,272014673,13.120000,200,2,13.900000,4,1,13.030000,100,1,13.920000,2,1,13.000000,2,1,13.980000,200,2,12.730000,100,1,14.120000,100,1,12.710000,100,1,14.280000,100,1,12.500000,700,1,14.450000,100,1,12.460000,200,2,14.560000,800,2,12.430000,700,1,14.600000,700,1,12.420000,700,1,14.630000,100,1,12.370000,700,1,14.680000,1400,2,ARL,326082353
2025-07-17T16:02:43.843036936Z,2025-07-17T16:02:43.842871428Z,10,2,1108,A,A,-1,14.92,100,130,165508,272014673,13.120000,200,2,13.900000,4,1,13.030000,100,1,13.920000,2,1,13.000000,2,1,13.980000,200,2,12.730000,100,1,14.120000,100,1,12.710000,100,1,14.280000,100,1,12.500000,700,1,14.450000,100,1,12.460000,200,2,14.560000,800,2,12.430000,700,1,14.600000,700,1,12.420000,700,1,14.630000,100,1,12.370000,700,1,14.680000,1400,2,ARL,326158869
2025-07-17T16:02:43.843106749Z,2025-07-17T16:02:43.842941514Z,10,2,1108,A,B,1,13.11,100,130,165235,272014674,13.120000,200,2,13.900000,4,1,13.110000,100,1,13.920000,2,1,13.030000,100,1,13.980000,200,2,13.000000,2,1,14.120000,100,1,12.730000,100,1,14.280000,100,1,12.710000,100,1,14.450000,100,1,12.500000,700,1,14.560000,800,2,12.460000,200,2,14.600000,700,1,12.430000,700,1,14.630000,100,1,12.420000,700,1,14.680000,1400,2,ARL,326158877
2025-07-17T16:02:43.843109026Z,2025-07-17T16:02:43.842943173Z,10,2,1108,C,A,11,14.81,100,0,165853,272014675,13.120000,200,2,13.900000,4,1,13.110000,100,1,13.920000,2,1,13.030000,100,1,13.980000,200,2,13.000000,2,1,14.120000,100,1,12.730000,100,1,14.280000,100,1,12.710000,100,1,14.450000,100,1,12.500000,700,1,14.560000,800,2,12.460000,200,2,14.600000,700,1,12.430000,700,1,14.630000,100,1,12.420000,700,1,14.680000,1400,2,ARL,325718549
2025-07-17T16:02:43.843109026Z,2025-07-17T16:02:43.842943173Z,10,2,1108,A,A,-1,14.96,100,130,165853,272014675,13.120000,200,2,13.900000,4,1,13.110000,100,1,13.920000,2,1,13.030000,100,1,13.980000,200,2,13.000000,2,1,14.120000,100,1,12.730000,100,1,14.280000,100,1,12.710000,100,1,14.450000,100,1,12.500000,700,1,14.560000,800,2,12.460000,200,2,14.600000,700,1,12.430000,700,1,14.630000,100,1,12.420000,700,1,14.680000,1400,2,ARL,326158881
2025-07-17T16:02:43.843204692Z,2025-07-17T16:02:43.843039530Z,10,2,1108,C,A,0,13.90,4,130,165162,272014681,13.120000,200,2,13.920000,2,1,13.110000,100,1,13.980000,200,2,13.030000,100,1,14.120000,100,1,13.000000,2,1,14.280000,100,1,12.730000,100,1,14.450000,100,1,12.710000,100,1,14.560000,800,2,12.500000,700,1,14.600000,700,1,12.460000,200,2,14.630000,100,1,12.430000,700,1,14.680000,1400,2,12.420000,700,1,14.730000,200,2,ARL,326158809
2025-07-17T16:02:43.843956820Z,2025-07-17T16:02:43.843791297Z,10,2,1108,C,A,20,17.58,100,0,165523,272014689,13.120000,200,2,13.920000,2,1,13.110000,100,1,13.980000,200,2,13.030000,100,1,14.120000,100,1,13.000000,2,1,14.280000,100,1,12.730000,100,1,14.450000,100,1,12.710000,100,1,14.560000,800,2,12.500000,700,1,14.600000,700,1,12.460000,200,2,14.630000,100,1,12.430000,700,1,14.680000,1400,2,12.420000,700,1,14.730000,200,2,ARL,325718557
2025-07-17T16:02:43.843956820Z,2025-07-17T16:02:43.843791297Z,10,2,1108,A,A,-1,17.76,100,130,165523,272014689,13.120000,200,2,13.920000,2,1,13.110000,100,1,13.980000,200,2,13.030000,100,1,14.120000,100,1,13.000000,2,1,14.280000,100,1,12.730000,100,1,14.450000,100,1,12.710000,100,1,14.560000,800,2,12.500000,700,1,14.600000,700,1,12.460000,200,2,14.630000,100,1,12.430000,700,1,14.680000,1400,2,12.420000,700,1,14.730000,200,2,ARL,326158953
2025-07-17T16:02:43.844653014Z,2025-07-17T16:02:43.844487204Z,10,2,1108,C,A,16,15.92,100,0,165810,272014697,13.120000,200,2,13.920000,2,1,13.110000,100,1,13.980000,200,2,13.030000,100,1,14.120000,100,1,13.000000,2,1,14.280000,100,1,12.730000,100,1,14.450000,100,1,12.710000,100,1,14.560000,800,2,12.500000,700,1,14.600000,700,1,12.460000,200,2,14.630000,100,1,12.430000,700,1,14.680000,1400,2,12.420000,700,1,14.730000,200,2,ARL,325718525
2025-07-17T16:02:43.844653014Z,2025-07-17T16:02:43.844487204Z,10,2,1108,A,A,-1,16.08,100,130,165810,272014697,13.120000,200,2,13.920000,2,1,13.110000,100,1,13.980000,200,2,13.030000,100,1,14.120000,100,1,13.000000,2,1,14.280000,100,1,12.730000,100,1,14.450000,100,1,12.710000,100,1,14.560000,800,2,12.500000,700,1,14.600000,700,1,12.460000,200,2,14.630000,100,1,12.430000,700,1,14.680000,1400,2,12.420000,700,1,14.730000,200,2,ARL,326158989
2025-07-17T16:02:43.844801951Z,2025-07-17T16:02:43.844636465Z,10,2,1108,C,A,10,14.81,100,0,165486,272014698,13.120000,200,2,13.920000,2,1,13.110000,100,1,13.980000,200,2,13.030000,100,1,14.120000,100,1,13.000000,2,1,14.280000,100,1,12.730000,100,1,14.450000,100,1,12.710000,100,1,14.560000,800,2,12.500000,700,1,14.600000,700,1,12.460000,200,2,14.630000,100,1,12.430000,700,1,14.680000,1400,2,12.420000,700,1,14.730000,200,2,ARL,325718517
2025-07-17T16:02:43.844801951Z,2025-07-17T16:02:43.844636465Z,10,2,1108,A,A,-1,14.96,100,130,165486,272014698,13.120000,200,2,13.920000,2,1,13.110000,100,1,13.980000,200,2,13.030000,100,1,14.120000,100,1,13.000000,2,1,14.280000,100,1,12.730000,100,1,14.450000,100,1,12.710000,100,1,14.560000,800,2,12.500000,700,1,14.600000,700,1,12.460000,200,2,14.630000,100,1,12.430000,700,1,14.680000,1400,2,12.420000,700,1,14.730000,200,2,ARL,326158997
2025-07-17T16:02:43.847026795Z,2025-07-17T16:02:43.846861336Z,10,2,1108,C,A,0,13.92,2,0,165459,272014713,13.120000,200,2,13.980000,200,2,13.110000,100,1,14.120000,100,1,13.030000,100,1,14.280000,100,1,13.000000,2,1,14.450000,100,1,12.730000,100,1,14.560000,800,2,12.710000,100,1,14.600000,700,1,12.500000,700,1,14.630000,100,1,12.460000,200,2,14.680000,1400,2,12.430000,700,1,14.730000,200,2,12.420000,700,1,14.920000,100,1,ARL,325297093
2025-07-17T16:02:43.847026795Z,2025-07-17T16:02:43.846861336Z,10,2,1108,A,A,1,14.03,2,130,165459,272014713,13.120000,200,2,13.980000,200,2,13.110000,100,1,14.030000,2,1,13.030000,100,1,14.120000,100,1,13.000000,2,1,14.280000,100,1,12.730000,100,1,14.450000,100,1,12.710000,100,1,14.560000,800,2,12.500000,700,1,14.600000,700,1,12.460000,200,2,14.630000,100,1,12.430000,700,1,14.680000,1400,2,12.420000,700,1,14.730000,200,2,ARL,326159041
2025-07-17T16:02:43.847832258Z,2025-07-17T16:02:43.847666979Z,10,2,1108,C,A,9,14.73,100,0,165279,272014721,13.120000,200,2,13.980000,200,2,13.110000,100,1,14.030000,2,1,13.030000,100,1,14.120000,100,1,13.000000,2,1,14.280000,100,1,12.730000,100,1,14.450000,100,1,12.710000,100,1,14.560000,800,2,12.500000,700,1,14.600000,700,1,12.460000,200,2,14.630000,100,1,12.430000,700,1,14.680000,1400,2,12.420000,700,1,14.730000,100,1,ARL,325714613
2025-07-17T16:02:43.847832258Z,2025-07-17T16:02:43.847666979Z,10,2,1108,A,A,-1,14.87,100,130,165279,272014721,13.120000,200,2,13.980000,200,2,13.110000,100,1,14.030000,2,1,13.030000,100,1,14.120000,100,1,13.000000,2,1,14.280000,100,1,12.730000,100,1,14.450000,100,1,12.710000,100,1,14.560000,800,2,12.500000,700,1,14.600000,700,1,12.460000,200,2,14.630000,100,1,12.430000,700,1,14.680000,1400,2,12.420000,700,1,14.730000,100,1,ARL,326159049
2025-07-17T16:02:43.848147198Z,2025-07-17T16:02:43.847981726Z,10,2,1108,C,A,9,14.73,100,0,165472,272014724,13.120000,200,2,13.980000,200,2,13.110000,100,1,14.030000,2,1,13.030000,100,1,14.120000,100,1,13.000000,2,1,14.280000,100,1,12.730000,100,1,14.450000,100,1,12.710000,100,1,14.560000,800,2,12.500000,700,1,14.600000,700,1,12.460000,200,2,14.630000,100,1,12.430000,700,1,14.680000,1400,2,12.420000,700,1,14.870000,100,1,ARL,325714577
2025-07-17T16:02:43.848147198Z,2025-07-17T16:02:43.847981726Z,10,2,1108,A,A,9,14.87,100,130,165472,272014724,13.120000,200,2,13.980000,200,2,13.110000,100,1,14.030000,2,1,13.030000,100,1,14.120000,100,1,13.000000,2,1,14.280000,100,1,12.730000,100,1,14.450000,100,1,12.710000,100,1,14.560000,800,2,12.500000,700,1,14.600000,700,1,12.460000,200,2,14.630000,100,1,12.430000,700,1,14.680000,1400,2,12.420000,700,1,14.870000,200,2,ARL,326159061
2025-07-17T16:02:43.860199647Z,2025-07-17T16:02:43.860034354Z,10,2,1108,C,A,2,14.12,100,130,165293,272014788,13.120000,200,2,13.980000,200,2,13.110000,100,1,14.030000,2,1,13.030000,100,1,14.280000,100,1,13.000000,2,1,14.450000,100,1,12.730000,100,1,14.560000,800,2,12.710000,100,1,14.600000,700,1,12.500000,700,1,14.630000,100,1,12.460000,200,2,14.680000,1400,2,12.430000,700,1,14.870000,200,2,12.420000,700,1,14.920000,100,1,ARL,325718637
2025-07-17T16:02:43.860252446Z,2025-07-17T16:02:43.860087215Z,10,2,1108,A,A,2,14.26,100,130,165231,272014789,13.120000,200,2,13.980000,200,2,13.110000,100,1,14.030000,2,1,13.030000,100,1,14.260000,100,1,13.000000,2,1,14.280000,100,1,12.730000,100,1,14.450000,100,1,12.710000,100,1,14.560000,800,2,12.500000,700,1,14.600000,700,1,12.460000,200,2,14.630000,100,1,12.430000,700,1,14.680000,1400,2,12.420000,700,1,14.870000,200,2,ARL,326159201
2025-07-17T16:02:43.893176312Z,2025-07-17T16:02:43.893011012Z,10,2,1108,C,A,10,14.92,100,0,165300,272014986,13.120000,200,2,13.980000,200,2,13.110000,100,1,14.030000,2,1,13.030000,100,1,14.260000,100,1,13.000000,2,1,14.280000,100,1,12.730000,100,1,14.450000,100,1,12.710000,100,1,14.560000,800,2,12.500000,700,1,14.600000,700,1,12.460000,200,2,14.630000,100,1,12.430000,700,1,14.680000,1400,2,12.420000,700,1,14.870000,200,2,ARL,326158869
2025-07-17T16:02:43.893176312Z,2025-07-17T16:02:43.893011012Z,10,2,1108,A,A,-1,15.06,100,130,165300,272014986,13.120000,200,2,13.980000,200,2,13.110000,100,1,14.030000,2,1,13.030000,100,1,14.260000,100,1,13.000000,2,1,14.280000,100,1,12.730000,100,1,14.450000,100,1,12.710000,100,1,14.560000,800,2,12.500000,700,1,14.600000,700,1,12.460000,200,2,14.630000,100,1,12.430000,700,1,14.680000,1400,2,12.420000,700,1,14.870000,200,2,ARL,326159425
2025-07-17T16:02:43.946967137Z,2025-07-17T16:02:43.946801538Z,10,2,1108,C,A,7,14.63,100,0,165599,272015584,13.120000,200,2,13.980000,200,2,13.110000,100,1,14.030000,2,1,13.030000,100,1,14.260000,100,1,13.000000,2,1,14.280000,100,1,12.730000,100,1,14.450000,100,1,12.710000,100,1,14.560000,800,2,12.500000,700,1,14.600000,700,1,12.460000,200,2,14.680000,1400,2,12.430000,700,1,14.870000,200,2,12.420000,700,1,14.960000,200,2,ARL,325714653
2025-07-17T16:02:43.946967137Z,2025-07-17T16:02:43.946801538Z,10,2,1108,A,A,8,14.77,100,130,165599,272015584,13.120000,200,2,13.980000,200,2,13.110000,100,1,14.030000,2,1,13.030000,100,1,14.260000,100,1,13.000000,2,1,14.280000,100,1,12.730000,100,1,14.450000,100,1,12.710000,100,1,14.560000,800,2,12.500000,700,1,14.600000,700,1,12.460000,200,2,14.680000,1400,2,12.430000,700,1,14.770000,100,1,12.420000,700,1,14.870000,200,2,ARL,326160141
2025-07-17T16:02:44.664219784Z,2025-07-17T16:02:44.664054457Z,10,2,1108,A,A,1,13.99,100,130,165327,272021808,13.120000,200,2,13.980000,200,2,13.110000,100,1,13.990000,100,1,13.030000,100,1,14.030000,2,1,13.000000,2,1,14.260000,100,1,12.730000,100,1,14.280000,100,1,12.710000,100,1,14.450000,100,1,12.500000,700,1,14.560000,800,2,12.460000,200,2,14.600000,700,1,12.430000,700,1,14.680000,1400,2,12.420000,700,1,14.770000,100,1,ARL,326167529
2025-07-17T16:03:02.985987598Z,2025-07-17T16:03:02.985818199Z,10,2,1108,C,A,10,14.87,100,0,169399,272331833,13.120000,200,2,13.980000,200,2,13.110000,100,1,13.990000,100,1,13.030000,100,1,14.030000,2,1,13.000000,2,1,14.260000,100,1,12.730000,100,1,14.280000,100,1,12.710000,100,1,14.450000,100,1,12.500000,700,1,14.560000,800,2,12.460000,200,2,14.600000,700,1,12.430000,700,1,14.680000,1400,2,12.420000,700,1,14.770000,100,1,ARL,326159049
2025-07-17T16:03:02.985987598Z,2025-07-17T16:03:02.985818199Z,10,2,1108,A,A,9,14.70,100,128,169399,272331833,13.120000,200,2,13.980000,200,2,13.110000,100,1,13.990000,100,1,13.030000,100,1,14.030000,2,1,13.000000,2,1,14.260000,100,1,12.730000,100,1,14.280000,100,1,12.710000,100,1,14.450000,100,1,12.500000,700,1,14.560000,800,2,12.460000,200,2,14.600000,700,1,12.430000,700,1,14.680000,1400,2,12.420000,700,1,14.700000,100,1,ARL,326551237
2025-07-17T16:03:02.987969729Z,2025-07-17T16:03:02.987797728Z,10,2,1108,C,A,11,14.87,100,0,172001,272332718,13.120000,200,2,13.980000,200,2,13.110000,100,1,13.990000,100,1,13.030000,100,1,14.030000,2,1,13.000000,2,1,14.260000,100,1,12.730000,100,1,14.280000,100,1,12.710000,100,1,14.450000,100,1,12.500000,700,1,14.560000,800,2,12.460000,200,2,14.600000,700,1,12.430000,700,1,14.680000,1400,2,12.420000,700,1,14.700000,100,1,ARL,326159061
2025-07-17T16:03:02.987969729Z,2025-07-17T16:03:02.987797728Z,10,2,1108,A,A,9,14.70,100,128,172001,272332718,13.120000,200,2,13.980000,200,2,13.110000,100,1,13.990000,100,1,13.030000,100,1,14.030000,2,1,13.000000,2,1,14.260000,100,1,12.730000,100,1,14.280000,100,1,12.710000,100,1,14.450000,100,1,12.500000,700,1,14.560000,800,2,12.460000,200,2,14.600000,700,1,12.430000,700,1,14.680000,1400,2,12.420000,700,1,14.700000,200,2,ARL,326551829
2025-07-17T16:03:10.807446975Z,2025-07-17T16:03:10.807281669Z,10,2,1108,A,A,0,13.72,15,130,165306,272474575,13.120000,200,2,13.720000,15,1,13.110000,100,1,13.980000,200,2,13.030000,100,1,13.990000,100,1,13.000000,2,1,14.030000,2,1,12.730000,100,1,14.260000,100,1,12.710000,100,1,14.280000,100,1,12.500000,700,1,14.450000,100,1,12.460000,200,2,14.560000,800,2,12.430000,700,1,14.600000,700,1,12.420000,700,1,14.680000,1400,2,ARL,326729677
2025-07-17T16:03:10.807714421Z,2025-07-17T16:03:10.807548848Z,10,2,1108,C,A,2,13.99,100,0,165573,272474576,13.120000,200,2,13.720000,15,1,13.110000,100,1,13.980000,200,2,13.030000,100,1,14.030000,2,1,13.000000,2,1,14.260000,100,1,12.730000,100,1,14.280000,100,1,12.710000,100,1,14.450000,100,1,12.500000,700,1,14.560000,800,2,12.460000,200,2,14.600000,700,1,12.430000,700,1,14.680000,1400,2,12.420000,700,1,14.700000,200,2,ARL,326167529
2025-07-17T16:03:10.807714421Z,2025-07-17T16:03:10.807548848Z,10,2,1108,A,A,1,13.73,100,130,165573,272474576,13.120000,200,2,13.720000,15,1,13.110000,100,1,13.730000,100,1,13.030000,100,1,13.980000,200,2,13.000000,2,1,14.030000,2,1,12.730000,100,1,14.260000,100,1,12.710000,100,1,14.280000,100,1,12.500000,700,1,14.450000,100,1,12.460000,200,2,14.560000,800,2,12.430000,700,1,14.600000,700,1,12.420000,700,1,14.680000,1400,2,ARL,326729685
2025-07-17T16:03:10.808457278Z,2025-07-17T16:03:10.808290914Z,10,2,1108,C,A,13,15.06,100,0,166364,272474580,13.120000,200,2,13.720000,15,1,13.110000,100,1,13.730000,100,1,13.030000,100,1,13.980000,200,2,13.000000,2,1,14.030000,2,1,12.730000,100,1,14.260000,100,1,12.710000,100,1,14.280000,100,1,12.500000,700,1,14.450000,100,1,12.460000,200,2,14.560000,800,2,12.430000,700,1,14.600000,700,1,12.420000,700,1,14.680000,1400,2,ARL,326159425
2025-07-17T16:03:10.808457278Z,2025-07-17T16:03:10.808290914Z,10,2,1108,A,A,-1,14.79,100,128,166364,272474580,13.120000,200,2,13.720000,15,1,13.110000,100,1,13.730000,100,1,13.030000,100,1,13.980000,200,2,13.000000,2,1,14.030000,2,1,12.730000,100,1,14.260000,100,1,12.710000,100,1,14.280000,100,1,12.500000,700,1,14.450000,100,1,12.460000,200,2,14.560000,800,2,12.430000,700,1,14.600000,700,1,12.420000,700,1,14.680000,1400,2,ARL,326729705
2025-07-17T16:03:10.809707274Z,2025-07-17T16:03:10.809541651Z,10,2,1108,C,A,13,14.96,100,0,165623,272474585,13.120000,200,2,13.720000,15,1,13.110000,100,1,13.730000,100,1,13.030000,100,1,13.980000,200,2,13.000000,2,1,14.030000,2,1,12.730000,100,1,14.260000,100,1,12.710000,100,1,14.280000,100,1,12.500000,700,1,14.450000,100,1,12.460000,200,2,14.560000,800,2,12.430000,700,1,14.600000,700,1,12.420000,700,1,14.680000,1400,2,ARL,326158881
2025-07-17T16:03:10.809707274Z,2025-07-17T16:03:10.809541651Z,10,2,1108,A,A,-1,14.70,100,130,165623,272474585,13.120000,200,2,13.720000,15,1,13.110000,100,1,13.730000,100,1,13.030000,100,1,13.980000,200,2,13.000000,2,1,14.030000,2,1,12.730000,100,1,14.260000,100,1,12.710000,100,1,14.280000,100,1,12.500000,700,1,14.450000,100,1,12.460000,200,2,14.560000,800,2,12.430000,700,1,14.600000,700,1,12.420000,700,1,14.680000,1400,2,ARL,326729721
2025-07-17T16:03:10.809936821Z,2025-07-17T16:03:10.809771527Z,10,2,1108,C,A,11,14.77,100,130,165294,272474594,13.120000,200,2,13.720000,15,1,13.110000,100,1,13.730000,100,1,13.030000,100,1,13.980000,200,2,13.000000,2,1,14.030000,2,1,12.730000,100,1,14.260000,100,1,12.710000,100,1,14.280000,100,1,12.500000,700,1,14.450000,100,1,12.460000,200,2,14.560000,800,2,12.430000,700,1,14.600000,700,1,12.420000,700,1,14.680000,1400,2,ARL,326160141
2025-07-17T16:03:10.809963577Z,2025-07-17T16:03:10.809798084Z,10,2,1108,C,A,19,17.76,100,0,165493,272474595,13.120000,200,2,13.720000,15,1,13.110000,100,1,13.730000,100,1,13.030000,100,1,13.980000,200,2,13.000000,2,1,14.030000,2,1,12.730000,100,1,14.260000,100,1,12.710000,100,1,14.280000,100,1,12.500000,700,1,14.450000,100,1,12.460000,200,2,14.560000,800,2,12.430000,700,1,14.600000,700,1,12.420000,700,1,14.680000,1400,2,ARL,326158953
2025-07-17T16:03:10.809963577Z,2025-07-17T16:03:10.809798084Z,10,2,1108,A,A,-1,17.44,100,130,165493,272474595,13.120000,200,2,13.720000,15,1,13.110000,100,1,13.730000,100,1,13.030000,100,1,13.980000,200,2,13.000000,2,1,14.030000,2,1,12.730000,100,1,14.260000,100,1,12.710000,100,1,14.280000,100,1,12.500000,700,1,14.450000,100,1,12.460000,200,2,14.560000,800,2,12.430000,700,1,14.600000,700,1,12.420000,700,1,14.680000,1400,2,ARL,326729725
2025-07-17T16:03:10.810059442Z,2025-07-17T16:03:10.809894317Z,10,2,1108,A,A,7,14.52,100,130,165125,272474597,13.120000,200,2,13.720000,15,1,13.110000,100,1,13.730000,100,1,13.030000,100,1,13.980000,200,2,13.000000,2,1,14.030000,2,1,12.730000,100,1,14.260000,100,1,12.710000,100,1,14.280000,100,1,12.500000,700,1,14.450000,100,1,12.460000,200,2,14.520000,100,1,12.430000,700,1,14.560000,800,2,12.420000,700,1,14.600000,700,1,ARL,326729729
2025-07-17T16:03:10.810478524Z,2025-07-17T16:03:10.810312923Z,10,2,1108,C,A,18,16.08,100,0,165601,272474600,13.120000,200,2,13.720000,15,1,13.110000,100,1,13.730000,100,1,13.030000,100,1,13.980000,200,2,13.000000,2,1,14.030000,2,1,12.730000,100,1,14.260000,100,1,12.710000,100,1,14.280000,100,1,12.500000,700,1,14.450000,100,1,12.460000,200,2,14.520000,100,1,12.430000,700,1,14.560000,800,2,12.420000,700,1,14.600000,700,1,ARL,326158989
2025-07-17T16:03:10.810478524Z,2025-07-17T16:03:10.810312923Z,10,2,1108,A,A,-1,15.79,100,130,165601,272474600,13.120000,200,2,13.720000,15,1,13.110000,100,1,13.730000,100,1,13.030000,100,1,13.980000,200,2,13.000000,2,1,14.030000,2,1,12.730000,100,1,14.260000,100,1,12.710000,100,1,14.280000,100,1,12.500000,700,1,14.450000,100,1,12.460000,200,2,14.520000,100,1,12.430000,700,1,14.560000,800,2,12.420000,700,1,14.600000,700,1,ARL,326729733
2025-07-17T16:03:10.814646270Z,2025-07-17T16:03:10.814480532Z,10,2,1108,C,A,13,14.96,100,0,165738,272474635,13.120000,200,2,13.720000,15,1,13.110000,100,1,13.730000,100,1,13.030000,100,1,13.980000,200,2,13.000000,2,1,14.030000,2,1,12.730000,100,1,14.260000,100,1,12.710000,100,1,14.280000,100,1,12.500000,700,1,14.450000,100,1,12.460000,200,2,14.520000,100,1,12.430000,700,1,14.560000,800,2,12.420000,700,1,14.600000,700,1,ARL,326158997
2025-07-17T16:03:10.814646270Z,2025-07-17T16:03:10.814480532Z,10,2,1108,A,A,-1,14.70,100,130,165738,272474635,13.120000,200,2,13.720000,15,1,13.110000,100,1,13.730000,100,1,13.030000,100,1,13.980000,200,2,13.000000,2,1,14.030000,2,1,12.730000,100,1,14.260000,100,1,12.710000,100,1,14.280000,100,1,12.500000,700,1,14.450000,100,1,12.460000,200,2,14.520000,100,1,12.430000,700,1,14.560000,800,2,12.420000,700,1,14.600000,700,1,ARL,326729821
2025-07-17T16:03:10.817866066Z,2025-07-17T16:03:10.817700664Z,10,2,1108,C,A,4,14.26,100,130,165402,272474675,13.120000,200,2,13.720000,15,1,13.110000,100,1,13.730000,100,1,13.030000,100,1,13.980000,200,2,13.000000,2,1,14.030000,2,1,12.730000,100,1,14.280000,100,1,12.710000,100,1,14.450000,100,1,12.500000,700,1,14.520000,100,1,12.460000,200,2,14.560000,800,2,12.430000,700,1,14.600000,700,1,12.420000,700,1,14.680000,1400,2,ARL,326159201
2025-07-17T16:03:10.817919970Z,2025-07-17T16:03:10.817754737Z,10,2,1108,A,A,3,14.00,100,130,165233,272474676,13.120000,200,2,13.720000,15,1,13.110000,100,1,13.730000,100,1,13.030000,100,1,13.980000,200,2,13.000000,2,1,14.000000,100,1,12.730000,100,1,14.030000,2,1,12.710000,100,1,14.280000,100,1,12.500000,700,1,14.450000,100,1,12.460000,200,2,14.520000,100,1,12.430000,700,1,14.560000,800,2,12.420000,700,1,14.600000,700,1,ARL,326729929
2025-07-17T16:03:10.843337845Z,2025-07-17T16:03:10.843172549Z,10,2,1108,A,A,-1,15.66,100,130,165296,272474826,13.120000,200,2,13.720000,15,1,13.110000,100,1,13.730000,100,1,13.030000,100,1,13.980000,200,2,13.000000,2,1,14.000000,100,1,12.730000,100,1,14.030000,2,1,12.710000,100,1,14.280000,100,1,12.500000,700,1,14.450000,100,1,12.460000,200,2,14.520000,100,1,12.430000,700,1,14.560000,800,2,12.420000,700,1,14.600000,700,1,ARL,326730513
2025-07-17T16:03:10.843350160Z,2025-07-17T16:03:10.843184785Z,10,2,1108,C,A,18,15.94,100,130,165375,272474827,13.120000,200,2,13.720000,15,1,13.110000,100,1,13.730000,100,1,13.030000,100,1,13.980000,200,2,13.000000,2,1,14.000000,100,1,12.730000,100,1,14.030000,2,1,12.710000,100,1,14.280000,100,1,12.500000,700,1,14.450000,100,1,12.460000,200,2,14.520000,100,1,12.430000,700,1,14.560000,800,2,12.420000,700,1,14.600000,700,1,ARL,325714909
2025-07-17T16:03:10.843615537Z,2025-07-17T16:03:10.843448998Z,10,2,1108,C,A,2,13.98,100,0,166539,272474828,13.120000,200,2,13.720000,15,1,13.110000,100,1,13.730000,100,1,13.030000,100,1,13.980000,100,1,13.000000,2,1,14.000000,100,1,12.730000,100,1,14.030000,2,1,12.710000,100,1,14.280000,100,1,12.500000,700,1,14.450000,100,1,12.460000,200,2,14.520000,100,1,12.430000,700,1,14.560000,800,2,12.420000,700,1,14.600000,700,1,ARL,325719357
2025-07-17T16:03:10.843615537Z,2025-07-17T16:03:10.843449402Z,10,2,1108,C,A,2,13.98,100,130,166135,272474829,13.120000,200,2,13.720000,15,1,13.110000,100,1,13.730000,100,1,13.030000,100,1,14.000000,100,1,13.000000,2,1,14.030000,2,1,12.730000,100,1,14.280000,100,1,12.710000,100,1,14.450000,100,1,12.500000,700,1,14.520000,100,1,12.460000,200,2,14.560000,800,2,12.430000,700,1,14.600000,700,1,12.420000,700,1,14.680000,1400,2,ARL,325719353
2025-07-17T16:03:10.843628246Z,2025-07-17T16:03:10.843462898Z,10,2,1108,A,A,2,13.87,100,130,165348,272474830,13.120000,200,2,13.720000,15,1,13.110000,100,1,13.730000,100,1,13.030000,100,1,13.870000,100,1,13.000000,2,1,14.000000,100,1,12.730000,100,1,14.030000,2,1,12.710000,100,1,14.280000,100,1,12.500000,700,1,14.450000,100,1,12.460000,200,2,14.520000,100,1,12.430000,700,1,14.560000,800,2,12.420000,700,1,14.600000,700,1,ARL,326730517
2025-07-17T16:03:10.843629633Z,2025-07-17T16:03:10.843464369Z,10,2,1108,A,A,2,13.87,100,130,165264,272474831,13.120000,200,2,13.720000,15,1,13.110000,100,1,13.730000,100,1,13.030000,100,1,13.870000,200,2,13.000000,2,1,14.000000,100,1,12.730000,100,1,14.030000,2,1,12.710000,100,1,14.280000,100,1,12.500000,700,1,14.450000,100,1,12.460000,200,2,14.520000,100,1,12.430000,700,1,14.560000,800,2,12.420000,700,1,14.600000,700,1,ARL,326730521
2025-07-17T16:03:16.348189077Z,2025-07-17T16:03:16.348023740Z,10,2,1108,A,A,0,13.69,15,130,165337,272557172,13.120000,200,2,13.690000,15,1,13.110000,100,1,13.720000,15,1,13.030000,100,1,13.730000,100,1,13.000000,2,1,13.870000,200,2,12.730000,100,1,14.000000,100,1,12.710000,100,1,14.030000,2,1,12.500000,700,1,14.280000,100,1,12.460000,200,2,14.450000,100,1,12.430000,700,1,14.520000,100,1,12.420000,700,1,14.560000,800,2,ARL,326835877
2025-07-17T16:03:16.348468824Z,2025-07-17T16:03:16.348302787Z,10,2,1108,C,A,12,14.70,100,0,166037,272557230,13.120000,200,2,13.690000,15,1,13.110000,100,1,13.720000,15,1,13.030000,100,1,13.730000,100,1,13.000000,2,1,13.870000,200,2,12.730000,100,1,14.000000,100,1,12.710000,100,1,14.030000,2,1,12.500000,700,1,14.280000,100,1,12.460000,200,2,14.450000,100,1,12.430000,700,1,14.520000,100,1,12.420000,700,1,14.560000,800,2,ARL,326551829
2025-07-17T16:03:16.348468824Z,2025-07-17T16:03:16.348302787Z,10,2,1108,A,A,-1,14.58,100,130,166037,272557230,13.120000,200,2,13.690000,15,1,13.110000,100,1,13.720000,15,1,13.030000,100,1,13.730000,100,1,13.000000,2,1,13.870000,200,2,12.730000,100,1,14.000000,100,1,12.710000,100,1,14.030000,2,1,12.500000,700,1,14.280000,100,1,12.460000,200,2,14.450000,100,1,12.430000,700,1,14.520000,100,1,12.420000,700,1,14.560000,800,2,ARL,326835885
2025-07-17T16:03:16.349679949Z,2025-07-17T16:03:16.349513354Z,10,2,1108,C,A,13,14.70,100,0,166595,272557430,13.120000,200,2,13.690000,15,1,13.110000,100,1,13.720000,15,1,13.030000,100,1,13.730000,100,1,13.000000,2,1,13.870000,200,2,12.730000,100,1,14.000000,100,1,12.710000,100,1,14.030000,2,1,12.500000,700,1,14.280000,100,1,12.460000,200,2,14.450000,100,1,12.430000,700,1,14.520000,100,1,12.420000,700,1,14.560000,800,2,ARL,326551237
2025-07-17T16:03:16.349679949Z,2025-07-17T16:03:16.349513354Z,10,2,1108,A,A,-1,14.58,100,130,166595,272557430,13.120000,200,2,13.690000,15,1,13.110000,100,1,13.720000,15,1,13.030000,100,1,13.730000,100,1,13.000000,2,1,13.870000,200,2,12.730000,100,1,14.000000,100,1,12.710000,100,1,14.030000,2,1,12.500000,700,1,14.280000,100,1,12.460000,200,2,14.450000,100,1,12.430000,700,1,14.520000,100,1,12.420000,700,1,14.560000,800,2,ARL,326836085
2025-07-17T16:03:16.352011831Z,2025-07-17T16:03:16.351845457Z,10,2,1108,C,A,2,13.73,100,0,166374,272557789,13.120000,200,2,13.690000,15,1,13.110000,100,1,13.720000,15,1,13.030000,100,1,13.870000,200,2,13.000000,2,1,14.000000,100,1,12.730000,100,1,14.030000,2,1,12.710000,100,1,14.280000,100,1,12.500000,700,1,14.450000,100,1,12.460000,200,2,14.520000,100,1,12.430000,700,1,14.560000,800,2,12.420000,700,1,14.580000,200,2,ARL,326729685
2025-07-17T16:03:16.352011831Z,2025-07-17T16:03:16.351845457Z,10,2,1108,A,A,1,13.70,100,130,166374,272557789,13.120000,200,2,13.690000,15,1,13.110000,100,1,13.700000,100,1,13.030000,100,1,13.720000,15,1,13.000000,2,1,13.870000,200,2,12.730000,100,1,14.000000,100,1,12.710000,100,1,14.030000,2,1,12.500000,700,1,14.280000,100,1,12.460000,200,2,14.450000,100,1,12.430000,700,1,14.520000,100,1,12.420000,700,1,14.560000,800,2,ARL,326836533
2025-07-17T16:03:16.365985162Z,2025-07-17T16:03:16.365819243Z,10,2,1108,C,A,17,15.38,100,0,165919,272559024,13.120000,200,2,13.690000,15,1,13.110000,100,1,13.700000,100,1,13.030000,100,1,13.720000,15,1,13.000000,2,1,13.870000,200,2,12.730000,100,1,14.000000,100,1,12.710000,100,1,14.030000,2,1,12.500000,700,1,14.280000,100,1,12.460000,200,2,14.450000,100,1,12.430000,700,1,14.520000,100,1,12.420000,700,1,14.560000,800,2,ARL,325714965
2025-07-17T16:03:16.365985162Z,2025-07-17T16:03:16.365819243Z,10,2,1108,A,A,-1,15.07,100,130,165919,272559024,13.120000,200,2,13.690000,15,1,13.110000,100,1,13.700000,100,1,13.030000,100,1,13.720000,15,1,13.000000,2,1,13.870000,200,2,12.730000,100,1,14.000000,100,1,12.710000,100,1,14.030000,2,1,12.500000,700,1,14.280000,100,1,12.460000,200,2,14.450000,100,1,12.430000,700,1,14.520000,100,1,12.420000,700,1,14.560000,800,2,ARL,326837501
2025-07-17T16:03:18.804325078Z,2025-07-17T16:03:18.804159952Z,10,2,1108,C,A,0,13.69,15,130,165126,272609485,13.120000,200,2,13.700000,100,1,13.110000,100,1,13.720000,15,1,13.030000,100,1,13.870000,200,2,13.000000,2,1,14.000000,100,1,12.730000,100,1,14.030000,2,1,12.710000,100,1,14.280000,100,1,12.500000,700,1,14.450000,100,1,12.460000,200,2,14.520000,100,1,12.430000,700,1,14.560000,800,2,12.420000,700,1,14.580000,200,2,ARL,326835877
2025-07-17T16:03:18.804367560Z,2025-07-17T16:03:18.804202246Z,10,2,1108,C,A,0,13.70,100,130,165314,272609486,13.120000,200,2,13.720000,15,1,13.110000,100,1,13.870000,200,2,13.030000,100,1,14.000000,100,1,13.000000,2,1,14.030000,2,1,12.730000,100,1,14.280000,100,1,12.710000,100,1,14.450000,100,1,12.500000,700,1,14.520000,100,1,12.460000,200,2,14.560000,800,2,12.430000,700,1,14.580000,200,2,12.420000,700,1,14.600000,700,1,ARL,326836533
2025-07-17T16:03:18.805099118Z,2025-07-17T16:03:18.804933488Z,10,2,1108,C,A,12,14.79,100,0,165630,272609510,13.120000,200,2,13.720000,15,1,13.110000,100,1,13.870000,200,2,13.030000,100,1,14.000000,100,1,13.000000,2,1,14.030000,2,1,12.730000,100,1,14.280000,100,1,12.710000,100,1,14.450000,100,1,12.500000,700,1,14.520000,100,1,12.460000,200,2,14.560000,800,2,12.430000,700,1,14.580000,200,2,12.420000,700,1,14.600000,700,1,ARL,326729705
2025-07-17T16:03:18.805099118Z,2025-07-17T16:03:18.804933488Z,10,2,1108,A,A,-1,14.95,100,130,165630,272609510,13.120000,200,2,13.720000,15,1,13.110000,100,1,13.870000,200,2,13.030000,100,1,14.000000,100,1,13.000000,2,1,14.030000,2,1,12.730000,100,1,14.280000,100,1,12.710000,100,1,14.450000,100,1,12.500000,700,1,14.520000,100,1,12.460000,200,2,14.560000,800,2,12.430000,700,1,14.580000,200,2,12.420000,700,1,14.600000,700,1,ARL,326892717
2025-07-17T16:03:18.805291629Z,2025-07-17T16:03:18.805126035Z,10,2,1108,C,A,11,14.70,100,0,165594,272609526,13.120000,200,2,13.720000,15,1,13.110000,100,1,13.870000,200,2,13.030000,100,1,14.000000,100,1,13.000000,2,1,14.030000,2,1,12.730000,100,1,14.280000,100,1,12.710000,100,1,14.450000,100,1,12.500000,700,1,14.520000,100,1,12.460000,200,2,14.560000,800,2,12.430000,700,1,14.580000,200,2,12.420000,700,1,14.600000,700,1,ARL,326729721
2025-07-17T16:03:18.805291629Z,2025-07-17T16:03:18.805126035Z,10,2,1108,A,A,-1,14.85,100,130,165594,272609526,13.120000,200,2,13.720000,15,1,13.110000,100,1,13.870000,200,2,13.030000,100,1,14.000000,100,1,13.000000,2,1,14.030000,2,1,12.730000,100,1,14.280000,100,1,12.710000,100,1,14.450000,100,1,12.500000,700,1,14.520000,100,1,12.460000,200,2,14.560000,800,2,12.430000,700,1,14.580000,200,2,12.420000,700,1,14.600000,700,1,ARL,326892721
2025-07-17T16:03:18.805449089Z,2025-07-17T16:03:18.805283236Z,10,2,1108,C,A,0,13.72,15,130,165853,272609541,13.120000,200,2,13.870000,200,2,13.110000,100,1,14.000000,100,1,13.030000,100,1,14.030000,2,1,13.000000,2,1,14.280000,100,1,12.730000,100,1,14.450000,100,1,12.710000,100,1,14.520000,100,1,12.500000,700,1,14.560000,800,2,12.460000,200,2,14.580000,200,2,12.430000,700,1,14.600000,700,1,12.420000,700,1,14.680000,1400,2,ARL,326729677
2025-07-17T16:03:18.806535903Z,2025-07-17T16:03:18.806370373Z,10,2,1108,C,A,7,14.58,100,0,165530,272609577,13.120000,200,2,13.870000,200,2,13.110000,100,1,14.000000,100,1,13.030000,100,1,14.030000,2,1,13.000000,2,1,14.280000,100,1,12.730000,100,1,14.450000,100,1,12.710000,100,1,14.520000,100,1,12.500000,700,1,14.560000,800,2,12.460000,200,2,14.580000,100,1,12.430000,700,1,14.600000,700,1,12.420000,700,1,14.680000,1400,2,ARL,326835885
2025-07-17T16:03:18.806535903Z,2025-07-17T16:03:18.806370373Z,10,2,1108,A,A,-1,14.76,100,130,165530,272609577,13.120000,200,2,13.870000,200,2,13.110000,100,1,14.000000,100,1,13.030000,100,1,14.030000,2,1,13.000000,2,1,14.280000,100,1,12.730000,100,1,14.450000,100,1,12.710000,100,1,14.520000,100,1,12.500000,700,1,14.560000,800,2,12.460000,200,2,14.580000,100,1,12.430000,700,1,14.600000,700,1,12.420000,700,1,14.680000,1400,2,ARL,326892817
2025-07-17T16:03:18.806802589Z,2025-07-17T16:03:18.806637004Z,10,2,1108,C,A,7,14.58,100,0,165585,272609583,13.120000,200,2,13.870000,200,2,13.110000,100,1,14.000000,100,1,13.030000,100,1,14.030000,2,1,13.000000,2,1,14.280000,100,1,12.730000,100,1,14.450000,100,1,12.710000,100,1,14.520000,100,1,12.500000,700,1,14.560000,800,2,12.460000,200,2,14.600000,700,1,12.430000,700,1,14.680000,1400,2,12.420000,700,1,14.700000,100,1,ARL,326836085
2025-07-17T16:03:18.806802589Z,2025-07-17T16:03:18.806637004Z,10,2,1108,A,A,-1,14.76,100,130,165585,272609583,13.120000,200,2,13.870000,200,2,13.110000,100,1,14.000000,100,1,13.030000,100,1,14.030000,2,1,13.000000,2,1,14.280000,100,1,12.730000,100,1,14.450000,100,1,12.710000,100,1,14.520000,100,1,12.500000,700,1,14.560000,800,2,12.460000,200,2,14.600000,700,1,12.430000,700,1,14.680000,1400,2,12.420000,700,1,14.700000,100,1,ARL,326892825
2025-07-17T16:03:18.809706334Z,2025-07-17T16:03:18.809540733Z,10,2,1108,C,A,5,14.52,100,0,165601,272609656,13.120000,200,2,13.870000,200,2,13.110000,100,1,14.000000,100,1,13.030000,100,1,14.030000,2,1,13.000000,2,1,14.280000,100,1,12.730000,100,1,14.450000,100,1,12.710000,100,1,14.560000,800,2,12.500000,700,1,14.600000,700,1,12.460000,200,2,14.680000,1400,2,12.430000,700,1,14.700000,100,1,12.420000,700,1,14.760000,200,2,ARL,326729729
2025-07-17T16:03:18.809706334Z,2025-07-17T16:03:18.809540733Z,10,2,1108,A,A,7,14.66,100,130,165601,272609656,13.120000,200,2,13.870000,200,2,13.110000,100,1,14.000000,100,1,13.030000,100,1,14.030000,2,1,13.000000,2,1,14.280000,100,1,12.730000,100,1,14.450000,100,1,12.710000,100,1,14.560000,800,2,12.500000,700,1,14.600000,700,1,12.460000,200,2,14.660000,100,1,12.430000,700,1,14.680000,1400,2,12.420000,700,1,14.700000,100,1,ARL,326892885
2025-07-17T16:03:18.809848665Z,2025-07-17T16:03:18.809683187Z,10,2,1108,C,A,17,15.79,100,0,165478,272609658,13.120000,200,2,13.870000,200,2,13.110000,100,1,14.000000,100,1,13.030000,100,1,14.030000,2,1,13.000000,2,1,14.280000,100,1,12.730000,100,1,14.450000,100,1,12.710000,100,1,14.560000,800,2,12.500000,700,1,14.600000,700,1,12.460000,200,2,14.660000,100,1,12.430000,700,1,14.680000,1400,2,12.420000,700,1,14.700000,100,1,ARL,326729733
2025-07-17T16:03:18.809848665Z,2025-07-17T16:03:18.809683187Z,10,2,1108,A,A,-1,15.96,100,130,165478,272609658,13.120000,200,2,13.870000,200,2,13.110000,100,1,14.000000,100,1,13.030000,100,1,14.030000,2,1,13.000000,2,1,14.280000,100,1,12.730000,100,1,14.450000,100,1,12.710000,100,1,14.560000,800,2,12.500000,700,1,14.600000,700,1,12.460000,200,2,14.660000,100,1,12.430000,700,1,14.680000,1400,2,12.420000,700,1,14.700000,100,1,ARL,326892889
2025-07-17T16:03:18.812107206Z,2025-07-17T16:03:18.811941680Z,10,2,1108,C,A,20,17.44,100,0,165526,272609679,13.120000,200,2,13.870000,200,2,13.110000,100,1,14.000000,100,1,13.030000,100,1,14.030000,2,1,13.000000,2,1,14.280000,100,1,12.730000,100,1,14.450000,100,1,12.710000,100,1,14.560000,800,2,12.500000,700,1,14.600000,700,1,12.460000,200,2,14.660000,100,1,12.430000,700,1,14.680000,1400,2,12.420000,700,1,14.700000,100,1,ARL,326729725
2025-07-17T16:03:18.812107206Z,2025-07-17T16:03:18.811941680Z,10,2,1108,A,A,-1,17.62,100,130,165526,272609679,13.120000,200,2,13.870000,200,2,13.110000,100,1,14.000000,100,1,13.030000,100,1,14.030000,2,1,13.000000,2,1,14.280000,100,1,12.730000,100,1,14.450000,100,1,12.710000,100,1,14.560000,800,2,12.500000,700,1,14.600000,700,1,12.460000,200,2,14.660000,100,1,12.430000,700,1,14.680000,1400,2,12.420000,700,1,14.700000,100,1,ARL,326892921
2025-07-17T16:03:18.818245629Z,2025-07-17T16:03:18.818080239Z,10,2,1108,C,A,1,14.00,100,130,165390,272609768,13.120000,200,2,13.870000,200,2,13.110000,100,1,14.030000,2,1,13.030000,100,1,14.280000,100,1,13.000000,2,1,14.450000,100,1,12.730000,100,1,14.560000,800,2,12.710000,100,1,14.600000,700,1,12.500000,700,1,14.660000,100,1,12.460000,200,2,14.680000,1400,2,12.430000,700,1,14.700000,100,1,12.420000,700,1,14.760000,200,2,ARL,326729929
2025-07-17T16:03:18.818301143Z,2025-07-17T16:03:18.818135688Z,10,2,1108,A,A,2,14.15,100,130,165455,272609769,13.120000,200,2,13.870000,200,2,13.110000,100,1,14.030000,2,1,13.030000,100,1,14.150000,100,1,13.000000,2,1,14.280000,100,1,12.730000,100,1,14.450000,100,1,12.710000,100,1,14.560000,800,2,12.500000,700,1,14.600000,700,1,12.460000,200,2,14.660000,100,1,12.430000,700,1,14.680000,1400,2,12.420000,700,1,14.700000,100,1,ARL,326893213
2025-07-17T16:03:18.868420503Z,2025-07-17T16:03:18.868254768Z,10,2,1108,C,A,9,14.70,100,0,165735,272610397,13.120000,200,2,13.870000,200,2,13.110000,100,1,14.030000,2,1,13.030000,100,1,14.150000,100,1,13.000000,2,1,14.280000,100,1,12.730000,100,1,14.450000,100,1,12.710000,100,1,14.560000,800,2,12.500000,700,1,14.600000,700,1,12.460000,200,2,14.660000,100,1,12.430000,700,1,14.680000,1400,2,12.420000,700,1,14.760000,200,2,ARL,326729821
2025-07-17T16:03:18.868420503Z,2025-07-17T16:03:18.868254768Z,10,2,1108,A,A,-1,14.85,100,130,165735,272610397,13.120000,200,2,13.870000,200,2,13.110000,100,1,14.030000,2,1,13.030000,100,1,14.150000,100,1,13.000000,2,1,14.280000,100,1,12.730000,100,1,14.450000,100,1,12.710000,100,1,14.560000,800,2,12.500000,700,1,14.600000,700,1,12.460000,200,2,14.660000,100,1,12.430000,700,1,14.680000,1400,2,12.420000,700,1,14.760000,200,2,ARL,326893961
2025-07-17T16:03:19.191219507Z,2025-07-17T16:03:19.191054306Z,10,2,1108,A,A,1,13.88,100,130,165201,272614303,13.120000,200,2,13.870000,200,2,13.110000,100,1,13.880000,100,1,13.030000,100,1,14.030000,2,1,13.000000,2,1,14.150000,100,1,12.730000,100,1,14.280000,100,1,12.710000,100,1,14.450000,100,1,12.500000,700,1,14.560000,800,2,12.460000,200,2,14.600000,700,1,12.430000,700,1,14.660000,100,1,12.420000,700,1,14.680000,1400,2,ARL,326899125
2025-07-17T16:03:27.436323951Z,2025-07-17T16:03:27.436158395Z,10,2,1108,A,A,4,14.25,53,130,165556,272788767,13.120000,200,2,13.870000,200,2,13.110000,100,1,13.880000,100,1,13.030000,100,1,14.030000,2,1,13.000000,2,1,14.150000,100,1,12.730000,100,1,14.250000,53,1,12.710000,100,1,14.280000,100,1,12.500000,700,1,14.450000,100,1,12.460000,200,2,14.560000,800,2,12.430000,700,1,14.600000,700,1,12.420000,700,1,14.660000,100,1,ARL,327112281
2025-07-17T16:03:27.436880768Z,2025-07-17T16:03:27.436715001Z,10,2,1108,C,B,13,12.23,100,0,165767,272788774,13.120000,200,2,13.870000,200,2,13.110000,100,1,13.880000,100,1,13.030000,100,1,14.030000,2,1,13.000000,2,1,14.150000,100,1,12.730000,100,1,14.250000,53,1,12.710000,100,1,14.280000,100,1,12.500000,700,1,14.450000,100,1,12.460000,200,2,14.560000,800,2,12.430000,700,1,14.600000,700,1,12.420000,700,1,14.660000,100,1,ARL,291964745
2025-07-17T16:03:27.436880768Z,2025-07-17T16:03:27.436715001Z,10,2,1108,A,B,-1,12.10,100,130,165767,272788774,13.120000,200,2,13.870000,200,2,13.110000,100,1,13.880000,100,1,13.030000,100,1,14.030000,2,1,13.000000,2,1,14.150000,100,1,12.730000,100,1,14.250000,53,1,12.710000,100,1,14.280000,100,1,12.500000,700,1,14.450000,100,1,12.460000,200,2,14.560000,800,2,12.430000,700,1,14.600000,700,1,12.420000,700,1,14.660000,100,1,ARL,327112289
2025-07-17T16:03:27.438566971Z,2025-07-17T16:03:27.438400828Z,10,2,1108,C,B,12,12.34,100,0,166143,272788792,13.120000,200,2,13.870000,200,2,13.110000,100,1,13.880000,100,1,13.030000,100,1,14.030000,2,1,13.000000,2,1,14.150000,100,1,12.730000,100,1,14.250000,53,1,12.710000,100,1,14.280000,100,1,12.500000,700,1,14.450000,100,1,12.460000,200,2,14.560000,800,2,12.430000,700,1,14.600000,700,1,12.420000,700,1,14.660000,100,1,ARL,285586113
2025-07-17T16:03:27.438566971Z,2025-07-17T16:03:27.438400828Z,10,2,1108,A,B,-1,12.20,100,130,166143,272788792,13.120000,200,2,13.870000,200,2,13.110000,100,1,13.880000,100,1,13.030000,100,1,14.030000,2,1,13.000000,2,1,14.150000,100,1,12.730000,100,1,14.250000,53,1,12.710000,100,1,14.280000,100,1,12.500000,700,1,14.450000,100,1,12.460000,200,2,14.560000,800,2,12.430000,700,1,14.600000,700,1,12.420000,700,1,14.660000,100,1,ARL,327112385
2025-07-17T16:03:27.438603564Z,2025-07-17T16:03:27.438437969Z,10,2,1108,C,B,12,12.34,100,0,165595,272788793,13.120000,200,2,13.870000,200,2,13.110000,100,1,13.880000,100,1,13.030000,100,1,14.030000,2,1,13.000000,2,1,14.150000,100,1,12.730000,100,1,14.250000,53,1,12.710000,100,1,14.280000,100,1,12.500000,700,1,14.450000,100,1,12.460000,200,2,14.560000,800,2,12.430000,700,1,14.600000,700,1,12.420000,700,1,14.660000,100,1,ARL,285586189
2025-07-17T16:03:27.438603564Z,2025-07-17T16:03:27.438437969Z,10,2,1108,A,B,-1,12.20,100,130,165595,272788793,13.120000,200,2,13.870000,200,2,13.110000,100,1,13.880000,100,1,13.030000,100,1,14.030000,2,1,13.000000,2,1,14.150000,100,1,12.730000,100,1,14.250000,53,1,12.710000,100,1,14.280000,100,1,12.500000,700,1,14.450000,100,1,12.460000,200,2,14.560000,800,2,12.430000,700,1,14.600000,700,1,12.420000,700,1,14.660000,100,1,ARL,327112393
2025-07-17T16:03:27.454010355Z,2025-07-17T16:03:27.453845141Z,10,2,1108,C,B,2,13.03,100,130,165214,272788897,13.120000,200,2,13.870000,200,2,13.110000,100,1,13.880000,100,1,13.000000,2,1,14.030000,2,1,12.730000,100,1,14.150000,100,1,12.710000,100,1,14.250000,53,1,12.500000,700,1,14.280000,100,1,12.460000,200,2,14.450000,100,1,12.430000,700,1,14.560000,800,2,12.420000,700,1,14.600000,700,1,12.370000,700,1,14.660000,100,1,ARL,285586293
2025-07-17T16:03:27.454059719Z,2025-07-17T16:03:27.453894425Z,10,2,1108,A,B,3,12.95,100,130,165294,272788898,13.120000,200,2,13.870000,200,2,13.110000,100,1,13.880000,100,1,13.000000,2,1,14.030000,2,1,12.950000,100,1,14.150000,100,1,12.730000,100,1,14.250000,53,1,12.710000,100,1,14.280000,100,1,12.500000,700,1,14.450000,100,1,12.460000,200,2,14.560000,800,2,12.430000,700,1,14.600000,700,1,12.420000,700,1,14.660000,100,1,ARL,327112565
2025-07-17T16:03:27.454892321Z,2025-07-17T16:03:27.454726901Z,10,2,1108,C,B,3,12.95,100,130,165420,272788942,13.120000,200,2,13.870000,200,2,13.110000,100,1,13.880000,100,1,13.000000,2,1,14.030000,2,1,12.730000,100,1,14.150000,100,1,12.710000,100,1,14.250000,53,1,12.500000,700,1,14.280000,100,1,12.460000,200,2,14.450000,100,1,12.430000,700,1,14.560000,800,2,12.420000,700,1,14.600000,700,1,12.370000,700,1,14.660000,100,1,ARL,327112565
2025-07-17T16:03:27.454939600Z,2025-07-17T16:03:27.454773691Z,10,2,1108,A,B,3,12.86,100,130,165909,272788943,13.120000,200,2,13.870000,200,2,13.110000,100,1,13.880000,100,1,13.000000,2,1,14.030000,2,1,12.860000,100,1,14.150000,100,1,12.730000,100,1,14.250000,53,1,12.710000,100,1,14.280000,100,1,12.500000,700,1,14.450000,100,1,12.460000,200,2,14.560000,800,2,12.430000,700,1,14.600000,700,1,12.420000,700,1,14.660000,100,1,ARL,327112577
2025-07-17T16:03:27.517751270Z,2025-07-17T16:03:27.517585374Z,10,2,1108,C,B,7,12.46,100,130,165896,272790695,13.120000,200,2,13.870000,200,2,13.110000,100,1,13.880000,100,1,13.000000,2,1,14.030000,2,1,12.860000,100,1,14.150000,100,1,12.730000,100,1,14.250000,53,1,12.710000,100,1,14.280000,100,1,12.500000,700,1,14.450000,100,1,12.460000,100,1,14.560000,800,2,12.430000,700,1,14.600000,700,1,12.420000,700,1,14.660000,100,1,ARL,285587281
2025-07-17T16:03:27.517864675Z,2025-07-17T16:03:27.517699408Z,10,2,1108,A,B,-1,12.33,100,130,165267,272790696,13.120000,200,2,13.870000,200,2,13.110000,100,1,13.880000,100,1,13.000000,2,1,14.030000,2,1,12.860000,100,1,14.150000,100,1,12.730000,100,1,14.250000,53,1,12.710000,100,1,14.280000,100,1,12.500000,700,1,14.450000,100,1,12.460000,100,1,14.560000,800,2,12.430000,700,1,14.600000,700,1,12.420000,700,1,14.660000,100,1,ARL,327114465
2025-07-17T16:03:27.536343943Z,2025-07-17T16:03:27.536178718Z,10,2,1108,C,A,4,14.25,53,130,165225,272791410,13.120000,200,2,13.870000,200,2,13.110000,100,1,13.880000,100,1,13.000000,2,1,14.030000,2,1,12.860000,100,1,14.150000,100,1,12.730000,100,1,14.280000,100,1,12.710000,100,1,14.450000,100,1,12.500000,700,1,14.560000,800,2,12.460000,100,1,14.600000,700,1,12.430000,700,1,14.660000,100,1,12.420000,700,1,14.680000,1400,2,ARL,327112281
2025-07-17T16:03:56.548348047Z,2025-07-17T16:03:56.548182793Z,10,2,1108,A,A,0,13.80,15,130,165254,273208310,13.120000,200,2,13.800000,15,1,13.110000,100,1,13.870000,200,2,13.000000,2,1,13.880000,100,1,12.860000,100,1,14.030000,2,1,12.730000,100,1,14.150000,100,1,12.710000,100,1,14.280000,100,1,12.500000,700,1,14.450000,100,1,12.460000,100,1,14.560000,800,2,12.430000,700,1,14.600000,700,1,12.420000,700,1,14.660000,100,1,ARL,327675057
2025-07-17T16:03:56.548611716Z,2025-07-17T16:03:56.548446336Z,10,2,1108,C,A,2,13.88,100,0,165380,273208316,13.120000,200,2,13.800000,15,1,13.110000,100,1,13.870000,200,2,13.000000,2,1,14.030000,2,1,12.860000,100,1,14.150000,100,1,12.730000,100,1,14.280000,100,1,12.710000,100,1,14.450000,100,1,12.500000,700,1,14.560000,800,2,12.460000,100,1,14.600000,700,1,12.430000,700,1,14.660000,100,1,12.420000,700,1,14.680000,1400,2,ARL,326899125
2025-07-17T16:03:56.548611716Z,2025-07-17T16:03:56.548446336Z,10,2,1108,A,A,1,13.81,100,130,165380,273208316,13.120000,200,2,13.800000,15,1,13.110000,100,1,13.810000,100,1,13.000000,2,1,13.870000,200,2,12.860000,100,1,14.030000,2,1,12.730000,100,1,14.150000,100,1,12.710000,100,1,14.280000,100,1,12.500000,700,1,14.450000,100,1,12.460000,100,1,14.560000,800,2,12.430000,700,1,14.600000,700,1,12.420000,700,1,14.660000,100,1,ARL,327675065
2025-07-17T16:03:56.549354405Z,2025-07-17T16:03:56.549188993Z,10,2,1108,C,A,13,14.95,100,0,165412,273208325,13.120000,200,2,13.800000,15,1,13.110000,100,1,13.810000,100,1,13.000000,2,1,13.870000,200,2,12.860000,100,1,14.030000,2,1,12.730000,100,1,14.150000,100,1,12.710000,100,1,14.280000,100,1,12.500000,700,1,14.450000,100,1,12.460000,100,1,14.560000,800,2,12.430000,700,1,14.600000,700,1,12.420000,700,1,14.660000,100,1,ARL,326892717
2025-07-17T16:03:56.549354405Z,2025-07-17T16:03:56.549188993Z,10,2,1108,A,A,-1,14.88,100,130,165412,273208325,13.120000,200,2,13.800000,15,1,13.110000,100,1,13.810000,100,1,13.000000,2,1,13.870000,200,2,12.860000,100,1,14.030000,2,1,12.730000,100,1,14.150000,100,1,12.710000,100,1,14.280000,100,1,12.500000,700,1,14.450000,100,1,12.460000,100,1,14.560000,800,2,12.430000,700,1,14.600000,700,1,12.420000,700,1,14.660000,100,1,ARL,327675093
2025-07-17T16:04:06.233858611Z,2025-07-17T16:04:06.233692491Z,10,2,1108,C,A,11,14.76,100,0,166120,273345719,13.120000,200,2,13.800000,15,1,13.110000,100,1,13.810000,100,1,13.000000,2,1,13.870000,200,2,12.860000,100,1,14.030000,2,1,12.730000,100,1,14.150000,100,1,12.710000,100,1,14.280000,100,1,12.500000,700,1,14.450000,100,1,12.460000,100,1,14.560000,800,2,12.430000,700,1,14.600000,700,1,12.420000,700,1,14.660000,100,1,ARL,326892825
2025-07-17T16:04:06.233858611Z,2025-07-17T16:04:06.233692491Z,10,2,1108,A,A,9,14.64,100,130,166120,273345719,13.120000,200,2,13.800000,15,1,13.110000,100,1,13.810000,100,1,13.000000,2,1,13.870000,200,2,12.860000,100,1,14.030000,2,1,12.730000,100,1,14.150000,100,1,12.710000,100,1,14.280000,100,1,12.500000,700,1,14.450000,100,1,12.460000,100,1,14.560000,800,2,12.430000,700,1,14.600000,700,1,12.420000,700,1,14.640000,100,1,ARL,327856297
2025-07-17T16:04:06.234600198Z,2025-07-17T16:04:06.234433294Z,10,2,1108,C,A,12,14.76,100,0,166904,273345721,13.120000,200,2,13.800000,15,1,13.110000,100,1,13.810000,100,1,13.000000,2,1,13.870000,200,2,12.860000,100,1,14.030000,2,1,12.730000,100,1,14.150000,100,1,12.710000,100,1,14.280000,100,1,12.500000,700,1,14.450000,100,1,12.460000,100,1,14.560000,800,2,12.430000,700,1,14.600000,700,1,12.420000,700,1,14.640000,100,1,ARL,326892817
2025-07-17T16:04:06.234600198Z,2025-07-17T16:04:06.234433294Z,10,2,1108,A,A,9,14.64,100,130,166904,273345721,13.120000,200,2,13.800000,15,1,13.110000,100,1,13.810000,100,1,13.000000,2,1,13.870000,200,2,12.860000,100,1,14.030000,2,1,12.730000,100,1,14.150000,100,1,12.710000,100,1,14.280000,100,1,12.500000,700,1,14.450000,100,1,12.460000,100,1,14.560000,800,2,12.430000,700,1,14.600000,700,1,12.420000,700,1,14.640000,200,2,ARL,327856309
2025-07-17T16:04:06.510914101Z,2025-07-17T16:04:06.510748731Z,10,2,1108,A,A,0,13.72,15,130,165370,273352664,13.120000,200,2,13.720000,15,1,13.110000,100,1,13.800000,15,1,13.000000,2,1,13.810000,100,1,12.860000,100,1,13.870000,200,2,12.730000,100,1,14.030000,2,1,12.710000,100,1,14.150000,100,1,12.500000,700,1,14.280000,100,1,12.460000,100,1,14.450000,100,1,12.430000,700,1,14.560000,800,2,12.420000,700,1,14.600000,700,1,ARL,327863853
2025-07-17T16:04:06.512413102Z,2025-07-17T16:04:06.512244746Z,10,2,1108,C,A,2,13.81,100,0,168356,273352888,13.120000,200,2,13.720000,15,1,13.110000,100,1,13.800000,15,1,13.000000,2,1,13.870000,200,2,12.860000,100,1,14.030000,2,1,12.730000,100,1,14.150000,100,1,12.710000,100,1,14.280000,100,1,12.500000,700,1,14.450000,100,1,12.460000,100,1,14.560000,800,2,12.430000,700,1,14.600000,700,1,12.420000,700,1,14.640000,200,2,ARL,327675065
2025-07-17T16:04:06.512413102Z,2025-07-17T16:04:06.512244746Z,10,2,1108,A,A,1,13.73,100,128,168356,273352888,13.120000,200,2,13.720000,15,1,13.110000,100,1,13.730000,100,1,13.000000,2,1,13.800000,15,1,12.860000,100,1,13.870000,200,2,12.730000,100,1,14.030000,2,1,12.710000,100,1,14.150000,100,1,12.500000,700,1,14.280000,100,1,12.460000,100,1,14.450000,100,1,12.430000,700,1,14.560000,800,2,12.420000,700,1,14.600000,700,1,ARL,327864137
2025-07-17T16:04:06.513675299Z,2025-07-17T16:04:06.513497276Z,10,2,1108,C,A,14,14.88,100,0,178023,273353923,13.120000,200,2,13.720000,15,1,13.110000,100,1,13.730000,100,1,13.000000,2,1,13.800000,15,1,12.860000,100,1,13.870000,200,2,12.730000,100,1,14.030000,2,1,12.710000,100,1,14.150000,100,1,12.500000,700,1,14.280000,100,1,12.460000,100,1,14.450000,100,1,12.430000,700,1,14.560000,800,2,12.420000,700,1,14.600000,700,1,ARL,327675093
2025-07-17T16:04:06.513675299Z,2025-07-17T16:04:06.513497276Z,10,2,1108,A,A,-1,14.79,100,128,178023,273353923,13.120000,200,2,13.720000,15,1,13.110000,100,1,13.730000,100,1,13.000000,2,1,13.800000,15,1,12.860000,100,1,13.870000,200,2,12.730000,100,1,14.030000,2,1,12.710000,100,1,14.150000,100,1,12.500000,700,1,14.280000,100,1,12.460000,100,1,14.450000,100,1,12.430000,700,1,14.560000,800,2,12.420000,700,1,14.600000,700,1,ARL,327864893
2025-07-17T16:04:06.522853161Z,2025-07-17T16:04:06.522687474Z,10,2,1108,C,A,14,14.85,100,0,165687,273357758,13.120000,200,2,13.720000,15,1,13.110000,100,1,13.730000,100,1,13.000000,2,1,13.800000,15,1,12.860000,100,1,13.870000,200,2,12.730000,100,1,14.030000,2,1,12.710000,100,1,14.150000,100,1,12.500000,700,1,14.280000,100,1,12.460000,100,1,14.450000,100,1,12.430000,700,1,14.560000,800,2,12.420000,700,1,14.600000,700,1,ARL,326892721
2025-07-17T16:04:06.522853161Z,2025-07-17T16:04:06.522687474Z,10,2,1108,A,A,-1,14.70,100,130,165687,273357758,13.120000,200,2,13.720000,15,1,13.110000,100,1,13.730000,100,1,13.000000,2,1,13.800000,15,1,12.860000,100,1,13.870000,200,2,12.730000,100,1,14.030000,2,1,12.710000,100,1,14.150000,100,1,12.500000,700,1,14.280000,100,1,12.460000,100,1,14.450000,100,1,12.430000,700,1,14.560000,800,2,12.420000,700,1,14.600000,700,1,ARL,327868421
2025-07-17T16:04:06.525550815Z,2025-07-17T16:04:06.525385108Z,10,2,1108,C,A,5,14.15,100,130,165707,273358260,13.120000,200,2,13.720000,15,1,13.110000,100,1,13.730000,100,1,13.000000,2,1,13.800000,15,1,12.860000,100,1,13.870000,200,2,12.730000,100,1,14.030000,2,1,12.710000,100,1,14.280000,100,1,12.500000,700,1,14.450000,100,1,12.460000,100,1,14.560000,800,2,12.430000,700,1,14.600000,700,1,12.420000,700,1,14.640000,200,2,ARL,326893213
2025-07-17T16:04:06.525608746Z,2025-07-17T16:04:06.525442486Z,10,2,1108,A,A,4,14.00,100,128,166260,273358273,13.120000,200,2,13.720000,15,1,13.110000,100,1,13.730000,100,1,13.000000,2,1,13.800000,15,1,12.860000,100,1,13.870000,200,2,12.730000,100,1,14.000000,100,1,12.710000,100,1,14.030000,2,1,12.500000,700,1,14.280000,100,1,12.460000,100,1,14.450000,100,1,12.430000,700,1,14.560000,800,2,12.420000,700,1,14.600000,700,1,ARL,327869193
2025-07-17T16:04:06.528210755Z,2025-07-17T16:04:06.528043934Z,10,2,1108,C,A,11,14.66,100,130,166821,273358598,13.120000,200,2,13.720000,15,1,13.110000,100,1,13.730000,100,1,13.000000,2,1,13.800000,15,1,12.860000,100,1,13.870000,200,2,12.730000,100,1,14.000000,100,1,12.710000,100,1,14.030000,2,1,12.500000,700,1,14.280000,100,1,12.460000,100,1,14.450000,100,1,12.430000,700,1,14.560000,800,2,12.420000,700,1,14.600000,700,1,ARL,326892885
2025-07-17T16:04:06.528329048Z,2025-07-17T16:04:06.528161631Z,10,2,1108,A,A,8,14.52,100,128,167417,273358642,13.120000,200,2,13.720000,15,1,13.110000,100,1,13.730000,100,1,13.000000,2,1,13.800000,15,1,12.860000,100,1,13.870000,200,2,12.730000,100,1,14.000000,100,1,12.710000,100,1,14.030000,2,1,12.500000,700,1,14.280000,100,1,12.460000,100,1,14.450000,100,1,12.430000,700,1,14.520000,100,1,12.420000,700,1,14.560000,800,2,ARL,327869529
2025-07-17T16:04:06.543480312Z,2025-07-17T16:04:06.543314706Z,10,2,1108,C,A,23,17.62,100,0,165606,273359491,13.120000,200,2,13.720000,15,1,13.110000,100,1,13.730000,100,1,13.000000,2,1,13.800000,15,1,12.860000,100,1,13.870000,200,2,12.730000,100,1,14.000000,100,1,12.710000,100,1,14.030000,2,1,12.500000,700,1,14.280000,100,1,12.460000,100,1,14.450000,100,1,12.430000,700,1,14.520000,100,1,12.420000,700,1,14.560000,800,2,ARL,326892921
2025-07-17T16:04:06.543480312Z,2025-07-17T16:04:06.543314706Z,10,2,1108,A,A,-1,17.44,100,130,165606,273359491,13.120000,200,2,13.720000,15,1,13.110000,100,1,13.730000,100,1,13.000000,2,1,13.800000,15,1,12.860000,100,1,13.870000,200,2,12.730000,100,1,14.000000,100,1,12.710000,100,1,14.030000,2,1,12.500000,700,1,14.280000,100,1,12.460000,100,1,14.450000,100,1,12.430000,700,1,14.520000,100,1,12.420000,700,1,14.560000,800,2,ARL,327870217
2025-07-17T16:04:06.548945239Z,2025-07-17T16:04:06.548778200Z,10,2,1108,C,A,20,15.96,100,0,167039,273359672,13.120000,200,2,13.720000,15,1,13.110000,100,1,13.730000,100,1,13.000000,2,1,13.800000,15,1,12.860000,100,1,13.870000,200,2,12.730000,100,1,14.000000,100,1,12.710000,100,1,14.030000,2,1,12.500000,700,1,14.280000,100,1,12.460000,100,1,14.450000,100,1,12.430000,700,1,14.520000,100,1,12.420000,700,1,14.560000,800,2,ARL,326892889
2025-07-17T16:04:06.548945239Z,2025-07-17T16:04:06.548778200Z,10,2,1108,A,A,-1,15.79,100,130,167039,273359672,13.120000,200,2,13.720000,15,1,13.110000,100,1,13.730000,100,1,13.000000,2,1,13.800000,15,1,12.860000,100,1,13.870000,200,2,12.730000,100,1,14.000000,100,1,12.710000,100,1,14.030000,2,1,12.500000,700,1,14.280000,100,1,12.460000,100,1,14.450000,100,1,12.430000,700,1,14.520000,100,1,12.420000,700,1,14.560000,800,2,ARL,327870361
2025-07-17T16:04:06.648109829Z,2025-07-17T16:04:06.647944313Z,10,2,1108,C,A,15,14.85,100,0,165516,273361957,13.120000,200,2,13.720000,15,1,13.110000,100,1,13.730000,100,1,13.000000,2,1,13.800000,15,1,12.860000,100,1,13.870000,200,2,12.730000,100,1,14.000000,100,1,12.710000,100,1,14.030000,2,1,12.500000,700,1,14.280000,100,1,12.460000,100,1,14.450000,100,1,12.430000,700,1,14.520000,100,1,12.420000,700,1,14.560000,800,2,ARL,326893961
2025-07-17T16:04:06.648109829Z,2025-07-17T16:04:06.647944313Z,10,2,1108,A,A,-1,14.70,100,130,165516,273361957,13.120000,200,2,13.720000,15,1,13.110000,100,1,13.730000,100,1,13.000000,2,1,13.800000,15,1,12.860000,100,1,13.870000,200,2,12.730000,100,1,14.000000,100,1,12.710000,100,1,14.030000,2,1,12.500000,700,1,14.280000,100,1,12.460000,100,1,14.450000,100,1,12.430000,700,1,14.520000,100,1,12.420000,700,1,14.560000,800,2,ARL,327873009
2025-07-17T16:04:06.805500523Z,2025-07-17T16:04:06.805335354Z,10,2,1108,C,A,0,13.72,15,130,165169,273364089,13.120000,200,2,13.730000,100,1,13.110000,100,1,13.800000,15,1,13.000000,2,1,13.870000,200,2,12.860000,100,1,14.000000,100,1,12.730000,100,1,14.030000,2,1,12.710000,100,1,14.280000,100,1,12.500000,700,1,14.450000,100,1,12.460000,100,1,14.520000,100,1,12.430000,700,1,14.560000,800,2,12.420000,700,1,14.600000,700,1,ARL,327863853
2025-07-17T16:04:06.806217584Z,2025-07-17T16:04:06.806052396Z,10,2,1108,C,A,1,13.80,15,130,165188,273364090,13.120000,200,2,13.730000,100,1,13.110000,100,1,13.870000,200,2,13.000000,2,1,14.000000,100,1,12.860000,100,1,14.030000,2,1,12.730000,100,1,14.280000,100,1,12.710000,100,1,14.450000,100,1,12.500000,700,1,14.520000,100,1,12.460000,100,1,14.560000,800,2,12.430000,700,1,14.600000,700,1,12.420000,700,1,14.640000,200,2,ARL,327675057
2025-07-17T16:04:21.277142662Z,2025-07-17T16:04:21.276976977Z,10,2,1108,A,A,1,13.77,100,130,165685,273687857,13.120000,200,2,13.730000,100,1,13.110000,100,1,13.770000,100,1,13.000000,2,1,13.870000,200,2,12.860000,100,1,14.000000,100,1,12.730000,100,1,14.030000,2,1,12.710000,100,1,14.280000,100,1,12.500000,700,1,14.450000,100,1,12.460000,100,1,14.520000,100,1,12.430000,700,1,14.560000,800,2,12.420000,700,1,14.600000,700,1,ARL,328239293
2025-07-17T16:04:27.791055146Z,2025-07-17T16:04:27.790889618Z,10,2,1108,C,A,4,14.03,2,0,165528,273775264,13.120000,200,2,13.730000,100,1,13.110000,100,1,13.770000,100,1,13.000000,2,1,13.870000,200,2,12.860000,100,1,14.000000,100,1,12.730000,100,1,14.280000,100,1,12.710000,100,1,14.450000,100,1,12.500000,700,1,14.520000,100,1,12.460000,100,1,14.560000,800,2,12.430000,700,1,14.600000,700,1,12.420000,700,1,14.640000,200,2,ARL,326159041
2025-07-17T16:04:27.791055146Z,2025-07-17T16:04:27.790889618Z,10,2,1108,A,A,3,13.94,2,130,165528,273775264,13.120000,200,2,13.730000,100,1,13.110000,100,1,13.770000,100,1,13.000000,2,1,13.870000,200,2,12.860000,100,1,13.940000,2,1,12.730000,100,1,14.000000,100,1,12.710000,100,1,14.280000,100,1,12.500000,700,1,14.450000,100,1,12.460000,100,1,14.520000,100,1,12.430000,700,1,14.560000,800,2,12.420000,700,1,14.600000,700,1,ARL,328351217
2025-07-17T16:04:31.232053154Z,2025-07-17T16:04:31.231887784Z,10,2,1108,A,A,0,13.68,15,130,165370,273846737,13.120000,200,2,13.680000,15,1,13.110000,100,1,13.730000,100,1,13.000000,2,1,13.770000,100,1,12.860000,100,1,13.870000,200,2,12.730000,100,1,13.940000,2,1,12.710000,100,1,14.000000,100,1,12.500000,700,1,14.280000,100,1,12.460000,100,1,14.450000,100,1,12.430000,700,1,14.520000,100,1,12.420000,700,1,14.560000,800,2,ARL,328437797
2025-07-17T16:04:31.232606440Z,2025-07-17T16:04:31.232440773Z,10,2,1108,A,A,1,13.72,100,130,165667,273846745,13.120000,200,2,13.680000,15,1,13.110000,100,1,13.720000,100,1,13.000000,2,1,13.730000,100,1,12.860000,100,1,13.770000,100,1,12.730000,100,1,13.870000,200,2,12.710000,100,1,13.940000,2,1,12.500000,700,1,14.000000,100,1,12.460000,100,1,14.280000,100,1,12.430000,700,1,14.450000,100,1,12.420000,700,1,14.520000,100,1,ARL,328437805
2025-07-17T16:04:31.246681162Z,2025-07-17T16:04:31.246515467Z,10,2,1108,C,A,3,13.77,100,130,165695,273847000,13.120000,200,2,13.680000,15,1,13.110000,100,1,13.720000,100,1,13.000000,2,1,13.730000,100,1,12.860000,100,1,13.870000,200,2,12.730000,100,1,13.940000,2,1,12.710000,100,1,14.000000,100,1,12.500000,700,1,14.280000,100,1,12.460000,100,1,14.450000,100,1,12.430000,700,1,14.520000,100,1,12.420000,700,1,14.560000,800,2,ARL,328239293
2025-07-17T16:04:32.836802111Z,2025-07-17T16:04:32.836635838Z,10,2,1108,C,A,2,13.73,100,0,166273,273882084,13.120000,200,2,13.680000,15,1,13.110000,100,1,13.720000,100,1,13.000000,2,1,13.870000,200,2,12.860000,100,1,13.940000,2,1,12.730000,100,1,14.000000,100,1,12.710000,100,1,14.280000,100,1,12.500000,700,1,14.450000,100,1,12.460000,100,1,14.520000,100,1,12.430000,700,1,14.560000,800,2,12.420000,700,1,14.600000,700,1,ARL,327864137
2025-07-17T16:04:32.836802111Z,2025-07-17T16:04:32.836635838Z,10,2,1108,A,A,1,13.69,100,130,166273,273882084,13.120000,200,2,13.680000,15,1,13.110000,100,1,13.690000,100,1,13.000000,2,1,13.720000,100,1,12.860000,100,1,13.870000,200,2,12.730000,100,1,13.940000,2,1,12.710000,100,1,14.000000,100,1,12.500000,700,1,14.280000,100,1,12.460000,100,1,14.450000,100,1,12.430000,700,1,14.520000,100,1,12.420000,700,1,14.560000,800,2,ARL,328489153
2025-07-17T16:04:32.837165431Z,2025-07-17T16:04:32.837000154Z,10,2,1108,C,B,0,13.12,100,130,165277,273882201,13.120000,100,1,13.680000,15,1,13.110000,100,1,13.690000,100,1,13.000000,2,1,13.720000,100,1,12.860000,100,1,13.870000,200,2,12.730000,100,1,13.940000,2,1,12.710000,100,1,14.000000,100,1,12.500000,700,1,14.280000,100,1,12.460000,100,1,14.450000,100,1,12.430000,700,1,14.520000,100,1,12.420000,700,1,14.560000,800,2,ARL,325718833
2025-07-17T16:04:32.837169083Z,2025-07-17T16:04:32.837002825Z,10,2,1108,C,B,0,13.12,100,128,166258,273882202,13.110000,100,1,13.680000,15,1,13.000000,2,1,13.690000,100,1,12.860000,100,1,13.720000,100,1,12.730000,100,1,13.870000,200,2,12.710000,100,1,13.940000,2,1,12.500000,700,1,14.000000,100,1,12.460000,100,1,14.280000,100,1,12.430000,700,1,14.450000,100,1,12.420000,700,1,14.520000,100,1,12.370000,700,1,14.560000,800,2,ARL,325718837
2025-07-17T16:04:32.837179568Z,2025-07-17T16:04:32.837013456Z,10,2,1108,A,B,2,12.98,100,130,166112,273882207,13.110000,100,1,13.680000,15,1,13.000000,2,1,13.690000,100,1,12.980000,100,1,13.720000,100,1,12.860000,100,1,13.870000,200,2,12.730000,100,1,13.940000,2,1,12.710000,100,1,14.000000,100,1,12.500000,700,1,14.280000,100,1,12.460000,100,1,14.450000,100,1,12.430000,700,1,14.520000,100,1,12.420000,700,1,14.560000,800,2,ARL,328489377
2025-07-17T16:04:32.837181582Z,2025-07-17T16:04:32.837016087Z,10,2,1108,A,B,2,12.98,100,130,165495,273882208,13.110000,100,1,13.680000,15,1,13.000000,2,1,13.690000,100,1,12.980000,200,2,13.720000,100,1,12.860000,100,1,13.870000,200,2,12.730000,100,1,13.940000,2,1,12.710000,100,1,14.000000,100,1,12.500000,700,1,14.280000,100,1,12.460000,100,1,14.450000,100,1,12.430000,700,1,14.520000,100,1,12.420000,700,1,14.560000,800,2,ARL,328489385
2025-07-17T16:04:32.837536434Z,2025-07-17T16:04:32.837369811Z,10,2,1108,C,A,14,14.79,100,0,166623,273882286,13.110000,100,1,13.680000,15,1,13.000000,2,1,13.690000,100,1,12.980000,200,2,13.720000,100,1,12.860000,100,1,13.870000,200,2,12.730000,100,1,13.940000,2,1,12.710000,100,1,14.000000,100,1,12.500000,700,1,14.280000,100,1,12.460000,100,1,14.450000,100,1,12.430000,700,1,14.520000,100,1,12.420000,700,1,14.560000,800,2,ARL,327864893
2025-07-17T16:04:32.837536434Z,2025-07-17T16:04:32.837369811Z,10,2,1108,A,A,-1,14.75,100,128,166623,273882286,13.110000,100,1,13.680000,15,1,13.000000,2,1,13.690000,100,1,12.980000,200,2,13.720000,100,1,12.860000,100,1,13.870000,200,2,12.730000,100,1,13.940000,2,1,12.710000,100,1,14.000000,100,1,12.500000,700,1,14.280000,100,1,12.460000,100,1,14.450000,100,1,12.430000,700,1,14.520000,100,1,12.420000,700,1,14.560000,800,2,ARL,328489481
2025-07-17T16:04:36.810717146Z,2025-07-17T16:04:36.810551890Z,10,2,1108,A,A,0,13.65,15,130,165256,273963456,13.110000,100,1,13.650000,15,1,13.000000,2,1,13.680000,15,1,12.980000,200,2,13.690000,100,1,12.860000,100,1,13.720000,100,1,12.730000,100,1,13.870000,200,2,12.710000,100,1,13.940000,2,1,12.500000,700,1,14.000000,100,1,12.460000,100,1,14.280000,100,1,12.430000,700,1,14.450000,100,1,12.420000,700,1,14.520000,100,1,ARL,328603377
2025-07-17T16:04:37.026937493Z,2025-07-17T16:04:37.026771973Z,10,2,1108,A,A,2,13.69,100,130,165520,273965417,13.110000,100,1,13.650000,15,1,13.000000,2,1,13.680000,15,1,12.980000,200,2,13.690000,200,2,12.860000,100,1,13.720000,100,1,12.730000,100,1,13.870000,200,2,12.710000,100,1,13.940000,2,1,12.500000,700,1,14.000000,100,1,12.460000,100,1,14.280000,100,1,12.430000,700,1,14.450000,100,1,12.420000,700,1,14.520000,100,1,ARL,328606289
2025-07-17T16:04:37.033554557Z,2025-07-17T16:04:37.033389265Z,10,2,1108,C,A,3,13.72,100,130,165292,273965562,13.110000,100,1,13.650000,15,1,13.000000,2,1,13.680000,15,1,12.980000,200,2,13.690000,200,2,12.860000,100,1,13.870000,200,2,12.730000,100,1,13.940000,2,1,12.710000,100,1,14.000000,100,1,12.500000,700,1,14.280000,100,1,12.460000,100,1,14.450000,100,1,12.430000,700,1,14.520000,100,1,12.420000,700,1,14.560000,800,2,ARL,328437805
2025-07-17T16:04:37.542961161Z,2025-07-17T16:04:37.542795711Z,10,2,1108,C,A,2,13.69,100,0,165450,273971021,13.110000,100,1,13.650000,15,1,13.000000,2,1,13.680000,15,1,12.980000,200,2,13.690000,100,1,12.860000,100,1,13.870000,200,2,12.730000,100,1,13.940000,2,1,12.710000,100,1,14.000000,100,1,12.500000,700,1,14.280000,100,1,12.460000,100,1,14.450000,100,1,12.430000,700,1,14.520000,100,1,12.420000,700,1,14.560000,800,2,ARL,328489153
2025-07-17T16:04:37.542961161Z,2025-07-17T16:04:37.542795711Z,10,2,1108,A,A,1,13.66,100,130,165450,273971021,13.110000,100,1,13.650000,15,1,13.000000,2,1,13.660000,100,1,12.980000,200,2,13.680000,15,1,12.860000,100,1,13.690000,100,1,12.730000,100,1,13.870000,200,2,12.710000,100,1,13.940000,2,1,12.500000,700,1,14.000000,100,1,12.460000,100,1,14.280000,100,1,12.430000,700,1,14.450000,100,1,12.420000,700,1,14.520000,100,1,ARL,328614509
2025-07-17T16:04:37.543230680Z,2025-07-17T16:04:37.543063240Z,10,2,1108,C,A,4,13.87,100,0,167440,273971035,13.110000,100,1,13.650000,15,1,13.000000,2,1,13.660000,100,1,12.980000,200,2,13.680000,15,1,12.860000,100,1,13.690000,100,1,12.730000,100,1,13.870000,100,1,12.710000,100,1,13.940000,2,1,12.500000,700,1,14.000000,100,1,12.460000,100,1,14.280000,100,1,12.430000,700,1,14.450000,100,1,12.420000,700,1,14.520000,100,1,ARL,326730517
2025-07-17T16:04:37.543230680Z,2025-07-17T16:04:37.543064690Z,10,2,1108,C,A,4,13.87,100,130,165990,273971037,13.110000,100,1,13.650000,15,1,13.000000,2,1,13.660000,100,1,12.980000,200,2,13.680000,15,1,12.860000,100,1,13.690000,100,1,12.730000,100,1,13.940000,2,1,12.710000,100,1,14.000000,100,1,12.500000,700,1,14.280000,100,1,12.460000,100,1,14.450000,100,1,12.430000,700,1,14.520000,100,1,12.420000,700,1,14.560000,800,2,ARL,326730521
2025-07-17T16:04:37.543242390Z,2025-07-17T16:04:37.543077174Z,10,2,1108,A,A,4,13.80,100,130,165216,273971040,13.110000,100,1,13.650000,15,1,13.000000,2,1,13.660000,100,1,12.980000,200,2,13.680000,15,1,12.860000,100,1,13.690000,100,1,12.730000,100,1,13.800000,100,1,12.710000,100,1,13.940000,2,1,12.500000,700,1,14.000000,100,1,12.460000,100,1,14.280000,100,1,12.430000,700,1,14.450000,100,1,12.420000,700,1,14.520000,100,1,ARL,328614525
2025-07-17T16:04:37.543244193Z,2025-07-17T16:04:37.543078532Z,10,2,1108,A,A,4,13.80,100,130,165661,273971041,13.110000,100,1,13.650000,15,1,13.000000,2,1,13.660000,100,1,12.980000,200,2,13.680000,15,1,12.860000,100,1,13.690000,100,1,12.730000,100,1,13.800000,200,2,12.710000,100,1,13.940000,2,1,12.500000,700,1,14.000000,100,1,12.460000,100,1,14.280000,100,1,12.430000,700,1,14.450000,100,1,12.420000,700,1,14.520000,100,1,ARL,328614529
2025-07-17T16:04:37.549684713Z,2025-07-17T16:04:37.549519006Z,10,2,1108,C,A,6,14.00,100,130,165707,273973481,13.110000,100,1,13.650000,15,1,13.000000,2,1,13.660000,100,1,12.980000,200,2,13.680000,15,1,12.860000,100,1,13.690000,100,1,12.730000,100,1,13.800000,200,2,12.710000,100,1,13.940000,2,1,12.500000,700,1,14.280000,100,1,12.460000,100,1,14.450000,100,1,12.430000,700,1,14.520000,100,1,12.420000,700,1,14.560000,800,2,ARL,327869193
2025-07-17T16:04:37.549735824Z,2025-07-17T16:04:37.549570649Z,10,2,1108,A,A,5,13.93,100,130,165175,273973485,13.110000,100,1,13.650000,15,1,13.000000,2,1,13.660000,100,1,12.980000,200,2,13.680000,15,1,12.860000,100,1,13.690000,100,1,12.730000,100,1,13.800000,200,2,12.710000,100,1,13.930000,100,1,12.500000,700,1,13.940000,2,1,12.460000,100,1,14.280000,100,1,12.430000,700,1,14.450000,100,1,12.420000,700,1,14.520000,100,1,ARL,328616925
2025-07-17T16:04:44.524526545Z,2025-07-17T16:04:44.524360626Z,10,2,1108,C,A,2,13.68,15,130,165919,274066152,13.110000,100,1,13.650000,15,1,13.000000,2,1,13.660000,100,1,12.980000,200,2,13.690000,100,1,12.860000,100,1,13.800000,200,2,12.730000,100,1,13.930000,100,1,12.710000,100,1,13.940000,2,1,12.500000,700,1,14.280000,100,1,12.460000,100,1,14.450000,100,1,12.430000,700,1,14.520000,100,1,12.420000,700,1,14.560000,800,2,ARL,328437797
2025-07-17T16:04:45.528000143Z,2025-07-17T16:04:45.527835033Z,10,2,1108,A,A,0,13.63,15,130,165110,274088918,13.110000,100,1,13.630000,15,1,13.000000,2,1,13.650000,15,1,12.980000,200,2,13.660000,100,1,12.860000,100,1,13.690000,100,1,12.730000,100,1,13.800000,200,2,12.710000,100,1,13.930000,100,1,12.500000,700,1,13.940000,2,1,12.460000,100,1,14.280000,100,1,12.430000,700,1,14.450000,100,1,12.420000,700,1,14.520000,100,1,ARL,328780565
