ts_recv,ts_event,rtype,publisher_id,instrument_id,action,side,depth,price,size,flags,ts_in_delta,sequence,bid_px_00,bid_sz_00,bid_ct_00,ask_px_00,ask_sz_00,ask_ct_00,bid_px_01,bid_sz_01,bid_ct_01,ask_px_01,ask_sz_01,ask_ct_01,bid_px_02,bid_sz_02,bid_ct_02,ask_px_02,ask_sz_02,ask_ct_02,bid_px_03,bid_sz_03,bid_ct_03,ask_px_03,ask_sz_03,ask_ct_03,bid_px_04,bid_sz_04,bid_ct_04,ask_px_04,ask_sz_04,ask_ct_04,bid_px_05,bid_sz_05,bid_ct_05,ask_px_05,ask_sz_05,ask_ct_05,bid_px_06,bid_sz_06,bid_ct_06,ask_px_06,ask_sz_06,ask_ct_06,bid_px_07,bid_sz_07,bid_ct_07,ask_px_07,ask_sz_07,ask_ct_07,bid_px_08,bid_sz_08,bid_ct_08,ask_px_08,ask_sz_08,ask_ct_08,bid_px_09,bid_sz_09,bid_ct_09,ask_px_09,ask_sz_09,ask_ct_09,symbol,order_id
2025-07-17T16:04:45.528629613Z,2025-07-17T16:04:45.528464092Z,10,2,1108,C,A,12,14.64,100,0,165521,274088922,13.110000,100,1,13.630000,15,1,13.000000,2,1,13.650000,15,1,12.980000,200,2,13.660000,100,1,12.860000,100,1,13.690000,100,1,12.730000,100,1,13.800000,200,2,12.710000,100,1,13.930000,100,1,12.500000,700,1,13.940000,2,1,12.460000,100,1,14.280000,100,1,12.430000,700,1,14.450000,100,1,12.420000,700,1,14.520000,100,1,ARL,327856309
2025-07-17T16:04:45.528629613Z,2025-07-17T16:04:45.528464092Z,10,2,1108,A,A,9,14.52,100,130,165521,274088922,13.110000,100,1,13.630000,15,1,13.000000,2,1,13.650000,15,1,12.980000,200,2,13.660000,100,1,12.860000,100,1,13.690000,100,1,12.730000,100,1,13.800000,200,2,12.710000,100,1,13.930000,100,1,12.500000,700,1,13.940000,2,1,12.460000,100,1,14.280000,100,1,12.430000,700,1,14.450000,100,1,12.420000,700,1,14.520000,200,2,ARL,328780577
2025-07-17T16:04:45.530418278Z,2025-07-17T16:04:45.530252804Z,10,2,1108,C,A,12,14.64,100,0,165474,274088937,13.110000,100,1,13.630000,15,1,13.000000,2,1,13.650000,15,1,12.980000,200,2,13.660000,100,1,12.860000,100,1,13.690000,100,1,12.730000,100,1,13.800000,200,2,12.710000,100,1,13.930000,100,1,12.500000,700,1,13.940000,2,1,12.460000,100,1,14.280000,100,1,12.430000,700,1,14.450000,100,1,12.420000,700,1,14.520000,200,2,ARL,327856297
2025-07-17T16:04:45.530418278Z,2025-07-17T16:04:45.530252804Z,10,2,1108,A,A,9,14.52,100,130,165474,274088937,13.110000,100,1,13.630000,15,1,13.000000,2,1,13.650000,15,1,12.980000,200,2,13.660000,100,1,12.860000,100,1,13.690000,100,1,12.730000,100,1,13.800000,200,2,12.710000,100,1,13.930000,100,1,12.500000,700,1,13.940000,2,1,12.460000,100,1,14.280000,100,1,12.430000,700,1,14.450000,100,1,12.420000,700,1,14.520000,300,3,ARL,328780597
2025-07-17T16:04:45.533067029Z,2025-07-17T16:04:45.532901874Z,10,2,1108,C,A,2,13.66,100,0,165155,274088955,13.110000,100,1,13.630000,15,1,13.000000,2,1,13.650000,15,1,12.980000,200,2,13.690000,100,1,12.860000,100,1,13.800000,200,2,12.730000,100,1,13.930000,100,1,12.710000,100,1,13.940000,2,1,12.500000,700,1,14.280000,100,1,12.460000,100,1,14.450000,100,1,12.430000,700,1,14.520000,300,3,12.420000,700,1,14.560000,800,2,ARL,328614509
2025-07-17T16:04:45.533067029Z,2025-07-17T16:04:45.532901874Z,10,2,1108,A,A,1,13.64,100,130,165155,274088955,13.110000,100,1,13.630000,15,1,13.000000,2,1,13.640000,100,1,12.980000,200,2,13.650000,15,1,12.860000,100,1,13.690000,100,1,12.730000,100,1,13.800000,200,2,12.710000,100,1,13.930000,100,1,12.500000,700,1,13.940000,2,1,12.460000,100,1,14.280000,100,1,12.430000,700,1,14.450000,100,1,12.420000,700,1,14.520000,300,3,ARL,328780669
2025-07-17T16:04:45.533804768Z,2025-07-17T16:04:45.533639142Z,10,2,1108,C,A,14,14.75,100,0,165626,274088957,13.110000,100,1,13.630000,15,1,13.000000,2,1,13.640000,100,1,12.980000,200,2,13.650000,15,1,12.860000,100,1,13.690000,100,1,12.730000,100,1,13.800000,200,2,12.710000,100,1,13.930000,100,1,12.500000,700,1,13.940000,2,1,12.460000,100,1,14.280000,100,1,12.430000,700,1,14.450000,100,1,12.420000,700,1,14.520000,300,3,ARL,328489481
2025-07-17T16:04:45.533804768Z,2025-07-17T16:04:45.533639142Z,10,2,1108,A,A,-1,14.70,100,130,165626,274088957,13.110000,100,1,13.630000,15,1,13.000000,2,1,13.640000,100,1,12.980000,200,2,13.650000,15,1,12.860000,100,1,13.690000,100,1,12.730000,100,1,13.800000,200,2,12.710000,100,1,13.930000,100,1,12.500000,700,1,13.940000,2,1,12.460000,100,1,14.280000,100,1,12.430000,700,1,14.450000,100,1,12.420000,700,1,14.520000,300,3,ARL,328780685
2025-07-17T16:04:45.533870711Z,2025-07-17T16:04:45.533705428Z,10,2,1108,A,A,3,13.67,100,130,165283,274088959,13.110000,100,1,13.630000,15,1,13.000000,2,1,13.640000,100,1,12.980000,200,2,13.650000,15,1,12.860000,100,1,13.670000,100,1,12.730000,100,1,13.690000,100,1,12.710000,100,1,13.800000,200,2,12.500000,700,1,13.930000,100,1,12.460000,100,1,13.940000,2,1,12.430000,700,1,14.280000,100,1,12.420000,700,1,14.450000,100,1,ARL,328780689
2025-07-17T16:04:45.563137443Z,2025-07-17T16:04:45.562972204Z,10,2,1108,C,A,4,13.69,100,130,165239,274089319,13.110000,100,1,13.630000,15,1,13.000000,2,1,13.640000,100,1,12.980000,200,2,13.650000,15,1,12.860000,100,1,13.670000,100,1,12.730000,100,1,13.800000,200,2,12.710000,100,1,13.930000,100,1,12.500000,700,1,13.940000,2,1,12.460000,100,1,14.280000,100,1,12.430000,700,1,14.450000,100,1,12.420000,700,1,14.520000,300,3,ARL,328606289
2025-07-17T16:04:56.809749973Z,2025-07-17T16:04:56.809584701Z,10,2,1108,C,A,2,13.65,15,130,165272,274293432,13.110000,100,1,13.630000,15,1,13.000000,2,1,13.640000,100,1,12.980000,200,2,13.670000,100,1,12.860000,100,1,13.800000,200,2,12.730000,100,1,13.930000,100,1,12.710000,100,1,13.940000,2,1,12.500000,700,1,14.280000,100,1,12.460000,100,1,14.450000,100,1,12.430000,700,1,14.520000,300,3,12.420000,700,1,14.560000,800,2,ARL,328603377
2025-07-17T16:04:57.827079009Z,2025-07-17T16:04:57.826913717Z,10,2,1108,A,A,0,13.61,15,130,165292,274310244,13.110000,100,1,13.610000,15,1,13.000000,2,1,13.630000,15,1,12.980000,200,2,13.640000,100,1,12.860000,100,1,13.670000,100,1,12.730000,100,1,13.800000,200,2,12.710000,100,1,13.930000,100,1,12.500000,700,1,13.940000,2,1,12.460000,100,1,14.280000,100,1,12.430000,700,1,14.450000,100,1,12.420000,700,1,14.520000,300,3,ARL,329068341
2025-07-17T16:04:57.970616610Z,2025-07-17T16:04:57.970451236Z,10,2,1108,C,A,2,13.64,100,0,165374,274316281,13.110000,100,1,13.610000,15,1,13.000000,2,1,13.630000,15,1,12.980000,200,2,13.670000,100,1,12.860000,100,1,13.800000,200,2,12.730000,100,1,13.930000,100,1,12.710000,100,1,13.940000,2,1,12.500000,700,1,14.280000,100,1,12.460000,100,1,14.450000,100,1,12.430000,700,1,14.520000,300,3,12.420000,700,1,14.560000,800,2,ARL,328780669
2025-07-17T16:04:57.970616610Z,2025-07-17T16:04:57.970451236Z,10,2,1108,A,A,1,13.62,100,130,165374,274316281,13.110000,100,1,13.610000,15,1,13.000000,2,1,13.620000,100,1,12.980000,200,2,13.630000,15,1,12.860000,100,1,13.670000,100,1,12.730000,100,1,13.800000,200,2,12.710000,100,1,13.930000,100,1,12.500000,700,1,13.940000,2,1,12.460000,100,1,14.280000,100,1,12.430000,700,1,14.450000,100,1,12.420000,700,1,14.520000,300,3,ARL,329074609
2025-07-17T16:04:57.971360344Z,2025-07-17T16:04:57.971193734Z,10,2,1108,C,A,8,14.45,100,128,166610,274316507,13.110000,100,1,13.610000,15,1,13.000000,2,1,13.620000,100,1,12.980000,200,2,13.630000,15,1,12.860000,100,1,13.670000,100,1,12.730000,100,1,13.800000,200,2,12.710000,100,1,13.930000,100,1,12.500000,700,1,13.940000,2,1,12.460000,100,1,14.280000,100,1,12.430000,700,1,14.520000,300,3,12.420000,700,1,14.560000,800,2,ARL,325714601
2025-07-17T16:04:57.971717511Z,2025-07-17T16:04:57.971552262Z,10,2,1108,A,A,7,14.23,100,130,165249,274316527,13.110000,100,1,13.610000,15,1,13.000000,2,1,13.620000,100,1,12.980000,200,2,13.630000,15,1,12.860000,100,1,13.670000,100,1,12.730000,100,1,13.800000,200,2,12.710000,100,1,13.930000,100,1,12.500000,700,1,13.940000,2,1,12.460000,100,1,14.230000,100,1,12.430000,700,1,14.280000,100,1,12.420000,700,1,14.520000,300,3,ARL,329074833
2025-07-17T16:04:57.992131878Z,2025-07-17T16:04:57.991966904Z,10,2,1108,C,A,0,13.61,15,130,164974,274318490,13.110000,100,1,13.620000,100,1,13.000000,2,1,13.630000,15,1,12.980000,200,2,13.670000,100,1,12.860000,100,1,13.800000,200,2,12.730000,100,1,13.930000,100,1,12.710000,100,1,13.940000,2,1,12.500000,700,1,14.230000,100,1,12.460000,100,1,14.280000,100,1,12.430000,700,1,14.520000,300,3,12.420000,700,1,14.560000,800,2,ARL,329068341
2025-07-17T16:04:57.993141438Z,2025-07-17T16:04:57.992976406Z,10,2,1108,C,A,0,13.62,100,130,165032,274318579,13.110000,100,1,13.630000,15,1,13.000000,2,1,13.670000,100,1,12.980000,200,2,13.800000,200,2,12.860000,100,1,13.930000,100,1,12.730000,100,1,13.940000,2,1,12.710000,100,1,14.230000,100,1,12.500000,700,1,14.280000,100,1,12.460000,100,1,14.520000,300,3,12.430000,700,1,14.560000,800,2,12.420000,700,1,14.600000,700,1,ARL,329074609
2025-07-17T16:04:57.993309561Z,2025-07-17T16:04:57.993143873Z,10,2,1108,C,A,0,13.63,15,130,165688,274318603,13.110000,100,1,13.670000,100,1,13.000000,2,1,13.800000,200,2,12.980000,200,2,13.930000,100,1,12.860000,100,1,13.940000,2,1,12.730000,100,1,14.230000,100,1,12.710000,100,1,14.280000,100,1,12.500000,700,1,14.520000,300,3,12.460000,100,1,14.560000,800,2,12.430000,700,1,14.600000,700,1,12.420000,700,1,14.680000,1400,2,ARL,328780565
2025-07-17T16:04:58.002259715Z,2025-07-17T16:04:58.002094377Z,10,2,1108,C,A,0,13.67,100,130,165338,274319058,13.110000,100,1,13.800000,200,2,13.000000,2,1,13.930000,100,1,12.980000,200,2,13.940000,2,1,12.860000,100,1,14.230000,100,1,12.730000,100,1,14.280000,100,1,12.710000,100,1,14.520000,300,3,12.500000,700,1,14.560000,800,2,12.460000,100,1,14.600000,700,1,12.430000,700,1,14.680000,1400,2,12.420000,700,1,14.700000,300,3,ARL,328780689
2025-07-17T16:04:58.002989430Z,2025-07-17T16:04:58.002823841Z,10,2,1108,C,A,9,14.70,100,0,165589,274319069,13.110000,100,1,13.800000,200,2,13.000000,2,1,13.930000,100,1,12.980000,200,2,13.940000,2,1,12.860000,100,1,14.230000,100,1,12.730000,100,1,14.280000,100,1,12.710000,100,1,14.520000,300,3,12.500000,700,1,14.560000,800,2,12.460000,100,1,14.600000,700,1,12.430000,700,1,14.680000,1400,2,12.420000,700,1,14.700000,200,2,ARL,328780685
2025-07-17T16:04:58.002989430Z,2025-07-17T16:04:58.002823841Z,10,2,1108,A,A,-1,14.87,100,130,165589,274319069,13.110000,100,1,13.800000,200,2,13.000000,2,1,13.930000,100,1,12.980000,200,2,13.940000,2,1,12.860000,100,1,14.230000,100,1,12.730000,100,1,14.280000,100,1,12.710000,100,1,14.520000,300,3,12.500000,700,1,14.560000,800,2,12.460000,100,1,14.600000,700,1,12.430000,700,1,14.680000,1400,2,12.420000,700,1,14.700000,200,2,ARL,329078553
2025-07-17T16:04:58.013904697Z,2025-07-17T16:04:58.013739242Z,10,2,1108,C,A,1,13.93,100,130,165455,274319298,13.110000,100,1,13.800000,200,2,13.000000,2,1,13.940000,2,1,12.980000,200,2,14.230000,100,1,12.860000,100,1,14.280000,100,1,12.730000,100,1,14.520000,300,3,12.710000,100,1,14.560000,800,2,12.500000,700,1,14.600000,700,1,12.460000,100,1,14.680000,1400,2,12.430000,700,1,14.700000,200,2,12.420000,700,1,14.870000,100,1,ARL,328616925
2025-07-17T16:04:58.013959233Z,2025-07-17T16:04:58.013793974Z,10,2,1108,A,A,2,14.08,100,130,165259,274319304,13.110000,100,1,13.800000,200,2,13.000000,2,1,13.940000,2,1,12.980000,200,2,14.080000,100,1,12.860000,100,1,14.230000,100,1,12.730000,100,1,14.280000,100,1,12.710000,100,1,14.520000,300,3,12.500000,700,1,14.560000,800,2,12.460000,100,1,14.600000,700,1,12.430000,700,1,14.680000,1400,2,12.420000,700,1,14.700000,200,2,ARL,329078953
2025-07-17T16:04:58.536617917Z,2025-07-17T16:04:58.536452621Z,10,2,1108,A,A,1,13.81,100,130,165296,274326535,13.110000,100,1,13.800000,200,2,13.000000,2,1,13.810000,100,1,12.980000,200,2,13.940000,2,1,12.860000,100,1,14.080000,100,1,12.730000,100,1,14.230000,100,1,12.710000,100,1,14.280000,100,1,12.500000,700,1,14.520000,300,3,12.460000,100,1,14.560000,800,2,12.430000,700,1,14.600000,700,1,12.420000,700,1,14.680000,1400,2,ARL,329088265
2025-07-17T16:05:46.594131664Z,2025-07-17T16:05:46.593966383Z,10,2,1108,A,A,0,13.76,100,130,165281,275083968,13.110000,100,1,13.760000,100,1,13.000000,2,1,13.800000,200,2,12.980000,200,2,13.810000,100,1,12.860000,100,1,13.940000,2,1,12.730000,100,1,14.080000,100,1,12.710000,100,1,14.230000,100,1,12.500000,700,1,14.280000,100,1,12.460000,100,1,14.520000,300,3,12.430000,700,1,14.560000,800,2,12.420000,700,1,14.600000,700,1,ARL,330066537
2025-07-17T16:05:46.594871336Z,2025-07-17T16:05:46.594705962Z,10,2,1108,C,A,12,14.87,100,0,165374,275083970,13.110000,100,1,13.760000,100,1,13.000000,2,1,13.800000,200,2,12.980000,200,2,13.810000,100,1,12.860000,100,1,13.940000,2,1,12.730000,100,1,14.080000,100,1,12.710000,100,1,14.230000,100,1,12.500000,700,1,14.280000,100,1,12.460000,100,1,14.520000,300,3,12.430000,700,1,14.560000,800,2,12.420000,700,1,14.600000,700,1,ARL,329078553
2025-07-17T16:05:46.594871336Z,2025-07-17T16:05:46.594705962Z,10,2,1108,A,A,-1,14.83,100,130,165374,275083970,13.110000,100,1,13.760000,100,1,13.000000,2,1,13.800000,200,2,12.980000,200,2,13.810000,100,1,12.860000,100,1,13.940000,2,1,12.730000,100,1,14.080000,100,1,12.710000,100,1,14.230000,100,1,12.500000,700,1,14.280000,100,1,12.460000,100,1,14.520000,300,3,12.430000,700,1,14.560000,800,2,12.420000,700,1,14.600000,700,1,ARL,330066553
2025-07-17T16:05:46.996003552Z,2025-07-17T16:05:46.995837526Z,10,2,1108,C,A,2,13.81,100,0,166026,275092978,13.110000,100,1,13.760000,100,1,13.000000,2,1,13.800000,200,2,12.980000,200,2,13.940000,2,1,12.860000,100,1,14.080000,100,1,12.730000,100,1,14.230000,100,1,12.710000,100,1,14.280000,100,1,12.500000,700,1,14.520000,300,3,12.460000,100,1,14.560000,800,2,12.430000,700,1,14.600000,700,1,12.420000,700,1,14.680000,1400,2,ARL,329088265
2025-07-17T16:05:46.996003552Z,2025-07-17T16:05:46.995837526Z,10,2,1108,A,A,1,13.77,100,130,166026,275092978,13.110000,100,1,13.760000,100,1,13.000000,2,1,13.770000,100,1,12.980000,200,2,13.800000,200,2,12.860000,100,1,13.940000,2,1,12.730000,100,1,14.080000,100,1,12.710000,100,1,14.230000,100,1,12.500000,700,1,14.280000,100,1,12.460000,100,1,14.520000,300,3,12.430000,700,1,14.560000,800,2,12.420000,700,1,14.600000,700,1,ARL,330075425
2025-07-17T16:05:50.680333151Z,2025-07-17T16:05:50.680167632Z,10,2,1108,A,A,0,13.68,15,130,165519,275152014,13.110000,100,1,13.680000,15,1,13.000000,2,1,13.760000,100,1,12.980000,200,2,13.770000,100,1,12.860000,100,1,13.800000,200,2,12.730000,100,1,13.940000,2,1,12.710000,100,1,14.080000,100,1,12.500000,700,1,14.230000,100,1,12.460000,100,1,14.280000,100,1,12.430000,700,1,14.520000,300,3,12.420000,700,1,14.560000,800,2,ARL,330143813
2025-07-17T16:05:50.697170320Z,2025-07-17T16:05:50.697005084Z,10,2,1108,A,A,1,13.72,100,130,165236,275152383,13.110000,100,1,13.680000,15,1,13.000000,2,1,13.720000,100,1,12.980000,200,2,13.760000,100,1,12.860000,100,1,13.770000,100,1,12.730000,100,1,13.800000,200,2,12.710000,100,1,13.940000,2,1,12.500000,700,1,14.080000,100,1,12.460000,100,1,14.230000,100,1,12.430000,700,1,14.280000,100,1,12.420000,700,1,14.520000,300,3,ARL,330144301
2025-07-17T16:05:50.697905372Z,2025-07-17T16:05:50.697739933Z,10,2,1108,C,A,14,14.83,100,0,165439,275152385,13.110000,100,1,13.680000,15,1,13.000000,2,1,13.720000,100,1,12.980000,200,2,13.760000,100,1,12.860000,100,1,13.770000,100,1,12.730000,100,1,13.800000,200,2,12.710000,100,1,13.940000,2,1,12.500000,700,1,14.080000,100,1,12.460000,100,1,14.230000,100,1,12.430000,700,1,14.280000,100,1,12.420000,700,1,14.520000,300,3,ARL,330066553
2025-07-17T16:05:50.697905372Z,2025-07-17T16:05:50.697739933Z,10,2,1108,A,A,-1,14.78,100,130,165439,275152385,13.110000,100,1,13.680000,15,1,13.000000,2,1,13.720000,100,1,12.980000,200,2,13.760000,100,1,12.860000,100,1,13.770000,100,1,12.730000,100,1,13.800000,200,2,12.710000,100,1,13.940000,2,1,12.500000,700,1,14.080000,100,1,12.460000,100,1,14.230000,100,1,12.430000,700,1,14.280000,100,1,12.420000,700,1,14.520000,300,3,ARL,330144321
2025-07-17T16:05:50.704531748Z,2025-07-17T16:05:50.704366332Z,10,2,1108,C,A,2,13.76,100,130,165416,275152443,13.110000,100,1,13.680000,15,1,13.000000,2,1,13.720000,100,1,12.980000,200,2,13.770000,100,1,12.860000,100,1,13.800000,200,2,12.730000,100,1,13.940000,2,1,12.710000,100,1,14.080000,100,1,12.500000,700,1,14.230000,100,1,12.460000,100,1,14.280000,100,1,12.430000,700,1,14.520000,300,3,12.420000,700,1,14.560000,800,2,ARL,330066537
2025-07-17T16:05:50.708879311Z,2025-07-17T16:05:50.708714027Z,10,2,1108,C,A,5,14.08,100,130,165284,275152465,13.110000,100,1,13.680000,15,1,13.000000,2,1,13.720000,100,1,12.980000,200,2,13.770000,100,1,12.860000,100,1,13.800000,200,2,12.730000,100,1,13.940000,2,1,12.710000,100,1,14.230000,100,1,12.500000,700,1,14.280000,100,1,12.460000,100,1,14.520000,300,3,12.430000,700,1,14.560000,800,2,12.420000,700,1,14.600000,700,1,ARL,329078953
2025-07-17T16:05:50.708931189Z,2025-07-17T16:05:50.708766050Z,10,2,1108,A,A,5,13.99,100,130,165139,275152466,13.110000,100,1,13.680000,15,1,13.000000,2,1,13.720000,100,1,12.980000,200,2,13.770000,100,1,12.860000,100,1,13.800000,200,2,12.730000,100,1,13.940000,2,1,12.710000,100,1,13.990000,100,1,12.500000,700,1,14.230000,100,1,12.460000,100,1,14.280000,100,1,12.430000,700,1,14.520000,300,3,12.420000,700,1,14.560000,800,2,ARL,330144513
2025-07-17T16:05:50.913476268Z,2025-07-17T16:05:50.913310799Z,10,2,1108,C,A,2,13.77,100,0,165469,275159685,13.110000,100,1,13.680000,15,1,13.000000,2,1,13.720000,100,1,12.980000,200,2,13.800000,200,2,12.860000,100,1,13.940000,2,1,12.730000,100,1,13.990000,100,1,12.710000,100,1,14.230000,100,1,12.500000,700,1,14.280000,100,1,12.460000,100,1,14.520000,300,3,12.430000,700,1,14.560000,800,2,12.420000,700,1,14.600000,700,1,ARL,330075425
2025-07-17T16:05:50.913476268Z,2025-07-17T16:05:50.913310799Z,10,2,1108,A,A,1,13.69,100,130,165469,275159685,13.110000,100,1,13.680000,15,1,13.000000,2,1,13.690000,100,1,12.980000,200,2,13.720000,100,1,12.860000,100,1,13.800000,200,2,12.730000,100,1,13.940000,2,1,12.710000,100,1,13.990000,100,1,12.500000,700,1,14.230000,100,1,12.460000,100,1,14.280000,100,1,12.430000,700,1,14.520000,300,3,12.420000,700,1,14.560000,800,2,ARL,330151389
2025-07-17T16:05:59.704955970Z,2025-07-17T16:05:59.704790753Z,10,2,1108,A,A,0,13.64,15,130,165217,275325555,13.110000,100,1,13.640000,15,1,13.000000,2,1,13.680000,15,1,12.980000,200,2,13.690000,100,1,12.860000,100,1,13.720000,100,1,12.730000,100,1,13.800000,200,2,12.710000,100,1,13.940000,2,1,12.500000,700,1,13.990000,100,1,12.460000,100,1,14.230000,100,1,12.430000,700,1,14.280000,100,1,12.420000,700,1,14.520000,300,3,ARL,330357473
2025-07-17T16:05:59.715090662Z,2025-07-17T16:05:59.714925412Z,10,2,1108,A,A,1,13.68,100,130,165250,275325807,13.110000,100,1,13.640000,15,1,13.000000,2,1,13.680000,115,2,12.980000,200,2,13.690000,100,1,12.860000,100,1,13.720000,100,1,12.730000,100,1,13.800000,200,2,12.710000,100,1,13.940000,2,1,12.500000,700,1,13.990000,100,1,12.460000,100,1,14.230000,100,1,12.430000,700,1,14.280000,100,1,12.420000,700,1,14.520000,300,3,ARL,330357633
2025-07-17T16:05:59.722895750Z,2025-07-17T16:05:59.722730507Z,10,2,1108,C,A,3,13.72,100,130,165243,275325854,13.110000,100,1,13.640000,15,1,13.000000,2,1,13.680000,115,2,12.980000,200,2,13.690000,100,1,12.860000,100,1,13.800000,200,2,12.730000,100,1,13.940000,2,1,12.710000,100,1,13.990000,100,1,12.500000,700,1,14.230000,100,1,12.460000,100,1,14.280000,100,1,12.430000,700,1,14.520000,300,3,12.420000,700,1,14.560000,800,2,ARL,330144301
2025-07-17T16:05:59.802762087Z,2025-07-17T16:05:59.802596747Z,10,2,1108,C,A,2,13.69,100,0,165340,275327082,13.110000,100,1,13.640000,15,1,13.000000,2,1,13.680000,115,2,12.980000,200,2,13.800000,200,2,12.860000,100,1,13.940000,2,1,12.730000,100,1,13.990000,100,1,12.710000,100,1,14.230000,100,1,12.500000,700,1,14.280000,100,1,12.460000,100,1,14.520000,300,3,12.430000,700,1,14.560000,800,2,12.420000,700,1,14.600000,700,1,ARL,330151389
2025-07-17T16:05:59.802762087Z,2025-07-17T16:05:59.802596747Z,10,2,1108,A,A,1,13.65,100,130,165340,275327082,13.110000,100,1,13.640000,15,1,13.000000,2,1,13.650000,100,1,12.980000,200,2,13.680000,115,2,12.860000,100,1,13.800000,200,2,12.730000,100,1,13.940000,2,1,12.710000,100,1,13.990000,100,1,12.500000,700,1,14.230000,100,1,12.460000,100,1,14.280000,100,1,12.430000,700,1,14.520000,300,3,12.420000,700,1,14.560000,800,2,ARL,330359197
2025-07-17T16:05:59.803504658Z,2025-07-17T16:05:59.803338996Z,10,2,1108,C,A,13,14.78,100,0,165662,275327093,13.110000,100,1,13.640000,15,1,13.000000,2,1,13.650000,100,1,12.980000,200,2,13.680000,115,2,12.860000,100,1,13.800000,200,2,12.730000,100,1,13.940000,2,1,12.710000,100,1,13.990000,100,1,12.500000,700,1,14.230000,100,1,12.460000,100,1,14.280000,100,1,12.430000,700,1,14.520000,300,3,12.420000,700,1,14.560000,800,2,ARL,330144321
2025-07-17T16:05:59.803504658Z,2025-07-17T16:05:59.803338996Z,10,2,1108,A,A,-1,14.71,100,130,165662,275327093,13.110000,100,1,13.640000,15,1,13.000000,2,1,13.650000,100,1,12.980000,200,2,13.680000,115,2,12.860000,100,1,13.800000,200,2,12.730000,100,1,13.940000,2,1,12.710000,100,1,13.990000,100,1,12.500000,700,1,14.230000,100,1,12.460000,100,1,14.280000,100,1,12.430000,700,1,14.520000,300,3,12.420000,700,1,14.560000,800,2,ARL,330359225
2025-07-17T16:05:59.827787837Z,2025-07-17T16:05:59.827622529Z,10,2,1108,C,A,5,13.99,100,130,165308,275327416,13.110000,100,1,13.640000,15,1,13.000000,2,1,13.650000,100,1,12.980000,200,2,13.680000,115,2,12.860000,100,1,13.800000,200,2,12.730000,100,1,13.940000,2,1,12.710000,100,1,14.230000,100,1,12.500000,700,1,14.280000,100,1,12.460000,100,1,14.520000,300,3,12.430000,700,1,14.560000,800,2,12.420000,700,1,14.600000,700,1,ARL,330144513
2025-07-17T16:05:59.827839802Z,2025-07-17T16:05:59.827674437Z,10,2,1108,A,A,4,13.92,100,130,165365,275327417,13.110000,100,1,13.640000,15,1,13.000000,2,1,13.650000,100,1,12.980000,200,2,13.680000,115,2,12.860000,100,1,13.800000,200,2,12.730000,100,1,13.920000,100,1,12.710000,100,1,13.940000,2,1,12.500000,700,1,14.230000,100,1,12.460000,100,1,14.280000,100,1,12.430000,700,1,14.520000,300,3,12.420000,700,1,14.560000,800,2,ARL,330359625
2025-07-17T16:06:02.724446337Z,2025-07-17T16:06:02.724280161Z,10,2,1108,C,A,2,13.68,15,128,166176,275430576,13.110000,100,1,13.640000,15,1,13.000000,2,1,13.650000,100,1,12.980000,200,2,13.680000,100,1,12.860000,100,1,13.800000,200,2,12.730000,100,1,13.920000,100,1,12.710000,100,1,13.940000,2,1,12.500000,700,1,14.230000,100,1,12.460000,100,1,14.280000,100,1,12.430000,700,1,14.520000,300,3,12.420000,700,1,14.560000,800,2,ARL,330143813
2025-07-17T16:06:03.729377770Z,2025-07-17T16:06:03.729212428Z,10,2,1108,A,A,0,13.62,15,130,165342,275517342,13.110000,100,1,13.620000,15,1,13.000000,2,1,13.640000,15,1,12.980000,200,2,13.650000,100,1,12.860000,100,1,13.680000,100,1,12.730000,100,1,13.800000,200,2,12.710000,100,1,13.920000,100,1,12.500000,700,1,13.940000,2,1,12.460000,100,1,14.230000,100,1,12.430000,700,1,14.280000,100,1,12.420000,700,1,14.520000,300,3,ARL,330577045
2025-07-17T16:06:03.738497645Z,2025-07-17T16:06:03.738332427Z,10,2,1108,A,A,2,13.65,100,130,165218,275517997,13.110000,100,1,13.620000,15,1,13.000000,2,1,13.640000,15,1,12.980000,200,2,13.650000,200,2,12.860000,100,1,13.680000,100,1,12.730000,100,1,13.800000,200,2,12.710000,100,1,13.920000,100,1,12.500000,700,1,13.940000,2,1,12.460000,100,1,14.230000,100,1,12.430000,700,1,14.280000,100,1,12.420000,700,1,14.520000,300,3,ARL,330577773
2025-07-17T16:06:03.747495669Z,2025-07-17T16:06:03.747330178Z,10,2,1108,C,A,3,13.68,100,130,165491,275518621,13.110000,100,1,13.620000,15,1,13.000000,2,1,13.640000,15,1,12.980000,200,2,13.650000,200,2,12.860000,100,1,13.800000,200,2,12.730000,100,1,13.920000,100,1,12.710000,100,1,13.940000,2,1,12.500000,700,1,14.230000,100,1,12.460000,100,1,14.280000,100,1,12.430000,700,1,14.520000,300,3,12.420000,700,1,14.560000,800,2,ARL,330357633
2025-07-17T16:06:03.887274670Z,2025-07-17T16:06:03.887107153Z,10,2,1108,C,A,2,13.65,100,0,167517,275532429,13.110000,100,1,13.620000,15,1,13.000000,2,1,13.640000,15,1,12.980000,200,2,13.650000,100,1,12.860000,100,1,13.800000,200,2,12.730000,100,1,13.920000,100,1,12.710000,100,1,13.940000,2,1,12.500000,700,1,14.230000,100,1,12.460000,100,1,14.280000,100,1,12.430000,700,1,14.520000,300,3,12.420000,700,1,14.560000,800,2,ARL,330359197
2025-07-17T16:06:03.887274670Z,2025-07-17T16:06:03.887107153Z,10,2,1108,A,A,1,13.63,100,130,167517,275532429,13.110000,100,1,13.620000,15,1,13.000000,2,1,13.630000,100,1,12.980000,200,2,13.640000,15,1,12.860000,100,1,13.650000,100,1,12.730000,100,1,13.800000,200,2,12.710000,100,1,13.920000,100,1,12.500000,700,1,13.940000,2,1,12.460000,100,1,14.230000,100,1,12.430000,700,1,14.280000,100,1,12.420000,700,1,14.520000,300,3,ARL,330592465
2025-07-17T16:06:07.510050758Z,2025-07-17T16:06:07.509885114Z,10,2,1108,C,A,2,13.64,15,130,165644,275647392,13.110000,100,1,13.620000,15,1,13.000000,2,1,13.630000,100,1,12.980000,200,2,13.650000,100,1,12.860000,100,1,13.800000,200,2,12.730000,100,1,13.920000,100,1,12.710000,100,1,13.940000,2,1,12.500000,700,1,14.230000,100,1,12.460000,100,1,14.280000,100,1,12.430000,700,1,14.520000,300,3,12.420000,700,1,14.560000,800,2,ARL,330357473
2025-07-17T16:06:09.885143909Z,2025-07-17T16:06:09.884978592Z,10,2,1108,A,A,0,13.60,15,130,165317,275699092,13.110000,100,1,13.600000,15,1,13.000000,2,1,13.620000,15,1,12.980000,200,2,13.630000,100,1,12.860000,100,1,13.650000,100,1,12.730000,100,1,13.800000,200,2,12.710000,100,1,13.920000,100,1,12.500000,700,1,13.940000,2,1,12.460000,100,1,14.230000,100,1,12.430000,700,1,14.280000,100,1,12.420000,700,1,14.520000,300,3,ARL,330788421
2025-07-17T16:06:09.967608061Z,2025-07-17T16:06:09.967442600Z,10,2,1108,C,A,2,13.63,100,0,165461,275700261,13.110000,100,1,13.600000,15,1,13.000000,2,1,13.620000,15,1,12.980000,200,2,13.650000,100,1,12.860000,100,1,13.800000,200,2,12.730000,100,1,13.920000,100,1,12.710000,100,1,13.940000,2,1,12.500000,700,1,14.230000,100,1,12.460000,100,1,14.280000,100,1,12.430000,700,1,14.520000,300,3,12.420000,700,1,14.560000,800,2,ARL,330592465
2025-07-17T16:06:09.967608061Z,2025-07-17T16:06:09.967442600Z,10,2,1108,A,A,1,13.61,100,130,165461,275700261,13.110000,100,1,13.600000,15,1,13.000000,2,1,13.610000,100,1,12.980000,200,2,13.620000,15,1,12.860000,100,1,13.650000,100,1,12.730000,100,1,13.800000,200,2,12.710000,100,1,13.920000,100,1,12.500000,700,1,13.940000,2,1,12.460000,100,1,14.230000,100,1,12.430000,700,1,14.280000,100,1,12.420000,700,1,14.520000,300,3,ARL,330789481
2025-07-17T16:06:09.968352066Z,2025-07-17T16:06:09.968186617Z,10,2,1108,C,A,14,14.71,100,0,165449,275700270,13.110000,100,1,13.600000,15,1,13.000000,2,1,13.610000,100,1,12.980000,200,2,13.620000,15,1,12.860000,100,1,13.650000,100,1,12.730000,100,1,13.800000,200,2,12.710000,100,1,13.920000,100,1,12.500000,700,1,13.940000,2,1,12.460000,100,1,14.230000,100,1,12.430000,700,1,14.280000,100,1,12.420000,700,1,14.520000,300,3,ARL,330359225
2025-07-17T16:06:09.968352066Z,2025-07-17T16:06:09.968186617Z,10,2,1108,A,A,-1,14.67,100,130,165449,275700270,13.110000,100,1,13.600000,15,1,13.000000,2,1,13.610000,100,1,12.980000,200,2,13.620000,15,1,12.860000,100,1,13.650000,100,1,12.730000,100,1,13.800000,200,2,12.710000,100,1,13.920000,100,1,12.500000,700,1,13.940000,2,1,12.460000,100,1,14.230000,100,1,12.430000,700,1,14.280000,100,1,12.420000,700,1,14.520000,300,3,ARL,330789501
2025-07-17T16:06:09.970040686Z,2025-07-17T16:06:09.969875190Z,10,2,1108,C,A,22,17.44,100,0,165496,275700282,13.110000,100,1,13.600000,15,1,13.000000,2,1,13.610000,100,1,12.980000,200,2,13.620000,15,1,12.860000,100,1,13.650000,100,1,12.730000,100,1,13.800000,200,2,12.710000,100,1,13.920000,100,1,12.500000,700,1,13.940000,2,1,12.460000,100,1,14.230000,100,1,12.430000,700,1,14.280000,100,1,12.420000,700,1,14.520000,300,3,ARL,327870217
2025-07-17T16:06:09.970040686Z,2025-07-17T16:06:09.969875190Z,10,2,1108,A,A,-1,17.29,100,130,165496,275700282,13.110000,100,1,13.600000,15,1,13.000000,2,1,13.610000,100,1,12.980000,200,2,13.620000,15,1,12.860000,100,1,13.650000,100,1,12.730000,100,1,13.800000,200,2,12.710000,100,1,13.920000,100,1,12.500000,700,1,13.940000,2,1,12.460000,100,1,14.230000,100,1,12.430000,700,1,14.280000,100,1,12.420000,700,1,14.520000,300,3,ARL,330789509
2025-07-17T16:06:20.470889851Z,2025-07-17T16:06:20.470724464Z,10,2,1108,A,A,3,13.63,100,130,165387,275896138,13.110000,100,1,13.600000,15,1,13.000000,2,1,13.610000,100,1,12.980000,200,2,13.620000,15,1,12.860000,100,1,13.630000,100,1,12.730000,100,1,13.650000,100,1,12.710000,100,1,13.800000,200,2,12.500000,700,1,13.920000,100,1,12.460000,100,1,13.940000,2,1,12.430000,700,1,14.230000,100,1,12.420000,700,1,14.280000,100,1,ARL,331018065
2025-07-17T16:06:20.477598578Z,2025-07-17T16:06:20.477432988Z,10,2,1108,C,A,4,13.65,100,130,165590,275896242,13.110000,100,1,13.600000,15,1,13.000000,2,1,13.610000,100,1,12.980000,200,2,13.620000,15,1,12.860000,100,1,13.630000,100,1,12.730000,100,1,13.800000,200,2,12.710000,100,1,13.920000,100,1,12.500000,700,1,13.940000,2,1,12.460000,100,1,14.230000,100,1,12.430000,700,1,14.280000,100,1,12.420000,700,1,14.520000,300,3,ARL,330577773
2025-07-17T16:06:20.811164178Z,2025-07-17T16:06:20.810998706Z,10,2,1108,C,A,2,13.62,15,130,165472,275900161,13.110000,100,1,13.600000,15,1,13.000000,2,1,13.610000,100,1,12.980000,200,2,13.630000,100,1,12.860000,100,1,13.800000,200,2,12.730000,100,1,13.920000,100,1,12.710000,100,1,13.940000,2,1,12.500000,700,1,14.230000,100,1,12.460000,100,1,14.280000,100,1,12.430000,700,1,14.520000,300,3,12.420000,700,1,14.560000,800,2,ARL,330577045
2025-07-17T16:06:22.151222819Z,2025-07-17T16:06:22.151057292Z,10,2,1108,A,A,0,13.58,15,130,165527,275926927,13.110000,100,1,13.580000,15,1,13.000000,2,1,13.600000,15,1,12.980000,200,2,13.610000,100,1,12.860000,100,1,13.630000,100,1,12.730000,100,1,13.800000,200,2,12.710000,100,1,13.920000,100,1,12.500000,700,1,13.940000,2,1,12.460000,100,1,14.230000,100,1,12.430000,700,1,14.280000,100,1,12.420000,700,1,14.520000,300,3,ARL,331050981
2025-07-17T16:06:22.151491832Z,2025-07-17T16:06:22.151326300Z,10,2,1108,C,A,2,13.61,100,0,165532,275926940,13.110000,100,1,13.580000,15,1,13.000000,2,1,13.600000,15,1,12.980000,200,2,13.630000,100,1,12.860000,100,1,13.800000,200,2,12.730000,100,1,13.920000,100,1,12.710000,100,1,13.940000,2,1,12.500000,700,1,14.230000,100,1,12.460000,100,1,14.280000,100,1,12.430000,700,1,14.520000,300,3,12.420000,700,1,14.560000,800,2,ARL,330789481
2025-07-17T16:06:22.151491832Z,2025-07-17T16:06:22.151326300Z,10,2,1108,A,A,1,13.59,100,130,165532,275926940,13.110000,100,1,13.580000,15,1,13.000000,2,1,13.590000,100,1,12.980000,200,2,13.600000,15,1,12.860000,100,1,13.630000,100,1,12.730000,100,1,13.800000,200,2,12.710000,100,1,13.920000,100,1,12.500000,700,1,13.940000,2,1,12.460000,100,1,14.230000,100,1,12.430000,700,1,14.280000,100,1,12.420000,700,1,14.520000,300,3,ARL,331050989
2025-07-17T16:06:22.151761329Z,2025-07-17T16:06:22.151595415Z,10,2,1108,C,A,4,13.80,100,0,165914,275926966,13.110000,100,1,13.580000,15,1,13.000000,2,1,13.590000,100,1,12.980000,200,2,13.600000,15,1,12.860000,100,1,13.630000,100,1,12.730000,100,1,13.800000,100,1,12.710000,100,1,13.920000,100,1,12.500000,700,1,13.940000,2,1,12.460000,100,1,14.230000,100,1,12.430000,700,1,14.280000,100,1,12.420000,700,1,14.520000,300,3,ARL,328614525
2025-07-17T16:06:22.151761329Z,2025-07-17T16:06:22.151595781Z,10,2,1108,C,A,4,13.80,100,130,165548,275926967,13.110000,100,1,13.580000,15,1,13.000000,2,1,13.590000,100,1,12.980000,200,2,13.600000,15,1,12.860000,100,1,13.630000,100,1,12.730000,100,1,13.920000,100,1,12.710000,100,1,13.940000,2,1,12.500000,700,1,14.230000,100,1,12.460000,100,1,14.280000,100,1,12.430000,700,1,14.520000,300,3,12.420000,700,1,14.560000,800,2,ARL,328614529
2025-07-17T16:06:22.153148893Z,2025-07-17T16:06:22.152983326Z,10,2,1108,C,A,18,15.79,100,0,165567,275927034,13.110000,100,1,13.580000,15,1,13.000000,2,1,13.590000,100,1,12.980000,200,2,13.600000,15,1,12.860000,100,1,13.630000,100,1,12.730000,100,1,13.920000,100,1,12.710000,100,1,13.940000,2,1,12.500000,700,1,14.230000,100,1,12.460000,100,1,14.280000,100,1,12.430000,700,1,14.520000,300,3,12.420000,700,1,14.560000,800,2,ARL,327870361
2025-07-17T16:06:22.153148893Z,2025-07-17T16:06:22.152983326Z,10,2,1108,A,A,-1,15.63,100,130,165567,275927034,13.110000,100,1,13.580000,15,1,13.000000,2,1,13.590000,100,1,12.980000,200,2,13.600000,15,1,12.860000,100,1,13.630000,100,1,12.730000,100,1,13.920000,100,1,12.710000,100,1,13.940000,2,1,12.500000,700,1,14.230000,100,1,12.460000,100,1,14.280000,100,1,12.430000,700,1,14.520000,300,3,12.420000,700,1,14.560000,800,2,ARL,331051145
2025-07-17T16:06:22.153916169Z,2025-07-17T16:06:22.153749481Z,10,2,1108,C,A,13,14.70,100,0,166688,275927046,13.110000,100,1,13.580000,15,1,13.000000,2,1,13.590000,100,1,12.980000,200,2,13.600000,15,1,12.860000,100,1,13.630000,100,1,12.730000,100,1,13.920000,100,1,12.710000,100,1,13.940000,2,1,12.500000,700,1,14.230000,100,1,12.460000,100,1,14.280000,100,1,12.430000,700,1,14.520000,300,3,12.420000,700,1,14.560000,800,2,ARL,327868421
2025-07-17T16:06:22.153916169Z,2025-07-17T16:06:22.153749481Z,10,2,1108,A,A,9,14.55,100,130,166688,275927046,13.110000,100,1,13.580000,15,1,13.000000,2,1,13.590000,100,1,12.980000,200,2,13.600000,15,1,12.860000,100,1,13.630000,100,1,12.730000,100,1,13.920000,100,1,12.710000,100,1,13.940000,2,1,12.500000,700,1,14.230000,100,1,12.460000,100,1,14.280000,100,1,12.430000,700,1,14.520000,300,3,12.420000,700,1,14.550000,100,1,ARL,331051173
2025-07-17T16:06:22.156070698Z,2025-07-17T16:06:22.155905240Z,10,2,1108,C,A,8,14.52,100,0,165458,275927117,13.110000,100,1,13.580000,15,1,13.000000,2,1,13.590000,100,1,12.980000,200,2,13.600000,15,1,12.860000,100,1,13.630000,100,1,12.730000,100,1,13.920000,100,1,12.710000,100,1,13.940000,2,1,12.500000,700,1,14.230000,100,1,12.460000,100,1,14.280000,100,1,12.430000,700,1,14.520000,200,2,12.420000,700,1,14.550000,100,1,ARL,327869529
2025-07-17T16:06:22.156070698Z,2025-07-17T16:06:22.155905240Z,10,2,1108,A,A,8,14.38,100,130,165458,275927117,13.110000,100,1,13.580000,15,1,13.000000,2,1,13.590000,100,1,12.980000,200,2,13.600000,15,1,12.860000,100,1,13.630000,100,1,12.730000,100,1,13.920000,100,1,12.710000,100,1,13.940000,2,1,12.500000,700,1,14.230000,100,1,12.460000,100,1,14.280000,100,1,12.430000,700,1,14.380000,100,1,12.420000,700,1,14.520000,200,2,ARL,331051369
2025-07-17T16:06:22.178044675Z,2025-07-17T16:06:22.177879233Z,10,2,1108,C,A,15,14.70,100,0,165442,275927444,13.110000,100,1,13.580000,15,1,13.000000,2,1,13.590000,100,1,12.980000,200,2,13.600000,15,1,12.860000,100,1,13.630000,100,1,12.730000,100,1,13.920000,100,1,12.710000,100,1,13.940000,2,1,12.500000,700,1,14.230000,100,1,12.460000,100,1,14.280000,100,1,12.430000,700,1,14.380000,100,1,12.420000,700,1,14.520000,200,2,ARL,327873009
2025-07-17T16:06:22.178044675Z,2025-07-17T16:06:22.177879233Z,10,2,1108,A,A,-1,14.55,100,130,165442,275927444,13.110000,100,1,13.580000,15,1,13.000000,2,1,13.590000,100,1,12.980000,200,2,13.600000,15,1,12.860000,100,1,13.630000,100,1,12.730000,100,1,13.920000,100,1,12.710000,100,1,13.940000,2,1,12.500000,700,1,14.230000,100,1,12.460000,100,1,14.280000,100,1,12.430000,700,1,14.380000,100,1,12.420000,700,1,14.520000,200,2,ARL,331052197
2025-07-17T16:06:24.519511128Z,2025-07-17T16:06:24.519345743Z,10,2,1108,A,A,2,13.60,100,130,165385,275968354,13.110000,100,1,13.580000,15,1,13.000000,2,1,13.590000,100,1,12.980000,200,2,13.600000,115,2,12.860000,100,1,13.630000,100,1,12.730000,100,1,13.920000,100,1,12.710000,100,1,13.940000,2,1,12.500000,700,1,14.230000,100,1,12.460000,100,1,14.280000,100,1,12.430000,700,1,14.380000,100,1,12.420000,700,1,14.520000,200,2,ARL,331104725
2025-07-17T16:06:24.526359716Z,2025-07-17T16:06:24.526194457Z,10,2,1108,C,A,3,13.63,100,130,165259,275968393,13.110000,100,1,13.580000,15,1,13.000000,2,1,13.590000,100,1,12.980000,200,2,13.600000,115,2,12.860000,100,1,13.920000,100,1,12.730000,100,1,13.940000,2,1,12.710000,100,1,14.230000,100,1,12.500000,700,1,14.280000,100,1,12.460000,100,1,14.380000,100,1,12.430000,700,1,14.520000,200,2,12.420000,700,1,14.550000,200,2,ARL,331018065
2025-07-17T16:06:26.610345800Z,2025-07-17T16:06:26.610180184Z,10,2,1108,C,A,4,13.94,2,0,165616,276013080,13.110000,100,1,13.580000,15,1,13.000000,2,1,13.590000,100,1,12.980000,200,2,13.600000,115,2,12.860000,100,1,13.920000,100,1,12.730000,100,1,14.230000,100,1,12.710000,100,1,14.280000,100,1,12.500000,700,1,14.380000,100,1,12.460000,100,1,14.520000,200,2,12.430000,700,1,14.550000,200,2,12.420000,700,1,14.560000,800,2,ARL,328351217
2025-07-17T16:06:26.610345800Z,2025-07-17T16:06:26.610180184Z,10,2,1108,A,A,3,13.85,2,130,165616,276013080,13.110000,100,1,13.580000,15,1,13.000000,2,1,13.590000,100,1,12.980000,200,2,13.600000,115,2,12.860000,100,1,13.850000,2,1,12.730000,100,1,13.920000,100,1,12.710000,100,1,14.230000,100,1,12.500000,700,1,14.280000,100,1,12.460000,100,1,14.380000,100,1,12.430000,700,1,14.520000,200,2,12.420000,700,1,14.550000,200,2,ARL,331155889
2025-07-17T16:06:30.625877214Z,2025-07-17T16:06:30.625711923Z,10,2,1108,A,A,6,14.27,700,130,165291,276103282,13.110000,100,1,13.580000,15,1,13.000000,2,1,13.590000,100,1,12.980000,200,2,13.600000,115,2,12.860000,100,1,13.850000,2,1,12.730000,100,1,13.920000,100,1,12.710000,100,1,14.230000,100,1,12.500000,700,1,14.270000,700,1,12.460000,100,1,14.280000,100,1,12.430000,700,1,14.380000,100,1,12.420000,700,1,14.520000,200,2,ARL,331257169
2025-07-17T16:06:30.625956307Z,2025-07-17T16:06:30.625790910Z,10,2,1108,C,A,14,14.68,700,130,165397,276103283,13.110000,100,1,13.580000,15,1,13.000000,2,1,13.590000,100,1,12.980000,200,2,13.600000,115,2,12.860000,100,1,13.850000,2,1,12.730000,100,1,13.920000,100,1,12.710000,100,1,14.230000,100,1,12.500000,700,1,14.270000,700,1,12.460000,100,1,14.280000,100,1,12.430000,700,1,14.380000,100,1,12.420000,700,1,14.520000,200,2,ARL,325716945
2025-07-17T16:06:31.127827805Z,2025-07-17T16:06:31.127662311Z,10,2,1108,A,A,9,14.48,700,130,165494,276118990,13.110000,100,1,13.580000,15,1,13.000000,2,1,13.590000,100,1,12.980000,200,2,13.600000,115,2,12.860000,100,1,13.850000,2,1,12.730000,100,1,13.920000,100,1,12.710000,100,1,14.230000,100,1,12.500000,700,1,14.270000,700,1,12.460000,100,1,14.280000,100,1,12.430000,700,1,14.380000,100,1,12.420000,700,1,14.480000,700,1,ARL,331272997
2025-07-17T16:06:31.128581831Z,2025-07-17T16:06:31.128416336Z,10,2,1108,C,A,15,14.68,700,130,165495,276119017,13.110000,100,1,13.580000,15,1,13.000000,2,1,13.590000,100,1,12.980000,200,2,13.600000,115,2,12.860000,100,1,13.850000,2,1,12.730000,100,1,13.920000,100,1,12.710000,100,1,14.230000,100,1,12.500000,700,1,14.270000,700,1,12.460000,100,1,14.280000,100,1,12.430000,700,1,14.380000,100,1,12.420000,700,1,14.480000,700,1,ARL,289932801
2025-07-17T16:06:31.990649229Z,2025-07-17T16:06:31.990483799Z,10,2,1108,C,A,2,13.60,15,130,165430,276135226,13.110000,100,1,13.580000,15,1,13.000000,2,1,13.590000,100,1,12.980000,200,2,13.600000,100,1,12.860000,100,1,13.850000,2,1,12.730000,100,1,13.920000,100,1,12.710000,100,1,14.230000,100,1,12.500000,700,1,14.270000,700,1,12.460000,100,1,14.280000,100,1,12.430000,700,1,14.380000,100,1,12.420000,700,1,14.480000,700,1,ARL,330788421
2025-07-17T16:06:42.812807096Z,2025-07-17T16:06:42.812641697Z,10,2,1108,A,A,0,13.56,15,130,165399,276276783,13.110000,100,1,13.560000,15,1,13.000000,2,1,13.580000,15,1,12.980000,200,2,13.590000,100,1,12.860000,100,1,13.600000,100,1,12.730000,100,1,13.850000,2,1,12.710000,100,1,13.920000,100,1,12.500000,700,1,14.230000,100,1,12.460000,100,1,14.270000,700,1,12.430000,700,1,14.280000,100,1,12.420000,700,1,14.380000,100,1,ARL,331488089
2025-07-17T16:06:43.012965957Z,2025-07-17T16:06:43.012799164Z,10,2,1108,C,A,2,13.59,100,0,166793,276279311,13.110000,100,1,13.560000,15,1,13.000000,2,1,13.580000,15,1,12.980000,200,2,13.600000,100,1,12.860000,100,1,13.850000,2,1,12.730000,100,1,13.920000,100,1,12.710000,100,1,14.230000,100,1,12.500000,700,1,14.270000,700,1,12.460000,100,1,14.280000,100,1,12.430000,700,1,14.380000,100,1,12.420000,700,1,14.480000,700,1,ARL,331050989
2025-07-17T16:06:43.012965957Z,2025-07-17T16:06:43.012799164Z,10,2,1108,A,A,1,13.57,100,128,166793,276279311,13.110000,100,1,13.560000,15,1,13.000000,2,1,13.570000,100,1,12.980000,200,2,13.580000,15,1,12.860000,100,1,13.600000,100,1,12.730000,100,1,13.850000,2,1,12.710000,100,1,13.920000,100,1,12.500000,700,1,14.230000,100,1,12.460000,100,1,14.270000,700,1,12.430000,700,1,14.280000,100,1,12.420000,700,1,14.380000,100,1,ARL,331491049
2025-07-17T16:06:43.013716205Z,2025-07-17T16:06:43.013550575Z,10,2,1108,C,A,15,14.67,100,0,165630,276279331,13.110000,100,1,13.560000,15,1,13.000000,2,1,13.570000,100,1,12.980000,200,2,13.580000,15,1,12.860000,100,1,13.600000,100,1,12.730000,100,1,13.850000,2,1,12.710000,100,1,13.920000,100,1,12.500000,700,1,14.230000,100,1,12.460000,100,1,14.270000,700,1,12.430000,700,1,14.280000,100,1,12.420000,700,1,14.380000,100,1,ARL,330789501
2025-07-17T16:06:43.013716205Z,2025-07-17T16:06:43.013550575Z,10,2,1108,A,A,-1,14.62,100,130,165630,276279331,13.110000,100,1,13.560000,15,1,13.000000,2,1,13.570000,100,1,12.980000,200,2,13.580000,15,1,12.860000,100,1,13.600000,100,1,12.730000,100,1,13.850000,2,1,12.710000,100,1,13.920000,100,1,12.500000,700,1,14.230000,100,1,12.460000,100,1,14.270000,700,1,12.430000,700,1,14.280000,100,1,12.420000,700,1,14.380000,100,1,ARL,331491077
2025-07-17T16:06:43.024656023Z,2025-07-17T16:06:43.024490355Z,10,2,1108,C,A,5,13.92,100,130,165668,276279620,13.110000,100,1,13.560000,15,1,13.000000,2,1,13.570000,100,1,12.980000,200,2,13.580000,15,1,12.860000,100,1,13.600000,100,1,12.730000,100,1,13.850000,2,1,12.710000,100,1,14.230000,100,1,12.500000,700,1,14.270000,700,1,12.460000,100,1,14.280000,100,1,12.430000,700,1,14.380000,100,1,12.420000,700,1,14.480000,700,1,ARL,330359625
2025-07-17T16:06:43.024708304Z,2025-07-17T16:06:43.024543099Z,10,2,1108,A,A,4,13.84,100,130,165205,276279621,13.110000,100,1,13.560000,15,1,13.000000,2,1,13.570000,100,1,12.980000,200,2,13.580000,15,1,12.860000,100,1,13.600000,100,1,12.730000,100,1,13.840000,100,1,12.710000,100,1,13.850000,2,1,12.500000,700,1,14.230000,100,1,12.460000,100,1,14.270000,700,1,12.430000,700,1,14.280000,100,1,12.420000,700,1,14.380000,100,1,ARL,331491269
2025-07-17T16:06:49.613941821Z,2025-07-17T16:06:49.613776144Z,10,2,1108,C,A,2,13.58,15,130,165677,276382302,13.110000,100,1,13.560000,15,1,13.000000,2,1,13.570000,100,1,12.980000,200,2,13.600000,100,1,12.860000,100,1,13.840000,100,1,12.730000,100,1,13.850000,2,1,12.710000,100,1,14.230000,100,1,12.500000,700,1,14.270000,700,1,12.460000,100,1,14.280000,100,1,12.430000,700,1,14.380000,100,1,12.420000,700,1,14.480000,700,1,ARL,331050981
2025-07-17T16:06:50.618669843Z,2025-07-17T16:06:50.618504506Z,10,2,1108,A,A,0,13.54,15,130,165337,276408477,13.110000,100,1,13.540000,15,1,13.000000,2,1,13.560000,15,1,12.980000,200,2,13.570000,100,1,12.860000,100,1,13.600000,100,1,12.730000,100,1,13.840000,100,1,12.710000,100,1,13.850000,2,1,12.500000,700,1,14.230000,100,1,12.460000,100,1,14.270000,700,1,12.430000,700,1,14.280000,100,1,12.420000,700,1,14.380000,100,1,ARL,331666961
2025-07-17T16:06:50.626438205Z,2025-07-17T16:06:50.626272828Z,10,2,1108,A,A,3,13.58,100,130,165377,276408566,13.110000,100,1,13.540000,15,1,13.000000,2,1,13.560000,15,1,12.980000,200,2,13.570000,100,1,12.860000,100,1,13.580000,100,1,12.730000,100,1,13.600000,100,1,12.710000,100,1,13.840000,100,1,12.500000,700,1,13.850000,2,1,12.460000,100,1,14.230000,100,1,12.430000,700,1,14.270000,700,1,12.420000,700,1,14.280000,100,1,ARL,331667121
2025-07-17T16:06:50.633113557Z,2025-07-17T16:06:50.632947998Z,10,2,1108,C,A,4,13.60,100,130,165559,276408644,13.110000,100,1,13.540000,15,1,13.000000,2,1,13.560000,15,1,12.980000,200,2,13.570000,100,1,12.860000,100,1,13.580000,100,1,12.730000,100,1,13.840000,100,1,12.710000,100,1,13.850000,2,1,12.500000,700,1,14.230000,100,1,12.460000,100,1,14.270000,700,1,12.430000,700,1,14.280000,100,1,12.420000,700,1,14.380000,100,1,ARL,331104725
2025-07-17T16:06:51.754576322Z,2025-07-17T16:06:51.754410704Z,10,2,1108,C,A,2,13.57,100,0,165618,276428315,13.110000,100,1,13.540000,15,1,13.000000,2,1,13.560000,15,1,12.980000,200,2,13.580000,100,1,12.860000,100,1,13.840000,100,1,12.730000,100,1,13.850000,2,1,12.710000,100,1,14.230000,100,1,12.500000,700,1,14.270000,700,1,12.460000,100,1,14.280000,100,1,12.430000,700,1,14.380000,100,1,12.420000,700,1,14.480000,700,1,ARL,331491049
2025-07-17T16:06:51.754576322Z,2025-07-17T16:06:51.754410704Z,10,2,1108,A,A,1,13.55,100,130,165618,276428315,13.110000,100,1,13.540000,15,1,13.000000,2,1,13.550000,100,1,12.980000,200,2,13.560000,15,1,12.860000,100,1,13.580000,100,1,12.730000,100,1,13.840000,100,1,12.710000,100,1,13.850000,2,1,12.500000,700,1,14.230000,100,1,12.460000,100,1,14.270000,700,1,12.430000,700,1,14.280000,100,1,12.420000,700,1,14.380000,100,1,ARL,331694265
2025-07-17T16:06:51.757403109Z,2025-07-17T16:06:51.757237300Z,10,2,1108,C,B,1,13.00,2,0,165809,276428333,13.110000,100,1,13.540000,15,1,12.980000,200,2,13.550000,100,1,12.860000,100,1,13.560000,15,1,12.730000,100,1,13.580000,100,1,12.710000,100,1,13.840000,100,1,12.500000,700,1,13.850000,2,1,12.460000,100,1,14.230000,100,1,12.430000,700,1,14.270000,700,1,12.420000,700,1,14.280000,100,1,12.370000,700,1,14.380000,100,1,ARL,325967705
2025-07-17T16:06:51.757403109Z,2025-07-17T16:06:51.757237300Z,10,2,1108,A,B,2,12.90,2,130,165809,276428333,13.110000,100,1,13.540000,15,1,12.980000,200,2,13.550000,100,1,12.900000,2,1,13.560000,15,1,12.860000,100,1,13.580000,100,1,12.730000,100,1,13.840000,100,1,12.710000,100,1,13.850000,2,1,12.500000,700,1,14.230000,100,1,12.460000,100,1,14.270000,700,1,12.430000,700,1,14.280000,100,1,12.420000,700,1,14.380000,100,1,ARL,331694297
2025-07-17T16:06:55.056300861Z,2025-07-17T16:06:55.056135380Z,10,2,1108,C,A,0,13.54,15,130,165481,276516227,13.110000,100,1,13.550000,100,1,12.980000,200,2,13.560000,15,1,12.900000,2,1,13.580000,100,1,12.860000,100,1,13.840000,100,1,12.730000,100,1,13.850000,2,1,12.710000,100,1,14.230000,100,1,12.500000,700,1,14.270000,700,1,12.460000,100,1,14.280000,100,1,12.430000,700,1,14.380000,100,1,12.420000,700,1,14.480000,700,1,ARL,331666961
2025-07-17T16:06:55.056466231Z,2025-07-17T16:06:55.056301001Z,10,2,1108,C,A,1,13.56,15,130,165230,276516239,13.110000,100,1,13.550000,100,1,12.980000,200,2,13.580000,100,1,12.900000,2,1,13.840000,100,1,12.860000,100,1,13.850000,2,1,12.730000,100,1,14.230000,100,1,12.710000,100,1,14.270000,700,1,12.500000,700,1,14.280000,100,1,12.460000,100,1,14.380000,100,1,12.430000,700,1,14.480000,700,1,12.420000,700,1,14.520000,200,2,ARL,331488089
2025-07-17T16:07:00.010995558Z,2025-07-17T16:07:00.010829521Z,10,2,1108,C,A,0,13.55,100,130,166037,276611719,13.110000,100,1,13.580000,100,1,12.980000,200,2,13.840000,100,1,12.900000,2,1,13.850000,2,1,12.860000,100,1,14.230000,100,1,12.730000,100,1,14.270000,700,1,12.710000,100,1,14.280000,100,1,12.500000,700,1,14.380000,100,1,12.460000,100,1,14.480000,700,1,12.430000,700,1,14.520000,200,2,12.420000,700,1,14.550000,200,2,ARL,331694265
2025-07-17T16:07:00.023849180Z,2025-07-17T16:07:00.023683961Z,10,2,1108,C,A,0,13.58,100,130,165219,276613073,13.110000,100,1,13.840000,100,1,12.980000,200,2,13.850000,2,1,12.900000,2,1,14.230000,100,1,12.860000,100,1,14.270000,700,1,12.730000,100,1,14.280000,100,1,12.710000,100,1,14.380000,100,1,12.500000,700,1,14.480000,700,1,12.460000,100,1,14.520000,200,2,12.430000,700,1,14.550000,200,2,12.420000,700,1,14.560000,800,2,ARL,331667121
2025-07-17T16:07:00.023917543Z,2025-07-17T16:07:00.023752163Z,10,2,1108,C,A,3,14.27,700,130,165380,276613077,13.110000,100,1,13.840000,100,1,12.980000,200,2,13.850000,2,1,12.900000,2,1,14.230000,100,1,12.860000,100,1,14.280000,100,1,12.730000,100,1,14.380000,100,1,12.710000,100,1,14.480000,700,1,12.500000,700,1,14.520000,200,2,12.460000,100,1,14.550000,200,2,12.430000,700,1,14.560000,800,2,12.420000,700,1,14.600000,700,1,ARL,331257169
2025-07-17T16:07:00.023980805Z,2025-07-17T16:07:00.023815326Z,10,2,1108,A,A,6,14.51,700,130,165479,276613078,13.110000,100,1,13.840000,100,1,12.980000,200,2,13.850000,2,1,12.900000,2,1,14.230000,100,1,12.860000,100,1,14.280000,100,1,12.730000,100,1,14.380000,100,1,12.710000,100,1,14.480000,700,1,12.500000,700,1,14.510000,700,1,12.460000,100,1,14.520000,200,2,12.430000,700,1,14.550000,200,2,12.420000,700,1,14.560000,800,2,ARL,331926981
2025-07-17T16:07:00.024590283Z,2025-07-17T16:07:00.024424816Z,10,2,1108,C,A,11,14.62,100,0,165467,276613110,13.110000,100,1,13.840000,100,1,12.980000,200,2,13.850000,2,1,12.900000,2,1,14.230000,100,1,12.860000,100,1,14.280000,100,1,12.730000,100,1,14.380000,100,1,12.710000,100,1,14.480000,700,1,12.500000,700,1,14.510000,700,1,12.460000,100,1,14.520000,200,2,12.430000,700,1,14.550000,200,2,12.420000,700,1,14.560000,800,2,ARL,331491077
2025-07-17T16:07:00.024590283Z,2025-07-17T16:07:00.024424816Z,10,2,1108,A,A,-1,14.88,100,130,165467,276613110,13.110000,100,1,13.840000,100,1,12.980000,200,2,13.850000,2,1,12.900000,2,1,14.230000,100,1,12.860000,100,1,14.280000,100,1,12.730000,100,1,14.380000,100,1,12.710000,100,1,14.480000,700,1,12.500000,700,1,14.510000,700,1,12.460000,100,1,14.520000,200,2,12.430000,700,1,14.550000,200,2,12.420000,700,1,14.560000,800,2,ARL,331927017
2025-07-17T16:07:00.025231164Z,2025-07-17T16:07:00.025064913Z,10,2,1108,C,A,2,14.23,100,130,166251,276613157,13.110000,100,1,13.840000,100,1,12.980000,200,2,13.850000,2,1,12.900000,2,1,14.280000,100,1,12.860000,100,1,14.380000,100,1,12.730000,100,1,14.480000,700,1,12.710000,100,1,14.510000,700,1,12.500000,700,1,14.520000,200,2,12.460000,100,1,14.550000,200,2,12.430000,700,1,14.560000,800,2,12.420000,700,1,14.600000,700,1,ARL,329074833
2025-07-17T16:07:00.025587549Z,2025-07-17T16:07:00.025422082Z,10,2,1108,A,A,4,14.46,100,130,165467,276613175,13.110000,100,1,13.840000,100,1,12.980000,200,2,13.850000,2,1,12.900000,2,1,14.280000,100,1,12.860000,100,1,14.380000,100,1,12.730000,100,1,14.460000,100,1,12.710000,100,1,14.480000,700,1,12.500000,700,1,14.510000,700,1,12.460000,100,1,14.520000,200,2,12.430000,700,1,14.550000,200,2,12.420000,700,1,14.560000,800,2,ARL,331927161
2025-07-17T16:07:00.025793260Z,2025-07-17T16:07:00.025628157Z,10,2,1108,A,A,0,13.59,100,130,165103,276613194,13.110000,100,1,13.590000,100,1,12.980000,200,2,13.840000,100,1,12.900000,2,1,13.850000,2,1,12.860000,100,1,14.280000,100,1,12.730000,100,1,14.380000,100,1,12.710000,100,1,14.460000,100,1,12.500000,700,1,14.480000,700,1,12.460000,100,1,14.510000,700,1,12.430000,700,1,14.520000,200,2,12.420000,700,1,14.550000,200,2,ARL,331927177
2025-07-17T16:07:00.026998695Z,2025-07-17T16:07:00.026833761Z,10,2,1108,C,A,0,13.59,100,130,164934,276613224,13.110000,100,1,13.840000,100,1,12.980000,200,2,13.850000,2,1,12.900000,2,1,14.280000,100,1,12.860000,100,1,14.380000,100,1,12.730000,100,1,14.460000,100,1,12.710000,100,1,14.480000,700,1,12.500000,700,1,14.510000,700,1,12.460000,100,1,14.520000,200,2,12.430000,700,1,14.550000,200,2,12.420000,700,1,14.560000,800,2,ARL,331927177
2025-07-17T16:07:00.032762182Z,2025-07-17T16:07:00.032596898Z,10,2,1108,C,A,3,14.38,100,130,165284,276613329,13.110000,100,1,13.840000,100,1,12.980000,200,2,13.850000,2,1,12.900000,2,1,14.280000,100,1,12.860000,100,1,14.460000,100,1,12.730000,100,1,14.480000,700,1,12.710000,100,1,14.510000,700,1,12.500000,700,1,14.520000,200,2,12.460000,100,1,14.550000,200,2,12.430000,700,1,14.560000,800,2,12.420000,700,1,14.600000,700,1,ARL,331051369
2025-07-17T16:07:00.032876947Z,2025-07-17T16:07:00.032711777Z,10,2,1108,A,A,-1,14.63,100,130,165170,276613336,13.110000,100,1,13.840000,100,1,12.980000,200,2,13.850000,2,1,12.900000,2,1,14.280000,100,1,12.860000,100,1,14.460000,100,1,12.730000,100,1,14.480000,700,1,12.710000,100,1,14.510000,700,1,12.500000,700,1,14.520000,200,2,12.460000,100,1,14.550000,200,2,12.430000,700,1,14.560000,800,2,12.420000,700,1,14.600000,700,1,ARL,331927477
2025-07-17T16:07:00.045525047Z,2025-07-17T16:07:00.045359807Z,10,2,1108,C,A,0,13.84,100,130,165240,276613663,13.110000,100,1,13.850000,2,1,12.980000,200,2,14.280000,100,1,12.900000,2,1,14.460000,100,1,12.860000,100,1,14.480000,700,1,12.730000,100,1,14.510000,700,1,12.710000,100,1,14.520000,200,2,12.500000,700,1,14.550000,200,2,12.460000,100,1,14.560000,800,2,12.430000,700,1,14.600000,700,1,12.420000,700,1,14.630000,100,1,ARL,331491269
2025-07-17T16:07:00.045559272Z,2025-07-17T16:07:00.045394317Z,10,2,1108,C,A,4,14.51,700,130,164955,276613664,13.110000,100,1,13.850000,2,1,12.980000,200,2,14.280000,100,1,12.900000,2,1,14.460000,100,1,12.860000,100,1,14.480000,700,1,12.730000,100,1,14.520000,200,2,12.710000,100,1,14.550000,200,2,12.500000,700,1,14.560000,800,2,12.460000,100,1,14.600000,700,1,12.430000,700,1,14.630000,100,1,12.420000,700,1,14.880000,100,1,ARL,331926981
2025-07-17T16:07:00.045574786Z,2025-07-17T16:07:00.045409635Z,10,2,1108,A,A,1,14.09,100,130,165151,276613665,13.110000,100,1,13.850000,2,1,12.980000,200,2,14.090000,100,1,12.900000,2,1,14.280000,100,1,12.860000,100,1,14.460000,100,1,12.730000,100,1,14.480000,700,1,12.710000,100,1,14.520000,200,2,12.500000,700,1,14.550000,200,2,12.460000,100,1,14.560000,800,2,12.430000,700,1,14.600000,700,1,12.420000,700,1,14.630000,100,1,ARL,331927857
2025-07-17T16:07:00.046838602Z,2025-07-17T16:07:00.046672908Z,10,2,1108,C,A,1,14.09,100,130,165694,276613680,13.110000,100,1,13.850000,2,1,12.980000,200,2,14.280000,100,1,12.900000,2,1,14.460000,100,1,12.860000,100,1,14.480000,700,1,12.730000,100,1,14.520000,200,2,12.710000,100,1,14.550000,200,2,12.500000,700,1,14.560000,800,2,12.460000,100,1,14.600000,700,1,12.430000,700,1,14.630000,100,1,12.420000,700,1,14.880000,100,1,ARL,331927857
2025-07-17T16:07:00.046887005Z,2025-07-17T16:07:00.046721624Z,10,2,1108,A,A,1,13.86,100,130,165381,276613681,13.110000,100,1,13.850000,2,1,12.980000,200,2,13.860000,100,1,12.900000,2,1,14.280000,100,1,12.860000,100,1,14.460000,100,1,12.730000,100,1,14.480000,700,1,12.710000,100,1,14.520000,200,2,12.500000,700,1,14.550000,200,2,12.460000,100,1,14.560000,800,2,12.430000,700,1,14.600000,700,1,12.420000,700,1,14.630000,100,1,ARL,331927877
2025-07-17T16:07:00.047708936Z,2025-07-17T16:07:00.047544064Z,10,2,1108,C,A,1,13.86,100,130,164872,276613692,13.110000,100,1,13.850000,2,1,12.980000,200,2,14.280000,100,1,12.900000,2,1,14.460000,100,1,12.860000,100,1,14.480000,700,1,12.730000,100,1,14.520000,200,2,12.710000,100,1,14.550000,200,2,12.500000,700,1,14.560000,800,2,12.460000,100,1,14.600000,700,1,12.430000,700,1,14.630000,100,1,12.420000,700,1,14.880000,100,1,ARL,331927877
2025-07-17T16:07:00.047755498Z,2025-07-17T16:07:00.047590313Z,10,2,1108,A,A,1,14.12,100,130,165185,276613693,13.110000,100,1,13.850000,2,1,12.980000,200,2,14.120000,100,1,12.900000,2,1,14.280000,100,1,12.860000,100,1,14.460000,100,1,12.730000,100,1,14.480000,700,1,12.710000,100,1,14.520000,200,2,12.500000,700,1,14.550000,200,2,12.460000,100,1,14.560000,800,2,12.430000,700,1,14.600000,700,1,12.420000,700,1,14.630000,100,1,ARL,331927921
2025-07-17T16:07:00.053448670Z,2025-07-17T16:07:00.053283700Z,10,2,1108,C,A,1,14.12,100,130,164970,276613731,13.110000,100,1,13.850000,2,1,12.980000,200,2,14.280000,100,1,12.900000,2,1,14.460000,100,1,12.860000,100,1,14.480000,700,1,12.730000,100,1,14.520000,200,2,12.710000,100,1,14.550000,200,2,12.500000,700,1,14.560000,800,2,12.460000,100,1,14.600000,700,1,12.430000,700,1,14.630000,100,1,12.420000,700,1,14.880000,100,1,ARL,331927921
2025-07-17T16:07:00.053495095Z,2025-07-17T16:07:00.053329959Z,10,2,1108,A,A,1,14.26,100,130,165136,276613732,13.110000,100,1,13.850000,2,1,12.980000,200,2,14.260000,100,1,12.900000,2,1,14.280000,100,1,12.860000,100,1,14.460000,100,1,12.730000,100,1,14.480000,700,1,12.710000,100,1,14.520000,200,2,12.500000,700,1,14.550000,200,2,12.460000,100,1,14.560000,800,2,12.430000,700,1,14.600000,700,1,12.420000,700,1,14.630000,100,1,ARL,331928009
2025-07-17T16:07:00.057809857Z,2025-07-17T16:07:00.057644427Z,10,2,1108,C,A,6,14.55,100,0,165430,276613800,13.110000,100,1,13.850000,2,1,12.980000,200,2,14.260000,100,1,12.900000,2,1,14.280000,100,1,12.860000,100,1,14.460000,100,1,12.730000,100,1,14.480000,700,1,12.710000,100,1,14.520000,200,2,12.500000,700,1,14.550000,100,1,12.460000,100,1,14.560000,800,2,12.430000,700,1,14.600000,700,1,12.420000,700,1,14.630000,100,1,ARL,331052197
2025-07-17T16:07:00.057809857Z,2025-07-17T16:07:00.057644427Z,10,2,1108,A,A,-1,14.96,100,130,165430,276613800,13.110000,100,1,13.850000,2,1,12.980000,200,2,14.260000,100,1,12.900000,2,1,14.280000,100,1,12.860000,100,1,14.460000,100,1,12.730000,100,1,14.480000,700,1,12.710000,100,1,14.520000,200,2,12.500000,700,1,14.550000,100,1,12.460000,100,1,14.560000,800,2,12.430000,700,1,14.600000,700,1,12.420000,700,1,14.630000,100,1,ARL,331928129
2025-07-17T16:07:00.070490835Z,2025-07-17T16:07:00.070325784Z,10,2,1108,C,A,1,14.26,100,130,165051,276614087,13.110000,100,1,13.850000,2,1,12.980000,200,2,14.280000,100,1,12.900000,2,1,14.460000,100,1,12.860000,100,1,14.480000,700,1,12.730000,100,1,14.520000,200,2,12.710000,100,1,14.550000,100,1,12.500000,700,1,14.560000,800,2,12.460000,100,1,14.600000,700,1,12.430000,700,1,14.630000,100,1,12.420000,700,1,14.880000,100,1,ARL,331928009
2025-07-17T16:07:00.070539222Z,2025-07-17T16:07:00.070373975Z,10,2,1108,A,A,1,14.14,100,130,165247,276614089,13.110000,100,1,13.850000,2,1,12.980000,200,2,14.140000,100,1,12.900000,2,1,14.280000,100,1,12.860000,100,1,14.460000,100,1,12.730000,100,1,14.480000,700,1,12.710000,100,1,14.520000,200,2,12.500000,700,1,14.550000,100,1,12.460000,100,1,14.560000,800,2,12.430000,700,1,14.600000,700,1,12.420000,700,1,14.630000,100,1,ARL,331929033
2025-07-17T16:07:00.071359350Z,2025-07-17T16:07:00.071194493Z,10,2,1108,C,A,1,14.14,100,130,164857,276614094,13.110000,100,1,13.850000,2,1,12.980000,200,2,14.280000,100,1,12.900000,2,1,14.460000,100,1,12.860000,100,1,14.480000,700,1,12.730000,100,1,14.520000,200,2,12.710000,100,1,14.550000,100,1,12.500000,700,1,14.560000,800,2,12.460000,100,1,14.600000,700,1,12.430000,700,1,14.630000,100,1,12.420000,700,1,14.880000,100,1,ARL,331929033
2025-07-17T16:07:00.071405105Z,2025-07-17T16:07:00.071239867Z,10,2,1108,A,A,1,14.26,100,130,165238,276614095,13.110000,100,1,13.850000,2,1,12.980000,200,2,14.260000,100,1,12.900000,2,1,14.280000,100,1,12.860000,100,1,14.460000,100,1,12.730000,100,1,14.480000,700,1,12.710000,100,1,14.520000,200,2,12.500000,700,1,14.550000,100,1,12.460000,100,1,14.560000,800,2,12.430000,700,1,14.600000,700,1,12.420000,700,1,14.630000,100,1,ARL,331929041
2025-07-17T16:07:00.074580946Z,2025-07-17T16:07:00.074415631Z,10,2,1108,C,A,10,14.88,100,0,165315,276614119,13.110000,100,1,13.850000,2,1,12.980000,200,2,14.260000,100,1,12.900000,2,1,14.280000,100,1,12.860000,100,1,14.460000,100,1,12.730000,100,1,14.480000,700,1,12.710000,100,1,14.520000,200,2,12.500000,700,1,14.550000,100,1,12.460000,100,1,14.560000,800,2,12.430000,700,1,14.600000,700,1,12.420000,700,1,14.630000,100,1,ARL,331927017
2025-07-17T16:07:00.074580946Z,2025-07-17T16:07:00.074415631Z,10,2,1108,A,A,-1,15.06,100,130,165315,276614119,13.110000,100,1,13.850000,2,1,12.980000,200,2,14.260000,100,1,12.900000,2,1,14.280000,100,1,12.860000,100,1,14.460000,100,1,12.730000,100,1,14.480000,700,1,12.710000,100,1,14.520000,200,2,12.500000,700,1,14.550000,100,1,12.460000,100,1,14.560000,800,2,12.430000,700,1,14.600000,700,1,12.420000,700,1,14.630000,100,1,ARL,331929065
2025-07-17T16:07:00.085131263Z,2025-07-17T16:07:00.084965637Z,10,2,1108,C,A,12,15.07,100,0,165626,276614295,13.110000,100,1,13.850000,2,1,12.980000,200,2,14.260000,100,1,12.900000,2,1,14.280000,100,1,12.860000,100,1,14.460000,100,1,12.730000,100,1,14.480000,700,1,12.710000,100,1,14.520000,200,2,12.500000,700,1,14.550000,100,1,12.460000,100,1,14.560000,800,2,12.430000,700,1,14.600000,700,1,12.420000,700,1,14.630000,100,1,ARL,326837501
2025-07-17T16:07:00.085131263Z,2025-07-17T16:07:00.084965637Z,10,2,1108,A,A,-1,15.38,100,130,165626,276614295,13.110000,100,1,13.850000,2,1,12.980000,200,2,14.260000,100,1,12.900000,2,1,14.280000,100,1,12.860000,100,1,14.460000,100,1,12.730000,100,1,14.480000,700,1,12.710000,100,1,14.520000,200,2,12.500000,700,1,14.550000,100,1,12.460000,100,1,14.560000,800,2,12.430000,700,1,14.600000,700,1,12.420000,700,1,14.630000,100,1,ARL,331929445
2025-07-17T16:07:00.090359757Z,2025-07-17T16:07:00.090194106Z,10,2,1108,C,A,6,14.55,100,0,165651,276614378,13.110000,100,1,13.850000,2,1,12.980000,200,2,14.260000,100,1,12.900000,2,1,14.280000,100,1,12.860000,100,1,14.460000,100,1,12.730000,100,1,14.480000,700,1,12.710000,100,1,14.520000,200,2,12.500000,700,1,14.560000,800,2,12.460000,100,1,14.600000,700,1,12.430000,700,1,14.630000,100,1,12.420000,700,1,14.960000,100,1,ARL,331051173
2025-07-17T16:07:00.090359757Z,2025-07-17T16:07:00.090194106Z,10,2,1108,A,A,9,14.96,100,130,165651,276614378,13.110000,100,1,13.850000,2,1,12.980000,200,2,14.260000,100,1,12.900000,2,1,14.280000,100,1,12.860000,100,1,14.460000,100,1,12.730000,100,1,14.480000,700,1,12.710000,100,1,14.520000,200,2,12.500000,700,1,14.560000,800,2,12.460000,100,1,14.600000,700,1,12.430000,700,1,14.630000,100,1,12.420000,700,1,14.960000,200,2,ARL,331929633
2025-07-17T16:07:00.102092147Z,2025-07-17T16:07:00.101927028Z,10,2,1108,A,A,9,14.68,700,130,165119,276614699,13.110000,100,1,13.850000,2,1,12.980000,200,2,14.260000,100,1,12.900000,2,1,14.280000,100,1,12.860000,100,1,14.460000,100,1,12.730000,100,1,14.480000,700,1,12.710000,100,1,14.520000,200,2,12.500000,700,1,14.560000,800,2,12.460000,100,1,14.600000,700,1,12.430000,700,1,14.630000,100,1,12.420000,700,1,14.680000,700,1,ARL,331929977
2025-07-17T16:07:00.287582448Z,2025-07-17T16:07:00.287416733Z,10,2,1108,C,A,19,17.29,100,0,165715,276617288,13.110000,100,1,13.850000,2,1,12.980000,200,2,14.260000,100,1,12.900000,2,1,14.280000,100,1,12.860000,100,1,14.460000,100,1,12.730000,100,1,14.480000,700,1,12.710000,100,1,14.520000,200,2,12.500000,700,1,14.560000,800,2,12.460000,100,1,14.600000,700,1,12.430000,700,1,14.630000,100,1,12.420000,700,1,14.680000,700,1,ARL,330789509
2025-07-17T16:07:00.287582448Z,2025-07-17T16:07:00.287416733Z,10,2,1108,A,A,-1,17.76,100,130,165715,276617288,13.110000,100,1,13.850000,2,1,12.980000,200,2,14.260000,100,1,12.900000,2,1,14.280000,100,1,12.860000,100,1,14.460000,100,1,12.730000,100,1,14.480000,700,1,12.710000,100,1,14.520000,200,2,12.500000,700,1,14.560000,800,2,12.460000,100,1,14.600000,700,1,12.430000,700,1,14.630000,100,1,12.420000,700,1,14.680000,700,1,ARL,331934277
2025-07-17T16:07:00.293620434Z,2025-07-17T16:07:00.293454856Z,10,2,1108,C,A,15,15.63,100,0,165578,276617317,13.110000,100,1,13.850000,2,1,12.980000,200,2,14.260000,100,1,12.900000,2,1,14.280000,100,1,12.860000,100,1,14.460000,100,1,12.730000,100,1,14.480000,700,1,12.710000,100,1,14.520000,200,2,12.500000,700,1,14.560000,800,2,12.460000,100,1,14.600000,700,1,12.430000,700,1,14.630000,100,1,12.420000,700,1,14.680000,700,1,ARL,331051145
2025-07-17T16:07:00.293620434Z,2025-07-17T16:07:00.293454856Z,10,2,1108,A,A,-1,16.08,100,130,165578,276617317,13.110000,100,1,13.850000,2,1,12.980000,200,2,14.260000,100,1,12.900000,2,1,14.280000,100,1,12.860000,100,1,14.460000,100,1,12.730000,100,1,14.480000,700,1,12.710000,100,1,14.520000,200,2,12.500000,700,1,14.560000,800,2,12.460000,100,1,14.600000,700,1,12.430000,700,1,14.630000,100,1,12.420000,700,1,14.680000,700,1,ARL,331934377
2025-07-17T16:07:00.494657495Z,2025-07-17T16:07:00.494492099Z,10,2,1108,A,A,1,13.86,100,130,165396,276622423,13.110000,100,1,13.850000,2,1,12.980000,200,2,13.860000,100,1,12.900000,2,1,14.260000,100,1,12.860000,100,1,14.280000,100,1,12.730000,100,1,14.460000,100,1,12.710000,100,1,14.480000,700,1,12.500000,700,1,14.520000,200,2,12.460000,100,1,14.560000,800,2,12.430000,700,1,14.600000,700,1,12.420000,700,1,14.630000,100,1,ARL,331942821
2025-07-17T16:07:00.495318245Z,2025-07-17T16:07:00.495152219Z,10,2,1108,C,B,11,12.36,100,0,166026,276622452,13.110000,100,1,13.850000,2,1,12.980000,200,2,13.860000,100,1,12.900000,2,1,14.260000,100,1,12.860000,100,1,14.280000,100,1,12.730000,100,1,14.460000,100,1,12.710000,100,1,14.480000,700,1,12.500000,700,1,14.520000,200,2,12.460000,100,1,14.560000,800,2,12.430000,700,1,14.600000,700,1,12.420000,700,1,14.630000,100,1,ARL,288723817
2025-07-17T16:07:00.495318245Z,2025-07-17T16:07:00.495152219Z,10,2,1108,A,B,7,12.49,100,130,166026,276622452,13.110000,100,1,13.850000,2,1,12.980000,200,2,13.860000,100,1,12.900000,2,1,14.260000,100,1,12.860000,100,1,14.280000,100,1,12.730000,100,1,14.460000,100,1,12.710000,100,1,14.480000,700,1,12.500000,700,1,14.520000,200,2,12.490000,100,1,14.560000,800,2,12.460000,100,1,14.600000,700,1,12.430000,700,1,14.630000,100,1,ARL,331942901
2025-07-17T16:07:00.495398644Z,2025-07-17T16:07:00.495233001Z,10,2,1108,C,A,12,15.06,100,0,165643,276622455,13.110000,100,1,13.850000,2,1,12.980000,200,2,13.860000,100,1,12.900000,2,1,14.260000,100,1,12.860000,100,1,14.280000,100,1,12.730000,100,1,14.460000,100,1,12.710000,100,1,14.480000,700,1,12.500000,700,1,14.520000,200,2,12.490000,100,1,14.560000,800,2,12.460000,100,1,14.600000,700,1,12.430000,700,1,14.630000,100,1,ARL,331929065
2025-07-17T16:07:00.495398644Z,2025-07-17T16:07:00.495233001Z,10,2,1108,A,A,-1,14.93,100,130,165643,276622455,13.110000,100,1,13.850000,2,1,12.980000,200,2,13.860000,100,1,12.900000,2,1,14.260000,100,1,12.860000,100,1,14.280000,100,1,12.730000,100,1,14.460000,100,1,12.710000,100,1,14.480000,700,1,12.500000,700,1,14.520000,200,2,12.490000,100,1,14.560000,800,2,12.460000,100,1,14.600000,700,1,12.430000,700,1,14.630000,100,1,ARL,331942913
2025-07-17T16:07:00.495989598Z,2025-07-17T16:07:00.495823953Z,10,2,1108,C,B,12,12.36,100,0,165645,276622469,13.110000,100,1,13.850000,2,1,12.980000,200,2,13.860000,100,1,12.900000,2,1,14.260000,100,1,12.860000,100,1,14.280000,100,1,12.730000,100,1,14.460000,100,1,12.710000,100,1,14.480000,700,1,12.500000,700,1,14.520000,200,2,12.490000,100,1,14.560000,800,2,12.460000,100,1,14.600000,700,1,12.430000,700,1,14.630000,100,1,ARL,288723813
2025-07-17T16:07:00.495989598Z,2025-07-17T16:07:00.495823953Z,10,2,1108,A,B,7,12.49,100,130,165645,276622469,13.110000,100,1,13.850000,2,1,12.980000,200,2,13.860000,100,1,12.900000,2,1,14.260000,100,1,12.860000,100,1,14.280000,100,1,12.730000,100,1,14.460000,100,1,12.710000,100,1,14.480000,700,1,12.500000,700,1,14.520000,200,2,12.490000,200,2,14.560000,800,2,12.460000,100,1,14.600000,700,1,12.430000,700,1,14.630000,100,1,ARL,331942945
2025-07-17T16:07:00.496483460Z,2025-07-17T16:07:00.496317847Z,10,2,1108,C,A,19,17.76,100,0,165613,276622478,13.110000,100,1,13.850000,2,1,12.980000,200,2,13.860000,100,1,12.900000,2,1,14.260000,100,1,12.860000,100,1,14.280000,100,1,12.730000,100,1,14.460000,100,1,12.710000,100,1,14.480000,700,1,12.500000,700,1,14.520000,200,2,12.490000,200,2,14.560000,800,2,12.460000,100,1,14.600000,700,1,12.430000,700,1,14.630000,100,1,ARL,331934277
2025-07-17T16:07:00.496483460Z,2025-07-17T16:07:00.496317847Z,10,2,1108,A,A,-1,17.61,100,130,165613,276622478,13.110000,100,1,13.850000,2,1,12.980000,200,2,13.860000,100,1,12.900000,2,1,14.260000,100,1,12.860000,100,1,14.280000,100,1,12.730000,100,1,14.460000,100,1,12.710000,100,1,14.480000,700,1,12.500000,700,1,14.520000,200,2,12.490000,200,2,14.560000,800,2,12.460000,100,1,14.600000,700,1,12.430000,700,1,14.630000,100,1,ARL,331942981
2025-07-17T16:07:00.499666149Z,2025-07-17T16:07:00.499501052Z,10,2,1108,C,A,2,14.26,100,130,165097,276622569,13.110000,100,1,13.850000,2,1,12.980000,200,2,13.860000,100,1,12.900000,2,1,14.280000,100,1,12.860000,100,1,14.460000,100,1,12.730000,100,1,14.480000,700,1,12.710000,100,1,14.520000,200,2,12.500000,700,1,14.560000,800,2,12.490000,200,2,14.600000,700,1,12.460000,100,1,14.630000,100,1,12.430000,700,1,14.680000,700,1,ARL,331929041
2025-07-17T16:07:00.499714918Z,2025-07-17T16:07:00.499549738Z,10,2,1108,A,A,2,14.14,100,130,165180,276622571,13.110000,100,1,13.850000,2,1,12.980000,200,2,13.860000,100,1,12.900000,2,1,14.140000,100,1,12.860000,100,1,14.280000,100,1,12.730000,100,1,14.460000,100,1,12.710000,100,1,14.480000,700,1,12.500000,700,1,14.520000,200,2,12.490000,200,2,14.560000,800,2,12.460000,100,1,14.600000,700,1,12.430000,700,1,14.630000,100,1,ARL,331943133
2025-07-17T16:07:22.814941809Z,2025-07-17T16:07:22.814776694Z,10,2,1108,A,A,0,13.69,15,130,165115,276946179,13.110000,100,1,13.690000,15,1,12.980000,200,2,13.850000,2,1,12.900000,2,1,13.860000,100,1,12.860000,100,1,14.140000,100,1,12.730000,100,1,14.280000,100,1,12.710000,100,1,14.460000,100,1,12.500000,700,1,14.480000,700,1,12.490000,200,2,14.520000,200,2,12.460000,100,1,14.560000,800,2,12.430000,700,1,14.600000,700,1,ARL,332385317
2025-07-17T16:07:22.815057507Z,2025-07-17T16:07:22.814891345Z,10,2,1108,C,A,2,13.86,100,0,166162,276946183,13.110000,100,1,13.690000,15,1,12.980000,200,2,13.850000,2,1,12.900000,2,1,14.140000,100,1,12.860000,100,1,14.280000,100,1,12.730000,100,1,14.460000,100,1,12.710000,100,1,14.480000,700,1,12.500000,700,1,14.520000,200,2,12.490000,200,2,14.560000,800,2,12.460000,100,1,14.600000,700,1,12.430000,700,1,14.630000,100,1,ARL,331942821
2025-07-17T16:07:22.815057507Z,2025-07-17T16:07:22.814891345Z,10,2,1108,A,A,1,13.70,100,130,166162,276946183,13.110000,100,1,13.690000,15,1,12.980000,200,2,13.700000,100,1,12.900000,2,1,13.850000,2,1,12.860000,100,1,14.140000,100,1,12.730000,100,1,14.280000,100,1,12.710000,100,1,14.460000,100,1,12.500000,700,1,14.480000,700,1,12.490000,200,2,14.520000,200,2,12.460000,100,1,14.560000,800,2,12.430000,700,1,14.600000,700,1,ARL,332385325
2025-07-17T16:07:22.815790890Z,2025-07-17T16:07:22.815625345Z,10,2,1108,C,A,12,14.93,100,0,165545,276946264,13.110000,100,1,13.690000,15,1,12.980000,200,2,13.700000,100,1,12.900000,2,1,13.850000,2,1,12.860000,100,1,14.140000,100,1,12.730000,100,1,14.280000,100,1,12.710000,100,1,14.460000,100,1,12.500000,700,1,14.480000,700,1,12.490000,200,2,14.520000,200,2,12.460000,100,1,14.560000,800,2,12.430000,700,1,14.600000,700,1,ARL,331942913
2025-07-17T16:07:22.815790890Z,2025-07-17T16:07:22.815625345Z,10,2,1108,A,A,-1,14.76,100,130,165545,276946264,13.110000,100,1,13.690000,15,1,12.980000,200,2,13.700000,100,1,12.900000,2,1,13.850000,2,1,12.860000,100,1,14.140000,100,1,12.730000,100,1,14.280000,100,1,12.710000,100,1,14.460000,100,1,12.500000,700,1,14.480000,700,1,12.490000,200,2,14.520000,200,2,12.460000,100,1,14.560000,800,2,12.430000,700,1,14.600000,700,1,ARL,332385501
2025-07-17T16:07:22.817507809Z,2025-07-17T16:07:22.817341789Z,10,2,1108,C,A,13,14.96,100,0,166020,276946309,13.110000,100,1,13.690000,15,1,12.980000,200,2,13.700000,100,1,12.900000,2,1,13.850000,2,1,12.860000,100,1,14.140000,100,1,12.730000,100,1,14.280000,100,1,12.710000,100,1,14.460000,100,1,12.500000,700,1,14.480000,700,1,12.490000,200,2,14.520000,200,2,12.460000,100,1,14.560000,800,2,12.430000,700,1,14.600000,700,1,ARL,331929633
2025-07-17T16:07:22.817507809Z,2025-07-17T16:07:22.817341789Z,10,2,1108,A,A,-1,14.66,100,130,166020,276946309,13.110000,100,1,13.690000,15,1,12.980000,200,2,13.700000,100,1,12.900000,2,1,13.850000,2,1,12.860000,100,1,14.140000,100,1,12.730000,100,1,14.280000,100,1,12.710000,100,1,14.460000,100,1,12.500000,700,1,14.480000,700,1,12.490000,200,2,14.520000,200,2,12.460000,100,1,14.560000,800,2,12.430000,700,1,14.600000,700,1,ARL,332385565
2025-07-17T16:07:22.817624699Z,2025-07-17T16:07:22.817459170Z,10,2,1108,C,A,17,15.38,100,0,165529,276946313,13.110000,100,1,13.690000,15,1,12.980000,200,2,13.700000,100,1,12.900000,2,1,13.850000,2,1,12.860000,100,1,14.140000,100,1,12.730000,100,1,14.280000,100,1,12.710000,100,1,14.460000,100,1,12.500000,700,1,14.480000,700,1,12.490000,200,2,14.520000,200,2,12.460000,100,1,14.560000,800,2,12.430000,700,1,14.600000,700,1,ARL,331929445
2025-07-17T16:07:22.817624699Z,2025-07-17T16:07:22.817459170Z,10,2,1108,A,A,-1,15.07,100,130,165529,276946313,13.110000,100,1,13.690000,15,1,12.980000,200,2,13.700000,100,1,12.900000,2,1,13.850000,2,1,12.860000,100,1,14.140000,100,1,12.730000,100,1,14.280000,100,1,12.710000,100,1,14.460000,100,1,12.500000,700,1,14.480000,700,1,12.490000,200,2,14.520000,200,2,12.460000,100,1,14.560000,800,2,12.430000,700,1,14.600000,700,1,ARL,332385569
2025-07-17T16:07:22.818565766Z,2025-07-17T16:07:22.818400003Z,10,2,1108,C,A,19,16.08,100,0,165763,276946327,13.110000,100,1,13.690000,15,1,12.980000,200,2,13.700000,100,1,12.900000,2,1,13.850000,2,1,12.860000,100,1,14.140000,100,1,12.730000,100,1,14.280000,100,1,12.710000,100,1,14.460000,100,1,12.500000,700,1,14.480000,700,1,12.490000,200,2,14.520000,200,2,12.460000,100,1,14.560000,800,2,12.430000,700,1,14.600000,700,1,ARL,331934377
2025-07-17T16:07:22.818565766Z,2025-07-17T16:07:22.818400003Z,10,2,1108,A,A,-1,15.76,100,130,165763,276946327,13.110000,100,1,13.690000,15,1,12.980000,200,2,13.700000,100,1,12.900000,2,1,13.850000,2,1,12.860000,100,1,14.140000,100,1,12.730000,100,1,14.280000,100,1,12.710000,100,1,14.460000,100,1,12.500000,700,1,14.480000,700,1,12.490000,200,2,14.520000,200,2,12.460000,100,1,14.560000,800,2,12.430000,700,1,14.600000,700,1,ARL,332385585
2025-07-17T16:07:22.819710983Z,2025-07-17T16:07:22.819545360Z,10,2,1108,C,A,22,17.61,100,0,165623,276946336,13.110000,100,1,13.690000,15,1,12.980000,200,2,13.700000,100,1,12.900000,2,1,13.850000,2,1,12.860000,100,1,14.140000,100,1,12.730000,100,1,14.280000,100,1,12.710000,100,1,14.460000,100,1,12.500000,700,1,14.480000,700,1,12.490000,200,2,14.520000,200,2,12.460000,100,1,14.560000,800,2,12.430000,700,1,14.600000,700,1,ARL,331942981
2025-07-17T16:07:22.819710983Z,2025-07-17T16:07:22.819545360Z,10,2,1108,A,A,-1,17.40,100,130,165623,276946336,13.110000,100,1,13.690000,15,1,12.980000,200,2,13.700000,100,1,12.900000,2,1,13.850000,2,1,12.860000,100,1,14.140000,100,1,12.730000,100,1,14.280000,100,1,12.710000,100,1,14.460000,100,1,12.500000,700,1,14.480000,700,1,12.490000,200,2,14.520000,200,2,12.460000,100,1,14.560000,800,2,12.430000,700,1,14.600000,700,1,ARL,332385593
2025-07-17T16:07:22.819772408Z,2025-07-17T16:07:22.819606945Z,10,2,1108,C,A,10,14.63,100,0,165463,276946337,13.110000,100,1,13.690000,15,1,12.980000,200,2,13.700000,100,1,12.900000,2,1,13.850000,2,1,12.860000,100,1,14.140000,100,1,12.730000,100,1,14.280000,100,1,12.710000,100,1,14.460000,100,1,12.500000,700,1,14.480000,700,1,12.490000,200,2,14.520000,200,2,12.460000,100,1,14.560000,800,2,12.430000,700,1,14.600000,700,1,ARL,331927477
2025-07-17T16:07:22.819772408Z,2025-07-17T16:07:22.819606945Z,10,2,1108,A,A,7,14.49,100,130,165463,276946337,13.110000,100,1,13.690000,15,1,12.980000,200,2,13.700000,100,1,12.900000,2,1,13.850000,2,1,12.860000,100,1,14.140000,100,1,12.730000,100,1,14.280000,100,1,12.710000,100,1,14.460000,100,1,12.500000,700,1,14.480000,700,1,12.490000,200,2,14.490000,100,1,12.460000,100,1,14.520000,200,2,12.430000,700,1,14.560000,800,2,ARL,332385597
2025-07-17T16:07:22.821165451Z,2025-07-17T16:07:22.821000003Z,10,2,1108,C,A,3,14.14,100,130,165448,276946343,13.110000,100,1,13.690000,15,1,12.980000,200,2,13.700000,100,1,12.900000,2,1,13.850000,2,1,12.860000,100,1,14.280000,100,1,12.730000,100,1,14.460000,100,1,12.710000,100,1,14.480000,700,1,12.500000,700,1,14.490000,100,1,12.490000,200,2,14.520000,200,2,12.460000,100,1,14.560000,800,2,12.430000,700,1,14.600000,700,1,ARL,331943133
2025-07-17T16:07:22.821218207Z,2025-07-17T16:07:22.821052982Z,10,2,1108,A,A,3,13.97,100,130,165225,276946344,13.110000,100,1,13.690000,15,1,12.980000,200,2,13.700000,100,1,12.900000,2,1,13.850000,2,1,12.860000,100,1,13.970000,100,1,12.730000,100,1,14.280000,100,1,12.710000,100,1,14.460000,100,1,12.500000,700,1,14.480000,700,1,12.490000,200,2,14.490000,100,1,12.460000,100,1,14.520000,200,2,12.430000,700,1,14.560000,800,2,ARL,332385613
2025-07-17T16:07:22.832119220Z,2025-07-17T16:07:22.831949887Z,10,2,1108,C,A,14,14.96,100,0,169333,276946801,13.110000,100,1,13.690000,15,1,12.980000,200,2,13.700000,100,1,12.900000,2,1,13.850000,2,1,12.860000,100,1,13.970000,100,1,12.730000,100,1,14.280000,100,1,12.710000,100,1,14.460000,100,1,12.500000,700,1,14.480000,700,1,12.490000,200,2,14.490000,100,1,12.460000,100,1,14.520000,200,2,12.430000,700,1,14.560000,800,2,ARL,331928129
2025-07-17T16:07:22.832119220Z,2025-07-17T16:07:22.831949887Z,10,2,1108,A,A,-1,14.66,100,128,169333,276946801,13.110000,100,1,13.690000,15,1,12.980000,200,2,13.700000,100,1,12.900000,2,1,13.850000,2,1,12.860000,100,1,13.970000,100,1,12.730000,100,1,14.280000,100,1,12.710000,100,1,14.460000,100,1,12.500000,700,1,14.480000,700,1,12.490000,200,2,14.490000,100,1,12.460000,100,1,14.520000,200,2,12.430000,700,1,14.560000,800,2,ARL,332386121
2025-07-17T16:07:28.273823608Z,2025-07-17T16:07:28.273658191Z,10,2,1108,C,A,0,13.69,15,130,165417,277012951,13.110000,100,1,13.700000,100,1,12.980000,200,2,13.850000,2,1,12.900000,2,1,13.970000,100,1,12.860000,100,1,14.280000,100,1,12.730000,100,1,14.460000,100,1,12.710000,100,1,14.480000,700,1,12.500000,700,1,14.490000,100,1,12.490000,200,2,14.520000,200,2,12.460000,100,1,14.560000,800,2,12.430000,700,1,14.600000,700,1,ARL,332385317
2025-07-17T16:07:28.700981149Z,2025-07-17T16:07:28.700815737Z,10,2,1108,C,A,0,13.70,100,130,165412,277019711,13.110000,100,1,13.850000,2,1,12.980000,200,2,13.970000,100,1,12.900000,2,1,14.280000,100,1,12.860000,100,1,14.460000,100,1,12.730000,100,1,14.480000,700,1,12.710000,100,1,14.490000,100,1,12.500000,700,1,14.520000,200,2,12.490000,200,2,14.560000,800,2,12.460000,100,1,14.600000,700,1,12.430000,700,1,14.660000,200,2,ARL,332385325
2025-07-17T16:07:28.701396669Z,2025-07-17T16:07:28.701230409Z,10,2,1108,C,B,2,12.90,2,0,166260,277019718,13.110000,100,1,13.850000,2,1,12.980000,200,2,13.970000,100,1,12.860000,100,1,14.280000,100,1,12.730000,100,1,14.460000,100,1,12.710000,100,1,14.480000,700,1,12.500000,700,1,14.490000,100,1,12.490000,200,2,14.520000,200,2,12.460000,100,1,14.560000,800,2,12.430000,700,1,14.600000,700,1,12.420000,700,1,14.660000,200,2,ARL,331694297
2025-07-17T16:07:28.701396669Z,2025-07-17T16:07:28.701230409Z,10,2,1108,A,B,1,13.01,2,130,166260,277019718,13.110000,100,1,13.850000,2,1,13.010000,2,1,13.970000,100,1,12.980000,200,2,14.280000,100,1,12.860000,100,1,14.460000,100,1,12.730000,100,1,14.480000,700,1,12.710000,100,1,14.490000,100,1,12.500000,700,1,14.520000,200,2,12.490000,200,2,14.560000,800,2,12.460000,100,1,14.600000,700,1,12.430000,700,1,14.660000,200,2,ARL,332494213
2025-07-17T16:07:28.701713232Z,2025-07-17T16:07:28.701547540Z,10,2,1108,C,A,11,14.76,100,0,165692,277019720,13.110000,100,1,13.850000,2,1,13.010000,2,1,13.970000,100,1,12.980000,200,2,14.280000,100,1,12.860000,100,1,14.460000,100,1,12.730000,100,1,14.480000,700,1,12.710000,100,1,14.490000,100,1,12.500000,700,1,14.520000,200,2,12.490000,200,2,14.560000,800,2,12.460000,100,1,14.600000,700,1,12.430000,700,1,14.660000,200,2,ARL,332385501
2025-07-17T16:07:28.701713232Z,2025-07-17T16:07:28.701547540Z,10,2,1108,A,A,-1,14.82,100,130,165692,277019720,13.110000,100,1,13.850000,2,1,13.010000,2,1,13.970000,100,1,12.980000,200,2,14.280000,100,1,12.860000,100,1,14.460000,100,1,12.730000,100,1,14.480000,700,1,12.710000,100,1,14.490000,100,1,12.500000,700,1,14.520000,200,2,12.490000,200,2,14.560000,800,2,12.460000,100,1,14.600000,700,1,12.430000,700,1,14.660000,200,2,ARL,332494229
2025-07-17T16:07:28.702166297Z,2025-07-17T16:07:28.702000772Z,10,2,1108,C,A,16,15.76,100,0,165525,277019722,13.110000,100,1,13.850000,2,1,13.010000,2,1,13.970000,100,1,12.980000,200,2,14.280000,100,1,12.860000,100,1,14.460000,100,1,12.730000,100,1,14.480000,700,1,12.710000,100,1,14.490000,100,1,12.500000,700,1,14.520000,200,2,12.490000,200,2,14.560000,800,2,12.460000,100,1,14.600000,700,1,12.430000,700,1,14.660000,200,2,ARL,332385585
2025-07-17T16:07:28.702166297Z,2025-07-17T16:07:28.702000772Z,10,2,1108,A,A,-1,16.01,100,130,165525,277019722,13.110000,100,1,13.850000,2,1,13.010000,2,1,13.970000,100,1,12.980000,200,2,14.280000,100,1,12.860000,100,1,14.460000,100,1,12.730000,100,1,14.480000,700,1,12.710000,100,1,14.490000,100,1,12.500000,700,1,14.520000,200,2,12.490000,200,2,14.560000,800,2,12.460000,100,1,14.600000,700,1,12.430000,700,1,14.660000,200,2,ARL,332494245
2025-07-17T16:07:28.702642020Z,2025-07-17T16:07:28.702476699Z,10,2,1108,C,A,9,14.66,100,0,165321,277019729,13.110000,100,1,13.850000,2,1,13.010000,2,1,13.970000,100,1,12.980000,200,2,14.280000,100,1,12.860000,100,1,14.460000,100,1,12.730000,100,1,14.480000,700,1,12.710000,100,1,14.490000,100,1,12.500000,700,1,14.520000,200,2,12.490000,200,2,14.560000,800,2,12.460000,100,1,14.600000,700,1,12.430000,700,1,14.660000,100,1,ARL,332386121
2025-07-17T16:07:28.702642020Z,2025-07-17T16:07:28.702476699Z,10,2,1108,A,A,-1,14.95,100,130,165321,277019729,13.110000,100,1,13.850000,2,1,13.010000,2,1,13.970000,100,1,12.980000,200,2,14.280000,100,1,12.860000,100,1,14.460000,100,1,12.730000,100,1,14.480000,700,1,12.710000,100,1,14.490000,100,1,12.500000,700,1,14.520000,200,2,12.490000,200,2,14.560000,800,2,12.460000,100,1,14.600000,700,1,12.430000,700,1,14.660000,100,1,ARL,332494281
2025-07-17T16:07:28.703523092Z,2025-07-17T16:07:28.703357714Z,10,2,1108,C,A,9,14.66,100,0,165378,277019733,13.110000,100,1,13.850000,2,1,13.010000,2,1,13.970000,100,1,12.980000,200,2,14.280000,100,1,12.860000,100,1,14.460000,100,1,12.730000,100,1,14.480000,700,1,12.710000,100,1,14.490000,100,1,12.500000,700,1,14.520000,200,2,12.490000,200,2,14.560000,800,2,12.460000,100,1,14.600000,700,1,12.430000,700,1,14.680000,700,1,ARL,332385565
2025-07-17T16:07:28.703523092Z,2025-07-17T16:07:28.703357714Z,10,2,1108,A,A,-1,14.95,100,130,165378,277019733,13.110000,100,1,13.850000,2,1,13.010000,2,1,13.970000,100,1,12.980000,200,2,14.280000,100,1,12.860000,100,1,14.460000,100,1,12.730000,100,1,14.480000,700,1,12.710000,100,1,14.490000,100,1,12.500000,700,1,14.520000,200,2,12.490000,200,2,14.560000,800,2,12.460000,100,1,14.600000,700,1,12.430000,700,1,14.680000,700,1,ARL,332494285
2025-07-17T16:07:28.703920336Z,2025-07-17T16:07:28.703754662Z,10,2,1108,C,A,12,15.07,100,0,165674,277019735,13.110000,100,1,13.850000,2,1,13.010000,2,1,13.970000,100,1,12.980000,200,2,14.280000,100,1,12.860000,100,1,14.460000,100,1,12.730000,100,1,14.480000,700,1,12.710000,100,1,14.490000,100,1,12.500000,700,1,14.520000,200,2,12.490000,200,2,14.560000,800,2,12.460000,100,1,14.600000,700,1,12.430000,700,1,14.680000,700,1,ARL,332385569
2025-07-17T16:07:28.703920336Z,2025-07-17T16:07:28.703754662Z,10,2,1108,A,A,-1,15.37,100,130,165674,277019735,13.110000,100,1,13.850000,2,1,13.010000,2,1,13.970000,100,1,12.980000,200,2,14.280000,100,1,12.860000,100,1,14.460000,100,1,12.730000,100,1,14.480000,700,1,12.710000,100,1,14.490000,100,1,12.500000,700,1,14.520000,200,2,12.490000,200,2,14.560000,800,2,12.460000,100,1,14.600000,700,1,12.430000,700,1,14.680000,700,1,ARL,332494289
2025-07-17T16:07:28.704198103Z,2025-07-17T16:07:28.704032725Z,10,2,1108,C,A,19,17.40,100,0,165378,277019738,13.110000,100,1,13.850000,2,1,13.010000,2,1,13.970000,100,1,12.980000,200,2,14.280000,100,1,12.860000,100,1,14.460000,100,1,12.730000,100,1,14.480000,700,1,12.710000,100,1,14.490000,100,1,12.500000,700,1,14.520000,200,2,12.490000,200,2,14.560000,800,2,12.460000,100,1,14.600000,700,1,12.430000,700,1,14.680000,700,1,ARL,332385593
2025-07-17T16:07:28.704198103Z,2025-07-17T16:07:28.704032725Z,10,2,1108,A,A,-1,17.75,100,130,165378,277019738,13.110000,100,1,13.850000,2,1,13.010000,2,1,13.970000,100,1,12.980000,200,2,14.280000,100,1,12.860000,100,1,14.460000,100,1,12.730000,100,1,14.480000,700,1,12.710000,100,1,14.490000,100,1,12.500000,700,1,14.520000,200,2,12.490000,200,2,14.560000,800,2,12.460000,100,1,14.600000,700,1,12.430000,700,1,14.680000,700,1,ARL,332494297
2025-07-17T16:07:28.724201840Z,2025-07-17T16:07:28.724036175Z,10,2,1108,C,A,1,13.97,100,130,165665,277019926,13.110000,100,1,13.850000,2,1,13.010000,2,1,14.280000,100,1,12.980000,200,2,14.460000,100,1,12.860000,100,1,14.480000,700,1,12.730000,100,1,14.490000,100,1,12.710000,100,1,14.520000,200,2,12.500000,700,1,14.560000,800,2,12.490000,200,2,14.600000,700,1,12.460000,100,1,14.680000,700,1,12.430000,700,1,14.820000,100,1,ARL,332385613
2025-07-17T16:07:28.724250835Z,2025-07-17T16:07:28.724085453Z,10,2,1108,A,A,1,14.20,100,130,165382,277019929,13.110000,100,1,13.850000,2,1,13.010000,2,1,14.200000,100,1,12.980000,200,2,14.280000,100,1,12.860000,100,1,14.460000,100,1,12.730000,100,1,14.480000,700,1,12.710000,100,1,14.490000,100,1,12.500000,700,1,14.520000,200,2,12.490000,200,2,14.560000,800,2,12.460000,100,1,14.600000,700,1,12.430000,700,1,14.680000,700,1,ARL,332494893
2025-07-17T16:07:28.751828120Z,2025-07-17T16:07:28.751662660Z,10,2,1108,C,A,10,14.82,100,0,165460,277020284,13.110000,100,1,13.850000,2,1,13.010000,2,1,14.200000,100,1,12.980000,200,2,14.280000,100,1,12.860000,100,1,14.460000,100,1,12.730000,100,1,14.480000,700,1,12.710000,100,1,14.490000,100,1,12.500000,700,1,14.520000,200,2,12.490000,200,2,14.560000,800,2,12.460000,100,1,14.600000,700,1,12.430000,700,1,14.680000,700,1,ARL,332494229
2025-07-17T16:07:28.751828120Z,2025-07-17T16:07:28.751662660Z,10,2,1108,A,A,-1,15.05,100,130,165460,277020284,13.110000,100,1,13.850000,2,1,13.010000,2,1,14.200000,100,1,12.980000,200,2,14.280000,100,1,12.860000,100,1,14.460000,100,1,12.730000,100,1,14.480000,700,1,12.710000,100,1,14.490000,100,1,12.500000,700,1,14.520000,200,2,12.490000,200,2,14.560000,800,2,12.460000,100,1,14.600000,700,1,12.430000,700,1,14.680000,700,1,ARL,332495781
2025-07-17T16:07:28.831160987Z,2025-07-17T16:07:28.830995364Z,10,2,1108,C,A,5,14.49,100,130,165623,277021007,13.110000,100,1,13.850000,2,1,13.010000,2,1,14.200000,100,1,12.980000,200,2,14.280000,100,1,12.860000,100,1,14.460000,100,1,12.730000,100,1,14.480000,700,1,12.710000,100,1,14.520000,200,2,12.500000,700,1,14.560000,800,2,12.490000,200,2,14.600000,700,1,12.460000,100,1,14.680000,700,1,12.430000,700,1,14.950000,200,2,ARL,332385597
2025-07-17T16:07:28.831291377Z,2025-07-17T16:07:28.831125667Z,10,2,1108,A,A,9,14.77,100,130,165710,277021012,13.110000,100,1,13.850000,2,1,13.010000,2,1,14.200000,100,1,12.980000,200,2,14.280000,100,1,12.860000,100,1,14.460000,100,1,12.730000,100,1,14.480000,700,1,12.710000,100,1,14.520000,200,2,12.500000,700,1,14.560000,800,2,12.490000,200,2,14.600000,700,1,12.460000,100,1,14.680000,700,1,12.430000,700,1,14.770000,100,1,ARL,332497653
2025-07-17T16:07:29.214667270Z,2025-07-17T16:07:29.214500816Z,10,2,1108,A,A,1,13.86,100,128,166454,277029015,13.110000,100,1,13.850000,2,1,13.010000,2,1,13.860000,100,1,12.980000,200,2,14.200000,100,1,12.860000,100,1,14.280000,100,1,12.730000,100,1,14.460000,100,1,12.710000,100,1,14.480000,700,1,12.500000,700,1,14.520000,200,2,12.490000,200,2,14.560000,800,2,12.460000,100,1,14.600000,700,1,12.430000,700,1,14.680000,700,1,ARL,332508813
2025-07-17T16:07:29.215458844Z,2025-07-17T16:07:29.215292291Z,10,2,1108,C,A,12,15.05,100,0,166553,277029273,13.110000,100,1,13.850000,2,1,13.010000,2,1,13.860000,100,1,12.980000,200,2,14.200000,100,1,12.860000,100,1,14.280000,100,1,12.730000,100,1,14.460000,100,1,12.710000,100,1,14.480000,700,1,12.500000,700,1,14.520000,200,2,12.490000,200,2,14.560000,800,2,12.460000,100,1,14.600000,700,1,12.430000,700,1,14.680000,700,1,ARL,332495781
2025-07-17T16:07:29.215458844Z,2025-07-17T16:07:29.215292291Z,10,2,1108,A,A,-1,14.93,100,128,166553,277029273,13.110000,100,1,13.850000,2,1,13.010000,2,1,13.860000,100,1,12.980000,200,2,14.200000,100,1,12.860000,100,1,14.280000,100,1,12.730000,100,1,14.460000,100,1,12.710000,100,1,14.480000,700,1,12.500000,700,1,14.520000,200,2,12.490000,200,2,14.560000,800,2,12.460000,100,1,14.600000,700,1,12.430000,700,1,14.680000,700,1,ARL,332508997
2025-07-17T16:08:20.816252850Z,2025-07-17T16:08:20.816087447Z,10,2,1108,A,A,0,13.68,15,130,165403,277732167,13.110000,100,1,13.680000,15,1,13.010000,2,1,13.850000,2,1,12.980000,200,2,13.860000,100,1,12.860000,100,1,14.200000,100,1,12.730000,100,1,14.280000,100,1,12.710000,100,1,14.460000,100,1,12.500000,700,1,14.480000,700,1,12.490000,200,2,14.520000,200,2,12.460000,100,1,14.560000,800,2,12.430000,700,1,14.600000,700,1,ARL,333436357
2025-07-17T16:08:20.816366205Z,2025-07-17T16:08:20.816200644Z,10,2,1108,C,A,2,13.86,100,0,165561,277732170,13.110000,100,1,13.680000,15,1,13.010000,2,1,13.850000,2,1,12.980000,200,2,14.200000,100,1,12.860000,100,1,14.280000,100,1,12.730000,100,1,14.460000,100,1,12.710000,100,1,14.480000,700,1,12.500000,700,1,14.520000,200,2,12.490000,200,2,14.560000,800,2,12.460000,100,1,14.600000,700,1,12.430000,700,1,14.680000,700,1,ARL,332508813
2025-07-17T16:08:20.816366205Z,2025-07-17T16:08:20.816200644Z,10,2,1108,A,A,1,13.69,100,130,165561,277732170,13.110000,100,1,13.680000,15,1,13.010000,2,1,13.690000,100,1,12.980000,200,2,13.850000,2,1,12.860000,100,1,14.200000,100,1,12.730000,100,1,14.280000,100,1,12.710000,100,1,14.460000,100,1,12.500000,700,1,14.480000,700,1,12.490000,200,2,14.520000,200,2,12.460000,100,1,14.560000,800,2,12.430000,700,1,14.600000,700,1,ARL,333436361
2025-07-17T16:08:20.817097587Z,2025-07-17T16:08:20.816932150Z,10,2,1108,C,A,12,14.93,100,0,165437,277732194,13.110000,100,1,13.680000,15,1,13.010000,2,1,13.690000,100,1,12.980000,200,2,13.850000,2,1,12.860000,100,1,14.200000,100,1,12.730000,100,1,14.280000,100,1,12.710000,100,1,14.460000,100,1,12.500000,700,1,14.480000,700,1,12.490000,200,2,14.520000,200,2,12.460000,100,1,14.560000,800,2,12.430000,700,1,14.600000,700,1,ARL,332508997
2025-07-17T16:08:20.817097587Z,2025-07-17T16:08:20.816932150Z,10,2,1108,A,A,-1,14.75,100,130,165437,277732194,13.110000,100,1,13.680000,15,1,13.010000,2,1,13.690000,100,1,12.980000,200,2,13.850000,2,1,12.860000,100,1,14.200000,100,1,12.730000,100,1,14.280000,100,1,12.710000,100,1,14.460000,100,1,12.500000,700,1,14.480000,700,1,12.490000,200,2,14.520000,200,2,12.460000,100,1,14.560000,800,2,12.430000,700,1,14.600000,700,1,ARL,333436397
2025-07-17T16:08:20.818725102Z,2025-07-17T16:08:20.818559377Z,10,2,1108,C,A,16,15.37,100,0,165725,277732213,13.110000,100,1,13.680000,15,1,13.010000,2,1,13.690000,100,1,12.980000,200,2,13.850000,2,1,12.860000,100,1,14.200000,100,1,12.730000,100,1,14.280000,100,1,12.710000,100,1,14.460000,100,1,12.500000,700,1,14.480000,700,1,12.490000,200,2,14.520000,200,2,12.460000,100,1,14.560000,800,2,12.430000,700,1,14.600000,700,1,ARL,332494289
2025-07-17T16:08:20.818725102Z,2025-07-17T16:08:20.818559377Z,10,2,1108,A,A,-1,15.06,100,130,165725,277732213,13.110000,100,1,13.680000,15,1,13.010000,2,1,13.690000,100,1,12.980000,200,2,13.850000,2,1,12.860000,100,1,14.200000,100,1,12.730000,100,1,14.280000,100,1,12.710000,100,1,14.460000,100,1,12.500000,700,1,14.480000,700,1,12.490000,200,2,14.520000,200,2,12.460000,100,1,14.560000,800,2,12.430000,700,1,14.600000,700,1,ARL,333436421
2025-07-17T16:08:20.819130820Z,2025-07-17T16:08:20.818965359Z,10,2,1108,C,A,13,14.95,100,0,165461,277732216,13.110000,100,1,13.680000,15,1,13.010000,2,1,13.690000,100,1,12.980000,200,2,13.850000,2,1,12.860000,100,1,14.200000,100,1,12.730000,100,1,14.280000,100,1,12.710000,100,1,14.460000,100,1,12.500000,700,1,14.480000,700,1,12.490000,200,2,14.520000,200,2,12.460000,100,1,14.560000,800,2,12.430000,700,1,14.600000,700,1,ARL,332494285
2025-07-17T16:08:20.819130820Z,2025-07-17T16:08:20.818965359Z,10,2,1108,A,A,-1,14.65,100,130,165461,277732216,13.110000,100,1,13.680000,15,1,13.010000,2,1,13.690000,100,1,12.980000,200,2,13.850000,2,1,12.860000,100,1,14.200000,100,1,12.730000,100,1,14.280000,100,1,12.710000,100,1,14.460000,100,1,12.500000,700,1,14.480000,700,1,12.490000,200,2,14.520000,200,2,12.460000,100,1,14.560000,800,2,12.430000,700,1,14.600000,700,1,ARL,333436425
2025-07-17T16:08:20.819767091Z,2025-07-17T16:08:20.819601669Z,10,2,1108,C,A,22,17.75,100,0,165422,277732221,13.110000,100,1,13.680000,15,1,13.010000,2,1,13.690000,100,1,12.980000,200,2,13.850000,2,1,12.860000,100,1,14.200000,100,1,12.730000,100,1,14.280000,100,1,12.710000,100,1,14.460000,100,1,12.500000,700,1,14.480000,700,1,12.490000,200,2,14.520000,200,2,12.460000,100,1,14.560000,800,2,12.430000,700,1,14.600000,700,1,ARL,332494297
2025-07-17T16:08:20.819767091Z,2025-07-17T16:08:20.819601669Z,10,2,1108,A,A,-1,17.39,100,130,165422,277732221,13.110000,100,1,13.680000,15,1,13.010000,2,1,13.690000,100,1,12.980000,200,2,13.850000,2,1,12.860000,100,1,14.200000,100,1,12.730000,100,1,14.280000,100,1,12.710000,100,1,14.460000,100,1,12.500000,700,1,14.480000,700,1,12.490000,200,2,14.520000,200,2,12.460000,100,1,14.560000,800,2,12.430000,700,1,14.600000,700,1,ARL,333436441
2025-07-17T16:08:20.820666169Z,2025-07-17T16:08:20.820500575Z,10,2,1108,C,A,19,16.01,100,0,165594,277732228,13.110000,100,1,13.680000,15,1,13.010000,2,1,13.690000,100,1,12.980000,200,2,13.850000,2,1,12.860000,100,1,14.200000,100,1,12.730000,100,1,14.280000,100,1,12.710000,100,1,14.460000,100,1,12.500000,700,1,14.480000,700,1,12.490000,200,2,14.520000,200,2,12.460000,100,1,14.560000,800,2,12.430000,700,1,14.600000,700,1,ARL,332494245
2025-07-17T16:08:20.820666169Z,2025-07-17T16:08:20.820500575Z,10,2,1108,A,A,-1,15.75,100,130,165594,277732228,13.110000,100,1,13.680000,15,1,13.010000,2,1,13.690000,100,1,12.980000,200,2,13.850000,2,1,12.860000,100,1,14.200000,100,1,12.730000,100,1,14.280000,100,1,12.710000,100,1,14.460000,100,1,12.500000,700,1,14.480000,700,1,12.490000,200,2,14.520000,200,2,12.460000,100,1,14.560000,800,2,12.430000,700,1,14.600000,700,1,ARL,333436449
2025-07-17T16:08:20.822089544Z,2025-07-17T16:08:20.821924168Z,10,2,1108,C,A,3,14.20,100,130,165376,277732239,13.110000,100,1,13.680000,15,1,13.010000,2,1,13.690000,100,1,12.980000,200,2,13.850000,2,1,12.860000,100,1,14.280000,100,1,12.730000,100,1,14.460000,100,1,12.710000,100,1,14.480000,700,1,12.500000,700,1,14.520000,200,2,12.490000,200,2,14.560000,800,2,12.460000,100,1,14.600000,700,1,12.430000,700,1,14.650000,100,1,ARL,332494893
2025-07-17T16:08:20.822139541Z,2025-07-17T16:08:20.821974299Z,10,2,1108,A,A,3,13.96,100,130,165242,277732240,13.110000,100,1,13.680000,15,1,13.010000,2,1,13.690000,100,1,12.980000,200,2,13.850000,2,1,12.860000,100,1,13.960000,100,1,12.730000,100,1,14.280000,100,1,12.710000,100,1,14.460000,100,1,12.500000,700,1,14.480000,700,1,12.490000,200,2,14.520000,200,2,12.460000,100,1,14.560000,800,2,12.430000,700,1,14.600000,700,1,ARL,333436473
2025-07-17T16:08:20.830110499Z,2025-07-17T16:08:20.829945074Z,10,2,1108,C,A,14,14.95,100,0,165425,277732299,13.110000,100,1,13.680000,15,1,13.010000,2,1,13.690000,100,1,12.980000,200,2,13.850000,2,1,12.860000,100,1,13.960000,100,1,12.730000,100,1,14.280000,100,1,12.710000,100,1,14.460000,100,1,12.500000,700,1,14.480000,700,1,12.490000,200,2,14.520000,200,2,12.460000,100,1,14.560000,800,2,12.430000,700,1,14.600000,700,1,ARL,332494281
2025-07-17T16:08:20.830110499Z,2025-07-17T16:08:20.829945074Z,10,2,1108,A,A,-1,14.65,100,130,165425,277732299,13.110000,100,1,13.680000,15,1,13.010000,2,1,13.690000,100,1,12.980000,200,2,13.850000,2,1,12.860000,100,1,13.960000,100,1,12.730000,100,1,14.280000,100,1,12.710000,100,1,14.460000,100,1,12.500000,700,1,14.480000,700,1,12.490000,200,2,14.520000,200,2,12.460000,100,1,14.560000,800,2,12.430000,700,1,14.600000,700,1,ARL,333436589
2025-07-17T16:08:20.966229266Z,2025-07-17T16:08:20.966063681Z,10,2,1108,C,A,13,14.77,100,0,165585,277733304,13.110000,100,1,13.680000,15,1,13.010000,2,1,13.690000,100,1,12.980000,200,2,13.850000,2,1,12.860000,100,1,13.960000,100,1,12.730000,100,1,14.280000,100,1,12.710000,100,1,14.460000,100,1,12.500000,700,1,14.480000,700,1,12.490000,200,2,14.520000,200,2,12.460000,100,1,14.560000,800,2,12.430000,700,1,14.600000,700,1,ARL,332497653
2025-07-17T16:08:20.966229266Z,2025-07-17T16:08:20.966063681Z,10,2,1108,A,A,6,14.48,100,130,165585,277733304,13.110000,100,1,13.680000,15,1,13.010000,2,1,13.690000,100,1,12.980000,200,2,13.850000,2,1,12.860000,100,1,13.960000,100,1,12.730000,100,1,14.280000,100,1,12.710000,100,1,14.460000,100,1,12.500000,700,1,14.480000,800,2,12.490000,200,2,14.520000,200,2,12.460000,100,1,14.560000,800,2,12.430000,700,1,14.600000,700,1,ARL,333438545
2025-07-17T16:08:22.998168186Z,2025-07-17T16:08:22.998002821Z,10,2,1108,C,A,0,13.68,15,130,165365,277766492,13.110000,100,1,13.690000,100,1,13.010000,2,1,13.850000,2,1,12.980000,200,2,13.960000,100,1,12.860000,100,1,14.280000,100,1,12.730000,100,1,14.460000,100,1,12.710000,100,1,14.480000,800,2,12.500000,700,1,14.520000,200,2,12.490000,200,2,14.560000,800,2,12.460000,100,1,14.600000,700,1,12.430000,700,1,14.650000,200,2,ARL,333436357
2025-07-17T16:08:27.482509684Z,2025-07-17T16:08:27.482344236Z,10,2,1108,C,A,0,13.69,100,130,165448,277841171,13.110000,100,1,13.850000,2,1,13.010000,2,1,13.960000,100,1,12.980000,200,2,14.280000,100,1,12.860000,100,1,14.460000,100,1,12.730000,100,1,14.480000,800,2,12.710000,100,1,14.520000,200,2,12.500000,700,1,14.560000,800,2,12.490000,200,2,14.600000,700,1,12.460000,100,1,14.650000,200,2,12.430000,700,1,14.680000,700,1,ARL,333436361
2025-07-17T16:08:27.483241007Z,2025-07-17T16:08:27.483075481Z,10,2,1108,C,A,10,14.75,100,0,165526,277841175,13.110000,100,1,13.850000,2,1,13.010000,2,1,13.960000,100,1,12.980000,200,2,14.280000,100,1,12.860000,100,1,14.460000,100,1,12.730000,100,1,14.480000,800,2,12.710000,100,1,14.520000,200,2,12.500000,700,1,14.560000,800,2,12.490000,200,2,14.600000,700,1,12.460000,100,1,14.650000,200,2,12.430000,700,1,14.680000,700,1,ARL,333436397
2025-07-17T16:08:27.483241007Z,2025-07-17T16:08:27.483075481Z,10,2,1108,A,A,-1,14.99,100,130,165526,277841175,13.110000,100,1,13.850000,2,1,13.010000,2,1,13.960000,100,1,12.980000,200,2,14.280000,100,1,12.860000,100,1,14.460000,100,1,12.730000,100,1,14.480000,800,2,12.710000,100,1,14.520000,200,2,12.500000,700,1,14.560000,800,2,12.490000,200,2,14.600000,700,1,12.460000,100,1,14.650000,200,2,12.430000,700,1,14.680000,700,1,ARL,333581389
2025-07-17T16:08:27.483585892Z,2025-07-17T16:08:27.483420069Z,10,2,1108,C,A,5,14.52,100,0,165823,277841178,13.110000,100,1,13.850000,2,1,13.010000,2,1,13.960000,100,1,12.980000,200,2,14.280000,100,1,12.860000,100,1,14.460000,100,1,12.730000,100,1,14.480000,800,2,12.710000,100,1,14.520000,100,1,12.500000,700,1,14.560000,800,2,12.490000,200,2,14.600000,700,1,12.460000,100,1,14.650000,200,2,12.430000,700,1,14.680000,700,1,ARL,328780577
2025-07-17T16:08:27.483585892Z,2025-07-17T16:08:27.483420069Z,10,2,1108,A,A,-1,14.74,100,130,165823,277841178,13.110000,100,1,13.850000,2,1,13.010000,2,1,13.960000,100,1,12.980000,200,2,14.280000,100,1,12.860000,100,1,14.460000,100,1,12.730000,100,1,14.480000,800,2,12.710000,100,1,14.520000,100,1,12.500000,700,1,14.560000,800,2,12.490000,200,2,14.600000,700,1,12.460000,100,1,14.650000,200,2,12.430000,700,1,14.680000,700,1,ARL,333581393
2025-07-17T16:08:27.484079224Z,2025-07-17T16:08:27.483913735Z,10,2,1108,C,A,8,14.65,100,0,165489,277841218,13.110000,100,1,13.850000,2,1,13.010000,2,1,13.960000,100,1,12.980000,200,2,14.280000,100,1,12.860000,100,1,14.460000,100,1,12.730000,100,1,14.480000,800,2,12.710000,100,1,14.520000,100,1,12.500000,700,1,14.560000,800,2,12.490000,200,2,14.600000,700,1,12.460000,100,1,14.650000,100,1,12.430000,700,1,14.680000,700,1,ARL,333436589
2025-07-17T16:08:27.484079224Z,2025-07-17T16:08:27.483913735Z,10,2,1108,A,A,-1,14.94,100,130,165489,277841218,13.110000,100,1,13.850000,2,1,13.010000,2,1,13.960000,100,1,12.980000,200,2,14.280000,100,1,12.860000,100,1,14.460000,100,1,12.730000,100,1,14.480000,800,2,12.710000,100,1,14.520000,100,1,12.500000,700,1,14.560000,800,2,12.490000,200,2,14.600000,700,1,12.460000,100,1,14.650000,100,1,12.430000,700,1,14.680000,700,1,ARL,333581409
2025-07-17T16:08:27.484859188Z,2025-07-17T16:08:27.484693568Z,10,2,1108,C,A,20,17.39,100,0,165620,277841226,13.110000,100,1,13.850000,2,1,13.010000,2,1,13.960000,100,1,12.980000,200,2,14.280000,100,1,12.860000,100,1,14.460000,100,1,12.730000,100,1,14.480000,800,2,12.710000,100,1,14.520000,100,1,12.500000,700,1,14.560000,800,2,12.490000,200,2,14.600000,700,1,12.460000,100,1,14.650000,100,1,12.430000,700,1,14.680000,700,1,ARL,333436441
2025-07-17T16:08:27.484859188Z,2025-07-17T16:08:27.484693568Z,10,2,1108,A,A,-1,17.73,100,130,165620,277841226,13.110000,100,1,13.850000,2,1,13.010000,2,1,13.960000,100,1,12.980000,200,2,14.280000,100,1,12.860000,100,1,14.460000,100,1,12.730000,100,1,14.480000,800,2,12.710000,100,1,14.520000,100,1,12.500000,700,1,14.560000,800,2,12.490000,200,2,14.600000,700,1,12.460000,100,1,14.650000,100,1,12.430000,700,1,14.680000,700,1,ARL,333581425
2025-07-17T16:08:27.484965957Z,2025-07-17T16:08:27.484800296Z,10,2,1108,C,A,8,14.65,100,0,165661,277841228,13.110000,100,1,13.850000,2,1,13.010000,2,1,13.960000,100,1,12.980000,200,2,14.280000,100,1,12.860000,100,1,14.460000,100,1,12.730000,100,1,14.480000,800,2,12.710000,100,1,14.520000,100,1,12.500000,700,1,14.560000,800,2,12.490000,200,2,14.600000,700,1,12.460000,100,1,14.680000,700,1,12.430000,700,1,14.740000,100,1,ARL,333436425
2025-07-17T16:08:27.484965957Z,2025-07-17T16:08:27.484800296Z,10,2,1108,A,A,-1,14.94,100,130,165661,277841228,13.110000,100,1,13.850000,2,1,13.010000,2,1,13.960000,100,1,12.980000,200,2,14.280000,100,1,12.860000,100,1,14.460000,100,1,12.730000,100,1,14.480000,800,2,12.710000,100,1,14.520000,100,1,12.500000,700,1,14.560000,800,2,12.490000,200,2,14.600000,700,1,12.460000,100,1,14.680000,700,1,12.430000,700,1,14.740000,100,1,ARL,333581429
2025-07-17T16:08:27.484978859Z,2025-07-17T16:08:27.484813280Z,10,2,1108,C,A,16,15.75,100,0,165579,277841229,13.110000,100,1,13.850000,2,1,13.010000,2,1,13.960000,100,1,12.980000,200,2,14.280000,100,1,12.860000,100,1,14.460000,100,1,12.730000,100,1,14.480000,800,2,12.710000,100,1,14.520000,100,1,12.500000,700,1,14.560000,800,2,12.490000,200,2,14.600000,700,1,12.460000,100,1,14.680000,700,1,12.430000,700,1,14.740000,100,1,ARL,333436449
2025-07-17T16:08:27.484978859Z,2025-07-17T16:08:27.484813280Z,10,2,1108,A,A,-1,16.06,100,130,165579,277841229,13.110000,100,1,13.850000,2,1,13.010000,2,1,13.960000,100,1,12.980000,200,2,14.280000,100,1,12.860000,100,1,14.460000,100,1,12.730000,100,1,14.480000,800,2,12.710000,100,1,14.520000,100,1,12.500000,700,1,14.560000,800,2,12.490000,200,2,14.600000,700,1,12.460000,100,1,14.680000,700,1,12.430000,700,1,14.740000,100,1,ARL,333581433
2025-07-17T16:08:27.485352204Z,2025-07-17T16:08:27.485186411Z,10,2,1108,C,A,12,15.06,100,0,165793,277841231,13.110000,100,1,13.850000,2,1,13.010000,2,1,13.960000,100,1,12.980000,200,2,14.280000,100,1,12.860000,100,1,14.460000,100,1,12.730000,100,1,14.480000,800,2,12.710000,100,1,14.520000,100,1,12.500000,700,1,14.560000,800,2,12.490000,200,2,14.600000,700,1,12.460000,100,1,14.680000,700,1,12.430000,700,1,14.740000,100,1,ARL,333436421
2025-07-17T16:08:27.485352204Z,2025-07-17T16:08:27.485186411Z,10,2,1108,A,A,-1,15.36,100,130,165793,277841231,13.110000,100,1,13.850000,2,1,13.010000,2,1,13.960000,100,1,12.980000,200,2,14.280000,100,1,12.860000,100,1,14.460000,100,1,12.730000,100,1,14.480000,800,2,12.710000,100,1,14.520000,100,1,12.500000,700,1,14.560000,800,2,12.490000,200,2,14.600000,700,1,12.460000,100,1,14.680000,700,1,12.430000,700,1,14.740000,100,1,ARL,333581441
2025-07-17T16:08:27.487263276Z,2025-07-17T16:08:27.487097702Z,10,2,1108,C,A,5,14.52,100,0,165574,277841319,13.110000,100,1,13.850000,2,1,13.010000,2,1,13.960000,100,1,12.980000,200,2,14.280000,100,1,12.860000,100,1,14.460000,100,1,12.730000,100,1,14.480000,800,2,12.710000,100,1,14.560000,800,2,12.500000,700,1,14.600000,700,1,12.490000,200,2,14.680000,700,1,12.460000,100,1,14.740000,100,1,12.430000,700,1,14.940000,200,2,ARL,328780597
2025-07-17T16:08:27.487263276Z,2025-07-17T16:08:27.487097702Z,10,2,1108,A,A,8,14.74,100,130,165574,277841319,13.110000,100,1,13.850000,2,1,13.010000,2,1,13.960000,100,1,12.980000,200,2,14.280000,100,1,12.860000,100,1,14.460000,100,1,12.730000,100,1,14.480000,800,2,12.710000,100,1,14.560000,800,2,12.500000,700,1,14.600000,700,1,12.490000,200,2,14.680000,700,1,12.460000,100,1,14.740000,200,2,12.430000,700,1,14.940000,200,2,ARL,333581481
2025-07-17T16:08:27.492258906Z,2025-07-17T16:08:27.492093401Z,10,2,1108,C,A,4,14.48,100,130,165505,277841396,13.110000,100,1,13.850000,2,1,13.010000,2,1,13.960000,100,1,12.980000,200,2,14.280000,100,1,12.860000,100,1,14.460000,100,1,12.730000,100,1,14.480000,700,1,12.710000,100,1,14.560000,800,2,12.500000,700,1,14.600000,700,1,12.490000,200,2,14.680000,700,1,12.460000,100,1,14.740000,200,2,12.430000,700,1,14.940000,200,2,ARL,333438545
2025-07-17T16:08:27.492385750Z,2025-07-17T16:08:27.492220454Z,10,2,1108,A,A,9,14.75,100,130,165296,277841397,13.110000,100,1,13.850000,2,1,13.010000,2,1,13.960000,100,1,12.980000,200,2,14.280000,100,1,12.860000,100,1,14.460000,100,1,12.730000,100,1,14.480000,700,1,12.710000,100,1,14.560000,800,2,12.500000,700,1,14.600000,700,1,12.490000,200,2,14.680000,700,1,12.460000,100,1,14.740000,200,2,12.430000,700,1,14.750000,100,1,ARL,333581569
2025-07-17T16:08:27.496936122Z,2025-07-17T16:08:27.496770678Z,10,2,1108,C,A,1,13.96,100,130,165444,277841427,13.110000,100,1,13.850000,2,1,13.010000,2,1,14.280000,100,1,12.980000,200,2,14.460000,100,1,12.860000,100,1,14.480000,700,1,12.730000,100,1,14.560000,800,2,12.710000,100,1,14.600000,700,1,12.500000,700,1,14.680000,700,1,12.490000,200,2,14.740000,200,2,12.460000,100,1,14.750000,100,1,12.430000,700,1,14.940000,200,2,ARL,333436473
2025-07-17T16:08:27.496987832Z,2025-07-17T16:08:27.496822540Z,10,2,1108,A,A,1,14.19,100,130,165292,277841428,13.110000,100,1,13.850000,2,1,13.010000,2,1,14.190000,100,1,12.980000,200,2,14.280000,100,1,12.860000,100,1,14.460000,100,1,12.730000,100,1,14.480000,700,1,12.710000,100,1,14.560000,800,2,12.500000,700,1,14.600000,700,1,12.490000,200,2,14.680000,700,1,12.460000,100,1,14.740000,200,2,12.430000,700,1,14.750000,100,1,ARL,333581625
2025-07-17T16:08:27.501093618Z,2025-07-17T16:08:27.500928061Z,10,2,1108,C,A,0,13.85,2,0,165557,277841469,13.110000,100,1,14.190000,100,1,13.010000,2,1,14.280000,100,1,12.980000,200,2,14.460000,100,1,12.860000,100,1,14.480000,700,1,12.730000,100,1,14.560000,800,2,12.710000,100,1,14.600000,700,1,12.500000,700,1,14.680000,700,1,12.490000,200,2,14.740000,200,2,12.460000,100,1,14.750000,100,1,12.430000,700,1,14.940000,200,2,ARL,331155889
2025-07-17T16:08:27.501093618Z,2025-07-17T16:08:27.500928061Z,10,2,1108,A,A,0,13.98,2,130,165557,277841469,13.110000,100,1,13.980000,2,1,13.010000,2,1,14.190000,100,1,12.980000,200,2,14.280000,100,1,12.860000,100,1,14.460000,100,1,12.730000,100,1,14.480000,700,1,12.710000,100,1,14.560000,800,2,12.500000,700,1,14.600000,700,1,12.490000,200,2,14.680000,700,1,12.460000,100,1,14.740000,200,2,12.430000,700,1,14.750000,100,1,ARL,333581677
2025-07-17T16:08:27.516614373Z,2025-07-17T16:08:27.516449334Z,10,2,1108,C,A,1,14.19,100,130,165039,277841551,13.110000,100,1,13.980000,2,1,13.010000,2,1,14.280000,100,1,12.980000,200,2,14.460000,100,1,12.860000,100,1,14.480000,700,1,12.730000,100,1,14.560000,800,2,12.710000,100,1,14.600000,700,1,12.500000,700,1,14.680000,700,1,12.490000,200,2,14.740000,200,2,12.460000,100,1,14.750000,100,1,12.430000,700,1,14.940000,200,2,ARL,333581625
2025-07-17T16:08:27.516662099Z,2025-07-17T16:08:27.516496962Z,10,2,1108,A,A,1,14.26,100,130,165137,277841552,13.110000,100,1,13.980000,2,1,13.010000,2,1,14.260000,100,1,12.980000,200,2,14.280000,100,1,12.860000,100,1,14.460000,100,1,12.730000,100,1,14.480000,700,1,12.710000,100,1,14.560000,800,2,12.500000,700,1,14.600000,700,1,12.490000,200,2,14.680000,700,1,12.460000,100,1,14.740000,200,2,12.430000,700,1,14.750000,100,1,ARL,333581765
2025-07-17T16:08:27.533938450Z,2025-07-17T16:08:27.533773259Z,10,2,1108,C,A,11,14.99,100,0,165191,277841588,13.110000,100,1,13.980000,2,1,13.010000,2,1,14.260000,100,1,12.980000,200,2,14.280000,100,1,12.860000,100,1,14.460000,100,1,12.730000,100,1,14.480000,700,1,12.710000,100,1,14.560000,800,2,12.500000,700,1,14.600000,700,1,12.490000,200,2,14.680000,700,1,12.460000,100,1,14.740000,200,2,12.430000,700,1,14.750000,100,1,ARL,333581389
2025-07-17T16:08:27.533938450Z,2025-07-17T16:08:27.533773259Z,10,2,1108,A,A,-1,15.04,100,130,165191,277841588,13.110000,100,1,13.980000,2,1,13.010000,2,1,14.260000,100,1,12.980000,200,2,14.280000,100,1,12.860000,100,1,14.460000,100,1,12.730000,100,1,14.480000,700,1,12.710000,100,1,14.560000,800,2,12.500000,700,1,14.600000,700,1,12.490000,200,2,14.680000,700,1,12.460000,100,1,14.740000,200,2,12.430000,700,1,14.750000,100,1,ARL,333581845
2025-07-17T16:08:27.987678739Z,2025-07-17T16:08:27.987513451Z,10,2,1108,A,A,1,13.99,100,130,165288,277846288,13.110000,100,1,13.980000,2,1,13.010000,2,1,13.990000,100,1,12.980000,200,2,14.260000,100,1,12.860000,100,1,14.280000,100,1,12.730000,100,1,14.460000,100,1,12.710000,100,1,14.480000,700,1,12.500000,700,1,14.560000,800,2,12.490000,200,2,14.600000,700,1,12.460000,100,1,14.680000,700,1,12.430000,700,1,14.740000,200,2,ARL,333590057
2025-07-17T16:08:58.024979382Z,2025-07-17T16:08:58.024814068Z,10,2,1108,A,A,0,13.81,15,130,165314,278261182,13.110000,100,1,13.810000,15,1,13.010000,2,1,13.980000,2,1,12.980000,200,2,13.990000,100,1,12.860000,100,1,14.260000,100,1,12.730000,100,1,14.280000,100,1,12.710000,100,1,14.460000,100,1,12.500000,700,1,14.480000,700,1,12.490000,200,2,14.560000,800,2,12.460000,100,1,14.600000,700,1,12.430000,700,1,14.680000,700,1,ARL,334141429
2025-07-17T16:09:00.222675234Z,2025-07-17T16:09:00.222509491Z,10,2,1108,C,A,2,13.99,100,0,165743,278295684,13.110000,100,1,13.810000,15,1,13.010000,2,1,13.980000,2,1,12.980000,200,2,14.260000,100,1,12.860000,100,1,14.280000,100,1,12.730000,100,1,14.460000,100,1,12.710000,100,1,14.480000,700,1,12.500000,700,1,14.560000,800,2,12.490000,200,2,14.600000,700,1,12.460000,100,1,14.680000,700,1,12.430000,700,1,14.740000,200,2,ARL,333590057
2025-07-17T16:09:00.222675234Z,2025-07-17T16:09:00.222509491Z,10,2,1108,A,A,1,13.82,100,130,165743,278295684,13.110000,100,1,13.810000,15,1,13.010000,2,1,13.820000,100,1,12.980000,200,2,13.980000,2,1,12.860000,100,1,14.260000,100,1,12.730000,100,1,14.280000,100,1,12.710000,100,1,14.460000,100,1,12.500000,700,1,14.480000,700,1,12.490000,200,2,14.560000,800,2,12.460000,100,1,14.600000,700,1,12.430000,700,1,14.680000,700,1,ARL,334189729
2025-07-17T16:09:00.223436757Z,2025-07-17T16:09:00.223269382Z,10,2,1108,C,A,13,15.04,100,0,167375,278295848,13.110000,100,1,13.810000,15,1,13.010000,2,1,13.820000,100,1,12.980000,200,2,13.980000,2,1,12.860000,100,1,14.260000,100,1,12.730000,100,1,14.280000,100,1,12.710000,100,1,14.460000,100,1,12.500000,700,1,14.480000,700,1,12.490000,200,2,14.560000,800,2,12.460000,100,1,14.600000,700,1,12.430000,700,1,14.680000,700,1,ARL,333581845
2025-07-17T16:09:00.223436757Z,2025-07-17T16:09:00.223269382Z,10,2,1108,A,A,-1,14.89,100,128,167375,278295848,13.110000,100,1,13.810000,15,1,13.010000,2,1,13.820000,100,1,12.980000,200,2,13.980000,2,1,12.860000,100,1,14.260000,100,1,12.730000,100,1,14.280000,100,1,12.710000,100,1,14.460000,100,1,12.500000,700,1,14.480000,700,1,12.490000,200,2,14.560000,800,2,12.460000,100,1,14.600000,700,1,12.430000,700,1,14.680000,700,1,ARL,334189777
2025-07-17T16:09:00.226504346Z,2025-07-17T16:09:00.226338384Z,10,2,1108,C,A,11,14.75,100,0,165962,278296281,13.110000,100,1,13.810000,15,1,13.010000,2,1,13.820000,100,1,12.980000,200,2,13.980000,2,1,12.860000,100,1,14.260000,100,1,12.730000,100,1,14.280000,100,1,12.710000,100,1,14.460000,100,1,12.500000,700,1,14.480000,700,1,12.490000,200,2,14.560000,800,2,12.460000,100,1,14.600000,700,1,12.430000,700,1,14.680000,700,1,ARL,333581569
2025-07-17T16:09:00.226504346Z,2025-07-17T16:09:00.226338384Z,10,2,1108,A,A,9,14.61,100,130,165962,278296281,13.110000,100,1,13.810000,15,1,13.010000,2,1,13.820000,100,1,12.980000,200,2,13.980000,2,1,12.860000,100,1,14.260000,100,1,12.730000,100,1,14.280000,100,1,12.710000,100,1,14.460000,100,1,12.500000,700,1,14.480000,700,1,12.490000,200,2,14.560000,800,2,12.460000,100,1,14.600000,700,1,12.430000,700,1,14.610000,100,1,ARL,334190189
2025-07-17T16:09:00.227929061Z,2025-07-17T16:09:00.227763275Z,10,2,1108,C,A,3,14.26,100,130,165786,278296402,13.110000,100,1,13.810000,15,1,13.010000,2,1,13.820000,100,1,12.980000,200,2,13.980000,2,1,12.860000,100,1,14.280000,100,1,12.730000,100,1,14.460000,100,1,12.710000,100,1,14.480000,700,1,12.500000,700,1,14.560000,800,2,12.490000,200,2,14.600000,700,1,12.460000,100,1,14.610000,100,1,12.430000,700,1,14.680000,700,1,ARL,333581765
2025-07-17T16:09:00.227983483Z,2025-07-17T16:09:00.227818153Z,10,2,1108,A,A,3,14.10,100,130,165330,278296411,13.110000,100,1,13.810000,15,1,13.010000,2,1,13.820000,100,1,12.980000,200,2,13.980000,2,1,12.860000,100,1,14.100000,100,1,12.730000,100,1,14.280000,100,1,12.710000,100,1,14.460000,100,1,12.500000,700,1,14.480000,700,1,12.490000,200,2,14.560000,800,2,12.460000,100,1,14.600000,700,1,12.430000,700,1,14.610000,100,1,ARL,334190225
2025-07-17T16:09:00.232908882Z,2025-07-17T16:09:00.232743323Z,10,2,1108,C,A,13,14.94,100,0,165559,278296544,13.110000,100,1,13.810000,15,1,13.010000,2,1,13.820000,100,1,12.980000,200,2,13.980000,2,1,12.860000,100,1,14.100000,100,1,12.730000,100,1,14.280000,100,1,12.710000,100,1,14.460000,100,1,12.500000,700,1,14.480000,700,1,12.490000,200,2,14.560000,800,2,12.460000,100,1,14.600000,700,1,12.430000,700,1,14.610000,100,1,ARL,333581429
2025-07-17T16:09:00.232908882Z,2025-07-17T16:09:00.232743323Z,10,2,1108,A,A,-1,14.79,100,130,165559,278296544,13.110000,100,1,13.810000,15,1,13.010000,2,1,13.820000,100,1,12.980000,200,2,13.980000,2,1,12.860000,100,1,14.100000,100,1,12.730000,100,1,14.280000,100,1,12.710000,100,1,14.460000,100,1,12.500000,700,1,14.480000,700,1,12.490000,200,2,14.560000,800,2,12.460000,100,1,14.600000,700,1,12.430000,700,1,14.610000,100,1,ARL,334190353
2025-07-17T16:09:00.326293286Z,2025-07-17T16:09:00.326127587Z,10,2,1108,C,A,22,17.73,100,0,165699,278298302,13.110000,100,1,13.810000,15,1,13.010000,2,1,13.820000,100,1,12.980000,200,2,13.980000,2,1,12.860000,100,1,14.100000,100,1,12.730000,100,1,14.280000,100,1,12.710000,100,1,14.460000,100,1,12.500000,700,1,14.480000,700,1,12.490000,200,2,14.560000,800,2,12.460000,100,1,14.600000,700,1,12.430000,700,1,14.610000,100,1,ARL,333581425
2025-07-17T16:09:00.326293286Z,2025-07-17T16:09:00.326127587Z,10,2,1108,A,A,-1,17.56,100,130,165699,278298302,13.110000,100,1,13.810000,15,1,13.010000,2,1,13.820000,100,1,12.980000,200,2,13.980000,2,1,12.860000,100,1,14.100000,100,1,12.730000,100,1,14.280000,100,1,12.710000,100,1,14.460000,100,1,12.500000,700,1,14.480000,700,1,12.490000,200,2,14.560000,800,2,12.460000,100,1,14.600000,700,1,12.430000,700,1,14.610000,100,1,ARL,334192253
2025-07-17T16:09:00.335607827Z,2025-07-17T16:09:00.335442266Z,10,2,1108,C,A,19,16.06,100,0,165561,278298372,13.110000,100,1,13.810000,15,1,13.010000,2,1,13.820000,100,1,12.980000,200,2,13.980000,2,1,12.860000,100,1,14.100000,100,1,12.730000,100,1,14.280000,100,1,12.710000,100,1,14.460000,100,1,12.500000,700,1,14.480000,700,1,12.490000,200,2,14.560000,800,2,12.460000,100,1,14.600000,700,1,12.430000,700,1,14.610000,100,1,ARL,333581433
2025-07-17T16:09:00.335607827Z,2025-07-17T16:09:00.335442266Z,10,2,1108,A,A,-1,15.90,100,130,165561,278298372,13.110000,100,1,13.810000,15,1,13.010000,2,1,13.820000,100,1,12.980000,200,2,13.980000,2,1,12.860000,100,1,14.100000,100,1,12.730000,100,1,14.280000,100,1,12.710000,100,1,14.460000,100,1,12.500000,700,1,14.480000,700,1,12.490000,200,2,14.560000,800,2,12.460000,100,1,14.600000,700,1,12.430000,700,1,14.610000,100,1,ARL,334192405
2025-07-17T16:09:00.695776010Z,2025-07-17T16:09:00.695610142Z,10,2,1108,C,A,14,14.94,100,0,165868,278304343,13.110000,100,1,13.810000,15,1,13.010000,2,1,13.820000,100,1,12.980000,200,2,13.980000,2,1,12.860000,100,1,14.100000,100,1,12.730000,100,1,14.280000,100,1,12.710000,100,1,14.460000,100,1,12.500000,700,1,14.480000,700,1,12.490000,200,2,14.560000,800,2,12.460000,100,1,14.600000,700,1,12.430000,700,1,14.610000,100,1,ARL,333581409
2025-07-17T16:09:00.695776010Z,2025-07-17T16:09:00.695610142Z,10,2,1108,A,A,-1,14.79,100,130,165868,278304343,13.110000,100,1,13.810000,15,1,13.010000,2,1,13.820000,100,1,12.980000,200,2,13.980000,2,1,12.860000,100,1,14.100000,100,1,12.730000,100,1,14.280000,100,1,12.710000,100,1,14.460000,100,1,12.500000,700,1,14.480000,700,1,12.490000,200,2,14.560000,800,2,12.460000,100,1,14.600000,700,1,12.430000,700,1,14.610000,100,1,ARL,334199009
2025-07-17T16:09:08.719690693Z,2025-07-17T16:09:08.719524374Z,10,2,1108,A,A,0,13.75,15,130,166319,278436950,13.110000,100,1,13.750000,15,1,13.010000,2,1,13.810000,15,1,12.980000,200,2,13.820000,100,1,12.860000,100,1,13.980000,2,1,12.730000,100,1,14.100000,100,1,12.710000,100,1,14.280000,100,1,12.500000,700,1,14.460000,100,1,12.490000,200,2,14.480000,700,1,12.460000,100,1,14.560000,800,2,12.430000,700,1,14.600000,700,1,ARL,334366613
2025-07-17T16:09:08.719871410Z,2025-07-17T16:09:08.719706070Z,10,2,1108,C,A,2,13.82,100,0,165340,278436967,13.110000,100,1,13.750000,15,1,13.010000,2,1,13.810000,15,1,12.980000,200,2,13.980000,2,1,12.860000,100,1,14.100000,100,1,12.730000,100,1,14.280000,100,1,12.710000,100,1,14.460000,100,1,12.500000,700,1,14.480000,700,1,12.490000,200,2,14.560000,800,2,12.460000,100,1,14.600000,700,1,12.430000,700,1,14.610000,100,1,ARL,334189729
2025-07-17T16:09:08.719871410Z,2025-07-17T16:09:08.719706070Z,10,2,1108,A,A,1,13.76,100,130,165340,278436967,13.110000,100,1,13.750000,15,1,13.010000,2,1,13.760000,100,1,12.980000,200,2,13.810000,15,1,12.860000,100,1,13.980000,2,1,12.730000,100,1,14.100000,100,1,12.710000,100,1,14.280000,100,1,12.500000,700,1,14.460000,100,1,12.490000,200,2,14.480000,700,1,12.460000,100,1,14.560000,800,2,12.430000,700,1,14.600000,700,1,ARL,334366617
2025-07-17T16:09:08.720607932Z,2025-07-17T16:09:08.720442245Z,10,2,1108,C,A,14,14.89,100,0,165687,278436994,13.110000,100,1,13.750000,15,1,13.010000,2,1,13.760000,100,1,12.980000,200,2,13.810000,15,1,12.860000,100,1,13.980000,2,1,12.730000,100,1,14.100000,100,1,12.710000,100,1,14.280000,100,1,12.500000,700,1,14.460000,100,1,12.490000,200,2,14.480000,700,1,12.460000,100,1,14.560000,800,2,12.430000,700,1,14.600000,700,1,ARL,334189777
2025-07-17T16:09:08.720607932Z,2025-07-17T16:09:08.720442245Z,10,2,1108,A,A,-1,14.83,100,130,165687,278436994,13.110000,100,1,13.750000,15,1,13.010000,2,1,13.760000,100,1,12.980000,200,2,13.810000,15,1,12.860000,100,1,13.980000,2,1,12.730000,100,1,14.100000,100,1,12.710000,100,1,14.280000,100,1,12.500000,700,1,14.460000,100,1,12.490000,200,2,14.480000,700,1,12.460000,100,1,14.560000,800,2,12.430000,700,1,14.600000,700,1,ARL,334366645
2025-07-17T16:09:18.819300735Z,2025-07-17T16:09:18.819135505Z,10,2,1108,C,A,2,13.81,15,130,165230,278596985,13.110000,100,1,13.750000,15,1,13.010000,2,1,13.760000,100,1,12.980000,200,2,13.980000,2,1,12.860000,100,1,14.100000,100,1,12.730000,100,1,14.280000,100,1,12.710000,100,1,14.460000,100,1,12.500000,700,1,14.480000,700,1,12.490000,200,2,14.560000,800,2,12.460000,100,1,14.600000,700,1,12.430000,700,1,14.610000,100,1,ARL,334141429
2025-07-17T16:09:19.927205023Z,2025-07-17T16:09:19.927039122Z,10,2,1108,A,A,0,13.73,15,130,165901,278621672,13.110000,100,1,13.730000,15,1,13.010000,2,1,13.750000,15,1,12.980000,200,2,13.760000,100,1,12.860000,100,1,13.980000,2,1,12.730000,100,1,14.100000,100,1,12.710000,100,1,14.280000,100,1,12.500000,700,1,14.460000,100,1,12.490000,200,2,14.480000,700,1,12.460000,100,1,14.560000,800,2,12.430000,700,1,14.600000,700,1,ARL,334583329
2025-07-17T16:09:19.927910703Z,2025-07-17T16:09:19.927745104Z,10,2,1108,C,A,12,14.74,100,0,165599,278621693,13.110000,100,1,13.730000,15,1,13.010000,2,1,13.750000,15,1,12.980000,200,2,13.760000,100,1,12.860000,100,1,13.980000,2,1,12.730000,100,1,14.100000,100,1,12.710000,100,1,14.280000,100,1,12.500000,700,1,14.460000,100,1,12.490000,200,2,14.480000,700,1,12.460000,100,1,14.560000,800,2,12.430000,700,1,14.600000,700,1,ARL,333581393
2025-07-17T16:09:19.927910703Z,2025-07-17T16:09:19.927745104Z,10,2,1108,A,A,-1,14.62,100,130,165599,278621693,13.110000,100,1,13.730000,15,1,13.010000,2,1,13.750000,15,1,12.980000,200,2,13.760000,100,1,12.860000,100,1,13.980000,2,1,12.730000,100,1,14.100000,100,1,12.710000,100,1,14.280000,100,1,12.500000,700,1,14.460000,100,1,12.490000,200,2,14.480000,700,1,12.460000,100,1,14.560000,800,2,12.430000,700,1,14.600000,700,1,ARL,334583349
2025-07-17T16:09:19.928319369Z,2025-07-17T16:09:19.928153837Z,10,2,1108,C,A,13,14.74,100,0,165532,278621695,13.110000,100,1,13.730000,15,1,13.010000,2,1,13.750000,15,1,12.980000,200,2,13.760000,100,1,12.860000,100,1,13.980000,2,1,12.730000,100,1,14.100000,100,1,12.710000,100,1,14.280000,100,1,12.500000,700,1,14.460000,100,1,12.490000,200,2,14.480000,700,1,12.460000,100,1,14.560000,800,2,12.430000,700,1,14.600000,700,1,ARL,333581481
2025-07-17T16:09:19.928319369Z,2025-07-17T16:09:19.928153837Z,10,2,1108,A,A,-1,14.62,100,130,165532,278621695,13.110000,100,1,13.730000,15,1,13.010000,2,1,13.750000,15,1,12.980000,200,2,13.760000,100,1,12.860000,100,1,13.980000,2,1,12.730000,100,1,14.100000,100,1,12.710000,100,1,14.280000,100,1,12.500000,700,1,14.460000,100,1,12.490000,200,2,14.480000,700,1,12.460000,100,1,14.560000,800,2,12.430000,700,1,14.600000,700,1,ARL,334583361
2025-07-17T16:09:20.284861075Z,2025-07-17T16:09:20.284695585Z,10,2,1108,C,A,2,13.76,100,0,165490,278629057,13.110000,100,1,13.730000,15,1,13.010000,2,1,13.750000,15,1,12.980000,200,2,13.980000,2,1,12.860000,100,1,14.100000,100,1,12.730000,100,1,14.280000,100,1,12.710000,100,1,14.460000,100,1,12.500000,700,1,14.480000,700,1,12.490000,200,2,14.560000,800,2,12.460000,100,1,14.600000,700,1,12.430000,700,1,14.610000,100,1,ARL,334366617
2025-07-17T16:09:20.284861075Z,2025-07-17T16:09:20.284695585Z,10,2,1108,A,A,1,13.74,100,130,165490,278629057,13.110000,100,1,13.730000,15,1,13.010000,2,1,13.740000,100,1,12.980000,200,2,13.750000,15,1,12.860000,100,1,13.980000,2,1,12.730000,100,1,14.100000,100,1,12.710000,100,1,14.280000,100,1,12.500000,700,1,14.460000,100,1,12.490000,200,2,14.480000,700,1,12.460000,100,1,14.560000,800,2,12.430000,700,1,14.600000,700,1,ARL,334593569
2025-07-17T16:09:20.293271620Z,2025-07-17T16:09:20.293106270Z,10,2,1108,C,A,4,14.10,100,130,165350,278629219,13.110000,100,1,13.730000,15,1,13.010000,2,1,13.740000,100,1,12.980000,200,2,13.750000,15,1,12.860000,100,1,13.980000,2,1,12.730000,100,1,14.280000,100,1,12.710000,100,1,14.460000,100,1,12.500000,700,1,14.480000,700,1,12.490000,200,2,14.560000,800,2,12.460000,100,1,14.600000,700,1,12.430000,700,1,14.610000,100,1,ARL,334190225
2025-07-17T16:09:20.293326641Z,2025-07-17T16:09:20.293161454Z,10,2,1108,A,A,4,14.01,100,130,165187,278629220,13.110000,100,1,13.730000,15,1,13.010000,2,1,13.740000,100,1,12.980000,200,2,13.750000,15,1,12.860000,100,1,13.980000,2,1,12.730000,100,1,14.010000,100,1,12.710000,100,1,14.280000,100,1,12.500000,700,1,14.460000,100,1,12.490000,200,2,14.480000,700,1,12.460000,100,1,14.560000,800,2,12.430000,700,1,14.600000,700,1,ARL,334593753
2025-07-17T16:09:20.818813935Z,2025-07-17T16:09:20.818648795Z,10,2,1108,C,A,0,13.73,15,130,165140,278640667,13.110000,100,1,13.740000,100,1,13.010000,2,1,13.750000,15,1,12.980000,200,2,13.980000,2,1,12.860000,100,1,14.010000,100,1,12.730000,100,1,14.280000,100,1,12.710000,100,1,14.460000,100,1,12.500000,700,1,14.480000,700,1,12.490000,200,2,14.560000,800,2,12.460000,100,1,14.600000,700,1,12.430000,700,1,14.610000,100,1,ARL,334583329
2025-07-17T16:09:20.818926356Z,2025-07-17T16:09:20.818761228Z,10,2,1108,C,A,1,13.75,15,130,165128,278640670,13.110000,100,1,13.740000,100,1,13.010000,2,1,13.980000,2,1,12.980000,200,2,14.010000,100,1,12.860000,100,1,14.280000,100,1,12.730000,100,1,14.460000,100,1,12.710000,100,1,14.480000,700,1,12.500000,700,1,14.560000,800,2,12.490000,200,2,14.600000,700,1,12.460000,100,1,14.610000,100,1,12.430000,700,1,14.620000,200,2,ARL,334366613
2025-07-17T16:09:28.986122432Z,2025-07-17T16:09:28.985956629Z,10,2,1108,C,A,1,13.98,2,0,165803,278784943,13.110000,100,1,13.740000,100,1,13.010000,2,1,14.010000,100,1,12.980000,200,2,14.280000,100,1,12.860000,100,1,14.460000,100,1,12.730000,100,1,14.480000,700,1,12.710000,100,1,14.560000,800,2,12.500000,700,1,14.600000,700,1,12.490000,200,2,14.610000,100,1,12.460000,100,1,14.620000,200,2,12.430000,700,1,14.680000,700,1,ARL,333581677
2025-07-17T16:09:28.986122432Z,2025-07-17T16:09:28.985956629Z,10,2,1108,A,A,1,13.90,2,130,165803,278784943,13.110000,100,1,13.740000,100,1,13.010000,2,1,13.900000,2,1,12.980000,200,2,14.010000,100,1,12.860000,100,1,14.280000,100,1,12.730000,100,1,14.460000,100,1,12.710000,100,1,14.480000,700,1,12.500000,700,1,14.560000,800,2,12.490000,200,2,14.600000,700,1,12.460000,100,1,14.610000,100,1,12.430000,700,1,14.620000,200,2,ARL,334804177
2025-07-17T16:09:40.821687905Z,2025-07-17T16:09:40.821522565Z,10,2,1108,A,A,0,13.70,15,130,165340,278938091,13.110000,100,1,13.700000,15,1,13.010000,2,1,13.740000,100,1,12.980000,200,2,13.900000,2,1,12.860000,100,1,14.010000,100,1,12.730000,100,1,14.280000,100,1,12.710000,100,1,14.460000,100,1,12.500000,700,1,14.480000,700,1,12.490000,200,2,14.560000,800,2,12.460000,100,1,14.600000,700,1,12.430000,700,1,14.610000,100,1,ARL,335003269
2025-07-17T16:09:40.853604577Z,2025-07-17T16:09:40.853439053Z,10,2,1108,C,A,1,13.74,100,0,165524,278938747,13.110000,100,1,13.700000,15,1,13.010000,2,1,13.900000,2,1,12.980000,200,2,14.010000,100,1,12.860000,100,1,14.280000,100,1,12.730000,100,1,14.460000,100,1,12.710000,100,1,14.480000,700,1,12.500000,700,1,14.560000,800,2,12.490000,200,2,14.600000,700,1,12.460000,100,1,14.610000,100,1,12.430000,700,1,14.620000,200,2,ARL,334593569
2025-07-17T16:09:40.853604577Z,2025-07-17T16:09:40.853439053Z,10,2,1108,A,A,1,13.71,100,130,165524,278938747,13.110000,100,1,13.700000,15,1,13.010000,2,1,13.710000,100,1,12.980000,200,2,13.900000,2,1,12.860000,100,1,14.010000,100,1,12.730000,100,1,14.280000,100,1,12.710000,100,1,14.460000,100,1,12.500000,700,1,14.480000,700,1,12.490000,200,2,14.560000,800,2,12.460000,100,1,14.600000,700,1,12.430000,700,1,14.610000,100,1,ARL,335003813
2025-07-17T16:09:40.854356022Z,2025-07-17T16:09:40.854190408Z,10,2,1108,C,A,13,14.83,100,0,165614,278938765,13.110000,100,1,13.700000,15,1,13.010000,2,1,13.710000,100,1,12.980000,200,2,13.900000,2,1,12.860000,100,1,14.010000,100,1,12.730000,100,1,14.280000,100,1,12.710000,100,1,14.460000,100,1,12.500000,700,1,14.480000,700,1,12.490000,200,2,14.560000,800,2,12.460000,100,1,14.600000,700,1,12.430000,700,1,14.610000,100,1,ARL,334366645
2025-07-17T16:09:40.854356022Z,2025-07-17T16:09:40.854190408Z,10,2,1108,A,A,-1,14.77,100,130,165614,278938765,13.110000,100,1,13.700000,15,1,13.010000,2,1,13.710000,100,1,12.980000,200,2,13.900000,2,1,12.860000,100,1,14.010000,100,1,12.730000,100,1,14.280000,100,1,12.710000,100,1,14.460000,100,1,12.500000,700,1,14.480000,700,1,12.490000,200,2,14.560000,800,2,12.460000,100,1,14.600000,700,1,12.430000,700,1,14.610000,100,1,ARL,335003845
2025-07-17T16:09:40.855724422Z,2025-07-17T16:09:40.855558831Z,10,2,1108,C,A,21,17.56,100,0,165591,278938788,13.110000,100,1,13.700000,15,1,13.010000,2,1,13.710000,100,1,12.980000,200,2,13.900000,2,1,12.860000,100,1,14.010000,100,1,12.730000,100,1,14.280000,100,1,12.710000,100,1,14.460000,100,1,12.500000,700,1,14.480000,700,1,12.490000,200,2,14.560000,800,2,12.460000,100,1,14.600000,700,1,12.430000,700,1,14.610000,100,1,ARL,334192253
2025-07-17T16:09:40.855724422Z,2025-07-17T16:09:40.855558831Z,10,2,1108,A,A,-1,17.42,100,130,165591,278938788,13.110000,100,1,13.700000,15,1,13.010000,2,1,13.710000,100,1,12.980000,200,2,13.900000,2,1,12.860000,100,1,14.010000,100,1,12.730000,100,1,14.280000,100,1,12.710000,100,1,14.460000,100,1,12.500000,700,1,14.480000,700,1,12.490000,200,2,14.560000,800,2,12.460000,100,1,14.600000,700,1,12.430000,700,1,14.610000,100,1,ARL,335003849
2025-07-17T16:09:50.820949131Z,2025-07-17T16:09:50.820783486Z,10,2,1108,A,A,0,13.67,15,130,165645,279081140,13.110000,100,1,13.670000,15,1,13.010000,2,1,13.700000,15,1,12.980000,200,2,13.710000,100,1,12.860000,100,1,13.900000,2,1,12.730000,100,1,14.010000,100,1,12.710000,100,1,14.280000,100,1,12.500000,700,1,14.460000,100,1,12.490000,200,2,14.480000,700,1,12.460000,100,1,14.560000,800,2,12.430000,700,1,14.600000,700,1,ARL,335178437
2025-07-17T16:09:52.678777358Z,2025-07-17T16:09:52.678611805Z,10,2,1108,C,A,2,13.71,100,0,165553,279109959,13.110000,100,1,13.670000,15,1,13.010000,2,1,13.700000,15,1,12.980000,200,2,13.900000,2,1,12.860000,100,1,14.010000,100,1,12.730000,100,1,14.280000,100,1,12.710000,100,1,14.460000,100,1,12.500000,700,1,14.480000,700,1,12.490000,200,2,14.560000,800,2,12.460000,100,1,14.600000,700,1,12.430000,700,1,14.610000,100,1,ARL,335003813
2025-07-17T16:09:52.678777358Z,2025-07-17T16:09:52.678611805Z,10,2,1108,A,A,1,13.68,100,130,165553,279109959,13.110000,100,1,13.670000,15,1,13.010000,2,1,13.680000,100,1,12.980000,200,2,13.700000,15,1,12.860000,100,1,13.900000,2,1,12.730000,100,1,14.010000,100,1,12.710000,100,1,14.280000,100,1,12.500000,700,1,14.460000,100,1,12.490000,200,2,14.480000,700,1,12.460000,100,1,14.560000,800,2,12.430000,700,1,14.600000,700,1,ARL,335220349
2025-07-17T16:09:52.679844338Z,2025-07-17T16:09:52.679678566Z,10,2,1108,C,A,19,15.90,100,0,165772,279109991,13.110000,100,1,13.670000,15,1,13.010000,2,1,13.680000,100,1,12.980000,200,2,13.700000,15,1,12.860000,100,1,13.900000,2,1,12.730000,100,1,14.010000,100,1,12.710000,100,1,14.280000,100,1,12.500000,700,1,14.460000,100,1,12.490000,200,2,14.480000,700,1,12.460000,100,1,14.560000,800,2,12.430000,700,1,14.600000,700,1,ARL,334192405
2025-07-17T16:09:52.679844338Z,2025-07-17T16:09:52.679678566Z,10,2,1108,A,A,-1,15.74,100,130,165772,279109991,13.110000,100,1,13.670000,15,1,13.010000,2,1,13.680000,100,1,12.980000,200,2,13.700000,15,1,12.860000,100,1,13.900000,2,1,12.730000,100,1,14.010000,100,1,12.710000,100,1,14.280000,100,1,12.500000,700,1,14.460000,100,1,12.490000,200,2,14.480000,700,1,12.460000,100,1,14.560000,800,2,12.430000,700,1,14.600000,700,1,ARL,335220497
2025-07-17T16:09:52.679936826Z,2025-07-17T16:09:52.679769832Z,10,2,1108,C,A,14,14.79,100,0,166994,279109996,13.110000,100,1,13.670000,15,1,13.010000,2,1,13.680000,100,1,12.980000,200,2,13.700000,15,1,12.860000,100,1,13.900000,2,1,12.730000,100,1,14.010000,100,1,12.710000,100,1,14.280000,100,1,12.500000,700,1,14.460000,100,1,12.490000,200,2,14.480000,700,1,12.460000,100,1,14.560000,800,2,12.430000,700,1,14.600000,700,1,ARL,334190353
2025-07-17T16:09:52.679936826Z,2025-07-17T16:09:52.679769832Z,10,2,1108,A,A,-1,14.64,100,130,166994,279109996,13.110000,100,1,13.670000,15,1,13.010000,2,1,13.680000,100,1,12.980000,200,2,13.700000,15,1,12.860000,100,1,13.900000,2,1,12.730000,100,1,14.010000,100,1,12.710000,100,1,14.280000,100,1,12.500000,700,1,14.460000,100,1,12.490000,200,2,14.480000,700,1,12.460000,100,1,14.560000,800,2,12.430000,700,1,14.600000,700,1,ARL,335220525
2025-07-17T16:09:52.680837736Z,2025-07-17T16:09:52.680672148Z,10,2,1108,C,A,18,15.36,100,0,165588,279110032,13.110000,100,1,13.670000,15,1,13.010000,2,1,13.680000,100,1,12.980000,200,2,13.700000,15,1,12.860000,100,1,13.900000,2,1,12.730000,100,1,14.010000,100,1,12.710000,100,1,14.280000,100,1,12.500000,700,1,14.460000,100,1,12.490000,200,2,14.480000,700,1,12.460000,100,1,14.560000,800,2,12.430000,700,1,14.600000,700,1,ARL,333581441
2025-07-17T16:09:52.680837736Z,2025-07-17T16:09:52.680672148Z,10,2,1108,A,A,-1,15.05,100,130,165588,279110032,13.110000,100,1,13.670000,15,1,13.010000,2,1,13.680000,100,1,12.980000,200,2,13.700000,15,1,12.860000,100,1,13.900000,2,1,12.730000,100,1,14.010000,100,1,12.710000,100,1,14.280000,100,1,12.500000,700,1,14.460000,100,1,12.490000,200,2,14.480000,700,1,12.460000,100,1,14.560000,800,2,12.430000,700,1,14.600000,700,1,ARL,335220549
2025-07-17T16:09:52.682009938Z,2025-07-17T16:09:52.681844377Z,10,2,1108,C,A,10,14.61,100,130,165561,279110066,13.110000,100,1,13.670000,15,1,13.010000,2,1,13.680000,100,1,12.980000,200,2,13.700000,15,1,12.860000,100,1,13.900000,2,1,12.730000,100,1,14.010000,100,1,12.710000,100,1,14.280000,100,1,12.500000,700,1,14.460000,100,1,12.490000,200,2,14.480000,700,1,12.460000,100,1,14.560000,800,2,12.430000,700,1,14.600000,700,1,ARL,334190189
2025-07-17T16:09:52.682127530Z,2025-07-17T16:09:52.681961200Z,10,2,1108,A,A,7,14.47,100,130,166330,279110068,13.110000,100,1,13.670000,15,1,13.010000,2,1,13.680000,100,1,12.980000,200,2,13.700000,15,1,12.860000,100,1,13.900000,2,1,12.730000,100,1,14.010000,100,1,12.710000,100,1,14.280000,100,1,12.500000,700,1,14.460000,100,1,12.490000,200,2,14.470000,100,1,12.460000,100,1,14.480000,700,1,12.430000,700,1,14.560000,800,2,ARL,335220561
2025-07-17T16:09:52.683922707Z,2025-07-17T16:09:52.683757265Z,10,2,1108,C,A,15,14.79,100,0,165442,279110090,13.110000,100,1,13.670000,15,1,13.010000,2,1,13.680000,100,1,12.980000,200,2,13.700000,15,1,12.860000,100,1,13.900000,2,1,12.730000,100,1,14.010000,100,1,12.710000,100,1,14.280000,100,1,12.500000,700,1,14.460000,100,1,12.490000,200,2,14.470000,100,1,12.460000,100,1,14.480000,700,1,12.430000,700,1,14.560000,800,2,ARL,334199009
2025-07-17T16:09:52.683922707Z,2025-07-17T16:09:52.683757265Z,10,2,1108,A,A,-1,14.64,100,130,165442,279110090,13.110000,100,1,13.670000,15,1,13.010000,2,1,13.680000,100,1,12.980000,200,2,13.700000,15,1,12.860000,100,1,13.900000,2,1,12.730000,100,1,14.010000,100,1,12.710000,100,1,14.280000,100,1,12.500000,700,1,14.460000,100,1,12.490000,200,2,14.470000,100,1,12.460000,100,1,14.480000,700,1,12.430000,700,1,14.560000,800,2,ARL,335220629
2025-07-17T16:10:04.521471804Z,2025-07-17T16:10:04.521306513Z,10,2,1108,C,A,0,13.67,15,130,165291,279306715,13.110000,100,1,13.680000,100,1,13.010000,2,1,13.700000,15,1,12.980000,200,2,13.900000,2,1,12.860000,100,1,14.010000,100,1,12.730000,100,1,14.280000,100,1,12.710000,100,1,14.460000,100,1,12.500000,700,1,14.470000,100,1,12.490000,200,2,14.480000,700,1,12.460000,100,1,14.560000,800,2,12.430000,700,1,14.600000,700,1,ARL,335178437
2025-07-17T16:10:04.561854856Z,2025-07-17T16:10:04.561688313Z,10,2,1108,C,A,1,13.70,15,128,166543,279312083,13.110000,100,1,13.680000,100,1,13.010000,2,1,13.900000,2,1,12.980000,200,2,14.010000,100,1,12.860000,100,1,14.280000,100,1,12.730000,100,1,14.460000,100,1,12.710000,100,1,14.470000,100,1,12.500000,700,1,14.480000,700,1,12.490000,200,2,14.560000,800,2,12.460000,100,1,14.600000,700,1,12.430000,700,1,14.620000,200,2,ARL,335003269
2025-07-17T16:10:32.822660498Z,2025-07-17T16:10:32.822495087Z,10,2,1108,A,A,0,13.65,15,130,165411,279705339,13.110000,100,1,13.650000,15,1,13.010000,2,1,13.680000,100,1,12.980000,200,2,13.900000,2,1,12.860000,100,1,14.010000,100,1,12.730000,100,1,14.280000,100,1,12.710000,100,1,14.460000,100,1,12.500000,700,1,14.470000,100,1,12.490000,200,2,14.480000,700,1,12.460000,100,1,14.560000,800,2,12.430000,700,1,14.600000,700,1,ARL,335996705
2025-07-17T16:10:32.822923138Z,2025-07-17T16:10:32.822757517Z,10,2,1108,C,A,1,13.68,100,0,165621,279705347,13.110000,100,1,13.650000,15,1,13.010000,2,1,13.900000,2,1,12.980000,200,2,14.010000,100,1,12.860000,100,1,14.280000,100,1,12.730000,100,1,14.460000,100,1,12.710000,100,1,14.470000,100,1,12.500000,700,1,14.480000,700,1,12.490000,200,2,14.560000,800,2,12.460000,100,1,14.600000,700,1,12.430000,700,1,14.620000,200,2,ARL,335220349
2025-07-17T16:10:32.822923138Z,2025-07-17T16:10:32.822757517Z,10,2,1108,A,A,1,13.66,100,130,165621,279705347,13.110000,100,1,13.650000,15,1,13.010000,2,1,13.660000,100,1,12.980000,200,2,13.900000,2,1,12.860000,100,1,14.010000,100,1,12.730000,100,1,14.280000,100,1,12.710000,100,1,14.460000,100,1,12.500000,700,1,14.470000,100,1,12.490000,200,2,14.480000,700,1,12.460000,100,1,14.560000,800,2,12.430000,700,1,14.600000,700,1,ARL,335996709
2025-07-17T16:10:32.823656903Z,2025-07-17T16:10:32.823491276Z,10,2,1108,C,A,13,14.77,100,0,165627,279705362,13.110000,100,1,13.650000,15,1,13.010000,2,1,13.660000,100,1,12.980000,200,2,13.900000,2,1,12.860000,100,1,14.010000,100,1,12.730000,100,1,14.280000,100,1,12.710000,100,1,14.460000,100,1,12.500000,700,1,14.470000,100,1,12.490000,200,2,14.480000,700,1,12.460000,100,1,14.560000,800,2,12.430000,700,1,14.600000,700,1,ARL,335003845
2025-07-17T16:10:32.823656903Z,2025-07-17T16:10:32.823491276Z,10,2,1108,A,A,-1,14.72,100,130,165627,279705362,13.110000,100,1,13.650000,15,1,13.010000,2,1,13.660000,100,1,12.980000,200,2,13.900000,2,1,12.860000,100,1,14.010000,100,1,12.730000,100,1,14.280000,100,1,12.710000,100,1,14.460000,100,1,12.500000,700,1,14.470000,100,1,12.490000,200,2,14.480000,700,1,12.460000,100,1,14.560000,800,2,12.430000,700,1,14.600000,700,1,ARL,335996725
2025-07-17T16:10:32.830200844Z,2025-07-17T16:10:32.830032662Z,10,2,1108,C,A,3,14.01,100,130,168182,279705485,13.110000,100,1,13.650000,15,1,13.010000,2,1,13.660000,100,1,12.980000,200,2,13.900000,2,1,12.860000,100,1,14.280000,100,1,12.730000,100,1,14.460000,100,1,12.710000,100,1,14.470000,100,1,12.500000,700,1,14.480000,700,1,12.490000,200,2,14.560000,800,2,12.460000,100,1,14.600000,700,1,12.430000,700,1,14.620000,200,2,ARL,334593753
2025-07-17T16:10:32.830250720Z,2025-07-17T16:10:32.830085472Z,10,2,1108,A,A,3,13.93,100,130,165248,279705486,13.110000,100,1,13.650000,15,1,13.010000,2,1,13.660000,100,1,12.980000,200,2,13.900000,2,1,12.860000,100,1,13.930000,100,1,12.730000,100,1,14.280000,100,1,12.710000,100,1,14.460000,100,1,12.500000,700,1,14.470000,100,1,12.490000,200,2,14.480000,700,1,12.460000,100,1,14.560000,800,2,12.430000,700,1,14.600000,700,1,ARL,335996777
2025-07-17T16:10:42.822354869Z,2025-07-17T16:10:42.822189504Z,10,2,1108,A,A,0,13.63,15,130,165365,279834760,13.110000,100,1,13.630000,15,1,13.010000,2,1,13.650000,15,1,12.980000,200,2,13.660000,100,1,12.860000,100,1,13.900000,2,1,12.730000,100,1,13.930000,100,1,12.710000,100,1,14.280000,100,1,12.500000,700,1,14.460000,100,1,12.490000,200,2,14.470000,100,1,12.460000,100,1,14.480000,700,1,12.430000,700,1,14.560000,800,2,ARL,336161333
2025-07-17T16:10:42.822424663Z,2025-07-17T16:10:42.822258887Z,10,2,1108,C,A,2,13.66,100,0,165776,279834761,13.110000,100,1,13.630000,15,1,13.010000,2,1,13.650000,15,1,12.980000,200,2,13.900000,2,1,12.860000,100,1,13.930000,100,1,12.730000,100,1,14.280000,100,1,12.710000,100,1,14.460000,100,1,12.500000,700,1,14.470000,100,1,12.490000,200,2,14.480000,700,1,12.460000,100,1,14.560000,800,2,12.430000,700,1,14.600000,700,1,ARL,335996709
2025-07-17T16:10:42.822424663Z,2025-07-17T16:10:42.822258887Z,10,2,1108,A,A,1,13.64,100,130,165776,279834761,13.110000,100,1,13.630000,15,1,13.010000,2,1,13.640000,100,1,12.980000,200,2,13.650000,15,1,12.860000,100,1,13.900000,2,1,12.730000,100,1,13.930000,100,1,12.710000,100,1,14.280000,100,1,12.500000,700,1,14.460000,100,1,12.490000,200,2,14.470000,100,1,12.460000,100,1,14.480000,700,1,12.430000,700,1,14.560000,800,2,ARL,336161337
2025-07-17T16:10:42.823163929Z,2025-07-17T16:10:42.822998664Z,10,2,1108,C,A,6,14.46,100,130,165265,279834765,13.110000,100,1,13.630000,15,1,13.010000,2,1,13.640000,100,1,12.980000,200,2,13.650000,15,1,12.860000,100,1,13.900000,2,1,12.730000,100,1,13.930000,100,1,12.710000,100,1,14.280000,100,1,12.500000,700,1,14.470000,100,1,12.490000,200,2,14.480000,700,1,12.460000,100,1,14.560000,800,2,12.430000,700,1,14.600000,700,1,ARL,331927161
2025-07-17T16:10:42.823517444Z,2025-07-17T16:10:42.823352130Z,10,2,1108,A,A,5,14.25,100,130,165314,279834767,13.110000,100,1,13.630000,15,1,13.010000,2,1,13.640000,100,1,12.980000,200,2,13.650000,15,1,12.860000,100,1,13.900000,2,1,12.730000,100,1,13.930000,100,1,12.710000,100,1,14.250000,100,1,12.500000,700,1,14.280000,100,1,12.490000,200,2,14.470000,100,1,12.460000,100,1,14.480000,700,1,12.430000,700,1,14.560000,800,2,ARL,336161365
2025-07-17T16:10:46.534055942Z,2025-07-17T16:10:46.533890361Z,10,2,1108,C,A,11,14.62,100,0,165581,279921726,13.110000,100,1,13.630000,15,1,13.010000,2,1,13.640000,100,1,12.980000,200,2,13.650000,15,1,12.860000,100,1,13.900000,2,1,12.730000,100,1,13.930000,100,1,12.710000,100,1,14.250000,100,1,12.500000,700,1,14.280000,100,1,12.490000,200,2,14.470000,100,1,12.460000,100,1,14.480000,700,1,12.430000,700,1,14.560000,800,2,ARL,334583349
2025-07-17T16:10:46.534055942Z,2025-07-17T16:10:46.533890361Z,10,2,1108,A,A,9,14.51,100,130,165581,279921726,13.110000,100,1,13.630000,15,1,13.010000,2,1,13.640000,100,1,12.980000,200,2,13.650000,15,1,12.860000,100,1,13.900000,2,1,12.730000,100,1,13.930000,100,1,12.710000,100,1,14.250000,100,1,12.500000,700,1,14.280000,100,1,12.490000,200,2,14.470000,100,1,12.460000,100,1,14.480000,700,1,12.430000,700,1,14.510000,100,1,ARL,336259225
2025-07-17T16:10:46.538158874Z,2025-07-17T16:10:46.537992315Z,10,2,1108,C,A,2,13.65,15,128,166559,279921911,13.110000,100,1,13.630000,15,1,13.010000,2,1,13.640000,100,1,12.980000,200,2,13.900000,2,1,12.860000,100,1,13.930000,100,1,12.730000,100,1,14.250000,100,1,12.710000,100,1,14.280000,100,1,12.500000,700,1,14.470000,100,1,12.490000,200,2,14.480000,700,1,12.460000,100,1,14.510000,100,1,12.430000,700,1,14.560000,800,2,ARL,335996705
2025-07-17T16:10:46.561246030Z,2025-07-17T16:10:46.561080616Z,10,2,1108,C,A,11,14.62,100,0,165414,279924883,13.110000,100,1,13.630000,15,1,13.010000,2,1,13.640000,100,1,12.980000,200,2,13.900000,2,1,12.860000,100,1,13.930000,100,1,12.730000,100,1,14.250000,100,1,12.710000,100,1,14.280000,100,1,12.500000,700,1,14.470000,100,1,12.490000,200,2,14.480000,700,1,12.460000,100,1,14.510000,100,1,12.430000,700,1,14.560000,800,2,ARL,334583361
2025-07-17T16:10:46.561246030Z,2025-07-17T16:10:46.561080616Z,10,2,1108,A,A,8,14.51,100,130,165414,279924883,13.110000,100,1,13.630000,15,1,13.010000,2,1,13.640000,100,1,12.980000,200,2,13.900000,2,1,12.860000,100,1,13.930000,100,1,12.730000,100,1,14.250000,100,1,12.710000,100,1,14.280000,100,1,12.500000,700,1,14.470000,100,1,12.490000,200,2,14.480000,700,1,12.460000,100,1,14.510000,200,2,12.430000,700,1,14.560000,800,2,ARL,336261905
2025-07-17T16:10:47.543404001Z,2025-07-17T16:10:47.543238729Z,10,2,1108,A,A,0,13.61,15,130,165272,279938097,13.110000,100,1,13.610000,15,1,13.010000,2,1,13.630000,15,1,12.980000,200,2,13.640000,100,1,12.860000,100,1,13.900000,2,1,12.730000,100,1,13.930000,100,1,12.710000,100,1,14.250000,100,1,12.500000,700,1,14.280000,100,1,12.490000,200,2,14.470000,100,1,12.460000,100,1,14.480000,700,1,12.430000,700,1,14.510000,200,2,ARL,336278197
2025-07-17T16:10:48.657456395Z,2025-07-17T16:10:48.657290980Z,10,2,1108,C,A,2,13.64,100,0,165415,279952266,13.110000,100,1,13.610000,15,1,13.010000,2,1,13.630000,15,1,12.980000,200,2,13.900000,2,1,12.860000,100,1,13.930000,100,1,12.730000,100,1,14.250000,100,1,12.710000,100,1,14.280000,100,1,12.500000,700,1,14.470000,100,1,12.490000,200,2,14.480000,700,1,12.460000,100,1,14.510000,200,2,12.430000,700,1,14.560000,800,2,ARL,336161337
2025-07-17T16:10:48.657456395Z,2025-07-17T16:10:48.657290980Z,10,2,1108,A,A,1,13.62,100,130,165415,279952266,13.110000,100,1,13.610000,15,1,13.010000,2,1,13.620000,100,1,12.980000,200,2,13.630000,15,1,12.860000,100,1,13.900000,2,1,12.730000,100,1,13.930000,100,1,12.710000,100,1,14.250000,100,1,12.500000,700,1,14.280000,100,1,12.490000,200,2,14.470000,100,1,12.460000,100,1,14.480000,700,1,12.430000,700,1,14.510000,200,2,ARL,336295769
2025-07-17T16:10:48.658199425Z,2025-07-17T16:10:48.658033954Z,10,2,1108,C,A,14,14.72,100,0,165471,279952282,13.110000,100,1,13.610000,15,1,13.010000,2,1,13.620000,100,1,12.980000,200,2,13.630000,15,1,12.860000,100,1,13.900000,2,1,12.730000,100,1,13.930000,100,1,12.710000,100,1,14.250000,100,1,12.500000,700,1,14.280000,100,1,12.490000,200,2,14.470000,100,1,12.460000,100,1,14.480000,700,1,12.430000,700,1,14.510000,200,2,ARL,335996725
2025-07-17T16:10:48.658199425Z,2025-07-17T16:10:48.658033954Z,10,2,1108,A,A,-1,14.68,100,130,165471,279952282,13.110000,100,1,13.610000,15,1,13.010000,2,1,13.620000,100,1,12.980000,200,2,13.630000,15,1,12.860000,100,1,13.900000,2,1,12.730000,100,1,13.930000,100,1,12.710000,100,1,14.250000,100,1,12.500000,700,1,14.280000,100,1,12.490000,200,2,14.470000,100,1,12.460000,100,1,14.480000,700,1,12.430000,700,1,14.510000,200,2,ARL,336295845
2025-07-17T16:10:51.059044292Z,2025-07-17T16:10:51.058878264Z,10,2,1108,C,A,0,13.61,15,128,166028,280001840,13.110000,100,1,13.620000,100,1,13.010000,2,1,13.630000,15,1,12.980000,200,2,13.900000,2,1,12.860000,100,1,13.930000,100,1,12.730000,100,1,14.250000,100,1,12.710000,100,1,14.280000,100,1,12.500000,700,1,14.470000,100,1,12.490000,200,2,14.480000,700,1,12.460000,100,1,14.510000,200,2,12.430000,700,1,14.560000,800,2,ARL,336278197
2025-07-17T16:10:51.059183923Z,2025-07-17T16:10:51.059016199Z,10,2,1108,C,A,1,13.63,15,128,167724,280001873,13.110000,100,1,13.620000,100,1,13.010000,2,1,13.900000,2,1,12.980000,200,2,13.930000,100,1,12.860000,100,1,14.250000,100,1,12.730000,100,1,14.280000,100,1,12.710000,100,1,14.470000,100,1,12.500000,700,1,14.480000,700,1,12.490000,200,2,14.510000,200,2,12.460000,100,1,14.560000,800,2,12.430000,700,1,14.600000,700,1,ARL,336161333
2025-07-17T16:10:51.059608753Z,2025-07-17T16:10:51.059443298Z,10,2,1108,C,A,0,13.62,100,130,165455,280001952,13.110000,100,1,13.900000,2,1,13.010000,2,1,13.930000,100,1,12.980000,200,2,14.250000,100,1,12.860000,100,1,14.280000,100,1,12.730000,100,1,14.470000,100,1,12.710000,100,1,14.480000,700,1,12.500000,700,1,14.510000,200,2,12.490000,200,2,14.560000,800,2,12.460000,100,1,14.600000,700,1,12.430000,700,1,14.640000,200,2,ARL,336295769
2025-07-17T16:10:51.170710609Z,2025-07-17T16:10:51.170545251Z,10,2,1108,A,A,1,13.91,100,130,165358,280003702,13.110000,100,1,13.900000,2,1,13.010000,2,1,13.910000,100,1,12.980000,200,2,13.930000,100,1,12.860000,100,1,14.250000,100,1,12.730000,100,1,14.280000,100,1,12.710000,100,1,14.470000,100,1,12.500000,700,1,14.480000,700,1,12.490000,200,2,14.510000,200,2,12.460000,100,1,14.560000,800,2,12.430000,700,1,14.600000,700,1,ARL,336351081
2025-07-17T16:10:52.958453641Z,2025-07-17T16:10:52.958288317Z,10,2,1108,A,A,0,13.60,15,130,165324,280050139,13.110000,100,1,13.600000,15,1,13.010000,2,1,13.900000,2,1,12.980000,200,2,13.910000,100,1,12.860000,100,1,13.930000,100,1,12.730000,100,1,14.250000,100,1,12.710000,100,1,14.280000,100,1,12.500000,700,1,14.470000,100,1,12.490000,200,2,14.480000,700,1,12.460000,100,1,14.510000,200,2,12.430000,700,1,14.560000,800,2,ARL,336402845
2025-07-17T16:10:53.102037173Z,2025-07-17T16:10:53.101871639Z,10,2,1108,C,A,2,13.91,100,0,165534,280057228,13.110000,100,1,13.600000,15,1,13.010000,2,1,13.900000,2,1,12.980000,200,2,13.930000,100,1,12.860000,100,1,14.250000,100,1,12.730000,100,1,14.280000,100,1,12.710000,100,1,14.470000,100,1,12.500000,700,1,14.480000,700,1,12.490000,200,2,14.510000,200,2,12.460000,100,1,14.560000,800,2,12.430000,700,1,14.600000,700,1,ARL,336351081
2025-07-17T16:10:53.102037173Z,2025-07-17T16:10:53.101871639Z,10,2,1108,A,A,1,13.61,100,130,165534,280057228,13.110000,100,1,13.600000,15,1,13.010000,2,1,13.610000,100,1,12.980000,200,2,13.900000,2,1,12.860000,100,1,13.930000,100,1,12.730000,100,1,14.250000,100,1,12.710000,100,1,14.280000,100,1,12.500000,700,1,14.470000,100,1,12.490000,200,2,14.480000,700,1,12.460000,100,1,14.510000,200,2,12.430000,700,1,14.560000,800,2,ARL,336410125
2025-07-17T16:10:54.959307592Z,2025-07-17T16:10:54.959141873Z,10,2,1108,C,A,2,13.90,2,0,165719,280084546,13.110000,100,1,13.600000,15,1,13.010000,2,1,13.610000,100,1,12.980000,200,2,13.930000,100,1,12.860000,100,1,14.250000,100,1,12.730000,100,1,14.280000,100,1,12.710000,100,1,14.470000,100,1,12.500000,700,1,14.480000,700,1,12.490000,200,2,14.510000,200,2,12.460000,100,1,14.560000,800,2,12.430000,700,1,14.600000,700,1,ARL,334804177
2025-07-17T16:10:54.959307592Z,2025-07-17T16:10:54.959141873Z,10,2,1108,A,A,2,13.82,2,130,165719,280084546,13.110000,100,1,13.600000,15,1,13.010000,2,1,13.610000,100,1,12.980000,200,2,13.820000,2,1,12.860000,100,1,13.930000,100,1,12.730000,100,1,14.250000,100,1,12.710000,100,1,14.280000,100,1,12.500000,700,1,14.470000,100,1,12.490000,200,2,14.480000,700,1,12.460000,100,1,14.510000,200,2,12.430000,700,1,14.560000,800,2,ARL,336447325
2025-07-17T16:10:59.518035805Z,2025-07-17T16:10:59.517870358Z,10,2,1108,A,A,0,13.58,15,130,165447,280173685,13.110000,100,1,13.580000,15,1,13.010000,2,1,13.600000,15,1,12.980000,200,2,13.610000,100,1,12.860000,100,1,13.820000,2,1,12.730000,100,1,13.930000,100,1,12.710000,100,1,14.250000,100,1,12.500000,700,1,14.280000,100,1,12.490000,200,2,14.470000,100,1,12.460000,100,1,14.480000,700,1,12.430000,700,1,14.510000,200,2,ARL,336555153
2025-07-17T16:11:00.215885294Z,2025-07-17T16:11:00.215719725Z,10,2,1108,C,A,2,13.61,100,0,165569,280184406,13.110000,100,1,13.580000,15,1,13.010000,2,1,13.600000,15,1,12.980000,200,2,13.820000,2,1,12.860000,100,1,13.930000,100,1,12.730000,100,1,14.250000,100,1,12.710000,100,1,14.280000,100,1,12.500000,700,1,14.470000,100,1,12.490000,200,2,14.480000,700,1,12.460000,100,1,14.510000,200,2,12.430000,700,1,14.560000,800,2,ARL,336410125
2025-07-17T16:11:00.215885294Z,2025-07-17T16:11:00.215719725Z,10,2,1108,A,A,1,13.59,100,130,165569,280184406,13.110000,100,1,13.580000,15,1,13.010000,2,1,13.590000,100,1,12.980000,200,2,13.600000,15,1,12.860000,100,1,13.820000,2,1,12.730000,100,1,13.930000,100,1,12.710000,100,1,14.250000,100,1,12.500000,700,1,14.280000,100,1,12.490000,200,2,14.470000,100,1,12.460000,100,1,14.480000,700,1,12.430000,700,1,14.510000,200,2,ARL,336567189
2025-07-17T16:11:00.216622121Z,2025-07-17T16:11:00.216456547Z,10,2,1108,C,A,13,14.68,100,0,165574,280184418,13.110000,100,1,13.580000,15,1,13.010000,2,1,13.590000,100,1,12.980000,200,2,13.600000,15,1,12.860000,100,1,13.820000,2,1,12.730000,100,1,13.930000,100,1,12.710000,100,1,14.250000,100,1,12.500000,700,1,14.280000,100,1,12.490000,200,2,14.470000,100,1,12.460000,100,1,14.480000,700,1,12.430000,700,1,14.510000,200,2,ARL,336295845
2025-07-17T16:11:00.216622121Z,2025-07-17T16:11:00.216456547Z,10,2,1108,A,A,-1,14.64,100,130,165574,280184418,13.110000,100,1,13.580000,15,1,13.010000,2,1,13.590000,100,1,12.980000,200,2,13.600000,15,1,12.860000,100,1,13.820000,2,1,12.730000,100,1,13.930000,100,1,12.710000,100,1,14.250000,100,1,12.500000,700,1,14.280000,100,1,12.490000,200,2,14.470000,100,1,12.460000,100,1,14.480000,700,1,12.430000,700,1,14.510000,200,2,ARL,336567213
2025-07-17T16:11:00.228999377Z,2025-07-17T16:11:00.228833925Z,10,2,1108,C,A,4,13.93,100,130,165452,280184613,13.110000,100,1,13.580000,15,1,13.010000,2,1,13.590000,100,1,12.980000,200,2,13.600000,15,1,12.860000,100,1,13.820000,2,1,12.730000,100,1,14.250000,100,1,12.710000,100,1,14.280000,100,1,12.500000,700,1,14.470000,100,1,12.490000,200,2,14.480000,700,1,12.460000,100,1,14.510000,200,2,12.430000,700,1,14.560000,800,2,ARL,335996777
2025-07-17T16:11:00.229051124Z,2025-07-17T16:11:00.228885790Z,10,2,1108,A,A,4,13.86,100,130,165334,280184614,13.110000,100,1,13.580000,15,1,13.010000,2,1,13.590000,100,1,12.980000,200,2,13.600000,15,1,12.860000,100,1,13.820000,2,1,12.730000,100,1,13.860000,100,1,12.710000,100,1,14.250000,100,1,12.500000,700,1,14.280000,100,1,12.490000,200,2,14.470000,100,1,12.460000,100,1,14.480000,700,1,12.430000,700,1,14.510000,200,2,ARL,336567333
2025-07-17T16:11:00.313087129Z,2025-07-17T16:11:00.312921679Z,10,2,1108,C,A,21,17.42,100,0,165450,280188038,13.110000,100,1,13.580000,15,1,13.010000,2,1,13.590000,100,1,12.980000,200,2,13.600000,15,1,12.860000,100,1,13.820000,2,1,12.730000,100,1,13.860000,100,1,12.710000,100,1,14.250000,100,1,12.500000,700,1,14.280000,100,1,12.490000,200,2,14.470000,100,1,12.460000,100,1,14.480000,700,1,12.430000,700,1,14.510000,200,2,ARL,335003849
2025-07-17T16:11:00.313087129Z,2025-07-17T16:11:00.312921679Z,10,2,1108,A,A,-1,17.26,100,130,165450,280188038,13.110000,100,1,13.580000,15,1,13.010000,2,1,13.590000,100,1,12.980000,200,2,13.600000,15,1,12.860000,100,1,13.820000,2,1,12.730000,100,1,13.860000,100,1,12.710000,100,1,14.250000,100,1,12.500000,700,1,14.280000,100,1,12.490000,200,2,14.470000,100,1,12.460000,100,1,14.480000,700,1,12.430000,700,1,14.510000,200,2,ARL,336570921
2025-07-17T16:11:00.366811541Z,2025-07-17T16:11:00.366645846Z,10,2,1108,A,A,3,13.62,1,130,165695,280189435,13.110000,100,1,13.580000,15,1,13.010000,2,1,13.590000,100,1,12.980000,200,2,13.600000,15,1,12.860000,100,1,13.620000,1,1,12.730000,100,1,13.820000,2,1,12.710000,100,1,13.860000,100,1,12.500000,700,1,14.250000,100,1,12.490000,200,2,14.280000,100,1,12.460000,100,1,14.470000,100,1,12.430000,700,1,14.480000,700,1,ARL,336572049
2025-07-17T16:11:00.367374773Z,2025-07-17T16:11:00.367209243Z,10,2,1108,C,B,7,12.49,100,0,165530,280189439,13.110000,100,1,13.580000,15,1,13.010000,2,1,13.590000,100,1,12.980000,200,2,13.600000,15,1,12.860000,100,1,13.620000,1,1,12.730000,100,1,13.820000,2,1,12.710000,100,1,13.860000,100,1,12.500000,700,1,14.250000,100,1,12.490000,100,1,14.280000,100,1,12.460000,100,1,14.470000,100,1,12.430000,700,1,14.480000,700,1,ARL,331942945
2025-07-17T16:11:00.367374773Z,2025-07-17T16:11:00.367209243Z,10,2,1108,A,B,-1,12.36,100,130,165530,280189439,13.110000,100,1,13.580000,15,1,13.010000,2,1,13.590000,100,1,12.980000,200,2,13.600000,15,1,12.860000,100,1,13.620000,1,1,12.730000,100,1,13.820000,2,1,12.710000,100,1,13.860000,100,1,12.500000,700,1,14.250000,100,1,12.490000,100,1,14.280000,100,1,12.460000,100,1,14.470000,100,1,12.430000,700,1,14.480000,700,1,ARL,336572057
2025-07-17T16:11:00.367485094Z,2025-07-17T16:11:00.367319059Z,10,2,1108,C,B,7,12.49,100,0,166035,280189441,13.110000,100,1,13.580000,15,1,13.010000,2,1,13.590000,100,1,12.980000,200,2,13.600000,15,1,12.860000,100,1,13.620000,1,1,12.730000,100,1,13.820000,2,1,12.710000,100,1,13.860000,100,1,12.500000,700,1,14.250000,100,1,12.460000,100,1,14.280000,100,1,12.430000,700,1,14.470000,100,1,12.420000,700,1,14.480000,700,1,ARL,331942901
2025-07-17T16:11:00.367485094Z,2025-07-17T16:11:00.367319059Z,10,2,1108,A,B,-1,12.36,100,130,166035,280189441,13.110000,100,1,13.580000,15,1,13.010000,2,1,13.590000,100,1,12.980000,200,2,13.600000,15,1,12.860000,100,1,13.620000,1,1,12.730000,100,1,13.820000,2,1,12.710000,100,1,13.860000,100,1,12.500000,700,1,14.250000,100,1,12.460000,100,1,14.280000,100,1,12.430000,700,1,14.470000,100,1,12.420000,700,1,14.480000,700,1,ARL,336572069
2025-07-17T16:11:00.466868624Z,2025-07-17T16:11:00.466703632Z,10,2,1108,C,A,3,13.62,1,130,164992,280191783,13.110000,100,1,13.580000,15,1,13.010000,2,1,13.590000,100,1,12.980000,200,2,13.600000,15,1,12.860000,100,1,13.820000,2,1,12.730000,100,1,13.860000,100,1,12.710000,100,1,14.250000,100,1,12.500000,700,1,14.280000,100,1,12.460000,100,1,14.470000,100,1,12.430000,700,1,14.480000,700,1,12.420000,700,1,14.510000,200,2,ARL,336572049
2025-07-17T16:11:06.626831799Z,2025-07-17T16:11:06.626666474Z,10,2,1108,A,A,6,14.27,700,130,165325,280342316,13.110000,100,1,13.580000,15,1,13.010000,2,1,13.590000,100,1,12.980000,200,2,13.600000,15,1,12.860000,100,1,13.820000,2,1,12.730000,100,1,13.860000,100,1,12.710000,100,1,14.250000,100,1,12.500000,700,1,14.270000,700,1,12.460000,100,1,14.280000,100,1,12.430000,700,1,14.470000,100,1,12.420000,700,1,14.480000,700,1,ARL,336747457
2025-07-17T16:11:06.626906700Z,2025-07-17T16:11:06.626741446Z,10,2,1108,C,A,14,14.68,700,130,165254,280342318,13.110000,100,1,13.580000,15,1,13.010000,2,1,13.590000,100,1,12.980000,200,2,13.600000,15,1,12.860000,100,1,13.820000,2,1,12.730000,100,1,13.860000,100,1,12.710000,100,1,14.250000,100,1,12.500000,700,1,14.270000,700,1,12.460000,100,1,14.280000,100,1,12.430000,700,1,14.470000,100,1,12.420000,700,1,14.480000,700,1,ARL,331929977
2025-07-17T16:11:08.308034538Z,2025-07-17T16:11:08.307868957Z,10,2,1108,C,A,2,13.60,15,130,165581,280374785,13.110000,100,1,13.580000,15,1,13.010000,2,1,13.590000,100,1,12.980000,200,2,13.820000,2,1,12.860000,100,1,13.860000,100,1,12.730000,100,1,14.250000,100,1,12.710000,100,1,14.270000,700,1,12.500000,700,1,14.280000,100,1,12.460000,100,1,14.470000,100,1,12.430000,700,1,14.480000,700,1,12.420000,700,1,14.510000,200,2,ARL,336402845
2025-07-17T16:11:09.568536292Z,2025-07-17T16:11:09.568370995Z,10,2,1108,A,A,0,13.56,15,130,165297,280401189,13.110000,100,1,13.560000,15,1,13.010000,2,1,13.580000,15,1,12.980000,200,2,13.590000,100,1,12.860000,100,1,13.820000,2,1,12.730000,100,1,13.860000,100,1,12.710000,100,1,14.250000,100,1,12.500000,700,1,14.270000,700,1,12.460000,100,1,14.280000,100,1,12.430000,700,1,14.470000,100,1,12.420000,700,1,14.480000,700,1,ARL,336816813
2025-07-17T16:11:10.341953971Z,2025-07-17T16:11:10.341788521Z,10,2,1108,C,A,2,13.59,100,0,165450,280411396,13.110000,100,1,13.560000,15,1,13.010000,2,1,13.580000,15,1,12.980000,200,2,13.820000,2,1,12.860000,100,1,13.860000,100,1,12.730000,100,1,14.250000,100,1,12.710000,100,1,14.270000,700,1,12.500000,700,1,14.280000,100,1,12.460000,100,1,14.470000,100,1,12.430000,700,1,14.480000,700,1,12.420000,700,1,14.510000,200,2,ARL,336567189
2025-07-17T16:11:10.341953971Z,2025-07-17T16:11:10.341788521Z,10,2,1108,A,A,1,13.57,100,130,165450,280411396,13.110000,100,1,13.560000,15,1,13.010000,2,1,13.570000,100,1,12.980000,200,2,13.580000,15,1,12.860000,100,1,13.820000,2,1,12.730000,100,1,13.860000,100,1,12.710000,100,1,14.250000,100,1,12.500000,700,1,14.270000,700,1,12.460000,100,1,14.280000,100,1,12.430000,700,1,14.470000,100,1,12.420000,700,1,14.480000,700,1,ARL,336828765
2025-07-17T16:11:14.610701450Z,2025-07-17T16:11:14.610535763Z,10,2,1108,C,A,2,13.58,15,130,165687,280482371,13.110000,100,1,13.560000,15,1,13.010000,2,1,13.570000,100,1,12.980000,200,2,13.820000,2,1,12.860000,100,1,13.860000,100,1,12.730000,100,1,14.250000,100,1,12.710000,100,1,14.270000,700,1,12.500000,700,1,14.280000,100,1,12.460000,100,1,14.470000,100,1,12.430000,700,1,14.480000,700,1,12.420000,700,1,14.510000,200,2,ARL,336555153
2025-07-17T16:11:16.025458231Z,2025-07-17T16:11:16.025292936Z,10,2,1108,C,A,0,13.56,15,130,165295,280514282,13.110000,100,1,13.570000,100,1,13.010000,2,1,13.820000,2,1,12.980000,200,2,13.860000,100,1,12.860000,100,1,14.250000,100,1,12.730000,100,1,14.270000,700,1,12.710000,100,1,14.280000,100,1,12.500000,700,1,14.470000,100,1,12.460000,100,1,14.480000,700,1,12.430000,700,1,14.510000,200,2,12.420000,700,1,14.560000,800,2,ARL,336816813
2025-07-17T16:11:50.026837358Z,2025-07-17T16:11:50.026672014Z,10,2,1108,A,A,0,13.55,15,130,165344,281078802,13.110000,100,1,13.550000,15,1,13.010000,2,1,13.570000,100,1,12.980000,200,2,13.820000,2,1,12.860000,100,1,13.860000,100,1,12.730000,100,1,14.250000,100,1,12.710000,100,1,14.270000,700,1,12.500000,700,1,14.280000,100,1,12.460000,100,1,14.470000,100,1,12.430000,700,1,14.480000,700,1,12.420000,700,1,14.510000,200,2,ARL,337690189
2025-07-17T16:11:50.027004977Z,2025-07-17T16:11:50.026839463Z,10,2,1108,C,A,1,13.57,100,0,165514,281078803,13.110000,100,1,13.550000,15,1,13.010000,2,1,13.820000,2,1,12.980000,200,2,13.860000,100,1,12.860000,100,1,14.250000,100,1,12.730000,100,1,14.270000,700,1,12.710000,100,1,14.280000,100,1,12.500000,700,1,14.470000,100,1,12.460000,100,1,14.480000,700,1,12.430000,700,1,14.510000,200,2,12.420000,700,1,14.560000,800,2,ARL,336828765
2025-07-17T16:11:50.027004977Z,2025-07-17T16:11:50.026839463Z,10,2,1108,A,A,1,13.56,100,130,165514,281078803,13.110000,100,1,13.550000,15,1,13.010000,2,1,13.560000,100,1,12.980000,200,2,13.820000,2,1,12.860000,100,1,13.860000,100,1,12.730000,100,1,14.250000,100,1,12.710000,100,1,14.270000,700,1,12.500000,700,1,14.280000,100,1,12.460000,100,1,14.470000,100,1,12.430000,700,1,14.480000,700,1,12.420000,700,1,14.510000,200,2,ARL,337690193
2025-07-17T16:11:50.033010798Z,2025-07-17T16:11:50.032845393Z,10,2,1108,C,A,17,15.74,100,0,165405,281078903,13.110000,100,1,13.550000,15,1,13.010000,2,1,13.560000,100,1,12.980000,200,2,13.820000,2,1,12.860000,100,1,13.860000,100,1,12.730000,100,1,14.250000,100,1,12.710000,100,1,14.270000,700,1,12.500000,700,1,14.280000,100,1,12.460000,100,1,14.470000,100,1,12.430000,700,1,14.480000,700,1,12.420000,700,1,14.510000,200,2,ARL,335220497
2025-07-17T16:11:50.033010798Z,2025-07-17T16:11:50.032845393Z,10,2,1108,A,A,-1,15.60,100,130,165405,281078903,13.110000,100,1,13.550000,15,1,13.010000,2,1,13.560000,100,1,12.980000,200,2,13.820000,2,1,12.860000,100,1,13.860000,100,1,12.730000,100,1,14.250000,100,1,12.710000,100,1,14.270000,700,1,12.500000,700,1,14.280000,100,1,12.460000,100,1,14.470000,100,1,12.430000,700,1,14.480000,700,1,12.420000,700,1,14.510000,200,2,ARL,337690641
2025-07-17T16:11:53.859909462Z,2025-07-17T16:11:53.859743991Z,10,2,1108,A,A,0,13.53,15,130,165471,281142794,13.110000,100,1,13.530000,15,1,13.010000,2,1,13.550000,15,1,12.980000,200,2,13.560000,100,1,12.860000,100,1,13.820000,2,1,12.730000,100,1,13.860000,100,1,12.710000,100,1,14.250000,100,1,12.500000,700,1,14.270000,700,1,12.460000,100,1,14.280000,100,1,12.430000,700,1,14.470000,100,1,12.420000,700,1,14.480000,700,1,ARL,337772837
2025-07-17T16:11:54.662527332Z,2025-07-17T16:11:54.662361841Z,10,2,1108,C,A,2,13.56,100,0,165491,281156215,13.110000,100,1,13.530000,15,1,13.010000,2,1,13.550000,15,1,12.980000,200,2,13.820000,2,1,12.860000,100,1,13.860000,100,1,12.730000,100,1,14.250000,100,1,12.710000,100,1,14.270000,700,1,12.500000,700,1,14.280000,100,1,12.460000,100,1,14.470000,100,1,12.430000,700,1,14.480000,700,1,12.420000,700,1,14.510000,200,2,ARL,337690193
2025-07-17T16:11:54.662527332Z,2025-07-17T16:11:54.662361841Z,10,2,1108,A,A,1,13.54,100,130,165491,281156215,13.110000,100,1,13.530000,15,1,13.010000,2,1,13.540000,100,1,12.980000,200,2,13.550000,15,1,12.860000,100,1,13.820000,2,1,12.730000,100,1,13.860000,100,1,12.710000,100,1,14.250000,100,1,12.500000,700,1,14.270000,700,1,12.460000,100,1,14.280000,100,1,12.430000,700,1,14.470000,100,1,12.420000,700,1,14.480000,700,1,ARL,337790717
2025-07-17T16:11:54.663278200Z,2025-07-17T16:11:54.663112543Z,10,2,1108,C,A,13,14.64,100,0,165657,281156222,13.110000,100,1,13.530000,15,1,13.010000,2,1,13.540000,100,1,12.980000,200,2,13.550000,15,1,12.860000,100,1,13.820000,2,1,12.730000,100,1,13.860000,100,1,12.710000,100,1,14.250000,100,1,12.500000,700,1,14.270000,700,1,12.460000,100,1,14.280000,100,1,12.430000,700,1,14.470000,100,1,12.420000,700,1,14.480000,700,1,ARL,336567213
2025-07-17T16:11:54.663278200Z,2025-07-17T16:11:54.663112543Z,10,2,1108,A,A,-1,14.59,100,130,165657,281156222,13.110000,100,1,13.530000,15,1,13.010000,2,1,13.540000,100,1,12.980000,200,2,13.550000,15,1,12.860000,100,1,13.820000,2,1,12.730000,100,1,13.860000,100,1,12.710000,100,1,14.250000,100,1,12.500000,700,1,14.270000,700,1,12.460000,100,1,14.280000,100,1,12.430000,700,1,14.470000,100,1,12.420000,700,1,14.480000,700,1,ARL,337790737
2025-07-17T16:11:54.664134026Z,2025-07-17T16:11:54.663968656Z,10,2,1108,C,A,14,14.64,100,0,165370,281156223,13.110000,100,1,13.530000,15,1,13.010000,2,1,13.540000,100,1,12.980000,200,2,13.550000,15,1,12.860000,100,1,13.820000,2,1,12.730000,100,1,13.860000,100,1,12.710000,100,1,14.250000,100,1,12.500000,700,1,14.270000,700,1,12.460000,100,1,14.280000,100,1,12.430000,700,1,14.470000,100,1,12.420000,700,1,14.480000,700,1,ARL,335220525
2025-07-17T16:11:54.664134026Z,2025-07-17T16:11:54.663968656Z,10,2,1108,A,A,-1,14.49,100,130,165370,281156223,13.110000,100,1,13.530000,15,1,13.010000,2,1,13.540000,100,1,12.980000,200,2,13.550000,15,1,12.860000,100,1,13.820000,2,1,12.730000,100,1,13.860000,100,1,12.710000,100,1,14.250000,100,1,12.500000,700,1,14.270000,700,1,12.460000,100,1,14.280000,100,1,12.430000,700,1,14.470000,100,1,12.420000,700,1,14.480000,700,1,ARL,337790745
2025-07-17T16:11:54.666326600Z,2025-07-17T16:11:54.666160990Z,10,2,1108,C,A,8,14.47,100,0,165610,281156243,13.110000,100,1,13.530000,15,1,13.010000,2,1,13.540000,100,1,12.980000,200,2,13.550000,15,1,12.860000,100,1,13.820000,2,1,12.730000,100,1,13.860000,100,1,12.710000,100,1,14.250000,100,1,12.500000,700,1,14.270000,700,1,12.460000,100,1,14.280000,100,1,12.430000,700,1,14.480000,700,1,12.420000,700,1,14.490000,100,1,ARL,335220561
2025-07-17T16:11:54.666326600Z,2025-07-17T16:11:54.666160990Z,10,2,1108,A,A,8,14.33,100,130,165610,281156243,13.110000,100,1,13.530000,15,1,13.010000,2,1,13.540000,100,1,12.980000,200,2,13.550000,15,1,12.860000,100,1,13.820000,2,1,12.730000,100,1,13.860000,100,1,12.710000,100,1,14.250000,100,1,12.500000,700,1,14.270000,700,1,12.460000,100,1,14.280000,100,1,12.430000,700,1,14.330000,100,1,12.420000,700,1,14.480000,700,1,ARL,337790761
2025-07-17T16:11:54.667504546Z,2025-07-17T16:11:54.667339002Z,10,2,1108,C,A,15,14.64,100,0,165544,281156250,13.110000,100,1,13.530000,15,1,13.010000,2,1,13.540000,100,1,12.980000,200,2,13.550000,15,1,12.860000,100,1,13.820000,2,1,12.730000,100,1,13.860000,100,1,12.710000,100,1,14.250000,100,1,12.500000,700,1,14.270000,700,1,12.460000,100,1,14.280000,100,1,12.430000,700,1,14.330000,100,1,12.420000,700,1,14.480000,700,1,ARL,335220629
2025-07-17T16:11:54.667504546Z,2025-07-17T16:11:54.667339002Z,10,2,1108,A,A,-1,14.49,100,130,165544,281156250,13.110000,100,1,13.530000,15,1,13.010000,2,1,13.540000,100,1,12.980000,200,2,13.550000,15,1,12.860000,100,1,13.820000,2,1,12.730000,100,1,13.860000,100,1,12.710000,100,1,14.250000,100,1,12.500000,700,1,14.270000,700,1,12.460000,100,1,14.280000,100,1,12.430000,700,1,14.330000,100,1,12.420000,700,1,14.480000,700,1,ARL,337790777
2025-07-17T16:11:59.382515678Z,2025-07-17T16:11:59.382350338Z,10,2,1108,C,A,2,13.55,15,130,165340,281270010,13.110000,100,1,13.530000,15,1,13.010000,2,1,13.540000,100,1,12.980000,200,2,13.820000,2,1,12.860000,100,1,13.860000,100,1,12.730000,100,1,14.250000,100,1,12.710000,100,1,14.270000,700,1,12.500000,700,1,14.280000,100,1,12.460000,100,1,14.330000,100,1,12.430000,700,1,14.480000,700,1,12.420000,700,1,14.490000,200,2,ARL,337690189
2025-07-17T16:12:02.982078719Z,2025-07-17T16:12:02.981913204Z,10,2,1108,A,A,0,13.51,15,130,165515,281348152,13.110000,100,1,13.510000,15,1,13.010000,2,1,13.530000,15,1,12.980000,200,2,13.540000,100,1,12.860000,100,1,13.820000,2,1,12.730000,100,1,13.860000,100,1,12.710000,100,1,14.250000,100,1,12.500000,700,1,14.270000,700,1,12.460000,100,1,14.280000,100,1,12.430000,700,1,14.330000,100,1,12.420000,700,1,14.480000,700,1,ARL,338041605
2025-07-17T16:12:03.064162605Z,2025-07-17T16:12:03.063997054Z,10,2,1108,C,A,2,13.54,100,0,165551,281351122,13.110000,100,1,13.510000,15,1,13.010000,2,1,13.530000,15,1,12.980000,200,2,13.820000,2,1,12.860000,100,1,13.860000,100,1,12.730000,100,1,14.250000,100,1,12.710000,100,1,14.270000,700,1,12.500000,700,1,14.280000,100,1,12.460000,100,1,14.330000,100,1,12.430000,700,1,14.480000,700,1,12.420000,700,1,14.490000,200,2,ARL,337790717
2025-07-17T16:12:03.064162605Z,2025-07-17T16:12:03.063997054Z,10,2,1108,A,A,1,13.52,100,130,165551,281351122,13.110000,100,1,13.510000,15,1,13.010000,2,1,13.520000,100,1,12.980000,200,2,13.530000,15,1,12.860000,100,1,13.820000,2,1,12.730000,100,1,13.860000,100,1,12.710000,100,1,14.250000,100,1,12.500000,700,1,14.270000,700,1,12.460000,100,1,14.280000,100,1,12.430000,700,1,14.330000,100,1,12.420000,700,1,14.480000,700,1,ARL,338044041
2025-07-17T16:12:03.068467146Z,2025-07-17T16:12:03.068301745Z,10,2,1108,C,B,1,13.01,2,0,165401,281351235,13.110000,100,1,13.510000,15,1,12.980000,200,2,13.520000,100,1,12.860000,100,1,13.530000,15,1,12.730000,100,1,13.820000,2,1,12.710000,100,1,13.860000,100,1,12.500000,700,1,14.250000,100,1,12.460000,100,1,14.270000,700,1,12.430000,700,1,14.280000,100,1,12.420000,700,1,14.330000,100,1,12.370000,700,1,14.480000,700,1,ARL,332494213
2025-07-17T16:12:03.068467146Z,2025-07-17T16:12:03.068301745Z,10,2,1108,A,B,2,12.92,2,130,165401,281351235,13.110000,100,1,13.510000,15,1,12.980000,200,2,13.520000,100,1,12.920000,2,1,13.530000,15,1,12.860000,100,1,13.820000,2,1,12.730000,100,1,13.860000,100,1,12.710000,100,1,14.250000,100,1,12.500000,700,1,14.270000,700,1,12.460000,100,1,14.280000,100,1,12.430000,700,1,14.330000,100,1,12.420000,700,1,14.480000,700,1,ARL,338044113
2025-07-17T16:12:03.075200038Z,2025-07-17T16:12:03.075034550Z,10,2,1108,C,A,4,13.86,100,130,165488,281351372,13.110000,100,1,13.510000,15,1,12.980000,200,2,13.520000,100,1,12.920000,2,1,13.530000,15,1,12.860000,100,1,13.820000,2,1,12.730000,100,1,14.250000,100,1,12.710000,100,1,14.270000,700,1,12.500000,700,1,14.280000,100,1,12.460000,100,1,14.330000,100,1,12.430000,700,1,14.480000,700,1,12.420000,700,1,14.490000,200,2,ARL,336567333
2025-07-17T16:12:03.075260529Z,2025-07-17T16:12:03.075095341Z,10,2,1108,A,A,3,13.79,100,130,165188,281351373,13.110000,100,1,13.510000,15,1,12.980000,200,2,13.520000,100,1,12.920000,2,1,13.530000,15,1,12.860000,100,1,13.790000,100,1,12.730000,100,1,13.820000,2,1,12.710000,100,1,14.250000,100,1,12.500000,700,1,14.270000,700,1,12.460000,100,1,14.280000,100,1,12.430000,700,1,14.330000,100,1,12.420000,700,1,14.480000,700,1,ARL,338044233
2025-07-17T16:12:06.775177637Z,2025-07-17T16:12:06.775011783Z,10,2,1108,C,A,11,14.51,100,0,165854,281422697,13.110000,100,1,13.510000,15,1,12.980000,200,2,13.520000,100,1,12.920000,2,1,13.530000,15,1,12.860000,100,1,13.790000,100,1,12.730000,100,1,13.820000,2,1,12.710000,100,1,14.250000,100,1,12.500000,700,1,14.270000,700,1,12.460000,100,1,14.280000,100,1,12.430000,700,1,14.330000,100,1,12.420000,700,1,14.480000,700,1,ARL,336259225
2025-07-17T16:12:06.775177637Z,2025-07-17T16:12:06.775011783Z,10,2,1108,A,A,9,14.40,100,130,165854,281422697,13.110000,100,1,13.510000,15,1,12.980000,200,2,13.520000,100,1,12.920000,2,1,13.530000,15,1,12.860000,100,1,13.790000,100,1,12.730000,100,1,13.820000,2,1,12.710000,100,1,14.250000,100,1,12.500000,700,1,14.270000,700,1,12.460000,100,1,14.280000,100,1,12.430000,700,1,14.330000,100,1,12.420000,700,1,14.400000,100,1,ARL,338139585
2025-07-17T16:12:06.775614536Z,2025-07-17T16:12:06.775449017Z,10,2,1108,C,A,12,14.51,100,0,165519,281422702,13.110000,100,1,13.510000,15,1,12.980000,200,2,13.520000,100,1,12.920000,2,1,13.530000,15,1,12.860000,100,1,13.790000,100,1,12.730000,100,1,13.820000,2,1,12.710000,100,1,14.250000,100,1,12.500000,700,1,14.270000,700,1,12.460000,100,1,14.280000,100,1,12.430000,700,1,14.330000,100,1,12.420000,700,1,14.400000,100,1,ARL,336261905
2025-07-17T16:12:06.775614536Z,2025-07-17T16:12:06.775449017Z,10,2,1108,A,A,9,14.40,100,130,165519,281422702,13.110000,100,1,13.510000,15,1,12.980000,200,2,13.520000,100,1,12.920000,2,1,13.530000,15,1,12.860000,100,1,13.790000,100,1,12.730000,100,1,13.820000,2,1,12.710000,100,1,14.250000,100,1,12.500000,700,1,14.270000,700,1,12.460000,100,1,14.280000,100,1,12.430000,700,1,14.330000,100,1,12.420000,700,1,14.400000,200,2,ARL,338139601
2025-07-17T16:12:06.779705717Z,2025-07-17T16:12:06.779540143Z,10,2,1108,C,A,2,13.53,15,130,165574,281422782,13.110000,100,1,13.510000,15,1,12.980000,200,2,13.520000,100,1,12.920000,2,1,13.790000,100,1,12.860000,100,1,13.820000,2,1,12.730000,100,1,14.250000,100,1,12.710000,100,1,14.270000,700,1,12.500000,700,1,14.280000,100,1,12.460000,100,1,14.330000,100,1,12.430000,700,1,14.400000,200,2,12.420000,700,1,14.480000,700,1,ARL,337772837
2025-07-17T16:12:07.784698893Z,2025-07-17T16:12:07.784533539Z,10,2,1108,A,A,0,13.49,15,130,165354,281443568,13.110000,100,1,13.490000,15,1,12.980000,200,2,13.510000,15,1,12.920000,2,1,13.520000,100,1,12.860000,100,1,13.790000,100,1,12.730000,100,1,13.820000,2,1,12.710000,100,1,14.250000,100,1,12.500000,700,1,14.270000,700,1,12.460000,100,1,14.280000,100,1,12.430000,700,1,14.330000,100,1,12.420000,700,1,14.400000,200,2,ARL,338167057
2025-07-17T16:12:08.585194585Z,2025-07-17T16:12:08.585029039Z,10,2,1108,C,A,2,13.52,100,0,165546,281451898,13.110000,100,1,13.490000,15,1,12.980000,200,2,13.510000,15,1,12.920000,2,1,13.790000,100,1,12.860000,100,1,13.820000,2,1,12.730000,100,1,14.250000,100,1,12.710000,100,1,14.270000,700,1,12.500000,700,1,14.280000,100,1,12.460000,100,1,14.330000,100,1,12.430000,700,1,14.400000,200,2,12.420000,700,1,14.480000,700,1,ARL,338044041
2025-07-17T16:12:08.585194585Z,2025-07-17T16:12:08.585029039Z,10,2,1108,A,A,1,13.50,100,130,165546,281451898,13.110000,100,1,13.490000,15,1,12.980000,200,2,13.500000,100,1,12.920000,2,1,13.510000,15,1,12.860000,100,1,13.790000,100,1,12.730000,100,1,13.820000,2,1,12.710000,100,1,14.250000,100,1,12.500000,700,1,14.270000,700,1,12.460000,100,1,14.280000,100,1,12.430000,700,1,14.330000,100,1,12.420000,700,1,14.400000,200,2,ARL,338180793
2025-07-17T16:12:08.585942049Z,2025-07-17T16:12:08.585776508Z,10,2,1108,C,A,13,14.59,100,0,165541,281451903,13.110000,100,1,13.490000,15,1,12.980000,200,2,13.500000,100,1,12.920000,2,1,13.510000,15,1,12.860000,100,1,13.790000,100,1,12.730000,100,1,13.820000,2,1,12.710000,100,1,14.250000,100,1,12.500000,700,1,14.270000,700,1,12.460000,100,1,14.280000,100,1,12.430000,700,1,14.330000,100,1,12.420000,700,1,14.400000,200,2,ARL,337790737
2025-07-17T16:12:08.585942049Z,2025-07-17T16:12:08.585776508Z,10,2,1108,A,A,-1,14.55,100,130,165541,281451903,13.110000,100,1,13.490000,15,1,12.980000,200,2,13.500000,100,1,12.920000,2,1,13.510000,15,1,12.860000,100,1,13.790000,100,1,12.730000,100,1,13.820000,2,1,12.710000,100,1,14.250000,100,1,12.500000,700,1,14.270000,700,1,12.460000,100,1,14.280000,100,1,12.430000,700,1,14.330000,100,1,12.420000,700,1,14.400000,200,2,ARL,338180841
2025-07-17T16:12:18.789922022Z,2025-07-17T16:12:18.789756367Z,10,2,1108,C,A,4,13.82,2,0,165655,281613266,13.110000,100,1,13.490000,15,1,12.980000,200,2,13.500000,100,1,12.920000,2,1,13.510000,15,1,12.860000,100,1,13.790000,100,1,12.730000,100,1,14.250000,100,1,12.710000,100,1,14.270000,700,1,12.500000,700,1,14.280000,100,1,12.460000,100,1,14.330000,100,1,12.430000,700,1,14.400000,200,2,12.420000,700,1,14.480000,700,1,ARL,336447325
2025-07-17T16:12:18.789922022Z,2025-07-17T16:12:18.789756367Z,10,2,1108,A,A,3,13.74,2,130,165655,281613266,13.110000,100,1,13.490000,15,1,12.980000,200,2,13.500000,100,1,12.920000,2,1,13.510000,15,1,12.860000,100,1,13.740000,2,1,12.730000,100,1,13.790000,100,1,12.710000,100,1,14.250000,100,1,12.500000,700,1,14.270000,700,1,12.460000,100,1,14.280000,100,1,12.430000,700,1,14.330000,100,1,12.420000,700,1,14.400000,200,2,ARL,338371797
2025-07-17T16:12:19.370986404Z,2025-07-17T16:12:19.370820933Z,10,2,1108,A,A,6,14.27,700,130,165471,281622545,13.110000,100,1,13.490000,15,1,12.980000,200,2,13.500000,100,1,12.920000,2,1,13.510000,15,1,12.860000,100,1,13.740000,2,1,12.730000,100,1,13.790000,100,1,12.710000,100,1,14.250000,100,1,12.500000,700,1,14.270000,1400,2,12.460000,100,1,14.280000,100,1,12.430000,700,1,14.330000,100,1,12.420000,700,1,14.400000,200,2,ARL,338382329
2025-07-17T16:12:19.371041049Z,2025-07-17T16:12:19.370875240Z,10,2,1108,C,A,14,14.60,700,130,165809,281622547,13.110000,100,1,13.490000,15,1,12.980000,200,2,13.500000,100,1,12.920000,2,1,13.510000,15,1,12.860000,100,1,13.740000,2,1,12.730000,100,1,13.790000,100,1,12.710000,100,1,14.250000,100,1,12.500000,700,1,14.270000,1400,2,12.460000,100,1,14.280000,100,1,12.430000,700,1,14.330000,100,1,12.420000,700,1,14.400000,200,2,ARL,282920685
2025-07-17T16:12:19.696689718Z,2025-07-17T16:12:19.696521343Z,10,2,1108,C,A,0,13.49,15,128,168375,281630053,13.110000,100,1,13.500000,100,1,12.980000,200,2,13.510000,15,1,12.920000,2,1,13.740000,2,1,12.860000,100,1,13.790000,100,1,12.730000,100,1,14.250000,100,1,12.710000,100,1,14.270000,1400,2,12.500000,700,1,14.280000,100,1,12.460000,100,1,14.330000,100,1,12.430000,700,1,14.400000,200,2,12.420000,700,1,14.480000,700,1,ARL,338167057
2025-07-17T16:12:19.711773364Z,2025-07-17T16:12:19.711591494Z,10,2,1108,C,A,1,13.51,15,128,181870,281634812,13.110000,100,1,13.500000,100,1,12.980000,200,2,13.740000,2,1,12.920000,2,1,13.790000,100,1,12.860000,100,1,14.250000,100,1,12.730000,100,1,14.270000,1400,2,12.710000,100,1,14.280000,100,1,12.500000,700,1,14.330000,100,1,12.460000,100,1,14.400000,200,2,12.430000,700,1,14.480000,700,1,12.420000,700,1,14.490000,200,2,ARL,338041605
2025-07-17T16:12:32.761277424Z,2025-07-17T16:12:32.761112078Z,10,2,1108,A,A,0,13.48,15,130,165346,281880398,13.110000,100,1,13.480000,15,1,12.980000,200,2,13.500000,100,1,12.920000,2,1,13.740000,2,1,12.860000,100,1,13.790000,100,1,12.730000,100,1,14.250000,100,1,12.710000,100,1,14.270000,1400,2,12.500000,700,1,14.280000,100,1,12.460000,100,1,14.330000,100,1,12.430000,700,1,14.400000,200,2,12.420000,700,1,14.480000,700,1,ARL,338707945
2025-07-17T16:12:32.761413202Z,2025-07-17T16:12:32.761246859Z,10,2,1108,C,A,1,13.50,100,0,166343,281880409,13.110000,100,1,13.480000,15,1,12.980000,200,2,13.740000,2,1,12.920000,2,1,13.790000,100,1,12.860000,100,1,14.250000,100,1,12.730000,100,1,14.270000,1400,2,12.710000,100,1,14.280000,100,1,12.500000,700,1,14.330000,100,1,12.460000,100,1,14.400000,200,2,12.430000,700,1,14.480000,700,1,12.420000,700,1,14.490000,200,2,ARL,338180793
2025-07-17T16:12:32.761413202Z,2025-07-17T16:12:32.761246859Z,10,2,1108,A,A,1,13.49,100,130,166343,281880409,13.110000,100,1,13.480000,15,1,12.980000,200,2,13.490000,100,1,12.920000,2,1,13.740000,2,1,12.860000,100,1,13.790000,100,1,12.730000,100,1,14.250000,100,1,12.710000,100,1,14.270000,1400,2,12.500000,700,1,14.280000,100,1,12.460000,100,1,14.330000,100,1,12.430000,700,1,14.400000,200,2,12.420000,700,1,14.480000,700,1,ARL,338707949
2025-07-17T16:12:32.779055996Z,2025-07-17T16:12:32.778890447Z,10,2,1108,C,A,14,15.12,100,0,165549,281880579,13.110000,100,1,13.480000,15,1,12.980000,200,2,13.490000,100,1,12.920000,2,1,13.740000,2,1,12.860000,100,1,13.790000,100,1,12.730000,100,1,14.250000,100,1,12.710000,100,1,14.270000,1400,2,12.500000,700,1,14.280000,100,1,12.460000,100,1,14.330000,100,1,12.430000,700,1,14.400000,200,2,12.420000,700,1,14.480000,700,1,ARL,296387089
2025-07-17T16:12:32.779055996Z,2025-07-17T16:12:32.778890447Z,10,2,1108,A,A,-1,14.84,100,130,165549,281880579,13.110000,100,1,13.480000,15,1,12.980000,200,2,13.490000,100,1,12.920000,2,1,13.740000,2,1,12.860000,100,1,13.790000,100,1,12.730000,100,1,14.250000,100,1,12.710000,100,1,14.270000,1400,2,12.500000,700,1,14.280000,100,1,12.460000,100,1,14.330000,100,1,12.430000,700,1,14.400000,200,2,12.420000,700,1,14.480000,700,1,ARL,338708241
2025-07-17T16:12:32.804318005Z,2025-07-17T16:12:32.804152457Z,10,2,1108,A,A,-1,15.38,100,130,165548,281880972,13.110000,100,1,13.480000,15,1,12.980000,200,2,13.490000,100,1,12.920000,2,1,13.740000,2,1,12.860000,100,1,13.790000,100,1,12.730000,100,1,14.250000,100,1,12.710000,100,1,14.270000,1400,2,12.500000,700,1,14.280000,100,1,12.460000,100,1,14.330000,100,1,12.430000,700,1,14.400000,200,2,12.420000,700,1,14.480000,700,1,ARL,338709513
2025-07-17T16:12:32.804332586Z,2025-07-17T16:12:32.804166092Z,10,2,1108,C,A,18,15.66,100,130,166494,281880973,13.110000,100,1,13.480000,15,1,12.980000,200,2,13.490000,100,1,12.920000,2,1,13.740000,2,1,12.860000,100,1,13.790000,100,1,12.730000,100,1,14.250000,100,1,12.710000,100,1,14.270000,1400,2,12.500000,700,1,14.280000,100,1,12.460000,100,1,14.330000,100,1,12.430000,700,1,14.400000,200,2,12.420000,700,1,14.480000,700,1,ARL,326730513
2025-07-17T16:12:40.993064296Z,2025-07-17T16:12:40.992898990Z,10,2,1108,C,A,1,13.49,100,130,165306,282007871,13.110000,100,1,13.480000,15,1,12.980000,200,2,13.740000,2,1,12.920000,2,1,13.790000,100,1,12.860000,100,1,14.250000,100,1,12.730000,100,1,14.270000,1400,2,12.710000,100,1,14.280000,100,1,12.500000,700,1,14.330000,100,1,12.460000,100,1,14.400000,200,2,12.430000,700,1,14.480000,700,1,12.420000,700,1,14.490000,200,2,ARL,338707949
2025-07-17T16:12:40.993332664Z,2025-07-17T16:12:40.993167418Z,10,2,1108,C,A,4,14.27,700,130,165246,282007875,13.110000,100,1,13.480000,15,1,12.980000,200,2,13.740000,2,1,12.920000,2,1,13.790000,100,1,12.860000,100,1,14.250000,100,1,12.730000,100,1,14.270000,700,1,12.710000,100,1,14.280000,100,1,12.500000,700,1,14.330000,100,1,12.460000,100,1,14.400000,200,2,12.430000,700,1,14.480000,700,1,12.420000,700,1,14.490000,200,2,ARL,338382329
2025-07-17T16:12:40.993333790Z,2025-07-17T16:12:40.993168470Z,10,2,1108,C,A,4,14.27,700,130,165320,282007876,13.110000,100,1,13.480000,15,1,12.980000,200,2,13.740000,2,1,12.920000,2,1,13.790000,100,1,12.860000,100,1,14.250000,100,1,12.730000,100,1,14.280000,100,1,12.710000,100,1,14.330000,100,1,12.500000,700,1,14.400000,200,2,12.460000,100,1,14.480000,700,1,12.430000,700,1,14.490000,200,2,12.420000,700,1,14.550000,100,1,ARL,336747457
2025-07-17T16:12:40.993379626Z,2025-07-17T16:12:40.993214193Z,10,2,1108,A,A,9,14.54,700,130,165433,282007877,13.110000,100,1,13.480000,15,1,12.980000,200,2,13.740000,2,1,12.920000,2,1,13.790000,100,1,12.860000,100,1,14.250000,100,1,12.730000,100,1,14.280000,100,1,12.710000,100,1,14.330000,100,1,12.500000,700,1,14.400000,200,2,12.460000,100,1,14.480000,700,1,12.430000,700,1,14.490000,200,2,12.420000,700,1,14.540000,700,1,ARL,338864169
2025-07-17T16:12:40.993393440Z,2025-07-17T16:12:40.993227993Z,10,2,1108,A,A,7,14.47,700,130,165447,282007878,13.110000,100,1,13.480000,15,1,12.980000,200,2,13.740000,2,1,12.920000,2,1,13.790000,100,1,12.860000,100,1,14.250000,100,1,12.730000,100,1,14.280000,100,1,12.710000,100,1,14.330000,100,1,12.500000,700,1,14.400000,200,2,12.460000,100,1,14.470000,700,1,12.430000,700,1,14.480000,700,1,12.420000,700,1,14.490000,200,2,ARL,338864173
2025-07-17T16:12:40.993432115Z,2025-07-17T16:12:40.993266591Z,10,2,1108,A,A,-1,15.71,100,130,165524,282007879,13.110000,100,1,13.480000,15,1,12.980000,200,2,13.740000,2,1,12.920000,2,1,13.790000,100,1,12.860000,100,1,14.250000,100,1,12.730000,100,1,14.280000,100,1,12.710000,100,1,14.330000,100,1,12.500000,700,1,14.400000,200,2,12.460000,100,1,14.470000,700,1,12.430000,700,1,14.480000,700,1,12.420000,700,1,14.490000,200,2,ARL,338864177
2025-07-17T16:12:40.993445042Z,2025-07-17T16:12:40.993279810Z,10,2,1108,C,A,16,15.38,100,130,165232,282007880,13.110000,100,1,13.480000,15,1,12.980000,200,2,13.740000,2,1,12.920000,2,1,13.790000,100,1,12.860000,100,1,14.250000,100,1,12.730000,100,1,14.280000,100,1,12.710000,100,1,14.330000,100,1,12.500000,700,1,14.400000,200,2,12.460000,100,1,14.470000,700,1,12.430000,700,1,14.480000,700,1,12.420000,700,1,14.490000,200,2,ARL,338709513
2025-07-17T16:12:40.993818130Z,2025-07-17T16:12:40.993652511Z,10,2,1108,C,A,11,14.55,100,0,165619,282007882,13.110000,100,1,13.480000,15,1,12.980000,200,2,13.740000,2,1,12.920000,2,1,13.790000,100,1,12.860000,100,1,14.250000,100,1,12.730000,100,1,14.280000,100,1,12.710000,100,1,14.330000,100,1,12.500000,700,1,14.400000,200,2,12.460000,100,1,14.470000,700,1,12.430000,700,1,14.480000,700,1,12.420000,700,1,14.490000,200,2,ARL,338180841
2025-07-17T16:12:40.993818130Z,2025-07-17T16:12:40.993652511Z,10,2,1108,A,A,-1,14.85,100,130,165619,282007882,13.110000,100,1,13.480000,15,1,12.980000,200,2,13.740000,2,1,12.920000,2,1,13.790000,100,1,12.860000,100,1,14.250000,100,1,12.730000,100,1,14.280000,100,1,12.710000,100,1,14.330000,100,1,12.500000,700,1,14.400000,200,2,12.460000,100,1,14.470000,700,1,12.430000,700,1,14.480000,700,1,12.420000,700,1,14.490000,200,2,ARL,338864189
2025-07-17T16:12:40.994783297Z,2025-07-17T16:12:40.994617858Z,10,2,1108,C,A,9,14.49,100,0,165439,282007892,13.110000,100,1,13.480000,15,1,12.980000,200,2,13.740000,2,1,12.920000,2,1,13.790000,100,1,12.860000,100,1,14.250000,100,1,12.730000,100,1,14.280000,100,1,12.710000,100,1,14.330000,100,1,12.500000,700,1,14.400000,200,2,12.460000,100,1,14.470000,700,1,12.430000,700,1,14.480000,700,1,12.420000,700,1,14.490000,100,1,ARL,337790745
2025-07-17T16:12:40.994783297Z,2025-07-17T16:12:40.994617858Z,10,2,1108,A,A,-1,14.76,100,130,165439,282007892,13.110000,100,1,13.480000,15,1,12.980000,200,2,13.740000,2,1,12.920000,2,1,13.790000,100,1,12.860000,100,1,14.250000,100,1,12.730000,100,1,14.280000,100,1,12.710000,100,1,14.330000,100,1,12.500000,700,1,14.400000,200,2,12.460000,100,1,14.470000,700,1,12.430000,700,1,14.480000,700,1,12.420000,700,1,14.490000,100,1,ARL,338864217
2025-07-17T16:12:40.995078856Z,2025-07-17T16:12:40.994913404Z,10,2,1108,C,A,13,14.84,100,0,165452,282007894,13.110000,100,1,13.480000,15,1,12.980000,200,2,13.740000,2,1,12.920000,2,1,13.790000,100,1,12.860000,100,1,14.250000,100,1,12.730000,100,1,14.280000,100,1,12.710000,100,1,14.330000,100,1,12.500000,700,1,14.400000,200,2,12.460000,100,1,14.470000,700,1,12.430000,700,1,14.480000,700,1,12.420000,700,1,14.490000,100,1,ARL,338708241
2025-07-17T16:12:40.995078856Z,2025-07-17T16:12:40.994913404Z,10,2,1108,A,A,-1,15.17,100,130,165452,282007894,13.110000,100,1,13.480000,15,1,12.980000,200,2,13.740000,2,1,12.920000,2,1,13.790000,100,1,12.860000,100,1,14.250000,100,1,12.730000,100,1,14.280000,100,1,12.710000,100,1,14.330000,100,1,12.500000,700,1,14.400000,200,2,12.460000,100,1,14.470000,700,1,12.430000,700,1,14.480000,700,1,12.420000,700,1,14.490000,100,1,ARL,338864221
2025-07-17T16:12:40.995349303Z,2025-07-17T16:12:40.995183768Z,10,2,1108,C,A,17,15.60,100,0,165535,282007898,13.110000,100,1,13.480000,15,1,12.980000,200,2,13.740000,2,1,12.920000,2,1,13.790000,100,1,12.860000,100,1,14.250000,100,1,12.730000,100,1,14.280000,100,1,12.710000,100,1,14.330000,100,1,12.500000,700,1,14.400000,200,2,12.460000,100,1,14.470000,700,1,12.430000,700,1,14.480000,700,1,12.420000,700,1,14.490000,100,1,ARL,337690641
2025-07-17T16:12:40.995349303Z,2025-07-17T16:12:40.995183768Z,10,2,1108,A,A,-1,15.86,100,130,165535,282007898,13.110000,100,1,13.480000,15,1,12.980000,200,2,13.740000,2,1,12.920000,2,1,13.790000,100,1,12.860000,100,1,14.250000,100,1,12.730000,100,1,14.280000,100,1,12.710000,100,1,14.330000,100,1,12.500000,700,1,14.400000,200,2,12.460000,100,1,14.470000,700,1,12.430000,700,1,14.480000,700,1,12.420000,700,1,14.490000,100,1,ARL,338864245
2025-07-17T16:12:40.996460080Z,2025-07-17T16:12:40.996294601Z,10,2,1108,C,A,21,17.26,100,0,165479,282007909,13.110000,100,1,13.480000,15,1,12.980000,200,2,13.740000,2,1,12.920000,2,1,13.790000,100,1,12.860000,100,1,14.250000,100,1,12.730000,100,1,14.280000,100,1,12.710000,100,1,14.330000,100,1,12.500000,700,1,14.400000,200,2,12.460000,100,1,14.470000,700,1,12.430000,700,1,14.480000,700,1,12.420000,700,1,14.490000,100,1,ARL,336570921
2025-07-17T16:12:40.996460080Z,2025-07-17T16:12:40.996294601Z,10,2,1108,A,A,-1,17.52,100,130,165479,282007909,13.110000,100,1,13.480000,15,1,12.980000,200,2,13.740000,2,1,12.920000,2,1,13.790000,100,1,12.860000,100,1,14.250000,100,1,12.730000,100,1,14.280000,100,1,12.710000,100,1,14.330000,100,1,12.500000,700,1,14.400000,200,2,12.460000,100,1,14.470000,700,1,12.430000,700,1,14.480000,700,1,12.420000,700,1,14.490000,100,1,ARL,338864289
2025-07-17T16:12:40.997300700Z,2025-07-17T16:12:40.997135307Z,10,2,1108,C,A,5,14.33,100,130,165393,282007914,13.110000,100,1,13.480000,15,1,12.980000,200,2,13.740000,2,1,12.920000,2,1,13.790000,100,1,12.860000,100,1,14.250000,100,1,12.730000,100,1,14.280000,100,1,12.710000,100,1,14.400000,200,2,12.500000,700,1,14.470000,700,1,12.460000,100,1,14.480000,700,1,12.430000,700,1,14.490000,100,1,12.420000,700,1,14.540000,700,1,ARL,337790761
2025-07-17T16:12:40.997422356Z,2025-07-17T16:12:40.997257014Z,10,2,1108,A,A,-1,14.58,100,130,165342,282007916,13.110000,100,1,13.480000,15,1,12.980000,200,2,13.740000,2,1,12.920000,2,1,13.790000,100,1,12.860000,100,1,14.250000,100,1,12.730000,100,1,14.280000,100,1,12.710000,100,1,14.400000,200,2,12.500000,700,1,14.470000,700,1,12.460000,100,1,14.480000,700,1,12.430000,700,1,14.490000,100,1,12.420000,700,1,14.540000,700,1,ARL,338864317
2025-07-17T16:12:41.004229622Z,2025-07-17T16:12:41.004063876Z,10,2,1108,C,A,8,14.49,100,0,165746,282007959,13.110000,100,1,13.480000,15,1,12.980000,200,2,13.740000,2,1,12.920000,2,1,13.790000,100,1,12.860000,100,1,14.250000,100,1,12.730000,100,1,14.280000,100,1,12.710000,100,1,14.400000,200,2,12.500000,700,1,14.470000,700,1,12.460000,100,1,14.480000,700,1,12.430000,700,1,14.540000,700,1,12.420000,700,1,14.560000,800,2,ARL,337790777
2025-07-17T16:12:41.004229622Z,2025-07-17T16:12:41.004063876Z,10,2,1108,A,A,-1,14.76,100,130,165746,282007959,13.110000,100,1,13.480000,15,1,12.980000,200,2,13.740000,2,1,12.920000,2,1,13.790000,100,1,12.860000,100,1,14.250000,100,1,12.730000,100,1,14.280000,100,1,12.710000,100,1,14.400000,200,2,12.500000,700,1,14.470000,700,1,12.460000,100,1,14.480000,700,1,12.430000,700,1,14.540000,700,1,12.420000,700,1,14.560000,800,2,ARL,338864405
2025-07-17T16:12:41.005576053Z,2025-07-17T16:12:41.005406614Z,10,2,1108,A,A,1,13.49,100,128,169439,282008256,13.110000,100,1,13.480000,15,1,12.980000,200,2,13.490000,100,1,12.920000,2,1,13.740000,2,1,12.860000,100,1,13.790000,100,1,12.730000,100,1,14.250000,100,1,12.710000,100,1,14.280000,100,1,12.500000,700,1,14.400000,200,2,12.460000,100,1,14.470000,700,1,12.430000,700,1,14.480000,700,1,12.420000,700,1,14.540000,700,1,ARL,338864581
2025-07-17T16:12:41.010638351Z,2025-07-17T16:12:41.010473041Z,10,2,1108,C,A,12,14.76,100,0,165310,282008884,13.110000,100,1,13.480000,15,1,12.980000,200,2,13.490000,100,1,12.920000,2,1,13.740000,2,1,12.860000,100,1,13.790000,100,1,12.730000,100,1,14.250000,100,1,12.710000,100,1,14.280000,100,1,12.500000,700,1,14.400000,200,2,12.460000,100,1,14.470000,700,1,12.430000,700,1,14.480000,700,1,12.420000,700,1,14.540000,700,1,ARL,338864405
2025-07-17T16:12:41.010638351Z,2025-07-17T16:12:41.010473041Z,10,2,1108,A,A,7,14.44,100,130,165310,282008884,13.110000,100,1,13.480000,15,1,12.980000,200,2,13.490000,100,1,12.920000,2,1,13.740000,2,1,12.860000,100,1,13.790000,100,1,12.730000,100,1,14.250000,100,1,12.710000,100,1,14.280000,100,1,12.500000,700,1,14.400000,200,2,12.460000,100,1,14.440000,100,1,12.430000,700,1,14.470000,700,1,12.420000,700,1,14.480000,700,1,ARL,338865133
2025-07-17T16:12:41.011160341Z,2025-07-17T16:12:41.010994859Z,10,2,1108,C,A,3,13.79,100,130,165482,282008914,13.110000,100,1,13.480000,15,1,12.980000,200,2,13.490000,100,1,12.920000,2,1,13.740000,2,1,12.860000,100,1,14.250000,100,1,12.730000,100,1,14.280000,100,1,12.710000,100,1,14.400000,200,2,12.500000,700,1,14.440000,100,1,12.460000,100,1,14.470000,700,1,12.430000,700,1,14.480000,700,1,12.420000,700,1,14.540000,700,1,ARL,338044233
2025-07-17T16:12:41.011211986Z,2025-07-17T16:12:41.011046717Z,10,2,1108,A,A,3,14.06,100,130,165269,282008916,13.110000,100,1,13.480000,15,1,12.980000,200,2,13.490000,100,1,12.920000,2,1,13.740000,2,1,12.860000,100,1,14.060000,100,1,12.730000,100,1,14.250000,100,1,12.710000,100,1,14.280000,100,1,12.500000,700,1,14.400000,200,2,12.460000,100,1,14.440000,100,1,12.430000,700,1,14.470000,700,1,12.420000,700,1,14.480000,700,1,ARL,338865141
2025-07-17T16:12:41.011555342Z,2025-07-17T16:12:41.011390077Z,10,2,1108,C,A,13,14.76,100,0,165265,282008942,13.110000,100,1,13.480000,15,1,12.980000,200,2,13.490000,100,1,12.920000,2,1,13.740000,2,1,12.860000,100,1,14.060000,100,1,12.730000,100,1,14.250000,100,1,12.710000,100,1,14.280000,100,1,12.500000,700,1,14.400000,200,2,12.460000,100,1,14.440000,100,1,12.430000,700,1,14.470000,700,1,12.420000,700,1,14.480000,700,1,ARL,338864217
2025-07-17T16:12:41.011555342Z,2025-07-17T16:12:41.011390077Z,10,2,1108,A,A,7,14.44,100,130,165265,282008942,13.110000,100,1,13.480000,15,1,12.980000,200,2,13.490000,100,1,12.920000,2,1,13.740000,2,1,12.860000,100,1,14.060000,100,1,12.730000,100,1,14.250000,100,1,12.710000,100,1,14.280000,100,1,12.500000,700,1,14.400000,200,2,12.460000,100,1,14.440000,200,2,12.430000,700,1,14.470000,700,1,12.420000,700,1,14.480000,700,1,ARL,338865165
2025-07-17T16:12:41.012044919Z,2025-07-17T16:12:41.011879795Z,10,2,1108,C,A,3,14.06,100,130,165124,282008953,13.110000,100,1,13.480000,15,1,12.980000,200,2,13.490000,100,1,12.920000,2,1,13.740000,2,1,12.860000,100,1,14.250000,100,1,12.730000,100,1,14.280000,100,1,12.710000,100,1,14.400000,200,2,12.500000,700,1,14.440000,200,2,12.460000,100,1,14.470000,700,1,12.430000,700,1,14.480000,700,1,12.420000,700,1,14.540000,700,1,ARL,338865141
2025-07-17T16:12:41.012094494Z,2025-07-17T16:12:41.011929033Z,10,2,1108,A,A,3,13.76,100,130,165461,282008954,13.110000,100,1,13.480000,15,1,12.980000,200,2,13.490000,100,1,12.920000,2,1,13.740000,2,1,12.860000,100,1,13.760000,100,1,12.730000,100,1,14.250000,100,1,12.710000,100,1,14.280000,100,1,12.500000,700,1,14.400000,200,2,12.460000,100,1,14.440000,200,2,12.430000,700,1,14.470000,700,1,12.420000,700,1,14.480000,700,1,ARL,338865177
2025-07-17T16:12:41.014974491Z,2025-07-17T16:12:41.014809197Z,10,2,1108,C,A,21,17.52,100,0,165294,282008990,13.110000,100,1,13.480000,15,1,12.980000,200,2,13.490000,100,1,12.920000,2,1,13.740000,2,1,12.860000,100,1,13.760000,100,1,12.730000,100,1,14.250000,100,1,12.710000,100,1,14.280000,100,1,12.500000,700,1,14.400000,200,2,12.460000,100,1,14.440000,200,2,12.430000,700,1,14.470000,700,1,12.420000,700,1,14.480000,700,1,ARL,338864289
2025-07-17T16:12:41.014974491Z,2025-07-17T16:12:41.014809197Z,10,2,1108,A,A,-1,17.14,100,130,165294,282008990,13.110000,100,1,13.480000,15,1,12.980000,200,2,13.490000,100,1,12.920000,2,1,13.740000,2,1,12.860000,100,1,13.760000,100,1,12.730000,100,1,14.250000,100,1,12.710000,100,1,14.280000,100,1,12.500000,700,1,14.400000,200,2,12.460000,100,1,14.440000,200,2,12.430000,700,1,14.470000,700,1,12.420000,700,1,14.480000,700,1,ARL,338865253
2025-07-17T16:12:41.017837378Z,2025-07-17T16:12:41.017672033Z,10,2,1108,C,A,18,15.86,100,0,165345,282009053,13.110000,100,1,13.480000,15,1,12.980000,200,2,13.490000,100,1,12.920000,2,1,13.740000,2,1,12.860000,100,1,13.760000,100,1,12.730000,100,1,14.250000,100,1,12.710000,100,1,14.280000,100,1,12.500000,700,1,14.400000,200,2,12.460000,100,1,14.440000,200,2,12.430000,700,1,14.470000,700,1,12.420000,700,1,14.480000,700,1,ARL,338864245
2025-07-17T16:12:41.017837378Z,2025-07-17T16:12:41.017672033Z,10,2,1108,A,A,-1,15.52,100,130,165345,282009053,13.110000,100,1,13.480000,15,1,12.980000,200,2,13.490000,100,1,12.920000,2,1,13.740000,2,1,12.860000,100,1,13.760000,100,1,12.730000,100,1,14.250000,100,1,12.710000,100,1,14.280000,100,1,12.500000,700,1,14.400000,200,2,12.460000,100,1,14.440000,200,2,12.430000,700,1,14.470000,700,1,12.420000,700,1,14.480000,700,1,ARL,338865301
2025-07-17T16:12:41.032270817Z,2025-07-17T16:12:41.032105565Z,10,2,1108,C,A,15,15.17,100,0,165252,282009412,13.110000,100,1,13.480000,15,1,12.980000,200,2,13.490000,100,1,12.920000,2,1,13.740000,2,1,12.860000,100,1,13.760000,100,1,12.730000,100,1,14.250000,100,1,12.710000,100,1,14.280000,100,1,12.500000,700,1,14.400000,200,2,12.460000,100,1,14.440000,200,2,12.430000,700,1,14.470000,700,1,12.420000,700,1,14.480000,700,1,ARL,338864221
2025-07-17T16:12:41.032270817Z,2025-07-17T16:12:41.032105565Z,10,2,1108,A,A,-1,14.84,100,130,165252,282009412,13.110000,100,1,13.480000,15,1,12.980000,200,2,13.490000,100,1,12.920000,2,1,13.740000,2,1,12.860000,100,1,13.760000,100,1,12.730000,100,1,14.250000,100,1,12.710000,100,1,14.280000,100,1,12.500000,700,1,14.400000,200,2,12.460000,100,1,14.440000,200,2,12.430000,700,1,14.470000,700,1,12.420000,700,1,14.480000,700,1,ARL,338866081
2025-07-17T16:12:41.032312420Z,2025-07-17T16:12:41.032147083Z,10,2,1108,A,A,-1,15.38,100,130,165337,282009414,13.110000,100,1,13.480000,15,1,12.980000,200,2,13.490000,100,1,12.920000,2,1,13.740000,2,1,12.860000,100,1,13.760000,100,1,12.730000,100,1,14.250000,100,1,12.710000,100,1,14.280000,100,1,12.500000,700,1,14.400000,200,2,12.460000,100,1,14.440000,200,2,12.430000,700,1,14.470000,700,1,12.420000,700,1,14.480000,700,1,ARL,338866089
2025-07-17T16:12:41.032324438Z,2025-07-17T16:12:41.032159348Z,10,2,1108,C,A,19,15.71,100,130,165090,282009415,13.110000,100,1,13.480000,15,1,12.980000,200,2,13.490000,100,1,12.920000,2,1,13.740000,2,1,12.860000,100,1,13.760000,100,1,12.730000,100,1,14.250000,100,1,12.710000,100,1,14.280000,100,1,12.500000,700,1,14.400000,200,2,12.460000,100,1,14.440000,200,2,12.430000,700,1,14.470000,700,1,12.420000,700,1,14.480000,700,1,ARL,338864177
2025-07-17T16:12:41.043406383Z,2025-07-17T16:12:41.043241012Z,10,2,1108,C,A,14,14.85,100,0,165371,282009482,13.110000,100,1,13.480000,15,1,12.980000,200,2,13.490000,100,1,12.920000,2,1,13.740000,2,1,12.860000,100,1,13.760000,100,1,12.730000,100,1,14.250000,100,1,12.710000,100,1,14.280000,100,1,12.500000,700,1,14.400000,200,2,12.460000,100,1,14.440000,200,2,12.430000,700,1,14.470000,700,1,12.420000,700,1,14.480000,700,1,ARL,338864189
2025-07-17T16:12:41.043406383Z,2025-07-17T16:12:41.043241012Z,10,2,1108,A,A,-1,14.54,100,130,165371,282009482,13.110000,100,1,13.480000,15,1,12.980000,200,2,13.490000,100,1,12.920000,2,1,13.740000,2,1,12.860000,100,1,13.760000,100,1,12.730000,100,1,14.250000,100,1,12.710000,100,1,14.280000,100,1,12.500000,700,1,14.400000,200,2,12.460000,100,1,14.440000,200,2,12.430000,700,1,14.470000,700,1,12.420000,700,1,14.480000,700,1,ARL,338866245
2025-07-17T16:12:42.001347844Z,2025-07-17T16:12:42.001182016Z,10,2,1108,C,A,12,14.58,100,0,165828,282033913,13.110000,100,1,13.480000,15,1,12.980000,200,2,13.490000,100,1,12.920000,2,1,13.740000,2,1,12.860000,100,1,13.760000,100,1,12.730000,100,1,14.250000,100,1,12.710000,100,1,14.280000,100,1,12.500000,700,1,14.400000,200,2,12.460000,100,1,14.440000,200,2,12.430000,700,1,14.470000,700,1,12.420000,700,1,14.480000,700,1,ARL,338864317
2025-07-17T16:12:42.001347844Z,2025-07-17T16:12:42.001182016Z,10,2,1108,A,A,5,14.28,100,130,165828,282033913,13.110000,100,1,13.480000,15,1,12.980000,200,2,13.490000,100,1,12.920000,2,1,13.740000,2,1,12.860000,100,1,13.760000,100,1,12.730000,100,1,14.250000,100,1,12.710000,100,1,14.280000,200,2,12.500000,700,1,14.400000,200,2,12.460000,100,1,14.440000,200,2,12.430000,700,1,14.470000,700,1,12.420000,700,1,14.480000,700,1,ARL,338894329
2025-07-17T16:12:42.762154469Z,2025-07-17T16:12:42.761989222Z,10,2,1108,A,A,0,13.46,15,130,165247,282042242,13.110000,100,1,13.460000,15,1,12.980000,200,2,13.480000,15,1,12.920000,2,1,13.490000,100,1,12.860000,100,1,13.740000,2,1,12.730000,100,1,13.760000,100,1,12.710000,100,1,14.250000,100,1,12.500000,700,1,14.280000,200,2,12.460000,100,1,14.400000,200,2,12.430000,700,1,14.440000,200,2,12.420000,700,1,14.470000,700,1,ARL,338904977
2025-07-17T16:12:43.022127902Z,2025-07-17T16:12:43.021951997Z,10,2,1108,C,A,2,13.49,100,0,175905,282057719,13.110000,100,1,13.460000,15,1,12.980000,200,2,13.480000,15,1,12.920000,2,1,13.740000,2,1,12.860000,100,1,13.760000,100,1,12.730000,100,1,14.250000,100,1,12.710000,100,1,14.280000,200,2,12.500000,700,1,14.400000,200,2,12.460000,100,1,14.440000,200,2,12.430000,700,1,14.470000,700,1,12.420000,700,1,14.480000,700,1,ARL,338864581
2025-07-17T16:12:43.022127902Z,2025-07-17T16:12:43.021951997Z,10,2,1108,A,A,1,13.47,100,128,175905,282057719,13.110000,100,1,13.460000,15,1,12.980000,200,2,13.470000,100,1,12.920000,2,1,13.480000,15,1,12.860000,100,1,13.740000,2,1,12.730000,100,1,13.760000,100,1,12.710000,100,1,14.250000,100,1,12.500000,700,1,14.280000,200,2,12.460000,100,1,14.400000,200,2,12.430000,700,1,14.440000,200,2,12.420000,700,1,14.470000,700,1,ARL,338918217
2025-07-17T16:12:43.022612177Z,2025-07-17T16:12:43.022444956Z,10,2,1108,A,A,-1,15.69,100,128,167221,282058085,13.110000,100,1,13.460000,15,1,12.980000,200,2,13.470000,100,1,12.920000,2,1,13.480000,15,1,12.860000,100,1,13.740000,2,1,12.730000,100,1,13.760000,100,1,12.710000,100,1,14.250000,100,1,12.500000,700,1,14.280000,200,2,12.460000,100,1,14.400000,200,2,12.430000,700,1,14.440000,200,2,12.420000,700,1,14.470000,700,1,ARL,338918553
2025-07-17T16:12:43.022627592Z,2025-07-17T16:12:43.022461725Z,10,2,1108,C,A,16,15.38,100,130,165867,282058088,13.110000,100,1,13.460000,15,1,12.980000,200,2,13.470000,100,1,12.920000,2,1,13.480000,15,1,12.860000,100,1,13.740000,2,1,12.730000,100,1,13.760000,100,1,12.710000,100,1,14.250000,100,1,12.500000,700,1,14.280000,200,2,12.460000,100,1,14.400000,200,2,12.430000,700,1,14.440000,200,2,12.420000,700,1,14.470000,700,1,ARL,338866089
2025-07-17T16:12:43.049284355Z,2025-07-17T16:12:43.049119139Z,10,2,1108,A,A,-1,15.36,100,130,165216,282065940,13.110000,100,1,13.460000,15,1,12.980000,200,2,13.470000,100,1,12.920000,2,1,13.480000,15,1,12.860000,100,1,13.740000,2,1,12.730000,100,1,13.760000,100,1,12.710000,100,1,14.250000,100,1,12.500000,700,1,14.280000,200,2,12.460000,100,1,14.400000,200,2,12.430000,700,1,14.440000,200,2,12.420000,700,1,14.470000,700,1,ARL,338926929
2025-07-17T16:12:43.049298989Z,2025-07-17T16:12:43.049132842Z,10,2,1108,C,A,18,15.69,100,128,166147,282065943,13.110000,100,1,13.460000,15,1,12.980000,200,2,13.470000,100,1,12.920000,2,1,13.480000,15,1,12.860000,100,1,13.740000,2,1,12.730000,100,1,13.760000,100,1,12.710000,100,1,14.250000,100,1,12.500000,700,1,14.280000,200,2,12.460000,100,1,14.400000,200,2,12.430000,700,1,14.440000,200,2,12.420000,700,1,14.470000,700,1,ARL,338918553
2025-07-17T16:12:43.154952375Z,2025-07-17T16:12:43.154787212Z,10,2,1108,A,A,6,14.27,100,130,165163,282073056,13.110000,100,1,13.460000,15,1,12.980000,200,2,13.470000,100,1,12.920000,2,1,13.480000,15,1,12.860000,100,1,13.740000,2,1,12.730000,100,1,13.760000,100,1,12.710000,100,1,14.250000,100,1,12.500000,700,1,14.270000,100,1,12.460000,100,1,14.280000,200,2,12.430000,700,1,14.400000,200,2,12.420000,700,1,14.440000,200,2,ARL,338932853
2025-07-17T16:12:43.154965183Z,2025-07-17T16:12:43.154800020Z,10,2,1108,C,A,13,14.56,100,130,165163,282073058,13.110000,100,1,13.460000,15,1,12.980000,200,2,13.470000,100,1,12.920000,2,1,13.480000,15,1,12.860000,100,1,13.740000,2,1,12.730000,100,1,13.760000,100,1,12.710000,100,1,14.250000,100,1,12.500000,700,1,14.270000,100,1,12.460000,100,1,14.280000,200,2,12.430000,700,1,14.400000,200,2,12.420000,700,1,14.440000,200,2,ARL,296391881
2025-07-17T16:12:43.915552526Z,2025-07-17T16:12:43.915387059Z,10,2,1108,C,A,7,14.28,100,130,165467,282085822,13.110000,100,1,13.460000,15,1,12.980000,200,2,13.470000,100,1,12.920000,2,1,13.480000,15,1,12.860000,100,1,13.740000,2,1,12.730000,100,1,13.760000,100,1,12.710000,100,1,14.250000,100,1,12.500000,700,1,14.270000,100,1,12.460000,100,1,14.280000,100,1,12.430000,700,1,14.400000,200,2,12.420000,700,1,14.440000,200,2,ARL,302681357
2025-07-17T16:12:43.915555340Z,2025-07-17T16:12:43.915389642Z,10,2,1108,A,A,5,14.00,100,130,165698,282085823,13.110000,100,1,13.460000,15,1,12.980000,200,2,13.470000,100,1,12.920000,2,1,13.480000,15,1,12.860000,100,1,13.740000,2,1,12.730000,100,1,13.760000,100,1,12.710000,100,1,14.000000,100,1,12.500000,700,1,14.250000,100,1,12.460000,100,1,14.270000,100,1,12.430000,700,1,14.280000,100,1,12.420000,700,1,14.400000,200,2,ARL,338945933
