ts_recv,ts_event,rtype,publisher_id,instrument_id,action,side,depth,price,size,flags,ts_in_delta,sequence,bid_px_00,bid_sz_00,bid_ct_00,ask_px_00,ask_sz_00,ask_ct_00,bid_px_01,bid_sz_01,bid_ct_01,ask_px_01,ask_sz_01,ask_ct_01,bid_px_02,bid_sz_02,bid_ct_02,ask_px_02,ask_sz_02,ask_ct_02,bid_px_03,bid_sz_03,bid_ct_03,ask_px_03,ask_sz_03,ask_ct_03,bid_px_04,bid_sz_04,bid_ct_04,ask_px_04,ask_sz_04,ask_ct_04,bid_px_05,bid_sz_05,bid_ct_05,ask_px_05,ask_sz_05,ask_ct_05,bid_px_06,bid_sz_06,bid_ct_06,ask_px_06,ask_sz_06,ask_ct_06,bid_px_07,bid_sz_07,bid_ct_07,ask_px_07,ask_sz_07,ask_ct_07,bid_px_08,bid_sz_08,bid_ct_08,ask_px_08,ask_sz_08,ask_ct_08,bid_px_09,bid_sz_09,bid_ct_09,ask_px_09,ask_sz_09,ask_ct_09,symbol,order_id
2025-07-17T07:05:09.035793433Z,2025-07-17T07:05:09.035627674Z,10,2,1108,R,N,0,0,0,8,0,0,0.00,0,0,0.00,0,0,0.00,0,0,0.00,0,0,0.00,0,0,0.00,0,0,0.00,0,0,0.00,0,0,0.00,0,0,0.00,0,0,0.00,0,0,0.00,0,0,0.00,0,0,0.00,0,0,0.00,0,0,0.00,0,0,0.00,0,0,0.00,0,0,0.00,0,0,0.00,0,0,ARL,0
2025-07-17T08:05:03.360842448Z,2025-07-17T08:05:03.360677248Z,10,2,1108,A,B,0,5.51,100,130,165200,851012,5.510000,100,1,,0,0,,0,0,,0,0,,0,0,,0,0,,0,0,,0,0,,0,0,,0,0,,0,0,,0,0,,0,0,,0,0,,0,0,,0,0,,0,0,,0,0,,0,0,,0,0,ARL,817593
2025-07-17T08:05:03.360848793Z,2025-07-17T08:05:03.360683462Z,10,2,1108,A,A,0,21.33,100,130,165331,851013,5.510000,100,1,21.330000,100,1,,0,0,,0,0,,0,0,,0,0,,0,0,,0,0,,0,0,,0,0,,0,0,,0,0,,0,0,,0,0,,0,0,,0,0,,0,0,,0,0,,0,0,,0,0,ARL,817597
2025-07-17T08:05:03.361492517Z,2025-07-17T08:05:03.361327319Z,10,2,1108,A,B,0,5.90,100,130,165198,851022,5.900000,100,1,21.330000,100,1,5.510000,100,1,,0,0,,0,0,,0,0,,0,0,,0,0,,0,0,,0,0,,0,0,,0,0,,0,0,,0,0,,0,0,,0,0,,0,0,,0,0,,0,0,,0,0,ARL,817633
2025-07-17T08:05:03.361497823Z,2025-07-17T08:05:03.361332576Z,10,2,1108,A,A,0,20.94,100,130,165247,851023,5.900000,100,1,20.940000,100,1,5.510000,100,1,21.330000,100,1,,0,0,,0,0,,0,0,,0,0,,0,0,,0,0,,0,0,,0,0,,0,0,,0,0,,0,0,,0,0,,0,0,,0,0,,0,0,,0,0,ARL,817637
2025-07-17T08:09:48.860862095Z,2025-07-17T08:09:48.860696464Z,10,2,1108,C,B,1,5.51,100,130,165631,1289631,5.900000,100,1,20.940000,100,1,,0,0,21.330000,100,1,,0,0,,0,0,,0,0,,0,0,,0,0,,0,0,,0,0,,0,0,,0,0,,0,0,,0,0,,0,0,,0,0,,0,0,,0,0,,0,0,ARL,817593
2025-07-17T08:09:48.860870885Z,2025-07-17T08:09:48.860705588Z,10,2,1108,A,B,1,5.37,100,130,165297,1289632,5.900000,100,1,20.940000,100,1,5.370000,100,1,21.330000,100,1,,0,0,,0,0,,0,0,,0,0,,0,0,,0,0,,0,0,,0,0,,0,0,,0,0,,0,0,,0,0,,0,0,,0,0,,0,0,,0,0,ARL,1263973
2025-07-17T08:09:49.158061899Z,2025-07-17T08:09:49.157896784Z,10,2,1108,C,B,0,5.90,100,130,165115,1290626,5.370000,100,1,20.940000,100,1,,0,0,21.330000,100,1,,0,0,,0,0,,0,0,,0,0,,0,0,,0,0,,0,0,,0,0,,0,0,,0,0,,0,0,,0,0,,0,0,,0,0,,0,0,,0,0,ARL,817633
2025-07-17T08:09:49.158069452Z,2025-07-17T08:09:49.157903443Z,10,2,1108,A,B,0,5.40,100,0,166009,1290627,5.400000,100,1,20.940000,100,1,5.370000,100,1,21.330000,100,1,,0,0,,0,0,,0,0,,0,0,,0,0,,0,0,,0,0,,0,0,,0,0,,0,0,,0,0,,0,0,,0,0,,0,0,,0,0,,0,0,ARL,1264721
2025-07-17T08:09:49.158069452Z,2025-07-17T08:09:49.157903798Z,10,2,1108,C,A,0,20.94,100,130,165654,1290628,5.400000,100,1,21.330000,100,1,5.370000,100,1,,0,0,,0,0,,0,0,,0,0,,0,0,,0,0,,0,0,,0,0,,0,0,,0,0,,0,0,,0,0,,0,0,,0,0,,0,0,,0,0,,0,0,ARL,817637
2025-07-17T08:09:49.158074599Z,2025-07-17T08:09:49.157909054Z,10,2,1108,A,A,1,21.47,100,130,165545,1290629,5.400000,100,1,21.330000,100,1,5.370000,100,1,21.470000,100,1,,0,0,,0,0,,0,0,,0,0,,0,0,,0,0,,0,0,,0,0,,0,0,,0,0,,0,0,,0,0,,0,0,,0,0,,0,0,,0,0,ARL,1264725
2025-07-17T11:00:00.125340914Z,2025-07-17T11:00:00.125174985Z,10,2,1108,C,B,1,5.37,100,130,165929,10583317,5.400000,100,1,21.330000,100,1,,0,0,21.470000,100,1,,0,0,,0,0,,0,0,,0,0,,0,0,,0,0,,0,0,,0,0,,0,0,,0,0,,0,0,,0,0,,0,0,,0,0,,0,0,,0,0,ARL,1263973
2025-07-17T11:00:00.125347247Z,2025-07-17T11:00:00.125182048Z,10,2,1108,A,B,0,9.79,100,130,165199,10583320,9.790000,100,1,21.330000,100,1,5.400000,100,1,21.470000,100,1,,0,0,,0,0,,0,0,,0,0,,0,0,,0,0,,0,0,,0,0,,0,0,,0,0,,0,0,,0,0,,0,0,,0,0,,0,0,,0,0,ARL,12852457
2025-07-17T11:00:00.125619742Z,2025-07-17T11:00:00.125454029Z,10,2,1108,C,B,1,5.40,100,130,165713,10583363,9.790000,100,1,21.330000,100,1,,0,0,21.470000,100,1,,0,0,,0,0,,0,0,,0,0,,0,0,,0,0,,0,0,,0,0,,0,0,,0,0,,0,0,,0,0,,0,0,,0,0,,0,0,,0,0,ARL,1264721
2025-07-17T11:00:00.125626050Z,2025-07-17T11:00:00.125460962Z,10,2,1108,A,B,0,9.84,100,130,165088,10583364,9.840000,100,1,21.330000,100,1,9.790000,100,1,21.470000,100,1,,0,0,,0,0,,0,0,,0,0,,0,0,,0,0,,0,0,,0,0,,0,0,,0,0,,0,0,,0,0,,0,0,,0,0,,0,0,,0,0,ARL,12852537
2025-07-17T11:00:07.975990221Z,2025-07-17T11:00:07.975824831Z,10,2,1108,C,A,0,21.33,100,130,165390,10674471,9.840000,100,1,21.470000,100,1,9.790000,100,1,,0,0,,0,0,,0,0,,0,0,,0,0,,0,0,,0,0,,0,0,,0,0,,0,0,,0,0,,0,0,,0,0,,0,0,,0,0,,0,0,,0,0,ARL,817597
2025-07-17T11:00:07.976003383Z,2025-07-17T11:00:07.975837956Z,10,2,1108,A,A,0,17.44,100,130,165427,10674472,9.840000,100,1,17.440000,100,1,9.790000,100,1,21.470000,100,1,,0,0,,0,0,,0,0,,0,0,,0,0,,0,0,,0,0,,0,0,,0,0,,0,0,,0,0,,0,0,,0,0,,0,0,,0,0,,0,0,ARL,12983425
2025-07-17T11:00:07.976138102Z,2025-07-17T11:00:07.975972618Z,10,2,1108,C,A,1,21.47,100,130,165484,10674473,9.840000,100,1,17.440000,100,1,9.790000,100,1,,0,0,,0,0,,0,0,,0,0,,0,0,,0,0,,0,0,,0,0,,0,0,,0,0,,0,0,,0,0,,0,0,,0,0,,0,0,,0,0,,0,0,ARL,1264725
2025-07-17T11:00:07.976144724Z,2025-07-17T11:00:07.975979367Z,10,2,1108,A,A,0,17.36,100,130,165357,10674474,9.840000,100,1,17.360000,100,1,9.790000,100,1,17.440000,100,1,,0,0,,0,0,,0,0,,0,0,,0,0,,0,0,,0,0,,0,0,,0,0,,0,0,,0,0,,0,0,,0,0,,0,0,,0,0,,0,0,ARL,12983429
2025-07-17T11:00:08.255140498Z,2025-07-17T11:00:08.254975294Z,10,2,1108,C,A,1,17.44,100,130,165204,10676310,9.840000,100,1,17.360000,100,1,9.790000,100,1,,0,0,,0,0,,0,0,,0,0,,0,0,,0,0,,0,0,,0,0,,0,0,,0,0,,0,0,,0,0,,0,0,,0,0,,0,0,,0,0,,0,0,ARL,12983425
2025-07-17T11:00:08.255150459Z,2025-07-17T11:00:08.254985173Z,10,2,1108,A,A,1,18.92,100,130,165286,10676311,9.840000,100,1,17.360000,100,1,9.790000,100,1,18.920000,100,1,,0,0,,0,0,,0,0,,0,0,,0,0,,0,0,,0,0,,0,0,,0,0,,0,0,,0,0,,0,0,,0,0,,0,0,,0,0,,0,0,ARL,12985397
2025-07-17T11:00:08.255312226Z,2025-07-17T11:00:08.255147130Z,10,2,1108,C,A,0,17.36,100,130,165096,10676314,9.840000,100,1,18.920000,100,1,9.790000,100,1,,0,0,,0,0,,0,0,,0,0,,0,0,,0,0,,0,0,,0,0,,0,0,,0,0,,0,0,,0,0,,0,0,,0,0,,0,0,,0,0,,0,0,ARL,12983429
2025-07-17T11:00:08.255320414Z,2025-07-17T11:00:08.255155317Z,10,2,1108,A,A,0,18.84,100,130,165097,10676315,9.840000,100,1,18.840000,100,1,9.790000,100,1,18.920000,100,1,,0,0,,0,0,,0,0,,0,0,,0,0,,0,0,,0,0,,0,0,,0,0,,0,0,,0,0,,0,0,,0,0,,0,0,,0,0,,0,0,ARL,12985401
2025-07-17T11:00:08.256027692Z,2025-07-17T11:00:08.255862656Z,10,2,1108,C,A,1,18.92,100,130,165036,10676320,9.840000,100,1,18.840000,100,1,9.790000,100,1,,0,0,,0,0,,0,0,,0,0,,0,0,,0,0,,0,0,,0,0,,0,0,,0,0,,0,0,,0,0,,0,0,,0,0,,0,0,,0,0,,0,0,ARL,12985397
2025-07-17T11:00:08.256037075Z,2025-07-17T11:00:08.255871843Z,10,2,1108,A,A,1,20.62,100,130,165232,10676321,9.840000,100,1,18.840000,100,1,9.790000,100,1,20.620000,100,1,,0,0,,0,0,,0,0,,0,0,,0,0,,0,0,,0,0,,0,0,,0,0,,0,0,,0,0,,0,0,,0,0,,0,0,,0,0,,0,0,ARL,12985405
2025-07-17T11:00:08.256333906Z,2025-07-17T11:00:08.256168895Z,10,2,1108,C,A,0,18.84,100,130,165011,10676324,9.840000,100,1,20.620000,100,1,9.790000,100,1,,0,0,,0,0,,0,0,,0,0,,0,0,,0,0,,0,0,,0,0,,0,0,,0,0,,0,0,,0,0,,0,0,,0,0,,0,0,,0,0,,0,0,ARL,12985401
2025-07-17T11:00:08.256340615Z,2025-07-17T11:00:08.256175346Z,10,2,1108,A,A,0,20.53,100,130,165269,10676325,9.840000,100,1,20.530000,100,1,9.790000,100,1,20.620000,100,1,,0,0,,0,0,,0,0,,0,0,,0,0,,0,0,,0,0,,0,0,,0,0,,0,0,,0,0,,0,0,,0,0,,0,0,,0,0,,0,0,ARL,12985413
2025-07-17T11:00:08.257050282Z,2025-07-17T11:00:08.256885010Z,10,2,1108,C,A,1,20.62,100,130,165272,10676333,9.840000,100,1,20.530000,100,1,9.790000,100,1,,0,0,,0,0,,0,0,,0,0,,0,0,,0,0,,0,0,,0,0,,0,0,,0,0,,0,0,,0,0,,0,0,,0,0,,0,0,,0,0,,0,0,ARL,12985405
2025-07-17T11:00:08.257058070Z,2025-07-17T11:00:08.256892686Z,10,2,1108,A,A,1,21.47,100,130,165384,10676334,9.840000,100,1,20.530000,100,1,9.790000,100,1,21.470000,100,1,,0,0,,0,0,,0,0,,0,0,,0,0,,0,0,,0,0,,0,0,,0,0,,0,0,,0,0,,0,0,,0,0,,0,0,,0,0,,0,0,ARL,12985417
2025-07-17T11:00:08.257234812Z,2025-07-17T11:00:08.257069458Z,10,2,1108,C,A,0,20.53,100,130,165354,10676335,9.840000,100,1,21.470000,100,1,9.790000,100,1,,0,0,,0,0,,0,0,,0,0,,0,0,,0,0,,0,0,,0,0,,0,0,,0,0,,0,0,,0,0,,0,0,,0,0,,0,0,,0,0,,0,0,ARL,12985413
2025-07-17T11:00:08.257241334Z,2025-07-17T11:00:08.257076085Z,10,2,1108,A,A,0,21.47,100,130,165249,10676336,9.840000,100,1,21.470000,200,2,9.790000,100,1,,0,0,,0,0,,0,0,,0,0,,0,0,,0,0,,0,0,,0,0,,0,0,,0,0,,0,0,,0,0,,0,0,,0,0,,0,0,,0,0,,0,0,ARL,12985421
2025-07-17T11:01:05.260586668Z,2025-07-17T11:01:05.260421351Z,10,2,1108,C,A,0,21.47,100,130,165317,10824633,9.840000,100,1,21.470000,100,1,9.790000,100,1,,0,0,,0,0,,0,0,,0,0,,0,0,,0,0,,0,0,,0,0,,0,0,,0,0,,0,0,,0,0,,0,0,,0,0,,0,0,,0,0,,0,0,ARL,12985417
2025-07-17T11:01:05.260611137Z,2025-07-17T11:01:05.260445703Z,10,2,1108,A,A,0,17.44,100,130,165434,10824634,9.840000,100,1,17.440000,100,1,9.790000,100,1,21.470000,100,1,,0,0,,0,0,,0,0,,0,0,,0,0,,0,0,,0,0,,0,0,,0,0,,0,0,,0,0,,0,0,,0,0,,0,0,,0,0,,0,0,ARL,13174157
2025-07-17T11:01:05.260858436Z,2025-07-17T11:01:05.260693130Z,10,2,1108,C,A,1,21.47,100,130,165306,10824635,9.840000,100,1,17.440000,100,1,9.790000,100,1,,0,0,,0,0,,0,0,,0,0,,0,0,,0,0,,0,0,,0,0,,0,0,,0,0,,0,0,,0,0,,0,0,,0,0,,0,0,,0,0,,0,0,ARL,12985421
2025-07-17T11:01:05.260874630Z,2025-07-17T11:01:05.260709480Z,10,2,1108,A,A,0,17.36,100,130,165150,10824636,9.840000,100,1,17.360000,100,1,9.790000,100,1,17.440000,100,1,,0,0,,0,0,,0,0,,0,0,,0,0,,0,0,,0,0,,0,0,,0,0,,0,0,,0,0,,0,0,,0,0,,0,0,,0,0,,0,0,ARL,13174161
2025-07-17T11:56:26.691626843Z,2025-07-17T11:56:26.691461161Z,10,2,1108,C,B,1,9.79,100,130,165682,14213017,9.840000,100,1,17.360000,100,1,,0,0,17.440000,100,1,,0,0,,0,0,,0,0,,0,0,,0,0,,0,0,,0,0,,0,0,,0,0,,0,0,,0,0,,0,0,,0,0,,0,0,,0,0,,0,0,ARL,12852457
2025-07-17T11:56:26.691630539Z,2025-07-17T11:56:26.691465204Z,10,2,1108,C,A,1,17.44,100,130,165335,14213018,9.840000,100,1,17.360000,100,1,,0,0,,0,0,,0,0,,0,0,,0,0,,0,0,,0,0,,0,0,,0,0,,0,0,,0,0,,0,0,,0,0,,0,0,,0,0,,0,0,,0,0,,0,0,ARL,13174157
2025-07-17T11:56:26.694933250Z,2025-07-17T11:56:26.694767820Z,10,2,1108,A,B,1,9.79,100,130,165430,14213075,9.840000,100,1,17.360000,100,1,9.790000,100,1,,0,0,,0,0,,0,0,,0,0,,0,0,,0,0,,0,0,,0,0,,0,0,,0,0,,0,0,,0,0,,0,0,,0,0,,0,0,,0,0,,0,0,ARL,19202569
2025-07-17T11:56:26.694937361Z,2025-07-17T11:56:26.694772016Z,10,2,1108,A,A,1,17.44,100,130,165345,14213076,9.840000,100,1,17.360000,100,1,9.790000,100,1,17.440000,100,1,,0,0,,0,0,,0,0,,0,0,,0,0,,0,0,,0,0,,0,0,,0,0,,0,0,,0,0,,0,0,,0,0,,0,0,,0,0,,0,0,ARL,19202573
2025-07-17T11:56:30.446102409Z,2025-07-17T11:56:30.445937099Z,10,2,1108,C,A,1,17.44,100,130,165310,14219824,9.840000,100,1,17.360000,100,1,9.790000,100,1,,0,0,,0,0,,0,0,,0,0,,0,0,,0,0,,0,0,,0,0,,0,0,,0,0,,0,0,,0,0,,0,0,,0,0,,0,0,,0,0,,0,0,ARL,19202573
2025-07-17T11:56:30.446117449Z,2025-07-17T11:56:30.445951937Z,10,2,1108,A,A,1,17.93,100,130,165512,14219825,9.840000,100,1,17.360000,100,1,9.790000,100,1,17.930000,100,1,,0,0,,0,0,,0,0,,0,0,,0,0,,0,0,,0,0,,0,0,,0,0,,0,0,,0,0,,0,0,,0,0,,0,0,,0,0,,0,0,ARL,19218909
2025-07-17T11:56:30.446231965Z,2025-07-17T11:56:30.446066952Z,10,2,1108,C,A,1,17.93,100,130,165013,14219826,9.840000,100,1,17.360000,100,1,9.790000,100,1,,0,0,,0,0,,0,0,,0,0,,0,0,,0,0,,0,0,,0,0,,0,0,,0,0,,0,0,,0,0,,0,0,,0,0,,0,0,,0,0,,0,0,ARL,19218909
2025-07-17T11:56:30.446250148Z,2025-07-17T11:56:30.446084801Z,10,2,1108,A,A,1,17.44,100,130,165347,14219827,9.840000,100,1,17.360000,100,1,9.790000,100,1,17.440000,100,1,,0,0,,0,0,,0,0,,0,0,,0,0,,0,0,,0,0,,0,0,,0,0,,0,0,,0,0,,0,0,,0,0,,0,0,,0,0,,0,0,ARL,19218913
2025-07-17T11:56:30.446357192Z,2025-07-17T11:56:30.446191769Z,10,2,1108,C,A,0,17.36,100,130,165423,14219828,9.840000,100,1,17.440000,100,1,9.790000,100,1,,0,0,,0,0,,0,0,,0,0,,0,0,,0,0,,0,0,,0,0,,0,0,,0,0,,0,0,,0,0,,0,0,,0,0,,0,0,,0,0,,0,0,ARL,13174161
2025-07-17T11:56:30.446379036Z,2025-07-17T11:56:30.446213519Z,10,2,1108,A,A,1,17.85,100,130,165517,14219829,9.840000,100,1,17.440000,100,1,9.790000,100,1,17.850000,100,1,,0,0,,0,0,,0,0,,0,0,,0,0,,0,0,,0,0,,0,0,,0,0,,0,0,,0,0,,0,0,,0,0,,0,0,,0,0,,0,0,ARL,19218917
2025-07-17T11:56:30.446543637Z,2025-07-17T11:56:30.446378732Z,10,2,1108,C,A,1,17.85,100,130,164905,14219830,9.840000,100,1,17.440000,100,1,9.790000,100,1,,0,0,,0,0,,0,0,,0,0,,0,0,,0,0,,0,0,,0,0,,0,0,,0,0,,0,0,,0,0,,0,0,,0,0,,0,0,,0,0,,0,0,ARL,19218917
2025-07-17T11:56:30.446723646Z,2025-07-17T11:56:30.446558412Z,10,2,1108,A,A,0,17.36,100,130,165234,14219831,9.840000,100,1,17.360000,100,1,9.790000,100,1,17.440000,100,1,,0,0,,0,0,,0,0,,0,0,,0,0,,0,0,,0,0,,0,0,,0,0,,0,0,,0,0,,0,0,,0,0,,0,0,,0,0,,0,0,ARL,19218921
2025-07-17T11:57:30.222987797Z,2025-07-17T11:57:30.222822537Z,10,2,1108,C,B,0,9.84,100,130,165260,14325877,9.790000,100,1,17.360000,100,1,,0,0,17.440000,100,1,,0,0,,0,0,,0,0,,0,0,,0,0,,0,0,,0,0,,0,0,,0,0,,0,0,,0,0,,0,0,,0,0,,0,0,,0,0,,0,0,ARL,12852537
2025-07-17T11:57:30.222988778Z,2025-07-17T11:57:30.222823580Z,10,2,1108,C,A,0,17.36,100,130,165198,14325878,9.790000,100,1,17.440000,100,1,,0,0,,0,0,,0,0,,0,0,,0,0,,0,0,,0,0,,0,0,,0,0,,0,0,,0,0,,0,0,,0,0,,0,0,,0,0,,0,0,,0,0,,0,0,ARL,19218921
2025-07-17T11:57:30.224151967Z,2025-07-17T11:57:30.223986626Z,10,2,1108,A,B,0,9.84,100,130,165341,14325937,9.840000,100,1,17.440000,100,1,9.790000,100,1,,0,0,,0,0,,0,0,,0,0,,0,0,,0,0,,0,0,,0,0,,0,0,,0,0,,0,0,,0,0,,0,0,,0,0,,0,0,,0,0,,0,0,ARL,19346173
2025-07-17T11:57:30.224156146Z,2025-07-17T11:57:30.223991040Z,10,2,1108,A,A,0,17.36,100,130,165106,14325938,9.840000,100,1,17.360000,100,1,9.790000,100,1,17.440000,100,1,,0,0,,0,0,,0,0,,0,0,,0,0,,0,0,,0,0,,0,0,,0,0,,0,0,,0,0,,0,0,,0,0,,0,0,,0,0,,0,0,ARL,19346177
2025-07-17T12:30:01.318008785Z,2025-07-17T12:30:01.317842911Z,10,2,1108,A,A,2,20.48,100,130,165874,16864046,9.840000,100,1,17.360000,100,1,9.790000,100,1,17.440000,100,1,,0,0,20.480000,100,1,,0,0,,0,0,,0,0,,0,0,,0,0,,0,0,,0,0,,0,0,,0,0,,0,0,,0,0,,0,0,,0,0,,0,0,ARL,23570297
2025-07-17T12:30:03.426465857Z,2025-07-17T12:30:03.426300621Z,10,2,1108,A,B,2,7.74,100,130,165236,16882670,9.840000,100,1,17.360000,100,1,9.790000,100,1,17.440000,100,1,7.740000,100,1,20.480000,100,1,,0,0,,0,0,,0,0,,0,0,,0,0,,0,0,,0,0,,0,0,,0,0,,0,0,,0,0,,0,0,,0,0,,0,0,ARL,23616197
2025-07-17T12:30:03.426466862Z,2025-07-17T12:30:03.426301523Z,10,2,1108,A,A,2,20.48,100,130,165339,16882671,9.840000,100,1,17.360000,100,1,9.790000,100,1,17.440000,100,1,7.740000,100,1,20.480000,200,2,,0,0,,0,0,,0,0,,0,0,,0,0,,0,0,,0,0,,0,0,,0,0,,0,0,,0,0,,0,0,,0,0,,0,0,ARL,23616201
2025-07-17T12:30:03.604699168Z,2025-07-17T12:30:03.604533925Z,10,2,1108,A,B,2,7.74,100,130,165243,16886020,9.840000,100,1,17.360000,100,1,9.790000,100,1,17.440000,100,1,7.740000,200,2,20.480000,200,2,,0,0,,0,0,,0,0,,0,0,,0,0,,0,0,,0,0,,0,0,,0,0,,0,0,,0,0,,0,0,,0,0,,0,0,ARL,23622101
2025-07-17T12:30:51.178394233Z,2025-07-17T12:30:51.178228608Z,10,2,1108,A,A,2,20.48,100,130,165625,17120703,9.840000,100,1,17.360000,100,1,9.790000,100,1,17.440000,100,1,7.740000,200,2,20.480000,300,3,,0,0,,0,0,,0,0,,0,0,,0,0,,0,0,,0,0,,0,0,,0,0,,0,0,,0,0,,0,0,,0,0,,0,0,ARL,24099409
2025-07-17T12:30:51.643125167Z,2025-07-17T12:30:51.642959794Z,10,2,1108,A,B,2,7.74,100,130,165373,17122998,9.840000,100,1,17.360000,100,1,9.790000,100,1,17.440000,100,1,7.740000,300,3,20.480000,300,3,,0,0,,0,0,,0,0,,0,0,,0,0,,0,0,,0,0,,0,0,,0,0,,0,0,,0,0,,0,0,,0,0,,0,0,ARL,24102329
2025-07-17T13:15:00.032611736Z,2025-07-17T13:15:00.032446132Z,10,2,1108,C,A,1,17.44,100,130,165604,23080007,9.840000,100,1,17.360000,100,1,9.790000,100,1,20.480000,300,3,7.740000,300,3,,0,0,,0,0,,0,0,,0,0,,0,0,,0,0,,0,0,,0,0,,0,0,,0,0,,0,0,,0,0,,0,0,,0,0,,0,0,ARL,19218913
2025-07-17T13:15:00.032651211Z,2025-07-17T13:15:00.032483824Z,10,2,1108,C,B,1,9.79,100,128,167387,23080041,9.840000,100,1,17.360000,100,1,7.740000,300,3,20.480000,300,3,,0,0,,0,0,,0,0,,0,0,,0,0,,0,0,,0,0,,0,0,,0,0,,0,0,,0,0,,0,0,,0,0,,0,0,,0,0,,0,0,ARL,19202569
2025-07-17T13:15:00.058480238Z,2025-07-17T13:15:00.058314138Z,10,2,1108,C,A,0,17.36,100,128,166100,23101369,9.840000,100,1,20.480000,300,3,7.740000,300,3,,0,0,,0,0,,0,0,,0,0,,0,0,,0,0,,0,0,,0,0,,0,0,,0,0,,0,0,,0,0,,0,0,,0,0,,0,0,,0,0,,0,0,ARL,19346177
2025-07-17T13:15:00.058537384Z,2025-07-17T13:15:00.058371545Z,10,2,1108,C,B,0,9.84,100,130,165839,23101396,7.740000,300,3,20.480000,300,3,,0,0,,0,0,,0,0,,0,0,,0,0,,0,0,,0,0,,0,0,,0,0,,0,0,,0,0,,0,0,,0,0,,0,0,,0,0,,0,0,,0,0,,0,0,ARL,19346173
2025-07-17T13:15:01.925239044Z,2025-07-17T13:15:01.925073727Z,10,2,1108,A,B,0,7.74,100,130,165317,23123943,7.740000,400,4,20.480000,300,3,,0,0,,0,0,,0,0,,0,0,,0,0,,0,0,,0,0,,0,0,,0,0,,0,0,,0,0,,0,0,,0,0,,0,0,,0,0,,0,0,,0,0,,0,0,ARL,31960841
2025-07-17T13:15:02.042906947Z,2025-07-17T13:15:02.042741730Z,10,2,1108,A,A,0,20.48,100,130,165217,23124563,7.740000,400,4,20.480000,400,4,,0,0,,0,0,,0,0,,0,0,,0,0,,0,0,,0,0,,0,0,,0,0,,0,0,,0,0,,0,0,,0,0,,0,0,,0,0,,0,0,,0,0,,0,0,ARL,31962113
2025-07-17T13:17:49.831329888Z,2025-07-17T13:17:49.831164624Z,10,2,1108,A,B,0,7.74,100,130,165264,23465434,7.740000,500,5,20.480000,400,4,,0,0,,0,0,,0,0,,0,0,,0,0,,0,0,,0,0,,0,0,,0,0,,0,0,,0,0,,0,0,,0,0,,0,0,,0,0,,0,0,,0,0,,0,0,ARL,33574717
2025-07-17T13:17:49.831709365Z,2025-07-17T13:17:49.831544051Z,10,2,1108,A,A,0,20.48,100,130,165314,23465435,7.740000,500,5,20.480000,500,5,,0,0,,0,0,,0,0,,0,0,,0,0,,0,0,,0,0,,0,0,,0,0,,0,0,,0,0,,0,0,,0,0,,0,0,,0,0,,0,0,,0,0,,0,0,ARL,33574725
2025-07-17T13:19:57.597368321Z,2025-07-17T13:19:57.597203040Z,10,2,1108,A,B,0,8.74,100,130,165281,23710201,8.740000,100,1,20.480000,500,5,7.740000,500,5,,0,0,,0,0,,0,0,,0,0,,0,0,,0,0,,0,0,,0,0,,0,0,,0,0,,0,0,,0,0,,0,0,,0,0,,0,0,,0,0,,0,0,ARL,34790041
2025-07-17T13:19:57.597456270Z,2025-07-17T13:19:57.597291053Z,10,2,1108,A,A,0,18.35,100,130,165217,23710202,8.740000,100,1,18.350000,100,1,7.740000,500,5,20.480000,500,5,,0,0,,0,0,,0,0,,0,0,,0,0,,0,0,,0,0,,0,0,,0,0,,0,0,,0,0,,0,0,,0,0,,0,0,,0,0,,0,0,ARL,34790045
2025-07-17T13:19:58.492785060Z,2025-07-17T13:19:58.492619751Z,10,2,1108,A,A,0,18.24,100,130,165309,23728432,8.740000,100,1,18.240000,100,1,7.740000,500,5,18.350000,100,1,,0,0,20.480000,500,5,,0,0,,0,0,,0,0,,0,0,,0,0,,0,0,,0,0,,0,0,,0,0,,0,0,,0,0,,0,0,,0,0,,0,0,ARL,34810233
2025-07-17T13:19:58.492799826Z,2025-07-17T13:19:58.492634480Z,10,2,1108,A,B,0,9.24,100,130,165346,23728435,9.240000,100,1,18.240000,100,1,8.740000,100,1,18.350000,100,1,7.740000,500,5,20.480000,500,5,,0,0,,0,0,,0,0,,0,0,,0,0,,0,0,,0,0,,0,0,,0,0,,0,0,,0,0,,0,0,,0,0,,0,0,ARL,34810241
2025-07-17T13:20:00.525430361Z,2025-07-17T13:20:00.525263842Z,10,2,1108,C,A,0,18.24,100,0,166519,23765825,9.240000,100,1,18.350000,100,1,8.740000,100,1,20.480000,500,5,7.740000,500,5,,0,0,,0,0,,0,0,,0,0,,0,0,,0,0,,0,0,,0,0,,0,0,,0,0,,0,0,,0,0,,0,0,,0,0,,0,0,ARL,34810233
2025-07-17T13:20:00.525430361Z,2025-07-17T13:20:00.525264700Z,10,2,1108,C,B,0,9.24,100,130,165661,23765826,8.740000,100,1,18.350000,100,1,7.740000,500,5,20.480000,500,5,,0,0,,0,0,,0,0,,0,0,,0,0,,0,0,,0,0,,0,0,,0,0,,0,0,,0,0,,0,0,,0,0,,0,0,,0,0,,0,0,ARL,34810241
2025-07-17T13:25:00.157632223Z,2025-07-17T13:25:00.157467184Z,10,2,1108,C,B,0,8.74,100,130,165039,24448205,7.740000,500,5,18.350000,100,1,,0,0,20.480000,500,5,,0,0,,0,0,,0,0,,0,0,,0,0,,0,0,,0,0,,0,0,,0,0,,0,0,,0,0,,0,0,,0,0,,0,0,,0,0,,0,0,ARL,34790041
2025-07-17T13:25:00.157638512Z,2025-07-17T13:25:00.157473422Z,10,2,1108,C,A,0,18.35,100,130,165090,24448207,7.740000,500,5,20.480000,500,5,,0,0,,0,0,,0,0,,0,0,,0,0,,0,0,,0,0,,0,0,,0,0,,0,0,,0,0,,0,0,,0,0,,0,0,,0,0,,0,0,,0,0,,0,0,ARL,34790045
2025-07-17T13:25:01.732485386Z,2025-07-17T13:25:01.732320109Z,10,2,1108,A,B,0,7.74,100,130,165277,24478872,7.740000,600,6,20.480000,500,5,,0,0,,0,0,,0,0,,0,0,,0,0,,0,0,,0,0,,0,0,,0,0,,0,0,,0,0,,0,0,,0,0,,0,0,,0,0,,0,0,,0,0,,0,0,ARL,38041417
2025-07-17T13:25:01.819447960Z,2025-07-17T13:25:01.819282823Z,10,2,1108,A,A,0,20.48,100,130,165137,24480276,7.740000,600,6,20.480000,600,6,,0,0,,0,0,,0,0,,0,0,,0,0,,0,0,,0,0,,0,0,,0,0,,0,0,,0,0,,0,0,,0,0,,0,0,,0,0,,0,0,,0,0,,0,0,ARL,38043741
2025-07-17T13:28:08.192080463Z,2025-07-17T13:28:08.191915168Z,10,2,1108,A,B,0,7.74,100,130,165295,25597187,7.740000,700,7,20.480000,600,6,,0,0,,0,0,,0,0,,0,0,,0,0,,0,0,,0,0,,0,0,,0,0,,0,0,,0,0,,0,0,,0,0,,0,0,,0,0,,0,0,,0,0,,0,0,ARL,40617777
2025-07-17T13:28:08.192147601Z,2025-07-17T13:28:08.191982270Z,10,2,1108,A,A,0,20.48,100,130,165331,25597189,7.740000,700,7,20.480000,700,7,,0,0,,0,0,,0,0,,0,0,,0,0,,0,0,,0,0,,0,0,,0,0,,0,0,,0,0,,0,0,,0,0,,0,0,,0,0,,0,0,,0,0,,0,0,ARL,40617785
2025-07-17T13:28:21.011414592Z,2025-07-17T13:28:21.011249114Z,10,2,1108,A,A,0,18.32,700,130,165478,25907820,7.740000,700,7,18.320000,700,1,,0,0,20.480000,700,7,,0,0,,0,0,,0,0,,0,0,,0,0,,0,0,,0,0,,0,0,,0,0,,0,0,,0,0,,0,0,,0,0,,0,0,,0,0,,0,0,ARL,40846101
2025-07-17T13:28:21.029030365Z,2025-07-17T13:28:21.028865155Z,10,2,1108,A,B,0,9.29,700,130,165210,25917006,9.290000,700,1,18.320000,700,1,7.740000,700,7,20.480000,700,7,,0,0,,0,0,,0,0,,0,0,,0,0,,0,0,,0,0,,0,0,,0,0,,0,0,,0,0,,0,0,,0,0,,0,0,,0,0,,0,0,ARL,40851989
2025-07-17T13:28:30.048895468Z,2025-07-17T13:28:30.048730211Z,10,2,1108,A,B,0,9.67,100,130,165257,26140646,9.670000,100,1,18.320000,700,1,9.290000,700,1,20.480000,700,7,7.740000,700,7,,0,0,,0,0,,0,0,,0,0,,0,0,,0,0,,0,0,,0,0,,0,0,,0,0,,0,0,,0,0,,0,0,,0,0,,0,0,ARL,40999441
2025-07-17T13:28:30.048907452Z,2025-07-17T13:28:30.048741690Z,10,2,1108,A,A,0,17.60,100,130,165762,26140658,9.670000,100,1,17.600000,100,1,9.290000,700,1,18.320000,700,1,7.740000,700,7,20.480000,700,7,,0,0,,0,0,,0,0,,0,0,,0,0,,0,0,,0,0,,0,0,,0,0,,0,0,,0,0,,0,0,,0,0,,0,0,ARL,40999449
2025-07-17T13:28:30.052061798Z,2025-07-17T13:28:30.051894007Z,10,2,1108,A,B,0,9.99,100,130,167791,26142104,9.990000,100,1,17.600000,100,1,9.670000,100,1,18.320000,700,1,9.290000,700,1,20.480000,700,7,7.740000,700,7,,0,0,,0,0,,0,0,,0,0,,0,0,,0,0,,0,0,,0,0,,0,0,,0,0,,0,0,,0,0,,0,0,ARL,41000165
2025-07-17T13:28:30.052072568Z,2025-07-17T13:28:30.051907073Z,10,2,1108,A,A,0,17.12,100,130,165495,26142118,9.990000,100,1,17.120000,100,1,9.670000,100,1,17.600000,100,1,9.290000,700,1,18.320000,700,1,7.740000,700,7,20.480000,700,7,,0,0,,0,0,,0,0,,0,0,,0,0,,0,0,,0,0,,0,0,,0,0,,0,0,,0,0,,0,0,ARL,41000173
2025-07-17T13:28:30.257018844Z,2025-07-17T13:28:30.256853564Z,10,2,1108,A,B,1,9.67,100,130,165280,26170917,9.990000,100,1,17.120000,100,1,9.670000,200,2,17.600000,100,1,9.290000,700,1,18.320000,700,1,7.740000,700,7,20.480000,700,7,,0,0,,0,0,,0,0,,0,0,,0,0,,0,0,,0,0,,0,0,,0,0,,0,0,,0,0,,0,0,ARL,41021369
2025-07-17T13:28:30.257031156Z,2025-07-17T13:28:30.256865858Z,10,2,1108,A,A,1,17.60,100,130,165298,26170918,9.990000,100,1,17.120000,100,1,9.670000,200,2,17.600000,200,2,9.290000,700,1,18.320000,700,1,7.740000,700,7,20.480000,700,7,,0,0,,0,0,,0,0,,0,0,,0,0,,0,0,,0,0,,0,0,,0,0,,0,0,,0,0,,0,0,ARL,41021373
2025-07-17T13:28:30.277622346Z,2025-07-17T13:28:30.277457031Z,10,2,1108,A,B,0,9.99,100,130,165315,26171531,9.990000,200,2,17.120000,100,1,9.670000,200,2,17.600000,200,2,9.290000,700,1,18.320000,700,1,7.740000,700,7,20.480000,700,7,,0,0,,0,0,,0,0,,0,0,,0,0,,0,0,,0,0,,0,0,,0,0,,0,0,,0,0,,0,0,ARL,41021837
2025-07-17T13:28:30.277635645Z,2025-07-17T13:28:30.277470320Z,10,2,1108,A,A,0,17.12,100,130,165325,26171533,9.990000,200,2,17.120000,200,2,9.670000,200,2,17.600000,200,2,9.290000,700,1,18.320000,700,1,7.740000,700,7,20.480000,700,7,,0,0,,0,0,,0,0,,0,0,,0,0,,0,0,,0,0,,0,0,,0,0,,0,0,,0,0,,0,0,ARL,41021841
2025-07-17T13:28:30.613482667Z,2025-07-17T13:28:30.613317490Z,10,2,1108,A,B,3,9.13,100,130,165177,26182390,9.990000,200,2,17.120000,200,2,9.670000,200,2,17.600000,200,2,9.290000,700,1,18.320000,700,1,9.130000,100,1,20.480000,700,7,7.740000,700,7,,0,0,,0,0,,0,0,,0,0,,0,0,,0,0,,0,0,,0,0,,0,0,,0,0,,0,0,ARL,41032049
2025-07-17T13:28:30.613495057Z,2025-07-17T13:28:30.613329849Z,10,2,1108,A,A,3,18.40,100,130,165208,26182393,9.990000,200,2,17.120000,200,2,9.670000,200,2,17.600000,200,2,9.290000,700,1,18.320000,700,1,9.130000,100,1,18.400000,100,1,7.740000,700,7,20.480000,700,7,,0,0,,0,0,,0,0,,0,0,,0,0,,0,0,,0,0,,0,0,,0,0,,0,0,ARL,41032057
2025-07-17T13:28:41.476876547Z,2025-07-17T13:28:41.476711173Z,10,2,1108,A,B,4,7.84,100,130,165374,26518296,9.990000,200,2,17.120000,200,2,9.670000,200,2,17.600000,200,2,9.290000,700,1,18.320000,700,1,9.130000,100,1,18.400000,100,1,7.840000,100,1,20.480000,700,7,7.740000,700,7,,0,0,,0,0,,0,0,,0,0,,0,0,,0,0,,0,0,,0,0,,0,0,ARL,41306441
2025-07-17T13:28:41.476887975Z,2025-07-17T13:28:41.476722715Z,10,2,1108,A,A,4,20.32,100,130,165260,26518297,9.990000,200,2,17.120000,200,2,9.670000,200,2,17.600000,200,2,9.290000,700,1,18.320000,700,1,9.130000,100,1,18.400000,100,1,7.840000,100,1,20.320000,100,1,7.740000,700,7,20.480000,700,7,,0,0,,0,0,,0,0,,0,0,,0,0,,0,0,,0,0,,0,0,ARL,41306445
2025-07-17T13:28:46.014904874Z,2025-07-17T13:28:46.014739305Z,10,2,1108,A,A,0,15.30,100,130,165569,26613800,9.990000,200,2,15.300000,100,1,9.670000,200,2,17.120000,200,2,9.290000,700,1,17.600000,200,2,9.130000,100,1,18.320000,700,1,7.840000,100,1,18.400000,100,1,7.740000,700,7,20.320000,100,1,,0,0,20.480000,700,7,,0,0,,0,0,,0,0,,0,0,,0,0,,0,0,ARL,41370837
2025-07-17T13:28:46.014968000Z,2025-07-17T13:28:46.014802018Z,10,2,1108,C,A,6,20.48,100,0,165982,26613836,9.990000,200,2,15.300000,100,1,9.670000,200,2,17.120000,200,2,9.290000,700,1,17.600000,200,2,9.130000,100,1,18.320000,700,1,7.840000,100,1,18.400000,100,1,7.740000,700,7,20.320000,100,1,,0,0,20.480000,600,6,,0,0,,0,0,,0,0,,0,0,,0,0,,0,0,ARL,23570297
2025-07-17T13:28:46.014968000Z,2025-07-17T13:28:46.014802018Z,10,2,1108,A,A,5,19.58,100,130,165982,26613836,9.990000,200,2,15.300000,100,1,9.670000,200,2,17.120000,200,2,9.290000,700,1,17.600000,200,2,9.130000,100,1,18.320000,700,1,7.840000,100,1,18.400000,100,1,7.740000,700,7,19.580000,100,1,,0,0,20.320000,100,1,,0,0,20.480000,600,6,,0,0,,0,0,,0,0,,0,0,ARL,41370945
2025-07-17T13:28:46.014969135Z,2025-07-17T13:28:46.014803011Z,10,2,1108,C,A,7,20.48,100,0,166124,26613837,9.990000,200,2,15.300000,100,1,9.670000,200,2,17.120000,200,2,9.290000,700,1,17.600000,200,2,9.130000,100,1,18.320000,700,1,7.840000,100,1,18.400000,100,1,7.740000,700,7,19.580000,100,1,,0,0,20.320000,100,1,,0,0,20.480000,500,5,,0,0,,0,0,,0,0,,0,0,ARL,23616201
2025-07-17T13:28:46.014969135Z,2025-07-17T13:28:46.014803011Z,10,2,1108,A,A,5,19.58,100,130,166124,26613837,9.990000,200,2,15.300000,100,1,9.670000,200,2,17.120000,200,2,9.290000,700,1,17.600000,200,2,9.130000,100,1,18.320000,700,1,7.840000,100,1,18.400000,100,1,7.740000,700,7,19.580000,200,2,,0,0,20.320000,100,1,,0,0,20.480000,500,5,,0,0,,0,0,,0,0,,0,0,ARL,41370949
2025-07-17T13:28:46.014970699Z,2025-07-17T13:28:46.014804158Z,10,2,1108,C,A,7,20.48,100,0,166541,26613838,9.990000,200,2,15.300000,100,1,9.670000,200,2,17.120000,200,2,9.290000,700,1,17.600000,200,2,9.130000,100,1,18.320000,700,1,7.840000,100,1,18.400000,100,1,7.740000,700,7,19.580000,200,2,,0,0,20.320000,100,1,,0,0,20.480000,400,4,,0,0,,0,0,,0,0,,0,0,ARL,24099409
2025-07-17T13:28:46.014970699Z,2025-07-17T13:28:46.014804158Z,10,2,1108,A,A,5,19.58,100,0,166541,26613838,9.990000,200,2,15.300000,100,1,9.670000,200,2,17.120000,200,2,9.290000,700,1,17.600000,200,2,9.130000,100,1,18.320000,700,1,7.840000,100,1,18.400000,100,1,7.740000,700,7,19.580000,300,3,,0,0,20.320000,100,1,,0,0,20.480000,400,4,,0,0,,0,0,,0,0,,0,0,ARL,41370953
2025-07-17T13:28:46.014970699Z,2025-07-17T13:28:46.014804564Z,10,2,1108,C,A,7,20.48,100,0,166135,26613839,9.990000,200,2,15.300000,100,1,9.670000,200,2,17.120000,200,2,9.290000,700,1,17.600000,200,2,9.130000,100,1,18.320000,700,1,7.840000,100,1,18.400000,100,1,7.740000,700,7,19.580000,300,3,,0,0,20.320000,100,1,,0,0,20.480000,300,3,,0,0,,0,0,,0,0,,0,0,ARL,31962113
2025-07-17T13:28:46.014970699Z,2025-07-17T13:28:46.014804564Z,10,2,1108,A,A,5,19.58,100,130,166135,26613839,9.990000,200,2,15.300000,100,1,9.670000,200,2,17.120000,200,2,9.290000,700,1,17.600000,200,2,9.130000,100,1,18.320000,700,1,7.840000,100,1,18.400000,100,1,7.740000,700,7,19.580000,400,4,,0,0,20.320000,100,1,,0,0,20.480000,300,3,,0,0,,0,0,,0,0,,0,0,ARL,41370957
2025-07-17T13:28:46.014972151Z,2025-07-17T13:28:46.014805680Z,10,2,1108,C,A,7,20.48,100,0,166471,26613840,9.990000,200,2,15.300000,100,1,9.670000,200,2,17.120000,200,2,9.290000,700,1,17.600000,200,2,9.130000,100,1,18.320000,700,1,7.840000,100,1,18.400000,100,1,7.740000,700,7,19.580000,400,4,,0,0,20.320000,100,1,,0,0,20.480000,200,2,,0,0,,0,0,,0,0,,0,0,ARL,33574725
2025-07-17T13:28:46.014972151Z,2025-07-17T13:28:46.014805680Z,10,2,1108,A,A,5,19.58,100,0,166471,26613840,9.990000,200,2,15.300000,100,1,9.670000,200,2,17.120000,200,2,9.290000,700,1,17.600000,200,2,9.130000,100,1,18.320000,700,1,7.840000,100,1,18.400000,100,1,7.740000,700,7,19.580000,500,5,,0,0,20.320000,100,1,,0,0,20.480000,200,2,,0,0,,0,0,,0,0,,0,0,ARL,41370961
2025-07-17T13:28:46.014972151Z,2025-07-17T13:28:46.014805841Z,10,2,1108,C,A,7,20.48,100,0,166310,26613841,9.990000,200,2,15.300000,100,1,9.670000,200,2,17.120000,200,2,9.290000,700,1,17.600000,200,2,9.130000,100,1,18.320000,700,1,7.840000,100,1,18.400000,100,1,7.740000,700,7,19.580000,500,5,,0,0,20.320000,100,1,,0,0,20.480000,100,1,,0,0,,0,0,,0,0,,0,0,ARL,38043741
2025-07-17T13:28:46.014972151Z,2025-07-17T13:28:46.014805841Z,10,2,1108,A,A,5,19.58,100,130,166310,26613841,9.990000,200,2,15.300000,100,1,9.670000,200,2,17.120000,200,2,9.290000,700,1,17.600000,200,2,9.130000,100,1,18.320000,700,1,7.840000,100,1,18.400000,100,1,7.740000,700,7,19.580000,600,6,,0,0,20.320000,100,1,,0,0,20.480000,100,1,,0,0,,0,0,,0,0,,0,0,ARL,41370965
2025-07-17T13:28:46.014973343Z,2025-07-17T13:28:46.014807086Z,10,2,1108,C,A,7,20.48,100,0,166257,26613842,9.990000,200,2,15.300000,100,1,9.670000,200,2,17.120000,200,2,9.290000,700,1,17.600000,200,2,9.130000,100,1,18.320000,700,1,7.840000,100,1,18.400000,100,1,7.740000,700,7,19.580000,600,6,,0,0,20.320000,100,1,,0,0,,0,0,,0,0,,0,0,,0,0,,0,0,ARL,40617785
2025-07-17T13:28:46.014973343Z,2025-07-17T13:28:46.014807086Z,10,2,1108,A,A,5,19.58,100,130,166257,26613842,9.990000,200,2,15.300000,100,1,9.670000,200,2,17.120000,200,2,9.290000,700,1,17.600000,200,2,9.130000,100,1,18.320000,700,1,7.840000,100,1,18.400000,100,1,7.740000,700,7,19.580000,700,7,,0,0,20.320000,100,1,,0,0,,0,0,,0,0,,0,0,,0,0,,0,0,ARL,41370969
2025-07-17T13:28:46.015690361Z,2025-07-17T13:28:46.015523291Z,10,2,1108,A,B,0,10.18,700,130,167070,26614152,10.180000,700,1,15.300000,100,1,9.990000,200,2,17.120000,200,2,9.670000,200,2,17.600000,200,2,9.290000,700,1,18.320000,700,1,9.130000,100,1,18.400000,100,1,7.840000,100,1,19.580000,700,7,7.740000,700,7,20.320000,100,1,,0,0,,0,0,,0,0,,0,0,,0,0,,0,0,ARL,41371221
2025-07-17T13:28:46.015691617Z,2025-07-17T13:28:46.015525315Z,10,2,1108,A,A,1,16.11,700,130,166302,26614155,10.180000,700,1,15.300000,100,1,9.990000,200,2,16.110000,700,1,9.670000,200,2,17.120000,200,2,9.290000,700,1,17.600000,200,2,9.130000,100,1,18.320000,700,1,7.840000,100,1,18.400000,100,1,7.740000,700,7,19.580000,700,7,,0,0,20.320000,100,1,,0,0,,0,0,,0,0,,0,0,ARL,41371225
2025-07-17T13:28:46.017375168Z,2025-07-17T13:28:46.017209641Z,10,2,1108,C,A,2,17.12,100,0,165527,26614961,10.180000,700,1,15.300000,100,1,9.990000,200,2,16.110000,700,1,9.670000,200,2,17.120000,100,1,9.290000,700,1,17.600000,200,2,9.130000,100,1,18.320000,700,1,7.840000,100,1,18.400000,100,1,7.740000,700,7,19.580000,700,7,,0,0,20.320000,100,1,,0,0,,0,0,,0,0,,0,0,ARL,41000173
2025-07-17T13:28:46.017375168Z,2025-07-17T13:28:46.017209641Z,10,2,1108,A,A,2,16.38,100,130,165527,26614961,10.180000,700,1,15.300000,100,1,9.990000,200,2,16.110000,700,1,9.670000,200,2,16.380000,100,1,9.290000,700,1,17.120000,100,1,9.130000,100,1,17.600000,200,2,7.840000,100,1,18.320000,700,1,7.740000,700,7,18.400000,100,1,,0,0,19.580000,700,7,,0,0,20.320000,100,1,,0,0,,0,0,ARL,41372085
2025-07-17T13:28:46.017425627Z,2025-07-17T13:28:46.017260228Z,10,2,1108,C,A,4,17.60,100,0,165399,26614991,10.180000,700,1,15.300000,100,1,9.990000,200,2,16.110000,700,1,9.670000,200,2,16.380000,100,1,9.290000,700,1,17.120000,100,1,9.130000,100,1,17.600000,100,1,7.840000,100,1,18.320000,700,1,7.740000,700,7,18.400000,100,1,,0,0,19.580000,700,7,,0,0,20.320000,100,1,,0,0,,0,0,ARL,40999449
2025-07-17T13:28:46.017425627Z,2025-07-17T13:28:46.017260228Z,10,2,1108,A,A,3,16.83,100,130,165399,26614991,10.180000,700,1,15.300000,100,1,9.990000,200,2,16.110000,700,1,9.670000,200,2,16.380000,100,1,9.290000,700,1,16.830000,100,1,9.130000,100,1,17.120000,100,1,7.840000,100,1,17.600000,100,1,7.740000,700,7,18.320000,700,1,,0,0,18.400000,100,1,,0,0,19.580000,700,7,,0,0,20.320000,100,1,ARL,41372125
2025-07-17T13:28:46.017696573Z,2025-07-17T13:28:46.017531156Z,10,2,1108,C,A,4,17.12,100,0,165417,26615138,10.180000,700,1,15.300000,100,1,9.990000,200,2,16.110000,700,1,9.670000,200,2,16.380000,100,1,9.290000,700,1,16.830000,100,1,9.130000,100,1,17.600000,100,1,7.840000,100,1,18.320000,700,1,7.740000,700,7,18.400000,100,1,,0,0,19.580000,700,7,,0,0,20.320000,100,1,,0,0,,0,0,ARL,41021841
2025-07-17T13:28:46.017696573Z,2025-07-17T13:28:46.017531156Z,10,2,1108,A,A,2,16.38,100,130,165417,26615138,10.180000,700,1,15.300000,100,1,9.990000,200,2,16.110000,700,1,9.670000,200,2,16.380000,200,2,9.290000,700,1,16.830000,100,1,9.130000,100,1,17.600000,100,1,7.840000,100,1,18.320000,700,1,7.740000,700,7,18.400000,100,1,,0,0,19.580000,700,7,,0,0,20.320000,100,1,,0,0,,0,0,ARL,41372369
2025-07-17T13:28:46.017823073Z,2025-07-17T13:28:46.017657609Z,10,2,1108,C,A,4,17.60,100,0,165464,26615203,10.180000,700,1,15.300000,100,1,9.990000,200,2,16.110000,700,1,9.670000,200,2,16.380000,200,2,9.290000,700,1,16.830000,100,1,9.130000,100,1,18.320000,700,1,7.840000,100,1,18.400000,100,1,7.740000,700,7,19.580000,700,7,,0,0,20.320000,100,1,,0,0,,0,0,,0,0,,0,0,ARL,41021373
2025-07-17T13:28:46.017823073Z,2025-07-17T13:28:46.017657609Z,10,2,1108,A,A,3,16.83,100,130,165464,26615203,10.180000,700,1,15.300000,100,1,9.990000,200,2,16.110000,700,1,9.670000,200,2,16.380000,200,2,9.290000,700,1,16.830000,200,2,9.130000,100,1,18.320000,700,1,7.840000,100,1,18.400000,100,1,7.740000,700,7,19.580000,700,7,,0,0,20.320000,100,1,,0,0,,0,0,,0,0,,0,0,ARL,41372469
2025-07-17T13:28:46.017886428Z,2025-07-17T13:28:46.017721028Z,10,2,1108,C,A,5,18.40,100,0,165400,26615230,10.180000,700,1,15.300000,100,1,9.990000,200,2,16.110000,700,1,9.670000,200,2,16.380000,200,2,9.290000,700,1,16.830000,200,2,9.130000,100,1,18.320000,700,1,7.840000,100,1,19.580000,700,7,7.740000,700,7,20.320000,100,1,,0,0,,0,0,,0,0,,0,0,,0,0,,0,0,ARL,41032057
2025-07-17T13:28:46.017886428Z,2025-07-17T13:28:46.017721028Z,10,2,1108,A,A,4,17.60,100,130,165400,26615230,10.180000,700,1,15.300000,100,1,9.990000,200,2,16.110000,700,1,9.670000,200,2,16.380000,200,2,9.290000,700,1,16.830000,200,2,9.130000,100,1,17.600000,100,1,7.840000,100,1,18.320000,700,1,7.740000,700,7,19.580000,700,7,,0,0,20.320000,100,1,,0,0,,0,0,,0,0,,0,0,ARL,41372493
2025-07-17T13:28:46.018003119Z,2025-07-17T13:28:46.017837874Z,10,2,1108,C,A,7,20.32,100,0,165245,26615283,10.180000,700,1,15.300000,100,1,9.990000,200,2,16.110000,700,1,9.670000,200,2,16.380000,200,2,9.290000,700,1,16.830000,200,2,9.130000,100,1,17.600000,100,1,7.840000,100,1,18.320000,700,1,7.740000,700,7,19.580000,700,7,,0,0,,0,0,,0,0,,0,0,,0,0,,0,0,ARL,41306445
2025-07-17T13:28:46.018003119Z,2025-07-17T13:28:46.017837874Z,10,2,1108,A,A,6,19.44,100,130,165245,26615283,10.180000,700,1,15.300000,100,1,9.990000,200,2,16.110000,700,1,9.670000,200,2,16.380000,200,2,9.290000,700,1,16.830000,200,2,9.130000,100,1,17.600000,100,1,7.840000,100,1,18.320000,700,1,7.740000,700,7,19.440000,100,1,,0,0,19.580000,700,7,,0,0,,0,0,,0,0,,0,0,ARL,41372549
2025-07-17T13:28:46.022262428Z,2025-07-17T13:28:46.022095254Z,10,2,1108,A,B,1,10.05,700,128,167174,26616844,10.180000,700,1,15.300000,100,1,10.050000,700,1,16.110000,700,1,9.990000,200,2,16.380000,200,2,9.670000,200,2,16.830000,200,2,9.290000,700,1,17.600000,100,1,9.130000,100,1,18.320000,700,1,7.840000,100,1,19.440000,100,1,7.740000,700,7,19.580000,700,7,,0,0,,0,0,,0,0,,0,0,ARL,41375793
2025-07-17T13:28:46.022988063Z,2025-07-17T13:28:46.022822832Z,10,2,1108,A,A,2,16.30,700,130,165231,26617168,10.180000,700,1,15.300000,100,1,10.050000,700,1,16.110000,700,1,9.990000,200,2,16.300000,700,1,9.670000,200,2,16.380000,200,2,9.290000,700,1,16.830000,200,2,9.130000,100,1,17.600000,100,1,7.840000,100,1,18.320000,700,1,7.740000,700,7,19.440000,100,1,,0,0,19.580000,700,7,,0,0,,0,0,ARL,41375973
2025-07-17T13:28:46.025981579Z,2025-07-17T13:28:46.025816567Z,10,2,1108,A,B,0,11.76,100,130,165012,26618403,11.760000,100,1,15.300000,100,1,10.180000,700,1,16.110000,700,1,10.050000,700,1,16.300000,700,1,9.990000,200,2,16.380000,200,2,9.670000,200,2,16.830000,200,2,9.290000,700,1,17.600000,100,1,9.130000,100,1,18.320000,700,1,7.840000,100,1,19.440000,100,1,7.740000,700,7,19.580000,700,7,,0,0,,0,0,ARL,41376297
2025-07-17T13:28:46.026037162Z,2025-07-17T13:28:46.025870563Z,10,2,1108,C,B,8,7.74,100,0,166599,26618436,11.760000,100,1,15.300000,100,1,10.180000,700,1,16.110000,700,1,10.050000,700,1,16.300000,700,1,9.990000,200,2,16.380000,200,2,9.670000,200,2,16.830000,200,2,9.290000,700,1,17.600000,100,1,9.130000,100,1,18.320000,700,1,7.840000,100,1,19.440000,100,1,7.740000,600,6,19.580000,700,7,,0,0,,0,0,ARL,23616197
2025-07-17T13:28:46.026037162Z,2025-07-17T13:28:46.025870563Z,10,2,1108,A,B,7,8.47,100,130,166599,26618436,11.760000,100,1,15.300000,100,1,10.180000,700,1,16.110000,700,1,10.050000,700,1,16.300000,700,1,9.990000,200,2,16.380000,200,2,9.670000,200,2,16.830000,200,2,9.290000,700,1,17.600000,100,1,9.130000,100,1,18.320000,700,1,8.470000,100,1,19.440000,100,1,7.840000,100,1,19.580000,700,7,7.740000,600,6,,0,0,ARL,41376333
2025-07-17T13:28:46.026038058Z,2025-07-17T13:28:46.025872146Z,10,2,1108,C,B,9,7.74,100,0,165912,26618438,11.760000,100,1,15.300000,100,1,10.180000,700,1,16.110000,700,1,10.050000,700,1,16.300000,700,1,9.990000,200,2,16.380000,200,2,9.670000,200,2,16.830000,200,2,9.290000,700,1,17.600000,100,1,9.130000,100,1,18.320000,700,1,8.470000,100,1,19.440000,100,1,7.840000,100,1,19.580000,700,7,7.740000,500,5,,0,0,ARL,23622101
2025-07-17T13:28:46.026038058Z,2025-07-17T13:28:46.025872146Z,10,2,1108,A,B,7,8.47,100,130,165912,26618438,11.760000,100,1,15.300000,100,1,10.180000,700,1,16.110000,700,1,10.050000,700,1,16.300000,700,1,9.990000,200,2,16.380000,200,2,9.670000,200,2,16.830000,200,2,9.290000,700,1,17.600000,100,1,9.130000,100,1,18.320000,700,1,8.470000,200,2,19.440000,100,1,7.840000,100,1,19.580000,700,7,7.740000,500,5,,0,0,ARL,41376337
2025-07-17T13:28:46.026039687Z,2025-07-17T13:28:46.025873388Z,10,2,1108,C,B,9,7.74,100,0,166299,26618439,11.760000,100,1,15.300000,100,1,10.180000,700,1,16.110000,700,1,10.050000,700,1,16.300000,700,1,9.990000,200,2,16.380000,200,2,9.670000,200,2,16.830000,200,2,9.290000,700,1,17.600000,100,1,9.130000,100,1,18.320000,700,1,8.470000,200,2,19.440000,100,1,7.840000,100,1,19.580000,700,7,7.740000,400,4,,0,0,ARL,24102329
2025-07-17T13:28:46.026039687Z,2025-07-17T13:28:46.025873388Z,10,2,1108,A,B,7,8.47,100,128,166299,26618439,11.760000,100,1,15.300000,100,1,10.180000,700,1,16.110000,700,1,10.050000,700,1,16.300000,700,1,9.990000,200,2,16.380000,200,2,9.670000,200,2,16.830000,200,2,9.290000,700,1,17.600000,100,1,9.130000,100,1,18.320000,700,1,8.470000,300,3,19.440000,100,1,7.840000,100,1,19.580000,700,7,7.740000,400,4,,0,0,ARL,41376341
2025-07-17T13:28:46.026045679Z,2025-07-17T13:28:46.025874774Z,10,2,1108,C,B,9,7.74,100,0,170905,26618441,11.760000,100,1,15.300000,100,1,10.180000,700,1,16.110000,700,1,10.050000,700,1,16.300000,700,1,9.990000,200,2,16.380000,200,2,9.670000,200,2,16.830000,200,2,9.290000,700,1,17.600000,100,1,9.130000,100,1,18.320000,700,1,8.470000,300,3,19.440000,100,1,7.840000,100,1,19.580000,700,7,7.740000,300,3,,0,0,ARL,31960841
2025-07-17T13:28:46.026045679Z,2025-07-17T13:28:46.025874774Z,10,2,1108,A,B,7,8.47,100,0,170905,26618441,11.760000,100,1,15.300000,100,1,10.180000,700,1,16.110000,700,1,10.050000,700,1,16.300000,700,1,9.990000,200,2,16.380000,200,2,9.670000,200,2,16.830000,200,2,9.290000,700,1,17.600000,100,1,9.130000,100,1,18.320000,700,1,8.470000,400,4,19.440000,100,1,7.840000,100,1,19.580000,700,7,7.740000,300,3,,0,0,ARL,41376345
2025-07-17T13:28:46.026045679Z,2025-07-17T13:28:46.025875041Z,10,2,1108,C,B,9,7.74,100,0,170638,26618442,11.760000,100,1,15.300000,100,1,10.180000,700,1,16.110000,700,1,10.050000,700,1,16.300000,700,1,9.990000,200,2,16.380000,200,2,9.670000,200,2,16.830000,200,2,9.290000,700,1,17.600000,100,1,9.130000,100,1,18.320000,700,1,8.470000,400,4,19.440000,100,1,7.840000,100,1,19.580000,700,7,7.740000,200,2,,0,0,ARL,33574717
2025-07-17T13:28:46.026045679Z,2025-07-17T13:28:46.025875041Z,10,2,1108,A,B,7,8.47,100,0,170638,26618442,11.760000,100,1,15.300000,100,1,10.180000,700,1,16.110000,700,1,10.050000,700,1,16.300000,700,1,9.990000,200,2,16.380000,200,2,9.670000,200,2,16.830000,200,2,9.290000,700,1,17.600000,100,1,9.130000,100,1,18.320000,700,1,8.470000,500,5,19.440000,100,1,7.840000,100,1,19.580000,700,7,7.740000,200,2,,0,0,ARL,41376349
2025-07-17T13:28:46.026045679Z,2025-07-17T13:28:46.025875401Z,10,2,1108,C,B,9,7.74,100,0,170278,26618443,11.760000,100,1,15.300000,100,1,10.180000,700,1,16.110000,700,1,10.050000,700,1,16.300000,700,1,9.990000,200,2,16.380000,200,2,9.670000,200,2,16.830000,200,2,9.290000,700,1,17.600000,100,1,9.130000,100,1,18.320000,700,1,8.470000,500,5,19.440000,100,1,7.840000,100,1,19.580000,700,7,7.740000,100,1,,0,0,ARL,38041417
2025-07-17T13:28:46.026045679Z,2025-07-17T13:28:46.025875401Z,10,2,1108,A,B,7,8.47,100,0,170278,26618443,11.760000,100,1,15.300000,100,1,10.180000,700,1,16.110000,700,1,10.050000,700,1,16.300000,700,1,9.990000,200,2,16.380000,200,2,9.670000,200,2,16.830000,200,2,9.290000,700,1,17.600000,100,1,9.130000,100,1,18.320000,700,1,8.470000,600,6,19.440000,100,1,7.840000,100,1,19.580000,700,7,7.740000,100,1,,0,0,ARL,41376353
2025-07-17T13:28:46.026045679Z,2025-07-17T13:28:46.025877502Z,10,2,1108,C,B,9,7.74,100,0,168177,26618447,11.760000,100,1,15.300000,100,1,10.180000,700,1,16.110000,700,1,10.050000,700,1,16.300000,700,1,9.990000,200,2,16.380000,200,2,9.670000,200,2,16.830000,200,2,9.290000,700,1,17.600000,100,1,9.130000,100,1,18.320000,700,1,8.470000,600,6,19.440000,100,1,7.840000,100,1,19.580000,700,7,,0,0,,0,0,ARL,40617777
2025-07-17T13:28:46.026045679Z,2025-07-17T13:28:46.025877502Z,10,2,1108,A,B,7,8.47,100,130,168177,26618447,11.760000,100,1,15.300000,100,1,10.180000,700,1,16.110000,700,1,10.050000,700,1,16.300000,700,1,9.990000,200,2,16.380000,200,2,9.670000,200,2,16.830000,200,2,9.290000,700,1,17.600000,100,1,9.130000,100,1,18.320000,700,1,8.470000,700,7,19.440000,100,1,7.840000,100,1,19.580000,700,7,,0,0,,0,0,ARL,41376357
2025-07-17T13:28:46.027725683Z,2025-07-17T13:28:46.027560174Z,10,2,1108,C,B,3,9.99,100,0,165509,26619144,11.760000,100,1,15.300000,100,1,10.180000,700,1,16.110000,700,1,10.050000,700,1,16.300000,700,1,9.990000,100,1,16.380000,200,2,9.670000,200,2,16.830000,200,2,9.290000,700,1,17.600000,100,1,9.130000,100,1,18.320000,700,1,8.470000,700,7,19.440000,100,1,7.840000,100,1,19.580000,700,7,,0,0,,0,0,ARL,41000165
2025-07-17T13:28:46.027725683Z,2025-07-17T13:28:46.027560174Z,10,2,1108,A,B,1,10.93,100,130,165509,26619144,11.760000,100,1,15.300000,100,1,10.930000,100,1,16.110000,700,1,10.180000,700,1,16.300000,700,1,10.050000,700,1,16.380000,200,2,9.990000,100,1,16.830000,200,2,9.670000,200,2,17.600000,100,1,9.290000,700,1,18.320000,700,1,9.130000,100,1,19.440000,100,1,8.470000,700,7,19.580000,700,7,7.840000,100,1,,0,0,ARL,41376501
2025-07-17T13:28:46.029726785Z,2025-07-17T13:28:46.029556957Z,10,2,1108,C,B,5,9.67,100,0,169828,26619966,11.760000,100,1,15.300000,100,1,10.930000,100,1,16.110000,700,1,10.180000,700,1,16.300000,700,1,10.050000,700,1,16.380000,200,2,9.990000,100,1,16.830000,200,2,9.670000,100,1,17.600000,100,1,9.290000,700,1,18.320000,700,1,9.130000,100,1,19.440000,100,1,8.470000,700,7,19.580000,700,7,7.840000,100,1,,0,0,ARL,40999441
2025-07-17T13:28:46.029726785Z,2025-07-17T13:28:46.029556957Z,10,2,1108,A,B,2,10.58,100,128,169828,26619966,11.760000,100,1,15.300000,100,1,10.930000,100,1,16.110000,700,1,10.580000,100,1,16.300000,700,1,10.180000,700,1,16.380000,200,2,10.050000,700,1,16.830000,200,2,9.990000,100,1,17.600000,100,1,9.670000,100,1,18.320000,700,1,9.290000,700,1,19.440000,100,1,9.130000,100,1,19.580000,700,7,8.470000,700,7,,0,0,ARL,41376725
2025-07-17T13:28:46.029775250Z,2025-07-17T13:28:46.029609064Z,10,2,1108,C,B,10,7.84,100,0,166186,26619999,11.760000,100,1,15.300000,100,1,10.930000,100,1,16.110000,700,1,10.580000,100,1,16.300000,700,1,10.180000,700,1,16.380000,200,2,10.050000,700,1,16.830000,200,2,9.990000,100,1,17.600000,100,1,9.670000,100,1,18.320000,700,1,9.290000,700,1,19.440000,100,1,9.130000,100,1,19.580000,700,7,8.470000,700,7,,0,0,ARL,41306441
2025-07-17T13:28:46.029775250Z,2025-07-17T13:28:46.029609064Z,10,2,1108,A,B,9,8.58,100,130,166186,26619999,11.760000,100,1,15.300000,100,1,10.930000,100,1,16.110000,700,1,10.580000,100,1,16.300000,700,1,10.180000,700,1,16.380000,200,2,10.050000,700,1,16.830000,200,2,9.990000,100,1,17.600000,100,1,9.670000,100,1,18.320000,700,1,9.290000,700,1,19.440000,100,1,9.130000,100,1,19.580000,700,7,8.580000,100,1,,0,0,ARL,41376733
2025-07-17T13:28:46.031239452Z,2025-07-17T13:28:46.031073916Z,10,2,1108,C,B,8,9.13,100,0,165536,26620530,11.760000,100,1,15.300000,100,1,10.930000,100,1,16.110000,700,1,10.580000,100,1,16.300000,700,1,10.180000,700,1,16.380000,200,2,10.050000,700,1,16.830000,200,2,9.990000,100,1,17.600000,100,1,9.670000,100,1,18.320000,700,1,9.290000,700,1,19.440000,100,1,8.580000,100,1,19.580000,700,7,8.470000,700,7,,0,0,ARL,41032049
2025-07-17T13:28:46.031239452Z,2025-07-17T13:28:46.031073916Z,10,2,1108,A,B,5,9.99,100,130,165536,26620530,11.760000,100,1,15.300000,100,1,10.930000,100,1,16.110000,700,1,10.580000,100,1,16.300000,700,1,10.180000,700,1,16.380000,200,2,10.050000,700,1,16.830000,200,2,9.990000,200,2,17.600000,100,1,9.670000,100,1,18.320000,700,1,9.290000,700,1,19.440000,100,1,8.580000,100,1,19.580000,700,7,8.470000,700,7,,0,0,ARL,41376769
2025-07-17T13:28:46.038120992Z,2025-07-17T13:28:46.037954661Z,10,2,1108,C,B,6,9.67,100,0,166331,26623213,11.760000,100,1,15.300000,100,1,10.930000,100,1,16.110000,700,1,10.580000,100,1,16.300000,700,1,10.180000,700,1,16.380000,200,2,10.050000,700,1,16.830000,200,2,9.990000,200,2,17.600000,100,1,9.290000,700,1,18.320000,700,1,8.580000,100,1,19.440000,100,1,8.470000,700,7,19.580000,700,7,,0,0,,0,0,ARL,41021369
2025-07-17T13:28:46.038120992Z,2025-07-17T13:28:46.037954661Z,10,2,1108,A,B,2,10.58,100,128,166331,26623213,11.760000,100,1,15.300000,100,1,10.930000,100,1,16.110000,700,1,10.580000,200,2,16.300000,700,1,10.180000,700,1,16.380000,200,2,10.050000,700,1,16.830000,200,2,9.990000,200,2,17.600000,100,1,9.290000,700,1,18.320000,700,1,8.580000,100,1,19.440000,100,1,8.470000,700,7,19.580000,700,7,,0,0,,0,0,ARL,41377117
2025-07-17T13:28:46.043024422Z,2025-07-17T13:28:46.042858782Z,10,2,1108,C,B,5,9.99,100,0,165640,26625366,11.760000,100,1,15.300000,100,1,10.930000,100,1,16.110000,700,1,10.580000,200,2,16.300000,700,1,10.180000,700,1,16.380000,200,2,10.050000,700,1,16.830000,200,2,9.990000,100,1,17.600000,100,1,9.290000,700,1,18.320000,700,1,8.580000,100,1,19.440000,100,1,8.470000,700,7,19.580000,700,7,,0,0,,0,0,ARL,41021837
2025-07-17T13:28:46.043024422Z,2025-07-17T13:28:46.042858782Z,10,2,1108,A,B,1,10.93,100,130,165640,26625366,11.760000,100,1,15.300000,100,1,10.930000,200,2,16.110000,700,1,10.580000,200,2,16.300000,700,1,10.180000,700,1,16.380000,200,2,10.050000,700,1,16.830000,200,2,9.990000,100,1,17.600000,100,1,9.290000,700,1,18.320000,700,1,8.580000,100,1,19.440000,100,1,8.470000,700,7,19.580000,700,7,,0,0,,0,0,ARL,41379985
2025-07-17T13:28:52.312460374Z,2025-07-17T13:28:52.312295020Z,10,2,1108,A,B,2,10.75,700,130,165354,26806665,11.760000,100,1,15.300000,100,1,10.930000,200,2,16.110000,700,1,10.750000,700,1,16.300000,700,1,10.580000,200,2,16.380000,200,2,10.180000,700,1,16.830000,200,2,10.050000,700,1,17.600000,100,1,9.990000,100,1,18.320000,700,1,9.290000,700,1,19.440000,100,1,8.580000,100,1,19.580000,700,7,8.470000,700,7,,0,0,ARL,41507073
2025-07-17T13:28:52.312496032Z,2025-07-17T13:28:52.312330796Z,10,2,1108,C,B,5,10.05,700,130,165236,26806666,11.760000,100,1,15.300000,100,1,10.930000,200,2,16.110000,700,1,10.750000,700,1,16.300000,700,1,10.580000,200,2,16.380000,200,2,10.180000,700,1,16.830000,200,2,9.990000,100,1,17.600000,100,1,9.290000,700,1,18.320000,700,1,8.580000,100,1,19.440000,100,1,8.470000,700,7,19.580000,700,7,,0,0,,0,0,ARL,41375793
2025-07-17T13:28:52.512457909Z,2025-07-17T13:28:52.512292648Z,10,2,1108,A,B,1,10.99,700,130,165261,26808221,11.760000,100,1,15.300000,100,1,10.990000,700,1,16.110000,700,1,10.930000,200,2,16.300000,700,1,10.750000,700,1,16.380000,200,2,10.580000,200,2,16.830000,200,2,10.180000,700,1,17.600000,100,1,9.990000,100,1,18.320000,700,1,9.290000,700,1,19.440000,100,1,8.580000,100,1,19.580000,700,7,8.470000,700,7,,0,0,ARL,41509393
2025-07-17T13:28:52.513255552Z,2025-07-17T13:28:52.513090520Z,10,2,1108,C,B,3,10.75,700,130,165032,26808222,11.760000,100,1,15.300000,100,1,10.990000,700,1,16.110000,700,1,10.930000,200,2,16.300000,700,1,10.580000,200,2,16.380000,200,2,10.180000,700,1,16.830000,200,2,9.990000,100,1,17.600000,100,1,9.290000,700,1,18.320000,700,1,8.580000,100,1,19.440000,100,1,8.470000,700,7,19.580000,700,7,,0,0,,0,0,ARL,41507073
2025-07-17T13:28:53.957233148Z,2025-07-17T13:28:53.957067631Z,10,2,1108,A,A,2,16.15,700,130,165517,26835971,11.760000,100,1,15.300000,100,1,10.990000,700,1,16.110000,700,1,10.930000,200,2,16.150000,700,1,10.580000,200,2,16.300000,700,1,10.180000,700,1,16.380000,200,2,9.990000,100,1,16.830000,200,2,9.290000,700,1,17.600000,100,1,8.580000,100,1,18.320000,700,1,8.470000,700,7,19.440000,100,1,,0,0,19.580000,700,7,ARL,41528029
2025-07-17T13:28:53.957281517Z,2025-07-17T13:28:53.957116061Z,10,2,1108,C,A,7,18.32,700,130,165456,26835974,11.760000,100,1,15.300000,100,1,10.990000,700,1,16.110000,700,1,10.930000,200,2,16.150000,700,1,10.580000,200,2,16.300000,700,1,10.180000,700,1,16.380000,200,2,9.990000,100,1,16.830000,200,2,9.290000,700,1,17.600000,100,1,8.580000,100,1,19.440000,100,1,8.470000,700,7,19.580000,700,7,,0,0,,0,0,ARL,40846101
2025-07-17T13:28:54.128476219Z,2025-07-17T13:28:54.128310778Z,10,2,1108,A,B,5,9.99,700,130,165441,26850111,11.760000,100,1,15.300000,100,1,10.990000,700,1,16.110000,700,1,10.930000,200,2,16.150000,700,1,10.580000,200,2,16.300000,700,1,10.180000,700,1,16.380000,200,2,9.990000,800,2,16.830000,200,2,9.290000,700,1,17.600000,100,1,8.580000,100,1,19.440000,100,1,8.470000,700,7,19.580000,700,7,,0,0,,0,0,ARL,41530665
2025-07-17T13:28:54.128503934Z,2025-07-17T13:28:54.128338727Z,10,2,1108,C,B,6,9.29,700,130,165207,26850112,11.760000,100,1,15.300000,100,1,10.990000,700,1,16.110000,700,1,10.930000,200,2,16.150000,700,1,10.580000,200,2,16.300000,700,1,10.180000,700,1,16.380000,200,2,9.990000,800,2,16.830000,200,2,8.580000,100,1,17.600000,100,1,8.470000,700,7,19.440000,100,1,,0,0,19.580000,700,7,,0,0,,0,0,ARL,40851989
2025-07-17T13:28:54.328652337Z,2025-07-17T13:28:54.328487063Z,10,2,1108,A,B,4,10.26,700,130,165274,26851888,11.760000,100,1,15.300000,100,1,10.990000,700,1,16.110000,700,1,10.930000,200,2,16.150000,700,1,10.580000,200,2,16.300000,700,1,10.260000,700,1,16.380000,200,2,10.180000,700,1,16.830000,200,2,9.990000,800,2,17.600000,100,1,8.580000,100,1,19.440000,100,1,8.470000,700,7,19.580000,700,7,,0,0,,0,0,ARL,41533513
2025-07-17T13:28:54.328684086Z,2025-07-17T13:28:54.328519057Z,10,2,1108,C,B,6,9.99,700,130,165029,26851889,11.760000,100,1,15.300000,100,1,10.990000,700,1,16.110000,700,1,10.930000,200,2,16.150000,700,1,10.580000,200,2,16.300000,700,1,10.260000,700,1,16.380000,200,2,10.180000,700,1,16.830000,200,2,9.990000,100,1,17.600000,100,1,8.580000,100,1,19.440000,100,1,8.470000,700,7,19.580000,700,7,,0,0,,0,0,ARL,41530665
2025-07-17T13:28:54.477620754Z,2025-07-17T13:28:54.477455479Z,10,2,1108,A,B,1,11.14,700,130,165275,26853475,11.760000,100,1,15.300000,100,1,11.140000,700,1,16.110000,700,1,10.990000,700,1,16.150000,700,1,10.930000,200,2,16.300000,700,1,10.580000,200,2,16.380000,200,2,10.260000,700,1,16.830000,200,2,10.180000,700,1,17.600000,100,1,9.990000,100,1,19.440000,100,1,8.580000,100,1,19.580000,700,7,8.470000,700,7,,0,0,ARL,41534785
2025-07-17T13:28:54.478018001Z,2025-07-17T13:28:54.477852651Z,10,2,1108,C,B,6,10.18,700,130,165350,26853478,11.760000,100,1,15.300000,100,1,11.140000,700,1,16.110000,700,1,10.990000,700,1,16.150000,700,1,10.930000,200,2,16.300000,700,1,10.580000,200,2,16.380000,200,2,10.260000,700,1,16.830000,200,2,9.990000,100,1,17.600000,100,1,8.580000,100,1,19.440000,100,1,8.470000,700,7,19.580000,700,7,,0,0,,0,0,ARL,41371221
2025-07-17T13:28:54.528708243Z,2025-07-17T13:28:54.528542919Z,10,2,1108,A,B,5,10.53,700,130,165324,26853925,11.760000,100,1,15.300000,100,1,11.140000,700,1,16.110000,700,1,10.990000,700,1,16.150000,700,1,10.930000,200,2,16.300000,700,1,10.580000,200,2,16.380000,200,2,10.530000,700,1,16.830000,200,2,10.260000,700,1,17.600000,100,1,9.990000,100,1,19.440000,100,1,8.580000,100,1,19.580000,700,7,8.470000,700,7,,0,0,ARL,41535173
2025-07-17T13:28:54.528736554Z,2025-07-17T13:28:54.528571375Z,10,2,1108,C,B,6,10.26,700,130,165179,26853926,11.760000,100,1,15.300000,100,1,11.140000,700,1,16.110000,700,1,10.990000,700,1,16.150000,700,1,10.930000,200,2,16.300000,700,1,10.580000,200,2,16.380000,200,2,10.530000,700,1,16.830000,200,2,9.990000,100,1,17.600000,100,1,8.580000,100,1,19.440000,100,1,8.470000,700,7,19.580000,700,7,,0,0,,0,0,ARL,41533513
2025-07-17T13:28:54.728740313Z,2025-07-17T13:28:54.728575124Z,10,2,1108,A,B,4,10.80,700,130,165189,26856081,11.760000,100,1,15.300000,100,1,11.140000,700,1,16.110000,700,1,10.990000,700,1,16.150000,700,1,10.930000,200,2,16.300000,700,1,10.800000,700,1,16.380000,200,2,10.580000,200,2,16.830000,200,2,10.530000,700,1,17.600000,100,1,9.990000,100,1,19.440000,100,1,8.580000,100,1,19.580000,700,7,8.470000,700,7,,0,0,ARL,41537525
2025-07-17T13:28:54.728816275Z,2025-07-17T13:28:54.728651317Z,10,2,1108,C,B,6,10.53,700,130,164958,26856082,11.760000,100,1,15.300000,100,1,11.140000,700,1,16.110000,700,1,10.990000,700,1,16.150000,700,1,10.930000,200,2,16.300000,700,1,10.800000,700,1,16.380000,200,2,10.580000,200,2,16.830000,200,2,9.990000,100,1,17.600000,100,1,8.580000,100,1,19.440000,100,1,8.470000,700,7,19.580000,700,7,,0,0,,0,0,ARL,41535173
2025-07-17T13:28:54.928577406Z,2025-07-17T13:28:54.928412211Z,10,2,1108,A,B,2,11.07,700,130,165195,26858349,11.760000,100,1,15.300000,100,1,11.140000,700,1,16.110000,700,1,11.070000,700,1,16.150000,700,1,10.990000,700,1,16.300000,700,1,10.930000,200,2,16.380000,200,2,10.800000,700,1,16.830000,200,2,10.580000,200,2,17.600000,100,1,9.990000,100,1,19.440000,100,1,8.580000,100,1,19.580000,700,7,8.470000,700,7,,0,0,ARL,41539477
2025-07-17T13:28:54.928653303Z,2025-07-17T13:28:54.928488170Z,10,2,1108,C,B,5,10.80,700,130,165133,26858351,11.760000,100,1,15.300000,100,1,11.140000,700,1,16.110000,700,1,11.070000,700,1,16.150000,700,1,10.990000,700,1,16.300000,700,1,10.930000,200,2,16.380000,200,2,10.580000,200,2,16.830000,200,2,9.990000,100,1,17.600000,100,1,8.580000,100,1,19.440000,100,1,8.470000,700,7,19.580000,700,7,,0,0,,0,0,ARL,41537525
2025-07-17T13:29:00.583276463Z,2025-07-17T13:29:00.583110843Z,10,2,1108,A,B,5,10.84,100,130,165620,27000961,11.760000,100,1,15.300000,100,1,11.140000,700,1,16.110000,700,1,11.070000,700,1,16.150000,700,1,10.990000,700,1,16.300000,700,1,10.930000,200,2,16.380000,200,2,10.840000,100,1,16.830000,200,2,10.580000,200,2,17.600000,100,1,9.990000,100,1,19.440000,100,1,8.580000,100,1,19.580000,700,7,8.470000,700,7,,0,0,ARL,41635065
2025-07-17T13:29:00.583289800Z,2025-07-17T13:29:00.583124331Z,10,2,1108,A,A,5,16.49,100,130,165469,27000962,11.760000,100,1,15.300000,100,1,11.140000,700,1,16.110000,700,1,11.070000,700,1,16.150000,700,1,10.990000,700,1,16.300000,700,1,10.930000,200,2,16.380000,200,2,10.840000,100,1,16.490000,100,1,10.580000,200,2,16.830000,200,2,9.990000,100,1,17.600000,100,1,8.580000,100,1,19.440000,100,1,8.470000,700,7,19.580000,700,7,ARL,41635069
2025-07-17T13:29:31.666650984Z,2025-07-17T13:29:31.666485583Z,10,2,1108,A,B,3,11.05,100,130,165401,27592251,11.760000,100,1,15.300000,100,1,11.140000,700,1,16.110000,700,1,11.070000,700,1,16.150000,700,1,11.050000,100,1,16.300000,700,1,10.990000,700,1,16.380000,200,2,10.930000,200,2,16.490000,100,1,10.840000,100,1,16.830000,200,2,10.580000,200,2,17.600000,100,1,9.990000,100,1,19.440000,100,1,8.580000,100,1,19.580000,700,7,ARL,42089321
2025-07-17T13:29:31.666676040Z,2025-07-17T13:29:31.666510533Z,10,2,1108,A,A,3,16.22,100,130,165507,27592252,11.760000,100,1,15.300000,100,1,11.140000,700,1,16.110000,700,1,11.070000,700,1,16.150000,700,1,11.050000,100,1,16.220000,100,1,10.990000,700,1,16.300000,700,1,10.930000,200,2,16.380000,200,2,10.840000,100,1,16.490000,100,1,10.580000,200,2,16.830000,200,2,9.990000,100,1,17.600000,100,1,8.580000,100,1,19.440000,100,1,ARL,42089325
2025-07-17T13:29:32.011253336Z,2025-07-17T13:29:32.011088073Z,10,2,1108,A,B,1,11.29,100,130,165263,27599196,11.760000,100,1,15.300000,100,1,11.290000,100,1,16.110000,700,1,11.140000,700,1,16.150000,700,1,11.070000,700,1,16.220000,100,1,11.050000,100,1,16.300000,700,1,10.990000,700,1,16.380000,200,2,10.930000,200,2,16.490000,100,1,10.840000,100,1,16.830000,200,2,10.580000,200,2,17.600000,100,1,9.990000,100,1,19.440000,100,1,ARL,42099317
2025-07-17T13:29:32.011257301Z,2025-07-17T13:29:32.011092154Z,10,2,1108,A,A,1,15.91,100,130,165147,27599197,11.760000,100,1,15.300000,100,1,11.290000,100,1,15.910000,100,1,11.140000,700,1,16.110000,700,1,11.070000,700,1,16.150000,700,1,11.050000,100,1,16.220000,100,1,10.990000,700,1,16.300000,700,1,10.930000,200,2,16.380000,200,2,10.840000,100,1,16.490000,100,1,10.580000,200,2,16.830000,200,2,9.990000,100,1,17.600000,100,1,ARL,42099321
2025-07-17T13:29:39.840138413Z,2025-07-17T13:29:39.839973111Z,10,2,1108,A,B,-1,8.47,100,130,165302,27759427,11.760000,100,1,15.300000,100,1,11.290000,100,1,15.910000,100,1,11.140000,700,1,16.110000,700,1,11.070000,700,1,16.150000,700,1,11.050000,100,1,16.220000,100,1,10.990000,700,1,16.300000,700,1,10.930000,200,2,16.380000,200,2,10.840000,100,1,16.490000,100,1,10.580000,200,2,16.830000,200,2,9.990000,100,1,17.600000,100,1,ARL,42202297
2025-07-17T13:29:40.000349567Z,2025-07-17T13:29:40.000183284Z,10,2,1108,A,A,-1,19.58,100,130,166283,27760200,11.760000,100,1,15.300000,100,1,11.290000,100,1,15.910000,100,1,11.140000,700,1,16.110000,700,1,11.070000,700,1,16.150000,700,1,11.050000,100,1,16.220000,100,1,10.990000,700,1,16.300000,700,1,10.930000,200,2,16.380000,200,2,10.840000,100,1,16.490000,100,1,10.580000,200,2,16.830000,200,2,9.990000,100,1,17.600000,100,1,ARL,42204681
2025-07-17T13:29:55.529348997Z,2025-07-17T13:29:55.529183618Z,10,2,1108,A,B,1,11.52,100,130,165379,28123971,11.760000,100,1,15.300000,100,1,11.520000,100,1,15.910000,100,1,11.290000,100,1,16.110000,700,1,11.140000,700,1,16.150000,700,1,11.070000,700,1,16.220000,100,1,11.050000,100,1,16.300000,700,1,10.990000,700,1,16.380000,200,2,10.930000,200,2,16.490000,100,1,10.840000,100,1,16.830000,200,2,10.580000,200,2,17.600000,100,1,ARL,42446497
2025-07-17T13:29:55.529365902Z,2025-07-17T13:29:55.529200619Z,10,2,1108,A,A,1,15.61,100,130,165283,28123973,11.760000,100,1,15.300000,100,1,11.520000,100,1,15.610000,100,1,11.290000,100,1,15.910000,100,1,11.140000,700,1,16.110000,700,1,11.070000,700,1,16.150000,700,1,11.050000,100,1,16.220000,100,1,10.990000,700,1,16.300000,700,1,10.930000,200,2,16.380000,200,2,10.840000,100,1,16.490000,100,1,10.580000,200,2,16.830000,200,2,ARL,42446501
2025-07-17T13:29:59.677450683Z,2025-07-17T13:29:59.677285294Z,10,2,1108,A,B,-1,10.11,100,130,165389,28321241,11.760000,100,1,15.300000,100,1,11.520000,100,1,15.610000,100,1,11.290000,100,1,15.910000,100,1,11.140000,700,1,16.110000,700,1,11.070000,700,1,16.150000,700,1,11.050000,100,1,16.220000,100,1,10.990000,700,1,16.300000,700,1,10.930000,200,2,16.380000,200,2,10.840000,100,1,16.490000,100,1,10.580000,200,2,16.830000,200,2,ARL,42583289
2025-07-17T13:29:59.677457187Z,2025-07-17T13:29:59.677290064Z,10,2,1108,A,A,-1,17.45,100,128,167123,28321242,11.760000,100,1,15.300000,100,1,11.520000,100,1,15.610000,100,1,11.290000,100,1,15.910000,100,1,11.140000,700,1,16.110000,700,1,11.070000,700,1,16.150000,700,1,11.050000,100,1,16.220000,100,1,10.990000,700,1,16.300000,700,1,10.930000,200,2,16.380000,200,2,10.840000,100,1,16.490000,100,1,10.580000,200,2,16.830000,200,2,ARL,42583293
2025-07-17T13:30:00.093085479Z,2025-07-17T13:30:00.092900330Z,10,2,1108,A,B,6,11.01,100,128,185149,28409476,11.760000,100,1,15.300000,100,1,11.520000,100,1,15.610000,100,1,11.290000,100,1,15.910000,100,1,11.140000,700,1,16.110000,700,1,11.070000,700,1,16.150000,700,1,11.050000,100,1,16.220000,100,1,11.010000,100,1,16.300000,700,1,10.990000,700,1,16.380000,200,2,10.930000,200,2,16.490000,100,1,10.840000,100,1,16.830000,200,2,ARL,42674817
2025-07-17T13:30:00.093164566Z,2025-07-17T13:30:00.092988904Z,10,2,1108,A,A,3,16.10,100,128,175662,28409593,11.760000,100,1,15.300000,100,1,11.520000,100,1,15.610000,100,1,11.290000,100,1,15.910000,100,1,11.140000,700,1,16.100000,100,1,11.070000,700,1,16.110000,700,1,11.050000,100,1,16.150000,700,1,11.010000,100,1,16.220000,100,1,10.990000,700,1,16.300000,700,1,10.930000,200,2,16.380000,200,2,10.840000,100,1,16.490000,100,1,ARL,42674989
2025-07-17T13:30:00.412816741Z,2025-07-17T13:30:00.412637542Z,10,2,1108,A,A,-1,19.58,100,128,179199,28676200,11.760000,100,1,15.300000,100,1,11.520000,100,1,15.610000,100,1,11.290000,100,1,15.910000,100,1,11.140000,700,1,16.100000,100,1,11.070000,700,1,16.110000,700,1,11.050000,100,1,16.150000,700,1,11.010000,100,1,16.220000,100,1,10.990000,700,1,16.300000,700,1,10.930000,200,2,16.380000,200,2,10.840000,100,1,16.490000,100,1,ARL,42946053
2025-07-17T13:30:00.422103919Z,2025-07-17T13:30:00.421937186Z,10,2,1108,A,B,-1,8.47,100,128,166733,28680759,11.760000,100,1,15.300000,100,1,11.520000,100,1,15.610000,100,1,11.290000,100,1,15.910000,100,1,11.140000,700,1,16.100000,100,1,11.070000,700,1,16.110000,700,1,11.050000,100,1,16.150000,700,1,11.010000,100,1,16.220000,100,1,10.990000,700,1,16.300000,700,1,10.930000,200,2,16.380000,200,2,10.840000,100,1,16.490000,100,1,ARL,42951397
2025-07-17T13:30:00.675725361Z,2025-07-17T13:30:00.675553569Z,10,2,1108,A,B,9,10.92,100,128,171792,28833560,11.760000,100,1,15.300000,100,1,11.520000,100,1,15.610000,100,1,11.290000,100,1,15.910000,100,1,11.140000,700,1,16.100000,100,1,11.070000,700,1,16.110000,700,1,11.050000,100,1,16.150000,700,1,11.010000,100,1,16.220000,100,1,10.990000,700,1,16.300000,700,1,10.930000,200,2,16.380000,200,2,10.920000,100,1,16.490000,100,1,ARL,43143317
2025-07-17T13:30:00.675748539Z,2025-07-17T13:30:00.675570319Z,10,2,1108,A,A,6,16.20,100,128,178220,28833574,11.760000,100,1,15.300000,100,1,11.520000,100,1,15.610000,100,1,11.290000,100,1,15.910000,100,1,11.140000,700,1,16.100000,100,1,11.070000,700,1,16.110000,700,1,11.050000,100,1,16.150000,700,1,11.010000,100,1,16.200000,100,1,10.990000,700,1,16.220000,100,1,10.930000,200,2,16.300000,700,1,10.920000,100,1,16.380000,200,2,ARL,43143333
2025-07-17T13:30:00.730859228Z,2025-07-17T13:30:00.730688348Z,10,2,1108,A,B,9,10.92,100,130,170880,28858298,11.760000,100,1,15.300000,100,1,11.520000,100,1,15.610000,100,1,11.290000,100,1,15.910000,100,1,11.140000,700,1,16.100000,100,1,11.070000,700,1,16.110000,700,1,11.050000,100,1,16.150000,700,1,11.010000,100,1,16.200000,100,1,10.990000,700,1,16.220000,100,1,10.930000,200,2,16.300000,700,1,10.920000,200,2,16.380000,200,2,ARL,43191333
2025-07-17T13:30:00.730867405Z,2025-07-17T13:30:00.730693126Z,10,2,1108,A,A,6,16.20,100,128,174279,28858300,11.760000,100,1,15.300000,100,1,11.520000,100,1,15.610000,100,1,11.290000,100,1,15.910000,100,1,11.140000,700,1,16.100000,100,1,11.070000,700,1,16.110000,700,1,11.050000,100,1,16.150000,700,1,11.010000,100,1,16.200000,200,2,10.990000,700,1,16.220000,100,1,10.930000,200,2,16.300000,700,1,10.920000,200,2,16.380000,200,2,ARL,43191369
2025-07-17T13:30:00.869893365Z,2025-07-17T13:30:00.869714108Z,10,2,1108,A,B,-1,9.41,100,0,179257,28963643,11.760000,100,1,15.300000,100,1,11.520000,100,1,15.610000,100,1,11.290000,100,1,15.910000,100,1,11.140000,700,1,16.100000,100,1,11.070000,700,1,16.110000,700,1,11.050000,100,1,16.150000,700,1,11.010000,100,1,16.200000,200,2,10.990000,700,1,16.220000,100,1,10.930000,200,2,16.300000,700,1,10.920000,200,2,16.380000,200,2,ARL,43313553
2025-07-17T13:30:00.869893365Z,2025-07-17T13:30:00.869715708Z,10,2,1108,A,A,-1,18.36,100,128,177657,28963646,11.760000,100,1,15.300000,100,1,11.520000,100,1,15.610000,100,1,11.290000,100,1,15.910000,100,1,11.140000,700,1,16.100000,100,1,11.070000,700,1,16.110000,700,1,11.050000,100,1,16.150000,700,1,11.010000,100,1,16.200000,200,2,10.990000,700,1,16.220000,100,1,10.930000,200,2,16.300000,700,1,10.920000,200,2,16.380000,200,2,ARL,43313565
2025-07-17T13:30:00.869922678Z,2025-07-17T13:30:00.869746905Z,10,2,1108,A,A,-1,18.36,100,128,175773,28963685,11.760000,100,1,15.300000,100,1,11.520000,100,1,15.610000,100,1,11.290000,100,1,15.910000,100,1,11.140000,700,1,16.100000,100,1,11.070000,700,1,16.110000,700,1,11.050000,100,1,16.150000,700,1,11.010000,100,1,16.200000,200,2,10.990000,700,1,16.220000,100,1,10.930000,200,2,16.300000,700,1,10.920000,200,2,16.380000,200,2,ARL,43313633
2025-07-17T13:30:00.869941215Z,2025-07-17T13:30:00.869768981Z,10,2,1108,A,B,-1,9.41,100,130,172234,28963699,11.760000,100,1,15.300000,100,1,11.520000,100,1,15.610000,100,1,11.290000,100,1,15.910000,100,1,11.140000,700,1,16.100000,100,1,11.070000,700,1,16.110000,700,1,11.050000,100,1,16.150000,700,1,11.010000,100,1,16.200000,200,2,10.990000,700,1,16.220000,100,1,10.930000,200,2,16.300000,700,1,10.920000,200,2,16.380000,200,2,ARL,43313681
2025-07-17T13:30:00.870056916Z,2025-07-17T13:30:00.869883482Z,10,2,1108,A,B,3,11.24,100,128,173434,28963823,11.760000,100,1,15.300000,100,1,11.520000,100,1,15.610000,100,1,11.290000,100,1,15.910000,100,1,11.240000,100,1,16.100000,100,1,11.140000,700,1,16.110000,700,1,11.070000,700,1,16.150000,700,1,11.050000,100,1,16.200000,200,2,11.010000,100,1,16.220000,100,1,10.990000,700,1,16.300000,700,1,10.930000,200,2,16.380000,200,2,ARL,43313941
2025-07-17T13:30:00.870086307Z,2025-07-17T13:30:00.869917271Z,10,2,1108,A,A,3,15.98,100,130,169036,28963843,11.760000,100,1,15.300000,100,1,11.520000,100,1,15.610000,100,1,11.290000,100,1,15.910000,100,1,11.240000,100,1,15.980000,100,1,11.140000,700,1,16.100000,100,1,11.070000,700,1,16.110000,700,1,11.050000,100,1,16.150000,700,1,11.010000,100,1,16.200000,200,2,10.990000,700,1,16.220000,100,1,10.930000,200,2,16.300000,700,1,ARL,43314009
2025-07-17T13:30:00.870161301Z,2025-07-17T13:30:00.869979897Z,10,2,1108,C,B,17,8.47,100,0,181404,28963935,11.760000,100,1,15.300000,100,1,11.520000,100,1,15.610000,100,1,11.290000,100,1,15.910000,100,1,11.240000,100,1,15.980000,100,1,11.140000,700,1,16.100000,100,1,11.070000,700,1,16.110000,700,1,11.050000,100,1,16.150000,700,1,11.010000,100,1,16.200000,200,2,10.990000,700,1,16.220000,100,1,10.930000,200,2,16.300000,700,1,ARL,41376333
2025-07-17T13:30:00.870161301Z,2025-07-17T13:30:00.869979897Z,10,2,1108,A,B,-1,9.55,100,0,181404,28963935,11.760000,100,1,15.300000,100,1,11.520000,100,1,15.610000,100,1,11.290000,100,1,15.910000,100,1,11.240000,100,1,15.980000,100,1,11.140000,700,1,16.100000,100,1,11.070000,700,1,16.110000,700,1,11.050000,100,1,16.150000,700,1,11.010000,100,1,16.200000,200,2,10.990000,700,1,16.220000,100,1,10.930000,200,2,16.300000,700,1,ARL,43314145
2025-07-17T13:30:00.870161301Z,2025-07-17T13:30:00.869983764Z,10,2,1108,C,B,18,8.47,100,0,177537,28963938,11.760000,100,1,15.300000,100,1,11.520000,100,1,15.610000,100,1,11.290000,100,1,15.910000,100,1,11.240000,100,1,15.980000,100,1,11.140000,700,1,16.100000,100,1,11.070000,700,1,16.110000,700,1,11.050000,100,1,16.150000,700,1,11.010000,100,1,16.200000,200,2,10.990000,700,1,16.220000,100,1,10.930000,200,2,16.300000,700,1,ARL,41376337
2025-07-17T13:30:00.870161301Z,2025-07-17T13:30:00.869983764Z,10,2,1108,A,B,-1,9.55,100,128,177537,28963938,11.760000,100,1,15.300000,100,1,11.520000,100,1,15.610000,100,1,11.290000,100,1,15.910000,100,1,11.240000,100,1,15.980000,100,1,11.140000,700,1,16.100000,100,1,11.070000,700,1,16.110000,700,1,11.050000,100,1,16.150000,700,1,11.010000,100,1,16.200000,200,2,10.990000,700,1,16.220000,100,1,10.930000,200,2,16.300000,700,1,ARL,43314149
2025-07-17T13:30:00.870165319Z,2025-07-17T13:30:00.869988740Z,10,2,1108,C,B,18,8.47,100,0,176579,28963943,11.760000,100,1,15.300000,100,1,11.520000,100,1,15.610000,100,1,11.290000,100,1,15.910000,100,1,11.240000,100,1,15.980000,100,1,11.140000,700,1,16.100000,100,1,11.070000,700,1,16.110000,700,1,11.050000,100,1,16.150000,700,1,11.010000,100,1,16.200000,200,2,10.990000,700,1,16.220000,100,1,10.930000,200,2,16.300000,700,1,ARL,41376341
2025-07-17T13:30:00.870165319Z,2025-07-17T13:30:00.869988740Z,10,2,1108,A,B,-1,9.55,100,0,176579,28963943,11.760000,100,1,15.300000,100,1,11.520000,100,1,15.610000,100,1,11.290000,100,1,15.910000,100,1,11.240000,100,1,15.980000,100,1,11.140000,700,1,16.100000,100,1,11.070000,700,1,16.110000,700,1,11.050000,100,1,16.150000,700,1,11.010000,100,1,16.200000,200,2,10.990000,700,1,16.220000,100,1,10.930000,200,2,16.300000,700,1,ARL,43314153
2025-07-17T13:30:00.870165319Z,2025-07-17T13:30:00.869989204Z,10,2,1108,C,B,18,8.47,100,0,176115,28963944,11.760000,100,1,15.300000,100,1,11.520000,100,1,15.610000,100,1,11.290000,100,1,15.910000,100,1,11.240000,100,1,15.980000,100,1,11.140000,700,1,16.100000,100,1,11.070000,700,1,16.110000,700,1,11.050000,100,1,16.150000,700,1,11.010000,100,1,16.200000,200,2,10.990000,700,1,16.220000,100,1,10.930000,200,2,16.300000,700,1,ARL,41376345
2025-07-17T13:30:00.870165319Z,2025-07-17T13:30:00.869989204Z,10,2,1108,A,B,-1,9.55,100,128,176115,28963944,11.760000,100,1,15.300000,100,1,11.520000,100,1,15.610000,100,1,11.290000,100,1,15.910000,100,1,11.240000,100,1,15.980000,100,1,11.140000,700,1,16.100000,100,1,11.070000,700,1,16.110000,700,1,11.050000,100,1,16.150000,700,1,11.010000,100,1,16.200000,200,2,10.990000,700,1,16.220000,100,1,10.930000,200,2,16.300000,700,1,ARL,43314157
2025-07-17T13:30:00.870174640Z,2025-07-17T13:30:00.869996105Z,10,2,1108,C,B,18,8.47,100,0,178535,28963952,11.760000,100,1,15.300000,100,1,11.520000,100,1,15.610000,100,1,11.290000,100,1,15.910000,100,1,11.240000,100,1,15.980000,100,1,11.140000,700,1,16.100000,100,1,11.070000,700,1,16.110000,700,1,11.050000,100,1,16.150000,700,1,11.010000,100,1,16.200000,200,2,10.990000,700,1,16.220000,100,1,10.930000,200,2,16.300000,700,1,ARL,41376349
2025-07-17T13:30:00.870174640Z,2025-07-17T13:30:00.869996105Z,10,2,1108,A,B,-1,9.55,100,0,178535,28963952,11.760000,100,1,15.300000,100,1,11.520000,100,1,15.610000,100,1,11.290000,100,1,15.910000,100,1,11.240000,100,1,15.980000,100,1,11.140000,700,1,16.100000,100,1,11.070000,700,1,16.110000,700,1,11.050000,100,1,16.150000,700,1,11.010000,100,1,16.200000,200,2,10.990000,700,1,16.220000,100,1,10.930000,200,2,16.300000,700,1,ARL,43314161
2025-07-17T13:30:00.870174640Z,2025-07-17T13:30:00.869996504Z,10,2,1108,C,B,18,8.47,100,0,178136,28963953,11.760000,100,1,15.300000,100,1,11.520000,100,1,15.610000,100,1,11.290000,100,1,15.910000,100,1,11.240000,100,1,15.980000,100,1,11.140000,700,1,16.100000,100,1,11.070000,700,1,16.110000,700,1,11.050000,100,1,16.150000,700,1,11.010000,100,1,16.200000,200,2,10.990000,700,1,16.220000,100,1,10.930000,200,2,16.300000,700,1,ARL,41376353
2025-07-17T13:30:00.870174640Z,2025-07-17T13:30:00.869996504Z,10,2,1108,A,B,-1,9.55,100,0,178136,28963953,11.760000,100,1,15.300000,100,1,11.520000,100,1,15.610000,100,1,11.290000,100,1,15.910000,100,1,11.240000,100,1,15.980000,100,1,11.140000,700,1,16.100000,100,1,11.070000,700,1,16.110000,700,1,11.050000,100,1,16.150000,700,1,11.010000,100,1,16.200000,200,2,10.990000,700,1,16.220000,100,1,10.930000,200,2,16.300000,700,1,ARL,43314165
2025-07-17T13:30:00.870174640Z,2025-07-17T13:30:00.869997057Z,10,2,1108,C,B,18,8.47,100,0,177583,28963954,11.760000,100,1,15.300000,100,1,11.520000,100,1,15.610000,100,1,11.290000,100,1,15.910000,100,1,11.240000,100,1,15.980000,100,1,11.140000,700,1,16.100000,100,1,11.070000,700,1,16.110000,700,1,11.050000,100,1,16.150000,700,1,11.010000,100,1,16.200000,200,2,10.990000,700,1,16.220000,100,1,10.930000,200,2,16.300000,700,1,ARL,41376357
2025-07-17T13:30:00.870174640Z,2025-07-17T13:30:00.869997057Z,10,2,1108,A,B,-1,9.55,100,128,177583,28963954,11.760000,100,1,15.300000,100,1,11.520000,100,1,15.610000,100,1,11.290000,100,1,15.910000,100,1,11.240000,100,1,15.980000,100,1,11.140000,700,1,16.100000,100,1,11.070000,700,1,16.110000,700,1,11.050000,100,1,16.150000,700,1,11.010000,100,1,16.200000,200,2,10.990000,700,1,16.220000,100,1,10.930000,200,2,16.300000,700,1,ARL,43314169
2025-07-17T13:30:00.870179751Z,2025-07-17T13:30:00.870003387Z,10,2,1108,C,B,18,8.47,100,0,176364,28963962,11.760000,100,1,15.300000,100,1,11.520000,100,1,15.610000,100,1,11.290000,100,1,15.910000,100,1,11.240000,100,1,15.980000,100,1,11.140000,700,1,16.100000,100,1,11.070000,700,1,16.110000,700,1,11.050000,100,1,16.150000,700,1,11.010000,100,1,16.200000,200,2,10.990000,700,1,16.220000,100,1,10.930000,200,2,16.300000,700,1,ARL,42202297
2025-07-17T13:30:00.870179751Z,2025-07-17T13:30:00.870003387Z,10,2,1108,A,B,-1,9.55,100,0,176364,28963962,11.760000,100,1,15.300000,100,1,11.520000,100,1,15.610000,100,1,11.290000,100,1,15.910000,100,1,11.240000,100,1,15.980000,100,1,11.140000,700,1,16.100000,100,1,11.070000,700,1,16.110000,700,1,11.050000,100,1,16.150000,700,1,11.010000,100,1,16.200000,200,2,10.990000,700,1,16.220000,100,1,10.930000,200,2,16.300000,700,1,ARL,43314173
2025-07-17T13:30:00.870179751Z,2025-07-17T13:30:00.870004158Z,10,2,1108,C,B,18,8.47,100,0,175593,28963963,11.760000,100,1,15.300000,100,1,11.520000,100,1,15.610000,100,1,11.290000,100,1,15.910000,100,1,11.240000,100,1,15.980000,100,1,11.140000,700,1,16.100000,100,1,11.070000,700,1,16.110000,700,1,11.050000,100,1,16.150000,700,1,11.010000,100,1,16.200000,200,2,10.990000,700,1,16.220000,100,1,10.930000,200,2,16.300000,700,1,ARL,42951397
2025-07-17T13:30:00.870179751Z,2025-07-17T13:30:00.870004158Z,10,2,1108,A,B,-1,9.55,100,128,175593,28963963,11.760000,100,1,15.300000,100,1,11.520000,100,1,15.610000,100,1,11.290000,100,1,15.910000,100,1,11.240000,100,1,15.980000,100,1,11.140000,700,1,16.100000,100,1,11.070000,700,1,16.110000,700,1,11.050000,100,1,16.150000,700,1,11.010000,100,1,16.200000,200,2,10.990000,700,1,16.220000,100,1,10.930000,200,2,16.300000,700,1,ARL,43314177
2025-07-17T13:30:00.870186428Z,2025-07-17T13:30:00.870009922Z,10,2,1108,C,A,17,19.58,100,0,176506,28963970,11.760000,100,1,15.300000,100,1,11.520000,100,1,15.610000,100,1,11.290000,100,1,15.910000,100,1,11.240000,100,1,15.980000,100,1,11.140000,700,1,16.100000,100,1,11.070000,700,1,16.110000,700,1,11.050000,100,1,16.150000,700,1,11.010000,100,1,16.200000,200,2,10.990000,700,1,16.220000,100,1,10.930000,200,2,16.300000,700,1,ARL,41370945
2025-07-17T13:30:00.870186428Z,2025-07-17T13:30:00.870009922Z,10,2,1108,A,A,-1,18.38,100,0,176506,28963970,11.760000,100,1,15.300000,100,1,11.520000,100,1,15.610000,100,1,11.290000,100,1,15.910000,100,1,11.240000,100,1,15.980000,100,1,11.140000,700,1,16.100000,100,1,11.070000,700,1,16.110000,700,1,11.050000,100,1,16.150000,700,1,11.010000,100,1,16.200000,200,2,10.990000,700,1,16.220000,100,1,10.930000,200,2,16.300000,700,1,ARL,43314181
2025-07-17T13:30:00.870186428Z,2025-07-17T13:30:00.870010386Z,10,2,1108,C,A,18,19.58,100,0,176042,28963971,11.760000,100,1,15.300000,100,1,11.520000,100,1,15.610000,100,1,11.290000,100,1,15.910000,100,1,11.240000,100,1,15.980000,100,1,11.140000,700,1,16.100000,100,1,11.070000,700,1,16.110000,700,1,11.050000,100,1,16.150000,700,1,11.010000,100,1,16.200000,200,2,10.990000,700,1,16.220000,100,1,10.930000,200,2,16.300000,700,1,ARL,41370949
2025-07-17T13:30:00.870186428Z,2025-07-17T13:30:00.870010386Z,10,2,1108,A,A,-1,18.38,100,128,176042,28963971,11.760000,100,1,15.300000,100,1,11.520000,100,1,15.610000,100,1,11.290000,100,1,15.910000,100,1,11.240000,100,1,15.980000,100,1,11.140000,700,1,16.100000,100,1,11.070000,700,1,16.110000,700,1,11.050000,100,1,16.150000,700,1,11.010000,100,1,16.200000,200,2,10.990000,700,1,16.220000,100,1,10.930000,200,2,16.300000,700,1,ARL,43314185
2025-07-17T13:30:00.870194394Z,2025-07-17T13:30:00.870017071Z,10,2,1108,C,A,18,19.58,100,0,177323,28963981,11.760000,100,1,15.300000,100,1,11.520000,100,1,15.610000,100,1,11.290000,100,1,15.910000,100,1,11.240000,100,1,15.980000,100,1,11.140000,700,1,16.100000,100,1,11.070000,700,1,16.110000,700,1,11.050000,100,1,16.150000,700,1,11.010000,100,1,16.200000,200,2,10.990000,700,1,16.220000,100,1,10.930000,200,2,16.300000,700,1,ARL,41370953
2025-07-17T13:30:00.870194394Z,2025-07-17T13:30:00.870017071Z,10,2,1108,A,A,-1,18.38,100,0,177323,28963981,11.760000,100,1,15.300000,100,1,11.520000,100,1,15.610000,100,1,11.290000,100,1,15.910000,100,1,11.240000,100,1,15.980000,100,1,11.140000,700,1,16.100000,100,1,11.070000,700,1,16.110000,700,1,11.050000,100,1,16.150000,700,1,11.010000,100,1,16.200000,200,2,10.990000,700,1,16.220000,100,1,10.930000,200,2,16.300000,700,1,ARL,43314189
2025-07-17T13:30:00.870194394Z,2025-07-17T13:30:00.870022776Z,10,2,1108,C,A,18,19.58,100,0,171618,28963983,11.760000,100,1,15.300000,100,1,11.520000,100,1,15.610000,100,1,11.290000,100,1,15.910000,100,1,11.240000,100,1,15.980000,100,1,11.140000,700,1,16.100000,100,1,11.070000,700,1,16.110000,700,1,11.050000,100,1,16.150000,700,1,11.010000,100,1,16.200000,200,2,10.990000,700,1,16.220000,100,1,10.930000,200,2,16.300000,700,1,ARL,41370957
2025-07-17T13:30:00.870194394Z,2025-07-17T13:30:00.870022776Z,10,2,1108,A,A,-1,18.38,100,0,171618,28963983,11.760000,100,1,15.300000,100,1,11.520000,100,1,15.610000,100,1,11.290000,100,1,15.910000,100,1,11.240000,100,1,15.980000,100,1,11.140000,700,1,16.100000,100,1,11.070000,700,1,16.110000,700,1,11.050000,100,1,16.150000,700,1,11.010000,100,1,16.200000,200,2,10.990000,700,1,16.220000,100,1,10.930000,200,2,16.300000,700,1,ARL,43314233
2025-07-17T13:30:00.870194394Z,2025-07-17T13:30:00.870023199Z,10,2,1108,C,A,18,19.58,100,0,171195,28963984,11.760000,100,1,15.300000,100,1,11.520000,100,1,15.610000,100,1,11.290000,100,1,15.910000,100,1,11.240000,100,1,15.980000,100,1,11.140000,700,1,16.100000,100,1,11.070000,700,1,16.110000,700,1,11.050000,100,1,16.150000,700,1,11.010000,100,1,16.200000,200,2,10.990000,700,1,16.220000,100,1,10.930000,200,2,16.300000,700,1,ARL,41370961
2025-07-17T13:30:00.870194394Z,2025-07-17T13:30:00.870023199Z,10,2,1108,A,A,-1,18.38,100,0,171195,28963984,11.760000,100,1,15.300000,100,1,11.520000,100,1,15.610000,100,1,11.290000,100,1,15.910000,100,1,11.240000,100,1,15.980000,100,1,11.140000,700,1,16.100000,100,1,11.070000,700,1,16.110000,700,1,11.050000,100,1,16.150000,700,1,11.010000,100,1,16.200000,200,2,10.990000,700,1,16.220000,100,1,10.930000,200,2,16.300000,700,1,ARL,43314237
2025-07-17T13:30:00.870194394Z,2025-07-17T13:30:00.870023701Z,10,2,1108,C,A,18,19.58,100,0,170693,28963985,11.760000,100,1,15.300000,100,1,11.520000,100,1,15.610000,100,1,11.290000,100,1,15.910000,100,1,11.240000,100,1,15.980000,100,1,11.140000,700,1,16.100000,100,1,11.070000,700,1,16.110000,700,1,11.050000,100,1,16.150000,700,1,11.010000,100,1,16.200000,200,2,10.990000,700,1,16.220000,100,1,10.930000,200,2,16.300000,700,1,ARL,41370965
2025-07-17T13:30:00.870194394Z,2025-07-17T13:30:00.870023701Z,10,2,1108,A,A,-1,18.38,100,130,170693,28963985,11.760000,100,1,15.300000,100,1,11.520000,100,1,15.610000,100,1,11.290000,100,1,15.910000,100,1,11.240000,100,1,15.980000,100,1,11.140000,700,1,16.100000,100,1,11.070000,700,1,16.110000,700,1,11.050000,100,1,16.150000,700,1,11.010000,100,1,16.200000,200,2,10.990000,700,1,16.220000,100,1,10.930000,200,2,16.300000,700,1,ARL,43314241
2025-07-17T13:30:00.870229401Z,2025-07-17T13:30:00.870053023Z,10,2,1108,C,A,18,19.58,100,0,176378,28964015,11.760000,100,1,15.300000,100,1,11.520000,100,1,15.610000,100,1,11.290000,100,1,15.910000,100,1,11.240000,100,1,15.980000,100,1,11.140000,700,1,16.100000,100,1,11.070000,700,1,16.110000,700,1,11.050000,100,1,16.150000,700,1,11.010000,100,1,16.200000,200,2,10.990000,700,1,16.220000,100,1,10.930000,200,2,16.300000,700,1,ARL,41370969
2025-07-17T13:30:00.870229401Z,2025-07-17T13:30:00.870053023Z,10,2,1108,A,A,-1,18.38,100,0,176378,28964015,11.760000,100,1,15.300000,100,1,11.520000,100,1,15.610000,100,1,11.290000,100,1,15.910000,100,1,11.240000,100,1,15.980000,100,1,11.140000,700,1,16.100000,100,1,11.070000,700,1,16.110000,700,1,11.050000,100,1,16.150000,700,1,11.010000,100,1,16.200000,200,2,10.990000,700,1,16.220000,100,1,10.930000,200,2,16.300000,700,1,ARL,43314245
2025-07-17T13:30:00.870229401Z,2025-07-17T13:30:00.870053791Z,10,2,1108,C,A,18,19.58,100,0,175610,28964016,11.760000,100,1,15.300000,100,1,11.520000,100,1,15.610000,100,1,11.290000,100,1,15.910000,100,1,11.240000,100,1,15.980000,100,1,11.140000,700,1,16.100000,100,1,11.070000,700,1,16.110000,700,1,11.050000,100,1,16.150000,700,1,11.010000,100,1,16.200000,200,2,10.990000,700,1,16.220000,100,1,10.930000,200,2,16.300000,700,1,ARL,42204681
2025-07-17T13:30:00.870229401Z,2025-07-17T13:30:00.870053791Z,10,2,1108,A,A,-1,18.38,100,0,175610,28964016,11.760000,100,1,15.300000,100,1,11.520000,100,1,15.610000,100,1,11.290000,100,1,15.910000,100,1,11.240000,100,1,15.980000,100,1,11.140000,700,1,16.100000,100,1,11.070000,700,1,16.110000,700,1,11.050000,100,1,16.150000,700,1,11.010000,100,1,16.200000,200,2,10.990000,700,1,16.220000,100,1,10.930000,200,2,16.300000,700,1,ARL,43314253
2025-07-17T13:30:00.870229401Z,2025-07-17T13:30:00.870054073Z,10,2,1108,C,A,18,19.58,100,0,175328,28964017,11.760000,100,1,15.300000,100,1,11.520000,100,1,15.610000,100,1,11.290000,100,1,15.910000,100,1,11.240000,100,1,15.980000,100,1,11.140000,700,1,16.100000,100,1,11.070000,700,1,16.110000,700,1,11.050000,100,1,16.150000,700,1,11.010000,100,1,16.200000,200,2,10.990000,700,1,16.220000,100,1,10.930000,200,2,16.300000,700,1,ARL,42946053
2025-07-17T13:30:00.870229401Z,2025-07-17T13:30:00.870054073Z,10,2,1108,A,A,-1,18.38,100,128,175328,28964017,11.760000,100,1,15.300000,100,1,11.520000,100,1,15.610000,100,1,11.290000,100,1,15.910000,100,1,11.240000,100,1,15.980000,100,1,11.140000,700,1,16.100000,100,1,11.070000,700,1,16.110000,700,1,11.050000,100,1,16.150000,700,1,11.010000,100,1,16.200000,200,2,10.990000,700,1,16.220000,100,1,10.930000,200,2,16.300000,700,1,ARL,43314257
2025-07-17T13:30:00.870236146Z,2025-07-17T13:30:00.870063003Z,10,2,1108,C,A,15,18.36,100,0,173143,28964020,11.760000,100,1,15.300000,100,1,11.520000,100,1,15.610000,100,1,11.290000,100,1,15.910000,100,1,11.240000,100,1,15.980000,100,1,11.140000,700,1,16.100000,100,1,11.070000,700,1,16.110000,700,1,11.050000,100,1,16.150000,700,1,11.010000,100,1,16.200000,200,2,10.990000,700,1,16.220000,100,1,10.930000,200,2,16.300000,700,1,ARL,43313633
2025-07-17T13:30:00.870236146Z,2025-07-17T13:30:00.870063920Z,10,2,1108,C,B,16,9.41,100,128,172226,28964021,11.760000,100,1,15.300000,100,1,11.520000,100,1,15.610000,100,1,11.290000,100,1,15.910000,100,1,11.240000,100,1,15.980000,100,1,11.140000,700,1,16.100000,100,1,11.070000,700,1,16.110000,700,1,11.050000,100,1,16.150000,700,1,11.010000,100,1,16.200000,200,2,10.990000,700,1,16.220000,100,1,10.930000,200,2,16.300000,700,1,ARL,43313681
2025-07-17T13:30:00.870319397Z,2025-07-17T13:30:00.870151543Z,10,2,1108,A,B,-1,10.61,100,128,167854,28964128,11.760000,100,1,15.300000,100,1,11.520000,100,1,15.610000,100,1,11.290000,100,1,15.910000,100,1,11.240000,100,1,15.980000,100,1,11.140000,700,1,16.100000,100,1,11.070000,700,1,16.110000,700,1,11.050000,100,1,16.150000,700,1,11.010000,100,1,16.200000,200,2,10.990000,700,1,16.220000,100,1,10.930000,200,2,16.300000,700,1,ARL,43314465
2025-07-17T13:30:00.870390228Z,2025-07-17T13:30:00.870209113Z,10,2,1108,A,A,-1,17.23,100,128,181115,28964207,11.760000,100,1,15.300000,100,1,11.520000,100,1,15.610000,100,1,11.290000,100,1,15.910000,100,1,11.240000,100,1,15.980000,100,1,11.140000,700,1,16.100000,100,1,11.070000,700,1,16.110000,700,1,11.050000,100,1,16.150000,700,1,11.010000,100,1,16.200000,200,2,10.990000,700,1,16.220000,100,1,10.930000,200,2,16.300000,700,1,ARL,43314561
2025-07-17T13:30:00.870452050Z,2025-07-17T13:30:00.870273955Z,10,2,1108,C,B,3,11.24,100,0,178095,28964259,11.760000,100,1,15.300000,100,1,11.520000,100,1,15.610000,100,1,11.290000,100,1,15.910000,100,1,11.140000,700,1,15.980000,100,1,11.070000,700,1,16.100000,100,1,11.050000,100,1,16.110000,700,1,11.010000,100,1,16.150000,700,1,10.990000,700,1,16.200000,200,2,10.930000,200,2,16.220000,100,1,10.920000,200,2,16.300000,700,1,ARL,43313941
2025-07-17T13:30:00.870452050Z,2025-07-17T13:30:00.870278857Z,10,2,1108,C,A,3,15.98,100,128,173193,28964260,11.760000,100,1,15.300000,100,1,11.520000,100,1,15.610000,100,1,11.290000,100,1,15.910000,100,1,11.140000,700,1,16.100000,100,1,11.070000,700,1,16.110000,700,1,11.050000,100,1,16.150000,700,1,11.010000,100,1,16.200000,200,2,10.990000,700,1,16.220000,100,1,10.930000,200,2,16.300000,700,1,10.920000,200,2,16.380000,200,2,ARL,43314009
2025-07-17T13:30:00.870748921Z,2025-07-17T13:30:00.870579856Z,10,2,1108,C,B,16,9.41,100,0,169065,28964629,11.760000,100,1,15.300000,100,1,11.520000,100,1,15.610000,100,1,11.290000,100,1,15.910000,100,1,11.140000,700,1,16.100000,100,1,11.070000,700,1,16.110000,700,1,11.050000,100,1,16.150000,700,1,11.010000,100,1,16.200000,200,2,10.990000,700,1,16.220000,100,1,10.930000,200,2,16.300000,700,1,10.920000,200,2,16.380000,200,2,ARL,43313553
2025-07-17T13:30:00.870748921Z,2025-07-17T13:30:00.870580243Z,10,2,1108,C,A,15,18.36,100,128,168678,28964630,11.760000,100,1,15.300000,100,1,11.520000,100,1,15.610000,100,1,11.290000,100,1,15.910000,100,1,11.140000,700,1,16.100000,100,1,11.070000,700,1,16.110000,700,1,11.050000,100,1,16.150000,700,1,11.010000,100,1,16.200000,200,2,10.990000,700,1,16.220000,100,1,10.930000,200,2,16.300000,700,1,10.920000,200,2,16.380000,200,2,ARL,43313565
2025-07-17T13:30:00.871024910Z,2025-07-17T13:30:00.870848973Z,10,2,1108,A,B,2,11.40,100,128,175937,28964903,11.760000,100,1,15.300000,100,1,11.520000,100,1,15.610000,100,1,11.400000,100,1,15.910000,100,1,11.290000,100,1,16.100000,100,1,11.140000,700,1,16.110000,700,1,11.070000,700,1,16.150000,700,1,11.050000,100,1,16.200000,200,2,11.010000,100,1,16.220000,100,1,10.990000,700,1,16.300000,700,1,10.930000,200,2,16.380000,200,2,ARL,43315905
2025-07-17T13:30:00.871047347Z,2025-07-17T13:30:00.870874152Z,10,2,1108,C,B,14,10.11,100,128,173195,28964931,11.760000,100,1,15.300000,100,1,11.520000,100,1,15.610000,100,1,11.400000,100,1,15.910000,100,1,11.290000,100,1,16.100000,100,1,11.140000,700,1,16.110000,700,1,11.070000,700,1,16.150000,700,1,11.050000,100,1,16.200000,200,2,11.010000,100,1,16.220000,100,1,10.990000,700,1,16.300000,700,1,10.930000,200,2,16.380000,200,2,ARL,42583289
2025-07-17T13:30:00.871535485Z,2025-07-17T13:30:00.871359085Z,10,2,1108,A,A,9,16.38,100,128,176400,28965402,11.760000,100,1,15.300000,100,1,11.520000,100,1,15.610000,100,1,11.400000,100,1,15.910000,100,1,11.290000,100,1,16.100000,100,1,11.140000,700,1,16.110000,700,1,11.070000,700,1,16.150000,700,1,11.050000,100,1,16.200000,200,2,11.010000,100,1,16.220000,100,1,10.990000,700,1,16.300000,700,1,10.930000,200,2,16.380000,300,3,ARL,43317137
2025-07-17T13:30:00.871544335Z,2025-07-17T13:30:00.871371794Z,10,2,1108,A,B,-1,10.61,100,128,172541,28965409,11.760000,100,1,15.300000,100,1,11.520000,100,1,15.610000,100,1,11.400000,100,1,15.910000,100,1,11.290000,100,1,16.100000,100,1,11.140000,700,1,16.110000,700,1,11.070000,700,1,16.150000,700,1,11.050000,100,1,16.200000,200,2,11.010000,100,1,16.220000,100,1,10.990000,700,1,16.300000,700,1,10.930000,200,2,16.380000,300,3,ARL,43317177
2025-07-17T13:30:00.871552017Z,2025-07-17T13:30:00.871379595Z,10,2,1108,A,A,-1,17.23,100,0,172422,28965416,11.760000,100,1,15.300000,100,1,11.520000,100,1,15.610000,100,1,11.400000,100,1,15.910000,100,1,11.290000,100,1,16.100000,100,1,11.140000,700,1,16.110000,700,1,11.070000,700,1,16.150000,700,1,11.050000,100,1,16.200000,200,2,11.010000,100,1,16.220000,100,1,10.990000,700,1,16.300000,700,1,10.930000,200,2,16.380000,300,3,ARL,43317185
2025-07-17T13:30:00.871552017Z,2025-07-17T13:30:00.871381021Z,10,2,1108,C,A,13,17.45,100,128,170996,28965418,11.760000,100,1,15.300000,100,1,11.520000,100,1,15.610000,100,1,11.400000,100,1,15.910000,100,1,11.290000,100,1,16.100000,100,1,11.140000,700,1,16.110000,700,1,11.070000,700,1,16.150000,700,1,11.050000,100,1,16.200000,200,2,11.010000,100,1,16.220000,100,1,10.990000,700,1,16.300000,700,1,10.930000,200,2,16.380000,300,3,ARL,42583293
2025-07-17T13:30:00.871701004Z,2025-07-17T13:30:00.871520352Z,10,2,1108,C,B,11,10.84,100,0,180652,28965571,11.760000,100,1,15.300000,100,1,11.520000,100,1,15.610000,100,1,11.400000,100,1,15.910000,100,1,11.290000,100,1,16.100000,100,1,11.140000,700,1,16.110000,700,1,11.070000,700,1,16.150000,700,1,11.050000,100,1,16.200000,200,2,11.010000,100,1,16.220000,100,1,10.990000,700,1,16.300000,700,1,10.930000,200,2,16.380000,300,3,ARL,41635065
2025-07-17T13:30:00.871701004Z,2025-07-17T13:30:00.871520352Z,10,2,1108,A,B,0,12.23,100,128,180652,28965571,12.230000,100,1,15.300000,100,1,11.760000,100,1,15.610000,100,1,11.520000,100,1,15.910000,100,1,11.400000,100,1,16.100000,100,1,11.290000,100,1,16.110000,700,1,11.140000,700,1,16.150000,700,1,11.070000,700,1,16.200000,200,2,11.050000,100,1,16.220000,100,1,11.010000,100,1,16.300000,700,1,10.990000,700,1,16.380000,300,3,ARL,43317473
2025-07-17T13:30:00.871723283Z,2025-07-17T13:30:00.871548318Z,10,2,1108,C,A,10,16.49,100,0,174965,28965592,12.230000,100,1,15.300000,100,1,11.760000,100,1,15.610000,100,1,11.520000,100,1,15.910000,100,1,11.400000,100,1,16.100000,100,1,11.290000,100,1,16.110000,700,1,11.140000,700,1,16.150000,700,1,11.070000,700,1,16.200000,200,2,11.050000,100,1,16.220000,100,1,11.010000,100,1,16.300000,700,1,10.990000,700,1,16.380000,300,3,ARL,41635069
2025-07-17T13:30:00.871723283Z,2025-07-17T13:30:00.871548318Z,10,2,1108,A,A,1,15.47,100,128,174965,28965592,12.230000,100,1,15.300000,100,1,11.760000,100,1,15.470000,100,1,11.520000,100,1,15.610000,100,1,11.400000,100,1,15.910000,100,1,11.290000,100,1,16.100000,100,1,11.140000,700,1,16.110000,700,1,11.070000,700,1,16.150000,700,1,11.050000,100,1,16.200000,200,2,11.010000,100,1,16.220000,100,1,10.990000,700,1,16.300000,700,1,ARL,43317561
2025-07-17T13:30:00.911711427Z,2025-07-17T13:30:00.911486897Z,10,2,1108,A,B,2,11.69,2,128,224530,28973032,12.230000,100,1,15.300000,100,1,11.760000,100,1,15.470000,100,1,11.690000,2,1,15.610000,100,1,11.520000,100,1,15.910000,100,1,11.400000,100,1,16.100000,100,1,11.290000,100,1,16.110000,700,1,11.140000,700,1,16.150000,700,1,11.070000,700,1,16.200000,200,2,11.050000,100,1,16.220000,100,1,11.010000,100,1,16.300000,700,1,ARL,43324133
2025-07-17T13:30:00.914528735Z,2025-07-17T13:30:00.914351054Z,10,2,1108,A,A,1,15.31,2,128,177681,28975648,12.230000,100,1,15.300000,100,1,11.760000,100,1,15.310000,2,1,11.690000,2,1,15.470000,100,1,11.520000,100,1,15.610000,100,1,11.400000,100,1,15.910000,100,1,11.290000,100,1,16.100000,100,1,11.140000,700,1,16.110000,700,1,11.070000,700,1,16.150000,700,1,11.050000,100,1,16.200000,200,2,11.010000,100,1,16.220000,100,1,ARL,43328313
2025-07-17T13:30:00.915372008Z,2025-07-17T13:30:00.915197739Z,10,2,1108,C,B,14,10.58,100,0,174269,28976307,12.230000,100,1,15.300000,100,1,11.760000,100,1,15.310000,2,1,11.690000,2,1,15.470000,100,1,11.520000,100,1,15.610000,100,1,11.400000,100,1,15.910000,100,1,11.290000,100,1,16.100000,100,1,11.140000,700,1,16.110000,700,1,11.070000,700,1,16.150000,700,1,11.050000,100,1,16.200000,200,2,11.010000,100,1,16.220000,100,1,ARL,41376725
2025-07-17T13:30:00.915372008Z,2025-07-17T13:30:00.915197739Z,10,2,1108,A,B,1,11.93,100,130,174269,28976307,12.230000,100,1,15.300000,100,1,11.930000,100,1,15.310000,2,1,11.760000,100,1,15.470000,100,1,11.690000,2,1,15.610000,100,1,11.520000,100,1,15.910000,100,1,11.400000,100,1,16.100000,100,1,11.290000,100,1,16.110000,700,1,11.140000,700,1,16.150000,700,1,11.070000,700,1,16.200000,200,2,11.050000,100,1,16.220000,100,1,ARL,43329953
2025-07-17T13:30:00.916507980Z,2025-07-17T13:30:00.916332252Z,10,2,1108,C,A,12,16.83,100,0,175728,28977103,12.230000,100,1,15.300000,100,1,11.930000,100,1,15.310000,2,1,11.760000,100,1,15.470000,100,1,11.690000,2,1,15.610000,100,1,11.520000,100,1,15.910000,100,1,11.400000,100,1,16.100000,100,1,11.290000,100,1,16.110000,700,1,11.140000,700,1,16.150000,700,1,11.070000,700,1,16.200000,200,2,11.050000,100,1,16.220000,100,1,ARL,41372125
2025-07-17T13:30:00.916507980Z,2025-07-17T13:30:00.916332252Z,10,2,1108,A,A,4,15.80,100,128,175728,28977103,12.230000,100,1,15.300000,100,1,11.930000,100,1,15.310000,2,1,11.760000,100,1,15.470000,100,1,11.690000,2,1,15.610000,100,1,11.520000,100,1,15.800000,100,1,11.400000,100,1,15.910000,100,1,11.290000,100,1,16.100000,100,1,11.140000,700,1,16.110000,700,1,11.070000,700,1,16.150000,700,1,11.050000,100,1,16.200000,200,2,ARL,43331877
2025-07-17T13:30:00.920319545Z,2025-07-17T13:30:00.920144110Z,10,2,1108,C,A,16,18.38,100,0,175435,28979475,12.230000,100,1,15.300000,100,1,11.930000,100,1,15.310000,2,1,11.760000,100,1,15.470000,100,1,11.690000,2,1,15.610000,100,1,11.520000,100,1,15.800000,100,1,11.400000,100,1,15.910000,100,1,11.290000,100,1,16.100000,100,1,11.140000,700,1,16.110000,700,1,11.070000,700,1,16.150000,700,1,11.050000,100,1,16.200000,200,2,ARL,43314181
2025-07-17T13:30:00.920319545Z,2025-07-17T13:30:00.920144110Z,10,2,1108,A,A,-1,17.15,100,0,175435,28979475,12.230000,100,1,15.300000,100,1,11.930000,100,1,15.310000,2,1,11.760000,100,1,15.470000,100,1,11.690000,2,1,15.610000,100,1,11.520000,100,1,15.800000,100,1,11.400000,100,1,15.910000,100,1,11.290000,100,1,16.100000,100,1,11.140000,700,1,16.110000,700,1,11.070000,700,1,16.150000,700,1,11.050000,100,1,16.200000,200,2,ARL,43339133
2025-07-17T13:30:00.920319545Z,2025-07-17T13:30:00.920147410Z,10,2,1108,C,A,17,18.38,100,0,172135,28979478,12.230000,100,1,15.300000,100,1,11.930000,100,1,15.310000,2,1,11.760000,100,1,15.470000,100,1,11.690000,2,1,15.610000,100,1,11.520000,100,1,15.800000,100,1,11.400000,100,1,15.910000,100,1,11.290000,100,1,16.100000,100,1,11.140000,700,1,16.110000,700,1,11.070000,700,1,16.150000,700,1,11.050000,100,1,16.200000,200,2,ARL,43314185
2025-07-17T13:30:00.920319545Z,2025-07-17T13:30:00.920147410Z,10,2,1108,A,A,-1,17.15,100,130,172135,28979478,12.230000,100,1,15.300000,100,1,11.930000,100,1,15.310000,2,1,11.760000,100,1,15.470000,100,1,11.690000,2,1,15.610000,100,1,11.520000,100,1,15.800000,100,1,11.400000,100,1,15.910000,100,1,11.290000,100,1,16.100000,100,1,11.140000,700,1,16.110000,700,1,11.070000,700,1,16.150000,700,1,11.050000,100,1,16.200000,200,2,ARL,43339165
2025-07-17T13:30:00.920380241Z,2025-07-17T13:30:00.920208398Z,10,2,1108,C,A,17,18.38,100,0,171843,28979515,12.230000,100,1,15.300000,100,1,11.930000,100,1,15.310000,2,1,11.760000,100,1,15.470000,100,1,11.690000,2,1,15.610000,100,1,11.520000,100,1,15.800000,100,1,11.400000,100,1,15.910000,100,1,11.290000,100,1,16.100000,100,1,11.140000,700,1,16.110000,700,1,11.070000,700,1,16.150000,700,1,11.050000,100,1,16.200000,200,2,ARL,43314189
2025-07-17T13:30:00.920380241Z,2025-07-17T13:30:00.920208398Z,10,2,1108,A,A,-1,17.15,100,0,171843,28979515,12.230000,100,1,15.300000,100,1,11.930000,100,1,15.310000,2,1,11.760000,100,1,15.470000,100,1,11.690000,2,1,15.610000,100,1,11.520000,100,1,15.800000,100,1,11.400000,100,1,15.910000,100,1,11.290000,100,1,16.100000,100,1,11.140000,700,1,16.110000,700,1,11.070000,700,1,16.150000,700,1,11.050000,100,1,16.200000,200,2,ARL,43339333
2025-07-17T13:30:00.920380241Z,2025-07-17T13:30:00.920208920Z,10,2,1108,C,A,17,18.38,100,0,171321,28979516,12.230000,100,1,15.300000,100,1,11.930000,100,1,15.310000,2,1,11.760000,100,1,15.470000,100,1,11.690000,2,1,15.610000,100,1,11.520000,100,1,15.800000,100,1,11.400000,100,1,15.910000,100,1,11.290000,100,1,16.100000,100,1,11.140000,700,1,16.110000,700,1,11.070000,700,1,16.150000,700,1,11.050000,100,1,16.200000,200,2,ARL,43314233
2025-07-17T13:30:00.920380241Z,2025-07-17T13:30:00.920208920Z,10,2,1108,A,A,-1,17.15,100,130,171321,28979516,12.230000,100,1,15.300000,100,1,11.930000,100,1,15.310000,2,1,11.760000,100,1,15.470000,100,1,11.690000,2,1,15.610000,100,1,11.520000,100,1,15.800000,100,1,11.400000,100,1,15.910000,100,1,11.290000,100,1,16.100000,100,1,11.140000,700,1,16.110000,700,1,11.070000,700,1,16.150000,700,1,11.050000,100,1,16.200000,200,2,ARL,43339337
2025-07-17T13:30:00.920390005Z,2025-07-17T13:30:00.920209286Z,10,2,1108,C,A,17,18.38,100,0,180719,28979517,12.230000,100,1,15.300000,100,1,11.930000,100,1,15.310000,2,1,11.760000,100,1,15.470000,100,1,11.690000,2,1,15.610000,100,1,11.520000,100,1,15.800000,100,1,11.400000,100,1,15.910000,100,1,11.290000,100,1,16.100000,100,1,11.140000,700,1,16.110000,700,1,11.070000,700,1,16.150000,700,1,11.050000,100,1,16.200000,200,2,ARL,43314237
2025-07-17T13:30:00.920390005Z,2025-07-17T13:30:00.920209286Z,10,2,1108,A,A,-1,17.15,100,0,180719,28979517,12.230000,100,1,15.300000,100,1,11.930000,100,1,15.310000,2,1,11.760000,100,1,15.470000,100,1,11.690000,2,1,15.610000,100,1,11.520000,100,1,15.800000,100,1,11.400000,100,1,15.910000,100,1,11.290000,100,1,16.100000,100,1,11.140000,700,1,16.110000,700,1,11.070000,700,1,16.150000,700,1,11.050000,100,1,16.200000,200,2,ARL,43339341
2025-07-17T13:30:00.920390005Z,2025-07-17T13:30:00.920216613Z,10,2,1108,C,A,17,18.38,100,0,173392,28979521,12.230000,100,1,15.300000,100,1,11.930000,100,1,15.310000,2,1,11.760000,100,1,15.470000,100,1,11.690000,2,1,15.610000,100,1,11.520000,100,1,15.800000,100,1,11.400000,100,1,15.910000,100,1,11.290000,100,1,16.100000,100,1,11.140000,700,1,16.110000,700,1,11.070000,700,1,16.150000,700,1,11.050000,100,1,16.200000,200,2,ARL,43314241
2025-07-17T13:30:00.920390005Z,2025-07-17T13:30:00.920216613Z,10,2,1108,A,A,-1,17.15,100,0,173392,28979521,12.230000,100,1,15.300000,100,1,11.930000,100,1,15.310000,2,1,11.760000,100,1,15.470000,100,1,11.690000,2,1,15.610000,100,1,11.520000,100,1,15.800000,100,1,11.400000,100,1,15.910000,100,1,11.290000,100,1,16.100000,100,1,11.140000,700,1,16.110000,700,1,11.070000,700,1,16.150000,700,1,11.050000,100,1,16.200000,200,2,ARL,43339377
2025-07-17T13:30:00.920390005Z,2025-07-17T13:30:00.920217193Z,10,2,1108,C,A,17,18.38,100,0,172812,28979522,12.230000,100,1,15.300000,100,1,11.930000,100,1,15.310000,2,1,11.760000,100,1,15.470000,100,1,11.690000,2,1,15.610000,100,1,11.520000,100,1,15.800000,100,1,11.400000,100,1,15.910000,100,1,11.290000,100,1,16.100000,100,1,11.140000,700,1,16.110000,700,1,11.070000,700,1,16.150000,700,1,11.050000,100,1,16.200000,200,2,ARL,43314245
2025-07-17T13:30:00.920390005Z,2025-07-17T13:30:00.920217193Z,10,2,1108,A,A,-1,17.15,100,0,172812,28979522,12.230000,100,1,15.300000,100,1,11.930000,100,1,15.310000,2,1,11.760000,100,1,15.470000,100,1,11.690000,2,1,15.610000,100,1,11.520000,100,1,15.800000,100,1,11.400000,100,1,15.910000,100,1,11.290000,100,1,16.100000,100,1,11.140000,700,1,16.110000,700,1,11.070000,700,1,16.150000,700,1,11.050000,100,1,16.200000,200,2,ARL,43339381
2025-07-17T13:30:00.920390005Z,2025-07-17T13:30:00.920217632Z,10,2,1108,C,A,17,18.38,100,0,172373,28979523,12.230000,100,1,15.300000,100,1,11.930000,100,1,15.310000,2,1,11.760000,100,1,15.470000,100,1,11.690000,2,1,15.610000,100,1,11.520000,100,1,15.800000,100,1,11.400000,100,1,15.910000,100,1,11.290000,100,1,16.100000,100,1,11.140000,700,1,16.110000,700,1,11.070000,700,1,16.150000,700,1,11.050000,100,1,16.200000,200,2,ARL,43314253
2025-07-17T13:30:00.920390005Z,2025-07-17T13:30:00.920217632Z,10,2,1108,A,A,-1,17.15,100,130,172373,28979523,12.230000,100,1,15.300000,100,1,11.930000,100,1,15.310000,2,1,11.760000,100,1,15.470000,100,1,11.690000,2,1,15.610000,100,1,11.520000,100,1,15.800000,100,1,11.400000,100,1,15.910000,100,1,11.290000,100,1,16.100000,100,1,11.140000,700,1,16.110000,700,1,11.070000,700,1,16.150000,700,1,11.050000,100,1,16.200000,200,2,ARL,43339385
2025-07-17T13:30:00.920530105Z,2025-07-17T13:30:00.920351772Z,10,2,1108,C,A,17,18.38,100,0,178333,28979649,12.230000,100,1,15.300000,100,1,11.930000,100,1,15.310000,2,1,11.760000,100,1,15.470000,100,1,11.690000,2,1,15.610000,100,1,11.520000,100,1,15.800000,100,1,11.400000,100,1,15.910000,100,1,11.290000,100,1,16.100000,100,1,11.140000,700,1,16.110000,700,1,11.070000,700,1,16.150000,700,1,11.050000,100,1,16.200000,200,2,ARL,43314257
2025-07-17T13:30:00.920530105Z,2025-07-17T13:30:00.920351772Z,10,2,1108,A,A,-1,17.15,100,128,178333,28979649,12.230000,100,1,15.300000,100,1,11.930000,100,1,15.310000,2,1,11.760000,100,1,15.470000,100,1,11.690000,2,1,15.610000,100,1,11.520000,100,1,15.800000,100,1,11.400000,100,1,15.910000,100,1,11.290000,100,1,16.100000,100,1,11.140000,700,1,16.110000,700,1,11.070000,700,1,16.150000,700,1,11.050000,100,1,16.200000,200,2,ARL,43339565
2025-07-17T13:30:00.931605690Z,2025-07-17T13:30:00.931432717Z,10,2,1108,C,A,4,15.80,100,0,172973,28991138,12.230000,100,1,15.300000,100,1,11.930000,100,1,15.310000,2,1,11.760000,100,1,15.470000,100,1,11.690000,2,1,15.610000,100,1,11.520000,100,1,15.910000,100,1,11.400000,100,1,16.100000,100,1,11.290000,100,1,16.110000,700,1,11.140000,700,1,16.150000,700,1,11.070000,700,1,16.200000,200,2,11.050000,100,1,16.220000,100,1,ARL,43331877
2025-07-17T13:30:00.931605690Z,2025-07-17T13:30:00.931432717Z,10,2,1108,A,A,0,14.74,100,128,172973,28991138,12.230000,100,1,14.740000,100,1,11.930000,100,1,15.300000,100,1,11.760000,100,1,15.310000,2,1,11.690000,2,1,15.470000,100,1,11.520000,100,1,15.610000,100,1,11.400000,100,1,15.910000,100,1,11.290000,100,1,16.100000,100,1,11.140000,700,1,16.110000,700,1,11.070000,700,1,16.150000,700,1,11.050000,100,1,16.200000,200,2,ARL,43357029
2025-07-17T13:30:00.941082601Z,2025-07-17T13:30:00.940916945Z,10,2,1108,C,A,3,15.47,100,0,165656,29000554,12.230000,100,1,14.740000,100,1,11.930000,100,1,15.300000,100,1,11.760000,100,1,15.310000,2,1,11.690000,2,1,15.610000,100,1,11.520000,100,1,15.910000,100,1,11.400000,100,1,16.100000,100,1,11.290000,100,1,16.110000,700,1,11.140000,700,1,16.150000,700,1,11.070000,700,1,16.200000,200,2,11.050000,100,1,16.220000,100,1,ARL,43317561
2025-07-17T13:30:00.941082601Z,2025-07-17T13:30:00.940916945Z,10,2,1108,A,A,0,14.44,100,130,165656,29000554,12.230000,100,1,14.440000,100,1,11.930000,100,1,14.740000,100,1,11.760000,100,1,15.300000,100,1,11.690000,2,1,15.310000,2,1,11.520000,100,1,15.610000,100,1,11.400000,100,1,15.910000,100,1,11.290000,100,1,16.100000,100,1,11.140000,700,1,16.110000,700,1,11.070000,700,1,16.150000,700,1,11.050000,100,1,16.200000,200,2,ARL,43373009
2025-07-17T13:30:00.941236862Z,2025-07-17T13:30:00.941071231Z,10,2,1108,A,A,2,15.28,100,130,165631,29000677,12.230000,100,1,14.440000,100,1,11.930000,100,1,14.740000,100,1,11.760000,100,1,15.280000,100,1,11.690000,2,1,15.300000,100,1,11.520000,100,1,15.310000,2,1,11.400000,100,1,15.610000,100,1,11.290000,100,1,15.910000,100,1,11.140000,700,1,16.100000,100,1,11.070000,700,1,16.110000,700,1,11.050000,100,1,16.150000,700,1,ARL,43373085
2025-07-17T13:30:00.941255157Z,2025-07-17T13:30:00.941085073Z,10,2,1108,C,A,13,16.38,100,128,170084,29000688,12.230000,100,1,14.440000,100,1,11.930000,100,1,14.740000,100,1,11.760000,100,1,15.280000,100,1,11.690000,2,1,15.300000,100,1,11.520000,100,1,15.310000,2,1,11.400000,100,1,15.610000,100,1,11.290000,100,1,15.910000,100,1,11.140000,700,1,16.100000,100,1,11.070000,700,1,16.110000,700,1,11.050000,100,1,16.150000,700,1,ARL,43317137
2025-07-17T13:30:01.086605950Z,2025-07-17T13:30:01.086438727Z,10,2,1108,C,B,10,11.01,100,0,167223,29116818,12.230000,100,1,14.440000,100,1,11.930000,100,1,14.740000,100,1,11.760000,100,1,15.280000,100,1,11.690000,2,1,15.300000,100,1,11.520000,100,1,15.310000,2,1,11.400000,100,1,15.610000,100,1,11.290000,100,1,15.910000,100,1,11.140000,700,1,16.100000,100,1,11.070000,700,1,16.110000,700,1,11.050000,100,1,16.150000,700,1,ARL,42674817
2025-07-17T13:30:01.086605950Z,2025-07-17T13:30:01.086438727Z,10,2,1108,A,B,0,12.47,100,130,167223,29116818,12.470000,100,1,14.440000,100,1,12.230000,100,1,14.740000,100,1,11.930000,100,1,15.280000,100,1,11.760000,100,1,15.300000,100,1,11.690000,2,1,15.310000,2,1,11.520000,100,1,15.610000,100,1,11.400000,100,1,15.910000,100,1,11.290000,100,1,16.100000,100,1,11.140000,700,1,16.110000,700,1,11.070000,700,1,16.150000,700,1,ARL,43554133
2025-07-17T13:30:01.086625226Z,2025-07-17T13:30:01.086456460Z,10,2,1108,C,A,7,16.10,100,0,168766,29116862,12.470000,100,1,14.440000,100,1,12.230000,100,1,14.740000,100,1,11.930000,100,1,15.280000,100,1,11.760000,100,1,15.300000,100,1,11.690000,2,1,15.310000,2,1,11.520000,100,1,15.610000,100,1,11.400000,100,1,15.910000,100,1,11.290000,100,1,16.110000,700,1,11.140000,700,1,16.150000,700,1,11.070000,700,1,16.200000,200,2,ARL,42674989
2025-07-17T13:30:01.086625226Z,2025-07-17T13:30:01.086456460Z,10,2,1108,A,A,0,14.20,100,128,168766,29116862,12.470000,100,1,14.200000,100,1,12.230000,100,1,14.440000,100,1,11.930000,100,1,14.740000,100,1,11.760000,100,1,15.280000,100,1,11.690000,2,1,15.300000,100,1,11.520000,100,1,15.310000,2,1,11.400000,100,1,15.610000,100,1,11.290000,100,1,15.910000,100,1,11.140000,700,1,16.110000,700,1,11.070000,700,1,16.150000,700,1,ARL,43554141
2025-07-17T13:30:01.214882922Z,2025-07-17T13:30:01.214703183Z,10,2,1108,A,B,0,12.67,100,0,179739,29196804,12.670000,100,1,14.200000,100,1,12.470000,100,1,14.440000,100,1,12.230000,100,1,14.740000,100,1,11.930000,100,1,15.280000,100,1,11.760000,100,1,15.300000,100,1,11.690000,2,1,15.310000,2,1,11.520000,100,1,15.610000,100,1,11.400000,100,1,15.910000,100,1,11.290000,100,1,16.110000,700,1,11.140000,700,1,16.150000,700,1,ARL,43663229
2025-07-17T13:30:01.214882922Z,2025-07-17T13:30:01.214704496Z,10,2,1108,A,A,0,14.00,100,128,178426,29196805,12.670000,100,1,14.000000,100,1,12.470000,100,1,14.200000,100,1,12.230000,100,1,14.440000,100,1,11.930000,100,1,14.740000,100,1,11.760000,100,1,15.280000,100,1,11.690000,2,1,15.300000,100,1,11.520000,100,1,15.310000,2,1,11.400000,100,1,15.610000,100,1,11.290000,100,1,15.910000,100,1,11.140000,700,1,16.110000,700,1,ARL,43663233
2025-07-17T13:30:01.252386379Z,2025-07-17T13:30:01.252206360Z,10,2,1108,A,B,-1,7.74,100,0,180019,29221770,12.670000,100,1,14.000000,100,1,12.470000,100,1,14.200000,100,1,12.230000,100,1,14.440000,100,1,11.930000,100,1,14.740000,100,1,11.760000,100,1,15.280000,100,1,11.690000,2,1,15.300000,100,1,11.520000,100,1,15.310000,2,1,11.400000,100,1,15.610000,100,1,11.290000,100,1,15.910000,100,1,11.140000,700,1,16.110000,700,1,ARL,27015957
2025-07-17T13:30:01.252386379Z,2025-07-17T13:30:01.252206360Z,10,2,1108,A,A,-1,20.48,100,0,180019,29221771,12.670000,100,1,14.000000,100,1,12.470000,100,1,14.200000,100,1,12.230000,100,1,14.440000,100,1,11.930000,100,1,14.740000,100,1,11.760000,100,1,15.280000,100,1,11.690000,2,1,15.300000,100,1,11.520000,100,1,15.310000,2,1,11.400000,100,1,15.610000,100,1,11.290000,100,1,15.910000,100,1,11.140000,700,1,16.110000,700,1,ARL,27015965
2025-07-17T13:30:01.252386379Z,2025-07-17T13:30:01.252206360Z,10,2,1108,A,B,-1,7.74,100,0,180019,29221772,12.670000,100,1,14.000000,100,1,12.470000,100,1,14.200000,100,1,12.230000,100,1,14.440000,100,1,11.930000,100,1,14.740000,100,1,11.760000,100,1,15.280000,100,1,11.690000,2,1,15.300000,100,1,11.520000,100,1,15.310000,2,1,11.400000,100,1,15.610000,100,1,11.290000,100,1,15.910000,100,1,11.140000,700,1,16.110000,700,1,ARL,38084501
2025-07-17T13:30:01.252386379Z,2025-07-17T13:30:01.252206360Z,10,2,1108,A,A,-1,20.48,100,0,180019,29221773,12.670000,100,1,14.000000,100,1,12.470000,100,1,14.200000,100,1,12.230000,100,1,14.440000,100,1,11.930000,100,1,14.740000,100,1,11.760000,100,1,15.280000,100,1,11.690000,2,1,15.300000,100,1,11.520000,100,1,15.310000,2,1,11.400000,100,1,15.610000,100,1,11.290000,100,1,15.910000,100,1,11.140000,700,1,16.110000,700,1,ARL,38073517
2025-07-17T13:30:01.252386379Z,2025-07-17T13:30:01.252206360Z,10,2,1108,A,B,-1,7.74,100,0,180019,29221774,12.670000,100,1,14.000000,100,1,12.470000,100,1,14.200000,100,1,12.230000,100,1,14.440000,100,1,11.930000,100,1,14.740000,100,1,11.760000,100,1,15.280000,100,1,11.690000,2,1,15.300000,100,1,11.520000,100,1,15.310000,2,1,11.400000,100,1,15.610000,100,1,11.290000,100,1,15.910000,100,1,11.140000,700,1,16.110000,700,1,ARL,38130589
2025-07-17T13:30:01.252386379Z,2025-07-17T13:30:01.252206360Z,10,2,1108,A,A,-1,20.48,100,0,180019,29221775,12.670000,100,1,14.000000,100,1,12.470000,100,1,14.200000,100,1,12.230000,100,1,14.440000,100,1,11.930000,100,1,14.740000,100,1,11.760000,100,1,15.280000,100,1,11.690000,2,1,15.300000,100,1,11.520000,100,1,15.310000,2,1,11.400000,100,1,15.610000,100,1,11.290000,100,1,15.910000,100,1,11.140000,700,1,16.110000,700,1,ARL,38134973
2025-07-17T13:30:01.252386379Z,2025-07-17T13:30:01.252206360Z,10,2,1108,A,B,-1,7.74,100,0,180019,29221776,12.670000,100,1,14.000000,100,1,12.470000,100,1,14.200000,100,1,12.230000,100,1,14.440000,100,1,11.930000,100,1,14.740000,100,1,11.760000,100,1,15.280000,100,1,11.690000,2,1,15.300000,100,1,11.520000,100,1,15.310000,2,1,11.400000,100,1,15.610000,100,1,11.290000,100,1,15.910000,100,1,11.140000,700,1,16.110000,700,1,ARL,38470185
2025-07-17T13:30:01.252386379Z,2025-07-17T13:30:01.252206360Z,10,2,1108,A,A,-1,20.48,100,0,180019,29221777,12.670000,100,1,14.000000,100,1,12.470000,100,1,14.200000,100,1,12.230000,100,1,14.440000,100,1,11.930000,100,1,14.740000,100,1,11.760000,100,1,15.280000,100,1,11.690000,2,1,15.300000,100,1,11.520000,100,1,15.310000,2,1,11.400000,100,1,15.610000,100,1,11.290000,100,1,15.910000,100,1,11.140000,700,1,16.110000,700,1,ARL,38471493
2025-07-17T13:30:01.252386379Z,2025-07-17T13:30:01.252206360Z,10,2,1108,A,B,-1,7.74,100,0,180019,29221778,12.670000,100,1,14.000000,100,1,12.470000,100,1,14.200000,100,1,12.230000,100,1,14.440000,100,1,11.930000,100,1,14.740000,100,1,11.760000,100,1,15.280000,100,1,11.690000,2,1,15.300000,100,1,11.520000,100,1,15.310000,2,1,11.400000,100,1,15.610000,100,1,11.290000,100,1,15.910000,100,1,11.140000,700,1,16.110000,700,1,ARL,38759997
2025-07-17T13:30:01.252386379Z,2025-07-17T13:30:01.252206360Z,10,2,1108,A,A,-1,20.48,100,0,180019,29221779,12.670000,100,1,14.000000,100,1,12.470000,100,1,14.200000,100,1,12.230000,100,1,14.440000,100,1,11.930000,100,1,14.740000,100,1,11.760000,100,1,15.280000,100,1,11.690000,2,1,15.300000,100,1,11.520000,100,1,15.310000,2,1,11.400000,100,1,15.610000,100,1,11.290000,100,1,15.910000,100,1,11.140000,700,1,16.110000,700,1,ARL,38758965
2025-07-17T13:30:01.252386379Z,2025-07-17T13:30:01.252206360Z,10,2,1108,A,B,-1,7.74,100,0,180019,29221780,12.670000,100,1,14.000000,100,1,12.470000,100,1,14.200000,100,1,12.230000,100,1,14.440000,100,1,11.930000,100,1,14.740000,100,1,11.760000,100,1,15.280000,100,1,11.690000,2,1,15.300000,100,1,11.520000,100,1,15.310000,2,1,11.400000,100,1,15.610000,100,1,11.290000,100,1,15.910000,100,1,11.140000,700,1,16.110000,700,1,ARL,38775373
2025-07-17T13:30:01.252386379Z,2025-07-17T13:30:01.252206360Z,10,2,1108,A,A,-1,20.48,100,0,180019,29221781,12.670000,100,1,14.000000,100,1,12.470000,100,1,14.200000,100,1,12.230000,100,1,14.440000,100,1,11.930000,100,1,14.740000,100,1,11.760000,100,1,15.280000,100,1,11.690000,2,1,15.300000,100,1,11.520000,100,1,15.310000,2,1,11.400000,100,1,15.610000,100,1,11.290000,100,1,15.910000,100,1,11.140000,700,1,16.110000,700,1,ARL,38776877
2025-07-17T13:30:01.252386379Z,2025-07-17T13:30:01.252206360Z,10,2,1108,A,B,-1,7.74,100,0,180019,29221782,12.670000,100,1,14.000000,100,1,12.470000,100,1,14.200000,100,1,12.230000,100,1,14.440000,100,1,11.930000,100,1,14.740000,100,1,11.760000,100,1,15.280000,100,1,11.690000,2,1,15.300000,100,1,11.520000,100,1,15.310000,2,1,11.400000,100,1,15.610000,100,1,11.290000,100,1,15.910000,100,1,11.140000,700,1,16.110000,700,1,ARL,38865193
2025-07-17T13:30:01.252386379Z,2025-07-17T13:30:01.252206360Z,10,2,1108,A,A,-1,20.48,100,128,180019,29221783,12.670000,100,1,14.000000,100,1,12.470000,100,1,14.200000,100,1,12.230000,100,1,14.440000,100,1,11.930000,100,1,14.740000,100,1,11.760000,100,1,15.280000,100,1,11.690000,2,1,15.300000,100,1,11.520000,100,1,15.310000,2,1,11.400000,100,1,15.610000,100,1,11.290000,100,1,15.910000,100,1,11.140000,700,1,16.110000,700,1,ARL,38863877
2025-07-17T13:30:01.252444419Z,2025-07-17T13:30:01.252269158Z,10,2,1108,C,B,20,7.74,100,0,175261,29221828,12.670000,100,1,14.000000,100,1,12.470000,100,1,14.200000,100,1,12.230000,100,1,14.440000,100,1,11.930000,100,1,14.740000,100,1,11.760000,100,1,15.280000,100,1,11.690000,2,1,15.300000,100,1,11.520000,100,1,15.310000,2,1,11.400000,100,1,15.610000,100,1,11.290000,100,1,15.910000,100,1,11.140000,700,1,16.110000,700,1,ARL,27015957
2025-07-17T13:30:01.252444419Z,2025-07-17T13:30:01.252269158Z,10,2,1108,A,B,-1,9.55,100,0,175261,29221828,12.670000,100,1,14.000000,100,1,12.470000,100,1,14.200000,100,1,12.230000,100,1,14.440000,100,1,11.930000,100,1,14.740000,100,1,11.760000,100,1,15.280000,100,1,11.690000,2,1,15.300000,100,1,11.520000,100,1,15.310000,2,1,11.400000,100,1,15.610000,100,1,11.290000,100,1,15.910000,100,1,11.140000,700,1,16.110000,700,1,ARL,43690797
2025-07-17T13:30:01.252444419Z,2025-07-17T13:30:01.252269575Z,10,2,1108,C,B,20,7.74,100,0,174844,29221829,12.670000,100,1,14.000000,100,1,12.470000,100,1,14.200000,100,1,12.230000,100,1,14.440000,100,1,11.930000,100,1,14.740000,100,1,11.760000,100,1,15.280000,100,1,11.690000,2,1,15.300000,100,1,11.520000,100,1,15.310000,2,1,11.400000,100,1,15.610000,100,1,11.290000,100,1,15.910000,100,1,11.140000,700,1,16.110000,700,1,ARL,38084501
2025-07-17T13:30:01.252444419Z,2025-07-17T13:30:01.252269575Z,10,2,1108,A,B,-1,9.55,100,0,174844,29221829,12.670000,100,1,14.000000,100,1,12.470000,100,1,14.200000,100,1,12.230000,100,1,14.440000,100,1,11.930000,100,1,14.740000,100,1,11.760000,100,1,15.280000,100,1,11.690000,2,1,15.300000,100,1,11.520000,100,1,15.310000,2,1,11.400000,100,1,15.610000,100,1,11.290000,100,1,15.910000,100,1,11.140000,700,1,16.110000,700,1,ARL,43690801
2025-07-17T13:30:01.252444419Z,2025-07-17T13:30:01.252269960Z,10,2,1108,C,B,20,7.74,100,0,174459,29221830,12.670000,100,1,14.000000,100,1,12.470000,100,1,14.200000,100,1,12.230000,100,1,14.440000,100,1,11.930000,100,1,14.740000,100,1,11.760000,100,1,15.280000,100,1,11.690000,2,1,15.300000,100,1,11.520000,100,1,15.310000,2,1,11.400000,100,1,15.610000,100,1,11.290000,100,1,15.910000,100,1,11.140000,700,1,16.110000,700,1,ARL,38130589
2025-07-17T13:30:01.252444419Z,2025-07-17T13:30:01.252269960Z,10,2,1108,A,B,-1,9.55,100,0,174459,29221830,12.670000,100,1,14.000000,100,1,12.470000,100,1,14.200000,100,1,12.230000,100,1,14.440000,100,1,11.930000,100,1,14.740000,100,1,11.760000,100,1,15.280000,100,1,11.690000,2,1,15.300000,100,1,11.520000,100,1,15.310000,2,1,11.400000,100,1,15.610000,100,1,11.290000,100,1,15.910000,100,1,11.140000,700,1,16.110000,700,1,ARL,43690805
2025-07-17T13:30:01.252444419Z,2025-07-17T13:30:01.252270596Z,10,2,1108,C,B,20,7.74,100,0,173823,29221831,12.670000,100,1,14.000000,100,1,12.470000,100,1,14.200000,100,1,12.230000,100,1,14.440000,100,1,11.930000,100,1,14.740000,100,1,11.760000,100,1,15.280000,100,1,11.690000,2,1,15.300000,100,1,11.520000,100,1,15.310000,2,1,11.400000,100,1,15.610000,100,1,11.290000,100,1,15.910000,100,1,11.140000,700,1,16.110000,700,1,ARL,38470185
2025-07-17T13:30:01.252444419Z,2025-07-17T13:30:01.252270596Z,10,2,1108,A,B,-1,9.55,100,0,173823,29221831,12.670000,100,1,14.000000,100,1,12.470000,100,1,14.200000,100,1,12.230000,100,1,14.440000,100,1,11.930000,100,1,14.740000,100,1,11.760000,100,1,15.280000,100,1,11.690000,2,1,15.300000,100,1,11.520000,100,1,15.310000,2,1,11.400000,100,1,15.610000,100,1,11.290000,100,1,15.910000,100,1,11.140000,700,1,16.110000,700,1,ARL,43690809
2025-07-17T13:30:01.252444419Z,2025-07-17T13:30:01.252270987Z,10,2,1108,C,B,20,7.74,100,0,173432,29221832,12.670000,100,1,14.000000,100,1,12.470000,100,1,14.200000,100,1,12.230000,100,1,14.440000,100,1,11.930000,100,1,14.740000,100,1,11.760000,100,1,15.280000,100,1,11.690000,2,1,15.300000,100,1,11.520000,100,1,15.310000,2,1,11.400000,100,1,15.610000,100,1,11.290000,100,1,15.910000,100,1,11.140000,700,1,16.110000,700,1,ARL,38759997
2025-07-17T13:30:01.252444419Z,2025-07-17T13:30:01.252270987Z,10,2,1108,A,B,-1,9.55,100,0,173432,29221832,12.670000,100,1,14.000000,100,1,12.470000,100,1,14.200000,100,1,12.230000,100,1,14.440000,100,1,11.930000,100,1,14.740000,100,1,11.760000,100,1,15.280000,100,1,11.690000,2,1,15.300000,100,1,11.520000,100,1,15.310000,2,1,11.400000,100,1,15.610000,100,1,11.290000,100,1,15.910000,100,1,11.140000,700,1,16.110000,700,1,ARL,43690813
2025-07-17T13:30:01.252444419Z,2025-07-17T13:30:01.252271274Z,10,2,1108,C,B,20,7.74,100,0,173145,29221833,12.670000,100,1,14.000000,100,1,12.470000,100,1,14.200000,100,1,12.230000,100,1,14.440000,100,1,11.930000,100,1,14.740000,100,1,11.760000,100,1,15.280000,100,1,11.690000,2,1,15.300000,100,1,11.520000,100,1,15.310000,2,1,11.400000,100,1,15.610000,100,1,11.290000,100,1,15.910000,100,1,11.140000,700,1,16.110000,700,1,ARL,38775373
2025-07-17T13:30:01.252444419Z,2025-07-17T13:30:01.252271274Z,10,2,1108,A,B,-1,9.55,100,0,173145,29221833,12.670000,100,1,14.000000,100,1,12.470000,100,1,14.200000,100,1,12.230000,100,1,14.440000,100,1,11.930000,100,1,14.740000,100,1,11.760000,100,1,15.280000,100,1,11.690000,2,1,15.300000,100,1,11.520000,100,1,15.310000,2,1,11.400000,100,1,15.610000,100,1,11.290000,100,1,15.910000,100,1,11.140000,700,1,16.110000,700,1,ARL,43690817
2025-07-17T13:30:01.252444419Z,2025-07-17T13:30:01.252272011Z,10,2,1108,C,B,20,7.74,100,0,172408,29221834,12.670000,100,1,14.000000,100,1,12.470000,100,1,14.200000,100,1,12.230000,100,1,14.440000,100,1,11.930000,100,1,14.740000,100,1,11.760000,100,1,15.280000,100,1,11.690000,2,1,15.300000,100,1,11.520000,100,1,15.310000,2,1,11.400000,100,1,15.610000,100,1,11.290000,100,1,15.910000,100,1,11.140000,700,1,16.110000,700,1,ARL,38865193
2025-07-17T13:30:01.252444419Z,2025-07-17T13:30:01.252272011Z,10,2,1108,A,B,-1,9.55,100,128,172408,29221834,12.670000,100,1,14.000000,100,1,12.470000,100,1,14.200000,100,1,12.230000,100,1,14.440000,100,1,11.930000,100,1,14.740000,100,1,11.760000,100,1,15.280000,100,1,11.690000,2,1,15.300000,100,1,11.520000,100,1,15.310000,2,1,11.400000,100,1,15.610000,100,1,11.290000,100,1,15.910000,100,1,11.140000,700,1,16.110000,700,1,ARL,43690821
2025-07-17T13:30:01.252457898Z,2025-07-17T13:30:01.252279681Z,10,2,1108,C,A,20,20.48,100,0,178217,29221840,12.670000,100,1,14.000000,100,1,12.470000,100,1,14.200000,100,1,12.230000,100,1,14.440000,100,1,11.930000,100,1,14.740000,100,1,11.760000,100,1,15.280000,100,1,11.690000,2,1,15.300000,100,1,11.520000,100,1,15.310000,2,1,11.400000,100,1,15.610000,100,1,11.290000,100,1,15.910000,100,1,11.140000,700,1,16.110000,700,1,ARL,27015965
2025-07-17T13:30:01.252457898Z,2025-07-17T13:30:01.252279681Z,10,2,1108,A,A,-1,17.15,100,0,178217,29221840,12.670000,100,1,14.000000,100,1,12.470000,100,1,14.200000,100,1,12.230000,100,1,14.440000,100,1,11.930000,100,1,14.740000,100,1,11.760000,100,1,15.280000,100,1,11.690000,2,1,15.300000,100,1,11.520000,100,1,15.310000,2,1,11.400000,100,1,15.610000,100,1,11.290000,100,1,15.910000,100,1,11.140000,700,1,16.110000,700,1,ARL,43690825
2025-07-17T13:30:01.252457898Z,2025-07-17T13:30:01.252280017Z,10,2,1108,C,A,20,20.48,100,0,177881,29221841,12.670000,100,1,14.000000,100,1,12.470000,100,1,14.200000,100,1,12.230000,100,1,14.440000,100,1,11.930000,100,1,14.740000,100,1,11.760000,100,1,15.280000,100,1,11.690000,2,1,15.300000,100,1,11.520000,100,1,15.310000,2,1,11.400000,100,1,15.610000,100,1,11.290000,100,1,15.910000,100,1,11.140000,700,1,16.110000,700,1,ARL,38073517
2025-07-17T13:30:01.252457898Z,2025-07-17T13:30:01.252280017Z,10,2,1108,A,A,-1,17.15,100,0,177881,29221841,12.670000,100,1,14.000000,100,1,12.470000,100,1,14.200000,100,1,12.230000,100,1,14.440000,100,1,11.930000,100,1,14.740000,100,1,11.760000,100,1,15.280000,100,1,11.690000,2,1,15.300000,100,1,11.520000,100,1,15.310000,2,1,11.400000,100,1,15.610000,100,1,11.290000,100,1,15.910000,100,1,11.140000,700,1,16.110000,700,1,ARL,43690829
2025-07-17T13:30:01.252457898Z,2025-07-17T13:30:01.252280383Z,10,2,1108,C,A,20,20.48,100,0,177515,29221842,12.670000,100,1,14.000000,100,1,12.470000,100,1,14.200000,100,1,12.230000,100,1,14.440000,100,1,11.930000,100,1,14.740000,100,1,11.760000,100,1,15.280000,100,1,11.690000,2,1,15.300000,100,1,11.520000,100,1,15.310000,2,1,11.400000,100,1,15.610000,100,1,11.290000,100,1,15.910000,100,1,11.140000,700,1,16.110000,700,1,ARL,38134973
2025-07-17T13:30:01.252457898Z,2025-07-17T13:30:01.252280383Z,10,2,1108,A,A,-1,17.15,100,0,177515,29221842,12.670000,100,1,14.000000,100,1,12.470000,100,1,14.200000,100,1,12.230000,100,1,14.440000,100,1,11.930000,100,1,14.740000,100,1,11.760000,100,1,15.280000,100,1,11.690000,2,1,15.300000,100,1,11.520000,100,1,15.310000,2,1,11.400000,100,1,15.610000,100,1,11.290000,100,1,15.910000,100,1,11.140000,700,1,16.110000,700,1,ARL,43690833
2025-07-17T13:30:01.252457898Z,2025-07-17T13:30:01.252280683Z,10,2,1108,C,A,20,20.48,100,0,177215,29221843,12.670000,100,1,14.000000,100,1,12.470000,100,1,14.200000,100,1,12.230000,100,1,14.440000,100,1,11.930000,100,1,14.740000,100,1,11.760000,100,1,15.280000,100,1,11.690000,2,1,15.300000,100,1,11.520000,100,1,15.310000,2,1,11.400000,100,1,15.610000,100,1,11.290000,100,1,15.910000,100,1,11.140000,700,1,16.110000,700,1,ARL,38471493
2025-07-17T13:30:01.252457898Z,2025-07-17T13:30:01.252280683Z,10,2,1108,A,A,-1,17.15,100,0,177215,29221843,12.670000,100,1,14.000000,100,1,12.470000,100,1,14.200000,100,1,12.230000,100,1,14.440000,100,1,11.930000,100,1,14.740000,100,1,11.760000,100,1,15.280000,100,1,11.690000,2,1,15.300000,100,1,11.520000,100,1,15.310000,2,1,11.400000,100,1,15.610000,100,1,11.290000,100,1,15.910000,100,1,11.140000,700,1,16.110000,700,1,ARL,43690837
2025-07-17T13:30:01.252457898Z,2025-07-17T13:30:01.252281079Z,10,2,1108,C,A,20,20.48,100,0,176819,29221844,12.670000,100,1,14.000000,100,1,12.470000,100,1,14.200000,100,1,12.230000,100,1,14.440000,100,1,11.930000,100,1,14.740000,100,1,11.760000,100,1,15.280000,100,1,11.690000,2,1,15.300000,100,1,11.520000,100,1,15.310000,2,1,11.400000,100,1,15.610000,100,1,11.290000,100,1,15.910000,100,1,11.140000,700,1,16.110000,700,1,ARL,38758965
2025-07-17T13:30:01.252457898Z,2025-07-17T13:30:01.252281079Z,10,2,1108,A,A,-1,17.15,100,0,176819,29221844,12.670000,100,1,14.000000,100,1,12.470000,100,1,14.200000,100,1,12.230000,100,1,14.440000,100,1,11.930000,100,1,14.740000,100,1,11.760000,100,1,15.280000,100,1,11.690000,2,1,15.300000,100,1,11.520000,100,1,15.310000,2,1,11.400000,100,1,15.610000,100,1,11.290000,100,1,15.910000,100,1,11.140000,700,1,16.110000,700,1,ARL,43690841
2025-07-17T13:30:01.252457898Z,2025-07-17T13:30:01.252281306Z,10,2,1108,C,A,20,20.48,100,0,176592,29221845,12.670000,100,1,14.000000,100,1,12.470000,100,1,14.200000,100,1,12.230000,100,1,14.440000,100,1,11.930000,100,1,14.740000,100,1,11.760000,100,1,15.280000,100,1,11.690000,2,1,15.300000,100,1,11.520000,100,1,15.310000,2,1,11.400000,100,1,15.610000,100,1,11.290000,100,1,15.910000,100,1,11.140000,700,1,16.110000,700,1,ARL,38776877
2025-07-17T13:30:01.252457898Z,2025-07-17T13:30:01.252281306Z,10,2,1108,A,A,-1,17.15,100,0,176592,29221845,12.670000,100,1,14.000000,100,1,12.470000,100,1,14.200000,100,1,12.230000,100,1,14.440000,100,1,11.930000,100,1,14.740000,100,1,11.760000,100,1,15.280000,100,1,11.690000,2,1,15.300000,100,1,11.520000,100,1,15.310000,2,1,11.400000,100,1,15.610000,100,1,11.290000,100,1,15.910000,100,1,11.140000,700,1,16.110000,700,1,ARL,43690845
2025-07-17T13:30:01.252457898Z,2025-07-17T13:30:01.252281648Z,10,2,1108,C,A,20,20.48,100,0,176250,29221846,12.670000,100,1,14.000000,100,1,12.470000,100,1,14.200000,100,1,12.230000,100,1,14.440000,100,1,11.930000,100,1,14.740000,100,1,11.760000,100,1,15.280000,100,1,11.690000,2,1,15.300000,100,1,11.520000,100,1,15.310000,2,1,11.400000,100,1,15.610000,100,1,11.290000,100,1,15.910000,100,1,11.140000,700,1,16.110000,700,1,ARL,38863877
2025-07-17T13:30:01.252457898Z,2025-07-17T13:30:01.252281648Z,10,2,1108,A,A,-1,17.15,100,130,176250,29221846,12.670000,100,1,14.000000,100,1,12.470000,100,1,14.200000,100,1,12.230000,100,1,14.440000,100,1,11.930000,100,1,14.740000,100,1,11.760000,100,1,15.280000,100,1,11.690000,2,1,15.300000,100,1,11.520000,100,1,15.310000,2,1,11.400000,100,1,15.610000,100,1,11.290000,100,1,15.910000,100,1,11.140000,700,1,16.110000,700,1,ARL,43690849
2025-07-17T13:30:01.255007539Z,2025-07-17T13:30:01.254829854Z,10,2,1108,C,B,5,11.69,2,0,177685,29223480,12.670000,100,1,14.000000,100,1,12.470000,100,1,14.200000,100,1,12.230000,100,1,14.440000,100,1,11.930000,100,1,14.740000,100,1,11.760000,100,1,15.280000,100,1,11.520000,100,1,15.300000,100,1,11.400000,100,1,15.310000,2,1,11.290000,100,1,15.610000,100,1,11.140000,700,1,15.910000,100,1,11.070000,700,1,16.110000,700,1,ARL,43324133
2025-07-17T13:30:01.255007539Z,2025-07-17T13:30:01.254829854Z,10,2,1108,A,B,2,12.33,2,128,177685,29223480,12.670000,100,1,14.000000,100,1,12.470000,100,1,14.200000,100,1,12.330000,2,1,14.440000,100,1,12.230000,100,1,14.740000,100,1,11.930000,100,1,15.280000,100,1,11.760000,100,1,15.300000,100,1,11.520000,100,1,15.310000,2,1,11.400000,100,1,15.610000,100,1,11.290000,100,1,15.910000,100,1,11.140000,700,1,16.110000,700,1,ARL,43692153
2025-07-17T13:30:01.255016966Z,2025-07-17T13:30:01.254836082Z,10,2,1108,C,A,6,15.31,2,0,180884,29223485,12.670000,100,1,14.000000,100,1,12.470000,100,1,14.200000,100,1,12.330000,2,1,14.440000,100,1,12.230000,100,1,14.740000,100,1,11.930000,100,1,15.280000,100,1,11.760000,100,1,15.300000,100,1,11.520000,100,1,15.610000,100,1,11.400000,100,1,15.910000,100,1,11.290000,100,1,16.110000,700,1,11.140000,700,1,16.150000,700,1,ARL,43328313
2025-07-17T13:30:01.255016966Z,2025-07-17T13:30:01.254836082Z,10,2,1108,A,A,3,14.65,2,128,180884,29223485,12.670000,100,1,14.000000,100,1,12.470000,100,1,14.200000,100,1,12.330000,2,1,14.440000,100,1,12.230000,100,1,14.650000,2,1,11.930000,100,1,14.740000,100,1,11.760000,100,1,15.280000,100,1,11.520000,100,1,15.300000,100,1,11.400000,100,1,15.610000,100,1,11.290000,100,1,15.910000,100,1,11.140000,700,1,16.110000,700,1,ARL,43692157
2025-07-17T13:30:01.327109477Z,2025-07-17T13:30:01.326934077Z,10,2,1108,C,B,6,11.52,100,130,175400,29250087,12.670000,100,1,14.000000,100,1,12.470000,100,1,14.200000,100,1,12.330000,2,1,14.440000,100,1,12.230000,100,1,14.650000,2,1,11.930000,100,1,14.740000,100,1,11.760000,100,1,15.280000,100,1,11.400000,100,1,15.300000,100,1,11.290000,100,1,15.610000,100,1,11.140000,700,1,15.910000,100,1,11.070000,700,1,16.110000,700,1,ARL,42446497
2025-07-17T13:30:01.327894898Z,2025-07-17T13:30:01.327714478Z,10,2,1108,C,A,7,15.61,100,128,180420,29250293,12.670000,100,1,14.000000,100,1,12.470000,100,1,14.200000,100,1,12.330000,2,1,14.440000,100,1,12.230000,100,1,14.650000,2,1,11.930000,100,1,14.740000,100,1,11.760000,100,1,15.280000,100,1,11.400000,100,1,15.300000,100,1,11.290000,100,1,15.910000,100,1,11.140000,700,1,16.110000,700,1,11.070000,700,1,16.150000,700,1,ARL,42446501
2025-07-17T13:30:01.367410233Z,2025-07-17T13:30:01.367244122Z,10,2,1108,C,B,12,10.93,100,0,166111,29262273,12.670000,100,1,14.000000,100,1,12.470000,100,1,14.200000,100,1,12.330000,2,1,14.440000,100,1,12.230000,100,1,14.650000,2,1,11.930000,100,1,14.740000,100,1,11.760000,100,1,15.280000,100,1,11.400000,100,1,15.300000,100,1,11.290000,100,1,15.910000,100,1,11.140000,700,1,16.110000,700,1,11.070000,700,1,16.150000,700,1,ARL,41376501
2025-07-17T13:30:01.367410233Z,2025-07-17T13:30:01.367244122Z,10,2,1108,A,B,2,12.33,100,130,166111,29262273,12.670000,100,1,14.000000,100,1,12.470000,100,1,14.200000,100,1,12.330000,102,2,14.440000,100,1,12.230000,100,1,14.650000,2,1,11.930000,100,1,14.740000,100,1,11.760000,100,1,15.280000,100,1,11.400000,100,1,15.300000,100,1,11.290000,100,1,15.910000,100,1,11.140000,700,1,16.110000,700,1,11.070000,700,1,16.150000,700,1,ARL,43755813
2025-07-17T13:30:01.367421844Z,2025-07-17T13:30:01.367256226Z,10,2,1108,C,A,13,16.38,100,0,165618,29262274,12.670000,100,1,14.000000,100,1,12.470000,100,1,14.200000,100,1,12.330000,102,2,14.440000,100,1,12.230000,100,1,14.650000,2,1,11.930000,100,1,14.740000,100,1,11.760000,100,1,15.280000,100,1,11.400000,100,1,15.300000,100,1,11.290000,100,1,15.910000,100,1,11.140000,700,1,16.110000,700,1,11.070000,700,1,16.150000,700,1,ARL,41372085
2025-07-17T13:30:01.367421844Z,2025-07-17T13:30:01.367256226Z,10,2,1108,A,A,2,14.34,100,130,165618,29262274,12.670000,100,1,14.000000,100,1,12.470000,100,1,14.200000,100,1,12.330000,102,2,14.340000,100,1,12.230000,100,1,14.440000,100,1,11.930000,100,1,14.650000,2,1,11.760000,100,1,14.740000,100,1,11.400000,100,1,15.280000,100,1,11.290000,100,1,15.300000,100,1,11.140000,700,1,15.910000,100,1,11.070000,700,1,16.110000,700,1,ARL,43755821
2025-07-17T13:30:01.456631847Z,2025-07-17T13:30:01.456460560Z,10,2,1108,C,B,13,10.92,100,0,171287,29285993,12.670000,100,1,14.000000,100,1,12.470000,100,1,14.200000,100,1,12.330000,102,2,14.340000,100,1,12.230000,100,1,14.440000,100,1,11.930000,100,1,14.650000,2,1,11.760000,100,1,14.740000,100,1,11.400000,100,1,15.280000,100,1,11.290000,100,1,15.300000,100,1,11.140000,700,1,15.910000,100,1,11.070000,700,1,16.110000,700,1,ARL,43143317
2025-07-17T13:30:01.456631847Z,2025-07-17T13:30:01.456460560Z,10,2,1108,A,B,2,12.36,100,130,171287,29285993,12.670000,100,1,14.000000,100,1,12.470000,100,1,14.200000,100,1,12.360000,100,1,14.340000,100,1,12.330000,102,2,14.440000,100,1,12.230000,100,1,14.650000,2,1,11.930000,100,1,14.740000,100,1,11.760000,100,1,15.280000,100,1,11.400000,100,1,15.300000,100,1,11.290000,100,1,15.910000,100,1,11.140000,700,1,16.110000,700,1,ARL,43781537
2025-07-17T13:30:01.456642950Z,2025-07-17T13:30:01.456476348Z,10,2,1108,C,A,11,16.20,100,0,166602,29285996,12.670000,100,1,14.000000,100,1,12.470000,100,1,14.200000,100,1,12.360000,100,1,14.340000,100,1,12.330000,102,2,14.440000,100,1,12.230000,100,1,14.650000,2,1,11.930000,100,1,14.740000,100,1,11.760000,100,1,15.280000,100,1,11.400000,100,1,15.300000,100,1,11.290000,100,1,15.910000,100,1,11.140000,700,1,16.110000,700,1,ARL,43143333
2025-07-17T13:30:01.456642950Z,2025-07-17T13:30:01.456476348Z,10,2,1108,A,A,6,14.90,100,130,166602,29285996,12.670000,100,1,14.000000,100,1,12.470000,100,1,14.200000,100,1,12.360000,100,1,14.340000,100,1,12.330000,102,2,14.440000,100,1,12.230000,100,1,14.650000,2,1,11.930000,100,1,14.740000,100,1,11.760000,100,1,14.900000,100,1,11.400000,100,1,15.280000,100,1,11.290000,100,1,15.300000,100,1,11.140000,700,1,15.910000,100,1,ARL,43781545
2025-07-17T13:30:01.488050182Z,2025-07-17T13:30:01.487884350Z,10,2,1108,C,B,14,10.92,100,0,165832,29297612,12.670000,100,1,14.000000,100,1,12.470000,100,1,14.200000,100,1,12.360000,100,1,14.340000,100,1,12.330000,102,2,14.440000,100,1,12.230000,100,1,14.650000,2,1,11.930000,100,1,14.740000,100,1,11.760000,100,1,14.900000,100,1,11.400000,100,1,15.280000,100,1,11.290000,100,1,15.300000,100,1,11.140000,700,1,15.910000,100,1,ARL,43191333
2025-07-17T13:30:01.488050182Z,2025-07-17T13:30:01.487884350Z,10,2,1108,A,B,2,12.36,100,130,165832,29297612,12.670000,100,1,14.000000,100,1,12.470000,100,1,14.200000,100,1,12.360000,200,2,14.340000,100,1,12.330000,102,2,14.440000,100,1,12.230000,100,1,14.650000,2,1,11.930000,100,1,14.740000,100,1,11.760000,100,1,14.900000,100,1,11.400000,100,1,15.280000,100,1,11.290000,100,1,15.300000,100,1,11.140000,700,1,15.910000,100,1,ARL,43787977
2025-07-17T13:30:01.488082852Z,2025-07-17T13:30:01.487905785Z,10,2,1108,C,A,12,16.20,100,0,177067,29297619,12.670000,100,1,14.000000,100,1,12.470000,100,1,14.200000,100,1,12.360000,200,2,14.340000,100,1,12.330000,102,2,14.440000,100,1,12.230000,100,1,14.650000,2,1,11.930000,100,1,14.740000,100,1,11.760000,100,1,14.900000,100,1,11.400000,100,1,15.280000,100,1,11.290000,100,1,15.300000,100,1,11.140000,700,1,15.910000,100,1,ARL,43191369
2025-07-17T13:30:01.488082852Z,2025-07-17T13:30:01.487905785Z,10,2,1108,A,A,6,14.90,100,128,177067,29297619,12.670000,100,1,14.000000,100,1,12.470000,100,1,14.200000,100,1,12.360000,200,2,14.340000,100,1,12.330000,102,2,14.440000,100,1,12.230000,100,1,14.650000,2,1,11.930000,100,1,14.740000,100,1,11.760000,100,1,14.900000,200,2,11.400000,100,1,15.280000,100,1,11.290000,100,1,15.300000,100,1,11.140000,700,1,15.910000,100,1,ARL,43787985
2025-07-17T13:30:01.488981292Z,2025-07-17T13:30:01.488809902Z,10,2,1108,C,A,17,17.23,100,128,171390,29298089,12.670000,100,1,14.000000,100,1,12.470000,100,1,14.200000,100,1,12.360000,200,2,14.340000,100,1,12.330000,102,2,14.440000,100,1,12.230000,100,1,14.650000,2,1,11.930000,100,1,14.740000,100,1,11.760000,100,1,14.900000,200,2,11.400000,100,1,15.280000,100,1,11.290000,100,1,15.300000,100,1,11.140000,700,1,15.910000,100,1,ARL,43314561
2025-07-17T13:30:01.489038112Z,2025-07-17T13:30:01.488866053Z,10,2,1108,A,A,-1,16.08,100,128,172059,29298118,12.670000,100,1,14.000000,100,1,12.470000,100,1,14.200000,100,1,12.360000,200,2,14.340000,100,1,12.330000,102,2,14.440000,100,1,12.230000,100,1,14.650000,2,1,11.930000,100,1,14.740000,100,1,11.760000,100,1,14.900000,200,2,11.400000,100,1,15.280000,100,1,11.290000,100,1,15.300000,100,1,11.140000,700,1,15.910000,100,1,ARL,43788313
2025-07-17T13:30:01.532444998Z,2025-07-17T13:30:01.532274368Z,10,2,1108,A,B,2,12.46,100,128,170630,29318499,12.670000,100,1,14.000000,100,1,12.470000,100,1,14.200000,100,1,12.460000,100,1,14.340000,100,1,12.360000,200,2,14.440000,100,1,12.330000,102,2,14.650000,2,1,12.230000,100,1,14.740000,100,1,11.930000,100,1,14.900000,200,2,11.760000,100,1,15.280000,100,1,11.400000,100,1,15.300000,100,1,11.290000,100,1,15.910000,100,1,ARL,43804025
2025-07-17T13:30:01.532474492Z,2025-07-17T13:30:01.532293890Z,10,2,1108,C,B,12,11.05,100,128,180602,29318513,12.670000,100,1,14.000000,100,1,12.470000,100,1,14.200000,100,1,12.460000,100,1,14.340000,100,1,12.360000,200,2,14.440000,100,1,12.330000,102,2,14.650000,2,1,12.230000,100,1,14.740000,100,1,11.930000,100,1,14.900000,200,2,11.760000,100,1,15.280000,100,1,11.400000,100,1,15.300000,100,1,11.290000,100,1,15.910000,100,1,ARL,42089321
2025-07-17T13:30:01.532498294Z,2025-07-17T13:30:01.532324961Z,10,2,1108,A,A,1,14.20,100,128,173333,29318528,12.670000,100,1,14.000000,100,1,12.470000,100,1,14.200000,200,2,12.460000,100,1,14.340000,100,1,12.360000,200,2,14.440000,100,1,12.330000,102,2,14.650000,2,1,12.230000,100,1,14.740000,100,1,11.930000,100,1,14.900000,200,2,11.760000,100,1,15.280000,100,1,11.400000,100,1,15.300000,100,1,11.290000,100,1,15.910000,100,1,ARL,43804081
2025-07-17T13:30:01.532528215Z,2025-07-17T13:30:01.532347519Z,10,2,1108,C,A,13,16.22,100,128,180696,29318534,12.670000,100,1,14.000000,100,1,12.470000,100,1,14.200000,200,2,12.460000,100,1,14.340000,100,1,12.360000,200,2,14.440000,100,1,12.330000,102,2,14.650000,2,1,12.230000,100,1,14.740000,100,1,11.930000,100,1,14.900000,200,2,11.760000,100,1,15.280000,100,1,11.400000,100,1,15.300000,100,1,11.290000,100,1,15.910000,100,1,ARL,42089325
2025-07-17T13:30:01.537373659Z,2025-07-17T13:30:01.537195873Z,10,2,1108,A,B,0,12.99,100,128,177786,29320724,12.990000,100,1,14.000000,100,1,12.670000,100,1,14.200000,200,2,12.470000,100,1,14.340000,100,1,12.460000,100,1,14.440000,100,1,12.360000,200,2,14.650000,2,1,12.330000,102,2,14.740000,100,1,12.230000,100,1,14.900000,200,2,11.930000,100,1,15.280000,100,1,11.760000,100,1,15.300000,100,1,11.400000,100,1,15.910000,100,1,ARL,43805737
2025-07-17T13:30:01.537387032Z,2025-07-17T13:30:01.537219414Z,10,2,1108,A,A,4,14.65,100,128,167618,29320743,12.990000,100,1,14.000000,100,1,12.670000,100,1,14.200000,200,2,12.470000,100,1,14.340000,100,1,12.460000,100,1,14.440000,100,1,12.360000,200,2,14.650000,102,2,12.330000,102,2,14.740000,100,1,12.230000,100,1,14.900000,200,2,11.930000,100,1,15.280000,100,1,11.760000,100,1,15.300000,100,1,11.400000,100,1,15.910000,100,1,ARL,43805773
2025-07-17T13:30:01.571558801Z,2025-07-17T13:30:01.571375465Z,10,2,1108,A,B,0,13.20,28,130,183336,29336931,13.200000,28,1,14.000000,100,1,12.990000,100,1,14.200000,200,2,12.670000,100,1,14.340000,100,1,12.470000,100,1,14.440000,100,1,12.460000,100,1,14.650000,102,2,12.360000,200,2,14.740000,100,1,12.330000,102,2,14.900000,200,2,12.230000,100,1,15.280000,100,1,11.930000,100,1,15.300000,100,1,11.760000,100,1,15.910000,100,1,ARL,43820541
2025-07-17T13:30:01.589767581Z,2025-07-17T13:30:01.589592733Z,10,2,1108,C,A,17,17.23,100,128,174848,29345825,13.200000,28,1,14.000000,100,1,12.990000,100,1,14.200000,200,2,12.670000,100,1,14.340000,100,1,12.470000,100,1,14.440000,100,1,12.460000,100,1,14.650000,102,2,12.360000,200,2,14.740000,100,1,12.330000,102,2,14.900000,200,2,12.230000,100,1,15.280000,100,1,11.930000,100,1,15.300000,100,1,11.760000,100,1,15.910000,100,1,ARL,43317185
2025-07-17T13:30:01.590564534Z,2025-07-17T13:30:01.590381387Z,10,2,1108,A,A,-1,16.08,100,128,183147,29346224,13.200000,28,1,14.000000,100,1,12.990000,100,1,14.200000,200,2,12.670000,100,1,14.340000,100,1,12.470000,100,1,14.440000,100,1,12.460000,100,1,14.650000,102,2,12.360000,200,2,14.740000,100,1,12.330000,102,2,14.900000,200,2,12.230000,100,1,15.280000,100,1,11.930000,100,1,15.300000,100,1,11.760000,100,1,15.910000,100,1,ARL,43826261
2025-07-17T13:30:01.592691520Z,2025-07-17T13:30:01.592507554Z,10,2,1108,C,B,18,9.99,100,0,183966,29347436,13.200000,28,1,14.000000,100,1,12.990000,100,1,14.200000,200,2,12.670000,100,1,14.340000,100,1,12.470000,100,1,14.440000,100,1,12.460000,100,1,14.650000,102,2,12.360000,200,2,14.740000,100,1,12.330000,102,2,14.900000,200,2,12.230000,100,1,15.280000,100,1,11.930000,100,1,15.300000,100,1,11.760000,100,1,15.910000,100,1,ARL,41376769
2025-07-17T13:30:01.592691520Z,2025-07-17T13:30:01.592507554Z,10,2,1108,A,B,-1,11.27,100,128,183966,29347436,13.200000,28,1,14.000000,100,1,12.990000,100,1,14.200000,200,2,12.670000,100,1,14.340000,100,1,12.470000,100,1,14.440000,100,1,12.460000,100,1,14.650000,102,2,12.360000,200,2,14.740000,100,1,12.330000,102,2,14.900000,200,2,12.230000,100,1,15.280000,100,1,11.930000,100,1,15.300000,100,1,11.760000,100,1,15.910000,100,1,ARL,43826785
2025-07-17T13:30:01.592712062Z,2025-07-17T13:30:01.592539240Z,10,2,1108,C,A,17,17.60,100,0,172822,29347463,13.200000,28,1,14.000000,100,1,12.990000,100,1,14.200000,200,2,12.670000,100,1,14.340000,100,1,12.470000,100,1,14.440000,100,1,12.460000,100,1,14.650000,102,2,12.360000,200,2,14.740000,100,1,12.330000,102,2,14.900000,200,2,12.230000,100,1,15.280000,100,1,11.930000,100,1,15.300000,100,1,11.760000,100,1,15.910000,100,1,ARL,41372493
2025-07-17T13:30:01.592712062Z,2025-07-17T13:30:01.592539240Z,10,2,1108,A,A,9,15.41,100,128,172822,29347463,13.200000,28,1,14.000000,100,1,12.990000,100,1,14.200000,200,2,12.670000,100,1,14.340000,100,1,12.470000,100,1,14.440000,100,1,12.460000,100,1,14.650000,102,2,12.360000,200,2,14.740000,100,1,12.330000,102,2,14.900000,200,2,12.230000,100,1,15.280000,100,1,11.930000,100,1,15.300000,100,1,11.760000,100,1,15.410000,100,1,ARL,43826805
2025-07-17T13:30:01.662123703Z,2025-07-17T13:30:01.661958252Z,10,2,1108,C,B,18,10.58,100,0,165451,29378719,13.200000,28,1,14.000000,100,1,12.990000,100,1,14.200000,200,2,12.670000,100,1,14.340000,100,1,12.470000,100,1,14.440000,100,1,12.460000,100,1,14.650000,102,2,12.360000,200,2,14.740000,100,1,12.330000,102,2,14.900000,200,2,12.230000,100,1,15.280000,100,1,11.930000,100,1,15.300000,100,1,11.760000,100,1,15.410000,100,1,ARL,41377117
2025-07-17T13:30:01.662123703Z,2025-07-17T13:30:01.661958252Z,10,2,1108,A,B,8,11.93,100,130,165451,29378719,13.200000,28,1,14.000000,100,1,12.990000,100,1,14.200000,200,2,12.670000,100,1,14.340000,100,1,12.470000,100,1,14.440000,100,1,12.460000,100,1,14.650000,102,2,12.360000,200,2,14.740000,100,1,12.330000,102,2,14.900000,200,2,12.230000,100,1,15.280000,100,1,11.930000,200,2,15.300000,100,1,11.760000,100,1,15.410000,100,1,ARL,43852121
2025-07-17T13:30:01.662159610Z,2025-07-17T13:30:01.661989524Z,10,2,1108,C,A,16,16.83,100,0,170086,29378727,13.200000,28,1,14.000000,100,1,12.990000,100,1,14.200000,200,2,12.670000,100,1,14.340000,100,1,12.470000,100,1,14.440000,100,1,12.460000,100,1,14.650000,102,2,12.360000,200,2,14.740000,100,1,12.330000,102,2,14.900000,200,2,12.230000,100,1,15.280000,100,1,11.930000,200,2,15.300000,100,1,11.760000,100,1,15.410000,100,1,ARL,41372469
2025-07-17T13:30:01.662159610Z,2025-07-17T13:30:01.661989524Z,10,2,1108,A,A,5,14.74,100,128,170086,29378727,13.200000,28,1,14.000000,100,1,12.990000,100,1,14.200000,200,2,12.670000,100,1,14.340000,100,1,12.470000,100,1,14.440000,100,1,12.460000,100,1,14.650000,102,2,12.360000,200,2,14.740000,200,2,12.330000,102,2,14.900000,200,2,12.230000,100,1,15.280000,100,1,11.930000,200,2,15.300000,100,1,11.760000,100,1,15.410000,100,1,ARL,43852129
2025-07-17T13:30:01.929560509Z,2025-07-17T13:30:01.929395142Z,10,2,1108,C,A,4,14.65,100,130,165367,29480243,13.200000,28,1,14.000000,100,1,12.990000,100,1,14.200000,200,2,12.670000,100,1,14.340000,100,1,12.470000,100,1,14.440000,100,1,12.460000,100,1,14.650000,2,1,12.360000,200,2,14.740000,200,2,12.330000,102,2,14.900000,200,2,12.230000,100,1,15.280000,100,1,11.930000,200,2,15.300000,100,1,11.760000,100,1,15.410000,100,1,ARL,43805773
2025-07-17T13:30:01.930966377Z,2025-07-17T13:30:01.930800767Z,10,2,1108,A,A,0,13.67,100,130,165610,29480698,13.200000,28,1,13.670000,100,1,12.990000,100,1,14.000000,100,1,12.670000,100,1,14.200000,200,2,12.470000,100,1,14.340000,100,1,12.460000,100,1,14.440000,100,1,12.360000,200,2,14.650000,2,1,12.330000,102,2,14.740000,200,2,12.230000,100,1,14.900000,200,2,11.930000,200,2,15.280000,100,1,11.760000,100,1,15.300000,100,1,ARL,43953649
2025-07-17T13:30:02.209154979Z,2025-07-17T13:30:02.208989359Z,10,2,1108,A,A,-1,17.15,100,130,165620,29556866,13.200000,28,1,13.670000,100,1,12.990000,100,1,14.000000,100,1,12.670000,100,1,14.200000,200,2,12.470000,100,1,14.340000,100,1,12.460000,100,1,14.440000,100,1,12.360000,200,2,14.650000,2,1,12.330000,102,2,14.740000,200,2,12.230000,100,1,14.900000,200,2,11.930000,200,2,15.280000,100,1,11.760000,100,1,15.300000,100,1,ARL,44040361
2025-07-17T13:30:02.209170665Z,2025-07-17T13:30:02.209004229Z,10,2,1108,A,B,-1,9.55,100,128,166436,29556867,13.200000,28,1,13.670000,100,1,12.990000,100,1,14.000000,100,1,12.670000,100,1,14.200000,200,2,12.470000,100,1,14.340000,100,1,12.460000,100,1,14.440000,100,1,12.360000,200,2,14.650000,2,1,12.330000,102,2,14.740000,200,2,12.230000,100,1,14.900000,200,2,11.930000,200,2,15.280000,100,1,11.760000,100,1,15.300000,100,1,ARL,44040369
2025-07-17T13:30:02.378440054Z,2025-07-17T13:30:02.378274380Z,10,2,1108,A,B,2,12.73,100,130,165674,29585499,13.200000,28,1,13.670000,100,1,12.990000,100,1,14.000000,100,1,12.730000,100,1,14.200000,200,2,12.670000,100,1,14.340000,100,1,12.470000,100,1,14.440000,100,1,12.460000,100,1,14.650000,2,1,12.360000,200,2,14.740000,200,2,12.330000,102,2,14.900000,200,2,12.230000,100,1,15.280000,100,1,11.930000,200,2,15.300000,100,1,ARL,44066409
2025-07-17T13:30:02.378446229Z,2025-07-17T13:30:02.378280610Z,10,2,1108,A,A,1,13.93,100,130,165619,29585501,13.200000,28,1,13.670000,100,1,12.990000,100,1,13.930000,100,1,12.730000,100,1,14.000000,100,1,12.670000,100,1,14.200000,200,2,12.470000,100,1,14.340000,100,1,12.460000,100,1,14.440000,100,1,12.360000,200,2,14.650000,2,1,12.330000,102,2,14.740000,200,2,12.230000,100,1,14.900000,200,2,11.930000,200,2,15.280000,100,1,ARL,44066417
2025-07-17T13:30:02.378454598Z,2025-07-17T13:30:02.378286605Z,10,2,1108,C,B,12,11.29,100,128,167993,29585502,13.200000,28,1,13.670000,100,1,12.990000,100,1,13.930000,100,1,12.730000,100,1,14.000000,100,1,12.670000,100,1,14.200000,200,2,12.470000,100,1,14.340000,100,1,12.460000,100,1,14.440000,100,1,12.360000,200,2,14.650000,2,1,12.330000,102,2,14.740000,200,2,12.230000,100,1,14.900000,200,2,11.930000,200,2,15.280000,100,1,ARL,42099317
2025-07-17T13:30:02.378458883Z,2025-07-17T13:30:02.378293244Z,10,2,1108,C,A,12,15.91,100,130,165639,29585504,13.200000,28,1,13.670000,100,1,12.990000,100,1,13.930000,100,1,12.730000,100,1,14.000000,100,1,12.670000,100,1,14.200000,200,2,12.470000,100,1,14.340000,100,1,12.460000,100,1,14.440000,100,1,12.360000,200,2,14.650000,2,1,12.330000,102,2,14.740000,200,2,12.230000,100,1,14.900000,200,2,11.930000,200,2,15.280000,100,1,ARL,42099321
2025-07-17T13:30:02.476983806Z,2025-07-17T13:30:02.476818222Z,10,2,1108,C,A,8,14.90,100,0,165584,29601178,13.200000,28,1,13.670000,100,1,12.990000,100,1,13.930000,100,1,12.730000,100,1,14.000000,100,1,12.670000,100,1,14.200000,200,2,12.470000,100,1,14.340000,100,1,12.460000,100,1,14.440000,100,1,12.360000,200,2,14.650000,2,1,12.330000,102,2,14.740000,200,2,12.230000,100,1,14.900000,100,1,11.930000,200,2,15.280000,100,1,ARL,43781545
2025-07-17T13:30:02.476983806Z,2025-07-17T13:30:02.476818222Z,10,2,1108,A,A,6,14.57,100,130,165584,29601178,13.200000,28,1,13.670000,100,1,12.990000,100,1,13.930000,100,1,12.730000,100,1,14.000000,100,1,12.670000,100,1,14.200000,200,2,12.470000,100,1,14.340000,100,1,12.460000,100,1,14.440000,100,1,12.360000,200,2,14.570000,100,1,12.330000,102,2,14.650000,2,1,12.230000,100,1,14.740000,200,2,11.930000,200,2,14.900000,100,1,ARL,44076709
2025-07-17T13:30:02.483297761Z,2025-07-17T13:30:02.483131658Z,10,2,1108,C,A,9,14.90,100,0,166103,29601999,13.200000,28,1,13.670000,100,1,12.990000,100,1,13.930000,100,1,12.730000,100,1,14.000000,100,1,12.670000,100,1,14.200000,200,2,12.470000,100,1,14.340000,100,1,12.460000,100,1,14.440000,100,1,12.360000,200,2,14.570000,100,1,12.330000,102,2,14.650000,2,1,12.230000,100,1,14.740000,200,2,11.930000,200,2,15.280000,100,1,ARL,43787985
2025-07-17T13:30:02.483297761Z,2025-07-17T13:30:02.483131658Z,10,2,1108,A,A,6,14.57,100,130,166103,29601999,13.200000,28,1,13.670000,100,1,12.990000,100,1,13.930000,100,1,12.730000,100,1,14.000000,100,1,12.670000,100,1,14.200000,200,2,12.470000,100,1,14.340000,100,1,12.460000,100,1,14.440000,100,1,12.360000,200,2,14.570000,200,2,12.330000,102,2,14.650000,2,1,12.230000,100,1,14.740000,200,2,11.930000,200,2,15.280000,100,1,ARL,44077497
2025-07-17T13:30:02.524921786Z,2025-07-17T13:30:02.524755932Z,10,2,1108,C,B,19,8.58,100,0,165854,29608933,13.200000,28,1,13.670000,100,1,12.990000,100,1,13.930000,100,1,12.730000,100,1,14.000000,100,1,12.670000,100,1,14.200000,200,2,12.470000,100,1,14.340000,100,1,12.460000,100,1,14.440000,100,1,12.360000,200,2,14.570000,200,2,12.330000,102,2,14.650000,2,1,12.230000,100,1,14.740000,200,2,11.930000,200,2,15.280000,100,1,ARL,41376733
2025-07-17T13:30:02.524921786Z,2025-07-17T13:30:02.524755932Z,10,2,1108,A,B,-1,9.67,100,130,165854,29608933,13.200000,28,1,13.670000,100,1,12.990000,100,1,13.930000,100,1,12.730000,100,1,14.000000,100,1,12.670000,100,1,14.200000,200,2,12.470000,100,1,14.340000,100,1,12.460000,100,1,14.440000,100,1,12.360000,200,2,14.570000,200,2,12.330000,102,2,14.650000,2,1,12.230000,100,1,14.740000,200,2,11.930000,200,2,15.280000,100,1,ARL,44082961
2025-07-17T13:30:02.524935181Z,2025-07-17T13:30:02.524769583Z,10,2,1108,C,A,18,19.44,100,0,165598,29608936,13.200000,28,1,13.670000,100,1,12.990000,100,1,13.930000,100,1,12.730000,100,1,14.000000,100,1,12.670000,100,1,14.200000,200,2,12.470000,100,1,14.340000,100,1,12.460000,100,1,14.440000,100,1,12.360000,200,2,14.570000,200,2,12.330000,102,2,14.650000,2,1,12.230000,100,1,14.740000,200,2,11.930000,200,2,15.280000,100,1,ARL,41372549
2025-07-17T13:30:02.524935181Z,2025-07-17T13:30:02.524769583Z,10,2,1108,A,A,-1,17.02,100,130,165598,29608936,13.200000,28,1,13.670000,100,1,12.990000,100,1,13.930000,100,1,12.730000,100,1,14.000000,100,1,12.670000,100,1,14.200000,200,2,12.470000,100,1,14.340000,100,1,12.460000,100,1,14.440000,100,1,12.360000,200,2,14.570000,200,2,12.330000,102,2,14.650000,2,1,12.230000,100,1,14.740000,200,2,11.930000,200,2,15.280000,100,1,ARL,44082969
2025-07-17T13:30:02.573774313Z,2025-07-17T13:30:02.573606685Z,10,2,1108,C,B,16,10.93,100,0,167628,29618524,13.200000,28,1,13.670000,100,1,12.990000,100,1,13.930000,100,1,12.730000,100,1,14.000000,100,1,12.670000,100,1,14.200000,200,2,12.470000,100,1,14.340000,100,1,12.460000,100,1,14.440000,100,1,12.360000,200,2,14.570000,200,2,12.330000,102,2,14.650000,2,1,12.230000,100,1,14.740000,200,2,11.930000,200,2,15.280000,100,1,ARL,41379985
2025-07-17T13:30:02.573774313Z,2025-07-17T13:30:02.573606685Z,10,2,1108,A,B,7,12.33,100,128,167628,29618524,13.200000,28,1,13.670000,100,1,12.990000,100,1,13.930000,100,1,12.730000,100,1,14.000000,100,1,12.670000,100,1,14.200000,200,2,12.470000,100,1,14.340000,100,1,12.460000,100,1,14.440000,100,1,12.360000,200,2,14.570000,200,2,12.330000,202,3,14.650000,2,1,12.230000,100,1,14.740000,200,2,11.930000,200,2,15.280000,100,1,ARL,44088633
2025-07-17T13:30:02.573792046Z,2025-07-17T13:30:02.573623478Z,10,2,1108,C,A,16,16.38,100,0,168568,29618531,13.200000,28,1,13.670000,100,1,12.990000,100,1,13.930000,100,1,12.730000,100,1,14.000000,100,1,12.670000,100,1,14.200000,200,2,12.470000,100,1,14.340000,100,1,12.460000,100,1,14.440000,100,1,12.360000,200,2,14.570000,200,2,12.330000,202,3,14.650000,2,1,12.230000,100,1,14.740000,200,2,11.930000,200,2,15.280000,100,1,ARL,41372369
2025-07-17T13:30:02.573792046Z,2025-07-17T13:30:02.573623478Z,10,2,1108,A,A,4,14.34,100,128,168568,29618531,13.200000,28,1,13.670000,100,1,12.990000,100,1,13.930000,100,1,12.730000,100,1,14.000000,100,1,12.670000,100,1,14.200000,200,2,12.470000,100,1,14.340000,200,2,12.460000,100,1,14.440000,100,1,12.360000,200,2,14.570000,200,2,12.330000,202,3,14.650000,2,1,12.230000,100,1,14.740000,200,2,11.930000,200,2,15.280000,100,1,ARL,44088637
2025-07-17T13:30:06.757549069Z,2025-07-17T13:30:06.757383618Z,10,2,1108,A,A,4,14.27,700,130,165451,30107583,13.200000,28,1,13.670000,100,1,12.990000,100,1,13.930000,100,1,12.730000,100,1,14.000000,100,1,12.670000,100,1,14.200000,200,2,12.470000,100,1,14.270000,700,1,12.460000,100,1,14.340000,200,2,12.360000,200,2,14.440000,100,1,12.330000,202,3,14.570000,200,2,12.230000,100,1,14.650000,2,1,11.930000,200,2,14.740000,200,2,ARL,44491681
2025-07-17T13:30:06.757600916Z,2025-07-17T13:30:06.757435491Z,10,2,1108,C,A,15,16.15,700,130,165425,30107590,13.200000,28,1,13.670000,100,1,12.990000,100,1,13.930000,100,1,12.730000,100,1,14.000000,100,1,12.670000,100,1,14.200000,200,2,12.470000,100,1,14.270000,700,1,12.460000,100,1,14.340000,200,2,12.360000,200,2,14.440000,100,1,12.330000,202,3,14.570000,200,2,12.230000,100,1,14.650000,2,1,11.930000,200,2,14.740000,200,2,ARL,41528029
2025-07-17T13:30:07.195006880Z,2025-07-17T13:30:07.194841610Z,10,2,1108,A,A,-1,15.30,700,130,165270,30150210,13.200000,28,1,13.670000,100,1,12.990000,100,1,13.930000,100,1,12.730000,100,1,14.000000,100,1,12.670000,100,1,14.200000,200,2,12.470000,100,1,14.270000,700,1,12.460000,100,1,14.340000,200,2,12.360000,200,2,14.440000,100,1,12.330000,202,3,14.570000,200,2,12.230000,100,1,14.650000,2,1,11.930000,200,2,14.740000,200,2,ARL,44520965
2025-07-17T13:30:07.195046929Z,2025-07-17T13:30:07.194880522Z,10,2,1108,C,A,15,16.30,700,128,166407,30150214,13.200000,28,1,13.670000,100,1,12.990000,100,1,13.930000,100,1,12.730000,100,1,14.000000,100,1,12.670000,100,1,14.200000,200,2,12.470000,100,1,14.270000,700,1,12.460000,100,1,14.340000,200,2,12.360000,200,2,14.440000,100,1,12.330000,202,3,14.570000,200,2,12.230000,100,1,14.650000,2,1,11.930000,200,2,14.740000,200,2,ARL,41375973
2025-07-17T13:30:07.395047633Z,2025-07-17T13:30:07.394882479Z,10,2,1108,A,A,-1,15.00,700,130,165154,30169157,13.200000,28,1,13.670000,100,1,12.990000,100,1,13.930000,100,1,12.730000,100,1,14.000000,100,1,12.670000,100,1,14.200000,200,2,12.470000,100,1,14.270000,700,1,12.460000,100,1,14.340000,200,2,12.360000,200,2,14.440000,100,1,12.330000,202,3,14.570000,200,2,12.230000,100,1,14.650000,2,1,11.930000,200,2,14.740000,200,2,ARL,44533061
2025-07-17T13:30:07.395522844Z,2025-07-17T13:30:07.395357697Z,10,2,1108,C,A,12,15.30,700,130,165147,30169278,13.200000,28,1,13.670000,100,1,12.990000,100,1,13.930000,100,1,12.730000,100,1,14.000000,100,1,12.670000,100,1,14.200000,200,2,12.470000,100,1,14.270000,700,1,12.460000,100,1,14.340000,200,2,12.360000,200,2,14.440000,100,1,12.330000,202,3,14.570000,200,2,12.230000,100,1,14.650000,2,1,11.930000,200,2,14.740000,200,2,ARL,44520965
2025-07-17T13:30:07.594948559Z,2025-07-17T13:30:07.594772046Z,10,2,1108,A,A,9,14.70,700,128,176513,30189080,13.200000,28,1,13.670000,100,1,12.990000,100,1,13.930000,100,1,12.730000,100,1,14.000000,100,1,12.670000,100,1,14.200000,200,2,12.470000,100,1,14.270000,700,1,12.460000,100,1,14.340000,200,2,12.360000,200,2,14.440000,100,1,12.330000,202,3,14.570000,200,2,12.230000,100,1,14.650000,2,1,11.930000,200,2,14.700000,700,1,ARL,44545381
2025-07-17T13:30:07.594962236Z,2025-07-17T13:30:07.594797098Z,10,2,1108,C,A,11,15.00,700,130,165138,30189120,13.200000,28,1,13.670000,100,1,12.990000,100,1,13.930000,100,1,12.730000,100,1,14.000000,100,1,12.670000,100,1,14.200000,200,2,12.470000,100,1,14.270000,700,1,12.460000,100,1,14.340000,200,2,12.360000,200,2,14.440000,100,1,12.330000,202,3,14.570000,200,2,12.230000,100,1,14.650000,2,1,11.930000,200,2,14.700000,700,1,ARL,44533061
2025-07-17T13:30:07.663249150Z,2025-07-17T13:30:07.663083798Z,10,2,1108,A,A,7,14.46,700,130,165352,30194197,13.200000,28,1,13.670000,100,1,12.990000,100,1,13.930000,100,1,12.730000,100,1,14.000000,100,1,12.670000,100,1,14.200000,200,2,12.470000,100,1,14.270000,700,1,12.460000,100,1,14.340000,200,2,12.360000,200,2,14.440000,100,1,12.330000,202,3,14.460000,700,1,12.230000,100,1,14.570000,200,2,11.930000,200,2,14.650000,2,1,ARL,44548325
2025-07-17T13:30:07.663963574Z,2025-07-17T13:30:07.663798482Z,10,2,1108,C,A,10,14.70,700,130,165092,30194234,13.200000,28,1,13.670000,100,1,12.990000,100,1,13.930000,100,1,12.730000,100,1,14.000000,100,1,12.670000,100,1,14.200000,200,2,12.470000,100,1,14.270000,700,1,12.460000,100,1,14.340000,200,2,12.360000,200,2,14.440000,100,1,12.330000,202,3,14.460000,700,1,12.230000,100,1,14.570000,200,2,11.930000,200,2,14.650000,2,1,ARL,44545381
2025-07-17T13:30:07.914437226Z,2025-07-17T13:30:07.914271879Z,10,2,1108,A,B,-1,11.76,700,130,165347,30213834,13.200000,28,1,13.670000,100,1,12.990000,100,1,13.930000,100,1,12.730000,100,1,14.000000,100,1,12.670000,100,1,14.200000,200,2,12.470000,100,1,14.270000,700,1,12.460000,100,1,14.340000,200,2,12.360000,200,2,14.440000,100,1,12.330000,202,3,14.460000,700,1,12.230000,100,1,14.570000,200,2,11.930000,200,2,14.650000,2,1,ARL,44560257
2025-07-17T13:30:07.915115414Z,2025-07-17T13:30:07.914949951Z,10,2,1108,C,B,15,10.99,700,130,165463,30213941,13.200000,28,1,13.670000,100,1,12.990000,100,1,13.930000,100,1,12.730000,100,1,14.000000,100,1,12.670000,100,1,14.200000,200,2,12.470000,100,1,14.270000,700,1,12.460000,100,1,14.340000,200,2,12.360000,200,2,14.440000,100,1,12.330000,202,3,14.460000,700,1,12.230000,100,1,14.570000,200,2,11.930000,200,2,14.650000,2,1,ARL,41509393
2025-07-17T13:30:08.025826192Z,2025-07-17T13:30:08.025660842Z,10,2,1108,A,B,9,12.02,700,130,165350,30224657,13.200000,28,1,13.670000,100,1,12.990000,100,1,13.930000,100,1,12.730000,100,1,14.000000,100,1,12.670000,100,1,14.200000,200,2,12.470000,100,1,14.270000,700,1,12.460000,100,1,14.340000,200,2,12.360000,200,2,14.440000,100,1,12.330000,202,3,14.460000,700,1,12.230000,100,1,14.570000,200,2,12.020000,700,1,14.650000,2,1,ARL,44565617
2025-07-17T13:30:08.025838588Z,2025-07-17T13:30:08.025673570Z,10,2,1108,C,B,11,11.76,700,130,165018,30224658,13.200000,28,1,13.670000,100,1,12.990000,100,1,13.930000,100,1,12.730000,100,1,14.000000,100,1,12.670000,100,1,14.200000,200,2,12.470000,100,1,14.270000,700,1,12.460000,100,1,14.340000,200,2,12.360000,200,2,14.440000,100,1,12.330000,202,3,14.460000,700,1,12.230000,100,1,14.570000,200,2,12.020000,700,1,14.650000,2,1,ARL,44560257
2025-07-17T13:30:08.114437837Z,2025-07-17T13:30:08.114272470Z,10,2,1108,A,B,8,12.26,700,130,165367,30233944,13.200000,28,1,13.670000,100,1,12.990000,100,1,13.930000,100,1,12.730000,100,1,14.000000,100,1,12.670000,100,1,14.200000,200,2,12.470000,100,1,14.270000,700,1,12.460000,100,1,14.340000,200,2,12.360000,200,2,14.440000,100,1,12.330000,202,3,14.460000,700,1,12.260000,700,1,14.570000,200,2,12.230000,100,1,14.650000,2,1,ARL,44570585
2025-07-17T13:30:08.115234484Z,2025-07-17T13:30:08.115068904Z,10,2,1108,C,B,10,12.02,700,130,165580,30234078,13.200000,28,1,13.670000,100,1,12.990000,100,1,13.930000,100,1,12.730000,100,1,14.000000,100,1,12.670000,100,1,14.200000,200,2,12.470000,100,1,14.270000,700,1,12.460000,100,1,14.340000,200,2,12.360000,200,2,14.440000,100,1,12.330000,202,3,14.460000,700,1,12.260000,700,1,14.570000,200,2,12.230000,100,1,14.650000,2,1,ARL,44565617
2025-07-17T13:30:08.394538665Z,2025-07-17T13:30:08.394373251Z,10,2,1108,A,B,0,13.25,11,130,165414,30258008,13.250000,11,1,13.670000,100,1,13.200000,28,1,13.930000,100,1,12.990000,100,1,14.000000,100,1,12.730000,100,1,14.200000,200,2,12.670000,100,1,14.270000,700,1,12.470000,100,1,14.340000,200,2,12.460000,100,1,14.440000,100,1,12.360000,200,2,14.460000,700,1,12.330000,202,3,14.570000,200,2,12.260000,700,1,14.650000,2,1,ARL,44586753
2025-07-17T13:30:08.402177882Z,2025-07-17T13:30:08.402012613Z,10,2,1108,C,B,1,13.20,28,130,165269,30259240,13.250000,11,1,13.670000,100,1,12.990000,100,1,13.930000,100,1,12.730000,100,1,14.000000,100,1,12.670000,100,1,14.200000,200,2,12.470000,100,1,14.270000,700,1,12.460000,100,1,14.340000,200,2,12.360000,200,2,14.440000,100,1,12.330000,202,3,14.460000,700,1,12.260000,700,1,14.570000,200,2,12.230000,100,1,14.650000,2,1,ARL,43820541
2025-07-17T13:30:08.512744920Z,2025-07-17T13:30:08.512579639Z,10,2,1108,A,A,4,14.26,700,130,165281,30276907,13.250000,11,1,13.670000,100,1,12.990000,100,1,13.930000,100,1,12.730000,100,1,14.000000,100,1,12.670000,100,1,14.200000,200,2,12.470000,100,1,14.260000,700,1,12.460000,100,1,14.270000,700,1,12.360000,200,2,14.340000,200,2,12.330000,202,3,14.440000,100,1,12.260000,700,1,14.460000,700,1,12.230000,100,1,14.570000,200,2,ARL,44598153
2025-07-17T13:30:08.513140882Z,2025-07-17T13:30:08.512974877Z,10,2,1108,C,A,16,16.11,700,130,166005,30276990,13.250000,11,1,13.670000,100,1,12.990000,100,1,13.930000,100,1,12.730000,100,1,14.000000,100,1,12.670000,100,1,14.200000,200,2,12.470000,100,1,14.260000,700,1,12.460000,100,1,14.270000,700,1,12.360000,200,2,14.340000,200,2,12.330000,202,3,14.440000,100,1,12.260000,700,1,14.460000,700,1,12.230000,100,1,14.570000,200,2,ARL,41371225
2025-07-17T13:30:09.129158268Z,2025-07-17T13:30:09.128991840Z,10,2,1108,A,B,-1,11.76,700,128,166428,30336805,13.250000,11,1,13.670000,100,1,12.990000,100,1,13.930000,100,1,12.730000,100,1,14.000000,100,1,12.670000,100,1,14.200000,200,2,12.470000,100,1,14.260000,700,1,12.460000,100,1,14.270000,700,1,12.360000,200,2,14.340000,200,2,12.330000,202,3,14.440000,100,1,12.260000,700,1,14.460000,700,1,12.230000,100,1,14.570000,200,2,ARL,44628617
2025-07-17T13:30:09.129171567Z,2025-07-17T13:30:09.129006013Z,10,2,1108,C,B,15,11.07,700,130,165554,30336807,13.250000,11,1,13.670000,100,1,12.990000,100,1,13.930000,100,1,12.730000,100,1,14.000000,100,1,12.670000,100,1,14.200000,200,2,12.470000,100,1,14.260000,700,1,12.460000,100,1,14.270000,700,1,12.360000,200,2,14.340000,200,2,12.330000,202,3,14.440000,100,1,12.260000,700,1,14.460000,700,1,12.230000,100,1,14.570000,200,2,ARL,41539477
2025-07-17T13:30:09.329216559Z,2025-07-17T13:30:09.329050977Z,10,2,1108,A,B,-1,12.02,700,130,165582,30353905,13.250000,11,1,13.670000,100,1,12.990000,100,1,13.930000,100,1,12.730000,100,1,14.000000,100,1,12.670000,100,1,14.200000,200,2,12.470000,100,1,14.260000,700,1,12.460000,100,1,14.270000,700,1,12.360000,200,2,14.340000,200,2,12.330000,202,3,14.440000,100,1,12.260000,700,1,14.460000,700,1,12.230000,100,1,14.570000,200,2,ARL,44641397
2025-07-17T13:30:09.329283504Z,2025-07-17T13:30:09.329118219Z,10,2,1108,C,B,12,11.76,700,130,165285,30353910,13.250000,11,1,13.670000,100,1,12.990000,100,1,13.930000,100,1,12.730000,100,1,14.000000,100,1,12.670000,100,1,14.200000,200,2,12.470000,100,1,14.260000,700,1,12.460000,100,1,14.270000,700,1,12.360000,200,2,14.340000,200,2,12.330000,202,3,14.440000,100,1,12.260000,700,1,14.460000,700,1,12.230000,100,1,14.570000,200,2,ARL,44628617
2025-07-17T13:30:10.081340519Z,2025-07-17T13:30:10.081175039Z,10,2,1108,A,A,0,13.40,10,130,165480,30441651,13.250000,11,1,13.400000,10,1,12.990000,100,1,13.670000,100,1,12.730000,100,1,13.930000,100,1,12.670000,100,1,14.000000,100,1,12.470000,100,1,14.200000,200,2,12.460000,100,1,14.260000,700,1,12.360000,200,2,14.270000,700,1,12.330000,202,3,14.340000,200,2,12.260000,700,1,14.440000,100,1,12.230000,100,1,14.460000,700,1,ARL,44719917
2025-07-17T13:30:10.082315658Z,2025-07-17T13:30:10.082150107Z,10,2,1108,C,A,10,14.57,100,0,165551,30441855,13.250000,11,1,13.400000,10,1,12.990000,100,1,13.670000,100,1,12.730000,100,1,13.930000,100,1,12.670000,100,1,14.000000,100,1,12.470000,100,1,14.200000,200,2,12.460000,100,1,14.260000,700,1,12.360000,200,2,14.270000,700,1,12.330000,202,3,14.340000,200,2,12.260000,700,1,14.440000,100,1,12.230000,100,1,14.460000,700,1,ARL,44076709
2025-07-17T13:30:10.082315658Z,2025-07-17T13:30:10.082150107Z,10,2,1108,A,A,7,14.29,100,130,165551,30441855,13.250000,11,1,13.400000,10,1,12.990000,100,1,13.670000,100,1,12.730000,100,1,13.930000,100,1,12.670000,100,1,14.000000,100,1,12.470000,100,1,14.200000,200,2,12.460000,100,1,14.260000,700,1,12.360000,200,2,14.270000,700,1,12.330000,202,3,14.290000,100,1,12.260000,700,1,14.340000,200,2,12.230000,100,1,14.440000,100,1,ARL,44719985
2025-07-17T13:30:10.082828352Z,2025-07-17T13:30:10.082662762Z,10,2,1108,C,A,11,14.57,100,0,165590,30441930,13.250000,11,1,13.400000,10,1,12.990000,100,1,13.670000,100,1,12.730000,100,1,13.930000,100,1,12.670000,100,1,14.000000,100,1,12.470000,100,1,14.200000,200,2,12.460000,100,1,14.260000,700,1,12.360000,200,2,14.270000,700,1,12.330000,202,3,14.290000,100,1,12.260000,700,1,14.340000,200,2,12.230000,100,1,14.440000,100,1,ARL,44077497
2025-07-17T13:30:10.082828352Z,2025-07-17T13:30:10.082662762Z,10,2,1108,A,A,7,14.29,100,130,165590,30441930,13.250000,11,1,13.400000,10,1,12.990000,100,1,13.670000,100,1,12.730000,100,1,13.930000,100,1,12.670000,100,1,14.000000,100,1,12.470000,100,1,14.200000,200,2,12.460000,100,1,14.260000,700,1,12.360000,200,2,14.270000,700,1,12.330000,202,3,14.290000,200,2,12.260000,700,1,14.340000,200,2,12.230000,100,1,14.440000,100,1,ARL,44720033
2025-07-17T13:30:10.085062201Z,2025-07-17T13:30:10.084896414Z,10,2,1108,A,B,6,12.42,700,130,165787,30442720,13.250000,11,1,13.400000,10,1,12.990000,100,1,13.670000,100,1,12.730000,100,1,13.930000,100,1,12.670000,100,1,14.000000,100,1,12.470000,100,1,14.200000,200,2,12.460000,100,1,14.260000,700,1,12.420000,700,1,14.270000,700,1,12.360000,200,2,14.290000,200,2,12.330000,202,3,14.340000,200,2,12.260000,700,1,14.440000,100,1,ARL,44720357
2025-07-17T13:30:10.085497770Z,2025-07-17T13:30:10.085332605Z,10,2,1108,C,B,16,11.14,700,130,165165,30442750,13.250000,11,1,13.400000,10,1,12.990000,100,1,13.670000,100,1,12.730000,100,1,13.930000,100,1,12.670000,100,1,14.000000,100,1,12.470000,100,1,14.200000,200,2,12.460000,100,1,14.260000,700,1,12.420000,700,1,14.270000,700,1,12.360000,200,2,14.290000,200,2,12.330000,202,3,14.340000,200,2,12.260000,700,1,14.440000,100,1,ARL,41534785
2025-07-17T13:30:12.194748173Z,2025-07-17T13:30:12.194582572Z,10,2,1108,C,A,11,14.65,2,0,165601,30681385,13.250000,11,1,13.400000,10,1,12.990000,100,1,13.670000,100,1,12.730000,100,1,13.930000,100,1,12.670000,100,1,14.000000,100,1,12.470000,100,1,14.200000,200,2,12.460000,100,1,14.260000,700,1,12.420000,700,1,14.270000,700,1,12.360000,200,2,14.290000,200,2,12.330000,202,3,14.340000,200,2,12.260000,700,1,14.440000,100,1,ARL,43692157
2025-07-17T13:30:12.194748173Z,2025-07-17T13:30:12.194582572Z,10,2,1108,A,A,9,14.43,2,130,165601,30681385,13.250000,11,1,13.400000,10,1,12.990000,100,1,13.670000,100,1,12.730000,100,1,13.930000,100,1,12.670000,100,1,14.000000,100,1,12.470000,100,1,14.200000,200,2,12.460000,100,1,14.260000,700,1,12.420000,700,1,14.270000,700,1,12.360000,200,2,14.290000,200,2,12.330000,202,3,14.340000,200,2,12.260000,700,1,14.430000,2,1,ARL,44904733
2025-07-17T13:30:14.129097570Z,2025-07-17T13:30:14.128932140Z,10,2,1108,A,B,7,12.37,700,130,165430,30851531,13.250000,11,1,13.400000,10,1,12.990000,100,1,13.670000,100,1,12.730000,100,1,13.930000,100,1,12.670000,100,1,14.000000,100,1,12.470000,100,1,14.200000,200,2,12.460000,100,1,14.260000,700,1,12.420000,700,1,14.270000,700,1,12.370000,700,1,14.290000,200,2,12.360000,200,2,14.340000,200,2,12.330000,202,3,14.430000,2,1,ARL,45025165
2025-07-17T13:30:14.129174026Z,2025-07-17T13:30:14.129008546Z,10,2,1108,C,B,12,12.02,700,130,165480,30851532,13.250000,11,1,13.400000,10,1,12.990000,100,1,13.670000,100,1,12.730000,100,1,13.930000,100,1,12.670000,100,1,14.000000,100,1,12.470000,100,1,14.200000,200,2,12.460000,100,1,14.260000,700,1,12.420000,700,1,14.270000,700,1,12.370000,700,1,14.290000,200,2,12.360000,200,2,14.340000,200,2,12.330000,202,3,14.430000,2,1,ARL,44641397
2025-07-17T13:30:23.695729484Z,2025-07-17T13:30:23.695564208Z,10,2,1108,A,A,0,13.40,12,130,165276,31649134,13.250000,11,1,13.400000,22,2,12.990000,100,1,13.670000,100,1,12.730000,100,1,13.930000,100,1,12.670000,100,1,14.000000,100,1,12.470000,100,1,14.200000,200,2,12.460000,100,1,14.260000,700,1,12.420000,700,1,14.270000,700,1,12.370000,700,1,14.290000,200,2,12.360000,200,2,14.340000,200,2,12.330000,202,3,14.430000,2,1,ARL,45593201
2025-07-17T13:30:25.512235443Z,2025-07-17T13:30:25.512069243Z,10,2,1108,C,A,0,13.40,10,128,166200,31806233,13.250000,11,1,13.400000,12,1,12.990000,100,1,13.670000,100,1,12.730000,100,1,13.930000,100,1,12.670000,100,1,14.000000,100,1,12.470000,100,1,14.200000,200,2,12.460000,100,1,14.260000,700,1,12.420000,700,1,14.270000,700,1,12.370000,700,1,14.290000,200,2,12.360000,200,2,14.340000,200,2,12.330000,202,3,14.430000,2,1,ARL,44719917
2025-07-17T13:30:26.553325979Z,2025-07-17T13:30:26.553160650Z,10,2,1108,A,A,0,13.40,10,130,165329,31897785,13.250000,11,1,13.400000,22,2,12.990000,100,1,13.670000,100,1,12.730000,100,1,13.930000,100,1,12.670000,100,1,14.000000,100,1,12.470000,100,1,14.200000,200,2,12.460000,100,1,14.260000,700,1,12.420000,700,1,14.270000,700,1,12.370000,700,1,14.290000,200,2,12.360000,200,2,14.340000,200,2,12.330000,202,3,14.430000,2,1,ARL,45748261
2025-07-17T13:30:35.240569990Z,2025-07-17T13:30:35.240400172Z,10,2,1108,C,A,0,13.40,10,130,169818,32725426,13.250000,11,1,13.400000,12,1,12.990000,100,1,13.670000,100,1,12.730000,100,1,13.930000,100,1,12.670000,100,1,14.000000,100,1,12.470000,100,1,14.200000,200,2,12.460000,100,1,14.260000,700,1,12.420000,700,1,14.270000,700,1,12.370000,700,1,14.290000,200,2,12.360000,200,2,14.340000,200,2,12.330000,202,3,14.430000,2,1,ARL,45748261
2025-07-17T13:30:43.953164386Z,2025-07-17T13:30:43.952999157Z,10,2,1108,C,A,0,13.40,12,130,165229,33659635,13.250000,11,1,13.670000,100,1,12.990000,100,1,13.930000,100,1,12.730000,100,1,14.000000,100,1,12.670000,100,1,14.200000,200,2,12.470000,100,1,14.260000,700,1,12.460000,100,1,14.270000,700,1,12.420000,700,1,14.290000,200,2,12.370000,700,1,14.340000,200,2,12.360000,200,2,14.430000,2,1,12.330000,202,3,14.440000,100,1,ARL,45593201
2025-07-17T13:30:43.953528491Z,2025-07-17T13:30:43.953363128Z,10,2,1108,A,A,0,13.40,24,130,165363,33659657,13.250000,11,1,13.400000,24,1,12.990000,100,1,13.670000,100,1,12.730000,100,1,13.930000,100,1,12.670000,100,1,14.000000,100,1,12.470000,100,1,14.200000,200,2,12.460000,100,1,14.260000,700,1,12.420000,700,1,14.270000,700,1,12.370000,700,1,14.290000,200,2,12.360000,200,2,14.340000,200,2,12.330000,202,3,14.430000,2,1,ARL,46613073
2025-07-17T13:30:47.814275253Z,2025-07-17T13:30:47.814108950Z,10,2,1108,A,A,0,13.40,10,130,166303,34075767,13.250000,11,1,13.400000,34,2,12.990000,100,1,13.670000,100,1,12.730000,100,1,13.930000,100,1,12.670000,100,1,14.000000,100,1,12.470000,100,1,14.200000,200,2,12.460000,100,1,14.260000,700,1,12.420000,700,1,14.270000,700,1,12.370000,700,1,14.290000,200,2,12.360000,200,2,14.340000,200,2,12.330000,202,3,14.430000,2,1,ARL,46784085
2025-07-17T13:30:48.271777831Z,2025-07-17T13:30:48.271611303Z,10,2,1108,C,A,0,13.40,10,130,166528,34129837,13.250000,11,1,13.400000,24,1,12.990000,100,1,13.670000,100,1,12.730000,100,1,13.930000,100,1,12.670000,100,1,14.000000,100,1,12.470000,100,1,14.200000,200,2,12.460000,100,1,14.260000,700,1,12.420000,700,1,14.270000,700,1,12.370000,700,1,14.290000,200,2,12.360000,200,2,14.340000,200,2,12.330000,202,3,14.430000,2,1,ARL,46784085
2025-07-17T13:30:56.518448581Z,2025-07-17T13:30:56.518283181Z,10,2,1108,A,A,0,13.40,10,130,165400,34951153,13.250000,11,1,13.400000,34,2,12.990000,100,1,13.670000,100,1,12.730000,100,1,13.930000,100,1,12.670000,100,1,14.000000,100,1,12.470000,100,1,14.200000,200,2,12.460000,100,1,14.260000,700,1,12.420000,700,1,14.270000,700,1,12.370000,700,1,14.290000,200,2,12.360000,200,2,14.340000,200,2,12.330000,202,3,14.430000,2,1,ARL,47164169
2025-07-17T13:31:01.011909405Z,2025-07-17T13:31:01.011743292Z,10,2,1108,A,A,4,14.20,700,128,166113,35180694,13.250000,11,1,13.400000,34,2,12.990000,100,1,13.670000,100,1,12.730000,100,1,13.930000,100,1,12.670000,100,1,14.000000,100,1,12.470000,100,1,14.200000,900,3,12.460000,100,1,14.260000,700,1,12.420000,700,1,14.270000,700,1,12.370000,700,1,14.290000,200,2,12.360000,200,2,14.340000,200,2,12.330000,202,3,14.430000,2,1,ARL,47376925
2025-07-17T13:31:01.029013770Z,2025-07-17T13:31:01.028848502Z,10,2,1108,A,B,6,12.43,700,130,165268,35188622,13.250000,11,1,13.400000,34,2,12.990000,100,1,13.670000,100,1,12.730000,100,1,13.930000,100,1,12.670000,100,1,14.000000,100,1,12.470000,100,1,14.200000,900,3,12.460000,100,1,14.260000,700,1,12.430000,700,1,14.270000,700,1,12.420000,700,1,14.290000,200,2,12.370000,700,1,14.340000,200,2,12.360000,200,2,14.430000,2,1,ARL,47383873
2025-07-17T13:31:01.131725810Z,2025-07-17T13:31:01.131557345Z,10,2,1108,C,A,0,13.40,10,128,168465,35203355,13.250000,11,1,13.400000,24,1,12.990000,100,1,13.670000,100,1,12.730000,100,1,13.930000,100,1,12.670000,100,1,14.000000,100,1,12.470000,100,1,14.200000,900,3,12.460000,100,1,14.260000,700,1,12.430000,700,1,14.270000,700,1,12.420000,700,1,14.290000,200,2,12.370000,700,1,14.340000,200,2,12.360000,200,2,14.430000,2,1,ARL,47164169
2025-07-17T13:31:08.376486633Z,2025-07-17T13:31:08.376321454Z,10,2,1108,C,A,0,13.40,24,130,165179,35703639,13.250000,11,1,13.670000,100,1,12.990000,100,1,13.930000,100,1,12.730000,100,1,14.000000,100,1,12.670000,100,1,14.200000,900,3,12.470000,100,1,14.260000,700,1,12.460000,100,1,14.270000,700,1,12.430000,700,1,14.290000,200,2,12.420000,700,1,14.340000,200,2,12.370000,700,1,14.430000,2,1,12.360000,200,2,14.440000,100,1,ARL,46613073
2025-07-17T13:31:08.376858048Z,2025-07-17T13:31:08.376692815Z,10,2,1108,A,A,0,13.40,18,130,165233,35703653,13.250000,11,1,13.400000,18,1,12.990000,100,1,13.670000,100,1,12.730000,100,1,13.930000,100,1,12.670000,100,1,14.000000,100,1,12.470000,100,1,14.200000,900,3,12.460000,100,1,14.260000,700,1,12.430000,700,1,14.270000,700,1,12.420000,700,1,14.290000,200,2,12.370000,700,1,14.340000,200,2,12.360000,200,2,14.430000,2,1,ARL,47873813
2025-07-17T13:31:08.377188468Z,2025-07-17T13:31:08.377022927Z,10,2,1108,C,A,7,14.29,100,0,165541,35703666,13.250000,11,1,13.400000,18,1,12.990000,100,1,13.670000,100,1,12.730000,100,1,13.930000,100,1,12.670000,100,1,14.000000,100,1,12.470000,100,1,14.200000,900,3,12.460000,100,1,14.260000,700,1,12.430000,700,1,14.270000,700,1,12.420000,700,1,14.290000,100,1,12.370000,700,1,14.340000,200,2,12.360000,200,2,14.430000,2,1,ARL,44720033
2025-07-17T13:31:08.377188468Z,2025-07-17T13:31:08.377022927Z,10,2,1108,A,A,-1,14.56,100,130,165541,35703666,13.250000,11,1,13.400000,18,1,12.990000,100,1,13.670000,100,1,12.730000,100,1,13.930000,100,1,12.670000,100,1,14.000000,100,1,12.470000,100,1,14.200000,900,3,12.460000,100,1,14.260000,700,1,12.430000,700,1,14.270000,700,1,12.420000,700,1,14.290000,100,1,12.370000,700,1,14.340000,200,2,12.360000,200,2,14.430000,2,1,ARL,47873821
2025-07-17T13:31:09.400094773Z,2025-07-17T13:31:09.399928944Z,10,2,1108,C,A,12,14.56,100,0,165829,35758774,13.250000,11,1,13.400000,18,1,12.990000,100,1,13.670000,100,1,12.730000,100,1,13.930000,100,1,12.670000,100,1,14.000000,100,1,12.470000,100,1,14.200000,900,3,12.460000,100,1,14.260000,700,1,12.430000,700,1,14.270000,700,1,12.420000,700,1,14.290000,100,1,12.370000,700,1,14.340000,200,2,12.360000,200,2,14.430000,2,1,ARL,47873821
2025-07-17T13:31:09.400094773Z,2025-07-17T13:31:09.399928944Z,10,2,1108,A,A,7,14.29,100,130,165829,35758774,13.250000,11,1,13.400000,18,1,12.990000,100,1,13.670000,100,1,12.730000,100,1,13.930000,100,1,12.670000,100,1,14.000000,100,1,12.470000,100,1,14.200000,900,3,12.460000,100,1,14.260000,700,1,12.430000,700,1,14.270000,700,1,12.420000,700,1,14.290000,200,2,12.370000,700,1,14.340000,200,2,12.360000,200,2,14.430000,2,1,ARL,47927629
2025-07-17T13:31:16.539042057Z,2025-07-17T13:31:16.538876621Z,10,2,1108,A,A,0,13.40,10,130,165436,36186495,13.250000,11,1,13.400000,28,2,12.990000,100,1,13.670000,100,1,12.730000,100,1,13.930000,100,1,12.670000,100,1,14.000000,100,1,12.470000,100,1,14.200000,900,3,12.460000,100,1,14.260000,700,1,12.430000,700,1,14.270000,700,1,12.420000,700,1,14.290000,200,2,12.370000,700,1,14.340000,200,2,12.360000,200,2,14.430000,2,1,ARL,48315949
2025-07-17T13:31:17.448727976Z,2025-07-17T13:31:17.448559991Z,10,2,1108,C,A,0,13.40,10,128,167985,36232894,13.250000,11,1,13.400000,18,1,12.990000,100,1,13.670000,100,1,12.730000,100,1,13.930000,100,1,12.670000,100,1,14.000000,100,1,12.470000,100,1,14.200000,900,3,12.460000,100,1,14.260000,700,1,12.430000,700,1,14.270000,700,1,12.420000,700,1,14.290000,200,2,12.370000,700,1,14.340000,200,2,12.360000,200,2,14.430000,2,1,ARL,48315949
2025-07-17T13:31:34.836102962Z,2025-07-17T13:31:34.835937627Z,10,2,1108,C,A,0,13.40,18,130,165335,37177882,13.250000,11,1,13.670000,100,1,12.990000,100,1,13.930000,100,1,12.730000,100,1,14.000000,100,1,12.670000,100,1,14.200000,900,3,12.470000,100,1,14.260000,700,1,12.460000,100,1,14.270000,700,1,12.430000,700,1,14.290000,200,2,12.420000,700,1,14.340000,200,2,12.370000,700,1,14.430000,2,1,12.360000,200,2,14.440000,100,1,ARL,47873813
2025-07-17T13:31:34.836860858Z,2025-07-17T13:31:34.836694504Z,10,2,1108,C,A,6,14.29,100,0,166354,37177896,13.250000,11,1,13.670000,100,1,12.990000,100,1,13.930000,100,1,12.730000,100,1,14.000000,100,1,12.670000,100,1,14.200000,900,3,12.470000,100,1,14.260000,700,1,12.460000,100,1,14.270000,700,1,12.430000,700,1,14.290000,100,1,12.420000,700,1,14.340000,200,2,12.370000,700,1,14.430000,2,1,12.360000,200,2,14.440000,100,1,ARL,44719985
2025-07-17T13:31:34.836860858Z,2025-07-17T13:31:34.836694504Z,10,2,1108,A,A,-1,14.56,100,130,166354,37177896,13.250000,11,1,13.670000,100,1,12.990000,100,1,13.930000,100,1,12.730000,100,1,14.000000,100,1,12.670000,100,1,14.200000,900,3,12.470000,100,1,14.260000,700,1,12.460000,100,1,14.270000,700,1,12.430000,700,1,14.290000,100,1,12.420000,700,1,14.340000,200,2,12.370000,700,1,14.430000,2,1,12.360000,200,2,14.440000,100,1,ARL,49226081
2025-07-17T13:31:34.837265065Z,2025-07-17T13:31:34.837099615Z,10,2,1108,C,A,6,14.29,100,0,165450,37177905,13.250000,11,1,13.670000,100,1,12.990000,100,1,13.930000,100,1,12.730000,100,1,14.000000,100,1,12.670000,100,1,14.200000,900,3,12.470000,100,1,14.260000,700,1,12.460000,100,1,14.270000,700,1,12.430000,700,1,14.340000,200,2,12.420000,700,1,14.430000,2,1,12.370000,700,1,14.440000,100,1,12.360000,200,2,14.460000,700,1,ARL,47927629
2025-07-17T13:31:34.837265065Z,2025-07-17T13:31:34.837099615Z,10,2,1108,A,A,-1,14.56,100,130,165450,37177905,13.250000,11,1,13.670000,100,1,12.990000,100,1,13.930000,100,1,12.730000,100,1,14.000000,100,1,12.670000,100,1,14.200000,900,3,12.470000,100,1,14.260000,700,1,12.460000,100,1,14.270000,700,1,12.430000,700,1,14.340000,200,2,12.420000,700,1,14.430000,2,1,12.370000,700,1,14.440000,100,1,12.360000,200,2,14.460000,700,1,ARL,49226101
2025-07-17T13:35:00.187694195Z,2025-07-17T13:35:00.187526221Z,10,2,1108,C,B,10,12.33,2,0,167974,45447658,13.250000,11,1,13.670000,100,1,12.990000,100,1,13.930000,100,1,12.730000,100,1,14.000000,100,1,12.670000,100,1,14.200000,900,3,12.470000,100,1,14.260000,700,1,12.460000,100,1,14.270000,700,1,12.430000,700,1,14.340000,200,2,12.420000,700,1,14.430000,2,1,12.370000,700,1,14.440000,100,1,12.360000,200,2,14.460000,700,1,ARL,43692153
2025-07-17T13:35:00.187694195Z,2025-07-17T13:35:00.187526221Z,10,2,1108,A,B,2,12.88,2,128,167974,45447658,13.250000,11,1,13.670000,100,1,12.990000,100,1,13.930000,100,1,12.880000,2,1,14.000000,100,1,12.730000,100,1,14.200000,900,3,12.670000,100,1,14.260000,700,1,12.470000,100,1,14.270000,700,1,12.460000,100,1,14.340000,200,2,12.430000,700,1,14.430000,2,1,12.420000,700,1,14.440000,100,1,12.370000,700,1,14.460000,700,1,ARL,58709193
2025-07-17T13:35:00.187694720Z,2025-07-17T13:35:00.187528642Z,10,2,1108,C,A,7,14.43,2,0,166078,45447661,13.250000,11,1,13.670000,100,1,12.990000,100,1,13.930000,100,1,12.880000,2,1,14.000000,100,1,12.730000,100,1,14.200000,900,3,12.670000,100,1,14.260000,700,1,12.470000,100,1,14.270000,700,1,12.460000,100,1,14.340000,200,2,12.430000,700,1,14.440000,100,1,12.420000,700,1,14.460000,700,1,12.370000,700,1,14.560000,200,2,ARL,44904733
2025-07-17T13:35:00.187694720Z,2025-07-17T13:35:00.187528642Z,10,2,1108,A,A,1,13.78,2,130,166078,45447661,13.250000,11,1,13.670000,100,1,12.990000,100,1,13.780000,2,1,12.880000,2,1,13.930000,100,1,12.730000,100,1,14.000000,100,1,12.670000,100,1,14.200000,900,3,12.470000,100,1,14.260000,700,1,12.460000,100,1,14.270000,700,1,12.430000,700,1,14.340000,200,2,12.420000,700,1,14.440000,100,1,12.370000,700,1,14.460000,700,1,ARL,58709197
2025-07-17T13:37:31.076320046Z,2025-07-17T13:37:31.076154614Z,10,2,1108,C,A,10,14.56,100,0,165432,51978366,13.250000,11,1,13.670000,100,1,12.990000,100,1,13.780000,2,1,12.880000,2,1,13.930000,100,1,12.730000,100,1,14.000000,100,1,12.670000,100,1,14.200000,900,3,12.470000,100,1,14.260000,700,1,12.460000,100,1,14.270000,700,1,12.430000,700,1,14.340000,200,2,12.420000,700,1,14.440000,100,1,12.370000,700,1,14.460000,700,1,ARL,49226101
2025-07-17T13:37:31.076320046Z,2025-07-17T13:37:31.076154614Z,10,2,1108,A,A,7,14.29,100,130,165432,51978366,13.250000,11,1,13.670000,100,1,12.990000,100,1,13.780000,2,1,12.880000,2,1,13.930000,100,1,12.730000,100,1,14.000000,100,1,12.670000,100,1,14.200000,900,3,12.470000,100,1,14.260000,700,1,12.460000,100,1,14.270000,700,1,12.430000,700,1,14.290000,100,1,12.420000,700,1,14.340000,200,2,12.370000,700,1,14.440000,100,1,ARL,65160189
2025-07-17T13:37:31.076496403Z,2025-07-17T13:37:31.076330756Z,10,2,1108,C,A,11,14.56,100,0,165647,51978372,13.250000,11,1,13.670000,100,1,12.990000,100,1,13.780000,2,1,12.880000,2,1,13.930000,100,1,12.730000,100,1,14.000000,100,1,12.670000,100,1,14.200000,900,3,12.470000,100,1,14.260000,700,1,12.460000,100,1,14.270000,700,1,12.430000,700,1,14.290000,100,1,12.420000,700,1,14.340000,200,2,12.370000,700,1,14.440000,100,1,ARL,49226081
2025-07-17T13:37:31.076496403Z,2025-07-17T13:37:31.076330756Z,10,2,1108,A,A,7,14.29,100,130,165647,51978372,13.250000,11,1,13.670000,100,1,12.990000,100,1,13.780000,2,1,12.880000,2,1,13.930000,100,1,12.730000,100,1,14.000000,100,1,12.670000,100,1,14.200000,900,3,12.470000,100,1,14.260000,700,1,12.460000,100,1,14.270000,700,1,12.430000,700,1,14.290000,200,2,12.420000,700,1,14.340000,200,2,12.370000,700,1,14.440000,100,1,ARL,65160193
2025-07-17T13:38:08.679910189Z,2025-07-17T13:38:08.679744459Z,10,2,1108,C,A,7,14.29,100,0,165730,53264917,13.250000,11,1,13.670000,100,1,12.990000,100,1,13.780000,2,1,12.880000,2,1,13.930000,100,1,12.730000,100,1,14.000000,100,1,12.670000,100,1,14.200000,900,3,12.470000,100,1,14.260000,700,1,12.460000,100,1,14.270000,700,1,12.430000,700,1,14.290000,100,1,12.420000,700,1,14.340000,200,2,12.370000,700,1,14.440000,100,1,ARL,65160189
2025-07-17T13:38:08.679910189Z,2025-07-17T13:38:08.679744459Z,10,2,1108,A,A,-1,14.56,100,130,165730,53264917,13.250000,11,1,13.670000,100,1,12.990000,100,1,13.780000,2,1,12.880000,2,1,13.930000,100,1,12.730000,100,1,14.000000,100,1,12.670000,100,1,14.200000,900,3,12.470000,100,1,14.260000,700,1,12.460000,100,1,14.270000,700,1,12.430000,700,1,14.290000,100,1,12.420000,700,1,14.340000,200,2,12.370000,700,1,14.440000,100,1,ARL,66501333
2025-07-17T13:38:08.679917832Z,2025-07-17T13:38:08.679752190Z,10,2,1108,C,A,7,14.29,100,0,165642,53264918,13.250000,11,1,13.670000,100,1,12.990000,100,1,13.780000,2,1,12.880000,2,1,13.930000,100,1,12.730000,100,1,14.000000,100,1,12.670000,100,1,14.200000,900,3,12.470000,100,1,14.260000,700,1,12.460000,100,1,14.270000,700,1,12.430000,700,1,14.340000,200,2,12.420000,700,1,14.440000,100,1,12.370000,700,1,14.460000,700,1,ARL,65160193
2025-07-17T13:38:08.679917832Z,2025-07-17T13:38:08.679752190Z,10,2,1108,A,A,-1,14.56,100,130,165642,53264918,13.250000,11,1,13.670000,100,1,12.990000,100,1,13.780000,2,1,12.880000,2,1,13.930000,100,1,12.730000,100,1,14.000000,100,1,12.670000,100,1,14.200000,900,3,12.470000,100,1,14.260000,700,1,12.460000,100,1,14.270000,700,1,12.430000,700,1,14.340000,200,2,12.420000,700,1,14.440000,100,1,12.370000,700,1,14.460000,700,1,ARL,66501341
2025-07-17T13:38:09.687028970Z,2025-07-17T13:38:09.686863512Z,10,2,1108,C,A,10,14.56,100,0,165458,53302839,13.250000,11,1,13.670000,100,1,12.990000,100,1,13.780000,2,1,12.880000,2,1,13.930000,100,1,12.730000,100,1,14.000000,100,1,12.670000,100,1,14.200000,900,3,12.470000,100,1,14.260000,700,1,12.460000,100,1,14.270000,700,1,12.430000,700,1,14.340000,200,2,12.420000,700,1,14.440000,100,1,12.370000,700,1,14.460000,700,1,ARL,66501333
2025-07-17T13:38:09.687028970Z,2025-07-17T13:38:09.686863512Z,10,2,1108,A,A,7,14.29,100,130,165458,53302839,13.250000,11,1,13.670000,100,1,12.990000,100,1,13.780000,2,1,12.880000,2,1,13.930000,100,1,12.730000,100,1,14.000000,100,1,12.670000,100,1,14.200000,900,3,12.470000,100,1,14.260000,700,1,12.460000,100,1,14.270000,700,1,12.430000,700,1,14.290000,100,1,12.420000,700,1,14.340000,200,2,12.370000,700,1,14.440000,100,1,ARL,66538149
2025-07-17T13:38:09.708195003Z,2025-07-17T13:38:09.708029202Z,10,2,1108,C,A,11,14.56,100,0,165801,53303094,13.250000,11,1,13.670000,100,1,12.990000,100,1,13.780000,2,1,12.880000,2,1,13.930000,100,1,12.730000,100,1,14.000000,100,1,12.670000,100,1,14.200000,900,3,12.470000,100,1,14.260000,700,1,12.460000,100,1,14.270000,700,1,12.430000,700,1,14.290000,100,1,12.420000,700,1,14.340000,200,2,12.370000,700,1,14.440000,100,1,ARL,66501341
2025-07-17T13:38:09.708195003Z,2025-07-17T13:38:09.708029202Z,10,2,1108,A,A,7,14.29,100,130,165801,53303094,13.250000,11,1,13.670000,100,1,12.990000,100,1,13.780000,2,1,12.880000,2,1,13.930000,100,1,12.730000,100,1,14.000000,100,1,12.670000,100,1,14.200000,900,3,12.470000,100,1,14.260000,700,1,12.460000,100,1,14.270000,700,1,12.430000,700,1,14.290000,200,2,12.420000,700,1,14.340000,200,2,12.370000,700,1,14.440000,100,1,ARL,66538573
2025-07-17T13:38:44.679122862Z,2025-07-17T13:38:44.678957477Z,10,2,1108,A,A,0,13.40,15,130,165385,54485050,13.250000,11,1,13.400000,15,1,12.990000,100,1,13.670000,100,1,12.880000,2,1,13.780000,2,1,12.730000,100,1,13.930000,100,1,12.670000,100,1,14.000000,100,1,12.470000,100,1,14.200000,900,3,12.460000,100,1,14.260000,700,1,12.430000,700,1,14.270000,700,1,12.420000,700,1,14.290000,200,2,12.370000,700,1,14.340000,200,2,ARL,67832461
2025-07-17T13:38:44.679444346Z,2025-07-17T13:38:44.679278833Z,10,2,1108,C,A,8,14.29,100,0,165513,54485052,13.250000,11,1,13.400000,15,1,12.990000,100,1,13.670000,100,1,12.880000,2,1,13.780000,2,1,12.730000,100,1,13.930000,100,1,12.670000,100,1,14.000000,100,1,12.470000,100,1,14.200000,900,3,12.460000,100,1,14.260000,700,1,12.430000,700,1,14.270000,700,1,12.420000,700,1,14.290000,100,1,12.370000,700,1,14.340000,200,2,ARL,66538149
2025-07-17T13:38:44.679444346Z,2025-07-17T13:38:44.679278833Z,10,2,1108,A,A,-1,14.56,100,130,165513,54485052,13.250000,11,1,13.400000,15,1,12.990000,100,1,13.670000,100,1,12.880000,2,1,13.780000,2,1,12.730000,100,1,13.930000,100,1,12.670000,100,1,14.000000,100,1,12.470000,100,1,14.200000,900,3,12.460000,100,1,14.260000,700,1,12.430000,700,1,14.270000,700,1,12.420000,700,1,14.290000,100,1,12.370000,700,1,14.340000,200,2,ARL,67832465
2025-07-17T13:38:45.695430520Z,2025-07-17T13:38:45.695265148Z,10,2,1108,C,A,12,14.56,100,0,165372,54508575,13.250000,11,1,13.400000,15,1,12.990000,100,1,13.670000,100,1,12.880000,2,1,13.780000,2,1,12.730000,100,1,13.930000,100,1,12.670000,100,1,14.000000,100,1,12.470000,100,1,14.200000,900,3,12.460000,100,1,14.260000,700,1,12.430000,700,1,14.270000,700,1,12.420000,700,1,14.290000,100,1,12.370000,700,1,14.340000,200,2,ARL,67832465
2025-07-17T13:38:45.695430520Z,2025-07-17T13:38:45.695265148Z,10,2,1108,A,A,8,14.29,100,130,165372,54508575,13.250000,11,1,13.400000,15,1,12.990000,100,1,13.670000,100,1,12.880000,2,1,13.780000,2,1,12.730000,100,1,13.930000,100,1,12.670000,100,1,14.000000,100,1,12.470000,100,1,14.200000,900,3,12.460000,100,1,14.260000,700,1,12.430000,700,1,14.270000,700,1,12.420000,700,1,14.290000,200,2,12.370000,700,1,14.340000,200,2,ARL,67857641
2025-07-17T13:39:08.714072882Z,2025-07-17T13:39:08.713907562Z,10,2,1108,C,A,0,13.40,15,130,165320,55204868,13.250000,11,1,13.670000,100,1,12.990000,100,1,13.780000,2,1,12.880000,2,1,13.930000,100,1,12.730000,100,1,14.000000,100,1,12.670000,100,1,14.200000,900,3,12.470000,100,1,14.260000,700,1,12.460000,100,1,14.270000,700,1,12.430000,700,1,14.290000,200,2,12.420000,700,1,14.340000,200,2,12.370000,700,1,14.440000,100,1,ARL,67832461
2025-07-17T13:39:08.714449550Z,2025-07-17T13:39:08.714284059Z,10,2,1108,A,A,0,13.40,24,130,165491,55204884,13.250000,11,1,13.400000,24,1,12.990000,100,1,13.670000,100,1,12.880000,2,1,13.780000,2,1,12.730000,100,1,13.930000,100,1,12.670000,100,1,14.000000,100,1,12.470000,100,1,14.200000,900,3,12.460000,100,1,14.260000,700,1,12.430000,700,1,14.270000,700,1,12.420000,700,1,14.290000,200,2,12.370000,700,1,14.340000,200,2,ARL,68625181
2025-07-17T13:39:39.996603180Z,2025-07-17T13:39:39.996436857Z,10,2,1108,T,A,0,13.40,1,130,166323,56150102,13.250000,11,1,13.670000,100,1,12.990000,100,1,13.780000,2,1,12.880000,2,1,13.930000,100,1,12.730000,100,1,14.000000,100,1,12.670000,100,1,14.200000,900,3,12.470000,100,1,14.260000,700,1,12.460000,100,1,14.270000,700,1,12.430000,700,1,14.290000,200,2,12.420000,700,1,14.340000,200,2,12.370000,700,1,14.440000,100,1,ARL,68625181
2025-07-17T13:39:39.996998334Z,2025-07-17T13:39:39.996833282Z,10,2,1108,C,A,-1,13.40,23,130,165052,56150114,13.250000,11,1,13.670000,100,1,12.990000,100,1,13.780000,2,1,12.880000,2,1,13.930000,100,1,12.730000,100,1,14.000000,100,1,12.670000,100,1,14.200000,900,3,12.470000,100,1,14.260000,700,1,12.460000,100,1,14.270000,700,1,12.430000,700,1,14.290000,200,2,12.420000,700,1,14.340000,200,2,12.370000,700,1,14.440000,100,1,ARL,68625181
2025-07-17T13:39:39.997309515Z,2025-07-17T13:39:39.997144158Z,10,2,1108,C,A,7,14.29,100,0,165357,56150130,13.250000,11,1,13.670000,100,1,12.990000,100,1,13.780000,2,1,12.880000,2,1,13.930000,100,1,12.730000,100,1,14.000000,100,1,12.670000,100,1,14.200000,900,3,12.470000,100,1,14.260000,700,1,12.460000,100,1,14.270000,700,1,12.430000,700,1,14.290000,100,1,12.420000,700,1,14.340000,200,2,12.370000,700,1,14.440000,100,1,ARL,66538573
2025-07-17T13:39:39.997309515Z,2025-07-17T13:39:39.997144158Z,10,2,1108,A,A,-1,14.57,100,130,165357,56150130,13.250000,11,1,13.670000,100,1,12.990000,100,1,13.780000,2,1,12.880000,2,1,13.930000,100,1,12.730000,100,1,14.000000,100,1,12.670000,100,1,14.200000,900,3,12.470000,100,1,14.260000,700,1,12.460000,100,1,14.270000,700,1,12.430000,700,1,14.290000,100,1,12.420000,700,1,14.340000,200,2,12.370000,700,1,14.440000,100,1,ARL,69677517
2025-07-17T13:39:39.997376873Z,2025-07-17T13:39:39.997211562Z,10,2,1108,A,A,0,13.40,24,130,165311,56150131,13.250000,11,1,13.400000,24,1,12.990000,100,1,13.670000,100,1,12.880000,2,1,13.780000,2,1,12.730000,100,1,13.930000,100,1,12.670000,100,1,14.000000,100,1,12.470000,100,1,14.200000,900,3,12.460000,100,1,14.260000,700,1,12.430000,700,1,14.270000,700,1,12.420000,700,1,14.290000,100,1,12.370000,700,1,14.340000,200,2,ARL,69677521
2025-07-17T13:39:41.018948933Z,2025-07-17T13:39:41.018783466Z,10,2,1108,C,A,12,14.57,100,0,165467,56183429,13.250000,11,1,13.400000,24,1,12.990000,100,1,13.670000,100,1,12.880000,2,1,13.780000,2,1,12.730000,100,1,13.930000,100,1,12.670000,100,1,14.000000,100,1,12.470000,100,1,14.200000,900,3,12.460000,100,1,14.260000,700,1,12.430000,700,1,14.270000,700,1,12.420000,700,1,14.290000,100,1,12.370000,700,1,14.340000,200,2,ARL,69677517
2025-07-17T13:39:41.018948933Z,2025-07-17T13:39:41.018783466Z,10,2,1108,A,A,9,14.30,100,130,165467,56183429,13.250000,11,1,13.400000,24,1,12.990000,100,1,13.670000,100,1,12.880000,2,1,13.780000,2,1,12.730000,100,1,13.930000,100,1,12.670000,100,1,14.000000,100,1,12.470000,100,1,14.200000,900,3,12.460000,100,1,14.260000,700,1,12.430000,700,1,14.270000,700,1,12.420000,700,1,14.290000,100,1,12.370000,700,1,14.300000,100,1,ARL,69725541
2025-07-17T13:40:08.782549047Z,2025-07-17T13:40:08.782383621Z,10,2,1108,C,A,0,13.40,24,130,165426,57235944,13.250000,11,1,13.670000,100,1,12.990000,100,1,13.780000,2,1,12.880000,2,1,13.930000,100,1,12.730000,100,1,14.000000,100,1,12.670000,100,1,14.200000,900,3,12.470000,100,1,14.260000,700,1,12.460000,100,1,14.270000,700,1,12.430000,700,1,14.290000,100,1,12.420000,700,1,14.300000,100,1,12.370000,700,1,14.340000,200,2,ARL,69677521
2025-07-17T13:40:08.782923978Z,2025-07-17T13:40:08.782758499Z,10,2,1108,A,A,0,13.40,18,130,165479,57235956,13.250000,11,1,13.400000,18,1,12.990000,100,1,13.670000,100,1,12.880000,2,1,13.780000,2,1,12.730000,100,1,13.930000,100,1,12.670000,100,1,14.000000,100,1,12.470000,100,1,14.200000,900,3,12.460000,100,1,14.260000,700,1,12.430000,700,1,14.270000,700,1,12.420000,700,1,14.290000,100,1,12.370000,700,1,14.300000,100,1,ARL,70897053
2025-07-17T13:41:08.818876572Z,2025-07-17T13:41:08.818711250Z,10,2,1108,C,A,0,13.40,18,130,165322,59313726,13.250000,11,1,13.670000,100,1,12.990000,100,1,13.780000,2,1,12.880000,2,1,13.930000,100,1,12.730000,100,1,14.000000,100,1,12.670000,100,1,14.200000,900,3,12.470000,100,1,14.260000,700,1,12.460000,100,1,14.270000,700,1,12.430000,700,1,14.290000,100,1,12.420000,700,1,14.300000,100,1,12.370000,700,1,14.340000,200,2,ARL,70897053
2025-07-17T13:41:08.819249545Z,2025-07-17T13:41:08.819083504Z,10,2,1108,A,A,0,13.40,24,130,166041,59313736,13.250000,11,1,13.400000,24,1,12.990000,100,1,13.670000,100,1,12.880000,2,1,13.780000,2,1,12.730000,100,1,13.930000,100,1,12.670000,100,1,14.000000,100,1,12.470000,100,1,14.200000,900,3,12.460000,100,1,14.260000,700,1,12.430000,700,1,14.270000,700,1,12.420000,700,1,14.290000,100,1,12.370000,700,1,14.300000,100,1,ARL,73109413
2025-07-17T13:41:08.819270512Z,2025-07-17T13:41:08.819104931Z,10,2,1108,C,A,9,14.30,100,0,165581,59313739,13.250000,11,1,13.400000,24,1,12.990000,100,1,13.670000,100,1,12.880000,2,1,13.780000,2,1,12.730000,100,1,13.930000,100,1,12.670000,100,1,14.000000,100,1,12.470000,100,1,14.200000,900,3,12.460000,100,1,14.260000,700,1,12.430000,700,1,14.270000,700,1,12.420000,700,1,14.290000,100,1,12.370000,700,1,14.340000,200,2,ARL,69725541
2025-07-17T13:41:08.819270512Z,2025-07-17T13:41:08.819104931Z,10,2,1108,A,A,-1,14.57,100,130,165581,59313739,13.250000,11,1,13.400000,24,1,12.990000,100,1,13.670000,100,1,12.880000,2,1,13.780000,2,1,12.730000,100,1,13.930000,100,1,12.670000,100,1,14.000000,100,1,12.470000,100,1,14.200000,900,3,12.460000,100,1,14.260000,700,1,12.430000,700,1,14.270000,700,1,12.420000,700,1,14.290000,100,1,12.370000,700,1,14.340000,200,2,ARL,73109417
2025-07-17T13:41:09.881251193Z,2025-07-17T13:41:09.881085734Z,10,2,1108,C,A,12,14.57,100,0,165459,59383199,13.250000,11,1,13.400000,24,1,12.990000,100,1,13.670000,100,1,12.880000,2,1,13.780000,2,1,12.730000,100,1,13.930000,100,1,12.670000,100,1,14.000000,100,1,12.470000,100,1,14.200000,900,3,12.460000,100,1,14.260000,700,1,12.430000,700,1,14.270000,700,1,12.420000,700,1,14.290000,100,1,12.370000,700,1,14.340000,200,2,ARL,73109417
2025-07-17T13:41:09.881251193Z,2025-07-17T13:41:09.881085734Z,10,2,1108,A,A,9,14.30,100,130,165459,59383199,13.250000,11,1,13.400000,24,1,12.990000,100,1,13.670000,100,1,12.880000,2,1,13.780000,2,1,12.730000,100,1,13.930000,100,1,12.670000,100,1,14.000000,100,1,12.470000,100,1,14.200000,900,3,12.460000,100,1,14.260000,700,1,12.430000,700,1,14.270000,700,1,12.420000,700,1,14.290000,100,1,12.370000,700,1,14.300000,100,1,ARL,73183421
2025-07-17T13:41:44.348660105Z,2025-07-17T13:41:44.348494744Z,10,2,1108,C,A,0,13.40,24,130,165361,60614543,13.250000,11,1,13.670000,100,1,12.990000,100,1,13.780000,2,1,12.880000,2,1,13.930000,100,1,12.730000,100,1,14.000000,100,1,12.670000,100,1,14.200000,900,3,12.470000,100,1,14.260000,700,1,12.460000,100,1,14.270000,700,1,12.430000,700,1,14.290000,100,1,12.420000,700,1,14.300000,100,1,12.370000,700,1,14.340000,200,2,ARL,73109413
2025-07-17T13:41:44.349581977Z,2025-07-17T13:41:44.349416601Z,10,2,1108,C,A,8,14.30,100,0,165376,60614557,13.250000,11,1,13.670000,100,1,12.990000,100,1,13.780000,2,1,12.880000,2,1,13.930000,100,1,12.730000,100,1,14.000000,100,1,12.670000,100,1,14.200000,900,3,12.470000,100,1,14.260000,700,1,12.460000,100,1,14.270000,700,1,12.430000,700,1,14.290000,100,1,12.420000,700,1,14.340000,200,2,12.370000,700,1,14.440000,100,1,ARL,73183421
2025-07-17T13:41:44.349581977Z,2025-07-17T13:41:44.349416601Z,10,2,1108,A,A,-1,14.57,100,130,165376,60614557,13.250000,11,1,13.670000,100,1,12.990000,100,1,13.780000,2,1,12.880000,2,1,13.930000,100,1,12.730000,100,1,14.000000,100,1,12.670000,100,1,14.200000,900,3,12.470000,100,1,14.260000,700,1,12.460000,100,1,14.270000,700,1,12.430000,700,1,14.290000,100,1,12.420000,700,1,14.340000,200,2,12.370000,700,1,14.440000,100,1,ARL,74549681
2025-07-17T13:41:45.405178844Z,2025-07-17T13:41:45.405013016Z,10,2,1108,C,A,11,14.57,100,0,165828,60651462,13.250000,11,1,13.670000,100,1,12.990000,100,1,13.780000,2,1,12.880000,2,1,13.930000,100,1,12.730000,100,1,14.000000,100,1,12.670000,100,1,14.200000,900,3,12.470000,100,1,14.260000,700,1,12.460000,100,1,14.270000,700,1,12.430000,700,1,14.290000,100,1,12.420000,700,1,14.340000,200,2,12.370000,700,1,14.440000,100,1,ARL,74549681
2025-07-17T13:41:45.405178844Z,2025-07-17T13:41:45.405013016Z,10,2,1108,A,A,8,14.30,100,130,165828,60651462,13.250000,11,1,13.670000,100,1,12.990000,100,1,13.780000,2,1,12.880000,2,1,13.930000,100,1,12.730000,100,1,14.000000,100,1,12.670000,100,1,14.200000,900,3,12.470000,100,1,14.260000,700,1,12.460000,100,1,14.270000,700,1,12.430000,700,1,14.290000,100,1,12.420000,700,1,14.300000,100,1,12.370000,700,1,14.340000,200,2,ARL,74589605
2025-07-17T13:42:08.821320823Z,2025-07-17T13:42:08.821155108Z,10,2,1108,C,A,7,14.29,100,0,165715,61488742,13.250000,11,1,13.670000,100,1,12.990000,100,1,13.780000,2,1,12.880000,2,1,13.930000,100,1,12.730000,100,1,14.000000,100,1,12.670000,100,1,14.200000,900,3,12.470000,100,1,14.260000,700,1,12.460000,100,1,14.270000,700,1,12.430000,700,1,14.300000,100,1,12.420000,700,1,14.340000,200,2,12.370000,700,1,14.440000,100,1,ARL,67857641
2025-07-17T13:42:08.821320823Z,2025-07-17T13:42:08.821155108Z,10,2,1108,A,A,-1,14.57,100,130,165715,61488742,13.250000,11,1,13.670000,100,1,12.990000,100,1,13.780000,2,1,12.880000,2,1,13.930000,100,1,12.730000,100,1,14.000000,100,1,12.670000,100,1,14.200000,900,3,12.470000,100,1,14.260000,700,1,12.460000,100,1,14.270000,700,1,12.430000,700,1,14.300000,100,1,12.420000,700,1,14.340000,200,2,12.370000,700,1,14.440000,100,1,ARL,75537553
2025-07-17T13:42:09.827057338Z,2025-07-17T13:42:09.826891682Z,10,2,1108,C,A,11,14.57,100,0,165656,61523538,13.250000,11,1,13.670000,100,1,12.990000,100,1,13.780000,2,1,12.880000,2,1,13.930000,100,1,12.730000,100,1,14.000000,100,1,12.670000,100,1,14.200000,900,3,12.470000,100,1,14.260000,700,1,12.460000,100,1,14.270000,700,1,12.430000,700,1,14.300000,100,1,12.420000,700,1,14.340000,200,2,12.370000,700,1,14.440000,100,1,ARL,75537553
2025-07-17T13:42:09.827057338Z,2025-07-17T13:42:09.826891682Z,10,2,1108,A,A,7,14.30,100,130,165656,61523538,13.250000,11,1,13.670000,100,1,12.990000,100,1,13.780000,2,1,12.880000,2,1,13.930000,100,1,12.730000,100,1,14.000000,100,1,12.670000,100,1,14.200000,900,3,12.470000,100,1,14.260000,700,1,12.460000,100,1,14.270000,700,1,12.430000,700,1,14.300000,200,2,12.420000,700,1,14.340000,200,2,12.370000,700,1,14.440000,100,1,ARL,75577257
2025-07-17T13:43:08.826244125Z,2025-07-17T13:43:08.826078491Z,10,2,1108,C,A,7,14.30,100,0,165634,63579150,13.250000,11,1,13.670000,100,1,12.990000,100,1,13.780000,2,1,12.880000,2,1,13.930000,100,1,12.730000,100,1,14.000000,100,1,12.670000,100,1,14.200000,900,3,12.470000,100,1,14.260000,700,1,12.460000,100,1,14.270000,700,1,12.430000,700,1,14.300000,100,1,12.420000,700,1,14.340000,200,2,12.370000,700,1,14.440000,100,1,ARL,75577257
2025-07-17T13:43:08.826244125Z,2025-07-17T13:43:08.826078491Z,10,2,1108,A,A,-1,14.57,100,130,165634,63579150,13.250000,11,1,13.670000,100,1,12.990000,100,1,13.780000,2,1,12.880000,2,1,13.930000,100,1,12.730000,100,1,14.000000,100,1,12.670000,100,1,14.200000,900,3,12.470000,100,1,14.260000,700,1,12.460000,100,1,14.270000,700,1,12.430000,700,1,14.300000,100,1,12.420000,700,1,14.340000,200,2,12.370000,700,1,14.440000,100,1,ARL,77879933
2025-07-17T13:43:09.832572415Z,2025-07-17T13:43:09.832406764Z,10,2,1108,C,A,11,14.57,100,0,165651,63604352,13.250000,11,1,13.670000,100,1,12.990000,100,1,13.780000,2,1,12.880000,2,1,13.930000,100,1,12.730000,100,1,14.000000,100,1,12.670000,100,1,14.200000,900,3,12.470000,100,1,14.260000,700,1,12.460000,100,1,14.270000,700,1,12.430000,700,1,14.300000,100,1,12.420000,700,1,14.340000,200,2,12.370000,700,1,14.440000,100,1,ARL,77879933
2025-07-17T13:43:09.832572415Z,2025-07-17T13:43:09.832406764Z,10,2,1108,A,A,7,14.30,100,130,165651,63604352,13.250000,11,1,13.670000,100,1,12.990000,100,1,13.780000,2,1,12.880000,2,1,13.930000,100,1,12.730000,100,1,14.000000,100,1,12.670000,100,1,14.200000,900,3,12.470000,100,1,14.260000,700,1,12.460000,100,1,14.270000,700,1,12.430000,700,1,14.300000,200,2,12.420000,700,1,14.340000,200,2,12.370000,700,1,14.440000,100,1,ARL,77910357
2025-07-17T13:46:09.541016899Z,2025-07-17T13:46:09.540851349Z,10,2,1108,C,A,4,14.20,700,130,165550,69578535,13.250000,11,1,13.670000,100,1,12.990000,100,1,13.780000,2,1,12.880000,2,1,13.930000,100,1,12.730000,100,1,14.000000,100,1,12.670000,100,1,14.200000,200,2,12.470000,100,1,14.260000,700,1,12.460000,100,1,14.270000,700,1,12.430000,700,1,14.300000,200,2,12.420000,700,1,14.340000,200,2,12.370000,700,1,14.440000,100,1,ARL,47376925
2025-07-17T13:46:09.541058233Z,2025-07-17T13:46:09.540892810Z,10,2,1108,A,A,9,14.36,700,130,165423,69578537,13.250000,11,1,13.670000,100,1,12.990000,100,1,13.780000,2,1,12.880000,2,1,13.930000,100,1,12.730000,100,1,14.000000,100,1,12.670000,100,1,14.200000,200,2,12.470000,100,1,14.260000,700,1,12.460000,100,1,14.270000,700,1,12.430000,700,1,14.300000,200,2,12.420000,700,1,14.340000,200,2,12.370000,700,1,14.360000,700,1,ARL,84607761
2025-07-17T13:46:09.541097538Z,2025-07-17T13:46:09.540932260Z,10,2,1108,A,A,-1,15.59,100,130,165278,69578539,13.250000,11,1,13.670000,100,1,12.990000,100,1,13.780000,2,1,12.880000,2,1,13.930000,100,1,12.730000,100,1,14.000000,100,1,12.670000,100,1,14.200000,200,2,12.470000,100,1,14.260000,700,1,12.460000,100,1,14.270000,700,1,12.430000,700,1,14.300000,200,2,12.420000,700,1,14.340000,200,2,12.370000,700,1,14.360000,700,1,ARL,84607765
2025-07-17T13:46:09.541109881Z,2025-07-17T13:46:09.540944549Z,10,2,1108,C,A,13,15.28,100,130,165332,69578540,13.250000,11,1,13.670000,100,1,12.990000,100,1,13.780000,2,1,12.880000,2,1,13.930000,100,1,12.730000,100,1,14.000000,100,1,12.670000,100,1,14.200000,200,2,12.470000,100,1,14.260000,700,1,12.460000,100,1,14.270000,700,1,12.430000,700,1,14.300000,200,2,12.420000,700,1,14.340000,200,2,12.370000,700,1,14.360000,700,1,ARL,43373085
2025-07-17T13:46:09.541434576Z,2025-07-17T13:46:09.541269186Z,10,2,1108,C,A,10,14.44,100,0,165390,69578543,13.250000,11,1,13.670000,100,1,12.990000,100,1,13.780000,2,1,12.880000,2,1,13.930000,100,1,12.730000,100,1,14.000000,100,1,12.670000,100,1,14.200000,200,2,12.470000,100,1,14.260000,700,1,12.460000,100,1,14.270000,700,1,12.430000,700,1,14.300000,200,2,12.420000,700,1,14.340000,200,2,12.370000,700,1,14.360000,700,1,ARL,43373009
