ts_recv,ts_event,rtype,publisher_id,instrument_id,action,side,depth,price,size,flags,ts_in_delta,sequence,bid_px_00,bid_sz_00,bid_ct_00,ask_px_00,ask_sz_00,ask_ct_00,bid_px_01,bid_sz_01,bid_ct_01,ask_px_01,ask_sz_01,ask_ct_01,bid_px_02,bid_sz_02,bid_ct_02,ask_px_02,ask_sz_02,ask_ct_02,bid_px_03,bid_sz_03,bid_ct_03,ask_px_03,ask_sz_03,ask_ct_03,bid_px_04,bid_sz_04,bid_ct_04,ask_px_04,ask_sz_04,ask_ct_04,bid_px_05,bid_sz_05,bid_ct_05,ask_px_05,ask_sz_05,ask_ct_05,bid_px_06,bid_sz_06,bid_ct_06,ask_px_06,ask_sz_06,ask_ct_06,bid_px_07,bid_sz_07,bid_ct_07,ask_px_07,ask_sz_07,ask_ct_07,bid_px_08,bid_sz_08,bid_ct_08,ask_px_08,ask_sz_08,ask_ct_08,bid_px_09,bid_sz_09,bid_ct_09,ask_px_09,ask_sz_09,ask_ct_09,symbol,order_id
2025-07-17T13:46:09.541434576Z,2025-07-17T13:46:09.541269186Z,10,2,1108,A,A,-1,14.49,100,130,165390,69578543,13.250000,11,1,13.670000,100,1,12.990000,100,1,13.780000,2,1,12.880000,2,1,13.930000,100,1,12.730000,100,1,14.000000,100,1,12.670000,100,1,14.200000,200,2,12.470000,100,1,14.260000,700,1,12.460000,100,1,14.270000,700,1,12.430000,700,1,14.300000,200,2,12.420000,700,1,14.340000,200,2,12.370000,700,1,14.360000,700,1,ARL,84607785
2025-07-17T13:46:09.541492629Z,2025-07-17T13:46:09.541327298Z,10,2,1108,C,A,3,14.00,100,130,165331,69578544,13.250000,11,1,13.670000,100,1,12.990000,100,1,13.780000,2,1,12.880000,2,1,13.930000,100,1,12.730000,100,1,14.200000,200,2,12.670000,100,1,14.260000,700,1,12.470000,100,1,14.270000,700,1,12.460000,100,1,14.300000,200,2,12.430000,700,1,14.340000,200,2,12.420000,700,1,14.360000,700,1,12.370000,700,1,14.460000,700,1,ARL,43663233
2025-07-17T13:46:09.541795256Z,2025-07-17T13:46:09.541629920Z,10,2,1108,C,A,7,14.34,100,0,165336,69578547,13.250000,11,1,13.670000,100,1,12.990000,100,1,13.780000,2,1,12.880000,2,1,13.930000,100,1,12.730000,100,1,14.200000,200,2,12.670000,100,1,14.260000,700,1,12.470000,100,1,14.270000,700,1,12.460000,100,1,14.300000,200,2,12.430000,700,1,14.340000,100,1,12.420000,700,1,14.360000,700,1,12.370000,700,1,14.460000,700,1,ARL,43755821
2025-07-17T13:46:09.541795256Z,2025-07-17T13:46:09.541629920Z,10,2,1108,A,A,-1,14.63,100,130,165336,69578547,13.250000,11,1,13.670000,100,1,12.990000,100,1,13.780000,2,1,12.880000,2,1,13.930000,100,1,12.730000,100,1,14.200000,200,2,12.670000,100,1,14.260000,700,1,12.470000,100,1,14.270000,700,1,12.460000,100,1,14.300000,200,2,12.430000,700,1,14.340000,100,1,12.420000,700,1,14.360000,700,1,12.370000,700,1,14.460000,700,1,ARL,84607801
2025-07-17T13:46:09.541846554Z,2025-07-17T13:46:09.541680473Z,10,2,1108,C,A,12,14.74,100,0,166081,69578550,13.250000,11,1,13.670000,100,1,12.990000,100,1,13.780000,2,1,12.880000,2,1,13.930000,100,1,12.730000,100,1,14.200000,200,2,12.670000,100,1,14.260000,700,1,12.470000,100,1,14.270000,700,1,12.460000,100,1,14.300000,200,2,12.430000,700,1,14.340000,100,1,12.420000,700,1,14.360000,700,1,12.370000,700,1,14.460000,700,1,ARL,43357029
2025-07-17T13:46:09.541846554Z,2025-07-17T13:46:09.541680473Z,10,2,1108,A,A,-1,15.04,100,130,166081,69578550,13.250000,11,1,13.670000,100,1,12.990000,100,1,13.780000,2,1,12.880000,2,1,13.930000,100,1,12.730000,100,1,14.200000,200,2,12.670000,100,1,14.260000,700,1,12.470000,100,1,14.270000,700,1,12.460000,100,1,14.300000,200,2,12.430000,700,1,14.340000,100,1,12.420000,700,1,14.360000,700,1,12.370000,700,1,14.460000,700,1,ARL,84607805
2025-07-17T13:46:09.541847519Z,2025-07-17T13:46:09.541682402Z,10,2,1108,A,A,6,14.28,100,130,165117,69578551,13.250000,11,1,13.670000,100,1,12.990000,100,1,13.780000,2,1,12.880000,2,1,13.930000,100,1,12.730000,100,1,14.200000,200,2,12.670000,100,1,14.260000,700,1,12.470000,100,1,14.270000,700,1,12.460000,100,1,14.280000,100,1,12.430000,700,1,14.300000,200,2,12.420000,700,1,14.340000,100,1,12.370000,700,1,14.360000,700,1,ARL,84607809
2025-07-17T13:46:09.542961756Z,2025-07-17T13:46:09.542796050Z,10,2,1108,C,A,16,15.41,100,0,165706,69578574,13.250000,11,1,13.670000,100,1,12.990000,100,1,13.780000,2,1,12.880000,2,1,13.930000,100,1,12.730000,100,1,14.200000,200,2,12.670000,100,1,14.260000,700,1,12.470000,100,1,14.270000,700,1,12.460000,100,1,14.280000,100,1,12.430000,700,1,14.300000,200,2,12.420000,700,1,14.340000,100,1,12.370000,700,1,14.360000,700,1,ARL,43826805
2025-07-17T13:46:09.542961756Z,2025-07-17T13:46:09.542796050Z,10,2,1108,A,A,-1,15.73,100,130,165706,69578574,13.250000,11,1,13.670000,100,1,12.990000,100,1,13.780000,2,1,12.880000,2,1,13.930000,100,1,12.730000,100,1,14.200000,200,2,12.670000,100,1,14.260000,700,1,12.470000,100,1,14.270000,700,1,12.460000,100,1,14.280000,100,1,12.430000,700,1,14.300000,200,2,12.420000,700,1,14.340000,100,1,12.370000,700,1,14.360000,700,1,ARL,84607837
2025-07-17T13:46:09.543510155Z,2025-07-17T13:46:09.543344724Z,10,2,1108,C,A,19,17.02,100,0,165431,69578598,13.250000,11,1,13.670000,100,1,12.990000,100,1,13.780000,2,1,12.880000,2,1,13.930000,100,1,12.730000,100,1,14.200000,200,2,12.670000,100,1,14.260000,700,1,12.470000,100,1,14.270000,700,1,12.460000,100,1,14.280000,100,1,12.430000,700,1,14.300000,200,2,12.420000,700,1,14.340000,100,1,12.370000,700,1,14.360000,700,1,ARL,44082969
2025-07-17T13:46:09.543510155Z,2025-07-17T13:46:09.543344724Z,10,2,1108,A,A,-1,17.37,100,130,165431,69578598,13.250000,11,1,13.670000,100,1,12.990000,100,1,13.780000,2,1,12.880000,2,1,13.930000,100,1,12.730000,100,1,14.200000,200,2,12.670000,100,1,14.260000,700,1,12.470000,100,1,14.270000,700,1,12.460000,100,1,14.280000,100,1,12.430000,700,1,14.300000,200,2,12.420000,700,1,14.340000,100,1,12.370000,700,1,14.360000,700,1,ARL,84607861
2025-07-17T13:46:09.546546482Z,2025-07-17T13:46:09.546381306Z,10,2,1108,C,A,3,14.20,100,130,165176,69578814,13.250000,11,1,13.670000,100,1,12.990000,100,1,13.780000,2,1,12.880000,2,1,13.930000,100,1,12.730000,100,1,14.200000,100,1,12.670000,100,1,14.260000,700,1,12.470000,100,1,14.270000,700,1,12.460000,100,1,14.280000,100,1,12.430000,700,1,14.300000,200,2,12.420000,700,1,14.340000,100,1,12.370000,700,1,14.360000,700,1,ARL,43554141
2025-07-17T13:46:09.546656996Z,2025-07-17T13:46:09.546491223Z,10,2,1108,A,A,-1,14.47,100,130,165773,69578831,13.250000,11,1,13.670000,100,1,12.990000,100,1,13.780000,2,1,12.880000,2,1,13.930000,100,1,12.730000,100,1,14.200000,100,1,12.670000,100,1,14.260000,700,1,12.470000,100,1,14.270000,700,1,12.460000,100,1,14.280000,100,1,12.430000,700,1,14.300000,200,2,12.420000,700,1,14.340000,100,1,12.370000,700,1,14.360000,700,1,ARL,84608321
2025-07-17T13:46:09.560918620Z,2025-07-17T13:46:09.560753276Z,10,2,1108,C,A,0,13.67,100,130,165344,69579444,13.250000,11,1,13.780000,2,1,12.990000,100,1,13.930000,100,1,12.880000,2,1,14.200000,100,1,12.730000,100,1,14.260000,700,1,12.670000,100,1,14.270000,700,1,12.470000,100,1,14.280000,100,1,12.460000,100,1,14.300000,200,2,12.430000,700,1,14.340000,100,1,12.420000,700,1,14.360000,700,1,12.370000,700,1,14.460000,700,1,ARL,43953649
2025-07-17T13:46:09.560953850Z,2025-07-17T13:46:09.560789009Z,10,2,1108,C,A,8,14.36,700,130,164841,69579446,13.250000,11,1,13.780000,2,1,12.990000,100,1,13.930000,100,1,12.880000,2,1,14.200000,100,1,12.730000,100,1,14.260000,700,1,12.670000,100,1,14.270000,700,1,12.470000,100,1,14.280000,100,1,12.460000,100,1,14.300000,200,2,12.430000,700,1,14.340000,100,1,12.420000,700,1,14.460000,700,1,12.370000,700,1,14.470000,100,1,ARL,84607761
2025-07-17T13:46:09.560968819Z,2025-07-17T13:46:09.560803559Z,10,2,1108,A,A,2,13.94,100,130,165260,69579448,13.250000,11,1,13.780000,2,1,12.990000,100,1,13.930000,100,1,12.880000,2,1,13.940000,100,1,12.730000,100,1,14.200000,100,1,12.670000,100,1,14.260000,700,1,12.470000,100,1,14.270000,700,1,12.460000,100,1,14.280000,100,1,12.430000,700,1,14.300000,200,2,12.420000,700,1,14.340000,100,1,12.370000,700,1,14.460000,700,1,ARL,84609305
2025-07-17T13:46:09.560981020Z,2025-07-17T13:46:09.560815603Z,10,2,1108,C,A,5,14.27,700,130,165417,69579449,13.250000,11,1,13.780000,2,1,12.990000,100,1,13.930000,100,1,12.880000,2,1,13.940000,100,1,12.730000,100,1,14.200000,100,1,12.670000,100,1,14.260000,700,1,12.470000,100,1,14.280000,100,1,12.460000,100,1,14.300000,200,2,12.430000,700,1,14.340000,100,1,12.420000,700,1,14.460000,700,1,12.370000,700,1,14.470000,100,1,ARL,44491681
2025-07-17T13:46:09.560990769Z,2025-07-17T13:46:09.560825413Z,10,2,1108,A,A,-1,15.89,100,130,165356,69579450,13.250000,11,1,13.780000,2,1,12.990000,100,1,13.930000,100,1,12.880000,2,1,13.940000,100,1,12.730000,100,1,14.200000,100,1,12.670000,100,1,14.260000,700,1,12.470000,100,1,14.280000,100,1,12.460000,100,1,14.300000,200,2,12.430000,700,1,14.340000,100,1,12.420000,700,1,14.460000,700,1,12.370000,700,1,14.470000,100,1,ARL,84609309
2025-07-17T13:46:09.561002700Z,2025-07-17T13:46:09.560837771Z,10,2,1108,C,A,15,15.59,100,130,164929,69579453,13.250000,11,1,13.780000,2,1,12.990000,100,1,13.930000,100,1,12.880000,2,1,13.940000,100,1,12.730000,100,1,14.200000,100,1,12.670000,100,1,14.260000,700,1,12.470000,100,1,14.280000,100,1,12.460000,100,1,14.300000,200,2,12.430000,700,1,14.340000,100,1,12.420000,700,1,14.460000,700,1,12.370000,700,1,14.470000,100,1,ARL,84607765
2025-07-17T13:46:09.561059021Z,2025-07-17T13:46:09.560893546Z,10,2,1108,A,A,-1,14.70,700,130,165475,69579455,13.250000,11,1,13.780000,2,1,12.990000,100,1,13.930000,100,1,12.880000,2,1,13.940000,100,1,12.730000,100,1,14.200000,100,1,12.670000,100,1,14.260000,700,1,12.470000,100,1,14.280000,100,1,12.460000,100,1,14.300000,200,2,12.430000,700,1,14.340000,100,1,12.420000,700,1,14.460000,700,1,12.370000,700,1,14.470000,100,1,ARL,84609321
2025-07-17T13:46:09.561710911Z,2025-07-17T13:46:09.561543868Z,10,2,1108,C,A,4,14.26,700,128,167043,69579488,13.250000,11,1,13.780000,2,1,12.990000,100,1,13.930000,100,1,12.880000,2,1,13.940000,100,1,12.730000,100,1,14.200000,100,1,12.670000,100,1,14.280000,100,1,12.470000,100,1,14.300000,200,2,12.460000,100,1,14.340000,100,1,12.430000,700,1,14.460000,700,1,12.420000,700,1,14.470000,100,1,12.370000,700,1,14.490000,100,1,ARL,44598153
2025-07-17T13:46:09.561954989Z,2025-07-17T13:46:09.561788417Z,10,2,1108,C,A,13,15.04,100,0,166572,69579536,13.250000,11,1,13.780000,2,1,12.990000,100,1,13.930000,100,1,12.880000,2,1,13.940000,100,1,12.730000,100,1,14.200000,100,1,12.670000,100,1,14.280000,100,1,12.470000,100,1,14.300000,200,2,12.460000,100,1,14.340000,100,1,12.430000,700,1,14.460000,700,1,12.420000,700,1,14.470000,100,1,12.370000,700,1,14.490000,100,1,ARL,84607805
2025-07-17T13:46:09.561954989Z,2025-07-17T13:46:09.561788417Z,10,2,1108,A,A,-1,15.33,100,0,166572,69579536,13.250000,11,1,13.780000,2,1,12.990000,100,1,13.930000,100,1,12.880000,2,1,13.940000,100,1,12.730000,100,1,14.200000,100,1,12.670000,100,1,14.280000,100,1,12.470000,100,1,14.300000,200,2,12.460000,100,1,14.340000,100,1,12.430000,700,1,14.460000,700,1,12.420000,700,1,14.470000,100,1,12.370000,700,1,14.490000,100,1,ARL,84609385
2025-07-17T13:46:09.561954989Z,2025-07-17T13:46:09.561788902Z,10,2,1108,C,A,10,14.63,100,0,166087,69579537,13.250000,11,1,13.780000,2,1,12.990000,100,1,13.930000,100,1,12.880000,2,1,13.940000,100,1,12.730000,100,1,14.200000,100,1,12.670000,100,1,14.280000,100,1,12.470000,100,1,14.300000,200,2,12.460000,100,1,14.340000,100,1,12.430000,700,1,14.460000,700,1,12.420000,700,1,14.470000,100,1,12.370000,700,1,14.490000,100,1,ARL,84607801
2025-07-17T13:46:09.561954989Z,2025-07-17T13:46:09.561788902Z,10,2,1108,A,A,-1,14.91,100,130,166087,69579537,13.250000,11,1,13.780000,2,1,12.990000,100,1,13.930000,100,1,12.880000,2,1,13.940000,100,1,12.730000,100,1,14.200000,100,1,12.670000,100,1,14.280000,100,1,12.470000,100,1,14.300000,200,2,12.460000,100,1,14.340000,100,1,12.430000,700,1,14.460000,700,1,12.420000,700,1,14.470000,100,1,12.370000,700,1,14.490000,100,1,ARL,84609389
2025-07-17T13:46:09.562157451Z,2025-07-17T13:46:09.561992206Z,10,2,1108,A,A,-1,14.67,700,130,165245,69579579,13.250000,11,1,13.780000,2,1,12.990000,100,1,13.930000,100,1,12.880000,2,1,13.940000,100,1,12.730000,100,1,14.200000,100,1,12.670000,100,1,14.280000,100,1,12.470000,100,1,14.300000,200,2,12.460000,100,1,14.340000,100,1,12.430000,700,1,14.460000,700,1,12.420000,700,1,14.470000,100,1,12.370000,700,1,14.490000,100,1,ARL,84609409
2025-07-17T13:46:09.563782397Z,2025-07-17T13:46:09.563617017Z,10,2,1108,C,A,20,17.37,100,0,165380,69579787,13.250000,11,1,13.780000,2,1,12.990000,100,1,13.930000,100,1,12.880000,2,1,13.940000,100,1,12.730000,100,1,14.200000,100,1,12.670000,100,1,14.280000,100,1,12.470000,100,1,14.300000,200,2,12.460000,100,1,14.340000,100,1,12.430000,700,1,14.460000,700,1,12.420000,700,1,14.470000,100,1,12.370000,700,1,14.490000,100,1,ARL,84607861
2025-07-17T13:46:09.563782397Z,2025-07-17T13:46:09.563617017Z,10,2,1108,A,A,-1,17.70,100,130,165380,69579787,13.250000,11,1,13.780000,2,1,12.990000,100,1,13.930000,100,1,12.880000,2,1,13.940000,100,1,12.730000,100,1,14.200000,100,1,12.670000,100,1,14.280000,100,1,12.470000,100,1,14.300000,200,2,12.460000,100,1,14.340000,100,1,12.430000,700,1,14.460000,700,1,12.420000,700,1,14.470000,100,1,12.370000,700,1,14.490000,100,1,ARL,84609557
2025-07-17T13:46:09.565379544Z,2025-07-17T13:46:09.565213822Z,10,2,1108,C,A,0,13.78,2,0,165722,69579892,13.250000,11,1,13.930000,100,1,12.990000,100,1,13.940000,100,1,12.880000,2,1,14.200000,100,1,12.730000,100,1,14.280000,100,1,12.670000,100,1,14.300000,200,2,12.470000,100,1,14.340000,100,1,12.460000,100,1,14.460000,700,1,12.430000,700,1,14.470000,100,1,12.420000,700,1,14.490000,100,1,12.370000,700,1,14.670000,700,1,ARL,58709197
2025-07-17T13:46:09.565379544Z,2025-07-17T13:46:09.565213822Z,10,2,1108,A,A,0,13.93,2,130,165722,69579892,13.250000,11,1,13.930000,102,2,12.990000,100,1,13.940000,100,1,12.880000,2,1,14.200000,100,1,12.730000,100,1,14.280000,100,1,12.670000,100,1,14.300000,200,2,12.470000,100,1,14.340000,100,1,12.460000,100,1,14.460000,700,1,12.430000,700,1,14.470000,100,1,12.420000,700,1,14.490000,100,1,12.370000,700,1,14.670000,700,1,ARL,84609637
2025-07-17T13:46:09.565403598Z,2025-07-17T13:46:09.565237899Z,10,2,1108,C,A,15,15.73,100,0,165699,69579893,13.250000,11,1,13.930000,102,2,12.990000,100,1,13.940000,100,1,12.880000,2,1,14.200000,100,1,12.730000,100,1,14.280000,100,1,12.670000,100,1,14.300000,200,2,12.470000,100,1,14.340000,100,1,12.460000,100,1,14.460000,700,1,12.430000,700,1,14.470000,100,1,12.420000,700,1,14.490000,100,1,12.370000,700,1,14.670000,700,1,ARL,84607837
2025-07-17T13:46:09.565403598Z,2025-07-17T13:46:09.565237899Z,10,2,1108,A,A,-1,16.02,100,130,165699,69579893,13.250000,11,1,13.930000,102,2,12.990000,100,1,13.940000,100,1,12.880000,2,1,14.200000,100,1,12.730000,100,1,14.280000,100,1,12.670000,100,1,14.300000,200,2,12.470000,100,1,14.340000,100,1,12.460000,100,1,14.460000,700,1,12.430000,700,1,14.470000,100,1,12.420000,700,1,14.490000,100,1,12.370000,700,1,14.670000,700,1,ARL,84609645
2025-07-17T13:46:09.566687064Z,2025-07-17T13:46:09.566522227Z,10,2,1108,C,A,1,13.94,100,130,164837,69579922,13.250000,11,1,13.930000,102,2,12.990000,100,1,14.200000,100,1,12.880000,2,1,14.280000,100,1,12.730000,100,1,14.300000,200,2,12.670000,100,1,14.340000,100,1,12.470000,100,1,14.460000,700,1,12.460000,100,1,14.470000,100,1,12.430000,700,1,14.490000,100,1,12.420000,700,1,14.670000,700,1,12.370000,700,1,14.700000,700,1,ARL,84609305
2025-07-17T13:46:09.566736503Z,2025-07-17T13:46:09.566571131Z,10,2,1108,A,A,2,14.21,100,130,165372,69579923,13.250000,11,1,13.930000,102,2,12.990000,100,1,14.200000,100,1,12.880000,2,1,14.210000,100,1,12.730000,100,1,14.280000,100,1,12.670000,100,1,14.300000,200,2,12.470000,100,1,14.340000,100,1,12.460000,100,1,14.460000,700,1,12.430000,700,1,14.470000,100,1,12.420000,700,1,14.490000,100,1,12.370000,700,1,14.670000,700,1,ARL,84609733
2025-07-17T13:46:09.583735074Z,2025-07-17T13:46:09.583569619Z,10,2,1108,C,A,11,14.74,100,0,165455,69580598,13.250000,11,1,13.930000,102,2,12.990000,100,1,14.200000,100,1,12.880000,2,1,14.210000,100,1,12.730000,100,1,14.280000,100,1,12.670000,100,1,14.300000,200,2,12.470000,100,1,14.340000,100,1,12.460000,100,1,14.460000,700,1,12.430000,700,1,14.470000,100,1,12.420000,700,1,14.490000,100,1,12.370000,700,1,14.670000,700,1,ARL,43852129
2025-07-17T13:46:09.583735074Z,2025-07-17T13:46:09.583569619Z,10,2,1108,A,A,-1,15.33,100,130,165455,69580598,13.250000,11,1,13.930000,102,2,12.990000,100,1,14.200000,100,1,12.880000,2,1,14.210000,100,1,12.730000,100,1,14.280000,100,1,12.670000,100,1,14.300000,200,2,12.470000,100,1,14.340000,100,1,12.460000,100,1,14.460000,700,1,12.430000,700,1,14.470000,100,1,12.420000,700,1,14.490000,100,1,12.370000,700,1,14.670000,700,1,ARL,84611025
2025-07-17T13:46:09.591552337Z,2025-07-17T13:46:09.591386919Z,10,2,1108,C,A,8,14.49,100,0,165418,69581249,13.250000,11,1,13.930000,102,2,12.990000,100,1,14.200000,100,1,12.880000,2,1,14.210000,100,1,12.730000,100,1,14.280000,100,1,12.670000,100,1,14.300000,200,2,12.470000,100,1,14.340000,100,1,12.460000,100,1,14.460000,700,1,12.430000,700,1,14.470000,100,1,12.420000,700,1,14.670000,700,1,12.370000,700,1,14.700000,700,1,ARL,84607785
2025-07-17T13:46:09.591552337Z,2025-07-17T13:46:09.591386919Z,10,2,1108,A,A,-1,15.01,100,130,165418,69581249,13.250000,11,1,13.930000,102,2,12.990000,100,1,14.200000,100,1,12.880000,2,1,14.210000,100,1,12.730000,100,1,14.280000,100,1,12.670000,100,1,14.300000,200,2,12.470000,100,1,14.340000,100,1,12.460000,100,1,14.460000,700,1,12.430000,700,1,14.470000,100,1,12.420000,700,1,14.670000,700,1,12.370000,700,1,14.700000,700,1,ARL,84611613
2025-07-17T13:46:09.595667047Z,2025-07-17T13:46:09.595500037Z,10,2,1108,A,A,8,14.63,700,128,167010,69582059,13.250000,11,1,13.930000,102,2,12.990000,100,1,14.200000,100,1,12.880000,2,1,14.210000,100,1,12.730000,100,1,14.280000,100,1,12.670000,100,1,14.300000,200,2,12.470000,100,1,14.340000,100,1,12.460000,100,1,14.460000,700,1,12.430000,700,1,14.470000,100,1,12.420000,700,1,14.630000,700,1,12.370000,700,1,14.670000,700,1,ARL,84612081
2025-07-17T13:46:09.610291566Z,2025-07-17T13:46:09.610126066Z,10,2,1108,C,A,5,14.34,100,0,165500,69582709,13.250000,11,1,13.930000,102,2,12.990000,100,1,14.200000,100,1,12.880000,2,1,14.210000,100,1,12.730000,100,1,14.280000,100,1,12.670000,100,1,14.300000,200,2,12.470000,100,1,14.460000,700,1,12.460000,100,1,14.470000,100,1,12.430000,700,1,14.630000,700,1,12.420000,700,1,14.670000,700,1,12.370000,700,1,14.700000,700,1,ARL,44088637
2025-07-17T13:46:09.610291566Z,2025-07-17T13:46:09.610126066Z,10,2,1108,A,A,-1,14.91,100,130,165500,69582709,13.250000,11,1,13.930000,102,2,12.990000,100,1,14.200000,100,1,12.880000,2,1,14.210000,100,1,12.730000,100,1,14.280000,100,1,12.670000,100,1,14.300000,200,2,12.470000,100,1,14.460000,700,1,12.460000,100,1,14.470000,100,1,12.430000,700,1,14.630000,700,1,12.420000,700,1,14.670000,700,1,12.370000,700,1,14.700000,700,1,ARL,84612773
2025-07-17T13:46:09.812938843Z,2025-07-17T13:46:09.812773551Z,10,2,1108,A,A,-1,14.76,100,130,165292,69586965,13.250000,11,1,13.930000,102,2,12.990000,100,1,14.200000,100,1,12.880000,2,1,14.210000,100,1,12.730000,100,1,14.280000,100,1,12.670000,100,1,14.300000,200,2,12.470000,100,1,14.460000,700,1,12.460000,100,1,14.470000,100,1,12.430000,700,1,14.630000,700,1,12.420000,700,1,14.670000,700,1,12.370000,700,1,14.700000,700,1,ARL,84618189
2025-07-17T13:46:09.812950020Z,2025-07-17T13:46:09.812784722Z,10,2,1108,C,A,1,14.20,100,130,165298,69586966,13.250000,11,1,13.930000,102,2,12.990000,100,1,14.210000,100,1,12.880000,2,1,14.280000,100,1,12.730000,100,1,14.300000,200,2,12.670000,100,1,14.460000,700,1,12.470000,100,1,14.470000,100,1,12.460000,100,1,14.630000,700,1,12.430000,700,1,14.670000,700,1,12.420000,700,1,14.700000,700,1,12.370000,700,1,14.760000,100,1,ARL,43804081
2025-07-17T13:46:09.936895839Z,2025-07-17T13:46:09.936730596Z,10,2,1108,C,A,0,13.93,100,130,165243,69592193,13.250000,11,1,13.930000,2,1,12.990000,100,1,14.210000,100,1,12.880000,2,1,14.280000,100,1,12.730000,100,1,14.300000,200,2,12.670000,100,1,14.460000,700,1,12.470000,100,1,14.470000,100,1,12.460000,100,1,14.630000,700,1,12.430000,700,1,14.670000,700,1,12.420000,700,1,14.700000,700,1,12.370000,700,1,14.760000,100,1,ARL,44066417
2025-07-17T13:46:09.936896832Z,2025-07-17T13:46:09.936731544Z,10,2,1108,A,A,6,14.48,100,130,165288,69592194,13.250000,11,1,13.930000,2,1,12.990000,100,1,14.210000,100,1,12.880000,2,1,14.280000,100,1,12.730000,100,1,14.300000,200,2,12.670000,100,1,14.460000,700,1,12.470000,100,1,14.470000,100,1,12.460000,100,1,14.480000,100,1,12.430000,700,1,14.630000,700,1,12.420000,700,1,14.670000,700,1,12.370000,700,1,14.700000,700,1,ARL,84624129
2025-07-17T13:46:09.937622396Z,2025-07-17T13:46:09.937457145Z,10,2,1108,C,A,12,15.01,100,0,165251,69592231,13.250000,11,1,13.930000,2,1,12.990000,100,1,14.210000,100,1,12.880000,2,1,14.280000,100,1,12.730000,100,1,14.300000,200,2,12.670000,100,1,14.460000,700,1,12.470000,100,1,14.470000,100,1,12.460000,100,1,14.480000,100,1,12.430000,700,1,14.630000,700,1,12.420000,700,1,14.670000,700,1,12.370000,700,1,14.700000,700,1,ARL,84611613
2025-07-17T13:46:09.937622396Z,2025-07-17T13:46:09.937457145Z,10,2,1108,A,A,-1,15.06,100,130,165251,69592231,13.250000,11,1,13.930000,2,1,12.990000,100,1,14.210000,100,1,12.880000,2,1,14.280000,100,1,12.730000,100,1,14.300000,200,2,12.670000,100,1,14.460000,700,1,12.470000,100,1,14.470000,100,1,12.460000,100,1,14.480000,100,1,12.430000,700,1,14.630000,700,1,12.420000,700,1,14.670000,700,1,12.370000,700,1,14.700000,700,1,ARL,84624201
2025-07-17T13:46:10.046960966Z,2025-07-17T13:46:10.046795728Z,10,2,1108,C,A,9,14.70,700,130,165238,69596523,13.250000,11,1,13.930000,2,1,12.990000,100,1,14.210000,100,1,12.880000,2,1,14.280000,100,1,12.730000,100,1,14.300000,200,2,12.670000,100,1,14.460000,700,1,12.470000,100,1,14.470000,100,1,12.460000,100,1,14.480000,100,1,12.430000,700,1,14.630000,700,1,12.420000,700,1,14.670000,700,1,12.370000,700,1,14.760000,100,1,ARL,84609321
2025-07-17T13:46:10.046962793Z,2025-07-17T13:46:10.046796743Z,10,2,1108,C,A,7,14.63,700,130,166050,69596524,13.250000,11,1,13.930000,2,1,12.990000,100,1,14.210000,100,1,12.880000,2,1,14.280000,100,1,12.730000,100,1,14.300000,200,2,12.670000,100,1,14.460000,700,1,12.470000,100,1,14.470000,100,1,12.460000,100,1,14.480000,100,1,12.430000,700,1,14.670000,700,1,12.420000,700,1,14.760000,100,1,12.370000,700,1,14.910000,200,2,ARL,84612081
2025-07-17T13:46:10.047001176Z,2025-07-17T13:46:10.046834863Z,10,2,1108,A,A,-1,14.99,700,0,166313,69596525,13.250000,11,1,13.930000,2,1,12.990000,100,1,14.210000,100,1,12.880000,2,1,14.280000,100,1,12.730000,100,1,14.300000,200,2,12.670000,100,1,14.460000,700,1,12.470000,100,1,14.470000,100,1,12.460000,100,1,14.480000,100,1,12.430000,700,1,14.670000,700,1,12.420000,700,1,14.760000,100,1,12.370000,700,1,14.910000,200,2,ARL,84628757
2025-07-17T13:46:10.047001176Z,2025-07-17T13:46:10.046835277Z,10,2,1108,A,A,9,14.91,700,130,165899,69596526,13.250000,11,1,13.930000,2,1,12.990000,100,1,14.210000,100,1,12.880000,2,1,14.280000,100,1,12.730000,100,1,14.300000,200,2,12.670000,100,1,14.460000,700,1,12.470000,100,1,14.470000,100,1,12.460000,100,1,14.480000,100,1,12.430000,700,1,14.670000,700,1,12.420000,700,1,14.760000,100,1,12.370000,700,1,14.910000,900,3,ARL,84628761
2025-07-17T13:46:10.047030471Z,2025-07-17T13:46:10.046864551Z,10,2,1108,A,A,-1,16.20,100,130,165920,69596527,13.250000,11,1,13.930000,2,1,12.990000,100,1,14.210000,100,1,12.880000,2,1,14.280000,100,1,12.730000,100,1,14.300000,200,2,12.670000,100,1,14.460000,700,1,12.470000,100,1,14.470000,100,1,12.460000,100,1,14.480000,100,1,12.430000,700,1,14.670000,700,1,12.420000,700,1,14.760000,100,1,12.370000,700,1,14.910000,900,3,ARL,84628765
2025-07-17T13:46:10.047042954Z,2025-07-17T13:46:10.046877789Z,10,2,1108,C,A,14,15.89,100,130,165165,69596529,13.250000,11,1,13.930000,2,1,12.990000,100,1,14.210000,100,1,12.880000,2,1,14.280000,100,1,12.730000,100,1,14.300000,200,2,12.670000,100,1,14.460000,700,1,12.470000,100,1,14.470000,100,1,12.460000,100,1,14.480000,100,1,12.430000,700,1,14.670000,700,1,12.420000,700,1,14.760000,100,1,12.370000,700,1,14.910000,900,3,ARL,84609309
2025-07-17T13:46:10.047089640Z,2025-07-17T13:46:10.046924268Z,10,2,1108,C,A,0,13.93,2,0,165372,69596531,13.250000,11,1,14.210000,100,1,12.990000,100,1,14.280000,100,1,12.880000,2,1,14.300000,200,2,12.730000,100,1,14.460000,700,1,12.670000,100,1,14.470000,100,1,12.470000,100,1,14.480000,100,1,12.460000,100,1,14.670000,700,1,12.430000,700,1,14.760000,100,1,12.420000,700,1,14.910000,900,3,12.370000,700,1,14.990000,700,1,ARL,84609637
2025-07-17T13:46:10.047089640Z,2025-07-17T13:46:10.046924268Z,10,2,1108,A,A,0,14.20,2,130,165372,69596531,13.250000,11,1,14.200000,2,1,12.990000,100,1,14.210000,100,1,12.880000,2,1,14.280000,100,1,12.730000,100,1,14.300000,200,2,12.670000,100,1,14.460000,700,1,12.470000,100,1,14.470000,100,1,12.460000,100,1,14.480000,100,1,12.430000,700,1,14.670000,700,1,12.420000,700,1,14.760000,100,1,12.370000,700,1,14.910000,900,3,ARL,84628773
2025-07-17T13:46:10.047429477Z,2025-07-17T13:46:10.047264301Z,10,2,1108,C,A,2,14.28,100,130,165176,69596542,13.250000,11,1,14.200000,2,1,12.990000,100,1,14.210000,100,1,12.880000,2,1,14.300000,200,2,12.730000,100,1,14.460000,700,1,12.670000,100,1,14.470000,100,1,12.470000,100,1,14.480000,100,1,12.460000,100,1,14.670000,700,1,12.430000,700,1,14.760000,100,1,12.420000,700,1,14.910000,900,3,12.370000,700,1,14.990000,700,1,ARL,84607809
2025-07-17T13:46:10.047479201Z,2025-07-17T13:46:10.047313929Z,10,2,1108,C,A,6,14.67,700,130,165272,69596543,13.250000,11,1,14.200000,2,1,12.990000,100,1,14.210000,100,1,12.880000,2,1,14.300000,200,2,12.730000,100,1,14.460000,700,1,12.670000,100,1,14.470000,100,1,12.470000,100,1,14.480000,100,1,12.460000,100,1,14.760000,100,1,12.430000,700,1,14.910000,900,3,12.420000,700,1,14.990000,700,1,12.370000,700,1,15.060000,100,1,ARL,84609409
2025-07-17T13:46:10.047784342Z,2025-07-17T13:46:10.047618250Z,10,2,1108,A,A,7,14.83,100,128,166092,69596548,13.250000,11,1,14.200000,2,1,12.990000,100,1,14.210000,100,1,12.880000,2,1,14.300000,200,2,12.730000,100,1,14.460000,700,1,12.670000,100,1,14.470000,100,1,12.470000,100,1,14.480000,100,1,12.460000,100,1,14.760000,100,1,12.430000,700,1,14.830000,100,1,12.420000,700,1,14.910000,900,3,12.370000,700,1,14.990000,700,1,ARL,84628793
2025-07-17T13:46:10.047806230Z,2025-07-17T13:46:10.047640842Z,10,2,1108,C,A,3,14.46,700,130,165388,69596550,13.250000,11,1,14.200000,2,1,12.990000,100,1,14.210000,100,1,12.880000,2,1,14.300000,200,2,12.730000,100,1,14.470000,100,1,12.670000,100,1,14.480000,100,1,12.470000,100,1,14.760000,100,1,12.460000,100,1,14.830000,100,1,12.430000,700,1,14.910000,900,3,12.420000,700,1,14.990000,700,1,12.370000,700,1,15.060000,100,1,ARL,44548325
2025-07-17T13:46:10.047885265Z,2025-07-17T13:46:10.047719954Z,10,2,1108,A,A,8,14.95,700,130,165311,69596551,13.250000,11,1,14.200000,2,1,12.990000,100,1,14.210000,100,1,12.880000,2,1,14.300000,200,2,12.730000,100,1,14.470000,100,1,12.670000,100,1,14.480000,100,1,12.470000,100,1,14.760000,100,1,12.460000,100,1,14.830000,100,1,12.430000,700,1,14.910000,900,3,12.420000,700,1,14.950000,700,1,12.370000,700,1,14.990000,700,1,ARL,84628797
2025-07-17T13:46:10.047929072Z,2025-07-17T13:46:10.047763743Z,10,2,1108,C,A,7,14.91,100,0,165329,69596552,13.250000,11,1,14.200000,2,1,12.990000,100,1,14.210000,100,1,12.880000,2,1,14.300000,200,2,12.730000,100,1,14.470000,100,1,12.670000,100,1,14.480000,100,1,12.470000,100,1,14.760000,100,1,12.460000,100,1,14.830000,100,1,12.430000,700,1,14.910000,800,2,12.420000,700,1,14.950000,700,1,12.370000,700,1,14.990000,700,1,ARL,84609389
2025-07-17T13:46:10.047929072Z,2025-07-17T13:46:10.047763743Z,10,2,1108,A,A,-1,15.20,100,130,165329,69596552,13.250000,11,1,14.200000,2,1,12.990000,100,1,14.210000,100,1,12.880000,2,1,14.300000,200,2,12.730000,100,1,14.470000,100,1,12.670000,100,1,14.480000,100,1,12.470000,100,1,14.760000,100,1,12.460000,100,1,14.830000,100,1,12.430000,700,1,14.910000,800,2,12.420000,700,1,14.950000,700,1,12.370000,700,1,14.990000,700,1,ARL,84628801
2025-07-17T13:46:10.047983286Z,2025-07-17T13:46:10.047817649Z,10,2,1108,C,A,10,15.06,100,0,165637,69596553,13.250000,11,1,14.200000,2,1,12.990000,100,1,14.210000,100,1,12.880000,2,1,14.300000,200,2,12.730000,100,1,14.470000,100,1,12.670000,100,1,14.480000,100,1,12.470000,100,1,14.760000,100,1,12.460000,100,1,14.830000,100,1,12.430000,700,1,14.910000,800,2,12.420000,700,1,14.950000,700,1,12.370000,700,1,14.990000,700,1,ARL,84624201
2025-07-17T13:46:10.047983286Z,2025-07-17T13:46:10.047817649Z,10,2,1108,A,A,-1,15.30,100,130,165637,69596553,13.250000,11,1,14.200000,2,1,12.990000,100,1,14.210000,100,1,12.880000,2,1,14.300000,200,2,12.730000,100,1,14.470000,100,1,12.670000,100,1,14.480000,100,1,12.470000,100,1,14.760000,100,1,12.460000,100,1,14.830000,100,1,12.430000,700,1,14.910000,800,2,12.420000,700,1,14.950000,700,1,12.370000,700,1,14.990000,700,1,ARL,84628813
2025-07-17T13:46:10.048529147Z,2025-07-17T13:46:10.048363798Z,10,2,1108,A,A,-1,15.14,700,130,165349,69596568,13.250000,11,1,14.200000,2,1,12.990000,100,1,14.210000,100,1,12.880000,2,1,14.300000,200,2,12.730000,100,1,14.470000,100,1,12.670000,100,1,14.480000,100,1,12.470000,100,1,14.760000,100,1,12.460000,100,1,14.830000,100,1,12.430000,700,1,14.910000,800,2,12.420000,700,1,14.950000,700,1,12.370000,700,1,14.990000,700,1,ARL,84628829
2025-07-17T13:46:10.048840949Z,2025-07-17T13:46:10.048674815Z,10,2,1108,C,A,13,15.33,100,0,166134,69596577,13.250000,11,1,14.200000,2,1,12.990000,100,1,14.210000,100,1,12.880000,2,1,14.300000,200,2,12.730000,100,1,14.470000,100,1,12.670000,100,1,14.480000,100,1,12.470000,100,1,14.760000,100,1,12.460000,100,1,14.830000,100,1,12.430000,700,1,14.910000,800,2,12.420000,700,1,14.950000,700,1,12.370000,700,1,14.990000,700,1,ARL,84609385
2025-07-17T13:46:10.048840949Z,2025-07-17T13:46:10.048674815Z,10,2,1108,A,A,-1,15.64,100,130,166134,69596577,13.250000,11,1,14.200000,2,1,12.990000,100,1,14.210000,100,1,12.880000,2,1,14.300000,200,2,12.730000,100,1,14.470000,100,1,12.670000,100,1,14.480000,100,1,12.470000,100,1,14.760000,100,1,12.460000,100,1,14.830000,100,1,12.430000,700,1,14.910000,800,2,12.420000,700,1,14.950000,700,1,12.370000,700,1,14.990000,700,1,ARL,84628833
2025-07-17T13:46:10.051935025Z,2025-07-17T13:46:10.051769303Z,10,2,1108,C,A,19,17.70,100,0,165722,69596649,13.250000,11,1,14.200000,2,1,12.990000,100,1,14.210000,100,1,12.880000,2,1,14.300000,200,2,12.730000,100,1,14.470000,100,1,12.670000,100,1,14.480000,100,1,12.470000,100,1,14.760000,100,1,12.460000,100,1,14.830000,100,1,12.430000,700,1,14.910000,800,2,12.420000,700,1,14.950000,700,1,12.370000,700,1,14.990000,700,1,ARL,84609557
2025-07-17T13:46:10.051935025Z,2025-07-17T13:46:10.051769303Z,10,2,1108,A,A,-1,18.05,100,130,165722,69596649,13.250000,11,1,14.200000,2,1,12.990000,100,1,14.210000,100,1,12.880000,2,1,14.300000,200,2,12.730000,100,1,14.470000,100,1,12.670000,100,1,14.480000,100,1,12.470000,100,1,14.760000,100,1,12.460000,100,1,14.830000,100,1,12.430000,700,1,14.910000,800,2,12.420000,700,1,14.950000,700,1,12.370000,700,1,14.990000,700,1,ARL,84628913
2025-07-17T13:46:10.054332558Z,2025-07-17T13:46:10.054167322Z,10,2,1108,C,A,15,16.02,100,0,165236,69596777,13.250000,11,1,14.200000,2,1,12.990000,100,1,14.210000,100,1,12.880000,2,1,14.300000,200,2,12.730000,100,1,14.470000,100,1,12.670000,100,1,14.480000,100,1,12.470000,100,1,14.760000,100,1,12.460000,100,1,14.830000,100,1,12.430000,700,1,14.910000,800,2,12.420000,700,1,14.950000,700,1,12.370000,700,1,14.990000,700,1,ARL,84609645
2025-07-17T13:46:10.054332558Z,2025-07-17T13:46:10.054167322Z,10,2,1108,A,A,-1,16.35,100,130,165236,69596777,13.250000,11,1,14.200000,2,1,12.990000,100,1,14.210000,100,1,12.880000,2,1,14.300000,200,2,12.730000,100,1,14.470000,100,1,12.670000,100,1,14.480000,100,1,12.470000,100,1,14.760000,100,1,12.460000,100,1,14.830000,100,1,12.430000,700,1,14.910000,800,2,12.420000,700,1,14.950000,700,1,12.370000,700,1,14.990000,700,1,ARL,84629065
2025-07-17T13:46:10.055434148Z,2025-07-17T13:46:10.055269067Z,10,2,1108,C,A,1,14.21,100,130,165081,69596798,13.250000,11,1,14.200000,2,1,12.990000,100,1,14.300000,200,2,12.880000,2,1,14.470000,100,1,12.730000,100,1,14.480000,100,1,12.670000,100,1,14.760000,100,1,12.470000,100,1,14.830000,100,1,12.460000,100,1,14.910000,800,2,12.430000,700,1,14.950000,700,1,12.420000,700,1,14.990000,700,1,12.370000,700,1,15.140000,700,1,ARL,84609733
2025-07-17T13:46:10.055483249Z,2025-07-17T13:46:10.055317945Z,10,2,1108,A,A,3,14.48,100,130,165304,69596799,13.250000,11,1,14.200000,2,1,12.990000,100,1,14.300000,200,2,12.880000,2,1,14.470000,100,1,12.730000,100,1,14.480000,200,2,12.670000,100,1,14.760000,100,1,12.470000,100,1,14.830000,100,1,12.460000,100,1,14.910000,800,2,12.430000,700,1,14.950000,700,1,12.420000,700,1,14.990000,700,1,12.370000,700,1,15.140000,700,1,ARL,84629093
2025-07-17T13:46:10.061411059Z,2025-07-17T13:46:10.061246123Z,10,2,1108,C,A,3,14.48,100,130,164936,69596987,13.250000,11,1,14.200000,2,1,12.990000,100,1,14.300000,200,2,12.880000,2,1,14.470000,100,1,12.730000,100,1,14.480000,100,1,12.670000,100,1,14.760000,100,1,12.470000,100,1,14.830000,100,1,12.460000,100,1,14.910000,800,2,12.430000,700,1,14.950000,700,1,12.420000,700,1,14.990000,700,1,12.370000,700,1,15.140000,700,1,ARL,84629093
2025-07-17T13:46:10.061459915Z,2025-07-17T13:46:10.061294728Z,10,2,1108,A,A,4,14.59,100,130,165187,69596990,13.250000,11,1,14.200000,2,1,12.990000,100,1,14.300000,200,2,12.880000,2,1,14.470000,100,1,12.730000,100,1,14.480000,100,1,12.670000,100,1,14.590000,100,1,12.470000,100,1,14.760000,100,1,12.460000,100,1,14.830000,100,1,12.430000,700,1,14.910000,800,2,12.420000,700,1,14.950000,700,1,12.370000,700,1,14.990000,700,1,ARL,84629329
2025-07-17T13:46:10.087891846Z,2025-07-17T13:46:10.087725560Z,10,2,1108,C,A,13,15.33,100,0,166286,69597697,13.250000,11,1,14.200000,2,1,12.990000,100,1,14.300000,200,2,12.880000,2,1,14.470000,100,1,12.730000,100,1,14.480000,100,1,12.670000,100,1,14.590000,100,1,12.470000,100,1,14.760000,100,1,12.460000,100,1,14.830000,100,1,12.430000,700,1,14.910000,800,2,12.420000,700,1,14.950000,700,1,12.370000,700,1,14.990000,700,1,ARL,84611025
2025-07-17T13:46:10.087891846Z,2025-07-17T13:46:10.087725560Z,10,2,1108,A,A,-1,15.73,100,128,166286,69597697,13.250000,11,1,14.200000,2,1,12.990000,100,1,14.300000,200,2,12.880000,2,1,14.470000,100,1,12.730000,100,1,14.480000,100,1,12.670000,100,1,14.590000,100,1,12.470000,100,1,14.760000,100,1,12.460000,100,1,14.830000,100,1,12.430000,700,1,14.910000,800,2,12.420000,700,1,14.950000,700,1,12.370000,700,1,14.990000,700,1,ARL,84629953
2025-07-17T13:46:10.098194757Z,2025-07-17T13:46:10.098029439Z,10,2,1108,C,A,12,15.30,100,0,165318,69597813,13.250000,11,1,14.200000,2,1,12.990000,100,1,14.300000,200,2,12.880000,2,1,14.470000,100,1,12.730000,100,1,14.480000,100,1,12.670000,100,1,14.590000,100,1,12.470000,100,1,14.760000,100,1,12.460000,100,1,14.830000,100,1,12.430000,700,1,14.910000,800,2,12.420000,700,1,14.950000,700,1,12.370000,700,1,14.990000,700,1,ARL,84628813
2025-07-17T13:46:10.098194757Z,2025-07-17T13:46:10.098029439Z,10,2,1108,A,A,-1,15.41,100,130,165318,69597813,13.250000,11,1,14.200000,2,1,12.990000,100,1,14.300000,200,2,12.880000,2,1,14.470000,100,1,12.730000,100,1,14.480000,100,1,12.670000,100,1,14.590000,100,1,12.470000,100,1,14.760000,100,1,12.460000,100,1,14.830000,100,1,12.430000,700,1,14.910000,800,2,12.420000,700,1,14.950000,700,1,12.370000,700,1,14.990000,700,1,ARL,84630217
2025-07-17T13:46:10.109235050Z,2025-07-17T13:46:10.109069598Z,10,2,1108,C,A,7,14.91,100,0,165452,69598154,13.250000,11,1,14.200000,2,1,12.990000,100,1,14.300000,200,2,12.880000,2,1,14.470000,100,1,12.730000,100,1,14.480000,100,1,12.670000,100,1,14.590000,100,1,12.470000,100,1,14.760000,100,1,12.460000,100,1,14.830000,100,1,12.430000,700,1,14.910000,700,1,12.420000,700,1,14.950000,700,1,12.370000,700,1,14.990000,700,1,ARL,84612773
2025-07-17T13:46:10.109235050Z,2025-07-17T13:46:10.109069598Z,10,2,1108,A,A,-1,15.31,100,130,165452,69598154,13.250000,11,1,14.200000,2,1,12.990000,100,1,14.300000,200,2,12.880000,2,1,14.470000,100,1,12.730000,100,1,14.480000,100,1,12.670000,100,1,14.590000,100,1,12.470000,100,1,14.760000,100,1,12.460000,100,1,14.830000,100,1,12.430000,700,1,14.910000,700,1,12.420000,700,1,14.950000,700,1,12.370000,700,1,14.990000,700,1,ARL,84630849
2025-07-17T13:46:10.551481906Z,2025-07-17T13:46:10.551316402Z,10,2,1108,C,A,2,14.47,100,0,165504,69614455,13.250000,11,1,14.200000,2,1,12.990000,100,1,14.300000,200,2,12.880000,2,1,14.480000,100,1,12.730000,100,1,14.590000,100,1,12.670000,100,1,14.760000,100,1,12.470000,100,1,14.830000,100,1,12.460000,100,1,14.910000,700,1,12.430000,700,1,14.950000,700,1,12.420000,700,1,14.990000,700,1,12.370000,700,1,15.140000,700,1,ARL,84608321
2025-07-17T13:46:10.551481906Z,2025-07-17T13:46:10.551316402Z,10,2,1108,A,A,9,15.09,100,130,165504,69614455,13.250000,11,1,14.200000,2,1,12.990000,100,1,14.300000,200,2,12.880000,2,1,14.480000,100,1,12.730000,100,1,14.590000,100,1,12.670000,100,1,14.760000,100,1,12.470000,100,1,14.830000,100,1,12.460000,100,1,14.910000,700,1,12.430000,700,1,14.950000,700,1,12.420000,700,1,14.990000,700,1,12.370000,700,1,15.090000,100,1,ARL,84650629
2025-07-17T13:46:10.904838107Z,2025-07-17T13:46:10.904672934Z,10,2,1108,A,A,-1,15.16,100,130,165173,69628781,13.250000,11,1,14.200000,2,1,12.990000,100,1,14.300000,200,2,12.880000,2,1,14.480000,100,1,12.730000,100,1,14.590000,100,1,12.670000,100,1,14.760000,100,1,12.470000,100,1,14.830000,100,1,12.460000,100,1,14.910000,700,1,12.430000,700,1,14.950000,700,1,12.420000,700,1,14.990000,700,1,12.370000,700,1,15.090000,100,1,ARL,84668677
2025-07-17T13:46:10.904858553Z,2025-07-17T13:46:10.904693578Z,10,2,1108,C,A,4,14.76,100,130,164975,69628783,13.250000,11,1,14.200000,2,1,12.990000,100,1,14.300000,200,2,12.880000,2,1,14.480000,100,1,12.730000,100,1,14.590000,100,1,12.670000,100,1,14.830000,100,1,12.470000,100,1,14.910000,700,1,12.460000,100,1,14.950000,700,1,12.430000,700,1,14.990000,700,1,12.420000,700,1,15.090000,100,1,12.370000,700,1,15.140000,700,1,ARL,84618189
2025-07-17T13:46:11.840882444Z,2025-07-17T13:46:11.840717150Z,10,2,1108,A,A,5,14.87,100,130,165294,69663346,13.250000,11,1,14.200000,2,1,12.990000,100,1,14.300000,200,2,12.880000,2,1,14.480000,100,1,12.730000,100,1,14.590000,100,1,12.670000,100,1,14.830000,100,1,12.470000,100,1,14.870000,100,1,12.460000,100,1,14.910000,700,1,12.430000,700,1,14.950000,700,1,12.420000,700,1,14.990000,700,1,12.370000,700,1,15.090000,100,1,ARL,84708037
2025-07-17T13:46:11.840894787Z,2025-07-17T13:46:11.840729407Z,10,2,1108,C,A,2,14.48,100,130,165380,69663347,13.250000,11,1,14.200000,2,1,12.990000,100,1,14.300000,200,2,12.880000,2,1,14.590000,100,1,12.730000,100,1,14.830000,100,1,12.670000,100,1,14.870000,100,1,12.470000,100,1,14.910000,700,1,12.460000,100,1,14.950000,700,1,12.430000,700,1,14.990000,700,1,12.420000,700,1,15.090000,100,1,12.370000,700,1,15.140000,700,1,ARL,84624129
2025-07-17T13:46:23.920813185Z,2025-07-17T13:46:23.920647302Z,10,2,1108,C,B,2,12.88,2,0,165883,70104076,13.250000,11,1,14.200000,2,1,12.990000,100,1,14.300000,200,2,12.730000,100,1,14.590000,100,1,12.670000,100,1,14.830000,100,1,12.470000,100,1,14.870000,100,1,12.460000,100,1,14.910000,700,1,12.430000,700,1,14.950000,700,1,12.420000,700,1,14.990000,700,1,12.370000,700,1,15.090000,100,1,12.360000,200,2,15.140000,700,1,ARL,58709193
2025-07-17T13:46:23.920813185Z,2025-07-17T13:46:23.920647302Z,10,2,1108,A,B,1,13.12,2,130,165883,70104076,13.250000,11,1,14.200000,2,1,13.120000,2,1,14.300000,200,2,12.990000,100,1,14.590000,100,1,12.730000,100,1,14.830000,100,1,12.670000,100,1,14.870000,100,1,12.470000,100,1,14.910000,700,1,12.460000,100,1,14.950000,700,1,12.430000,700,1,14.990000,700,1,12.420000,700,1,15.090000,100,1,12.370000,700,1,15.140000,700,1,ARL,85194077
2025-07-17T13:46:45.786579604Z,2025-07-17T13:46:45.786413307Z,10,2,1108,C,B,1,13.12,2,0,166297,70834235,13.250000,11,1,14.200000,2,1,12.990000,100,1,14.300000,200,2,12.730000,100,1,14.590000,100,1,12.670000,100,1,14.830000,100,1,12.470000,100,1,14.870000,100,1,12.460000,100,1,14.910000,700,1,12.430000,700,1,14.950000,700,1,12.420000,700,1,14.990000,700,1,12.370000,700,1,15.090000,100,1,12.360000,200,2,15.140000,700,1,ARL,85194077
2025-07-17T13:46:45.786579604Z,2025-07-17T13:46:45.786413307Z,10,2,1108,A,B,1,13.20,2,130,166297,70834235,13.250000,11,1,14.200000,2,1,13.200000,2,1,14.300000,200,2,12.990000,100,1,14.590000,100,1,12.730000,100,1,14.830000,100,1,12.670000,100,1,14.870000,100,1,12.470000,100,1,14.910000,700,1,12.460000,100,1,14.950000,700,1,12.430000,700,1,14.990000,700,1,12.420000,700,1,15.090000,100,1,12.370000,700,1,15.140000,700,1,ARL,86056033
2025-07-17T13:47:34.987167177Z,2025-07-17T13:47:34.987001473Z,10,2,1108,C,B,1,13.20,2,0,165704,72269967,13.250000,11,1,14.200000,2,1,12.990000,100,1,14.300000,200,2,12.730000,100,1,14.590000,100,1,12.670000,100,1,14.830000,100,1,12.470000,100,1,14.870000,100,1,12.460000,100,1,14.910000,700,1,12.430000,700,1,14.950000,700,1,12.420000,700,1,14.990000,700,1,12.370000,700,1,15.090000,100,1,12.360000,200,2,15.140000,700,1,ARL,86056033
2025-07-17T13:47:34.987167177Z,2025-07-17T13:47:34.987001473Z,10,2,1108,A,B,0,13.26,2,130,165704,72269967,13.260000,2,1,14.200000,2,1,13.250000,11,1,14.300000,200,2,12.990000,100,1,14.590000,100,1,12.730000,100,1,14.830000,100,1,12.670000,100,1,14.870000,100,1,12.470000,100,1,14.910000,700,1,12.460000,100,1,14.950000,700,1,12.430000,700,1,14.990000,700,1,12.420000,700,1,15.090000,100,1,12.370000,700,1,15.140000,700,1,ARL,87750309
2025-07-17T13:49:46.533586484Z,2025-07-17T13:49:46.533420775Z,10,2,1108,C,A,1,14.30,100,0,165709,76393090,13.260000,2,1,14.200000,2,1,13.250000,11,1,14.300000,100,1,12.990000,100,1,14.590000,100,1,12.730000,100,1,14.830000,100,1,12.670000,100,1,14.870000,100,1,12.470000,100,1,14.910000,700,1,12.460000,100,1,14.950000,700,1,12.430000,700,1,14.990000,700,1,12.420000,700,1,15.090000,100,1,12.370000,700,1,15.140000,700,1,ARL,77910357
2025-07-17T13:49:46.533586484Z,2025-07-17T13:49:46.533420775Z,10,2,1108,A,A,-1,15.26,100,130,165709,76393090,13.260000,2,1,14.200000,2,1,13.250000,11,1,14.300000,100,1,12.990000,100,1,14.590000,100,1,12.730000,100,1,14.830000,100,1,12.670000,100,1,14.870000,100,1,12.470000,100,1,14.910000,700,1,12.460000,100,1,14.950000,700,1,12.430000,700,1,14.990000,700,1,12.420000,700,1,15.090000,100,1,12.370000,700,1,15.140000,700,1,ARL,92510725
2025-07-17T13:49:46.533732414Z,2025-07-17T13:49:46.533566805Z,10,2,1108,C,A,1,14.30,100,0,165609,76393092,13.260000,2,1,14.200000,2,1,13.250000,11,1,14.590000,100,1,12.990000,100,1,14.830000,100,1,12.730000,100,1,14.870000,100,1,12.670000,100,1,14.910000,700,1,12.470000,100,1,14.950000,700,1,12.460000,100,1,14.990000,700,1,12.430000,700,1,15.090000,100,1,12.420000,700,1,15.140000,700,1,12.370000,700,1,15.160000,100,1,ARL,74589605
2025-07-17T13:49:46.533732414Z,2025-07-17T13:49:46.533566805Z,10,2,1108,A,A,-1,15.26,100,130,165609,76393092,13.260000,2,1,14.200000,2,1,13.250000,11,1,14.590000,100,1,12.990000,100,1,14.830000,100,1,12.730000,100,1,14.870000,100,1,12.670000,100,1,14.910000,700,1,12.470000,100,1,14.950000,700,1,12.460000,100,1,14.990000,700,1,12.430000,700,1,15.090000,100,1,12.420000,700,1,15.140000,700,1,12.370000,700,1,15.160000,100,1,ARL,92510729
2025-07-17T13:49:46.533768662Z,2025-07-17T13:49:46.533603070Z,10,2,1108,C,A,4,14.91,700,130,165592,76393093,13.260000,2,1,14.200000,2,1,13.250000,11,1,14.590000,100,1,12.990000,100,1,14.830000,100,1,12.730000,100,1,14.870000,100,1,12.670000,100,1,14.950000,700,1,12.470000,100,1,14.990000,700,1,12.460000,100,1,15.090000,100,1,12.430000,700,1,15.140000,700,1,12.420000,700,1,15.160000,100,1,12.370000,700,1,15.200000,100,1,ARL,84628761
2025-07-17T13:49:46.533810238Z,2025-07-17T13:49:46.533644528Z,10,2,1108,A,A,6,15.07,700,130,165710,76393094,13.260000,2,1,14.200000,2,1,13.250000,11,1,14.590000,100,1,12.990000,100,1,14.830000,100,1,12.730000,100,1,14.870000,100,1,12.670000,100,1,14.950000,700,1,12.470000,100,1,14.990000,700,1,12.460000,100,1,15.070000,700,1,12.430000,700,1,15.090000,100,1,12.420000,700,1,15.140000,700,1,12.370000,700,1,15.160000,100,1,ARL,92510741
2025-07-17T13:49:46.534488891Z,2025-07-17T13:49:46.534323177Z,10,2,1108,C,A,14,15.41,100,0,165714,76393099,13.260000,2,1,14.200000,2,1,13.250000,11,1,14.590000,100,1,12.990000,100,1,14.830000,100,1,12.730000,100,1,14.870000,100,1,12.670000,100,1,14.950000,700,1,12.470000,100,1,14.990000,700,1,12.460000,100,1,15.070000,700,1,12.430000,700,1,15.090000,100,1,12.420000,700,1,15.140000,700,1,12.370000,700,1,15.160000,100,1,ARL,84630217
2025-07-17T13:49:46.534488891Z,2025-07-17T13:49:46.534323177Z,10,2,1108,A,A,-1,15.46,100,130,165714,76393099,13.260000,2,1,14.200000,2,1,13.250000,11,1,14.590000,100,1,12.990000,100,1,14.830000,100,1,12.730000,100,1,14.870000,100,1,12.670000,100,1,14.950000,700,1,12.470000,100,1,14.990000,700,1,12.460000,100,1,15.070000,700,1,12.430000,700,1,15.090000,100,1,12.420000,700,1,15.140000,700,1,12.370000,700,1,15.160000,100,1,ARL,92510753
2025-07-17T13:49:46.534555834Z,2025-07-17T13:49:46.534390219Z,10,2,1108,C,A,10,15.20,100,0,165615,76393100,13.260000,2,1,14.200000,2,1,13.250000,11,1,14.590000,100,1,12.990000,100,1,14.830000,100,1,12.730000,100,1,14.870000,100,1,12.670000,100,1,14.950000,700,1,12.470000,100,1,14.990000,700,1,12.460000,100,1,15.070000,700,1,12.430000,700,1,15.090000,100,1,12.420000,700,1,15.140000,700,1,12.370000,700,1,15.160000,100,1,ARL,84628801
2025-07-17T13:49:46.534555834Z,2025-07-17T13:49:46.534390219Z,10,2,1108,A,A,-1,15.36,100,130,165615,76393100,13.260000,2,1,14.200000,2,1,13.250000,11,1,14.590000,100,1,12.990000,100,1,14.830000,100,1,12.730000,100,1,14.870000,100,1,12.670000,100,1,14.950000,700,1,12.470000,100,1,14.990000,700,1,12.460000,100,1,15.070000,700,1,12.430000,700,1,15.090000,100,1,12.420000,700,1,15.140000,700,1,12.370000,700,1,15.160000,100,1,ARL,92510761
2025-07-17T13:49:46.535182699Z,2025-07-17T13:49:46.535017084Z,10,2,1108,C,A,19,16.35,100,0,165615,76393115,13.260000,2,1,14.200000,2,1,13.250000,11,1,14.590000,100,1,12.990000,100,1,14.830000,100,1,12.730000,100,1,14.870000,100,1,12.670000,100,1,14.950000,700,1,12.470000,100,1,14.990000,700,1,12.460000,100,1,15.070000,700,1,12.430000,700,1,15.090000,100,1,12.420000,700,1,15.140000,700,1,12.370000,700,1,15.160000,100,1,ARL,84629065
2025-07-17T13:49:46.535182699Z,2025-07-17T13:49:46.535017084Z,10,2,1108,A,A,-1,16.51,100,130,165615,76393115,13.260000,2,1,14.200000,2,1,13.250000,11,1,14.590000,100,1,12.990000,100,1,14.830000,100,1,12.730000,100,1,14.870000,100,1,12.670000,100,1,14.950000,700,1,12.470000,100,1,14.990000,700,1,12.460000,100,1,15.070000,700,1,12.430000,700,1,15.090000,100,1,12.420000,700,1,15.140000,700,1,12.370000,700,1,15.160000,100,1,ARL,92510813
2025-07-17T13:49:46.535737854Z,2025-07-17T13:49:46.535572067Z,10,2,1108,C,A,21,18.05,100,0,165787,76393138,13.260000,2,1,14.200000,2,1,13.250000,11,1,14.590000,100,1,12.990000,100,1,14.830000,100,1,12.730000,100,1,14.870000,100,1,12.670000,100,1,14.950000,700,1,12.470000,100,1,14.990000,700,1,12.460000,100,1,15.070000,700,1,12.430000,700,1,15.090000,100,1,12.420000,700,1,15.140000,700,1,12.370000,700,1,15.160000,100,1,ARL,84628913
2025-07-17T13:49:46.535737854Z,2025-07-17T13:49:46.535572067Z,10,2,1108,A,A,-1,18.23,100,130,165787,76393138,13.260000,2,1,14.200000,2,1,13.250000,11,1,14.590000,100,1,12.990000,100,1,14.830000,100,1,12.730000,100,1,14.870000,100,1,12.670000,100,1,14.950000,700,1,12.470000,100,1,14.990000,700,1,12.460000,100,1,15.070000,700,1,12.430000,700,1,15.090000,100,1,12.420000,700,1,15.140000,700,1,12.370000,700,1,15.160000,100,1,ARL,92510841
2025-07-17T13:56:11.001810226Z,2025-07-17T13:56:11.001642441Z,10,2,1108,A,B,0,13.28,1,128,167785,89819278,13.280000,1,1,14.200000,2,1,13.260000,2,1,14.590000,100,1,13.250000,11,1,14.830000,100,1,12.990000,100,1,14.870000,100,1,12.730000,100,1,14.950000,700,1,12.670000,100,1,14.990000,700,1,12.470000,100,1,15.070000,700,1,12.460000,100,1,15.090000,100,1,12.430000,700,1,15.140000,700,1,12.420000,700,1,15.160000,100,1,ARL,107702381
2025-07-17T13:56:11.005550129Z,2025-07-17T13:56:11.005384065Z,10,2,1108,A,B,0,13.28,10,130,166064,89819705,13.280000,11,2,14.200000,2,1,13.260000,2,1,14.590000,100,1,13.250000,11,1,14.830000,100,1,12.990000,100,1,14.870000,100,1,12.730000,100,1,14.950000,700,1,12.670000,100,1,14.990000,700,1,12.470000,100,1,15.070000,700,1,12.460000,100,1,15.090000,100,1,12.430000,700,1,15.140000,700,1,12.420000,700,1,15.160000,100,1,ARL,107702861
2025-07-17T13:56:11.005550669Z,2025-07-17T13:56:11.005385425Z,10,2,1108,A,A,0,13.94,10,130,165244,89819706,13.280000,11,2,13.940000,10,1,13.260000,2,1,14.200000,2,1,13.250000,11,1,14.590000,100,1,12.990000,100,1,14.830000,100,1,12.730000,100,1,14.870000,100,1,12.670000,100,1,14.950000,700,1,12.470000,100,1,14.990000,700,1,12.460000,100,1,15.070000,700,1,12.430000,700,1,15.090000,100,1,12.420000,700,1,15.140000,700,1,ARL,107702865
2025-07-17T13:56:11.013819857Z,2025-07-17T13:56:11.013654317Z,10,2,1108,C,A,11,15.26,100,0,165540,89820163,13.280000,11,2,13.940000,10,1,13.260000,2,1,14.200000,2,1,13.250000,11,1,14.590000,100,1,12.990000,100,1,14.830000,100,1,12.730000,100,1,14.870000,100,1,12.670000,100,1,14.950000,700,1,12.470000,100,1,14.990000,700,1,12.460000,100,1,15.070000,700,1,12.430000,700,1,15.090000,100,1,12.420000,700,1,15.140000,700,1,ARL,92510729
2025-07-17T13:56:11.013819857Z,2025-07-17T13:56:11.013654317Z,10,2,1108,A,A,4,14.84,100,130,165540,89820163,13.280000,11,2,13.940000,10,1,13.260000,2,1,14.200000,2,1,13.250000,11,1,14.590000,100,1,12.990000,100,1,14.830000,100,1,12.730000,100,1,14.840000,100,1,12.670000,100,1,14.870000,100,1,12.470000,100,1,14.950000,700,1,12.460000,100,1,14.990000,700,1,12.430000,700,1,15.070000,700,1,12.420000,700,1,15.090000,100,1,ARL,107703205
2025-07-17T13:56:11.026680779Z,2025-07-17T13:56:11.026515306Z,10,2,1108,C,A,12,15.26,100,0,165473,89820408,13.280000,11,2,13.940000,10,1,13.260000,2,1,14.200000,2,1,13.250000,11,1,14.590000,100,1,12.990000,100,1,14.830000,100,1,12.730000,100,1,14.840000,100,1,12.670000,100,1,14.870000,100,1,12.470000,100,1,14.950000,700,1,12.460000,100,1,14.990000,700,1,12.430000,700,1,15.070000,700,1,12.420000,700,1,15.090000,100,1,ARL,92510725
2025-07-17T13:56:11.026680779Z,2025-07-17T13:56:11.026515306Z,10,2,1108,A,A,4,14.84,100,130,165473,89820408,13.280000,11,2,13.940000,10,1,13.260000,2,1,14.200000,2,1,13.250000,11,1,14.590000,100,1,12.990000,100,1,14.830000,100,1,12.730000,100,1,14.840000,200,2,12.670000,100,1,14.870000,100,1,12.470000,100,1,14.950000,700,1,12.460000,100,1,14.990000,700,1,12.430000,700,1,15.070000,700,1,12.420000,700,1,15.090000,100,1,ARL,107703433
2025-07-17T13:56:11.101916770Z,2025-07-17T13:56:11.101751649Z,10,2,1108,C,B,0,13.28,1,130,165121,89823845,13.280000,10,1,13.940000,10,1,13.260000,2,1,14.200000,2,1,13.250000,11,1,14.590000,100,1,12.990000,100,1,14.830000,100,1,12.730000,100,1,14.840000,200,2,12.670000,100,1,14.870000,100,1,12.470000,100,1,14.950000,700,1,12.460000,100,1,14.990000,700,1,12.430000,700,1,15.070000,700,1,12.420000,700,1,15.090000,100,1,ARL,107702381
2025-07-17T13:56:19.511755342Z,2025-07-17T13:56:19.511590204Z,10,2,1108,C,B,0,13.28,10,130,165138,90148349,13.260000,2,1,13.940000,10,1,13.250000,11,1,14.200000,2,1,12.990000,100,1,14.590000,100,1,12.730000,100,1,14.830000,100,1,12.670000,100,1,14.840000,200,2,12.470000,100,1,14.870000,100,1,12.460000,100,1,14.950000,700,1,12.430000,700,1,14.990000,700,1,12.420000,700,1,15.070000,700,1,12.370000,700,1,15.090000,100,1,ARL,107702861
2025-07-17T13:56:22.512134723Z,2025-07-17T13:56:22.511968820Z,10,2,1108,C,A,0,13.94,10,130,165903,90281309,13.260000,2,1,14.200000,2,1,13.250000,11,1,14.590000,100,1,12.990000,100,1,14.830000,100,1,12.730000,100,1,14.840000,200,2,12.670000,100,1,14.870000,100,1,12.470000,100,1,14.950000,700,1,12.460000,100,1,14.990000,700,1,12.430000,700,1,15.070000,700,1,12.420000,700,1,15.090000,100,1,12.370000,700,1,15.140000,700,1,ARL,107702865
2025-07-17T13:56:22.517155918Z,2025-07-17T13:56:22.516990420Z,10,2,1108,C,A,3,14.84,100,0,165498,90281853,13.260000,2,1,14.200000,2,1,13.250000,11,1,14.590000,100,1,12.990000,100,1,14.830000,100,1,12.730000,100,1,14.840000,100,1,12.670000,100,1,14.870000,100,1,12.470000,100,1,14.950000,700,1,12.460000,100,1,14.990000,700,1,12.430000,700,1,15.070000,700,1,12.420000,700,1,15.090000,100,1,12.370000,700,1,15.140000,700,1,ARL,107703205
2025-07-17T13:56:22.517155918Z,2025-07-17T13:56:22.516990420Z,10,2,1108,A,A,-1,15.26,100,130,165498,90281853,13.260000,2,1,14.200000,2,1,13.250000,11,1,14.590000,100,1,12.990000,100,1,14.830000,100,1,12.730000,100,1,14.840000,100,1,12.670000,100,1,14.870000,100,1,12.470000,100,1,14.950000,700,1,12.460000,100,1,14.990000,700,1,12.430000,700,1,15.070000,700,1,12.420000,700,1,15.090000,100,1,12.370000,700,1,15.140000,700,1,ARL,108217045
2025-07-17T13:56:22.517527654Z,2025-07-17T13:56:22.517362170Z,10,2,1108,C,A,3,14.84,100,0,165484,90281893,13.260000,2,1,14.200000,2,1,13.250000,11,1,14.590000,100,1,12.990000,100,1,14.830000,100,1,12.730000,100,1,14.870000,100,1,12.670000,100,1,14.950000,700,1,12.470000,100,1,14.990000,700,1,12.460000,100,1,15.070000,700,1,12.430000,700,1,15.090000,100,1,12.420000,700,1,15.140000,700,1,12.370000,700,1,15.160000,100,1,ARL,107703433
2025-07-17T13:56:22.517527654Z,2025-07-17T13:56:22.517362170Z,10,2,1108,A,A,-1,15.26,100,130,165484,90281893,13.260000,2,1,14.200000,2,1,13.250000,11,1,14.590000,100,1,12.990000,100,1,14.830000,100,1,12.730000,100,1,14.870000,100,1,12.670000,100,1,14.950000,700,1,12.470000,100,1,14.990000,700,1,12.460000,100,1,15.070000,700,1,12.430000,700,1,15.090000,100,1,12.420000,700,1,15.140000,700,1,12.370000,700,1,15.160000,100,1,ARL,108217173
2025-07-17T13:56:40.757800894Z,2025-07-17T13:56:40.757635216Z,10,2,1108,C,A,0,14.20,2,0,165678,90866180,13.260000,2,1,14.590000,100,1,13.250000,11,1,14.830000,100,1,12.990000,100,1,14.870000,100,1,12.730000,100,1,14.950000,700,1,12.670000,100,1,14.990000,700,1,12.470000,100,1,15.070000,700,1,12.460000,100,1,15.090000,100,1,12.430000,700,1,15.140000,700,1,12.420000,700,1,15.160000,100,1,12.370000,700,1,15.260000,200,2,ARL,84628773
2025-07-17T13:56:40.757800894Z,2025-07-17T13:56:40.757635216Z,10,2,1108,A,A,0,14.36,2,130,165678,90866180,13.260000,2,1,14.360000,2,1,13.250000,11,1,14.590000,100,1,12.990000,100,1,14.830000,100,1,12.730000,100,1,14.870000,100,1,12.670000,100,1,14.950000,700,1,12.470000,100,1,14.990000,700,1,12.460000,100,1,15.070000,700,1,12.430000,700,1,15.090000,100,1,12.420000,700,1,15.140000,700,1,12.370000,700,1,15.160000,100,1,ARL,108872153
2025-07-17T13:57:40.142022323Z,2025-07-17T13:57:40.141855674Z,10,2,1108,C,B,0,13.26,2,0,166649,92821039,13.250000,11,1,14.360000,2,1,12.990000,100,1,14.590000,100,1,12.730000,100,1,14.830000,100,1,12.670000,100,1,14.870000,100,1,12.470000,100,1,14.950000,700,1,12.460000,100,1,14.990000,700,1,12.430000,700,1,15.070000,700,1,12.420000,700,1,15.090000,100,1,12.370000,700,1,15.140000,700,1,12.360000,200,2,15.160000,100,1,ARL,87750309
2025-07-17T13:57:40.142022323Z,2025-07-17T13:57:40.141855674Z,10,2,1108,A,B,1,13.12,2,128,166649,92821039,13.250000,11,1,14.360000,2,1,13.120000,2,1,14.590000,100,1,12.990000,100,1,14.830000,100,1,12.730000,100,1,14.870000,100,1,12.670000,100,1,14.950000,700,1,12.470000,100,1,14.990000,700,1,12.460000,100,1,15.070000,700,1,12.430000,700,1,15.090000,100,1,12.420000,700,1,15.140000,700,1,12.370000,700,1,15.160000,100,1,ARL,111169049
2025-07-17T13:57:44.947757237Z,2025-07-17T13:57:44.947591620Z,10,2,1108,C,A,0,14.36,2,0,165617,92961696,13.250000,11,1,14.590000,100,1,13.120000,2,1,14.830000,100,1,12.990000,100,1,14.870000,100,1,12.730000,100,1,14.950000,700,1,12.670000,100,1,14.990000,700,1,12.470000,100,1,15.070000,700,1,12.460000,100,1,15.090000,100,1,12.430000,700,1,15.140000,700,1,12.420000,700,1,15.160000,100,1,12.370000,700,1,15.260000,200,2,ARL,108872153
2025-07-17T13:57:44.947757237Z,2025-07-17T13:57:44.947591620Z,10,2,1108,A,A,0,14.50,2,130,165617,92961696,13.250000,11,1,14.500000,2,1,13.120000,2,1,14.590000,100,1,12.990000,100,1,14.830000,100,1,12.730000,100,1,14.870000,100,1,12.670000,100,1,14.950000,700,1,12.470000,100,1,14.990000,700,1,12.460000,100,1,15.070000,700,1,12.430000,700,1,15.090000,100,1,12.420000,700,1,15.140000,700,1,12.370000,700,1,15.160000,100,1,ARL,111347121
2025-07-17T13:59:50.477911158Z,2025-07-17T13:59:50.477745739Z,10,2,1108,C,B,0,13.25,11,130,165419,96389796,13.120000,2,1,14.500000,2,1,12.990000,100,1,14.590000,100,1,12.730000,100,1,14.830000,100,1,12.670000,100,1,14.870000,100,1,12.470000,100,1,14.950000,700,1,12.460000,100,1,14.990000,700,1,12.430000,700,1,15.070000,700,1,12.420000,700,1,15.090000,100,1,12.370000,700,1,15.140000,700,1,12.360000,200,2,15.160000,100,1,ARL,44586753
2025-07-17T13:59:50.479576984Z,2025-07-17T13:59:50.479411482Z,10,2,1108,C,B,9,12.36,100,0,165502,96389821,13.120000,2,1,14.500000,2,1,12.990000,100,1,14.590000,100,1,12.730000,100,1,14.830000,100,1,12.670000,100,1,14.870000,100,1,12.470000,100,1,14.950000,700,1,12.460000,100,1,14.990000,700,1,12.430000,700,1,15.070000,700,1,12.420000,700,1,15.090000,100,1,12.370000,700,1,15.140000,700,1,12.360000,100,1,15.160000,100,1,ARL,43787977
2025-07-17T13:59:50.479576984Z,2025-07-17T13:59:50.479411482Z,10,2,1108,A,B,4,12.51,100,130,165502,96389821,13.120000,2,1,14.500000,2,1,12.990000,100,1,14.590000,100,1,12.730000,100,1,14.830000,100,1,12.670000,100,1,14.870000,100,1,12.510000,100,1,14.950000,700,1,12.470000,100,1,14.990000,700,1,12.460000,100,1,15.070000,700,1,12.430000,700,1,15.090000,100,1,12.420000,700,1,15.140000,700,1,12.370000,700,1,15.160000,100,1,ARL,115474337
2025-07-17T13:59:50.480863637Z,2025-07-17T13:59:50.480698233Z,10,2,1108,C,B,10,12.36,100,0,165404,96389845,13.120000,2,1,14.500000,2,1,12.990000,100,1,14.590000,100,1,12.730000,100,1,14.830000,100,1,12.670000,100,1,14.870000,100,1,12.510000,100,1,14.950000,700,1,12.470000,100,1,14.990000,700,1,12.460000,100,1,15.070000,700,1,12.430000,700,1,15.090000,100,1,12.420000,700,1,15.140000,700,1,12.370000,700,1,15.160000,100,1,ARL,43781537
2025-07-17T13:59:50.480863637Z,2025-07-17T13:59:50.480698233Z,10,2,1108,A,B,4,12.51,100,130,165404,96389845,13.120000,2,1,14.500000,2,1,12.990000,100,1,14.590000,100,1,12.730000,100,1,14.830000,100,1,12.670000,100,1,14.870000,100,1,12.510000,200,2,14.950000,700,1,12.470000,100,1,14.990000,700,1,12.460000,100,1,15.070000,700,1,12.430000,700,1,15.090000,100,1,12.420000,700,1,15.140000,700,1,12.370000,700,1,15.160000,100,1,ARL,115474357
2025-07-17T14:00:00.063037446Z,2025-07-17T14:00:00.062872132Z,10,2,1108,A,B,1,13.11,100,130,165314,96673952,13.120000,2,1,14.500000,2,1,13.110000,100,1,14.590000,100,1,12.990000,100,1,14.830000,100,1,12.730000,100,1,14.870000,100,1,12.670000,100,1,14.950000,700,1,12.510000,200,2,14.990000,700,1,12.470000,100,1,15.070000,700,1,12.460000,100,1,15.090000,100,1,12.430000,700,1,15.140000,700,1,12.420000,700,1,15.160000,100,1,ARL,115813253
2025-07-17T14:00:00.063056200Z,2025-07-17T14:00:00.062890891Z,10,2,1108,A,A,1,14.51,100,130,165309,96673954,13.120000,2,1,14.500000,2,1,13.110000,100,1,14.510000,100,1,12.990000,100,1,14.590000,100,1,12.730000,100,1,14.830000,100,1,12.670000,100,1,14.870000,100,1,12.510000,200,2,14.950000,700,1,12.470000,100,1,14.990000,700,1,12.460000,100,1,15.070000,700,1,12.430000,700,1,15.090000,100,1,12.420000,700,1,15.140000,700,1,ARL,115813261
2025-07-17T14:02:01.157985602Z,2025-07-17T14:02:01.157819863Z,10,2,1108,C,B,0,13.12,2,0,165739,101310413,13.110000,100,1,14.500000,2,1,12.990000,100,1,14.510000,100,1,12.730000,100,1,14.590000,100,1,12.670000,100,1,14.830000,100,1,12.510000,200,2,14.870000,100,1,12.470000,100,1,14.950000,700,1,12.460000,100,1,14.990000,700,1,12.430000,700,1,15.070000,700,1,12.420000,700,1,15.090000,100,1,12.370000,700,1,15.140000,700,1,ARL,111169049
2025-07-17T14:02:01.157985602Z,2025-07-17T14:02:01.157819863Z,10,2,1108,A,B,0,13.26,2,130,165739,101310413,13.260000,2,1,14.500000,2,1,13.110000,100,1,14.510000,100,1,12.990000,100,1,14.590000,100,1,12.730000,100,1,14.830000,100,1,12.670000,100,1,14.870000,100,1,12.510000,200,2,14.950000,700,1,12.470000,100,1,14.990000,700,1,12.460000,100,1,15.070000,700,1,12.430000,700,1,15.090000,100,1,12.420000,700,1,15.140000,700,1,ARL,121098337
2025-07-17T14:02:01.157986499Z,2025-07-17T14:02:01.157820985Z,10,2,1108,C,A,0,14.50,2,0,165514,101310414,13.260000,2,1,14.510000,100,1,13.110000,100,1,14.590000,100,1,12.990000,100,1,14.830000,100,1,12.730000,100,1,14.870000,100,1,12.670000,100,1,14.950000,700,1,12.510000,200,2,14.990000,700,1,12.470000,100,1,15.070000,700,1,12.460000,100,1,15.090000,100,1,12.430000,700,1,15.140000,700,1,12.420000,700,1,15.160000,100,1,ARL,111347121
2025-07-17T14:02:01.157986499Z,2025-07-17T14:02:01.157820985Z,10,2,1108,A,A,0,14.36,2,130,165514,101310414,13.260000,2,1,14.360000,2,1,13.110000,100,1,14.510000,100,1,12.990000,100,1,14.590000,100,1,12.730000,100,1,14.830000,100,1,12.670000,100,1,14.870000,100,1,12.510000,200,2,14.950000,700,1,12.470000,100,1,14.990000,700,1,12.460000,100,1,15.070000,700,1,12.430000,700,1,15.090000,100,1,12.420000,700,1,15.140000,700,1,ARL,121098341
2025-07-17T14:02:01.283528838Z,2025-07-17T14:02:01.283363185Z,10,2,1108,C,B,1,13.11,100,0,165653,101317376,13.260000,2,1,14.360000,2,1,12.990000,100,1,14.510000,100,1,12.730000,100,1,14.590000,100,1,12.670000,100,1,14.830000,100,1,12.510000,200,2,14.870000,100,1,12.470000,100,1,14.950000,700,1,12.460000,100,1,14.990000,700,1,12.430000,700,1,15.070000,700,1,12.420000,700,1,15.090000,100,1,12.370000,700,1,15.140000,700,1,ARL,115813253
2025-07-17T14:02:01.283528838Z,2025-07-17T14:02:01.283363185Z,10,2,1108,A,B,1,13.25,100,130,165653,101317376,13.260000,2,1,14.360000,2,1,13.250000,100,1,14.510000,100,1,12.990000,100,1,14.590000,100,1,12.730000,100,1,14.830000,100,1,12.670000,100,1,14.870000,100,1,12.510000,200,2,14.950000,700,1,12.470000,100,1,14.990000,700,1,12.460000,100,1,15.070000,700,1,12.430000,700,1,15.090000,100,1,12.420000,700,1,15.140000,700,1,ARL,121107957
2025-07-17T14:02:01.283544588Z,2025-07-17T14:02:01.283378637Z,10,2,1108,C,A,1,14.51,100,0,165951,101317377,13.260000,2,1,14.360000,2,1,13.250000,100,1,14.590000,100,1,12.990000,100,1,14.830000,100,1,12.730000,100,1,14.870000,100,1,12.670000,100,1,14.950000,700,1,12.510000,200,2,14.990000,700,1,12.470000,100,1,15.070000,700,1,12.460000,100,1,15.090000,100,1,12.430000,700,1,15.140000,700,1,12.420000,700,1,15.160000,100,1,ARL,115813261
2025-07-17T14:02:01.283544588Z,2025-07-17T14:02:01.283378637Z,10,2,1108,A,A,1,14.37,100,130,165951,101317377,13.260000,2,1,14.360000,2,1,13.250000,100,1,14.370000,100,1,12.990000,100,1,14.590000,100,1,12.730000,100,1,14.830000,100,1,12.670000,100,1,14.870000,100,1,12.510000,200,2,14.950000,700,1,12.470000,100,1,14.990000,700,1,12.460000,100,1,15.070000,700,1,12.430000,700,1,15.090000,100,1,12.420000,700,1,15.140000,700,1,ARL,121107961
2025-07-17T14:04:21.248906318Z,2025-07-17T14:04:21.248740930Z,10,2,1108,A,A,0,14.35,1,130,165388,106336852,13.260000,2,1,14.350000,1,1,13.250000,100,1,14.360000,2,1,12.990000,100,1,14.370000,100,1,12.730000,100,1,14.590000,100,1,12.670000,100,1,14.830000,100,1,12.510000,200,2,14.870000,100,1,12.470000,100,1,14.950000,700,1,12.460000,100,1,14.990000,700,1,12.430000,700,1,15.070000,700,1,12.420000,700,1,15.090000,100,1,ARL,126872197
2025-07-17T14:04:21.250325900Z,2025-07-17T14:04:21.250160548Z,10,2,1108,C,B,5,12.51,100,0,165352,106336976,13.260000,2,1,14.350000,1,1,13.250000,100,1,14.360000,2,1,12.990000,100,1,14.370000,100,1,12.730000,100,1,14.590000,100,1,12.670000,100,1,14.830000,100,1,12.510000,100,1,14.870000,100,1,12.470000,100,1,14.950000,700,1,12.460000,100,1,14.990000,700,1,12.430000,700,1,15.070000,700,1,12.420000,700,1,15.090000,100,1,ARL,115474357
2025-07-17T14:04:21.250325900Z,2025-07-17T14:04:21.250160548Z,10,2,1108,A,B,-1,12.36,100,130,165352,106336976,13.260000,2,1,14.350000,1,1,13.250000,100,1,14.360000,2,1,12.990000,100,1,14.370000,100,1,12.730000,100,1,14.590000,100,1,12.670000,100,1,14.830000,100,1,12.510000,100,1,14.870000,100,1,12.470000,100,1,14.950000,700,1,12.460000,100,1,14.990000,700,1,12.430000,700,1,15.070000,700,1,12.420000,700,1,15.090000,100,1,ARL,126872345
2025-07-17T14:04:21.250797741Z,2025-07-17T14:04:21.250632048Z,10,2,1108,C,B,5,12.51,100,0,165693,106337002,13.260000,2,1,14.350000,1,1,13.250000,100,1,14.360000,2,1,12.990000,100,1,14.370000,100,1,12.730000,100,1,14.590000,100,1,12.670000,100,1,14.830000,100,1,12.470000,100,1,14.870000,100,1,12.460000,100,1,14.950000,700,1,12.430000,700,1,14.990000,700,1,12.420000,700,1,15.070000,700,1,12.370000,700,1,15.090000,100,1,ARL,115474337
2025-07-17T14:04:21.250797741Z,2025-07-17T14:04:21.250632048Z,10,2,1108,A,B,-1,12.36,100,130,165693,106337002,13.260000,2,1,14.350000,1,1,13.250000,100,1,14.360000,2,1,12.990000,100,1,14.370000,100,1,12.730000,100,1,14.590000,100,1,12.670000,100,1,14.830000,100,1,12.470000,100,1,14.870000,100,1,12.460000,100,1,14.950000,700,1,12.430000,700,1,14.990000,700,1,12.420000,700,1,15.070000,700,1,12.370000,700,1,15.090000,100,1,ARL,126872361
2025-07-17T14:04:21.350207939Z,2025-07-17T14:04:21.350041949Z,10,2,1108,C,A,0,14.35,1,128,165990,106339204,13.260000,2,1,14.360000,2,1,13.250000,100,1,14.370000,100,1,12.990000,100,1,14.590000,100,1,12.730000,100,1,14.830000,100,1,12.670000,100,1,14.870000,100,1,12.470000,100,1,14.950000,700,1,12.460000,100,1,14.990000,700,1,12.430000,700,1,15.070000,700,1,12.420000,700,1,15.090000,100,1,12.370000,700,1,15.140000,700,1,ARL,126872197
2025-07-17T14:04:54.699926747Z,2025-07-17T14:04:54.699761263Z,10,2,1108,C,A,15,15.46,100,0,165484,107313441,13.260000,2,1,14.360000,2,1,13.250000,100,1,14.370000,100,1,12.990000,100,1,14.590000,100,1,12.730000,100,1,14.830000,100,1,12.670000,100,1,14.870000,100,1,12.470000,100,1,14.950000,700,1,12.460000,100,1,14.990000,700,1,12.430000,700,1,15.070000,700,1,12.420000,700,1,15.090000,100,1,12.370000,700,1,15.140000,700,1,ARL,92510753
2025-07-17T14:04:54.699926747Z,2025-07-17T14:04:54.699761263Z,10,2,1108,A,A,-1,15.34,100,130,165484,107313441,13.260000,2,1,14.360000,2,1,13.250000,100,1,14.370000,100,1,12.990000,100,1,14.590000,100,1,12.730000,100,1,14.830000,100,1,12.670000,100,1,14.870000,100,1,12.470000,100,1,14.950000,700,1,12.460000,100,1,14.990000,700,1,12.430000,700,1,15.070000,700,1,12.420000,700,1,15.090000,100,1,12.370000,700,1,15.140000,700,1,ARL,127999501
2025-07-17T14:05:10.258855609Z,2025-07-17T14:05:10.258689253Z,10,2,1108,A,A,0,14.08,1,130,166356,107833096,13.260000,2,1,14.080000,1,1,13.250000,100,1,14.360000,2,1,12.990000,100,1,14.370000,100,1,12.730000,100,1,14.590000,100,1,12.670000,100,1,14.830000,100,1,12.470000,100,1,14.870000,100,1,12.460000,100,1,14.950000,700,1,12.430000,700,1,14.990000,700,1,12.420000,700,1,15.070000,700,1,12.370000,700,1,15.090000,100,1,ARL,128570149
2025-07-17T14:05:10.259513876Z,2025-07-17T14:05:10.259348471Z,10,2,1108,C,A,12,15.26,100,0,165405,107833168,13.260000,2,1,14.080000,1,1,13.250000,100,1,14.360000,2,1,12.990000,100,1,14.370000,100,1,12.730000,100,1,14.590000,100,1,12.670000,100,1,14.830000,100,1,12.470000,100,1,14.870000,100,1,12.460000,100,1,14.950000,700,1,12.430000,700,1,14.990000,700,1,12.420000,700,1,15.070000,700,1,12.370000,700,1,15.090000,100,1,ARL,108217173
2025-07-17T14:05:10.259513876Z,2025-07-17T14:05:10.259348471Z,10,2,1108,A,A,7,14.98,100,130,165405,107833168,13.260000,2,1,14.080000,1,1,13.250000,100,1,14.360000,2,1,12.990000,100,1,14.370000,100,1,12.730000,100,1,14.590000,100,1,12.670000,100,1,14.830000,100,1,12.470000,100,1,14.870000,100,1,12.460000,100,1,14.950000,700,1,12.430000,700,1,14.980000,100,1,12.420000,700,1,14.990000,700,1,12.370000,700,1,15.070000,700,1,ARL,128570229
2025-07-17T14:05:10.259895236Z,2025-07-17T14:05:10.259729446Z,10,2,1108,C,A,13,15.26,100,0,165790,107833188,13.260000,2,1,14.080000,1,1,13.250000,100,1,14.360000,2,1,12.990000,100,1,14.370000,100,1,12.730000,100,1,14.590000,100,1,12.670000,100,1,14.830000,100,1,12.470000,100,1,14.870000,100,1,12.460000,100,1,14.950000,700,1,12.430000,700,1,14.980000,100,1,12.420000,700,1,14.990000,700,1,12.370000,700,1,15.070000,700,1,ARL,108217045
2025-07-17T14:05:10.259895236Z,2025-07-17T14:05:10.259729446Z,10,2,1108,A,A,7,14.98,100,130,165790,107833188,13.260000,2,1,14.080000,1,1,13.250000,100,1,14.360000,2,1,12.990000,100,1,14.370000,100,1,12.730000,100,1,14.590000,100,1,12.670000,100,1,14.830000,100,1,12.470000,100,1,14.870000,100,1,12.460000,100,1,14.950000,700,1,12.430000,700,1,14.980000,200,2,12.420000,700,1,14.990000,700,1,12.370000,700,1,15.070000,700,1,ARL,128570237
2025-07-17T14:05:10.262461863Z,2025-07-17T14:05:10.262295631Z,10,2,1108,C,A,2,14.37,100,0,166232,107833310,13.260000,2,1,14.080000,1,1,13.250000,100,1,14.360000,2,1,12.990000,100,1,14.590000,100,1,12.730000,100,1,14.830000,100,1,12.670000,100,1,14.870000,100,1,12.470000,100,1,14.950000,700,1,12.460000,100,1,14.980000,200,2,12.430000,700,1,14.990000,700,1,12.420000,700,1,15.070000,700,1,12.370000,700,1,15.090000,100,1,ARL,121107961
2025-07-17T14:05:10.262461863Z,2025-07-17T14:05:10.262295631Z,10,2,1108,A,A,1,14.09,100,130,166232,107833310,13.260000,2,1,14.080000,1,1,13.250000,100,1,14.090000,100,1,12.990000,100,1,14.360000,2,1,12.730000,100,1,14.590000,100,1,12.670000,100,1,14.830000,100,1,12.470000,100,1,14.870000,100,1,12.460000,100,1,14.950000,700,1,12.430000,700,1,14.980000,200,2,12.420000,700,1,14.990000,700,1,12.370000,700,1,15.070000,700,1,ARL,128570317
2025-07-17T14:05:10.262866527Z,2025-07-17T14:05:10.262701351Z,10,2,1108,C,A,0,14.08,1,130,165176,107833359,13.260000,2,1,14.090000,100,1,13.250000,100,1,14.360000,2,1,12.990000,100,1,14.590000,100,1,12.730000,100,1,14.830000,100,1,12.670000,100,1,14.870000,100,1,12.470000,100,1,14.950000,700,1,12.460000,100,1,14.980000,200,2,12.430000,700,1,14.990000,700,1,12.420000,700,1,15.070000,700,1,12.370000,700,1,15.090000,100,1,ARL,128570149
2025-07-17T14:05:10.263188035Z,2025-07-17T14:05:10.263022539Z,10,2,1108,C,A,14,15.34,100,0,165496,107833371,13.260000,2,1,14.090000,100,1,13.250000,100,1,14.360000,2,1,12.990000,100,1,14.590000,100,1,12.730000,100,1,14.830000,100,1,12.670000,100,1,14.870000,100,1,12.470000,100,1,14.950000,700,1,12.460000,100,1,14.980000,200,2,12.430000,700,1,14.990000,700,1,12.420000,700,1,15.070000,700,1,12.370000,700,1,15.090000,100,1,ARL,127999501
2025-07-17T14:05:10.263188035Z,2025-07-17T14:05:10.263022539Z,10,2,1108,A,A,-1,15.18,100,130,165496,107833371,13.260000,2,1,14.090000,100,1,13.250000,100,1,14.360000,2,1,12.990000,100,1,14.590000,100,1,12.730000,100,1,14.830000,100,1,12.670000,100,1,14.870000,100,1,12.470000,100,1,14.950000,700,1,12.460000,100,1,14.980000,200,2,12.430000,700,1,14.990000,700,1,12.420000,700,1,15.070000,700,1,12.370000,700,1,15.090000,100,1,ARL,128570417
2025-07-17T14:05:10.264495078Z,2025-07-17T14:05:10.264329670Z,10,2,1108,C,A,15,15.36,100,0,165408,107833404,13.260000,2,1,14.090000,100,1,13.250000,100,1,14.360000,2,1,12.990000,100,1,14.590000,100,1,12.730000,100,1,14.830000,100,1,12.670000,100,1,14.870000,100,1,12.470000,100,1,14.950000,700,1,12.460000,100,1,14.980000,200,2,12.430000,700,1,14.990000,700,1,12.420000,700,1,15.070000,700,1,12.370000,700,1,15.090000,100,1,ARL,92510761
2025-07-17T14:05:10.264495078Z,2025-07-17T14:05:10.264329670Z,10,2,1108,A,A,9,15.08,100,130,165408,107833404,13.260000,2,1,14.090000,100,1,13.250000,100,1,14.360000,2,1,12.990000,100,1,14.590000,100,1,12.730000,100,1,14.830000,100,1,12.670000,100,1,14.870000,100,1,12.470000,100,1,14.950000,700,1,12.460000,100,1,14.980000,200,2,12.430000,700,1,14.990000,700,1,12.420000,700,1,15.070000,700,1,12.370000,700,1,15.080000,100,1,ARL,128570449
2025-07-17T14:05:10.264590318Z,2025-07-17T14:05:10.264425026Z,10,2,1108,C,A,10,15.09,100,130,165292,107833406,13.260000,2,1,14.090000,100,1,13.250000,100,1,14.360000,2,1,12.990000,100,1,14.590000,100,1,12.730000,100,1,14.830000,100,1,12.670000,100,1,14.870000,100,1,12.470000,100,1,14.950000,700,1,12.460000,100,1,14.980000,200,2,12.430000,700,1,14.990000,700,1,12.420000,700,1,15.070000,700,1,12.370000,700,1,15.080000,100,1,ARL,84650629
2025-07-17T14:05:10.264715723Z,2025-07-17T14:05:10.264550510Z,10,2,1108,A,A,5,14.89,100,130,165213,107833407,13.260000,2,1,14.090000,100,1,13.250000,100,1,14.360000,2,1,12.990000,100,1,14.590000,100,1,12.730000,100,1,14.830000,100,1,12.670000,100,1,14.870000,100,1,12.470000,100,1,14.890000,100,1,12.460000,100,1,14.950000,700,1,12.430000,700,1,14.980000,200,2,12.420000,700,1,14.990000,700,1,12.370000,700,1,15.070000,700,1,ARL,128570453
2025-07-17T14:05:10.269943051Z,2025-07-17T14:05:10.269777131Z,10,2,1108,C,A,2,14.59,100,128,165920,107833716,13.260000,2,1,14.090000,100,1,13.250000,100,1,14.360000,2,1,12.990000,100,1,14.830000,100,1,12.730000,100,1,14.870000,100,1,12.670000,100,1,14.890000,100,1,12.470000,100,1,14.950000,700,1,12.460000,100,1,14.980000,200,2,12.430000,700,1,14.990000,700,1,12.420000,700,1,15.070000,700,1,12.370000,700,1,15.080000,100,1,ARL,84629329
2025-07-17T14:05:10.269997960Z,2025-07-17T14:05:10.269832842Z,10,2,1108,A,A,2,14.37,100,130,165118,107833720,13.260000,2,1,14.090000,100,1,13.250000,100,1,14.360000,2,1,12.990000,100,1,14.370000,100,1,12.730000,100,1,14.830000,100,1,12.670000,100,1,14.870000,100,1,12.470000,100,1,14.890000,100,1,12.460000,100,1,14.950000,700,1,12.430000,700,1,14.980000,200,2,12.420000,700,1,14.990000,700,1,12.370000,700,1,15.070000,700,1,ARL,128570621
2025-07-17T14:05:10.271865423Z,2025-07-17T14:05:10.271699633Z,10,2,1108,C,A,22,18.23,100,0,165790,107833881,13.260000,2,1,14.090000,100,1,13.250000,100,1,14.360000,2,1,12.990000,100,1,14.370000,100,1,12.730000,100,1,14.830000,100,1,12.670000,100,1,14.870000,100,1,12.470000,100,1,14.890000,100,1,12.460000,100,1,14.950000,700,1,12.430000,700,1,14.980000,200,2,12.420000,700,1,14.990000,700,1,12.370000,700,1,15.070000,700,1,ARL,92510841
2025-07-17T14:05:10.271865423Z,2025-07-17T14:05:10.271699633Z,10,2,1108,A,A,-1,17.90,100,130,165790,107833881,13.260000,2,1,14.090000,100,1,13.250000,100,1,14.360000,2,1,12.990000,100,1,14.370000,100,1,12.730000,100,1,14.830000,100,1,12.670000,100,1,14.870000,100,1,12.470000,100,1,14.890000,100,1,12.460000,100,1,14.950000,700,1,12.430000,700,1,14.980000,200,2,12.420000,700,1,14.990000,700,1,12.370000,700,1,15.070000,700,1,ARL,128570685
2025-07-17T14:05:10.276320920Z,2025-07-17T14:05:10.276155439Z,10,2,1108,C,A,20,16.51,100,0,165481,107834635,13.260000,2,1,14.090000,100,1,13.250000,100,1,14.360000,2,1,12.990000,100,1,14.370000,100,1,12.730000,100,1,14.830000,100,1,12.670000,100,1,14.870000,100,1,12.470000,100,1,14.890000,100,1,12.460000,100,1,14.950000,700,1,12.430000,700,1,14.980000,200,2,12.420000,700,1,14.990000,700,1,12.370000,700,1,15.070000,700,1,ARL,92510813
2025-07-17T14:05:10.276320920Z,2025-07-17T14:05:10.276155439Z,10,2,1108,A,A,-1,16.21,100,130,165481,107834635,13.260000,2,1,14.090000,100,1,13.250000,100,1,14.360000,2,1,12.990000,100,1,14.370000,100,1,12.730000,100,1,14.830000,100,1,12.670000,100,1,14.870000,100,1,12.470000,100,1,14.890000,100,1,12.460000,100,1,14.950000,700,1,12.430000,700,1,14.980000,200,2,12.420000,700,1,14.990000,700,1,12.370000,700,1,15.070000,700,1,ARL,128570977
2025-07-17T14:05:10.342982797Z,2025-07-17T14:05:10.342817229Z,10,2,1108,C,A,15,15.31,100,0,165568,107837761,13.260000,2,1,14.090000,100,1,13.250000,100,1,14.360000,2,1,12.990000,100,1,14.370000,100,1,12.730000,100,1,14.830000,100,1,12.670000,100,1,14.870000,100,1,12.470000,100,1,14.890000,100,1,12.460000,100,1,14.950000,700,1,12.430000,700,1,14.980000,200,2,12.420000,700,1,14.990000,700,1,12.370000,700,1,15.070000,700,1,ARL,84630849
2025-07-17T14:05:10.342982797Z,2025-07-17T14:05:10.342817229Z,10,2,1108,A,A,-1,15.08,100,130,165568,107837761,13.260000,2,1,14.090000,100,1,13.250000,100,1,14.360000,2,1,12.990000,100,1,14.370000,100,1,12.730000,100,1,14.830000,100,1,12.670000,100,1,14.870000,100,1,12.470000,100,1,14.890000,100,1,12.460000,100,1,14.950000,700,1,12.430000,700,1,14.980000,200,2,12.420000,700,1,14.990000,700,1,12.370000,700,1,15.070000,700,1,ARL,128573957
2025-07-17T14:05:31.418741362Z,2025-07-17T14:05:31.418575692Z,10,2,1108,C,A,1,14.36,2,0,165670,108664911,13.260000,2,1,14.090000,100,1,13.250000,100,1,14.370000,100,1,12.990000,100,1,14.830000,100,1,12.730000,100,1,14.870000,100,1,12.670000,100,1,14.890000,100,1,12.470000,100,1,14.950000,700,1,12.460000,100,1,14.980000,200,2,12.430000,700,1,14.990000,700,1,12.420000,700,1,15.070000,700,1,12.370000,700,1,15.080000,200,2,ARL,121098341
2025-07-17T14:05:31.418741362Z,2025-07-17T14:05:31.418575692Z,10,2,1108,A,A,1,14.26,2,130,165670,108664911,13.260000,2,1,14.090000,100,1,13.250000,100,1,14.260000,2,1,12.990000,100,1,14.370000,100,1,12.730000,100,1,14.830000,100,1,12.670000,100,1,14.870000,100,1,12.470000,100,1,14.890000,100,1,12.460000,100,1,14.950000,700,1,12.430000,700,1,14.980000,200,2,12.420000,700,1,14.990000,700,1,12.370000,700,1,15.070000,700,1,ARL,129518753
2025-07-17T14:06:01.386006059Z,2025-07-17T14:06:01.385840471Z,10,2,1108,C,B,0,13.26,2,0,165588,109685525,13.250000,100,1,14.090000,100,1,12.990000,100,1,14.260000,2,1,12.730000,100,1,14.370000,100,1,12.670000,100,1,14.830000,100,1,12.470000,100,1,14.870000,100,1,12.460000,100,1,14.890000,100,1,12.430000,700,1,14.950000,700,1,12.420000,700,1,14.980000,200,2,12.370000,700,1,14.990000,700,1,12.360000,200,2,15.070000,700,1,ARL,121098337
2025-07-17T14:06:01.386006059Z,2025-07-17T14:06:01.385840471Z,10,2,1108,A,B,1,13.15,2,130,165588,109685525,13.250000,100,1,14.090000,100,1,13.150000,2,1,14.260000,2,1,12.990000,100,1,14.370000,100,1,12.730000,100,1,14.830000,100,1,12.670000,100,1,14.870000,100,1,12.470000,100,1,14.890000,100,1,12.460000,100,1,14.950000,700,1,12.430000,700,1,14.980000,200,2,12.420000,700,1,14.990000,700,1,12.370000,700,1,15.070000,700,1,ARL,130693973
2025-07-17T14:13:11.346377890Z,2025-07-17T14:13:11.346212166Z,10,2,1108,C,A,13,15.18,100,0,165724,123937587,13.250000,100,1,14.090000,100,1,13.150000,2,1,14.260000,2,1,12.990000,100,1,14.370000,100,1,12.730000,100,1,14.830000,100,1,12.670000,100,1,14.870000,100,1,12.470000,100,1,14.890000,100,1,12.460000,100,1,14.950000,700,1,12.430000,700,1,14.980000,200,2,12.420000,700,1,14.990000,700,1,12.370000,700,1,15.070000,700,1,ARL,128570417
2025-07-17T14:13:11.346377890Z,2025-07-17T14:13:11.346212166Z,10,2,1108,A,A,-1,15.09,100,130,165724,123937587,13.250000,100,1,14.090000,100,1,13.150000,2,1,14.260000,2,1,12.990000,100,1,14.370000,100,1,12.730000,100,1,14.830000,100,1,12.670000,100,1,14.870000,100,1,12.470000,100,1,14.890000,100,1,12.460000,100,1,14.950000,700,1,12.430000,700,1,14.980000,200,2,12.420000,700,1,14.990000,700,1,12.370000,700,1,15.070000,700,1,ARL,146955361
2025-07-17T14:13:11.358916626Z,2025-07-17T14:13:11.358751092Z,10,2,1108,C,A,2,14.37,100,130,165534,123938202,13.250000,100,1,14.090000,100,1,13.150000,2,1,14.260000,2,1,12.990000,100,1,14.830000,100,1,12.730000,100,1,14.870000,100,1,12.670000,100,1,14.890000,100,1,12.470000,100,1,14.950000,700,1,12.460000,100,1,14.980000,200,2,12.430000,700,1,14.990000,700,1,12.420000,700,1,15.070000,700,1,12.370000,700,1,15.080000,200,2,ARL,128570621
2025-07-17T14:13:11.358968656Z,2025-07-17T14:13:11.358802966Z,10,2,1108,A,A,2,14.28,100,130,165690,123938203,13.250000,100,1,14.090000,100,1,13.150000,2,1,14.260000,2,1,12.990000,100,1,14.280000,100,1,12.730000,100,1,14.830000,100,1,12.670000,100,1,14.870000,100,1,12.470000,100,1,14.890000,100,1,12.460000,100,1,14.950000,700,1,12.430000,700,1,14.980000,200,2,12.420000,700,1,14.990000,700,1,12.370000,700,1,15.070000,700,1,ARL,146956357
2025-07-17T14:13:11.393088913Z,2025-07-17T14:13:11.392923396Z,10,2,1108,C,A,16,15.73,100,0,165517,123939815,13.250000,100,1,14.090000,100,1,13.150000,2,1,14.260000,2,1,12.990000,100,1,14.280000,100,1,12.730000,100,1,14.830000,100,1,12.670000,100,1,14.870000,100,1,12.470000,100,1,14.890000,100,1,12.460000,100,1,14.950000,700,1,12.430000,700,1,14.980000,200,2,12.420000,700,1,14.990000,700,1,12.370000,700,1,15.070000,700,1,ARL,84629953
2025-07-17T14:13:11.393088913Z,2025-07-17T14:13:11.392923396Z,10,2,1108,A,A,-1,15.40,100,130,165517,123939815,13.250000,100,1,14.090000,100,1,13.150000,2,1,14.260000,2,1,12.990000,100,1,14.280000,100,1,12.730000,100,1,14.830000,100,1,12.670000,100,1,14.870000,100,1,12.470000,100,1,14.890000,100,1,12.460000,100,1,14.950000,700,1,12.430000,700,1,14.980000,200,2,12.420000,700,1,14.990000,700,1,12.370000,700,1,15.070000,700,1,ARL,146959177
2025-07-17T14:13:11.423482323Z,2025-07-17T14:13:11.423316840Z,10,2,1108,A,A,3,14.56,100,130,165483,123940437,13.250000,100,1,14.090000,100,1,13.150000,2,1,14.260000,2,1,12.990000,100,1,14.280000,100,1,12.730000,100,1,14.560000,100,1,12.670000,100,1,14.830000,100,1,12.470000,100,1,14.870000,100,1,12.460000,100,1,14.890000,100,1,12.430000,700,1,14.950000,700,1,12.420000,700,1,14.980000,200,2,12.370000,700,1,14.990000,700,1,ARL,146960005
2025-07-17T14:13:11.423483431Z,2025-07-17T14:13:11.423317922Z,10,2,1108,C,A,5,14.87,100,130,165509,123940438,13.250000,100,1,14.090000,100,1,13.150000,2,1,14.260000,2,1,12.990000,100,1,14.280000,100,1,12.730000,100,1,14.560000,100,1,12.670000,100,1,14.830000,100,1,12.470000,100,1,14.890000,100,1,12.460000,100,1,14.950000,700,1,12.430000,700,1,14.980000,200,2,12.420000,700,1,14.990000,700,1,12.370000,700,1,15.070000,700,1,ARL,84708037
2025-07-17T14:13:11.555808541Z,2025-07-17T14:13:11.555642984Z,10,2,1108,A,A,5,14.84,100,130,165557,123942727,13.250000,100,1,14.090000,100,1,13.150000,2,1,14.260000,2,1,12.990000,100,1,14.280000,100,1,12.730000,100,1,14.560000,100,1,12.670000,100,1,14.830000,100,1,12.470000,100,1,14.840000,100,1,12.460000,100,1,14.890000,100,1,12.430000,700,1,14.950000,700,1,12.420000,700,1,14.980000,200,2,12.370000,700,1,14.990000,700,1,ARL,146962993
2025-07-17T14:13:11.555828856Z,2025-07-17T14:13:11.555663413Z,10,2,1108,C,A,14,15.16,100,130,165443,123942728,13.250000,100,1,14.090000,100,1,13.150000,2,1,14.260000,2,1,12.990000,100,1,14.280000,100,1,12.730000,100,1,14.560000,100,1,12.670000,100,1,14.830000,100,1,12.470000,100,1,14.840000,100,1,12.460000,100,1,14.890000,100,1,12.430000,700,1,14.950000,700,1,12.420000,700,1,14.980000,200,2,12.370000,700,1,14.990000,700,1,ARL,84668677
2025-07-17T14:13:19.230983072Z,2025-07-17T14:13:19.230817808Z,10,2,1108,A,A,7,14.91,700,130,165264,124169794,13.250000,100,1,14.090000,100,1,13.150000,2,1,14.260000,2,1,12.990000,100,1,14.280000,100,1,12.730000,100,1,14.560000,100,1,12.670000,100,1,14.830000,100,1,12.470000,100,1,14.840000,100,1,12.460000,100,1,14.890000,100,1,12.430000,700,1,14.910000,700,1,12.420000,700,1,14.950000,700,1,12.370000,700,1,14.980000,200,2,ARL,147217629
2025-07-17T14:13:19.231778755Z,2025-07-17T14:13:19.231613044Z,10,2,1108,C,A,14,15.14,700,130,165711,124169802,13.250000,100,1,14.090000,100,1,13.150000,2,1,14.260000,2,1,12.990000,100,1,14.280000,100,1,12.730000,100,1,14.560000,100,1,12.670000,100,1,14.830000,100,1,12.470000,100,1,14.840000,100,1,12.460000,100,1,14.890000,100,1,12.430000,700,1,14.910000,700,1,12.420000,700,1,14.950000,700,1,12.370000,700,1,14.980000,200,2,ARL,84628829
2025-07-17T14:22:28.338174848Z,2025-07-17T14:22:28.338009329Z,10,2,1108,A,A,0,14.00,1,130,165519,142657338,13.250000,100,1,14.000000,1,1,13.150000,2,1,14.090000,100,1,12.990000,100,1,14.260000,2,1,12.730000,100,1,14.280000,100,1,12.670000,100,1,14.560000,100,1,12.470000,100,1,14.830000,100,1,12.460000,100,1,14.840000,100,1,12.430000,700,1,14.890000,100,1,12.420000,700,1,14.910000,700,1,12.370000,700,1,14.950000,700,1,ARL,168073025
2025-07-17T14:22:29.994011311Z,2025-07-17T14:22:29.993845812Z,10,2,1108,C,A,1,14.09,100,0,165499,142715813,13.250000,100,1,14.000000,1,1,13.150000,2,1,14.260000,2,1,12.990000,100,1,14.280000,100,1,12.730000,100,1,14.560000,100,1,12.670000,100,1,14.830000,100,1,12.470000,100,1,14.840000,100,1,12.460000,100,1,14.890000,100,1,12.430000,700,1,14.910000,700,1,12.420000,700,1,14.950000,700,1,12.370000,700,1,14.980000,200,2,ARL,128570317
2025-07-17T14:22:29.994011311Z,2025-07-17T14:22:29.993845812Z,10,2,1108,A,A,1,14.01,100,130,165499,142715813,13.250000,100,1,14.000000,1,1,13.150000,2,1,14.010000,100,1,12.990000,100,1,14.260000,2,1,12.730000,100,1,14.280000,100,1,12.670000,100,1,14.560000,100,1,12.470000,100,1,14.830000,100,1,12.460000,100,1,14.840000,100,1,12.430000,700,1,14.890000,100,1,12.420000,700,1,14.910000,700,1,12.370000,700,1,14.950000,700,1,ARL,168141389
2025-07-17T14:32:58.233129156Z,2025-07-17T14:32:58.232963791Z,10,2,1108,C,B,0,13.25,100,130,165365,162140358,13.150000,2,1,14.000000,1,1,12.990000,100,1,14.010000,100,1,12.730000,100,1,14.260000,2,1,12.670000,100,1,14.280000,100,1,12.470000,100,1,14.560000,100,1,12.460000,100,1,14.830000,100,1,12.430000,700,1,14.840000,100,1,12.420000,700,1,14.890000,100,1,12.370000,700,1,14.910000,700,1,12.360000,200,2,14.950000,700,1,ARL,121107957
2025-07-17T14:32:58.714015555Z,2025-07-17T14:32:58.713850212Z,10,2,1108,A,B,1,13.14,100,130,165343,162149922,13.150000,2,1,14.000000,1,1,13.140000,100,1,14.010000,100,1,12.990000,100,1,14.260000,2,1,12.730000,100,1,14.280000,100,1,12.670000,100,1,14.560000,100,1,12.470000,100,1,14.830000,100,1,12.460000,100,1,14.840000,100,1,12.430000,700,1,14.890000,100,1,12.420000,700,1,14.910000,700,1,12.370000,700,1,14.950000,700,1,ARL,190326921
2025-07-17T14:34:48.346344959Z,2025-07-17T14:34:48.346179643Z,10,2,1108,C,A,0,14.00,1,130,165316,164925706,13.150000,2,1,14.010000,100,1,13.140000,100,1,14.260000,2,1,12.990000,100,1,14.280000,100,1,12.730000,100,1,14.560000,100,1,12.670000,100,1,14.830000,100,1,12.470000,100,1,14.840000,100,1,12.460000,100,1,14.890000,100,1,12.430000,700,1,14.910000,700,1,12.420000,700,1,14.950000,700,1,12.370000,700,1,14.980000,200,2,ARL,168073025
2025-07-17T14:47:30.548081358Z,2025-07-17T14:47:30.547915870Z,10,2,1108,A,B,0,13.38,33,130,165488,183466992,13.380000,33,1,14.010000,100,1,13.150000,2,1,14.260000,2,1,13.140000,100,1,14.280000,100,1,12.990000,100,1,14.560000,100,1,12.730000,100,1,14.830000,100,1,12.670000,100,1,14.840000,100,1,12.470000,100,1,14.890000,100,1,12.460000,100,1,14.910000,700,1,12.430000,700,1,14.950000,700,1,12.420000,700,1,14.980000,200,2,ARL,215999733
2025-07-17T14:47:30.548346701Z,2025-07-17T14:47:30.548180936Z,10,2,1108,C,B,2,13.14,100,0,165765,183466994,13.380000,33,1,14.010000,100,1,13.150000,2,1,14.260000,2,1,12.990000,100,1,14.280000,100,1,12.730000,100,1,14.560000,100,1,12.670000,100,1,14.830000,100,1,12.470000,100,1,14.840000,100,1,12.460000,100,1,14.890000,100,1,12.430000,700,1,14.910000,700,1,12.420000,700,1,14.950000,700,1,12.370000,700,1,14.980000,200,2,ARL,190326921
2025-07-17T14:47:30.548346701Z,2025-07-17T14:47:30.548180936Z,10,2,1108,A,B,1,13.37,100,130,165765,183466994,13.380000,33,1,14.010000,100,1,13.370000,100,1,14.260000,2,1,13.150000,2,1,14.280000,100,1,12.990000,100,1,14.560000,100,1,12.730000,100,1,14.830000,100,1,12.670000,100,1,14.840000,100,1,12.470000,100,1,14.890000,100,1,12.460000,100,1,14.910000,700,1,12.430000,700,1,14.950000,700,1,12.420000,700,1,14.980000,200,2,ARL,215999737
2025-07-17T14:47:30.548831608Z,2025-07-17T14:47:30.548666035Z,10,2,1108,C,B,11,12.36,100,0,165573,183467001,13.380000,33,1,14.010000,100,1,13.370000,100,1,14.260000,2,1,13.150000,2,1,14.280000,100,1,12.990000,100,1,14.560000,100,1,12.730000,100,1,14.830000,100,1,12.670000,100,1,14.840000,100,1,12.470000,100,1,14.890000,100,1,12.460000,100,1,14.910000,700,1,12.430000,700,1,14.950000,700,1,12.420000,700,1,14.980000,200,2,ARL,126872345
2025-07-17T14:47:30.548831608Z,2025-07-17T14:47:30.548666035Z,10,2,1108,A,B,6,12.48,100,130,165573,183467001,13.380000,33,1,14.010000,100,1,13.370000,100,1,14.260000,2,1,13.150000,2,1,14.280000,100,1,12.990000,100,1,14.560000,100,1,12.730000,100,1,14.830000,100,1,12.670000,100,1,14.840000,100,1,12.480000,100,1,14.890000,100,1,12.470000,100,1,14.910000,700,1,12.460000,100,1,14.950000,700,1,12.430000,700,1,14.980000,200,2,ARL,215999741
2025-07-17T14:47:30.549090785Z,2025-07-17T14:47:30.548925394Z,10,2,1108,C,B,15,12.23,100,0,165391,183467002,13.380000,33,1,14.010000,100,1,13.370000,100,1,14.260000,2,1,13.150000,2,1,14.280000,100,1,12.990000,100,1,14.560000,100,1,12.730000,100,1,14.830000,100,1,12.670000,100,1,14.840000,100,1,12.480000,100,1,14.890000,100,1,12.470000,100,1,14.910000,700,1,12.460000,100,1,14.950000,700,1,12.430000,700,1,14.980000,200,2,ARL,43317473
2025-07-17T14:47:30.549090785Z,2025-07-17T14:47:30.548925394Z,10,2,1108,A,B,-1,12.33,100,130,165391,183467002,13.380000,33,1,14.010000,100,1,13.370000,100,1,14.260000,2,1,13.150000,2,1,14.280000,100,1,12.990000,100,1,14.560000,100,1,12.730000,100,1,14.830000,100,1,12.670000,100,1,14.840000,100,1,12.480000,100,1,14.890000,100,1,12.470000,100,1,14.910000,700,1,12.460000,100,1,14.950000,700,1,12.430000,700,1,14.980000,200,2,ARL,215999753
2025-07-17T14:47:30.549341156Z,2025-07-17T14:47:30.549175659Z,10,2,1108,C,B,12,12.36,100,0,165497,183467004,13.380000,33,1,14.010000,100,1,13.370000,100,1,14.260000,2,1,13.150000,2,1,14.280000,100,1,12.990000,100,1,14.560000,100,1,12.730000,100,1,14.830000,100,1,12.670000,100,1,14.840000,100,1,12.480000,100,1,14.890000,100,1,12.470000,100,1,14.910000,700,1,12.460000,100,1,14.950000,700,1,12.430000,700,1,14.980000,200,2,ARL,126872361
2025-07-17T14:47:30.549341156Z,2025-07-17T14:47:30.549175659Z,10,2,1108,A,B,6,12.48,100,130,165497,183467004,13.380000,33,1,14.010000,100,1,13.370000,100,1,14.260000,2,1,13.150000,2,1,14.280000,100,1,12.990000,100,1,14.560000,100,1,12.730000,100,1,14.830000,100,1,12.670000,100,1,14.840000,100,1,12.480000,200,2,14.890000,100,1,12.470000,100,1,14.910000,700,1,12.460000,100,1,14.950000,700,1,12.430000,700,1,14.980000,200,2,ARL,215999761
2025-07-17T14:47:30.571385383Z,2025-07-17T14:47:30.571220121Z,10,2,1108,C,B,3,12.99,100,130,165262,183468111,13.380000,33,1,14.010000,100,1,13.370000,100,1,14.260000,2,1,13.150000,2,1,14.280000,100,1,12.730000,100,1,14.560000,100,1,12.670000,100,1,14.830000,100,1,12.480000,200,2,14.840000,100,1,12.470000,100,1,14.890000,100,1,12.460000,100,1,14.910000,700,1,12.430000,700,1,14.950000,700,1,12.420000,700,1,14.980000,200,2,ARL,43805737
2025-07-17T14:47:30.571436944Z,2025-07-17T14:47:30.571271737Z,10,2,1108,A,B,3,13.10,100,130,165207,183468112,13.380000,33,1,14.010000,100,1,13.370000,100,1,14.260000,2,1,13.150000,2,1,14.280000,100,1,13.100000,100,1,14.560000,100,1,12.730000,100,1,14.830000,100,1,12.670000,100,1,14.840000,100,1,12.480000,200,2,14.890000,100,1,12.470000,100,1,14.910000,700,1,12.460000,100,1,14.950000,700,1,12.430000,700,1,14.980000,200,2,ARL,216001413
2025-07-17T14:47:37.384610677Z,2025-07-17T14:47:37.384441232Z,10,2,1108,A,B,6,12.50,700,130,169445,183649796,13.380000,33,1,14.010000,100,1,13.370000,100,1,14.260000,2,1,13.150000,2,1,14.280000,100,1,13.100000,100,1,14.560000,100,1,12.730000,100,1,14.830000,100,1,12.670000,100,1,14.840000,100,1,12.500000,700,1,14.890000,100,1,12.480000,200,2,14.910000,700,1,12.470000,100,1,14.950000,700,1,12.460000,100,1,14.980000,200,2,ARL,216223005
2025-07-17T14:47:37.385400265Z,2025-07-17T14:47:37.385234288Z,10,2,1108,C,B,14,12.26,700,130,165977,183649801,13.380000,33,1,14.010000,100,1,13.370000,100,1,14.260000,2,1,13.150000,2,1,14.280000,100,1,13.100000,100,1,14.560000,100,1,12.730000,100,1,14.830000,100,1,12.670000,100,1,14.840000,100,1,12.500000,700,1,14.890000,100,1,12.480000,200,2,14.910000,700,1,12.470000,100,1,14.950000,700,1,12.460000,100,1,14.980000,200,2,ARL,44570585
2025-07-17T14:52:02.610509102Z,2025-07-17T14:52:02.610343819Z,10,2,1108,A,A,0,13.71,1,130,165283,189559141,13.380000,33,1,13.710000,1,1,13.370000,100,1,14.010000,100,1,13.150000,2,1,14.260000,2,1,13.100000,100,1,14.280000,100,1,12.730000,100,1,14.560000,100,1,12.670000,100,1,14.830000,100,1,12.500000,700,1,14.840000,100,1,12.480000,200,2,14.890000,100,1,12.470000,100,1,14.910000,700,1,12.460000,100,1,14.950000,700,1,ARL,223347833
2025-07-17T14:52:02.611701408Z,2025-07-17T14:52:02.611536221Z,10,2,1108,C,A,0,13.71,1,130,165187,189559156,13.380000,33,1,14.010000,100,1,13.370000,100,1,14.260000,2,1,13.150000,2,1,14.280000,100,1,13.100000,100,1,14.560000,100,1,12.730000,100,1,14.830000,100,1,12.670000,100,1,14.840000,100,1,12.500000,700,1,14.890000,100,1,12.480000,200,2,14.910000,700,1,12.470000,100,1,14.950000,700,1,12.460000,100,1,14.980000,200,2,ARL,223347833
2025-07-17T15:00:11.560678862Z,2025-07-17T15:00:11.560513555Z,10,2,1108,C,B,0,13.38,33,130,165307,200140364,13.370000,100,1,14.010000,100,1,13.150000,2,1,14.260000,2,1,13.100000,100,1,14.280000,100,1,12.730000,100,1,14.560000,100,1,12.670000,100,1,14.830000,100,1,12.500000,700,1,14.840000,100,1,12.480000,200,2,14.890000,100,1,12.470000,100,1,14.910000,700,1,12.460000,100,1,14.950000,700,1,12.430000,700,1,14.980000,200,2,ARL,215999733
2025-07-17T15:00:11.563053782Z,2025-07-17T15:00:11.562887948Z,10,2,1108,C,B,6,12.48,100,0,165834,200140389,13.370000,100,1,14.010000,100,1,13.150000,2,1,14.260000,2,1,13.100000,100,1,14.280000,100,1,12.730000,100,1,14.560000,100,1,12.670000,100,1,14.830000,100,1,12.500000,700,1,14.840000,100,1,12.480000,100,1,14.890000,100,1,12.470000,100,1,14.910000,700,1,12.460000,100,1,14.950000,700,1,12.430000,700,1,14.980000,200,2,ARL,215999761
2025-07-17T15:00:11.563053782Z,2025-07-17T15:00:11.562887948Z,10,2,1108,A,B,5,12.65,100,130,165834,200140389,13.370000,100,1,14.010000,100,1,13.150000,2,1,14.260000,2,1,13.100000,100,1,14.280000,100,1,12.730000,100,1,14.560000,100,1,12.670000,100,1,14.830000,100,1,12.650000,100,1,14.840000,100,1,12.500000,700,1,14.890000,100,1,12.480000,100,1,14.910000,700,1,12.470000,100,1,14.950000,700,1,12.460000,100,1,14.980000,200,2,ARL,236179089
2025-07-17T15:00:12.536218524Z,2025-07-17T15:00:12.536052536Z,10,2,1108,C,B,7,12.48,100,0,165988,200161810,13.370000,100,1,14.010000,100,1,13.150000,2,1,14.260000,2,1,13.100000,100,1,14.280000,100,1,12.730000,100,1,14.560000,100,1,12.670000,100,1,14.830000,100,1,12.650000,100,1,14.840000,100,1,12.500000,700,1,14.890000,100,1,12.470000,100,1,14.910000,700,1,12.460000,100,1,14.950000,700,1,12.430000,700,1,14.980000,200,2,ARL,215999741
2025-07-17T15:00:12.536218524Z,2025-07-17T15:00:12.536052536Z,10,2,1108,A,B,5,12.65,100,130,165988,200161810,13.370000,100,1,14.010000,100,1,13.150000,2,1,14.260000,2,1,13.100000,100,1,14.280000,100,1,12.730000,100,1,14.560000,100,1,12.670000,100,1,14.830000,100,1,12.650000,200,2,14.840000,100,1,12.500000,700,1,14.890000,100,1,12.470000,100,1,14.910000,700,1,12.460000,100,1,14.950000,700,1,12.430000,700,1,14.980000,200,2,ARL,236206261
2025-07-17T15:01:11.658789910Z,2025-07-17T15:01:11.658624662Z,10,2,1108,A,A,0,13.98,10,130,165248,201616674,13.370000,100,1,13.980000,10,1,13.150000,2,1,14.010000,100,1,13.100000,100,1,14.260000,2,1,12.730000,100,1,14.280000,100,1,12.670000,100,1,14.560000,100,1,12.650000,200,2,14.830000,100,1,12.500000,700,1,14.840000,100,1,12.470000,100,1,14.890000,100,1,12.460000,100,1,14.910000,700,1,12.430000,700,1,14.950000,700,1,ARL,237940713
2025-07-17T15:01:12.948386121Z,2025-07-17T15:01:12.948220412Z,10,2,1108,C,A,1,14.01,100,0,165709,201642675,13.370000,100,1,13.980000,10,1,13.150000,2,1,14.260000,2,1,13.100000,100,1,14.280000,100,1,12.730000,100,1,14.560000,100,1,12.670000,100,1,14.830000,100,1,12.650000,200,2,14.840000,100,1,12.500000,700,1,14.890000,100,1,12.470000,100,1,14.910000,700,1,12.460000,100,1,14.950000,700,1,12.430000,700,1,14.980000,200,2,ARL,168141389
2025-07-17T15:01:12.948386121Z,2025-07-17T15:01:12.948220412Z,10,2,1108,A,A,1,13.99,100,130,165709,201642675,13.370000,100,1,13.980000,10,1,13.150000,2,1,13.990000,100,1,13.100000,100,1,14.260000,2,1,12.730000,100,1,14.280000,100,1,12.670000,100,1,14.560000,100,1,12.650000,200,2,14.830000,100,1,12.500000,700,1,14.840000,100,1,12.470000,100,1,14.890000,100,1,12.460000,100,1,14.910000,700,1,12.430000,700,1,14.950000,700,1,ARL,237978541
2025-07-17T15:01:12.949124493Z,2025-07-17T15:01:12.948959226Z,10,2,1108,C,A,5,14.83,100,130,165267,201642712,13.370000,100,1,13.980000,10,1,13.150000,2,1,13.990000,100,1,13.100000,100,1,14.260000,2,1,12.730000,100,1,14.280000,100,1,12.670000,100,1,14.560000,100,1,12.650000,200,2,14.840000,100,1,12.500000,700,1,14.890000,100,1,12.470000,100,1,14.910000,700,1,12.460000,100,1,14.950000,700,1,12.430000,700,1,14.980000,200,2,ARL,84628793
2025-07-17T15:01:12.949484115Z,2025-07-17T15:01:12.949317198Z,10,2,1108,A,A,5,14.61,100,130,166917,201642747,13.370000,100,1,13.980000,10,1,13.150000,2,1,13.990000,100,1,13.100000,100,1,14.260000,2,1,12.730000,100,1,14.280000,100,1,12.670000,100,1,14.560000,100,1,12.650000,200,2,14.610000,100,1,12.500000,700,1,14.840000,100,1,12.470000,100,1,14.890000,100,1,12.460000,100,1,14.910000,700,1,12.430000,700,1,14.950000,700,1,ARL,237978629
2025-07-17T15:01:26.963916368Z,2025-07-17T15:01:26.963746832Z,10,2,1108,C,A,0,13.98,10,128,169536,201984003,13.370000,100,1,13.990000,100,1,13.150000,2,1,14.260000,2,1,13.100000,100,1,14.280000,100,1,12.730000,100,1,14.560000,100,1,12.670000,100,1,14.610000,100,1,12.650000,200,2,14.840000,100,1,12.500000,700,1,14.890000,100,1,12.470000,100,1,14.910000,700,1,12.460000,100,1,14.950000,700,1,12.430000,700,1,14.980000,200,2,ARL,237940713
2025-07-17T15:01:37.513312432Z,2025-07-17T15:01:37.513147090Z,10,2,1108,A,A,0,13.98,10,130,165342,202186180,13.370000,100,1,13.980000,10,1,13.150000,2,1,13.990000,100,1,13.100000,100,1,14.260000,2,1,12.730000,100,1,14.280000,100,1,12.670000,100,1,14.560000,100,1,12.650000,200,2,14.610000,100,1,12.500000,700,1,14.840000,100,1,12.470000,100,1,14.890000,100,1,12.460000,100,1,14.910000,700,1,12.430000,700,1,14.950000,700,1,ARL,238668633
2025-07-17T15:05:36.047202557Z,2025-07-17T15:05:36.047029298Z,10,2,1108,C,A,0,13.98,10,128,173259,207097179,13.370000,100,1,13.990000,100,1,13.150000,2,1,14.260000,2,1,13.100000,100,1,14.280000,100,1,12.730000,100,1,14.560000,100,1,12.670000,100,1,14.610000,100,1,12.650000,200,2,14.840000,100,1,12.500000,700,1,14.890000,100,1,12.470000,100,1,14.910000,700,1,12.460000,100,1,14.950000,700,1,12.430000,700,1,14.980000,200,2,ARL,238668633
2025-07-17T15:10:34.469866273Z,2025-07-17T15:10:34.469700487Z,10,2,1108,C,A,1,14.26,2,0,165786,213735006,13.370000,100,1,13.990000,100,1,13.150000,2,1,14.280000,100,1,13.100000,100,1,14.560000,100,1,12.730000,100,1,14.610000,100,1,12.670000,100,1,14.840000,100,1,12.650000,200,2,14.890000,100,1,12.500000,700,1,14.910000,700,1,12.470000,100,1,14.950000,700,1,12.460000,100,1,14.980000,200,2,12.430000,700,1,14.990000,700,1,ARL,129518753
2025-07-17T15:10:34.469866273Z,2025-07-17T15:10:34.469700487Z,10,2,1108,A,A,1,14.17,2,130,165786,213735006,13.370000,100,1,13.990000,100,1,13.150000,2,1,14.170000,2,1,13.100000,100,1,14.280000,100,1,12.730000,100,1,14.560000,100,1,12.670000,100,1,14.610000,100,1,12.650000,200,2,14.840000,100,1,12.500000,700,1,14.890000,100,1,12.470000,100,1,14.910000,700,1,12.460000,100,1,14.950000,700,1,12.430000,700,1,14.980000,200,2,ARL,252720897
2025-07-17T15:12:52.735414592Z,2025-07-17T15:12:52.735249178Z,10,2,1108,A,A,1,14.03,100,130,165414,216651092,13.370000,100,1,13.990000,100,1,13.150000,2,1,14.030000,100,1,13.100000,100,1,14.170000,2,1,12.730000,100,1,14.280000,100,1,12.670000,100,1,14.560000,100,1,12.650000,200,2,14.610000,100,1,12.500000,700,1,14.840000,100,1,12.470000,100,1,14.890000,100,1,12.460000,100,1,14.910000,700,1,12.430000,700,1,14.950000,700,1,ARL,256325129
2025-07-17T15:13:06.511853457Z,2025-07-17T15:13:06.511687613Z,10,2,1108,A,A,0,13.98,10,130,165844,216995105,13.370000,100,1,13.980000,10,1,13.150000,2,1,13.990000,100,1,13.100000,100,1,14.030000,100,1,12.730000,100,1,14.170000,2,1,12.670000,100,1,14.280000,100,1,12.650000,200,2,14.560000,100,1,12.500000,700,1,14.610000,100,1,12.470000,100,1,14.840000,100,1,12.460000,100,1,14.890000,100,1,12.430000,700,1,14.910000,700,1,ARL,256739841
2025-07-17T15:13:08.654089411Z,2025-07-17T15:13:08.653923821Z,10,2,1108,A,A,2,14.01,100,130,165590,217058300,13.370000,100,1,13.980000,10,1,13.150000,2,1,13.990000,100,1,13.100000,100,1,14.010000,100,1,12.730000,100,1,14.030000,100,1,12.670000,100,1,14.170000,2,1,12.650000,200,2,14.280000,100,1,12.500000,700,1,14.560000,100,1,12.470000,100,1,14.610000,100,1,12.460000,100,1,14.840000,100,1,12.430000,700,1,14.890000,100,1,ARL,256818881
2025-07-17T15:13:08.661686458Z,2025-07-17T15:13:08.661521116Z,10,2,1108,C,A,3,14.03,100,130,165342,217058550,13.370000,100,1,13.980000,10,1,13.150000,2,1,13.990000,100,1,13.100000,100,1,14.010000,100,1,12.730000,100,1,14.170000,2,1,12.670000,100,1,14.280000,100,1,12.650000,200,2,14.560000,100,1,12.500000,700,1,14.610000,100,1,12.470000,100,1,14.840000,100,1,12.460000,100,1,14.890000,100,1,12.430000,700,1,14.910000,700,1,ARL,256325129
2025-07-17T15:14:00.440728359Z,2025-07-17T15:14:00.440563034Z,10,2,1108,C,A,0,13.98,10,130,165325,218096891,13.370000,100,1,13.990000,100,1,13.150000,2,1,14.010000,100,1,13.100000,100,1,14.170000,2,1,12.730000,100,1,14.280000,100,1,12.670000,100,1,14.560000,100,1,12.650000,200,2,14.610000,100,1,12.500000,700,1,14.840000,100,1,12.470000,100,1,14.890000,100,1,12.460000,100,1,14.910000,700,1,12.430000,700,1,14.950000,700,1,ARL,256739841
2025-07-17T15:14:52.382139830Z,2025-07-17T15:14:52.381974473Z,10,2,1108,A,A,0,13.98,10,130,165357,219204095,13.370000,100,1,13.980000,10,1,13.150000,2,1,13.990000,100,1,13.100000,100,1,14.010000,100,1,12.730000,100,1,14.170000,2,1,12.670000,100,1,14.280000,100,1,12.650000,200,2,14.560000,100,1,12.500000,700,1,14.610000,100,1,12.470000,100,1,14.840000,100,1,12.460000,100,1,14.890000,100,1,12.430000,700,1,14.910000,700,1,ARL,259546169
2025-07-17T15:14:56.683309707Z,2025-07-17T15:14:56.683144163Z,10,2,1108,C,A,2,14.01,100,130,165544,219317677,13.370000,100,1,13.980000,10,1,13.150000,2,1,13.990000,100,1,13.100000,100,1,14.170000,2,1,12.730000,100,1,14.280000,100,1,12.670000,100,1,14.560000,100,1,12.650000,200,2,14.610000,100,1,12.500000,700,1,14.840000,100,1,12.470000,100,1,14.890000,100,1,12.460000,100,1,14.910000,700,1,12.430000,700,1,14.950000,700,1,ARL,256818881
2025-07-17T15:15:11.661118778Z,2025-07-17T15:15:11.660953613Z,10,2,1108,A,A,2,14.02,100,130,165165,219726276,13.370000,100,1,13.980000,10,1,13.150000,2,1,13.990000,100,1,13.100000,100,1,14.020000,100,1,12.730000,100,1,14.170000,2,1,12.670000,100,1,14.280000,100,1,12.650000,200,2,14.560000,100,1,12.500000,700,1,14.610000,100,1,12.470000,100,1,14.840000,100,1,12.460000,100,1,14.890000,100,1,12.430000,700,1,14.910000,700,1,ARL,260184621
2025-07-17T15:15:32.408863263Z,2025-07-17T15:15:32.408694312Z,10,2,1108,C,A,0,13.98,10,128,168951,220152194,13.370000,100,1,13.990000,100,1,13.150000,2,1,14.020000,100,1,13.100000,100,1,14.170000,2,1,12.730000,100,1,14.280000,100,1,12.670000,100,1,14.560000,100,1,12.650000,200,2,14.610000,100,1,12.500000,700,1,14.840000,100,1,12.470000,100,1,14.890000,100,1,12.460000,100,1,14.910000,700,1,12.430000,700,1,14.950000,700,1,ARL,259546169
2025-07-17T15:16:31.607242914Z,2025-07-17T15:16:31.607077080Z,10,2,1108,A,A,1,14.00,100,130,165834,221423516,13.370000,100,1,13.990000,100,1,13.150000,2,1,14.000000,100,1,13.100000,100,1,14.020000,100,1,12.730000,100,1,14.170000,2,1,12.670000,100,1,14.280000,100,1,12.650000,200,2,14.560000,100,1,12.500000,700,1,14.610000,100,1,12.470000,100,1,14.840000,100,1,12.460000,100,1,14.890000,100,1,12.430000,700,1,14.910000,700,1,ARL,262279553
2025-07-17T15:16:31.614370696Z,2025-07-17T15:16:31.614205345Z,10,2,1108,C,A,2,14.02,100,130,165351,221423706,13.370000,100,1,13.990000,100,1,13.150000,2,1,14.000000,100,1,13.100000,100,1,14.170000,2,1,12.730000,100,1,14.280000,100,1,12.670000,100,1,14.560000,100,1,12.650000,200,2,14.610000,100,1,12.500000,700,1,14.840000,100,1,12.470000,100,1,14.890000,100,1,12.460000,100,1,14.910000,700,1,12.430000,700,1,14.950000,700,1,ARL,260184621
2025-07-17T15:16:39.373467449Z,2025-07-17T15:16:39.373301585Z,10,2,1108,A,A,0,13.98,10,130,165864,221549244,13.370000,100,1,13.980000,10,1,13.150000,2,1,13.990000,100,1,13.100000,100,1,14.000000,100,1,12.730000,100,1,14.170000,2,1,12.670000,100,1,14.280000,100,1,12.650000,200,2,14.560000,100,1,12.500000,700,1,14.610000,100,1,12.470000,100,1,14.840000,100,1,12.460000,100,1,14.890000,100,1,12.430000,700,1,14.910000,700,1,ARL,262432821
2025-07-17T15:17:50.916325497Z,2025-07-17T15:17:50.916157330Z,10,2,1108,C,A,0,13.98,10,130,168167,223060323,13.370000,100,1,13.990000,100,1,13.150000,2,1,14.000000,100,1,13.100000,100,1,14.170000,2,1,12.730000,100,1,14.280000,100,1,12.670000,100,1,14.560000,100,1,12.650000,200,2,14.610000,100,1,12.500000,700,1,14.840000,100,1,12.470000,100,1,14.890000,100,1,12.460000,100,1,14.910000,700,1,12.430000,700,1,14.950000,700,1,ARL,262432821
2025-07-17T15:17:51.938467389Z,2025-07-17T15:17:51.938301087Z,10,2,1108,C,A,1,14.00,100,130,166302,223092013,13.370000,100,1,13.990000,100,1,13.150000,2,1,14.170000,2,1,13.100000,100,1,14.280000,100,1,12.730000,100,1,14.560000,100,1,12.670000,100,1,14.610000,100,1,12.650000,200,2,14.840000,100,1,12.500000,700,1,14.890000,100,1,12.470000,100,1,14.910000,700,1,12.460000,100,1,14.950000,700,1,12.430000,700,1,14.980000,200,2,ARL,262279553
2025-07-17T15:17:55.957423821Z,2025-07-17T15:17:55.957258362Z,10,2,1108,A,A,1,14.01,100,130,165459,223181022,13.370000,100,1,13.990000,100,1,13.150000,2,1,14.010000,100,1,13.100000,100,1,14.170000,2,1,12.730000,100,1,14.280000,100,1,12.670000,100,1,14.560000,100,1,12.650000,200,2,14.610000,100,1,12.500000,700,1,14.840000,100,1,12.470000,100,1,14.890000,100,1,12.460000,100,1,14.910000,700,1,12.430000,700,1,14.950000,700,1,ARL,264420961
2025-07-17T15:19:23.618380576Z,2025-07-17T15:19:23.618215364Z,10,2,1108,C,A,1,14.01,100,130,165212,224925658,13.370000,100,1,13.990000,100,1,13.150000,2,1,14.170000,2,1,13.100000,100,1,14.280000,100,1,12.730000,100,1,14.560000,100,1,12.670000,100,1,14.610000,100,1,12.650000,200,2,14.840000,100,1,12.500000,700,1,14.890000,100,1,12.470000,100,1,14.910000,700,1,12.460000,100,1,14.950000,700,1,12.430000,700,1,14.980000,200,2,ARL,264420961
2025-07-17T15:19:27.663790911Z,2025-07-17T15:19:27.663625107Z,10,2,1108,A,A,1,14.03,100,130,165804,224999109,13.370000,100,1,13.990000,100,1,13.150000,2,1,14.030000,100,1,13.100000,100,1,14.170000,2,1,12.730000,100,1,14.280000,100,1,12.670000,100,1,14.560000,100,1,12.650000,200,2,14.610000,100,1,12.500000,700,1,14.840000,100,1,12.470000,100,1,14.890000,100,1,12.460000,100,1,14.910000,700,1,12.430000,700,1,14.950000,700,1,ARL,266714557
2025-07-17T15:20:46.705145876Z,2025-07-17T15:20:46.704980311Z,10,2,1108,A,A,1,14.01,100,130,165565,226851430,13.370000,100,1,13.990000,100,1,13.150000,2,1,14.010000,100,1,13.100000,100,1,14.030000,100,1,12.730000,100,1,14.170000,2,1,12.670000,100,1,14.280000,100,1,12.650000,200,2,14.560000,100,1,12.500000,700,1,14.610000,100,1,12.470000,100,1,14.840000,100,1,12.460000,100,1,14.890000,100,1,12.430000,700,1,14.910000,700,1,ARL,269075833
2025-07-17T15:20:46.716698477Z,2025-07-17T15:20:46.716532886Z,10,2,1108,C,A,2,14.03,100,130,165591,226851533,13.370000,100,1,13.990000,100,1,13.150000,2,1,14.010000,100,1,13.100000,100,1,14.170000,2,1,12.730000,100,1,14.280000,100,1,12.670000,100,1,14.560000,100,1,12.650000,200,2,14.610000,100,1,12.500000,700,1,14.840000,100,1,12.470000,100,1,14.890000,100,1,12.460000,100,1,14.910000,700,1,12.430000,700,1,14.950000,700,1,ARL,266714557
2025-07-17T15:23:00.249962772Z,2025-07-17T15:23:00.249796874Z,10,2,1108,C,B,1,13.15,2,0,165898,229397485,13.370000,100,1,13.990000,100,1,13.100000,100,1,14.010000,100,1,12.730000,100,1,14.170000,2,1,12.670000,100,1,14.280000,100,1,12.650000,200,2,14.560000,100,1,12.500000,700,1,14.610000,100,1,12.470000,100,1,14.840000,100,1,12.460000,100,1,14.890000,100,1,12.430000,700,1,14.910000,700,1,12.420000,700,1,14.950000,700,1,ARL,130693973
2025-07-17T15:23:00.249962772Z,2025-07-17T15:23:00.249796874Z,10,2,1108,A,B,1,13.23,2,130,165898,229397485,13.370000,100,1,13.990000,100,1,13.230000,2,1,14.010000,100,1,13.100000,100,1,14.170000,2,1,12.730000,100,1,14.280000,100,1,12.670000,100,1,14.560000,100,1,12.650000,200,2,14.610000,100,1,12.500000,700,1,14.840000,100,1,12.470000,100,1,14.890000,100,1,12.460000,100,1,14.910000,700,1,12.430000,700,1,14.950000,700,1,ARL,272263853
2025-07-17T15:26:04.666158860Z,2025-07-17T15:26:04.665993515Z,10,2,1108,C,A,2,14.17,2,0,165345,232977340,13.370000,100,1,13.990000,100,1,13.230000,2,1,14.010000,100,1,13.100000,100,1,14.280000,100,1,12.730000,100,1,14.560000,100,1,12.670000,100,1,14.610000,100,1,12.650000,200,2,14.840000,100,1,12.500000,700,1,14.890000,100,1,12.470000,100,1,14.910000,700,1,12.460000,100,1,14.950000,700,1,12.430000,700,1,14.980000,200,2,ARL,252720897
2025-07-17T15:26:04.666158860Z,2025-07-17T15:26:04.665993515Z,10,2,1108,A,A,2,14.09,2,130,165345,232977340,13.370000,100,1,13.990000,100,1,13.230000,2,1,14.010000,100,1,13.100000,100,1,14.090000,2,1,12.730000,100,1,14.280000,100,1,12.670000,100,1,14.560000,100,1,12.650000,200,2,14.610000,100,1,12.500000,700,1,14.840000,100,1,12.470000,100,1,14.890000,100,1,12.460000,100,1,14.910000,700,1,12.430000,700,1,14.950000,700,1,ARL,276751517
2025-07-17T15:28:38.882985923Z,2025-07-17T15:28:38.882820591Z,10,2,1108,A,A,0,13.99,100,130,165332,235874491,13.370000,100,1,13.990000,200,2,13.230000,2,1,14.010000,100,1,13.100000,100,1,14.090000,2,1,12.730000,100,1,14.280000,100,1,12.670000,100,1,14.560000,100,1,12.650000,200,2,14.610000,100,1,12.500000,700,1,14.840000,100,1,12.470000,100,1,14.890000,100,1,12.460000,100,1,14.910000,700,1,12.430000,700,1,14.950000,700,1,ARL,280387693
2025-07-17T15:28:38.890789214Z,2025-07-17T15:28:38.890623989Z,10,2,1108,C,A,1,14.01,100,130,165225,235874556,13.370000,100,1,13.990000,200,2,13.230000,2,1,14.090000,2,1,13.100000,100,1,14.280000,100,1,12.730000,100,1,14.560000,100,1,12.670000,100,1,14.610000,100,1,12.650000,200,2,14.840000,100,1,12.500000,700,1,14.890000,100,1,12.470000,100,1,14.910000,700,1,12.460000,100,1,14.950000,700,1,12.430000,700,1,14.980000,200,2,ARL,269075833
2025-07-17T15:28:44.820934614Z,2025-07-17T15:28:44.820769301Z,10,2,1108,C,A,0,13.99,100,130,165313,235961324,13.370000,100,1,13.990000,100,1,13.230000,2,1,14.090000,2,1,13.100000,100,1,14.280000,100,1,12.730000,100,1,14.560000,100,1,12.670000,100,1,14.610000,100,1,12.650000,200,2,14.840000,100,1,12.500000,700,1,14.890000,100,1,12.470000,100,1,14.910000,700,1,12.460000,100,1,14.950000,700,1,12.430000,700,1,14.980000,200,2,ARL,280387693
2025-07-17T15:28:48.918811203Z,2025-07-17T15:28:48.918645728Z,10,2,1108,A,A,1,14.01,100,130,165475,236028551,13.370000,100,1,13.990000,100,1,13.230000,2,1,14.010000,100,1,13.100000,100,1,14.090000,2,1,12.730000,100,1,14.280000,100,1,12.670000,100,1,14.560000,100,1,12.650000,200,2,14.610000,100,1,12.500000,700,1,14.840000,100,1,12.470000,100,1,14.890000,100,1,12.460000,100,1,14.910000,700,1,12.430000,700,1,14.950000,700,1,ARL,280580873
2025-07-17T15:30:23.573233259Z,2025-07-17T15:30:23.573067851Z,10,2,1108,A,A,0,13.82,10,130,165408,237754758,13.370000,100,1,13.820000,10,1,13.230000,2,1,13.990000,100,1,13.100000,100,1,14.010000,100,1,12.730000,100,1,14.090000,2,1,12.670000,100,1,14.280000,100,1,12.650000,200,2,14.560000,100,1,12.500000,700,1,14.610000,100,1,12.470000,100,1,14.840000,100,1,12.460000,100,1,14.890000,100,1,12.430000,700,1,14.910000,700,1,ARL,282775557
2025-07-17T15:30:23.573528359Z,2025-07-17T15:30:23.573362522Z,10,2,1108,C,A,11,14.98,100,0,165837,237754762,13.370000,100,1,13.820000,10,1,13.230000,2,1,13.990000,100,1,13.100000,100,1,14.010000,100,1,12.730000,100,1,14.090000,2,1,12.670000,100,1,14.280000,100,1,12.650000,200,2,14.560000,100,1,12.500000,700,1,14.610000,100,1,12.470000,100,1,14.840000,100,1,12.460000,100,1,14.890000,100,1,12.430000,700,1,14.910000,700,1,ARL,128570237
2025-07-17T15:30:23.573528359Z,2025-07-17T15:30:23.573362522Z,10,2,1108,A,A,7,14.72,100,130,165837,237754762,13.370000,100,1,13.820000,10,1,13.230000,2,1,13.990000,100,1,13.100000,100,1,14.010000,100,1,12.730000,100,1,14.090000,2,1,12.670000,100,1,14.280000,100,1,12.650000,200,2,14.560000,100,1,12.500000,700,1,14.610000,100,1,12.470000,100,1,14.720000,100,1,12.460000,100,1,14.840000,100,1,12.430000,700,1,14.890000,100,1,ARL,282775561
2025-07-17T15:30:23.574854165Z,2025-07-17T15:30:23.574688647Z,10,2,1108,C,A,12,14.98,100,0,165518,237754776,13.370000,100,1,13.820000,10,1,13.230000,2,1,13.990000,100,1,13.100000,100,1,14.010000,100,1,12.730000,100,1,14.090000,2,1,12.670000,100,1,14.280000,100,1,12.650000,200,2,14.560000,100,1,12.500000,700,1,14.610000,100,1,12.470000,100,1,14.720000,100,1,12.460000,100,1,14.840000,100,1,12.430000,700,1,14.890000,100,1,ARL,128570229
2025-07-17T15:30:23.574854165Z,2025-07-17T15:30:23.574688647Z,10,2,1108,A,A,7,14.72,100,130,165518,237754776,13.370000,100,1,13.820000,10,1,13.230000,2,1,13.990000,100,1,13.100000,100,1,14.010000,100,1,12.730000,100,1,14.090000,2,1,12.670000,100,1,14.280000,100,1,12.650000,200,2,14.560000,100,1,12.500000,700,1,14.610000,100,1,12.470000,100,1,14.720000,200,2,12.460000,100,1,14.840000,100,1,12.430000,700,1,14.890000,100,1,ARL,282775577
2025-07-17T15:30:23.585191081Z,2025-07-17T15:30:23.585025490Z,10,2,1108,A,A,1,13.84,100,130,165591,237755075,13.370000,100,1,13.820000,10,1,13.230000,2,1,13.840000,100,1,13.100000,100,1,13.990000,100,1,12.730000,100,1,14.010000,100,1,12.670000,100,1,14.090000,2,1,12.650000,200,2,14.280000,100,1,12.500000,700,1,14.560000,100,1,12.470000,100,1,14.610000,100,1,12.460000,100,1,14.720000,200,2,12.430000,700,1,14.840000,100,1,ARL,282775973
2025-07-17T15:30:23.585960886Z,2025-07-17T15:30:23.585795327Z,10,2,1108,C,A,16,15.09,100,0,165559,237755081,13.370000,100,1,13.820000,10,1,13.230000,2,1,13.840000,100,1,13.100000,100,1,13.990000,100,1,12.730000,100,1,14.010000,100,1,12.670000,100,1,14.090000,2,1,12.650000,200,2,14.280000,100,1,12.500000,700,1,14.560000,100,1,12.470000,100,1,14.610000,100,1,12.460000,100,1,14.720000,200,2,12.430000,700,1,14.840000,100,1,ARL,146955361
2025-07-17T15:30:23.585960886Z,2025-07-17T15:30:23.585795327Z,10,2,1108,A,A,-1,14.91,100,130,165559,237755081,13.370000,100,1,13.820000,10,1,13.230000,2,1,13.840000,100,1,13.100000,100,1,13.990000,100,1,12.730000,100,1,14.010000,100,1,12.670000,100,1,14.090000,2,1,12.650000,200,2,14.280000,100,1,12.500000,700,1,14.560000,100,1,12.470000,100,1,14.610000,100,1,12.460000,100,1,14.720000,200,2,12.430000,700,1,14.840000,100,1,ARL,282776009
2025-07-17T15:30:23.586719371Z,2025-07-17T15:30:23.586553674Z,10,2,1108,C,A,10,14.89,100,0,165697,237755086,13.370000,100,1,13.820000,10,1,13.230000,2,1,13.840000,100,1,13.100000,100,1,13.990000,100,1,12.730000,100,1,14.010000,100,1,12.670000,100,1,14.090000,2,1,12.650000,200,2,14.280000,100,1,12.500000,700,1,14.560000,100,1,12.470000,100,1,14.610000,100,1,12.460000,100,1,14.720000,200,2,12.430000,700,1,14.840000,100,1,ARL,128570453
2025-07-17T15:30:23.586719371Z,2025-07-17T15:30:23.586553674Z,10,2,1108,A,A,8,14.65,100,130,165697,237755086,13.370000,100,1,13.820000,10,1,13.230000,2,1,13.840000,100,1,13.100000,100,1,13.990000,100,1,12.730000,100,1,14.010000,100,1,12.670000,100,1,14.090000,2,1,12.650000,200,2,14.280000,100,1,12.500000,700,1,14.560000,100,1,12.470000,100,1,14.610000,100,1,12.460000,100,1,14.650000,100,1,12.430000,700,1,14.720000,200,2,ARL,282776013
2025-07-17T15:30:23.586762105Z,2025-07-17T15:30:23.586596452Z,10,2,1108,C,A,18,15.64,100,0,165653,237755087,13.370000,100,1,13.820000,10,1,13.230000,2,1,13.840000,100,1,13.100000,100,1,13.990000,100,1,12.730000,100,1,14.010000,100,1,12.670000,100,1,14.090000,2,1,12.650000,200,2,14.280000,100,1,12.500000,700,1,14.560000,100,1,12.470000,100,1,14.610000,100,1,12.460000,100,1,14.650000,100,1,12.430000,700,1,14.720000,200,2,ARL,84628833
2025-07-17T15:30:23.586762105Z,2025-07-17T15:30:23.586596452Z,10,2,1108,A,A,-1,15.23,100,130,165653,237755087,13.370000,100,1,13.820000,10,1,13.230000,2,1,13.840000,100,1,13.100000,100,1,13.990000,100,1,12.730000,100,1,14.010000,100,1,12.670000,100,1,14.090000,2,1,12.650000,200,2,14.280000,100,1,12.500000,700,1,14.560000,100,1,12.470000,100,1,14.610000,100,1,12.460000,100,1,14.650000,100,1,12.430000,700,1,14.720000,200,2,ARL,282776017
2025-07-17T15:30:23.587432517Z,2025-07-17T15:30:23.587267064Z,10,2,1108,C,A,23,17.90,100,0,165453,237755097,13.370000,100,1,13.820000,10,1,13.230000,2,1,13.840000,100,1,13.100000,100,1,13.990000,100,1,12.730000,100,1,14.010000,100,1,12.670000,100,1,14.090000,2,1,12.650000,200,2,14.280000,100,1,12.500000,700,1,14.560000,100,1,12.470000,100,1,14.610000,100,1,12.460000,100,1,14.650000,100,1,12.430000,700,1,14.720000,200,2,ARL,128570685
2025-07-17T15:30:23.587432517Z,2025-07-17T15:30:23.587267064Z,10,2,1108,A,A,-1,17.58,100,130,165453,237755097,13.370000,100,1,13.820000,10,1,13.230000,2,1,13.840000,100,1,13.100000,100,1,13.990000,100,1,12.730000,100,1,14.010000,100,1,12.670000,100,1,14.090000,2,1,12.650000,200,2,14.280000,100,1,12.500000,700,1,14.560000,100,1,12.470000,100,1,14.610000,100,1,12.460000,100,1,14.650000,100,1,12.430000,700,1,14.720000,200,2,ARL,282776025
2025-07-17T15:30:23.587581881Z,2025-07-17T15:30:23.587416236Z,10,2,1108,C,A,15,15.08,100,0,165645,237755098,13.370000,100,1,13.820000,10,1,13.230000,2,1,13.840000,100,1,13.100000,100,1,13.990000,100,1,12.730000,100,1,14.010000,100,1,12.670000,100,1,14.090000,2,1,12.650000,200,2,14.280000,100,1,12.500000,700,1,14.560000,100,1,12.470000,100,1,14.610000,100,1,12.460000,100,1,14.650000,100,1,12.430000,700,1,14.720000,200,2,ARL,128570449
2025-07-17T15:30:23.587581881Z,2025-07-17T15:30:23.587416236Z,10,2,1108,A,A,-1,14.81,100,130,165645,237755098,13.370000,100,1,13.820000,10,1,13.230000,2,1,13.840000,100,1,13.100000,100,1,13.990000,100,1,12.730000,100,1,14.010000,100,1,12.670000,100,1,14.090000,2,1,12.650000,200,2,14.280000,100,1,12.500000,700,1,14.560000,100,1,12.470000,100,1,14.610000,100,1,12.460000,100,1,14.650000,100,1,12.430000,700,1,14.720000,200,2,ARL,282776029
2025-07-17T15:30:23.587611440Z,2025-07-17T15:30:23.587445922Z,10,2,1108,C,A,22,16.21,100,0,165518,237755099,13.370000,100,1,13.820000,10,1,13.230000,2,1,13.840000,100,1,13.100000,100,1,13.990000,100,1,12.730000,100,1,14.010000,100,1,12.670000,100,1,14.090000,2,1,12.650000,200,2,14.280000,100,1,12.500000,700,1,14.560000,100,1,12.470000,100,1,14.610000,100,1,12.460000,100,1,14.650000,100,1,12.430000,700,1,14.720000,200,2,ARL,128570977
2025-07-17T15:30:23.587611440Z,2025-07-17T15:30:23.587445922Z,10,2,1108,A,A,-1,15.92,100,130,165518,237755099,13.370000,100,1,13.820000,10,1,13.230000,2,1,13.840000,100,1,13.100000,100,1,13.990000,100,1,12.730000,100,1,14.010000,100,1,12.670000,100,1,14.090000,2,1,12.650000,200,2,14.280000,100,1,12.500000,700,1,14.560000,100,1,12.470000,100,1,14.610000,100,1,12.460000,100,1,14.650000,100,1,12.430000,700,1,14.720000,200,2,ARL,282776033
2025-07-17T15:30:23.590261792Z,2025-07-17T15:30:23.590096343Z,10,2,1108,C,A,16,15.08,100,0,165449,237755128,13.370000,100,1,13.820000,10,1,13.230000,2,1,13.840000,100,1,13.100000,100,1,13.990000,100,1,12.730000,100,1,14.010000,100,1,12.670000,100,1,14.090000,2,1,12.650000,200,2,14.280000,100,1,12.500000,700,1,14.560000,100,1,12.470000,100,1,14.610000,100,1,12.460000,100,1,14.650000,100,1,12.430000,700,1,14.720000,200,2,ARL,128573957
2025-07-17T15:30:23.590261792Z,2025-07-17T15:30:23.590096343Z,10,2,1108,A,A,-1,14.81,100,130,165449,237755128,13.370000,100,1,13.820000,10,1,13.230000,2,1,13.840000,100,1,13.100000,100,1,13.990000,100,1,12.730000,100,1,14.010000,100,1,12.670000,100,1,14.090000,2,1,12.650000,200,2,14.280000,100,1,12.500000,700,1,14.560000,100,1,12.470000,100,1,14.610000,100,1,12.460000,100,1,14.650000,100,1,12.430000,700,1,14.720000,200,2,ARL,282776089
2025-07-17T15:30:23.591959120Z,2025-07-17T15:30:23.591793735Z,10,2,1108,C,A,3,14.01,100,130,165385,237755138,13.370000,100,1,13.820000,10,1,13.230000,2,1,13.840000,100,1,13.100000,100,1,13.990000,100,1,12.730000,100,1,14.090000,2,1,12.670000,100,1,14.280000,100,1,12.650000,200,2,14.560000,100,1,12.500000,700,1,14.610000,100,1,12.470000,100,1,14.650000,100,1,12.460000,100,1,14.720000,200,2,12.430000,700,1,14.810000,200,2,ARL,280580873
2025-07-17T15:30:23.602992439Z,2025-07-17T15:30:23.602827102Z,10,2,1108,C,A,4,14.28,100,130,165337,237755229,13.370000,100,1,13.820000,10,1,13.230000,2,1,13.840000,100,1,13.100000,100,1,13.990000,100,1,12.730000,100,1,14.090000,2,1,12.670000,100,1,14.560000,100,1,12.650000,200,2,14.610000,100,1,12.500000,700,1,14.650000,100,1,12.470000,100,1,14.720000,200,2,12.460000,100,1,14.810000,200,2,12.430000,700,1,14.840000,100,1,ARL,146956357
2025-07-17T15:30:23.603046460Z,2025-07-17T15:30:23.602881129Z,10,2,1108,A,A,4,14.12,100,130,165331,237755230,13.370000,100,1,13.820000,10,1,13.230000,2,1,13.840000,100,1,13.100000,100,1,13.990000,100,1,12.730000,100,1,14.090000,2,1,12.670000,100,1,14.120000,100,1,12.650000,200,2,14.560000,100,1,12.500000,700,1,14.610000,100,1,12.470000,100,1,14.650000,100,1,12.460000,100,1,14.720000,200,2,12.430000,700,1,14.810000,200,2,ARL,282776285
2025-07-17T15:30:23.628720816Z,2025-07-17T15:30:23.628555135Z,10,2,1108,A,A,-1,15.78,100,130,165681,237755415,13.370000,100,1,13.820000,10,1,13.230000,2,1,13.840000,100,1,13.100000,100,1,13.990000,100,1,12.730000,100,1,14.090000,2,1,12.670000,100,1,14.120000,100,1,12.650000,200,2,14.560000,100,1,12.500000,700,1,14.610000,100,1,12.470000,100,1,14.650000,100,1,12.460000,100,1,14.720000,200,2,12.430000,700,1,14.810000,200,2,ARL,282776733
2025-07-17T15:30:23.628732597Z,2025-07-17T15:30:23.628567293Z,10,2,1108,C,A,21,16.20,100,130,165304,237755416,13.370000,100,1,13.820000,10,1,13.230000,2,1,13.840000,100,1,13.100000,100,1,13.990000,100,1,12.730000,100,1,14.090000,2,1,12.670000,100,1,14.120000,100,1,12.650000,200,2,14.560000,100,1,12.500000,700,1,14.610000,100,1,12.470000,100,1,14.650000,100,1,12.460000,100,1,14.720000,200,2,12.430000,700,1,14.810000,200,2,ARL,84628765
2025-07-17T15:30:23.952122580Z,2025-07-17T15:30:23.951957017Z,10,2,1108,C,A,2,13.99,100,0,165563,237759683,13.370000,100,1,13.820000,10,1,13.230000,2,1,13.840000,100,1,13.100000,100,1,14.090000,2,1,12.730000,100,1,14.120000,100,1,12.670000,100,1,14.560000,100,1,12.650000,200,2,14.610000,100,1,12.500000,700,1,14.650000,100,1,12.470000,100,1,14.720000,200,2,12.460000,100,1,14.810000,200,2,12.430000,700,1,14.840000,100,1,ARL,237978541
2025-07-17T15:30:23.952122580Z,2025-07-17T15:30:23.951957017Z,10,2,1108,A,A,1,13.83,100,130,165563,237759683,13.370000,100,1,13.820000,10,1,13.230000,2,1,13.830000,100,1,13.100000,100,1,13.840000,100,1,12.730000,100,1,14.090000,2,1,12.670000,100,1,14.120000,100,1,12.650000,200,2,14.560000,100,1,12.500000,700,1,14.610000,100,1,12.470000,100,1,14.650000,100,1,12.460000,100,1,14.720000,200,2,12.430000,700,1,14.810000,200,2,ARL,282781741
2025-07-17T15:30:24.769074814Z,2025-07-17T15:30:24.768909757Z,10,2,1108,C,A,0,13.82,10,130,165057,237771822,13.370000,100,1,13.830000,100,1,13.230000,2,1,13.840000,100,1,13.100000,100,1,14.090000,2,1,12.730000,100,1,14.120000,100,1,12.670000,100,1,14.560000,100,1,12.650000,200,2,14.610000,100,1,12.500000,700,1,14.650000,100,1,12.470000,100,1,14.720000,200,2,12.460000,100,1,14.810000,200,2,12.430000,700,1,14.840000,100,1,ARL,282775557
2025-07-17T15:30:28.617337198Z,2025-07-17T15:30:28.617171810Z,10,2,1108,A,A,4,14.53,700,130,165388,237840336,13.370000,100,1,13.830000,100,1,13.230000,2,1,13.840000,100,1,13.100000,100,1,14.090000,2,1,12.730000,100,1,14.120000,100,1,12.670000,100,1,14.530000,700,1,12.650000,200,2,14.560000,100,1,12.500000,700,1,14.610000,100,1,12.470000,100,1,14.650000,100,1,12.460000,100,1,14.720000,200,2,12.430000,700,1,14.810000,200,2,ARL,282881853
2025-07-17T15:30:28.617387294Z,2025-07-17T15:30:28.617221981Z,10,2,1108,C,A,14,15.07,700,130,165313,237840337,13.370000,100,1,13.830000,100,1,13.230000,2,1,13.840000,100,1,13.100000,100,1,14.090000,2,1,12.730000,100,1,14.120000,100,1,12.670000,100,1,14.530000,700,1,12.650000,200,2,14.560000,100,1,12.500000,700,1,14.610000,100,1,12.470000,100,1,14.650000,100,1,12.460000,100,1,14.720000,200,2,12.430000,700,1,14.810000,200,2,ARL,92510741
2025-07-17T15:30:30.767213907Z,2025-07-17T15:30:30.767048606Z,10,2,1108,A,A,6,14.60,700,130,165301,237873135,13.370000,100,1,13.830000,100,1,13.230000,2,1,13.840000,100,1,13.100000,100,1,14.090000,2,1,12.730000,100,1,14.120000,100,1,12.670000,100,1,14.530000,700,1,12.650000,200,2,14.560000,100,1,12.500000,700,1,14.600000,700,1,12.470000,100,1,14.610000,100,1,12.460000,100,1,14.650000,100,1,12.430000,700,1,14.720000,200,2,ARL,282920685
2025-07-17T15:30:30.767267001Z,2025-07-17T15:30:30.767101317Z,10,2,1108,C,A,14,14.99,700,130,165684,237873136,13.370000,100,1,13.830000,100,1,13.230000,2,1,13.840000,100,1,13.100000,100,1,14.090000,2,1,12.730000,100,1,14.120000,100,1,12.670000,100,1,14.530000,700,1,12.650000,200,2,14.560000,100,1,12.500000,700,1,14.600000,700,1,12.470000,100,1,14.610000,100,1,12.460000,100,1,14.650000,100,1,12.430000,700,1,14.720000,200,2,ARL,84628757
2025-07-17T15:30:33.016987097Z,2025-07-17T15:30:33.016821395Z,10,2,1108,A,A,5,14.56,700,130,165702,237915946,13.370000,100,1,13.830000,100,1,13.230000,2,1,13.840000,100,1,13.100000,100,1,14.090000,2,1,12.730000,100,1,14.120000,100,1,12.670000,100,1,14.530000,700,1,12.650000,200,2,14.560000,800,2,12.500000,700,1,14.600000,700,1,12.470000,100,1,14.610000,100,1,12.460000,100,1,14.650000,100,1,12.430000,700,1,14.720000,200,2,ARL,282969973
2025-07-17T15:30:33.017384279Z,2025-07-17T15:30:33.017218657Z,10,2,1108,C,A,13,14.95,700,130,165622,237915951,13.370000,100,1,13.830000,100,1,13.230000,2,1,13.840000,100,1,13.100000,100,1,14.090000,2,1,12.730000,100,1,14.120000,100,1,12.670000,100,1,14.530000,700,1,12.650000,200,2,14.560000,800,2,12.500000,700,1,14.600000,700,1,12.470000,100,1,14.610000,100,1,12.460000,100,1,14.650000,100,1,12.430000,700,1,14.720000,200,2,ARL,84628797
2025-07-17T15:30:49.985906754Z,2025-07-17T15:30:49.985741094Z,10,2,1108,C,A,2,14.09,2,0,165660,238230724,13.370000,100,1,13.830000,100,1,13.230000,2,1,13.840000,100,1,13.100000,100,1,14.120000,100,1,12.730000,100,1,14.530000,700,1,12.670000,100,1,14.560000,800,2,12.650000,200,2,14.600000,700,1,12.500000,700,1,14.610000,100,1,12.470000,100,1,14.650000,100,1,12.460000,100,1,14.720000,200,2,12.430000,700,1,14.810000,200,2,ARL,276751517
2025-07-17T15:30:49.985906754Z,2025-07-17T15:30:49.985741094Z,10,2,1108,A,A,2,14.02,2,130,165660,238230724,13.370000,100,1,13.830000,100,1,13.230000,2,1,13.840000,100,1,13.100000,100,1,14.020000,2,1,12.730000,100,1,14.120000,100,1,12.670000,100,1,14.530000,700,1,12.650000,200,2,14.560000,800,2,12.500000,700,1,14.600000,700,1,12.470000,100,1,14.610000,100,1,12.460000,100,1,14.650000,100,1,12.430000,700,1,14.720000,200,2,ARL,283348193
2025-07-17T15:30:59.996516554Z,2025-07-17T15:30:59.996351383Z,10,2,1108,C,A,0,13.83,100,130,165171,238442318,13.370000,100,1,13.840000,100,1,13.230000,2,1,14.020000,2,1,13.100000,100,1,14.120000,100,1,12.730000,100,1,14.530000,700,1,12.670000,100,1,14.560000,800,2,12.650000,200,2,14.600000,700,1,12.500000,700,1,14.610000,100,1,12.470000,100,1,14.650000,100,1,12.460000,100,1,14.720000,200,2,12.430000,700,1,14.810000,200,2,ARL,282781741
2025-07-17T15:31:00.002203922Z,2025-07-17T15:31:00.002038446Z,10,2,1108,C,A,0,13.84,100,130,165476,238442443,13.370000,100,1,14.020000,2,1,13.230000,2,1,14.120000,100,1,13.100000,100,1,14.530000,700,1,12.730000,100,1,14.560000,800,2,12.670000,100,1,14.600000,700,1,12.650000,200,2,14.610000,100,1,12.500000,700,1,14.650000,100,1,12.470000,100,1,14.720000,200,2,12.460000,100,1,14.810000,200,2,12.430000,700,1,14.840000,100,1,ARL,282775973
2025-07-17T15:31:00.002478393Z,2025-07-17T15:31:00.002313250Z,10,2,1108,C,A,2,14.53,700,130,165143,238442461,13.370000,100,1,14.020000,2,1,13.230000,2,1,14.120000,100,1,13.100000,100,1,14.560000,800,2,12.730000,100,1,14.600000,700,1,12.670000,100,1,14.610000,100,1,12.650000,200,2,14.650000,100,1,12.500000,700,1,14.720000,200,2,12.470000,100,1,14.810000,200,2,12.460000,100,1,14.840000,100,1,12.430000,700,1,14.910000,800,2,ARL,282881853
2025-07-17T15:31:00.002525213Z,2025-07-17T15:31:00.002359969Z,10,2,1108,A,A,6,14.68,700,130,165244,238442467,13.370000,100,1,14.020000,2,1,13.230000,2,1,14.120000,100,1,13.100000,100,1,14.560000,800,2,12.730000,100,1,14.600000,700,1,12.670000,100,1,14.610000,100,1,12.650000,200,2,14.650000,100,1,12.500000,700,1,14.680000,700,1,12.470000,100,1,14.720000,200,2,12.460000,100,1,14.810000,200,2,12.430000,700,1,14.840000,100,1,ARL,283592941
2025-07-17T15:31:00.002938332Z,2025-07-17T15:31:00.002772683Z,10,2,1108,C,A,7,14.72,100,0,165649,238442486,13.370000,100,1,14.020000,2,1,13.230000,2,1,14.120000,100,1,13.100000,100,1,14.560000,800,2,12.730000,100,1,14.600000,700,1,12.670000,100,1,14.610000,100,1,12.650000,200,2,14.650000,100,1,12.500000,700,1,14.680000,700,1,12.470000,100,1,14.720000,100,1,12.460000,100,1,14.810000,200,2,12.430000,700,1,14.840000,100,1,ARL,282775577
2025-07-17T15:31:00.002938332Z,2025-07-17T15:31:00.002772683Z,10,2,1108,A,A,-1,14.97,100,130,165649,238442486,13.370000,100,1,14.020000,2,1,13.230000,2,1,14.120000,100,1,13.100000,100,1,14.560000,800,2,12.730000,100,1,14.600000,700,1,12.670000,100,1,14.610000,100,1,12.650000,200,2,14.650000,100,1,12.500000,700,1,14.680000,700,1,12.470000,100,1,14.720000,100,1,12.460000,100,1,14.810000,200,2,12.430000,700,1,14.840000,100,1,ARL,283592993
2025-07-17T15:31:00.002953704Z,2025-07-17T15:31:00.002788190Z,10,2,1108,C,A,10,14.91,100,0,165514,238442490,13.370000,100,1,14.020000,2,1,13.230000,2,1,14.120000,100,1,13.100000,100,1,14.560000,800,2,12.730000,100,1,14.600000,700,1,12.670000,100,1,14.610000,100,1,12.650000,200,2,14.650000,100,1,12.500000,700,1,14.680000,700,1,12.470000,100,1,14.720000,100,1,12.460000,100,1,14.810000,200,2,12.430000,700,1,14.840000,100,1,ARL,282776009
2025-07-17T15:31:00.002953704Z,2025-07-17T15:31:00.002788190Z,10,2,1108,A,A,-1,14.96,100,130,165514,238442490,13.370000,100,1,14.020000,2,1,13.230000,2,1,14.120000,100,1,13.100000,100,1,14.560000,800,2,12.730000,100,1,14.600000,700,1,12.670000,100,1,14.610000,100,1,12.650000,200,2,14.650000,100,1,12.500000,700,1,14.680000,700,1,12.470000,100,1,14.720000,100,1,12.460000,100,1,14.810000,200,2,12.430000,700,1,14.840000,100,1,ARL,283592997
2025-07-17T15:31:00.003368272Z,2025-07-17T15:31:00.003202003Z,10,2,1108,C,A,7,14.72,100,0,166269,238442510,13.370000,100,1,14.020000,2,1,13.230000,2,1,14.120000,100,1,13.100000,100,1,14.560000,800,2,12.730000,100,1,14.600000,700,1,12.670000,100,1,14.610000,100,1,12.650000,200,2,14.650000,100,1,12.500000,700,1,14.680000,700,1,12.470000,100,1,14.810000,200,2,12.460000,100,1,14.840000,100,1,12.430000,700,1,14.910000,700,1,ARL,282775561
2025-07-17T15:31:00.003368272Z,2025-07-17T15:31:00.003202003Z,10,2,1108,A,A,-1,14.97,100,130,166269,238442510,13.370000,100,1,14.020000,2,1,13.230000,2,1,14.120000,100,1,13.100000,100,1,14.560000,800,2,12.730000,100,1,14.600000,700,1,12.670000,100,1,14.610000,100,1,12.650000,200,2,14.650000,100,1,12.500000,700,1,14.680000,700,1,12.470000,100,1,14.810000,200,2,12.460000,100,1,14.840000,100,1,12.430000,700,1,14.910000,700,1,ARL,283593041
2025-07-17T15:31:00.006784947Z,2025-07-17T15:31:00.006618398Z,10,2,1108,C,A,5,14.65,100,130,166549,238442608,13.370000,100,1,14.020000,2,1,13.230000,2,1,14.120000,100,1,13.100000,100,1,14.560000,800,2,12.730000,100,1,14.600000,700,1,12.670000,100,1,14.610000,100,1,12.650000,200,2,14.680000,700,1,12.500000,700,1,14.810000,200,2,12.470000,100,1,14.840000,100,1,12.460000,100,1,14.910000,700,1,12.430000,700,1,14.960000,100,1,ARL,282776013
2025-07-17T15:31:00.006950491Z,2025-07-17T15:31:00.006784814Z,10,2,1108,A,A,6,14.79,100,130,165677,238442616,13.370000,100,1,14.020000,2,1,13.230000,2,1,14.120000,100,1,13.100000,100,1,14.560000,800,2,12.730000,100,1,14.600000,700,1,12.670000,100,1,14.610000,100,1,12.650000,200,2,14.680000,700,1,12.500000,700,1,14.790000,100,1,12.470000,100,1,14.810000,200,2,12.460000,100,1,14.840000,100,1,12.430000,700,1,14.910000,700,1,ARL,283593313
2025-07-17T15:31:00.017759891Z,2025-07-17T15:31:00.017594312Z,10,2,1108,C,A,19,17.58,100,0,165579,238443214,13.370000,100,1,14.020000,2,1,13.230000,2,1,14.120000,100,1,13.100000,100,1,14.560000,800,2,12.730000,100,1,14.600000,700,1,12.670000,100,1,14.610000,100,1,12.650000,200,2,14.680000,700,1,12.500000,700,1,14.790000,100,1,12.470000,100,1,14.810000,200,2,12.460000,100,1,14.840000,100,1,12.430000,700,1,14.910000,700,1,ARL,282776025
2025-07-17T15:31:00.017759891Z,2025-07-17T15:31:00.017594312Z,10,2,1108,A,A,-1,17.76,100,130,165579,238443214,13.370000,100,1,14.020000,2,1,13.230000,2,1,14.120000,100,1,13.100000,100,1,14.560000,800,2,12.730000,100,1,14.600000,700,1,12.670000,100,1,14.610000,100,1,12.650000,200,2,14.680000,700,1,12.500000,700,1,14.790000,100,1,12.470000,100,1,14.810000,200,2,12.460000,100,1,14.840000,100,1,12.430000,700,1,14.910000,700,1,ARL,283594173
2025-07-17T15:31:00.028894478Z,2025-07-17T15:31:00.028729168Z,10,2,1108,C,A,1,14.12,100,130,165310,238443996,13.370000,100,1,14.020000,2,1,13.230000,2,1,14.560000,800,2,13.100000,100,1,14.600000,700,1,12.730000,100,1,14.610000,100,1,12.670000,100,1,14.680000,700,1,12.650000,200,2,14.790000,100,1,12.500000,700,1,14.810000,200,2,12.470000,100,1,14.840000,100,1,12.460000,100,1,14.910000,700,1,12.430000,700,1,14.960000,100,1,ARL,282776285
2025-07-17T15:31:00.028947312Z,2025-07-17T15:31:00.028782030Z,10,2,1108,A,A,1,14.26,100,130,165282,238443998,13.370000,100,1,14.020000,2,1,13.230000,2,1,14.260000,100,1,13.100000,100,1,14.560000,800,2,12.730000,100,1,14.600000,700,1,12.670000,100,1,14.610000,100,1,12.650000,200,2,14.680000,700,1,12.500000,700,1,14.790000,100,1,12.470000,100,1,14.810000,200,2,12.460000,100,1,14.840000,100,1,12.430000,700,1,14.910000,700,1,ARL,283595181
2025-07-17T15:31:00.053107210Z,2025-07-17T15:31:00.052941898Z,10,2,1108,C,A,10,14.96,100,0,165312,238444735,13.370000,100,1,14.020000,2,1,13.230000,2,1,14.260000,100,1,13.100000,100,1,14.560000,800,2,12.730000,100,1,14.600000,700,1,12.670000,100,1,14.610000,100,1,12.650000,200,2,14.680000,700,1,12.500000,700,1,14.790000,100,1,12.470000,100,1,14.810000,200,2,12.460000,100,1,14.840000,100,1,12.430000,700,1,14.910000,700,1,ARL,283592997
2025-07-17T15:31:00.053107210Z,2025-07-17T15:31:00.052941898Z,10,2,1108,A,A,-1,15.06,100,130,165312,238444735,13.370000,100,1,14.020000,2,1,13.230000,2,1,14.260000,100,1,13.100000,100,1,14.560000,800,2,12.730000,100,1,14.600000,700,1,12.670000,100,1,14.610000,100,1,12.650000,200,2,14.680000,700,1,12.500000,700,1,14.790000,100,1,12.470000,100,1,14.810000,200,2,12.460000,100,1,14.840000,100,1,12.430000,700,1,14.910000,700,1,ARL,283596673
2025-07-17T15:31:00.054830847Z,2025-07-17T15:31:00.054665340Z,10,2,1108,C,A,7,14.81,100,0,165507,238444759,13.370000,100,1,14.020000,2,1,13.230000,2,1,14.260000,100,1,13.100000,100,1,14.560000,800,2,12.730000,100,1,14.600000,700,1,12.670000,100,1,14.610000,100,1,12.650000,200,2,14.680000,700,1,12.500000,700,1,14.790000,100,1,12.470000,100,1,14.810000,100,1,12.460000,100,1,14.840000,100,1,12.430000,700,1,14.910000,700,1,ARL,282776089
2025-07-17T15:31:00.054830847Z,2025-07-17T15:31:00.054665340Z,10,2,1108,A,A,-1,14.96,100,130,165507,238444759,13.370000,100,1,14.020000,2,1,13.230000,2,1,14.260000,100,1,13.100000,100,1,14.560000,800,2,12.730000,100,1,14.600000,700,1,12.670000,100,1,14.610000,100,1,12.650000,200,2,14.680000,700,1,12.500000,700,1,14.790000,100,1,12.470000,100,1,14.810000,100,1,12.460000,100,1,14.840000,100,1,12.430000,700,1,14.910000,700,1,ARL,283596721
2025-07-17T15:31:00.071409275Z,2025-07-17T15:31:00.071243665Z,10,2,1108,C,A,7,14.81,100,0,165610,238444961,13.370000,100,1,14.020000,2,1,13.230000,2,1,14.260000,100,1,13.100000,100,1,14.560000,800,2,12.730000,100,1,14.600000,700,1,12.670000,100,1,14.610000,100,1,12.650000,200,2,14.680000,700,1,12.500000,700,1,14.790000,100,1,12.470000,100,1,14.840000,100,1,12.460000,100,1,14.910000,700,1,12.430000,700,1,14.960000,100,1,ARL,282776029
2025-07-17T15:31:00.071409275Z,2025-07-17T15:31:00.071243665Z,10,2,1108,A,A,9,14.96,100,130,165610,238444961,13.370000,100,1,14.020000,2,1,13.230000,2,1,14.260000,100,1,13.100000,100,1,14.560000,800,2,12.730000,100,1,14.600000,700,1,12.670000,100,1,14.610000,100,1,12.650000,200,2,14.680000,700,1,12.500000,700,1,14.790000,100,1,12.470000,100,1,14.840000,100,1,12.460000,100,1,14.910000,700,1,12.430000,700,1,14.960000,200,2,ARL,283596945
2025-07-17T15:31:00.243369582Z,2025-07-17T15:31:00.243203860Z,10,2,1108,C,A,16,15.92,100,0,165722,238447595,13.370000,100,1,14.020000,2,1,13.230000,2,1,14.260000,100,1,13.100000,100,1,14.560000,800,2,12.730000,100,1,14.600000,700,1,12.670000,100,1,14.610000,100,1,12.650000,200,2,14.680000,700,1,12.500000,700,1,14.790000,100,1,12.470000,100,1,14.840000,100,1,12.460000,100,1,14.910000,700,1,12.430000,700,1,14.960000,200,2,ARL,282776033
2025-07-17T15:31:00.243369582Z,2025-07-17T15:31:00.243203860Z,10,2,1108,A,A,-1,16.08,100,130,165722,238447595,13.370000,100,1,14.020000,2,1,13.230000,2,1,14.260000,100,1,13.100000,100,1,14.560000,800,2,12.730000,100,1,14.600000,700,1,12.670000,100,1,14.610000,100,1,12.650000,200,2,14.680000,700,1,12.500000,700,1,14.790000,100,1,12.470000,100,1,14.840000,100,1,12.460000,100,1,14.910000,700,1,12.430000,700,1,14.960000,200,2,ARL,283599609
2025-07-17T15:31:00.347828545Z,2025-07-17T15:31:00.347663441Z,10,2,1108,A,A,1,14.03,100,130,165104,238450791,13.370000,100,1,14.020000,2,1,13.230000,2,1,14.030000,100,1,13.100000,100,1,14.260000,100,1,12.730000,100,1,14.560000,800,2,12.670000,100,1,14.600000,700,1,12.650000,200,2,14.610000,100,1,12.500000,700,1,14.680000,700,1,12.470000,100,1,14.790000,100,1,12.460000,100,1,14.840000,100,1,12.430000,700,1,14.910000,700,1,ARL,283604173
2025-07-17T15:31:04.014590575Z,2025-07-17T15:31:04.014425425Z,10,2,1108,A,A,0,14.00,100,130,165150,238529875,13.370000,100,1,14.000000,100,1,13.230000,2,1,14.020000,2,1,13.100000,100,1,14.030000,100,1,12.730000,100,1,14.260000,100,1,12.670000,100,1,14.560000,800,2,12.650000,200,2,14.600000,700,1,12.500000,700,1,14.610000,100,1,12.470000,100,1,14.680000,700,1,12.460000,100,1,14.790000,100,1,12.430000,700,1,14.840000,100,1,ARL,283694233
2025-07-17T15:31:04.124577845Z,2025-07-17T15:31:04.124411850Z,10,2,1108,C,A,2,14.03,100,0,165995,238531822,13.370000,100,1,14.000000,100,1,13.230000,2,1,14.020000,2,1,13.100000,100,1,14.260000,100,1,12.730000,100,1,14.560000,800,2,12.670000,100,1,14.600000,700,1,12.650000,200,2,14.610000,100,1,12.500000,700,1,14.680000,700,1,12.470000,100,1,14.790000,100,1,12.460000,100,1,14.840000,100,1,12.430000,700,1,14.910000,700,1,ARL,283604173
2025-07-17T15:31:04.124577845Z,2025-07-17T15:31:04.124411850Z,10,2,1108,A,A,1,14.01,100,130,165995,238531822,13.370000,100,1,14.000000,100,1,13.230000,2,1,14.010000,100,1,13.100000,100,1,14.020000,2,1,12.730000,100,1,14.260000,100,1,12.670000,100,1,14.560000,800,2,12.650000,200,2,14.600000,700,1,12.500000,700,1,14.610000,100,1,12.470000,100,1,14.680000,700,1,12.460000,100,1,14.790000,100,1,12.430000,700,1,14.840000,100,1,ARL,283695933
2025-07-17T15:32:28.644506279Z,2025-07-17T15:32:28.644335983Z,10,2,1108,A,B,0,13.55,10,128,170296,239938946,13.550000,10,1,14.000000,100,1,13.370000,100,1,14.010000,100,1,13.230000,2,1,14.020000,2,1,13.100000,100,1,14.260000,100,1,12.730000,100,1,14.560000,800,2,12.670000,100,1,14.600000,700,1,12.650000,200,2,14.610000,100,1,12.500000,700,1,14.680000,700,1,12.470000,100,1,14.790000,100,1,12.460000,100,1,14.840000,100,1,ARL,285545121
2025-07-17T15:32:28.653238729Z,2025-07-17T15:32:28.653073176Z,10,2,1108,C,B,1,13.37,100,0,165553,239940048,13.550000,10,1,14.000000,100,1,13.230000,2,1,14.010000,100,1,13.100000,100,1,14.020000,2,1,12.730000,100,1,14.260000,100,1,12.670000,100,1,14.560000,800,2,12.650000,200,2,14.600000,700,1,12.500000,700,1,14.610000,100,1,12.470000,100,1,14.680000,700,1,12.460000,100,1,14.790000,100,1,12.430000,700,1,14.840000,100,1,ARL,215999737
2025-07-17T15:32:28.653238729Z,2025-07-17T15:32:28.653073176Z,10,2,1108,A,B,1,13.54,100,130,165553,239940048,13.550000,10,1,14.000000,100,1,13.540000,100,1,14.010000,100,1,13.230000,2,1,14.020000,2,1,13.100000,100,1,14.260000,100,1,12.730000,100,1,14.560000,800,2,12.670000,100,1,14.600000,700,1,12.650000,200,2,14.610000,100,1,12.500000,700,1,14.680000,700,1,12.470000,100,1,14.790000,100,1,12.460000,100,1,14.840000,100,1,ARL,285545885
2025-07-17T15:32:28.653978501Z,2025-07-17T15:32:28.653812889Z,10,2,1108,C,B,13,12.33,100,0,165612,239940096,13.550000,10,1,14.000000,100,1,13.540000,100,1,14.010000,100,1,13.230000,2,1,14.020000,2,1,13.100000,100,1,14.260000,100,1,12.730000,100,1,14.560000,800,2,12.670000,100,1,14.600000,700,1,12.650000,200,2,14.610000,100,1,12.500000,700,1,14.680000,700,1,12.470000,100,1,14.790000,100,1,12.460000,100,1,14.840000,100,1,ARL,215999753
2025-07-17T15:32:28.653978501Z,2025-07-17T15:32:28.653812889Z,10,2,1108,A,B,8,12.49,100,130,165612,239940096,13.550000,10,1,14.000000,100,1,13.540000,100,1,14.010000,100,1,13.230000,2,1,14.020000,2,1,13.100000,100,1,14.260000,100,1,12.730000,100,1,14.560000,800,2,12.670000,100,1,14.600000,700,1,12.650000,200,2,14.610000,100,1,12.500000,700,1,14.680000,700,1,12.490000,100,1,14.790000,100,1,12.470000,100,1,14.840000,100,1,ARL,285545945
2025-07-17T15:32:28.653980648Z,2025-07-17T15:32:28.653815154Z,10,2,1108,C,B,5,12.67,100,130,165494,239940097,13.550000,10,1,14.000000,100,1,13.540000,100,1,14.010000,100,1,13.230000,2,1,14.020000,2,1,13.100000,100,1,14.260000,100,1,12.730000,100,1,14.560000,800,2,12.650000,200,2,14.600000,700,1,12.500000,700,1,14.610000,100,1,12.490000,100,1,14.680000,700,1,12.470000,100,1,14.790000,100,1,12.460000,100,1,14.840000,100,1,ARL,43663229
2025-07-17T15:32:28.654336987Z,2025-07-17T15:32:28.654171723Z,10,2,1108,A,B,4,12.94,100,130,165264,239940109,13.550000,10,1,14.000000,100,1,13.540000,100,1,14.010000,100,1,13.230000,2,1,14.020000,2,1,13.100000,100,1,14.260000,100,1,12.940000,100,1,14.560000,800,2,12.730000,100,1,14.600000,700,1,12.650000,200,2,14.610000,100,1,12.500000,700,1,14.680000,700,1,12.490000,100,1,14.790000,100,1,12.470000,100,1,14.840000,100,1,ARL,285545953
2025-07-17T15:32:28.657073743Z,2025-07-17T15:32:28.656908386Z,10,2,1108,C,B,9,12.47,100,130,165357,239940358,13.550000,10,1,14.000000,100,1,13.540000,100,1,14.010000,100,1,13.230000,2,1,14.020000,2,1,13.100000,100,1,14.260000,100,1,12.940000,100,1,14.560000,800,2,12.730000,100,1,14.600000,700,1,12.650000,200,2,14.610000,100,1,12.500000,700,1,14.680000,700,1,12.490000,100,1,14.790000,100,1,12.460000,100,1,14.840000,100,1,ARL,43554133
2025-07-17T15:32:28.657173856Z,2025-07-17T15:32:28.657008222Z,10,2,1108,A,B,5,12.73,100,130,165634,239940359,13.550000,10,1,14.000000,100,1,13.540000,100,1,14.010000,100,1,13.230000,2,1,14.020000,2,1,13.100000,100,1,14.260000,100,1,12.940000,100,1,14.560000,800,2,12.730000,200,2,14.600000,700,1,12.650000,200,2,14.610000,100,1,12.500000,700,1,14.680000,700,1,12.490000,100,1,14.790000,100,1,12.460000,100,1,14.840000,100,1,ARL,285546061
2025-07-17T15:32:28.667074437Z,2025-07-17T15:32:28.666909194Z,10,2,1108,C,B,3,13.10,100,130,165243,239940810,13.550000,10,1,14.000000,100,1,13.540000,100,1,14.010000,100,1,13.230000,2,1,14.020000,2,1,12.940000,100,1,14.260000,100,1,12.730000,200,2,14.560000,800,2,12.650000,200,2,14.600000,700,1,12.500000,700,1,14.610000,100,1,12.490000,100,1,14.680000,700,1,12.460000,100,1,14.790000,100,1,12.430000,700,1,14.840000,100,1,ARL,216001413
2025-07-17T15:32:28.667126637Z,2025-07-17T15:32:28.666961018Z,10,2,1108,A,B,2,13.27,100,130,165619,239940813,13.550000,10,1,14.000000,100,1,13.540000,100,1,14.010000,100,1,13.270000,100,1,14.020000,2,1,13.230000,2,1,14.260000,100,1,12.940000,100,1,14.560000,800,2,12.730000,200,2,14.600000,700,1,12.650000,200,2,14.610000,100,1,12.500000,700,1,14.680000,700,1,12.490000,100,1,14.790000,100,1,12.460000,100,1,14.840000,100,1,ARL,285546673
2025-07-17T15:32:28.674444711Z,2025-07-17T15:32:28.674279259Z,10,2,1108,C,B,13,12.33,100,0,165452,239941057,13.550000,10,1,14.000000,100,1,13.540000,100,1,14.010000,100,1,13.270000,100,1,14.020000,2,1,13.230000,2,1,14.260000,100,1,12.940000,100,1,14.560000,800,2,12.730000,200,2,14.600000,700,1,12.650000,200,2,14.610000,100,1,12.500000,700,1,14.680000,700,1,12.490000,100,1,14.790000,100,1,12.460000,100,1,14.840000,100,1,ARL,43755813
2025-07-17T15:32:28.674444711Z,2025-07-17T15:32:28.674279259Z,10,2,1108,A,B,7,12.59,100,130,165452,239941057,13.550000,10,1,14.000000,100,1,13.540000,100,1,14.010000,100,1,13.270000,100,1,14.020000,2,1,13.230000,2,1,14.260000,100,1,12.940000,100,1,14.560000,800,2,12.730000,200,2,14.600000,700,1,12.650000,200,2,14.610000,100,1,12.590000,100,1,14.680000,700,1,12.500000,700,1,14.790000,100,1,12.490000,100,1,14.840000,100,1,ARL,285546893
2025-07-17T15:32:28.691264796Z,2025-07-17T15:32:28.691099298Z,10,2,1108,C,B,20,9.67,100,0,165498,239941825,13.550000,10,1,14.000000,100,1,13.540000,100,1,14.010000,100,1,13.270000,100,1,14.020000,2,1,13.230000,2,1,14.260000,100,1,12.940000,100,1,14.560000,800,2,12.730000,200,2,14.600000,700,1,12.650000,200,2,14.610000,100,1,12.590000,100,1,14.680000,700,1,12.500000,700,1,14.790000,100,1,12.490000,100,1,14.840000,100,1,ARL,44082961
2025-07-17T15:32:28.691264796Z,2025-07-17T15:32:28.691099298Z,10,2,1108,A,B,-1,9.88,100,130,165498,239941825,13.550000,10,1,14.000000,100,1,13.540000,100,1,14.010000,100,1,13.270000,100,1,14.020000,2,1,13.230000,2,1,14.260000,100,1,12.940000,100,1,14.560000,800,2,12.730000,200,2,14.600000,700,1,12.650000,200,2,14.610000,100,1,12.590000,100,1,14.680000,700,1,12.500000,700,1,14.790000,100,1,12.490000,100,1,14.840000,100,1,ARL,285548137
2025-07-17T15:32:28.711494526Z,2025-07-17T15:32:28.711329066Z,10,2,1108,C,B,18,11.27,100,0,165460,239942732,13.550000,10,1,14.000000,100,1,13.540000,100,1,14.010000,100,1,13.270000,100,1,14.020000,2,1,13.230000,2,1,14.260000,100,1,12.940000,100,1,14.560000,800,2,12.730000,200,2,14.600000,700,1,12.650000,200,2,14.610000,100,1,12.590000,100,1,14.680000,700,1,12.500000,700,1,14.790000,100,1,12.490000,100,1,14.840000,100,1,ARL,43826785
2025-07-17T15:32:28.711494526Z,2025-07-17T15:32:28.711329066Z,10,2,1108,A,B,-1,11.50,100,130,165460,239942732,13.550000,10,1,14.000000,100,1,13.540000,100,1,14.010000,100,1,13.270000,100,1,14.020000,2,1,13.230000,2,1,14.260000,100,1,12.940000,100,1,14.560000,800,2,12.730000,200,2,14.600000,700,1,12.650000,200,2,14.610000,100,1,12.590000,100,1,14.680000,700,1,12.500000,700,1,14.790000,100,1,12.490000,100,1,14.840000,100,1,ARL,285549537
2025-07-17T15:32:28.771995987Z,2025-07-17T15:32:28.771830554Z,10,2,1108,C,B,0,13.55,10,128,165433,239945992,13.540000,100,1,14.000000,100,1,13.270000,100,1,14.010000,100,1,13.230000,2,1,14.020000,2,1,12.940000,100,1,14.260000,100,1,12.730000,200,2,14.560000,800,2,12.650000,200,2,14.600000,700,1,12.590000,100,1,14.610000,100,1,12.500000,700,1,14.680000,700,1,12.490000,100,1,14.790000,100,1,12.460000,100,1,14.840000,100,1,ARL,285545121
2025-07-17T15:32:28.806930722Z,2025-07-17T15:32:28.806765209Z,10,2,1108,C,B,13,12.33,100,0,165513,239948319,13.540000,100,1,14.000000,100,1,13.270000,100,1,14.010000,100,1,13.230000,2,1,14.020000,2,1,12.940000,100,1,14.260000,100,1,12.730000,200,2,14.560000,800,2,12.650000,200,2,14.600000,700,1,12.590000,100,1,14.610000,100,1,12.500000,700,1,14.680000,700,1,12.490000,100,1,14.790000,100,1,12.460000,100,1,14.840000,100,1,ARL,44088633
2025-07-17T15:32:28.806930722Z,2025-07-17T15:32:28.806765209Z,10,2,1108,A,B,6,12.59,100,130,165513,239948319,13.540000,100,1,14.000000,100,1,13.270000,100,1,14.010000,100,1,13.230000,2,1,14.020000,2,1,12.940000,100,1,14.260000,100,1,12.730000,200,2,14.560000,800,2,12.650000,200,2,14.600000,700,1,12.590000,200,2,14.610000,100,1,12.500000,700,1,14.680000,700,1,12.490000,100,1,14.790000,100,1,12.460000,100,1,14.840000,100,1,ARL,285553901
2025-07-17T15:32:28.850288215Z,2025-07-17T15:32:28.850122877Z,10,2,1108,A,A,0,13.98,100,130,165338,239950805,13.540000,100,1,13.980000,100,1,13.270000,100,1,14.000000,100,1,13.230000,2,1,14.010000,100,1,12.940000,100,1,14.020000,2,1,12.730000,200,2,14.260000,100,1,12.650000,200,2,14.560000,800,2,12.590000,200,2,14.600000,700,1,12.500000,700,1,14.610000,100,1,12.490000,100,1,14.680000,700,1,12.460000,100,1,14.790000,100,1,ARL,285556869
2025-07-17T15:32:28.857140107Z,2025-07-17T15:32:28.856973845Z,10,2,1108,C,A,1,14.00,100,130,166262,239951361,13.540000,100,1,13.980000,100,1,13.270000,100,1,14.010000,100,1,13.230000,2,1,14.020000,2,1,12.940000,100,1,14.260000,100,1,12.730000,200,2,14.560000,800,2,12.650000,200,2,14.600000,700,1,12.590000,200,2,14.610000,100,1,12.500000,700,1,14.680000,700,1,12.490000,100,1,14.790000,100,1,12.460000,100,1,14.840000,100,1,ARL,283694233
2025-07-17T15:32:29.573634202Z,2025-07-17T15:32:29.573469021Z,10,2,1108,C,B,0,13.54,100,130,165181,239975997,13.270000,100,1,13.980000,100,1,13.230000,2,1,14.010000,100,1,12.940000,100,1,14.020000,2,1,12.730000,200,2,14.260000,100,1,12.650000,200,2,14.560000,800,2,12.590000,200,2,14.600000,700,1,12.500000,700,1,14.610000,100,1,12.490000,100,1,14.680000,700,1,12.460000,100,1,14.790000,100,1,12.430000,700,1,14.840000,100,1,ARL,285545885
2025-07-17T15:32:29.574368326Z,2025-07-17T15:32:29.574202467Z,10,2,1108,C,B,7,12.49,100,0,165859,239976004,13.270000,100,1,13.980000,100,1,13.230000,2,1,14.010000,100,1,12.940000,100,1,14.020000,2,1,12.730000,200,2,14.260000,100,1,12.650000,200,2,14.560000,800,2,12.590000,200,2,14.600000,700,1,12.500000,700,1,14.610000,100,1,12.460000,100,1,14.680000,700,1,12.430000,700,1,14.790000,100,1,12.420000,700,1,14.840000,100,1,ARL,285545945
2025-07-17T15:32:29.574368326Z,2025-07-17T15:32:29.574202467Z,10,2,1108,A,B,-1,12.27,100,130,165859,239976004,13.270000,100,1,13.980000,100,1,13.230000,2,1,14.010000,100,1,12.940000,100,1,14.020000,2,1,12.730000,200,2,14.260000,100,1,12.650000,200,2,14.560000,800,2,12.590000,200,2,14.600000,700,1,12.500000,700,1,14.610000,100,1,12.460000,100,1,14.680000,700,1,12.430000,700,1,14.790000,100,1,12.420000,700,1,14.840000,100,1,ARL,285586089
2025-07-17T15:32:29.574371866Z,2025-07-17T15:32:29.574206685Z,10,2,1108,C,B,2,12.94,100,130,165181,239976005,13.270000,100,1,13.980000,100,1,13.230000,2,1,14.010000,100,1,12.730000,200,2,14.020000,2,1,12.650000,200,2,14.260000,100,1,12.590000,200,2,14.560000,800,2,12.500000,700,1,14.600000,700,1,12.460000,100,1,14.610000,100,1,12.430000,700,1,14.680000,700,1,12.420000,700,1,14.790000,100,1,12.370000,700,1,14.840000,100,1,ARL,285545953
2025-07-17T15:32:29.574722141Z,2025-07-17T15:32:29.574556760Z,10,2,1108,A,B,3,12.71,100,130,165381,239976069,13.270000,100,1,13.980000,100,1,13.230000,2,1,14.010000,100,1,12.730000,200,2,14.020000,2,1,12.710000,100,1,14.260000,100,1,12.650000,200,2,14.560000,800,2,12.590000,200,2,14.600000,700,1,12.500000,700,1,14.610000,100,1,12.460000,100,1,14.680000,700,1,12.430000,700,1,14.790000,100,1,12.420000,700,1,14.840000,100,1,ARL,285586093
2025-07-17T15:32:29.575134655Z,2025-07-17T15:32:29.574968914Z,10,2,1108,C,B,5,12.59,100,0,165741,239976143,13.270000,100,1,13.980000,100,1,13.230000,2,1,14.010000,100,1,12.730000,200,2,14.020000,2,1,12.710000,100,1,14.260000,100,1,12.650000,200,2,14.560000,800,2,12.590000,100,1,14.600000,700,1,12.500000,700,1,14.610000,100,1,12.460000,100,1,14.680000,700,1,12.430000,700,1,14.790000,100,1,12.420000,700,1,14.840000,100,1,ARL,285546893
2025-07-17T15:32:29.575134655Z,2025-07-17T15:32:29.574968914Z,10,2,1108,A,B,-1,12.34,100,130,165741,239976143,13.270000,100,1,13.980000,100,1,13.230000,2,1,14.010000,100,1,12.730000,200,2,14.020000,2,1,12.710000,100,1,14.260000,100,1,12.650000,200,2,14.560000,800,2,12.590000,100,1,14.600000,700,1,12.500000,700,1,14.610000,100,1,12.460000,100,1,14.680000,700,1,12.430000,700,1,14.790000,100,1,12.420000,700,1,14.840000,100,1,ARL,285586113
2025-07-17T15:32:29.575550333Z,2025-07-17T15:32:29.575384940Z,10,2,1108,C,B,15,11.50,100,0,165393,239976173,13.270000,100,1,13.980000,100,1,13.230000,2,1,14.010000,100,1,12.730000,200,2,14.020000,2,1,12.710000,100,1,14.260000,100,1,12.650000,200,2,14.560000,800,2,12.590000,100,1,14.600000,700,1,12.500000,700,1,14.610000,100,1,12.460000,100,1,14.680000,700,1,12.430000,700,1,14.790000,100,1,12.420000,700,1,14.840000,100,1,ARL,285549537
2025-07-17T15:32:29.575550333Z,2025-07-17T15:32:29.575384940Z,10,2,1108,A,B,-1,11.27,100,130,165393,239976173,13.270000,100,1,13.980000,100,1,13.230000,2,1,14.010000,100,1,12.730000,200,2,14.020000,2,1,12.710000,100,1,14.260000,100,1,12.650000,200,2,14.560000,800,2,12.590000,100,1,14.600000,700,1,12.500000,700,1,14.610000,100,1,12.460000,100,1,14.680000,700,1,12.430000,700,1,14.790000,100,1,12.420000,700,1,14.840000,100,1,ARL,285586145
2025-07-17T15:32:29.575821091Z,2025-07-17T15:32:29.575655631Z,10,2,1108,C,B,18,9.88,100,0,165460,239976183,13.270000,100,1,13.980000,100,1,13.230000,2,1,14.010000,100,1,12.730000,200,2,14.020000,2,1,12.710000,100,1,14.260000,100,1,12.650000,200,2,14.560000,800,2,12.590000,100,1,14.600000,700,1,12.500000,700,1,14.610000,100,1,12.460000,100,1,14.680000,700,1,12.430000,700,1,14.790000,100,1,12.420000,700,1,14.840000,100,1,ARL,285548137
2025-07-17T15:32:29.575821091Z,2025-07-17T15:32:29.575655631Z,10,2,1108,A,B,-1,9.68,100,130,165460,239976183,13.270000,100,1,13.980000,100,1,13.230000,2,1,14.010000,100,1,12.730000,200,2,14.020000,2,1,12.710000,100,1,14.260000,100,1,12.650000,200,2,14.560000,800,2,12.590000,100,1,14.600000,700,1,12.500000,700,1,14.610000,100,1,12.460000,100,1,14.680000,700,1,12.430000,700,1,14.790000,100,1,12.420000,700,1,14.840000,100,1,ARL,285586157
2025-07-17T15:32:29.578317238Z,2025-07-17T15:32:29.578151593Z,10,2,1108,C,B,5,12.59,100,0,165645,239976225,13.270000,100,1,13.980000,100,1,13.230000,2,1,14.010000,100,1,12.730000,200,2,14.020000,2,1,12.710000,100,1,14.260000,100,1,12.650000,200,2,14.560000,800,2,12.500000,700,1,14.600000,700,1,12.460000,100,1,14.610000,100,1,12.430000,700,1,14.680000,700,1,12.420000,700,1,14.790000,100,1,12.370000,700,1,14.840000,100,1,ARL,285553901
2025-07-17T15:32:29.578317238Z,2025-07-17T15:32:29.578151593Z,10,2,1108,A,B,-1,12.34,100,130,165645,239976225,13.270000,100,1,13.980000,100,1,13.230000,2,1,14.010000,100,1,12.730000,200,2,14.020000,2,1,12.710000,100,1,14.260000,100,1,12.650000,200,2,14.560000,800,2,12.500000,700,1,14.600000,700,1,12.460000,100,1,14.610000,100,1,12.430000,700,1,14.680000,700,1,12.420000,700,1,14.790000,100,1,12.370000,700,1,14.840000,100,1,ARL,285586189
2025-07-17T15:32:29.580933155Z,2025-07-17T15:32:29.580767960Z,10,2,1108,A,B,1,13.26,100,130,165195,239976262,13.270000,100,1,13.980000,100,1,13.260000,100,1,14.010000,100,1,13.230000,2,1,14.020000,2,1,12.730000,200,2,14.260000,100,1,12.710000,100,1,14.560000,800,2,12.650000,200,2,14.600000,700,1,12.500000,700,1,14.610000,100,1,12.460000,100,1,14.680000,700,1,12.430000,700,1,14.790000,100,1,12.420000,700,1,14.840000,100,1,ARL,285586221
2025-07-17T15:32:29.580952045Z,2025-07-17T15:32:29.580786478Z,10,2,1108,C,A,1,14.01,100,0,165567,239976263,13.270000,100,1,13.980000,100,1,13.260000,100,1,14.020000,2,1,13.230000,2,1,14.260000,100,1,12.730000,200,2,14.560000,800,2,12.710000,100,1,14.600000,700,1,12.650000,200,2,14.610000,100,1,12.500000,700,1,14.680000,700,1,12.460000,100,1,14.790000,100,1,12.430000,700,1,14.840000,100,1,12.420000,700,1,14.910000,700,1,ARL,283695933
2025-07-17T15:32:29.580952045Z,2025-07-17T15:32:29.580786478Z,10,2,1108,A,A,1,13.99,100,130,165567,239976263,13.270000,100,1,13.980000,100,1,13.260000,100,1,13.990000,100,1,13.230000,2,1,14.020000,2,1,12.730000,200,2,14.260000,100,1,12.710000,100,1,14.560000,800,2,12.650000,200,2,14.600000,700,1,12.500000,700,1,14.610000,100,1,12.460000,100,1,14.680000,700,1,12.430000,700,1,14.790000,100,1,12.420000,700,1,14.840000,100,1,ARL,285586225
2025-07-17T15:32:29.587192852Z,2025-07-17T15:32:29.587027681Z,10,2,1108,C,B,0,13.27,100,130,165171,239976327,13.260000,100,1,13.980000,100,1,13.230000,2,1,13.990000,100,1,12.730000,200,2,14.020000,2,1,12.710000,100,1,14.260000,100,1,12.650000,200,2,14.560000,800,2,12.500000,700,1,14.600000,700,1,12.460000,100,1,14.610000,100,1,12.430000,700,1,14.680000,700,1,12.420000,700,1,14.790000,100,1,12.370000,700,1,14.840000,100,1,ARL,285546673
2025-07-17T15:32:29.587246470Z,2025-07-17T15:32:29.587081086Z,10,2,1108,A,B,2,13.03,100,130,165384,239976336,13.260000,100,1,13.980000,100,1,13.230000,2,1,13.990000,100,1,13.030000,100,1,14.020000,2,1,12.730000,200,2,14.260000,100,1,12.710000,100,1,14.560000,800,2,12.650000,200,2,14.600000,700,1,12.500000,700,1,14.610000,100,1,12.460000,100,1,14.680000,700,1,12.430000,700,1,14.790000,100,1,12.420000,700,1,14.840000,100,1,ARL,285586293
2025-07-17T15:32:29.659679280Z,2025-07-17T15:32:29.659513918Z,10,2,1108,C,B,3,12.73,100,0,165362,239977574,13.260000,100,1,13.980000,100,1,13.230000,2,1,13.990000,100,1,13.030000,100,1,14.020000,2,1,12.730000,100,1,14.260000,100,1,12.710000,100,1,14.560000,800,2,12.650000,200,2,14.600000,700,1,12.500000,700,1,14.610000,100,1,12.460000,100,1,14.680000,700,1,12.430000,700,1,14.790000,100,1,12.420000,700,1,14.840000,100,1,ARL,285546061
2025-07-17T15:32:29.659679280Z,2025-07-17T15:32:29.659513918Z,10,2,1108,A,B,7,12.46,100,130,165362,239977574,13.260000,100,1,13.980000,100,1,13.230000,2,1,13.990000,100,1,13.030000,100,1,14.020000,2,1,12.730000,100,1,14.260000,100,1,12.710000,100,1,14.560000,800,2,12.650000,200,2,14.600000,700,1,12.500000,700,1,14.610000,100,1,12.460000,200,2,14.680000,700,1,12.430000,700,1,14.790000,100,1,12.420000,700,1,14.840000,100,1,ARL,285587281
2025-07-17T15:33:04.248156868Z,2025-07-17T15:33:04.247990788Z,10,2,1108,C,A,12,14.97,100,0,166080,240885845,13.260000,100,1,13.980000,100,1,13.230000,2,1,13.990000,100,1,13.030000,100,1,14.020000,2,1,12.730000,100,1,14.260000,100,1,12.710000,100,1,14.560000,800,2,12.650000,200,2,14.600000,700,1,12.500000,700,1,14.610000,100,1,12.460000,200,2,14.680000,700,1,12.430000,700,1,14.790000,100,1,12.420000,700,1,14.840000,100,1,ARL,283592993
2025-07-17T15:33:04.248156868Z,2025-07-17T15:33:04.247990788Z,10,2,1108,A,A,8,14.72,100,130,166080,240885845,13.260000,100,1,13.980000,100,1,13.230000,2,1,13.990000,100,1,13.030000,100,1,14.020000,2,1,12.730000,100,1,14.260000,100,1,12.710000,100,1,14.560000,800,2,12.650000,200,2,14.600000,700,1,12.500000,700,1,14.610000,100,1,12.460000,200,2,14.680000,700,1,12.430000,700,1,14.720000,100,1,12.420000,700,1,14.790000,100,1,ARL,286680573
2025-07-17T15:33:04.248189408Z,2025-07-17T15:33:04.248023883Z,10,2,1108,C,A,13,14.97,100,0,165525,240885847,13.260000,100,1,13.980000,100,1,13.230000,2,1,13.990000,100,1,13.030000,100,1,14.020000,2,1,12.730000,100,1,14.260000,100,1,12.710000,100,1,14.560000,800,2,12.650000,200,2,14.600000,700,1,12.500000,700,1,14.610000,100,1,12.460000,200,2,14.680000,700,1,12.430000,700,1,14.720000,100,1,12.420000,700,1,14.790000,100,1,ARL,283593041
2025-07-17T15:33:04.248189408Z,2025-07-17T15:33:04.248023883Z,10,2,1108,A,A,8,14.72,100,130,165525,240885847,13.260000,100,1,13.980000,100,1,13.230000,2,1,13.990000,100,1,13.030000,100,1,14.020000,2,1,12.730000,100,1,14.260000,100,1,12.710000,100,1,14.560000,800,2,12.650000,200,2,14.600000,700,1,12.500000,700,1,14.610000,100,1,12.460000,200,2,14.680000,700,1,12.430000,700,1,14.720000,200,2,12.420000,700,1,14.790000,100,1,ARL,286680577
2025-07-17T15:33:04.255712050Z,2025-07-17T15:33:04.255546094Z,10,2,1108,A,A,0,13.84,100,130,165956,240886132,13.260000,100,1,13.840000,100,1,13.230000,2,1,13.980000,100,1,13.030000,100,1,13.990000,100,1,12.730000,100,1,14.020000,2,1,12.710000,100,1,14.260000,100,1,12.650000,200,2,14.560000,800,2,12.500000,700,1,14.600000,700,1,12.460000,200,2,14.610000,100,1,12.430000,700,1,14.680000,700,1,12.420000,700,1,14.720000,200,2,ARL,286680685
2025-07-17T15:33:04.255777981Z,2025-07-17T15:33:04.255612126Z,10,2,1108,C,B,12,12.27,100,0,165855,240886133,13.260000,100,1,13.840000,100,1,13.230000,2,1,13.980000,100,1,13.030000,100,1,13.990000,100,1,12.730000,100,1,14.020000,2,1,12.710000,100,1,14.260000,100,1,12.650000,200,2,14.560000,800,2,12.500000,700,1,14.600000,700,1,12.460000,200,2,14.610000,100,1,12.430000,700,1,14.680000,700,1,12.420000,700,1,14.720000,200,2,ARL,285586089
2025-07-17T15:33:04.255777981Z,2025-07-17T15:33:04.255612126Z,10,2,1108,A,B,-1,12.23,100,130,165855,240886133,13.260000,100,1,13.840000,100,1,13.230000,2,1,13.980000,100,1,13.030000,100,1,13.990000,100,1,12.730000,100,1,14.020000,2,1,12.710000,100,1,14.260000,100,1,12.650000,200,2,14.560000,800,2,12.500000,700,1,14.600000,700,1,12.460000,200,2,14.610000,100,1,12.430000,700,1,14.680000,700,1,12.420000,700,1,14.720000,200,2,ARL,286680693
2025-07-17T15:33:04.256438228Z,2025-07-17T15:33:04.256272676Z,10,2,1108,C,A,14,15.06,100,0,165552,240886147,13.260000,100,1,13.840000,100,1,13.230000,2,1,13.980000,100,1,13.030000,100,1,13.990000,100,1,12.730000,100,1,14.020000,2,1,12.710000,100,1,14.260000,100,1,12.650000,200,2,14.560000,800,2,12.500000,700,1,14.600000,700,1,12.460000,200,2,14.610000,100,1,12.430000,700,1,14.680000,700,1,12.420000,700,1,14.720000,200,2,ARL,283596673
2025-07-17T15:33:04.256438228Z,2025-07-17T15:33:04.256272676Z,10,2,1108,A,A,-1,14.91,100,130,165552,240886147,13.260000,100,1,13.840000,100,1,13.230000,2,1,13.980000,100,1,13.030000,100,1,13.990000,100,1,12.730000,100,1,14.020000,2,1,12.710000,100,1,14.260000,100,1,12.650000,200,2,14.560000,800,2,12.500000,700,1,14.600000,700,1,12.460000,200,2,14.610000,100,1,12.430000,700,1,14.680000,700,1,12.420000,700,1,14.720000,200,2,ARL,286680721
2025-07-17T15:33:04.258080504Z,2025-07-17T15:33:04.257914956Z,10,2,1108,C,A,13,14.96,100,0,165548,240886188,13.260000,100,1,13.840000,100,1,13.230000,2,1,13.980000,100,1,13.030000,100,1,13.990000,100,1,12.730000,100,1,14.020000,2,1,12.710000,100,1,14.260000,100,1,12.650000,200,2,14.560000,800,2,12.500000,700,1,14.600000,700,1,12.460000,200,2,14.610000,100,1,12.430000,700,1,14.680000,700,1,12.420000,700,1,14.720000,200,2,ARL,283596945
2025-07-17T15:33:04.258080504Z,2025-07-17T15:33:04.257914956Z,10,2,1108,A,A,-1,14.81,100,130,165548,240886188,13.260000,100,1,13.840000,100,1,13.230000,2,1,13.980000,100,1,13.030000,100,1,13.990000,100,1,12.730000,100,1,14.020000,2,1,12.710000,100,1,14.260000,100,1,12.650000,200,2,14.560000,800,2,12.500000,700,1,14.600000,700,1,12.460000,200,2,14.610000,100,1,12.430000,700,1,14.680000,700,1,12.420000,700,1,14.720000,200,2,ARL,286680741
2025-07-17T15:33:04.261684319Z,2025-07-17T15:33:04.261518776Z,10,2,1108,C,A,10,14.79,100,0,165543,240886271,13.260000,100,1,13.840000,100,1,13.230000,2,1,13.980000,100,1,13.030000,100,1,13.990000,100,1,12.730000,100,1,14.020000,2,1,12.710000,100,1,14.260000,100,1,12.650000,200,2,14.560000,800,2,12.500000,700,1,14.600000,700,1,12.460000,200,2,14.610000,100,1,12.430000,700,1,14.680000,700,1,12.420000,700,1,14.720000,200,2,ARL,283593313
2025-07-17T15:33:04.261684319Z,2025-07-17T15:33:04.261518776Z,10,2,1108,A,A,8,14.65,100,130,165543,240886271,13.260000,100,1,13.840000,100,1,13.230000,2,1,13.980000,100,1,13.030000,100,1,13.990000,100,1,12.730000,100,1,14.020000,2,1,12.710000,100,1,14.260000,100,1,12.650000,200,2,14.560000,800,2,12.500000,700,1,14.600000,700,1,12.460000,200,2,14.610000,100,1,12.430000,700,1,14.650000,100,1,12.420000,700,1,14.680000,700,1,ARL,286680905
2025-07-17T15:33:04.263011314Z,2025-07-17T15:33:04.262845834Z,10,2,1108,C,A,4,14.26,100,130,165480,240886294,13.260000,100,1,13.840000,100,1,13.230000,2,1,13.980000,100,1,13.030000,100,1,13.990000,100,1,12.730000,100,1,14.020000,2,1,12.710000,100,1,14.560000,800,2,12.650000,200,2,14.600000,700,1,12.500000,700,1,14.610000,100,1,12.460000,200,2,14.650000,100,1,12.430000,700,1,14.680000,700,1,12.420000,700,1,14.720000,200,2,ARL,283595181
2025-07-17T15:33:04.263052660Z,2025-07-17T15:33:04.262887184Z,10,2,1108,C,A,1,13.98,100,130,165476,240886296,13.260000,100,1,13.840000,100,1,13.230000,2,1,13.990000,100,1,13.030000,100,1,14.020000,2,1,12.730000,100,1,14.560000,800,2,12.710000,100,1,14.600000,700,1,12.650000,200,2,14.610000,100,1,12.500000,700,1,14.650000,100,1,12.460000,200,2,14.680000,700,1,12.430000,700,1,14.720000,200,2,12.420000,700,1,14.810000,100,1,ARL,285556869
2025-07-17T15:33:04.263065252Z,2025-07-17T15:33:04.262899981Z,10,2,1108,A,A,3,14.12,100,130,165271,240886297,13.260000,100,1,13.840000,100,1,13.230000,2,1,13.990000,100,1,13.030000,100,1,14.020000,2,1,12.730000,100,1,14.120000,100,1,12.710000,100,1,14.560000,800,2,12.650000,200,2,14.600000,700,1,12.500000,700,1,14.610000,100,1,12.460000,200,2,14.650000,100,1,12.430000,700,1,14.680000,700,1,12.420000,700,1,14.720000,200,2,ARL,286680917
2025-07-17T15:33:04.271212113Z,2025-07-17T15:33:04.271046430Z,10,2,1108,C,A,20,17.76,100,0,165683,240886583,13.260000,100,1,13.840000,100,1,13.230000,2,1,13.990000,100,1,13.030000,100,1,14.020000,2,1,12.730000,100,1,14.120000,100,1,12.710000,100,1,14.560000,800,2,12.650000,200,2,14.600000,700,1,12.500000,700,1,14.610000,100,1,12.460000,200,2,14.650000,100,1,12.430000,700,1,14.680000,700,1,12.420000,700,1,14.720000,200,2,ARL,283594173
2025-07-17T15:33:04.271212113Z,2025-07-17T15:33:04.271046430Z,10,2,1108,A,A,-1,17.58,100,130,165683,240886583,13.260000,100,1,13.840000,100,1,13.230000,2,1,13.990000,100,1,13.030000,100,1,14.020000,2,1,12.730000,100,1,14.120000,100,1,12.710000,100,1,14.560000,800,2,12.650000,200,2,14.600000,700,1,12.500000,700,1,14.610000,100,1,12.460000,200,2,14.650000,100,1,12.430000,700,1,14.680000,700,1,12.420000,700,1,14.720000,200,2,ARL,286681057
2025-07-17T15:33:04.277880725Z,2025-07-17T15:33:04.277715123Z,10,2,1108,C,A,18,16.08,100,0,165602,240886720,13.260000,100,1,13.840000,100,1,13.230000,2,1,13.990000,100,1,13.030000,100,1,14.020000,2,1,12.730000,100,1,14.120000,100,1,12.710000,100,1,14.560000,800,2,12.650000,200,2,14.600000,700,1,12.500000,700,1,14.610000,100,1,12.460000,200,2,14.650000,100,1,12.430000,700,1,14.680000,700,1,12.420000,700,1,14.720000,200,2,ARL,283599609
2025-07-17T15:33:04.277880725Z,2025-07-17T15:33:04.277715123Z,10,2,1108,A,A,-1,15.92,100,130,165602,240886720,13.260000,100,1,13.840000,100,1,13.230000,2,1,13.990000,100,1,13.030000,100,1,14.020000,2,1,12.730000,100,1,14.120000,100,1,12.710000,100,1,14.560000,800,2,12.650000,200,2,14.600000,700,1,12.500000,700,1,14.610000,100,1,12.460000,200,2,14.650000,100,1,12.430000,700,1,14.680000,700,1,12.420000,700,1,14.720000,200,2,ARL,286681229
2025-07-17T15:33:04.418840148Z,2025-07-17T15:33:04.418674487Z,10,2,1108,C,A,13,14.96,100,0,165661,240888774,13.260000,100,1,13.840000,100,1,13.230000,2,1,13.990000,100,1,13.030000,100,1,14.020000,2,1,12.730000,100,1,14.120000,100,1,12.710000,100,1,14.560000,800,2,12.650000,200,2,14.600000,700,1,12.500000,700,1,14.610000,100,1,12.460000,200,2,14.650000,100,1,12.430000,700,1,14.680000,700,1,12.420000,700,1,14.720000,200,2,ARL,283596721
2025-07-17T15:33:04.418840148Z,2025-07-17T15:33:04.418674487Z,10,2,1108,A,A,-1,14.81,100,130,165661,240888774,13.260000,100,1,13.840000,100,1,13.230000,2,1,13.990000,100,1,13.030000,100,1,14.020000,2,1,12.730000,100,1,14.120000,100,1,12.710000,100,1,14.560000,800,2,12.650000,200,2,14.600000,700,1,12.500000,700,1,14.610000,100,1,12.460000,200,2,14.650000,100,1,12.430000,700,1,14.680000,700,1,12.420000,700,1,14.720000,200,2,ARL,286684005
2025-07-17T15:33:05.330854217Z,2025-07-17T15:33:05.330688486Z,10,2,1108,C,A,1,13.99,100,0,165731,240911093,13.260000,100,1,13.840000,100,1,13.230000,2,1,14.020000,2,1,13.030000,100,1,14.120000,100,1,12.730000,100,1,14.560000,800,2,12.710000,100,1,14.600000,700,1,12.650000,200,2,14.610000,100,1,12.500000,700,1,14.650000,100,1,12.460000,200,2,14.680000,700,1,12.430000,700,1,14.720000,200,2,12.420000,700,1,14.810000,200,2,ARL,285586225
2025-07-17T15:33:05.330854217Z,2025-07-17T15:33:05.330688486Z,10,2,1108,A,A,1,13.85,100,130,165731,240911093,13.260000,100,1,13.840000,100,1,13.230000,2,1,13.850000,100,1,13.030000,100,1,14.020000,2,1,12.730000,100,1,14.120000,100,1,12.710000,100,1,14.560000,800,2,12.650000,200,2,14.600000,700,1,12.500000,700,1,14.610000,100,1,12.460000,200,2,14.650000,100,1,12.430000,700,1,14.680000,700,1,12.420000,700,1,14.720000,200,2,ARL,286704785
2025-07-17T15:33:06.455979270Z,2025-07-17T15:33:06.455814002Z,10,2,1108,C,A,0,13.84,100,130,165268,240936407,13.260000,100,1,13.850000,100,1,13.230000,2,1,14.020000,2,1,13.030000,100,1,14.120000,100,1,12.730000,100,1,14.560000,800,2,12.710000,100,1,14.600000,700,1,12.650000,200,2,14.610000,100,1,12.500000,700,1,14.650000,100,1,12.460000,200,2,14.680000,700,1,12.430000,700,1,14.720000,200,2,12.420000,700,1,14.810000,200,2,ARL,286680685
2025-07-17T15:33:10.468005342Z,2025-07-17T15:33:10.467840054Z,10,2,1108,A,A,1,13.87,100,130,165288,241000095,13.260000,100,1,13.850000,100,1,13.230000,2,1,13.870000,100,1,13.030000,100,1,14.020000,2,1,12.730000,100,1,14.120000,100,1,12.710000,100,1,14.560000,800,2,12.650000,200,2,14.600000,700,1,12.500000,700,1,14.610000,100,1,12.460000,200,2,14.650000,100,1,12.430000,700,1,14.680000,700,1,12.420000,700,1,14.720000,200,2,ARL,286828253
2025-07-17T15:33:40.986585803Z,2025-07-17T15:33:40.986420127Z,10,2,1108,C,A,2,14.02,2,0,165676,241593788,13.260000,100,1,13.850000,100,1,13.230000,2,1,13.870000,100,1,13.030000,100,1,14.120000,100,1,12.730000,100,1,14.560000,800,2,12.710000,100,1,14.600000,700,1,12.650000,200,2,14.610000,100,1,12.500000,700,1,14.650000,100,1,12.460000,200,2,14.680000,700,1,12.430000,700,1,14.720000,200,2,12.420000,700,1,14.810000,200,2,ARL,283348193
2025-07-17T15:33:40.986585803Z,2025-07-17T15:33:40.986420127Z,10,2,1108,A,A,2,13.95,2,130,165676,241593788,13.260000,100,1,13.850000,100,1,13.230000,2,1,13.870000,100,1,13.030000,100,1,13.950000,2,1,12.730000,100,1,14.120000,100,1,12.710000,100,1,14.560000,800,2,12.650000,200,2,14.600000,700,1,12.500000,700,1,14.610000,100,1,12.460000,200,2,14.650000,100,1,12.430000,700,1,14.680000,700,1,12.420000,700,1,14.720000,200,2,ARL,287540393
2025-07-17T15:33:41.766184571Z,2025-07-17T15:33:41.766018916Z,10,2,1108,A,A,0,13.82,10,130,165655,241612289,13.260000,100,1,13.820000,10,1,13.230000,2,1,13.850000,100,1,13.030000,100,1,13.870000,100,1,12.730000,100,1,13.950000,2,1,12.710000,100,1,14.120000,100,1,12.650000,200,2,14.560000,800,2,12.500000,700,1,14.600000,700,1,12.460000,200,2,14.610000,100,1,12.430000,700,1,14.650000,100,1,12.420000,700,1,14.680000,700,1,ARL,287560109
2025-07-17T15:33:41.766265703Z,2025-07-17T15:33:41.766100204Z,10,2,1108,C,A,1,13.85,100,0,165499,241612294,13.260000,100,1,13.820000,10,1,13.230000,2,1,13.870000,100,1,13.030000,100,1,13.950000,2,1,12.730000,100,1,14.120000,100,1,12.710000,100,1,14.560000,800,2,12.650000,200,2,14.600000,700,1,12.500000,700,1,14.610000,100,1,12.460000,200,2,14.650000,100,1,12.430000,700,1,14.680000,700,1,12.420000,700,1,14.720000,200,2,ARL,286704785
2025-07-17T15:33:41.766265703Z,2025-07-17T15:33:41.766100204Z,10,2,1108,A,A,1,13.83,100,130,165499,241612294,13.260000,100,1,13.820000,10,1,13.230000,2,1,13.830000,100,1,13.030000,100,1,13.870000,100,1,12.730000,100,1,13.950000,2,1,12.710000,100,1,14.120000,100,1,12.650000,200,2,14.560000,800,2,12.500000,700,1,14.600000,700,1,12.460000,200,2,14.610000,100,1,12.430000,700,1,14.650000,100,1,12.420000,700,1,14.680000,700,1,ARL,287560121
2025-07-17T15:33:41.777404666Z,2025-07-17T15:33:41.777239400Z,10,2,1108,A,A,2,13.85,100,130,165266,241612426,13.260000,100,1,13.820000,10,1,13.230000,2,1,13.830000,100,1,13.030000,100,1,13.850000,100,1,12.730000,100,1,13.870000,100,1,12.710000,100,1,13.950000,2,1,12.650000,200,2,14.120000,100,1,12.500000,700,1,14.560000,800,2,12.460000,200,2,14.600000,700,1,12.430000,700,1,14.610000,100,1,12.420000,700,1,14.650000,100,1,ARL,287560333
2025-07-17T15:33:41.784121031Z,2025-07-17T15:33:41.783955668Z,10,2,1108,C,A,3,13.87,100,130,165363,241612450,13.260000,100,1,13.820000,10,1,13.230000,2,1,13.830000,100,1,13.030000,100,1,13.850000,100,1,12.730000,100,1,13.950000,2,1,12.710000,100,1,14.120000,100,1,12.650000,200,2,14.560000,800,2,12.500000,700,1,14.600000,700,1,12.460000,200,2,14.610000,100,1,12.430000,700,1,14.650000,100,1,12.420000,700,1,14.680000,700,1,ARL,286828253
2025-07-17T15:33:42.773141775Z,2025-07-17T15:33:42.772976862Z,10,2,1108,C,A,0,13.82,10,130,164913,241630390,13.260000,100,1,13.830000,100,1,13.230000,2,1,13.850000,100,1,13.030000,100,1,13.950000,2,1,12.730000,100,1,14.120000,100,1,12.710000,100,1,14.560000,800,2,12.650000,200,2,14.600000,700,1,12.500000,700,1,14.610000,100,1,12.460000,200,2,14.650000,100,1,12.430000,700,1,14.680000,700,1,12.420000,700,1,14.720000,200,2,ARL,287560109
2025-07-17T15:34:28.155773560Z,2025-07-17T15:34:28.155608087Z,10,2,1108,A,A,4,14.20,50,130,165473,242513312,13.260000,100,1,13.830000,100,1,13.230000,2,1,13.850000,100,1,13.030000,100,1,13.950000,2,1,12.730000,100,1,14.120000,100,1,12.710000,100,1,14.200000,50,1,12.650000,200,2,14.560000,800,2,12.500000,700,1,14.600000,700,1,12.460000,200,2,14.610000,100,1,12.430000,700,1,14.650000,100,1,12.420000,700,1,14.680000,700,1,ARL,288723725
2025-07-17T15:34:28.156815057Z,2025-07-17T15:34:28.156649544Z,10,2,1108,C,B,5,12.65,100,0,165513,242513329,13.260000,100,1,13.830000,100,1,13.230000,2,1,13.850000,100,1,13.030000,100,1,13.950000,2,1,12.730000,100,1,14.120000,100,1,12.710000,100,1,14.200000,50,1,12.650000,100,1,14.560000,800,2,12.500000,700,1,14.600000,700,1,12.460000,200,2,14.610000,100,1,12.430000,700,1,14.650000,100,1,12.420000,700,1,14.680000,700,1,ARL,236206261
2025-07-17T15:34:28.156815057Z,2025-07-17T15:34:28.156649544Z,10,2,1108,A,B,-1,12.36,100,130,165513,242513329,13.260000,100,1,13.830000,100,1,13.230000,2,1,13.850000,100,1,13.030000,100,1,13.950000,2,1,12.730000,100,1,14.120000,100,1,12.710000,100,1,14.200000,50,1,12.650000,100,1,14.560000,800,2,12.500000,700,1,14.600000,700,1,12.460000,200,2,14.610000,100,1,12.430000,700,1,14.650000,100,1,12.420000,700,1,14.680000,700,1,ARL,288723813
2025-07-17T15:34:28.156884900Z,2025-07-17T15:34:28.156719339Z,10,2,1108,C,B,5,12.65,100,0,165561,242513330,13.260000,100,1,13.830000,100,1,13.230000,2,1,13.850000,100,1,13.030000,100,1,13.950000,2,1,12.730000,100,1,14.120000,100,1,12.710000,100,1,14.200000,50,1,12.500000,700,1,14.560000,800,2,12.460000,200,2,14.600000,700,1,12.430000,700,1,14.610000,100,1,12.420000,700,1,14.650000,100,1,12.370000,700,1,14.680000,700,1,ARL,236179089
2025-07-17T15:34:28.156884900Z,2025-07-17T15:34:28.156719339Z,10,2,1108,A,B,-1,12.36,100,130,165561,242513330,13.260000,100,1,13.830000,100,1,13.230000,2,1,13.850000,100,1,13.030000,100,1,13.950000,2,1,12.730000,100,1,14.120000,100,1,12.710000,100,1,14.200000,50,1,12.500000,700,1,14.560000,800,2,12.460000,200,2,14.600000,700,1,12.430000,700,1,14.610000,100,1,12.420000,700,1,14.650000,100,1,12.370000,700,1,14.680000,700,1,ARL,288723817
2025-07-17T15:34:28.170740864Z,2025-07-17T15:34:28.170575785Z,10,2,1108,A,A,0,13.81,50,130,165079,242513651,13.260000,100,1,13.810000,50,1,13.230000,2,1,13.830000,100,1,13.030000,100,1,13.850000,100,1,12.730000,100,1,13.950000,2,1,12.710000,100,1,14.120000,100,1,12.500000,700,1,14.200000,50,1,12.460000,200,2,14.560000,800,2,12.430000,700,1,14.600000,700,1,12.420000,700,1,14.610000,100,1,12.370000,700,1,14.650000,100,1,ARL,288724173
2025-07-17T15:34:28.170792211Z,2025-07-17T15:34:28.170626756Z,10,2,1108,C,B,0,13.26,100,130,165455,242513653,13.230000,2,1,13.810000,50,1,13.030000,100,1,13.830000,100,1,12.730000,100,1,13.850000,100,1,12.710000,100,1,13.950000,2,1,12.500000,700,1,14.120000,100,1,12.460000,200,2,14.200000,50,1,12.430000,700,1,14.560000,800,2,12.420000,700,1,14.600000,700,1,12.370000,700,1,14.610000,100,1,12.360000,200,2,14.650000,100,1,ARL,285586221
2025-07-17T15:34:28.171437442Z,2025-07-17T15:34:28.171272157Z,10,2,1108,A,A,0,13.78,2,130,165285,242513665,13.230000,2,1,13.780000,2,1,13.030000,100,1,13.810000,50,1,12.730000,100,1,13.830000,100,1,12.710000,100,1,13.850000,100,1,12.500000,700,1,13.950000,2,1,12.460000,200,2,14.120000,100,1,12.430000,700,1,14.200000,50,1,12.420000,700,1,14.560000,800,2,12.370000,700,1,14.600000,700,1,12.360000,200,2,14.610000,100,1,ARL,288724201
2025-07-17T15:34:28.172057926Z,2025-07-17T15:34:28.171892519Z,10,2,1108,A,B,0,13.31,10,130,165407,242513691,13.310000,10,1,13.780000,2,1,13.230000,2,1,13.810000,50,1,13.030000,100,1,13.830000,100,1,12.730000,100,1,13.850000,100,1,12.710000,100,1,13.950000,2,1,12.500000,700,1,14.120000,100,1,12.460000,200,2,14.200000,50,1,12.430000,700,1,14.560000,800,2,12.420000,700,1,14.600000,700,1,12.370000,700,1,14.610000,100,1,ARL,288724225
2025-07-17T15:34:28.172058708Z,2025-07-17T15:34:28.171893498Z,10,2,1108,A,A,2,13.82,10,130,165210,242513692,13.310000,10,1,13.780000,2,1,13.230000,2,1,13.810000,50,1,13.030000,100,1,13.820000,10,1,12.730000,100,1,13.830000,100,1,12.710000,100,1,13.850000,100,1,12.500000,700,1,13.950000,2,1,12.460000,200,2,14.120000,100,1,12.430000,700,1,14.200000,50,1,12.420000,700,1,14.560000,800,2,12.370000,700,1,14.600000,700,1,ARL,288724229
2025-07-17T15:34:28.175011712Z,2025-07-17T15:34:28.174846475Z,10,2,1108,A,B,1,13.30,100,130,165237,242513742,13.310000,10,1,13.780000,2,1,13.300000,100,1,13.810000,50,1,13.230000,2,1,13.820000,10,1,13.030000,100,1,13.830000,100,1,12.730000,100,1,13.850000,100,1,12.710000,100,1,13.950000,2,1,12.500000,700,1,14.120000,100,1,12.460000,200,2,14.200000,50,1,12.430000,700,1,14.560000,800,2,12.420000,700,1,14.600000,700,1,ARL,288724429
2025-07-17T15:34:28.175030125Z,2025-07-17T15:34:28.174864618Z,10,2,1108,C,A,3,13.83,100,0,165507,242513743,13.310000,10,1,13.780000,2,1,13.300000,100,1,13.810000,50,1,13.230000,2,1,13.820000,10,1,13.030000,100,1,13.850000,100,1,12.730000,100,1,13.950000,2,1,12.710000,100,1,14.120000,100,1,12.500000,700,1,14.200000,50,1,12.460000,200,2,14.560000,800,2,12.430000,700,1,14.600000,700,1,12.420000,700,1,14.610000,100,1,ARL,287560121
2025-07-17T15:34:28.175030125Z,2025-07-17T15:34:28.174864618Z,10,2,1108,A,A,1,13.79,100,130,165507,242513743,13.310000,10,1,13.780000,2,1,13.300000,100,1,13.790000,100,1,13.230000,2,1,13.810000,50,1,13.030000,100,1,13.820000,10,1,12.730000,100,1,13.850000,100,1,12.710000,100,1,13.950000,2,1,12.500000,700,1,14.120000,100,1,12.460000,200,2,14.200000,50,1,12.430000,700,1,14.560000,800,2,12.420000,700,1,14.600000,700,1,ARL,288724433
2025-07-17T15:34:28.175329569Z,2025-07-17T15:34:28.175164464Z,10,2,1108,C,A,0,13.78,2,130,165105,242513747,13.310000,10,1,13.790000,100,1,13.300000,100,1,13.810000,50,1,13.230000,2,1,13.820000,10,1,13.030000,100,1,13.850000,100,1,12.730000,100,1,13.950000,2,1,12.710000,100,1,14.120000,100,1,12.500000,700,1,14.200000,50,1,12.460000,200,2,14.560000,800,2,12.430000,700,1,14.600000,700,1,12.420000,700,1,14.610000,100,1,ARL,288724201
2025-07-17T15:34:28.175752130Z,2025-07-17T15:34:28.175586497Z,10,2,1108,C,B,13,12.23,100,0,165633,242513748,13.310000,10,1,13.790000,100,1,13.300000,100,1,13.810000,50,1,13.230000,2,1,13.820000,10,1,13.030000,100,1,13.850000,100,1,12.730000,100,1,13.950000,2,1,12.710000,100,1,14.120000,100,1,12.500000,700,1,14.200000,50,1,12.460000,200,2,14.560000,800,2,12.430000,700,1,14.600000,700,1,12.420000,700,1,14.610000,100,1,ARL,286680693
2025-07-17T15:34:28.175752130Z,2025-07-17T15:34:28.175586497Z,10,2,1108,A,B,-1,12.27,100,130,165633,242513748,13.310000,10,1,13.790000,100,1,13.300000,100,1,13.810000,50,1,13.230000,2,1,13.820000,10,1,13.030000,100,1,13.850000,100,1,12.730000,100,1,13.950000,2,1,12.710000,100,1,14.120000,100,1,12.500000,700,1,14.200000,50,1,12.460000,200,2,14.560000,800,2,12.430000,700,1,14.600000,700,1,12.420000,700,1,14.610000,100,1,ARL,288724485
2025-07-17T15:34:28.175767666Z,2025-07-17T15:34:28.175602100Z,10,2,1108,C,A,15,14.91,100,0,165566,242513749,13.310000,10,1,13.790000,100,1,13.300000,100,1,13.810000,50,1,13.230000,2,1,13.820000,10,1,13.030000,100,1,13.850000,100,1,12.730000,100,1,13.950000,2,1,12.710000,100,1,14.120000,100,1,12.500000,700,1,14.200000,50,1,12.460000,200,2,14.560000,800,2,12.430000,700,1,14.600000,700,1,12.420000,700,1,14.610000,100,1,ARL,286680721
2025-07-17T15:34:28.175767666Z,2025-07-17T15:34:28.175602100Z,10,2,1108,A,A,-1,14.86,100,130,165566,242513749,13.310000,10,1,13.790000,100,1,13.300000,100,1,13.810000,50,1,13.230000,2,1,13.820000,10,1,13.030000,100,1,13.850000,100,1,12.730000,100,1,13.950000,2,1,12.710000,100,1,14.120000,100,1,12.500000,700,1,14.200000,50,1,12.460000,200,2,14.560000,800,2,12.430000,700,1,14.600000,700,1,12.420000,700,1,14.610000,100,1,ARL,288724489
2025-07-17T15:34:28.180356536Z,2025-07-17T15:34:28.180191067Z,10,2,1108,A,A,1,13.80,100,130,165469,242513781,13.310000,10,1,13.790000,100,1,13.300000,100,1,13.800000,100,1,13.230000,2,1,13.810000,50,1,13.030000,100,1,13.820000,10,1,12.730000,100,1,13.850000,100,1,12.710000,100,1,13.950000,2,1,12.500000,700,1,14.120000,100,1,12.460000,200,2,14.200000,50,1,12.430000,700,1,14.560000,800,2,12.420000,700,1,14.600000,700,1,ARL,288724565
2025-07-17T15:34:28.187237384Z,2025-07-17T15:34:28.187072050Z,10,2,1108,C,A,4,13.85,100,130,165334,242513907,13.310000,10,1,13.790000,100,1,13.300000,100,1,13.800000,100,1,13.230000,2,1,13.810000,50,1,13.030000,100,1,13.820000,10,1,12.730000,100,1,13.950000,2,1,12.710000,100,1,14.120000,100,1,12.500000,700,1,14.200000,50,1,12.460000,200,2,14.560000,800,2,12.430000,700,1,14.600000,700,1,12.420000,700,1,14.610000,100,1,ARL,287560333
2025-07-17T15:34:28.192269421Z,2025-07-17T15:34:28.192104387Z,10,2,1108,C,A,0,13.79,100,130,165034,242513974,13.310000,10,1,13.800000,100,1,13.300000,100,1,13.810000,50,1,13.230000,2,1,13.820000,10,1,13.030000,100,1,13.950000,2,1,12.730000,100,1,14.120000,100,1,12.710000,100,1,14.200000,50,1,12.500000,700,1,14.560000,800,2,12.460000,200,2,14.600000,700,1,12.430000,700,1,14.610000,100,1,12.420000,700,1,14.650000,100,1,ARL,288724433
2025-07-17T15:34:28.231601320Z,2025-07-17T15:34:28.231436134Z,10,2,1108,A,A,3,13.83,100,130,165186,242514372,13.310000,10,1,13.800000,100,1,13.300000,100,1,13.810000,50,1,13.230000,2,1,13.820000,10,1,13.030000,100,1,13.830000,100,1,12.730000,100,1,13.950000,2,1,12.710000,100,1,14.120000,100,1,12.500000,700,1,14.200000,50,1,12.460000,200,2,14.560000,800,2,12.430000,700,1,14.600000,700,1,12.420000,700,1,14.610000,100,1,ARL,288725173
2025-07-17T15:34:28.256123809Z,2025-07-17T15:34:28.255958718Z,10,2,1108,C,A,6,14.20,50,130,165091,242514761,13.310000,10,1,13.800000,100,1,13.300000,100,1,13.810000,50,1,13.230000,2,1,13.820000,10,1,13.030000,100,1,13.830000,100,1,12.730000,100,1,13.950000,2,1,12.710000,100,1,14.120000,100,1,12.500000,700,1,14.560000,800,2,12.460000,200,2,14.600000,700,1,12.430000,700,1,14.610000,100,1,12.420000,700,1,14.650000,100,1,ARL,288723725
2025-07-17T15:34:28.271275449Z,2025-07-17T15:34:28.271110273Z,10,2,1108,C,A,1,13.81,50,130,165176,242515164,13.310000,10,1,13.800000,100,1,13.300000,100,1,13.820000,10,1,13.230000,2,1,13.830000,100,1,13.030000,100,1,13.950000,2,1,12.730000,100,1,14.120000,100,1,12.710000,100,1,14.560000,800,2,12.500000,700,1,14.600000,700,1,12.460000,200,2,14.610000,100,1,12.430000,700,1,14.650000,100,1,12.420000,700,1,14.680000,700,1,ARL,288724173
2025-07-17T15:34:28.281217370Z,2025-07-17T15:34:28.281052249Z,10,2,1108,C,A,0,13.80,100,130,165121,242515254,13.310000,10,1,13.820000,10,1,13.300000,100,1,13.830000,100,1,13.230000,2,1,13.950000,2,1,13.030000,100,1,14.120000,100,1,12.730000,100,1,14.560000,800,2,12.710000,100,1,14.600000,700,1,12.500000,700,1,14.610000,100,1,12.460000,200,2,14.650000,100,1,12.430000,700,1,14.680000,700,1,12.420000,700,1,14.720000,200,2,ARL,288724565
2025-07-17T15:34:28.281945481Z,2025-07-17T15:34:28.281780230Z,10,2,1108,C,A,12,14.86,100,0,165251,242515263,13.310000,10,1,13.820000,10,1,13.300000,100,1,13.830000,100,1,13.230000,2,1,13.950000,2,1,13.030000,100,1,14.120000,100,1,12.730000,100,1,14.560000,800,2,12.710000,100,1,14.600000,700,1,12.500000,700,1,14.610000,100,1,12.460000,200,2,14.650000,100,1,12.430000,700,1,14.680000,700,1,12.420000,700,1,14.720000,200,2,ARL,288724489
2025-07-17T15:34:28.281945481Z,2025-07-17T15:34:28.281780230Z,10,2,1108,A,A,-1,14.90,100,130,165251,242515263,13.310000,10,1,13.820000,10,1,13.300000,100,1,13.830000,100,1,13.230000,2,1,13.950000,2,1,13.030000,100,1,14.120000,100,1,12.730000,100,1,14.560000,800,2,12.710000,100,1,14.600000,700,1,12.500000,700,1,14.610000,100,1,12.460000,200,2,14.650000,100,1,12.430000,700,1,14.680000,700,1,12.420000,700,1,14.720000,200,2,ARL,288726085
2025-07-17T15:34:32.289409612Z,2025-07-17T15:34:32.289244370Z,10,2,1108,A,A,2,13.84,100,130,165242,242598225,13.310000,10,1,13.820000,10,1,13.300000,100,1,13.830000,100,1,13.230000,2,1,13.840000,100,1,13.030000,100,1,13.950000,2,1,12.730000,100,1,14.120000,100,1,12.710000,100,1,14.560000,800,2,12.500000,700,1,14.600000,700,1,12.460000,200,2,14.610000,100,1,12.430000,700,1,14.650000,100,1,12.420000,700,1,14.680000,700,1,ARL,288845417
2025-07-17T15:34:39.864692027Z,2025-07-17T15:34:39.864526516Z,10,2,1108,A,A,0,13.80,15,130,165511,242774235,13.310000,10,1,13.800000,15,1,13.300000,100,1,13.820000,10,1,13.230000,2,1,13.830000,100,1,13.030000,100,1,13.840000,100,1,12.730000,100,1,13.950000,2,1,12.710000,100,1,14.120000,100,1,12.500000,700,1,14.560000,800,2,12.460000,200,2,14.600000,700,1,12.430000,700,1,14.610000,100,1,12.420000,700,1,14.650000,100,1,ARL,289055901
2025-07-17T15:34:39.865337932Z,2025-07-17T15:34:39.865171719Z,10,2,1108,C,A,2,13.83,100,0,166213,242774299,13.310000,10,1,13.800000,15,1,13.300000,100,1,13.820000,10,1,13.230000,2,1,13.840000,100,1,13.030000,100,1,13.950000,2,1,12.730000,100,1,14.120000,100,1,12.710000,100,1,14.560000,800,2,12.500000,700,1,14.600000,700,1,12.460000,200,2,14.610000,100,1,12.430000,700,1,14.650000,100,1,12.420000,700,1,14.680000,700,1,ARL,288725173
2025-07-17T15:34:39.865337932Z,2025-07-17T15:34:39.865171719Z,10,2,1108,A,A,1,13.81,100,130,166213,242774299,13.310000,10,1,13.800000,15,1,13.300000,100,1,13.810000,100,1,13.230000,2,1,13.820000,10,1,13.030000,100,1,13.840000,100,1,12.730000,100,1,13.950000,2,1,12.710000,100,1,14.120000,100,1,12.500000,700,1,14.560000,800,2,12.460000,200,2,14.600000,700,1,12.430000,700,1,14.610000,100,1,12.420000,700,1,14.650000,100,1,ARL,289056097
2025-07-17T15:34:39.871606986Z,2025-07-17T15:34:39.871441822Z,10,2,1108,A,A,1,13.81,100,130,165164,242774468,13.310000,10,1,13.800000,15,1,13.300000,100,1,13.810000,200,2,13.230000,2,1,13.820000,10,1,13.030000,100,1,13.840000,100,1,12.730000,100,1,13.950000,2,1,12.710000,100,1,14.120000,100,1,12.500000,700,1,14.560000,800,2,12.460000,200,2,14.600000,700,1,12.430000,700,1,14.610000,100,1,12.420000,700,1,14.650000,100,1,ARL,289056353
2025-07-17T15:34:39.878645012Z,2025-07-17T15:34:39.878479562Z,10,2,1108,C,A,3,13.84,100,130,165450,242774619,13.310000,10,1,13.800000,15,1,13.300000,100,1,13.810000,200,2,13.230000,2,1,13.820000,10,1,13.030000,100,1,13.950000,2,1,12.730000,100,1,14.120000,100,1,12.710000,100,1,14.560000,800,2,12.500000,700,1,14.600000,700,1,12.460000,200,2,14.610000,100,1,12.430000,700,1,14.650000,100,1,12.420000,700,1,14.680000,700,1,ARL,288845417
2025-07-17T15:34:42.774190041Z,2025-07-17T15:34:42.774024574Z,10,2,1108,C,B,0,13.31,10,130,165467,242816556,13.300000,100,1,13.800000,15,1,13.230000,2,1,13.810000,200,2,13.030000,100,1,13.820000,10,1,12.730000,100,1,13.950000,2,1,12.710000,100,1,14.120000,100,1,12.500000,700,1,14.560000,800,2,12.460000,200,2,14.600000,700,1,12.430000,700,1,14.610000,100,1,12.420000,700,1,14.650000,100,1,12.370000,700,1,14.680000,700,1,ARL,288724225
2025-07-17T15:34:42.775304741Z,2025-07-17T15:34:42.775139521Z,10,2,1108,C,A,1,13.81,100,130,165220,242816563,13.300000,100,1,13.800000,15,1,13.230000,2,1,13.810000,100,1,13.030000,100,1,13.820000,10,1,12.730000,100,1,13.950000,2,1,12.710000,100,1,14.120000,100,1,12.500000,700,1,14.560000,800,2,12.460000,200,2,14.600000,700,1,12.430000,700,1,14.610000,100,1,12.420000,700,1,14.650000,100,1,12.370000,700,1,14.680000,700,1,ARL,289056353
2025-07-17T15:34:46.774087945Z,2025-07-17T15:34:46.773922586Z,10,2,1108,C,A,0,13.80,15,130,165359,242893860,13.300000,100,1,13.810000,100,1,13.230000,2,1,13.820000,10,1,13.030000,100,1,13.950000,2,1,12.730000,100,1,14.120000,100,1,12.710000,100,1,14.560000,800,2,12.500000,700,1,14.600000,700,1,12.460000,200,2,14.610000,100,1,12.430000,700,1,14.650000,100,1,12.420000,700,1,14.680000,700,1,12.370000,700,1,14.720000,200,2,ARL,289055901
2025-07-17T15:34:46.800955057Z,2025-07-17T15:34:46.800789632Z,10,2,1108,A,A,2,13.83,100,130,165425,242894153,13.300000,100,1,13.810000,100,1,13.230000,2,1,13.820000,10,1,13.030000,100,1,13.830000,100,1,12.730000,100,1,13.950000,2,1,12.710000,100,1,14.120000,100,1,12.500000,700,1,14.560000,800,2,12.460000,200,2,14.600000,700,1,12.430000,700,1,14.610000,100,1,12.420000,700,1,14.650000,100,1,12.370000,700,1,14.680000,700,1,ARL,289199221
2025-07-17T15:34:53.545830704Z,2025-07-17T15:34:53.545665068Z,10,2,1108,C,A,1,13.82,10,130,165636,243011340,13.300000,100,1,13.810000,100,1,13.230000,2,1,13.830000,100,1,13.030000,100,1,13.950000,2,1,12.730000,100,1,14.120000,100,1,12.710000,100,1,14.560000,800,2,12.500000,700,1,14.600000,700,1,12.460000,200,2,14.610000,100,1,12.430000,700,1,14.650000,100,1,12.420000,700,1,14.680000,700,1,12.370000,700,1,14.720000,200,2,ARL,288724229
2025-07-17T15:35:05.620763928Z,2025-07-17T15:35:05.620598378Z,10,2,1108,A,A,0,13.77,15,130,165550,243344672,13.300000,100,1,13.770000,15,1,13.230000,2,1,13.810000,100,1,13.030000,100,1,13.830000,100,1,12.730000,100,1,13.950000,2,1,12.710000,100,1,14.120000,100,1,12.500000,700,1,14.560000,800,2,12.460000,200,2,14.600000,700,1,12.430000,700,1,14.610000,100,1,12.420000,700,1,14.650000,100,1,12.370000,700,1,14.680000,700,1,ARL,289722397
2025-07-17T15:35:05.712575243Z,2025-07-17T15:35:05.712409728Z,10,2,1108,C,A,1,13.81,100,0,165515,243347940,13.300000,100,1,13.770000,15,1,13.230000,2,1,13.830000,100,1,13.030000,100,1,13.950000,2,1,12.730000,100,1,14.120000,100,1,12.710000,100,1,14.560000,800,2,12.500000,700,1,14.600000,700,1,12.460000,200,2,14.610000,100,1,12.430000,700,1,14.650000,100,1,12.420000,700,1,14.680000,700,1,12.370000,700,1,14.720000,200,2,ARL,289056097
2025-07-17T15:35:05.712575243Z,2025-07-17T15:35:05.712409728Z,10,2,1108,A,A,1,13.78,100,130,165515,243347940,13.300000,100,1,13.770000,15,1,13.230000,2,1,13.780000,100,1,13.030000,100,1,13.830000,100,1,12.730000,100,1,13.950000,2,1,12.710000,100,1,14.120000,100,1,12.500000,700,1,14.560000,800,2,12.460000,200,2,14.600000,700,1,12.430000,700,1,14.610000,100,1,12.420000,700,1,14.650000,100,1,12.370000,700,1,14.680000,700,1,ARL,289726281
2025-07-17T15:35:05.713315450Z,2025-07-17T15:35:05.713150123Z,10,2,1108,C,A,7,14.61,100,130,165327,243347987,13.300000,100,1,13.770000,15,1,13.230000,2,1,13.780000,100,1,13.030000,100,1,13.830000,100,1,12.730000,100,1,13.950000,2,1,12.710000,100,1,14.120000,100,1,12.500000,700,1,14.560000,800,2,12.460000,200,2,14.600000,700,1,12.430000,700,1,14.650000,100,1,12.420000,700,1,14.680000,700,1,12.370000,700,1,14.720000,200,2,ARL,237978629
2025-07-17T15:35:05.713322577Z,2025-07-17T15:35:05.713157077Z,10,2,1108,C,A,12,14.90,100,0,165500,243347988,13.300000,100,1,13.770000,15,1,13.230000,2,1,13.780000,100,1,13.030000,100,1,13.830000,100,1,12.730000,100,1,13.950000,2,1,12.710000,100,1,14.120000,100,1,12.500000,700,1,14.560000,800,2,12.460000,200,2,14.600000,700,1,12.430000,700,1,14.650000,100,1,12.420000,700,1,14.680000,700,1,12.370000,700,1,14.720000,200,2,ARL,288726085
2025-07-17T15:35:05.713322577Z,2025-07-17T15:35:05.713157077Z,10,2,1108,A,A,-1,14.85,100,130,165500,243347988,13.300000,100,1,13.770000,15,1,13.230000,2,1,13.780000,100,1,13.030000,100,1,13.830000,100,1,12.730000,100,1,13.950000,2,1,12.710000,100,1,14.120000,100,1,12.500000,700,1,14.560000,800,2,12.460000,200,2,14.600000,700,1,12.430000,700,1,14.650000,100,1,12.420000,700,1,14.680000,700,1,12.370000,700,1,14.720000,200,2,ARL,289726349
2025-07-17T15:35:05.713677091Z,2025-07-17T15:35:05.713508657Z,10,2,1108,A,A,5,14.40,100,128,168434,243348032,13.300000,100,1,13.770000,15,1,13.230000,2,1,13.780000,100,1,13.030000,100,1,13.830000,100,1,12.730000,100,1,13.950000,2,1,12.710000,100,1,14.120000,100,1,12.500000,700,1,14.400000,100,1,12.460000,200,2,14.560000,800,2,12.430000,700,1,14.600000,700,1,12.420000,700,1,14.650000,100,1,12.370000,700,1,14.680000,700,1,ARL,289726421
2025-07-17T15:35:05.729568877Z,2025-07-17T15:35:05.729398505Z,10,2,1108,A,A,2,13.80,100,128,170372,243351264,13.300000,100,1,13.770000,15,1,13.230000,2,1,13.780000,100,1,13.030000,100,1,13.800000,100,1,12.730000,100,1,13.830000,100,1,12.710000,100,1,13.950000,2,1,12.500000,700,1,14.120000,100,1,12.460000,200,2,14.400000,100,1,12.430000,700,1,14.560000,800,2,12.420000,700,1,14.600000,700,1,12.370000,700,1,14.650000,100,1,ARL,289730309
2025-07-17T15:35:05.737967956Z,2025-07-17T15:35:05.737802616Z,10,2,1108,C,A,3,13.83,100,130,165340,243352644,13.300000,100,1,13.770000,15,1,13.230000,2,1,13.780000,100,1,13.030000,100,1,13.800000,100,1,12.730000,100,1,13.950000,2,1,12.710000,100,1,14.120000,100,1,12.500000,700,1,14.400000,100,1,12.460000,200,2,14.560000,800,2,12.430000,700,1,14.600000,700,1,12.420000,700,1,14.650000,100,1,12.370000,700,1,14.680000,700,1,ARL,289199221
2025-07-17T15:35:06.286572335Z,2025-07-17T15:35:06.286407017Z,10,2,1108,C,A,0,13.77,15,130,165318,243362628,13.300000,100,1,13.780000,100,1,13.230000,2,1,13.800000,100,1,13.030000,100,1,13.950000,2,1,12.730000,100,1,14.120000,100,1,12.710000,100,1,14.400000,100,1,12.500000,700,1,14.560000,800,2,12.460000,200,2,14.600000,700,1,12.430000,700,1,14.650000,100,1,12.420000,700,1,14.680000,700,1,12.370000,700,1,14.720000,200,2,ARL,289722397
2025-07-17T15:35:09.788280931Z,2025-07-17T15:35:09.788115219Z,10,2,1108,C,B,1,13.23,2,0,165712,243432828,13.300000,100,1,13.780000,100,1,13.030000,100,1,13.800000,100,1,12.730000,100,1,13.950000,2,1,12.710000,100,1,14.120000,100,1,12.500000,700,1,14.400000,100,1,12.460000,200,2,14.560000,800,2,12.430000,700,1,14.600000,700,1,12.420000,700,1,14.650000,100,1,12.370000,700,1,14.680000,700,1,12.360000,200,2,14.720000,200,2,ARL,272263853
2025-07-17T15:35:09.788280931Z,2025-07-17T15:35:09.788115219Z,10,2,1108,A,B,1,13.14,2,130,165712,243432828,13.300000,100,1,13.780000,100,1,13.140000,2,1,13.800000,100,1,13.030000,100,1,13.950000,2,1,12.730000,100,1,14.120000,100,1,12.710000,100,1,14.400000,100,1,12.500000,700,1,14.560000,800,2,12.460000,200,2,14.600000,700,1,12.430000,700,1,14.650000,100,1,12.420000,700,1,14.680000,700,1,12.370000,700,1,14.720000,200,2,ARL,289828293
2025-07-17T15:35:11.891867009Z,2025-07-17T15:35:11.891701845Z,10,2,1108,C,A,1,13.80,100,130,165164,243482295,13.300000,100,1,13.780000,100,1,13.140000,2,1,13.950000,2,1,13.030000,100,1,14.120000,100,1,12.730000,100,1,14.400000,100,1,12.710000,100,1,14.560000,800,2,12.500000,700,1,14.600000,700,1,12.460000,200,2,14.650000,100,1,12.430000,700,1,14.680000,700,1,12.420000,700,1,14.720000,200,2,12.370000,700,1,14.810000,200,2,ARL,289730309
2025-07-17T15:35:14.301647013Z,2025-07-17T15:35:14.301481698Z,10,2,1108,A,A,7,14.68,700,130,165315,243521615,13.300000,100,1,13.780000,100,1,13.140000,2,1,13.950000,2,1,13.030000,100,1,14.120000,100,1,12.730000,100,1,14.400000,100,1,12.710000,100,1,14.560000,800,2,12.500000,700,1,14.600000,700,1,12.460000,200,2,14.650000,100,1,12.430000,700,1,14.680000,1400,2,12.420000,700,1,14.720000,200,2,12.370000,700,1,14.810000,200,2,ARL,289932801
2025-07-17T15:35:14.302443648Z,2025-07-17T15:35:14.302278179Z,10,2,1108,C,A,12,14.91,700,130,165469,243521616,13.300000,100,1,13.780000,100,1,13.140000,2,1,13.950000,2,1,13.030000,100,1,14.120000,100,1,12.730000,100,1,14.400000,100,1,12.710000,100,1,14.560000,800,2,12.500000,700,1,14.600000,700,1,12.460000,200,2,14.650000,100,1,12.430000,700,1,14.680000,1400,2,12.420000,700,1,14.720000,200,2,12.370000,700,1,14.810000,200,2,ARL,147217629
2025-07-17T15:35:15.940644416Z,2025-07-17T15:35:15.940479233Z,10,2,1108,A,A,1,13.82,100,130,165183,243557058,13.300000,100,1,13.780000,100,1,13.140000,2,1,13.820000,100,1,13.030000,100,1,13.950000,2,1,12.730000,100,1,14.120000,100,1,12.710000,100,1,14.400000,100,1,12.500000,700,1,14.560000,800,2,12.460000,200,2,14.600000,700,1,12.430000,700,1,14.650000,100,1,12.420000,700,1,14.680000,1400,2,12.370000,700,1,14.720000,200,2,ARL,289976125
2025-07-17T15:35:23.746674314Z,2025-07-17T15:35:23.746509184Z,10,2,1108,A,A,1,13.80,100,130,165130,243692012,13.300000,100,1,13.780000,100,1,13.140000,2,1,13.800000,100,1,13.030000,100,1,13.820000,100,1,12.730000,100,1,13.950000,2,1,12.710000,100,1,14.120000,100,1,12.500000,700,1,14.400000,100,1,12.460000,200,2,14.560000,800,2,12.430000,700,1,14.600000,700,1,12.420000,700,1,14.650000,100,1,12.370000,700,1,14.680000,1400,2,ARL,290159301
2025-07-17T15:35:23.754618546Z,2025-07-17T15:35:23.754453294Z,10,2,1108,C,A,2,13.82,100,130,165252,243692501,13.300000,100,1,13.780000,100,1,13.140000,2,1,13.800000,100,1,13.030000,100,1,13.950000,2,1,12.730000,100,1,14.120000,100,1,12.710000,100,1,14.400000,100,1,12.500000,700,1,14.560000,800,2,12.460000,200,2,14.600000,700,1,12.430000,700,1,14.650000,100,1,12.420000,700,1,14.680000,1400,2,12.370000,700,1,14.720000,200,2,ARL,289976125
2025-07-17T15:35:39.056679600Z,2025-07-17T15:35:39.056513985Z,10,2,1108,C,A,1,13.80,100,130,165615,243992725,13.300000,100,1,13.780000,100,1,13.140000,2,1,13.950000,2,1,13.030000,100,1,14.120000,100,1,12.730000,100,1,14.400000,100,1,12.710000,100,1,14.560000,800,2,12.500000,700,1,14.600000,700,1,12.460000,200,2,14.650000,100,1,12.430000,700,1,14.680000,1400,2,12.420000,700,1,14.720000,200,2,12.370000,700,1,14.810000,200,2,ARL,290159301
2025-07-17T15:35:43.128809717Z,2025-07-17T15:35:43.128644252Z,10,2,1108,A,A,1,13.82,100,130,165465,244078096,13.300000,100,1,13.780000,100,1,13.140000,2,1,13.820000,100,1,13.030000,100,1,13.950000,2,1,12.730000,100,1,14.120000,100,1,12.710000,100,1,14.400000,100,1,12.500000,700,1,14.560000,800,2,12.460000,200,2,14.600000,700,1,12.430000,700,1,14.650000,100,1,12.420000,700,1,14.680000,1400,2,12.370000,700,1,14.720000,200,2,ARL,290630573
2025-07-17T15:36:30.044094509Z,2025-07-17T15:36:30.043928872Z,10,2,1108,A,A,1,13.80,100,130,165637,245013624,13.300000,100,1,13.780000,100,1,13.140000,2,1,13.800000,100,1,13.030000,100,1,13.820000,100,1,12.730000,100,1,13.950000,2,1,12.710000,100,1,14.120000,100,1,12.500000,700,1,14.400000,100,1,12.460000,200,2,14.560000,800,2,12.430000,700,1,14.600000,700,1,12.420000,700,1,14.650000,100,1,12.370000,700,1,14.680000,1400,2,ARL,291778909
2025-07-17T15:36:30.051045453Z,2025-07-17T15:36:30.050880126Z,10,2,1108,C,A,2,13.82,100,130,165327,245013914,13.300000,100,1,13.780000,100,1,13.140000,2,1,13.800000,100,1,13.030000,100,1,13.950000,2,1,12.730000,100,1,14.120000,100,1,12.710000,100,1,14.400000,100,1,12.500000,700,1,14.560000,800,2,12.460000,200,2,14.600000,700,1,12.430000,700,1,14.650000,100,1,12.420000,700,1,14.680000,1400,2,12.370000,700,1,14.720000,200,2,ARL,290630573
2025-07-17T15:36:34.298010005Z,2025-07-17T15:36:34.297844579Z,10,2,1108,C,B,0,13.30,100,130,165426,245144122,13.140000,2,1,13.780000,100,1,13.030000,100,1,13.800000,100,1,12.730000,100,1,13.950000,2,1,12.710000,100,1,14.120000,100,1,12.500000,700,1,14.400000,100,1,12.460000,200,2,14.560000,800,2,12.430000,700,1,14.600000,700,1,12.420000,700,1,14.650000,100,1,12.370000,700,1,14.680000,1400,2,12.360000,200,2,14.720000,200,2,ARL,288724429
2025-07-17T15:36:35.381330809Z,2025-07-17T15:36:35.381165559Z,10,2,1108,A,B,1,13.13,100,130,165250,245161447,13.140000,2,1,13.780000,100,1,13.130000,100,1,13.800000,100,1,13.030000,100,1,13.950000,2,1,12.730000,100,1,14.120000,100,1,12.710000,100,1,14.400000,100,1,12.500000,700,1,14.560000,800,2,12.460000,200,2,14.600000,700,1,12.430000,700,1,14.650000,100,1,12.420000,700,1,14.680000,1400,2,12.370000,700,1,14.720000,200,2,ARL,291951937
2025-07-17T15:36:35.532851032Z,2025-07-17T15:36:35.532685683Z,10,2,1108,A,B,0,13.27,10,130,165349,245174454,13.270000,10,1,13.780000,100,1,13.140000,2,1,13.800000,100,1,13.130000,100,1,13.950000,2,1,13.030000,100,1,14.120000,100,1,12.730000,100,1,14.400000,100,1,12.710000,100,1,14.560000,800,2,12.500000,700,1,14.600000,700,1,12.460000,200,2,14.650000,100,1,12.430000,700,1,14.680000,1400,2,12.420000,700,1,14.720000,200,2,ARL,291964737
2025-07-17T15:36:35.532926951Z,2025-07-17T15:36:35.532761335Z,10,2,1108,C,B,13,12.27,100,0,165616,245174461,13.270000,10,1,13.780000,100,1,13.140000,2,1,13.800000,100,1,13.130000,100,1,13.950000,2,1,13.030000,100,1,14.120000,100,1,12.730000,100,1,14.400000,100,1,12.710000,100,1,14.560000,800,2,12.500000,700,1,14.600000,700,1,12.460000,200,2,14.650000,100,1,12.430000,700,1,14.680000,1400,2,12.420000,700,1,14.720000,200,2,ARL,288724485
2025-07-17T15:36:35.532926951Z,2025-07-17T15:36:35.532761335Z,10,2,1108,A,B,-1,12.23,100,130,165616,245174461,13.270000,10,1,13.780000,100,1,13.140000,2,1,13.800000,100,1,13.130000,100,1,13.950000,2,1,13.030000,100,1,14.120000,100,1,12.730000,100,1,14.400000,100,1,12.710000,100,1,14.560000,800,2,12.500000,700,1,14.600000,700,1,12.460000,200,2,14.650000,100,1,12.430000,700,1,14.680000,1400,2,12.420000,700,1,14.720000,200,2,ARL,291964745
2025-07-17T15:36:36.152132527Z,2025-07-17T15:36:36.151966883Z,10,2,1108,C,B,2,13.13,100,0,165644,245183955,13.270000,10,1,13.780000,100,1,13.140000,2,1,13.800000,100,1,13.030000,100,1,13.950000,2,1,12.730000,100,1,14.120000,100,1,12.710000,100,1,14.400000,100,1,12.500000,700,1,14.560000,800,2,12.460000,200,2,14.600000,700,1,12.430000,700,1,14.650000,100,1,12.420000,700,1,14.680000,1400,2,12.370000,700,1,14.720000,200,2,ARL,291951937
